Workbook

Sheet Main
A1: Master
B2: ABT
B3: Price | C3: 102.98 | D3: 9/21/2026
B4: SO | C4: 1730.383 | D4: Q2'26
B5: MC | C5: =C3*C4 -> 178194.84
B6: Cash | C6: =5104+499 -> 5603 | D6: Q2'26
B7: Debt | C7: 10036 | D7: Q2'26
B8: EV | C8: =C5-C6+C7 -> 182627.84
B10: Abbott Laboratories (ABT)
B12: Founder(s): | C12: Wallace Calvin Abbott | F12: Registered Exchange: NYSE | N12: Resources:
B13: Founded: 1888 | F13: Address: | G13: 100 Abbott Park Road, Abbott Park North Chicago, IL 60064 U.S. | N13: SEC filings | Q13: https://www.sec.gov/edgar/browse/?CIK=1800&owner=exclude
B14: Headquarters: Chicago, IL | F14: Investor Relations Contact: | N14: Abbott Labs Homepage | Q14: https://www.abbott.com/
B15: Current CEO: Robert Ford | F15: Investors Relation Department | O15: Abbott Labs IR Page | R15: https://www.abbott.com/investors.html
B16: Employees: 114,000 | F16: Phone: | G16: (224) 667-6100 | I16: Email: | J16: investor.relations@abbott.com | O16: Abbott Vascular Products | R16: https://www.cardiovascular.abbott/us/en/hcp/products.html
B17: Industry: Medical Devices - Pharmaceuticals | N17: Earnings Calls | Q17: https://seekingalpha.com/symbol/ABT/earnings/transcripts
B18: Sector: Healthcare | N18: Equity Analysis | Q18: https://stockanalysis.com/stocks/abt/company/
B19: IPO: 1929 … shortly before the start of the Great Depression | N19: MacroTrends | Q19: https://www.macrotrends.net/stocks/charts/ORCL/oracle/income-statement?freq=Q
B20: Fiscal Year: [January - December] | N20: ROIC, WACC | Q20: https://www.gurufocus.com/term/wacc/ABT
N21: Godel Terminal | Q21: https://app.godelterminal.com/
A22: Company Overview:
B23: Founded in 1888 and headquartered in Abbott Park, Illinois, Abbott Laboratories is a diversified global healthcare company that discovers, develops, manufactures, and sells a broad range of healthcare products
C24: Abbott operates across diagnostics, medical devices, nutrition, and branded generic pharmaceuticals segments
B25: Business Segments:
B26: Branded Generic Pharmaceuticals (Approx. 10-15% of Revenue)
C27: Focus on emerging and international markets, offering affordable branded generics for chronic conditions
C28: Management describes a significant growth opportunity as middle-income populations expand in key regions
B29: Nutrition (Approx. 20-25% of Revenue)
C30: Includes adult and pediatric nutritional products like Ensure (meal replacements) and Similac (infant formula)
B31: Diagnostics (Approx. 20-25% of Revenue)
C32: Products include laboratory-based testing instruments and assays, point-of-care diagnostics, blood glucose monitoring (FreeStyle Libre CGM), and molecular diagnostics
D33: Market leader in point-of-care testing, including COVID-19, infectious diseases, and cardiovascular diagnostics
C34: Strong innovation pipeline and expanding global footprint … big MNC presence
B35: Medical Devices (Approx. 35-40% of Revenue)
C36: Includes cardiovascular devices (stents, catheters), neuromodulation devices, diabetes care including CGMs, thrombectomy and other minimally invasive surgical products
D37: Emphasis on implantable cardiac rhythm management and vascular access … Direct competitive overlap with PEN in the thrombectomy & embolization space
C38: Beneficiary of increasing global demand for medical technology and aging populations … large and established japanese presence … kinda the primary case study along with South Korea in reguards to the developed world aging population problem
B39: Market leadership in diagnostics and strong positioning in CGM products (Freestyle Libre platform) … competing with Dexcom
B40: Diversified portfolio across high-growth healthcare segments balancing cyclical risks
C41: Steady demand through economic cycles … especially desirable in economically uncertian times … Bond like earnings prints … evaluate equity beta
C42: Powerful global brands such as Ensure and Similac provide resilience in adverse economic conditions
...

Sheet Model
B1: [Use for Graphing] | AU1: Q1 2020 | AY1: Q1 2021 | BC1: Q1 2022 | BG1: Q1 2023 | BK1: Q1 2024 | BO1: Q1 2025 | BS1: Q1 2026
B2: Quarterly
B3: Revenues | C3: {="Q"&MOD(_xlfn.SEQUENCE(1,72)-1,4)+1&" "&(2009+INT((_xlfn.SEQUENCE(1,72)-1)/4))} -> Q1 2009 | D3: Q2 2009 | E3: Q3 2009 | F3: Q4 2009 | G3: Q1 2010 | H3: Q2 2010 | I3: Q3 2010 | J3: Q4 2010 | K3: Q1 2011 | L3: Q2 2011 | M3: Q3 2011 | N3: Q4 2011 | O3: Q1 2012 | P3: Q2 2012 | Q3: Q3 2012 | R3: Q4 2012 | S3: Q1 2013 | T3: Q2 2013 | U3: Q3 2013 | V3: Q4 2013 | W3: Q1 2014 | X3: Q2 2014 | Y3: Q3 2014 | Z3: Q4 2014 | AA3: Q1 2015 | AB3: Q2 2015 | AC3: Q3 2015 | AD3: Q4 2015 | AE3: Q1 2016 | AF3: Q2 2016 | AG3: Q3 2016 | AH3: Q4 2016 | AI3: Q1 2017 | AJ3: Q2 2017 | AK3: Q3 2017 | AL3: Q4 2017 | AM3: Q1 2018 | AN3: Q2 2018 | AO3: Q3 2018 | AP3: Q4 2018 | AQ3: Q1 2019 | AR3: Q2 2019 | AS3: Q3 2019 | AT3: Q4 2019 | AU3: Q1 2020 | AV3: Q2 2020 | AW3: Q3 2020 | AX3: Q4 2020 | AY3: Q1 2021 | AZ3: Q2 2021 | BA3: Q3 2021 | BB3: Q4 2021 | BC3: Q1 2022 | BD3: Q2 2022 | BE3: Q3 2022 | BF3: Q4 2022 | BG3: Q1 2023 | BH3: Q2 2023 | BI3: Q3 2023 | BJ3: Q4 2023 | BK3: Q1 2024 | BL3: Q2 2024 | BM3: Q3 2024 | BN3: Q4 2024 | BO3: Q1 2025 | BP3: Q2 2025 | BQ3: Q3 2025 | BR3: Q4 2025 | BS3: Q1 2026 | BT3: Q2 2026 | BU3: Q3 2026 | BV3: Q4 2026 | CA3: 2009 | CB3: =CA3+1 -> 2010 | CC3: =CB3+1 -> 2011 | CD3: =CC3+1 -> 2012 | CE3: =CD3+1 -> 2013 | CF3: =CE3+1 -> 2014 | CG3: =CF3+1 -> 2015 | CH3: =CG3+1 -> 2016 | CI3: =CH3+1 -> 2017 | ... EX3: =EW3+1 -> 2084
B4: Ttl Established Pharma Product Revenues | AU4: 1044 | AV4: 1013 | AW4: 1099 | AX4: =4303-SUM(AU4:AW4) -> 1147 | AY4: 1070 | AZ4: 1180 | BA4: 1265 | BB4: =4718-SUM(AY4:BA4) -> 1203 | BC4: 1147 | BD4: =1223 -> 1223 | BE4: 1326 | BF4: =3766+1146-SUM(BC4:BE4) -> 1216 | BG4: 1189 | BH4: 1287 | BI4: 1368 | BJ4: =3807+1259-SUM(BG4:BI4) -> 1222 | BK4: 1226 | BL4: 1294 | BM4: 1406 | BN4: =3858+1336-SUM(BK4:BM4) -> 1268 | BO4: 1260 | BP4: 1383 | BQ4: 1511 | BR4: =1046+336 -> 1382 | BS4: 1426 | BT4: 1426 | CL4: =SUM(AU4:AX4) -> 4303 | CM4: =SUM(AY4:BB4) -> 4718 | CN4: =SUM(BC4:BF4) -> 4912 | CO4: =SUM(BG4:BJ4) -> 5066 | CP4: =SUM(BK4:BN4) -> 5194 | CQ4: =SUM(BO4:BR4) -> 5536 | CR4: =CQ4*(1+CR24) -> 6255.68 | CS4: =CR4*(1+CS24) -> 6943.8048 | CT4: =CS4*(1+CT24) -> 7603.4663 | CU4: =CT4*(1+CU24) -> 8211.7436 | CV4: =CU4*(1+CV24) -> 8827.6243 | CW4: =CV4*(1+CW24) -> 9445.558 | CX4: =CW4*(1+CX24) -> 10059.519 | CY4: =CX4*(1+CY24) -> 10562.495 | CZ4: =CY4*(1+CZ24) -> 11037.808
B5: Pediatric Nutritionals | AU5: 1089 | AV5: 1024 | AW5: 1006 | AX5: =4127-SUM(AU5:AW5) -> 1008 | AY5: 1066 | AZ5: 1093 | BA5: 1100 | BB5: =4298-SUM(AY5:BA5) -> 1039 | BC5: 847 | BD5: 925 | BE5: 827 | BF5: =1919+1562-SUM(BC5:BE5) -> 882 | BG5: 924 | BH5: 1024 | BI5: 1001 | BJ5: =3934-SUM(BG5:BI5) -> 985 | BK5: 1009 | BL5: 1059 | BM5: 955 | BN5: =1815+2208-SUM(BK5:BM5) -> 1000 | BO5: 1041 | BP5: 1054 | BQ5: 977 | BR5: =3974-SUM(BO5:BQ5) -> 902 | BS5: 953 | BT5: 953 | CL5: =SUM(AU5:AX5) -> 4127 | CM5: =SUM(AY5:BB5) -> 4298 | CN5: =SUM(BC5:BF5) -> 3481 | CO5: =SUM(BG5:BJ5) -> 3934 | CP5: =SUM(BK5:BN5) -> 4023 | CQ5: =SUM(BO5:BR5) -> 3974 | CR5: =CQ5*(1+CR25) -> 4343.582 | CS5: =CR5*(1+CS25) -> 3822.3522 | CT5: =CS5*(1+CT25) -> 3593.011 | CU5: =CT5*(1+CU25) -> 3413.3605 | CV5: =CU5*(1+CV25) -> 3457.7342 | CW5: =CV5*(1+CW25) -> 3502.6847 | CX5: =CW5*(1+CX25) -> 3548.2196 | CY5: =CX5*(1+CY25) -> 3590.7982 | CZ5: =CY5*(1+CZ25) -> 3633.8878
B6: Adult Nutritionals | AU6: 815 | AV6: 859 | AW6: 918 | AX6: =3520-SUM(AU6:AW6) -> 928 | AY6: 970 | AZ6: 1015 | BA6: 1008 | BB6: =3996-SUM(AY6:BA6) -> 1003 | BC6: 1047 | BD6: 1028 | BE6: 968 | BF6: =2621+1357-SUM(BC6:BE6) -> 935 | BG6: 1043 | BH6: 1052 | BI6: 1072 | BJ6: =4220-SUM(BG6:BI6) -> 1053 | BK6: 1059 | BL6: 1091 | BM6: 1111 | BN6: =2909+1481-SUM(BK6:BM6) -> 1129 | BO6: 1105 | BP6: 1158 | BQ6: 1176 | BR6: =3029+1448-SUM(BO6:BQ6) -> 1038 | BS6: 1064 | BT6: 1064 | CL6: =SUM(AU6:AX6) -> 3520 | CM6: =SUM(AY6:BB6) -> 3996 | CN6: =SUM(BC6:BF6) -> 3978 | CO6: =SUM(BG6:BJ6) -> 4220 | CP6: =SUM(BK6:BN6) -> 4390 | CQ6: =SUM(BO6:BR6) -> 4477 | CR6: =CQ6*(1+CR26) -> 4208.38 | CS6: =CR6*(1+CS26) -> 3913.7934 | CT6: =CS6*(1+CT26) -> 3718.1037 | CU6: =CT6*(1+CU26) -> 3643.7417 | CV6: =CU6*(1+CV26) -> 3680.1791 | CW6: =CV6*(1+CW26) -> 3753.7827 | CX6: =CW6*(1+CX26) -> 3922.7029 | CY6: =CX6*(1+CY26) -> 4079.611 | CZ6: =CY6*(1+CZ26) -> 4201.9993
B7: Ttl Nutritionals Revenues | AU7: =SUM(AU5:AU6) -> 1904 | AV7: =SUM(AV5:AV6) -> 1883 | AW7: =SUM(AW5:AW6) -> 1924 | AX7: =SUM(AX5:AX6) -> 1936 | AY7: =SUM(AY5:AY6) -> 2036 | AZ7: =SUM(AZ5:AZ6) -> 2108 | BA7: =SUM(BA5:BA6) -> 2108 | BB7: =SUM(BB5:BB6) -> 2042 | ... BT7: =SUM(BT5:BT6) -> 2017 | CL7: =SUM(AU7:AX7) -> 7647 | CM7: =SUM(AY7:BB7) -> 8294 | CN7: =SUM(BC7:BF7) -> 7459 | CO7: =SUM(BG7:BJ7) -> 8154 | CP7: =SUM(BK7:BN7) -> 8413 | CQ7: =SUM(BO7:BR7) -> 8451 | CR7: =SUM(CR5:CR6) -> 8551.962 | CS7: =SUM(CS5:CS6) -> 7736.1456 | CT7: =SUM(CT5:CT6) -> 7311.1148 | CU7: =SUM(CU5:CU6) -> 7057.1021 | CV7: =SUM(CV5:CV6) -> 7137.9132 | CW7: =SUM(CW5:CW6) -> 7256.4674 | CX7: =SUM(CX5:CX6) -> 7470.9225 | CY7: =SUM(CY5:CY6) -> 7670.4092 | CZ7: =SUM(CZ5:CZ6) -> 7835.8871
B8: Core Lab | AU8: 989 | AV8: 987 | AW8: 1176 | AX8: =4475-SUM(AU8:AW8) -> 1323 | AY8: 1182 | AZ8: 1306 | BA8: 1292 | BB8: =5128-SUM(AY8:BA8) -> 1348 | BC8: 1184 | BD8: 1221 | BE8: 1219 | BF8: =4888-SUM(BC8:BE8) -> 1264 | BG8: 1182 | BH8: 1293 | BI8: 1314 | BJ8: =5159-SUM(BG8:BI8) -> 1370 | BK8: 1205 | BL8: 1329 | BM8: 1314 | BN8: =5235-SUM(BK8:BM8) -> 1387 | BO8: 1177 | BP8: 1358 | BQ8: 1364 | BR8: 1461 | BS8: 1272 | BT8: 1272 | CL8: =SUM(AU8:AX8) -> 4475 | CM8: =SUM(AY8:BB8) -> 5128 | CN8: =SUM(BC8:BF8) -> 4888 | CO8: =SUM(BG8:BJ8) -> 5159 | CP8: =SUM(BK8:BN8) -> 5235 | CQ8: =SUM(BO8:BR8) -> 5360 | CR8: =CQ8*(1+CR28) -> 5547.6 | CS8: =CR8*(1+CS28) -> 5625.2664 | CT8: =CS8*(1+CT28) -> 5704.0201 | CU8: =CT8*(1+CU28) -> 5778.1724 | CV8: =CU8*(1+CV28) -> 5853.2886 | CW8: =CV8*(1+CW28) -> 5923.5281 | CX8: =CW8*(1+CX28) -> 5994.6104 | CY8: =CX8*(1+CY28) -> 6060.5511 | CZ8: =CY8*(1+CZ28) -> 6127.2172
B9: Molecular | AU9: 139 | AV9: 359 | AW9: 458 | AX9: =1438-SUM(AU9:AW9) -> 482 | AY9: 447 | AZ9: 290 | BA9: 345 | BB9: =1427-SUM(AY9:BA9) -> 345 | BC9: 420 | BD9: 212 | BE9: 183 | BF9: =995-SUM(BC9:BE9) -> 180 | BG9: 147 | BH9: 141 | BI9: 133 | BJ9: =574-SUM(BG9:BI9) -> 153 | BK9: 129 | BL9: 127 | BM9: 128 | BN9: =521-SUM(BK9:BM9) -> 137 | BO9: 122 | BP9: 123 | BQ9: 131 | BR9: 141 | BS9: 149 | BT9: 149 | CL9: =SUM(AU9:AX9) -> 1438 | CM9: =SUM(AY9:BB9) -> 1427 | CN9: =SUM(BC9:BF9) -> 995 | CO9: =SUM(BG9:BJ9) -> 574 | CP9: =SUM(BK9:BN9) -> 521 | CQ9: =SUM(BO9:BR9) -> 517 | CR9: =CQ9*(1+CR29) -> 625.57 | CS9: =CR9*(1+CS29) -> 744.4283 | CT9: =CS9*(1+CT29) -> 863.53683 | CU9: =CT9*(1+CU29) -> 993.06735 | CV9: =CU9*(1+CV29) -> 1132.0968 | CW9: =CV9*(1+CW29) -> 1279.2694 | CX9: =CW9*(1+CX29) -> 1439.178 | CY9: =CX9*(1+CY29) -> 1611.8794 | CZ9: =CY9*(1+CZ29) -> 1797.2455
B10: Point of Care | AU10: 138 | AV10: 118 | AW10: 131 | AX10: =516-SUM(AU10:AW10) -> 129 | AY10: 129 | AZ10: 137 | BA10: 135 | BB10: =536-SUM(AY10:BA10) -> 135 | BC10: 128 | BD10: 139 | BE10: 127 | BF10: =525-SUM(BC10:BE10) -> 131 | BG10: 134 | BH10: 142 | BI10: 140 | BJ10: =565-SUM(BG10:BI10) -> 149 | BK10: 139 | BL10: 156 | BM10: 146 | BN10: =588-SUM(BK10:BM10) -> 147 | BO10: 142 | BP10: 148 | BQ10: 158 | BR10: 158 | BS10: 96 | BT10: 96 | CL10: =SUM(AU10:AX10) -> 516 | CM10: =SUM(AY10:BB10) -> 536 | CN10: =SUM(BC10:BF10) -> 525 | CO10: =SUM(BG10:BJ10) -> 565 | CP10: =SUM(BK10:BN10) -> 588 | CQ10: =SUM(BO10:BR10) -> 606 | CR10: =CQ10*(1+CR30) -> 412.08 | CS10: =CR10*(1+CS30) -> 296.6976 | CT10: =CS10*(1+CT30) -> 314.49946 | CU10: =CT10*(1+CU30) -> 331.79693 | CV10: =CU10*(1+CV30) -> 349.21626 | CW10: =CV10*(1+CW30) -> 366.67708 | CX10: =CW10*(1+CX30) -> 384.09424 | CY10: =CX10*(1+CY30) -> 401.37848 | CZ10: =CY10*(1+CZ30) -> 418.43707
B11: Rapid Diagnostics | AU11: 560 | AV11: 530 | AW11: 875 | AX11: =4376-SUM(AU11:AW11) -> 2411 | AY11: 2256 | AZ11: 1514 | BA11: 2140 | BB11: =8553-SUM(AY11:BA11) -> 2643 | BC11: 3525 | BD11: 2722 | BE11: 2112 | BF11: =10061-SUM(BC11:BE11) -> 1702 | BG11: 1225 | BH11: 741 | BI11: 862 | BJ11: =3690-SUM(BG11:BI11) -> 862 | BK11: 741 | BL11: 583 | BM11: 824 | BN11: =2997-SUM(BK11:BM11) -> 849 | BO11: 613 | BP11: 544 | BQ11: 600 | BR11: 697 | BS11: 663 | BT11: 663 | CL11: =SUM(AU11:AX11) -> 4376 | CM11: =SUM(AY11:BB11) -> 8553 | CN11: =SUM(BC11:BF11) -> 10061 | CO11: =SUM(BG11:BJ11) -> 3690 | CP11: =SUM(BK11:BN11) -> 2997 | CQ11: =SUM(BO11:BR11) -> 2454 | CR11: =CQ11*(1+CR31) -> 2871.18 | CS11: =CR11*(1+CS31) -> 3474.1278 | CT11: =CS11*(1+CT31) -> 4238.4359 | CU11: =CT11*(1+CU31) -> 5001.3544 | CV11: =CU11*(1+CV31) -> 5801.5711 | CW11: =CV11*(1+CW31) -> 6671.8067 | CX11: =CW11*(1+CX31) -> 7605.8597 | CY11: =CX11*(1+CY31) -> 8594.6214 | CZ11: =CY11*(1+CZ31) -> 9625.976
B12: Ttl Diagnostics Revenues | AU12: =SUM(AU8:AU11) -> 1826 | AV12: =SUM(AV8:AV11) -> 1994 | AW12: =SUM(AW8:AW11) -> 2640 | AX12: =SUM(AX8:AX11) -> 4345 | AY12: =SUM(AY8:AY11) -> 4014 | AZ12: =SUM(AZ8:AZ11) -> 3247 | BA12: =SUM(BA8:BA11) -> 3912 | BB12: =SUM(BB8:BB11) -> 4471 | ... BT12: =SUM(BT8:BT11) -> 2180 | CL12: =SUM(AU12:AX12) -> 10805 | CM12: =SUM(AY12:BB12) -> 15644 | CN12: =SUM(BC12:BF12) -> 16469 | CO12: =SUM(BG12:BJ12) -> 9988 | CP12: =SUM(BK12:BN12) -> 9341 | CQ12: =SUM(BO12:BR12) -> 8937 | CR12: =SUM(CR8:CR11) -> 9456.43 | CS12: =SUM(CS8:CS11) -> 10140.52 | CT12: =SUM(CT8:CT11) -> 11120.492 | CU12: =SUM(CU8:CU11) -> 12104.391 | CV12: =SUM(CV8:CV11) -> 13136.173 | CW12: =SUM(CW8:CW11) -> 14241.281 | CX12: =SUM(CX8:CX11) -> 15423.742 | CY12: =SUM(CY8:CY11) -> 16668.43 | CZ12: =SUM(CZ8:CZ11) -> 17968.876
B13: Rhythm Management | AU13: 474 | AV13: 401 | AW13: 507 | AX13: =1914-SUM(AU13:AW13) -> 532 | AY13: 519 | AZ13: 567 | BA13: 571 | BB13: =2198-SUM(AY13:BA13) -> 541 | BC13: 524 | BD13: 548 | BE13: 533 | BF13: =2119-SUM(BC13:BE13) -> 514 | BG13: 527 | BH13: 583 | BI13: 563 | BJ13: =2255-SUM(BG13:BI13) -> 582 | BK13: 562 | BL13: 607 | BM13: 597 | BN13: =2390-SUM(BK13:BM13) -> 624 | BO13: 585 | BP13: 673 | BQ13: 686 | BR13: 705 | BS13: 684 | BT13: 684 | CL13: =SUM(AU13:AX13) -> 1914 | CM13: =SUM(AY13:BB13) -> 2198 | CN13: =SUM(BC13:BF13) -> 2119 | CO13: =SUM(BG13:BJ13) -> 2255 | CP13: =SUM(BK13:BN13) -> 2390 | CQ13: =SUM(BO13:BR13) -> 2649 | CR13: =CQ13*(1+CR33) -> 2999.9925 | CS13: =CR13*(1+CS33) -> 3359.9916 | CT13: =CS13*(1+CT33) -> 3729.5907 | CU13: =CT13*(1+CU33) -> 4121.1977 | CV13: =CU13*(1+CV33) -> 4492.1055 | CW13: =CV13*(1+CW33) -> 4829.0134 | CX13: =CW13*(1+CX33) -> 5118.7542 | CY13: =CX13*(1+CY33) -> 5374.6919 | CZ13: =CY13*(1+CZ33) -> 5589.6796
B14: Electrophysiology | AU14: 388 | AV14: 299 | AW14: 441 | AX14: =1578-SUM(AU14:AW14) -> 450 | AY14: 431 | AZ14: 487 | BA14: 485 | BB14: =1907-SUM(AY14:BA14) -> 504 | BC14: 485 | BD14: 486 | BE14: 469 | BF14: =1927-SUM(BC14:BE14) -> 487 | BG14: 505 | BH14: 553 | BI14: 544 | BJ14: =2195-SUM(BG14:BI14) -> 593 | BK14: 587 | BL14: 627 | BM14: 610 | BN14: =2467-SUM(BK14:BM14) -> 643 | BO14: 629 | BP14: 700 | BQ14: 705 | BR14: 730 | BS14: 788 | BT14: 788 | CL14: =SUM(AU14:AX14) -> 1578 | CM14: =SUM(AY14:BB14) -> 1907 | CN14: =SUM(BC14:BF14) -> 1927 | CO14: =SUM(BG14:BJ14) -> 2195 | CP14: =SUM(BK14:BN14) -> 2467 | CQ14: =SUM(BO14:BR14) -> 2764 | CR14: =CQ14*(1+CR34) -> 3372.08 | CS14: =CR14*(1+CS34) -> 3945.3336 | CT14: =CS14*(1+CT34) -> 4576.587 | CU14: =CT14*(1+CU34) -> 5285.958 | CV14: =CU14*(1+CV34) -> 6052.4219 | CW14: =CV14*(1+CW34) -> 6839.2367 | CX14: =CW14*(1+CX34) -> 7591.5527 | CY14: =CX14*(1+CY34) -> 8236.8347 | CZ14: =CY14*(1+CZ34) -> 8772.229
B15: Heart Failure | AU15: 203 | AV15: 158 | AW15: 190 | AX15: =740-SUM(AU15:AW15) -> 189 | AY15: 194 | AZ15: 227 | BA15: 229 | BB15: =889-SUM(AY15:BA15) -> 239 | BC15: 250 | BD15: 269 | BE15: 258 | BF15: =1035-SUM(BC15:BE15) -> 258 | BG15: 281 | BH15: 295 | BI15: 284 | BJ15: =1161-SUM(BG15:BI15) -> 301 | BK15: 305 | BL15: 321 | BM15: 322 | BN15: =1279-SUM(BK15:BM15) -> 331 | BO15: 339 | BP15: 368 | BQ15: 366 | BR15: 375 | BS15: 389 | BT15: 389 | CL15: =SUM(AU15:AX15) -> 740 | CM15: =SUM(AY15:BB15) -> 889 | CN15: =SUM(BC15:BF15) -> 1035 | CO15: =SUM(BG15:BJ15) -> 1161 | CP15: =SUM(BK15:BN15) -> 1279 | CQ15: =SUM(BO15:BR15) -> 1448 | CR15: =CQ15*(1+CR35) -> 1629 | CS15: =CR15*(1+CS35) -> 1791.9 | CT15: =CS15*(1+CT35) -> 1935.252 | CU15: =CT15*(1+CU35) -> 2051.3671 | CV15: =CU15*(1+CV35) -> 2153.9355 | CW15: =CV15*(1+CW35) -> 2240.0929 | CX15: =CW15*(1+CX35) -> 2307.2957 | CY15: =CX15*(1+CY35) -> 2353.4416 | CZ15: =CY15*(1+CZ35) -> 2388.7432
B16: Vascular | AU16: 625 | AV16: 481 | AW16: 630 | AX16: =2339-SUM(AU16:AW16) -> 603 | AY16: 635 | AZ16: 697 | BA16: 644 | BB16: =2654-SUM(AY16:BA16) -> 678 | BC16: 619 | BD16: 653 | BE16: 606 | BF16: =2483-SUM(BC16:BE16) -> 605 | BG16: 617 | BH16: 715 | BI16: 672 | BJ16: =2681-SUM(BG16:BI16) -> 677 | BK16: 689 | BL16: 724 | BM16: 699 | BN16: =2837-SUM(BK16:BM16) -> 725 | BO16: 710 | BP16: 757 | BQ16: 745 | BR16: 783 | BS16: 777 | BT16: 777 | CL16: =SUM(AU16:AX16) -> 2339 | CM16: =SUM(AY16:BB16) -> 2654 | CN16: =SUM(BC16:BF16) -> 2483 | CO16: =SUM(BG16:BJ16) -> 2681 | CP16: =SUM(BK16:BN16) -> 2837 | CQ16: =SUM(BO16:BR16) -> 2995 | CR16: =CQ16*(1+CR36) -> 3264.55 | CS16: =CR16*(1+CS36) -> 3525.714 | CT16: =CS16*(1+CT36) -> 3772.514 | CU16: =CT16*(1+CU36) -> 3998.8648 | CV16: =CU16*(1+CV36) -> 4198.8081 | CW16: =CV16*(1+CW36) -> 4366.7604 | CX16: =CW16*(1+CX36) -> 4497.7632 | CY16: =CX16*(1+CY36) -> 4587.7185 | CZ16: =CY16*(1+CZ36) -> 4633.5956
B17: Structural Heart | AU17: 318 | AV17: 223 | AW17: 353 | AX17: =1247-SUM(AU17:AW17) -> 353 | AY17: 377 | AZ17: 422 | BA17: 392 | BB17: =1610-SUM(AY17:BA17) -> 419 | BC17: 411 | BD17: 440 | BE17: 420 | BF17: =1712-SUM(BC17:BE17) -> 441 | BG17: 461 | BH17: 498 | BI17: 487 | BJ17: =1944-SUM(BG17:BI17) -> 498 | BK17: 515 | BL17: 564 | BM17: 558 | BN17: =2246-SUM(BK17:BM17) -> 609 | BO17: 577 | BP17: 636 | BQ17: 635 | BR17: 675 | BS17: 578 | BT17: 578 | CL17: =SUM(AU17:AX17) -> 1247 | CM17: =SUM(AY17:BB17) -> 1610 | CN17: =SUM(BC17:BF17) -> 1712 | CO17: =SUM(BG17:BJ17) -> 1944 | CP17: =SUM(BK17:BN17) -> 2246 | CQ17: =SUM(BO17:BR17) -> 2523 | CR17: =CQ17*(1+CR37) -> 2422.08 | CS17: =CR17*(1+CS37) -> 2397.8592 | CT17: =CS17*(1+CT37) -> 2565.7093 | CU17: =CT17*(1+CU37) -> 2796.6232 | CV17: =CU17*(1+CV37) -> 3090.2686 | CW17: =CV17*(1+CW37) -> 3368.3928 | CX17: =CW17*(1+CX37) -> 3621.0223 | CY17: =CX17*(1+CY37) -> 3838.2836 | CZ17: =CY17*(1+CZ37) -> 4011.0064
B18: Neuromodulation | AU18: 177 | AV18: 106 | AW18: 206 | AX18: =702-SUM(AU18:AW18) -> 213 | AY18: 184 | AZ18: 210 | BA18: 190 | BB18: =781-SUM(AY18:BA18) -> 197 | BC18: 179 | BD18: 197 | BE18: 192 | BF18: =770-SUM(BC18:BE18) -> 202 | BG18: 196 | BH18: 227 | BI18: 227 | BJ18: =890-SUM(BG18:BI18) -> 240 | BK18: 226 | BL18: 243 | BM18: 236 | BN18: =962-SUM(BK18:BM18) -> 257 | BO18: 228 | BP18: 254 | BQ18: 254 | BR18: 274 | BS18: 243 | BT18: 243 | CL18: =SUM(AU18:AX18) -> 702 | CM18: =SUM(AY18:BB18) -> 781 | CN18: =SUM(BC18:BF18) -> 770 | CO18: =SUM(BG18:BJ18) -> 890 | CP18: =SUM(BK18:BN18) -> 962 | CQ18: =SUM(BO18:BR18) -> 1010 | CR18: =CQ18*(1+CR38) -> 1040.3 | CS18: =CR18*(1+CS38) -> 1087.1135 | CT18: =CS18*(1+CT38) -> 1152.3403 | CU18: =CT18*(1+CU38) -> 1227.2424 | CV18: =CU18*(1+CV38) -> 1300.877 | CW18: =CV18*(1+CW38) -> 1372.4252 | CX18: =CW18*(1+CX38) -> 1434.1843 | CY18: =CX18*(1+CY38) -> 1484.3808 | CZ18: =CY18*(1+CZ38) -> 1521.4903
B19: Diabetes Care | AU19: 752 | AV19: 755 | AW19: 843 | AX19: =3267-SUM(AU19:AW19) -> 917 | AY19: 980 | AZ19: 1056 | BA19: 1121 | BB19: =4328-SUM(AY19:BA19) -> 1171 | BC19: 1126 | BD19: 1192 | BE19: 1167 | BF19: =4756-SUM(BC19:BE19) -> 1271 | BG19: 1313 | BH19: 1424 | BI19: 1472 | BJ19: =5761-SUM(BG19:BI19) -> 1552 | BK19: 1569 | BL19: 1648 | BM19: 1725 | BN19: =6805-SUM(BK19:BM19) -> 1863 | BO19: 1827 | BP19: 1981 | BQ19: 2057 | BR19: 2133 | BS19: 2080 | BT19: 2080 | CL19: =SUM(AU19:AX19) -> 3267 | CM19: =SUM(AY19:BB19) -> 4328 | CN19: =SUM(BC19:BF19) -> 4756 | CO19: =SUM(BG19:BJ19) -> 5761 | CP19: =SUM(BK19:BN19) -> 6805 | CQ19: =SUM(BO19:BR19) -> 7998 | CR19: =CQ19*(1+CR39) -> 9117.72 | CS19: =CR19*(1+CS39) -> 10713.321 | CT19: =CS19*(1+CT39) -> 12641.719 | CU19: =CT19*(1+CU39) -> 14537.977 | CV19: =CU19*(1+CV39) -> 16427.914 | CW19: =CV19*(1+CW39) -> 18234.984 | CX19: =CW19*(1+CX39) -> 19876.133 | CY19: =CX19*(1+CY39) -> 21267.462 | CZ19: =CY19*(1+CZ39) -> 22543.51
B20: Ttl Med Device Revenues | AU20: =SUM(AU13:AU19) -> 2937 | AV20: =SUM(AV13:AV19) -> 2423 | AW20: =SUM(AW13:AW19) -> 3170 | AX20: =SUM(AX13:AX19) -> 3257 | AY20: =SUM(AY13:AY19) -> 3320 | AZ20: =SUM(AZ13:AZ19) -> 3666 | BA20: =SUM(BA13:BA19) -> 3632 | BB20: =SUM(BB13:BB19) -> 3749 | ... BT20: =SUM(BT13:BT19) -> 5539 | CL20: =SUM(AU20:AX20) -> 11787 | CM20: =SUM(AY20:BB20) -> 14367 | CN20: =SUM(BC20:BF20) -> 14802 | CO20: =SUM(BG20:BJ20) -> 16887 | CP20: =SUM(BK20:BN20) -> 18986 | CQ20: =SUM(BO20:BR20) -> 21387 | CR20: =SUM(CR13:CR19) -> 23845.723 | CS20: =SUM(CS13:CS19) -> 26821.233 | CT20: =SUM(CT13:CT19) -> 30373.712 | CU20: =SUM(CU13:CU19) -> 34019.23 | CV20: =SUM(CV13:CV19) -> 37716.33 | CW20: =SUM(CW13:CW19) -> 41250.905 | CX20: =SUM(CX13:CX19) -> 44446.705 | CY20: =SUM(CY13:CY19) -> 47142.813 | CZ20: =SUM(CZ13:CZ19) -> 49460.254
B21: Other Revenues | AU21: 15 | AV21: 15 | AW21: 20 | AX21: =66-SUM(AU21:AW21) -> 16 | AY21: 16 | AZ21: 22 | BA21: 11 | BB21: =52-SUM(AY21:BA21) -> 3 | BC21: 3 | BD21: 2 | BE21: 3 | BF21: =11-SUM(BC21:BE21) -> 3 | BG21: 3 | BH21: 3 | BI21: 4 | BJ21: =14-SUM(BG21:BI21) -> 4 | BK21: 3 | BL21: 4 | BM21: 4 | BN21: =16-SUM(BK21:BM21) -> 5 | BO21: 3 | BP21: 5 | BQ21: 4 | BR21: =17-SUM(BO21:BQ21) -> 5 | BS21: 2 | BT21: 2 | CL21: =SUM(AU21:AX21) -> 66 | CM21: =SUM(AY21:BB21) -> 52 | CN21: =SUM(BC21:BF21) -> 11 | CO21: =SUM(BG21:BJ21) -> 14 | CP21: =SUM(BK21:BN21) -> 16 | CQ21: =SUM(BO21:BR21) -> 17 | CR21: =CQ21*(1+CR41) -> 8.5 | CS21: =CR21*(1+CS41) -> 9.35 | CT21: =CS21*(1+CT41) -> 10.3785 | CU21: =CT21*(1+CU41) -> 11.727705 | CV21: =CU21*(1+CV41) -> 13.486861 | CW21: =CV21*(1+CW41) -> 15.50989 | CX21: =CW21*(1+CX41) -> 17.836373 | CY21: =CX21*(1+CY41) -> 20.511829 | CZ21: =CY21*(1+CZ41) -> 23.588604
B22: Ttl Revenues | AU22: =AU21+AU20+AU12+AU7+AU4 -> 7726 | AV22: =AV21+AV20+AV12+AV7+AV4 -> 7328 | AW22: =AW21+AW20+AW12+AW7+AW4 -> 8853 | AX22: =AX21+AX20+AX12+AX7+AX4 -> 10701 | AY22: =AY21+AY20+AY12+AY7+AY4 -> 10456 | AZ22: =AZ21+AZ20+AZ12+AZ7+AZ4 -> 10223 | BA22: =BA21+BA20+BA12+BA7+BA4 -> 10928 | BB22: =BB21+BB20+BB12+BB7+BB4 -> 11468 | ... BT22: =BT21+BT20+BT12+BT7+BT4 -> 11164 | CL22: =SUM(AU22:AX22) -> 34608 | CM22: =SUM(AY22:BB22) -> 43075 | CN22: =SUM(BC22:BF22) -> 43653 | CO22: =SUM(BG22:BJ22) -> 40109 | CP22: =SUM(BK22:BN22) -> 41950 | CQ22: =SUM(BO22:BR22) -> 44328 | CR22: =CR21+CR20+CR12+CR7+CR4 -> 48118.295 | CS22: =CS21+CS20+CS12+CS7+CS4 -> 51651.053 | CT22: =CT21+CT20+CT12+CT7+CT4 -> 56419.164 | CU22: =CU21+CU20+CU12+CU7+CU4 -> 61404.194 | CV22: =CV21+CV20+CV12+CV7+CV4 -> 66831.527 | CW22: =CW21+CW20+CW12+CW7+CW4 -> 72209.722 | CX22: =CX21+CX20+CX12+CX7+CX4 -> 77418.726 | CY22: =CY21+CY20+CY12+CY7+CY4 -> 82064.66 | CZ22: =CZ21+CZ20+CZ12+CZ7+CZ4 -> 86326.413
B24: Ttl Established Pharma Product Revenue Growth Y/y | AY24: =AY4/AU4-1 -> 0.024904215 | AZ24: =AZ4/AV4-1 -> 0.16485686 | BA24: =BA4/AW4-1 -> 0.15104641 | BB24: =BB4/AX4-1 -> 0.048823017 | BC24: =BC4/AY4-1 -> 0.071962617 | BD24: =BD4/AZ4-1 -> 0.036440678 | BE24: =BE4/BA4-1 -> 0.048221344 | BF24: =BF4/BB4-1 -> 0.010806318 | ... BT24: =BT4/BP4-1 -> 0.031091829 | CM24: =CM4/CL4-1 -> 0.096444341 | CN24: =CN4/CM4-1 -> 0.041119118 | CO24: =CO4/CN4-1 -> 0.031351792 | CP24: =CP4/CO4-1 -> 0.025266482 | CQ24: 0.15 | CR24: 0.13 | CS24: 0.11 | CT24: 0.095 | CU24: 0.08 | CV24: 0.075 | CW24: 0.07 | CX24: 0.065 | CY24: 0.05 | CZ24: 0.045
B25: Pediatric Nutritionals Growth Y/y | AY25: =AY5/AU5-1 -> -0.021120294 | AZ25: =AZ5/AV5-1 -> 0.067382812 | BA25: =BA5/AW5-1 -> 0.093439364 | BB25: =BB5/AX5-1 -> 0.030753968 | BC25: =BC5/AY5-1 -> -0.2054409 | BD25: =BD5/AZ5-1 -> -0.1537054 | BE25: =BE5/BA5-1 -> -0.24818182 | BF25: =BF5/BB5-1 -> -0.15110683 | ... BT25: =BT5/BP5-1 -> -0.095825427 | CM25: =CM5/CL5-1 -> 0.041434456 | CN25: =CN5/CM5-1 -> -0.19008841 | CO25: =CO5/CN5-1 -> 0.13013502 | CP25: =CP5/CO5-1 -> 0.022623284 | CQ25: 0.016 | CR25: 0.093 | CS25: -0.12 | CT25: -0.06 | CU25: -0.05 | CV25: 0.013 | CW25: 0.013 | CX25: 0.013 | CY25: 0.012 | CZ25: 0.012
B26: Adult Nutritionals Growth Y/y | AY26: =AY6/AU6-1 -> 0.19018405 | AZ26: =AZ6/AV6-1 -> 0.18160652 | BA26: =BA6/AW6-1 -> 0.098039216 | BB26: =BB6/AX6-1 -> 0.080818966 | BC26: =BC6/AY6-1 -> 0.079381443 | BD26: =BD6/AZ6-1 -> 0.012807882 | BE26: =BE6/BA6-1 -> -0.03968254 | BF26: =BF6/BB6-1 -> -0.06779661 | ... BT26: =BT6/BP6-1 -> -0.081174439 | CM26: =CM6/CL6-1 -> 0.13522727 | CN26: =CN6/CM6-1 -> -0.0045045045 | CO26: =CO6/CN6-1 -> 0.06083459 | CP26: =CP6/CO6-1 -> 0.04028436 | CQ26: 0.045 | CR26: -0.06 | CS26: -0.07 | CT26: -0.05 | CU26: -0.02 | CV26: 0.01 | CW26: 0.02 | CX26: 0.045 | CY26: 0.04 | CZ26: 0.03
B27: Ttl Nutritionals Revenues Growth Y/y | AY27: =AY7/AU7-1 -> 0.069327731 | AZ27: =AZ7/AV7-1 -> 0.11949018 | BA27: =BA7/AW7-1 -> 0.095634096 | BB27: =BB7/AX7-1 -> 0.054752066 | BC27: =BC7/AY7-1 -> -0.069744597 | BD27: =BD7/AZ7-1 -> -0.073529412 | BE27: =BE7/BA7-1 -> -0.14848197 | BF27: =BF7/BB7-1 -> -0.11018609 | ... BT27: =BT7/BP7-1 -> -0.088155515 | CM27: =CM7/CL7-1 -> 0.084608343 | CN27: =CN7/CM7-1 -> -0.10067519 | CO27: =CO7/CN7-1 -> 0.093176029 | CP27: =CP7/CO7-1 -> 0.031763552 | CQ27: =CQ7/CP7-1 -> 0.0045168192 | CR27: =CR7/CQ7-1 -> 0.011946752 | CS27: =CS7/CR7-1 -> -0.095395237 | CT27: =CT7/CS7-1 -> -0.0549409 | ... CZ27: =CZ7/CY7-1 -> 0.021573544
B28: Core Lab Growth Y/y | AY28: =AY8/AU8-1 -> 0.19514661 | AZ28: =AZ8/AV8-1 -> 0.32320162 | BA28: =BA8/AW8-1 -> 0.098639456 | BB28: =BB8/AX8-1 -> 0.018896447 | BC28: =BC8/AY8-1 -> 0.0016920474 | BD28: =BD8/AZ8-1 -> -0.065084227 | BE28: =BE8/BA8-1 -> -0.056501548 | BF28: =BF8/BB8-1 -> -0.06231454 | ... BT28: =BT8/BP8-1 -> -0.063328424 | CM28: =CM8/CL8-1 -> 0.14592179 | CN28: =CN8/CM8-1 -> -0.046801872 | CO28: =CO8/CN8-1 -> 0.055441899 | CP28: =CP8/CO8-1 -> 0.014731537 | CQ28: 0.02 | CR28: 0.035 | CS28: 0.014 | CT28: 0.014 | CU28: 0.013 | CV28: 0.013 | CW28: 0.012 | CX28: 0.012 | CY28: 0.011 | CZ28: 0.011
B29: Molecular Growth Y/y | AY29: =AY9/AU9-1 -> 2.2158273 | AZ29: =AZ9/AV9-1 -> -0.19220056 | BA29: =BA9/AW9-1 -> -0.24672489 | BB29: =BB9/AX9-1 -> -0.28423237 | BC29: =BC9/AY9-1 -> -0.060402685 | BD29: =BD9/AZ9-1 -> -0.26896552 | BE29: =BE9/BA9-1 -> -0.46956522 | BF29: =BF9/BB9-1 -> -0.47826087 | ... BT29: =BT9/BP9-1 -> 0.21138211 | CM29: =CM9/CL9-1 -> -0.0076495132 | CN29: =CN9/CM9-1 -> -0.30273301 | CO29: =CO9/CN9-1 -> -0.42311558 | CP29: =CP9/CO9-1 -> -0.092334495 | CQ29: 0.01 | CR29: 0.21 | CS29: 0.19 | CT29: 0.16 | CU29: 0.15 | CV29: 0.14 | CW29: 0.13 | CX29: 0.125 | CY29: 0.12 | CZ29: 0.115
B30: Point of Care Growth Y/y | AY30: =AY10/AU10-1 -> -0.065217391 | AZ30: =AZ10/AV10-1 -> 0.16101695 | BA30: =BA10/AW10-1 -> 0.030534351 | BB30: =BB10/AX10-1 -> 0.046511628 | BC30: =BC10/AY10-1 -> -0.007751938 | BD30: =BD10/AZ10-1 -> 0.01459854 | BE30: =BE10/BA10-1 -> -0.059259259 | BF30: =BF10/BB10-1 -> -0.02962963 | ... BT30: =BT10/BP10-1 -> -0.35135135 | CM30: =CM10/CL10-1 -> 0.03875969 | CN30: =CN10/CM10-1 -> -0.020522388 | CO30: =CO10/CN10-1 -> 0.076190476 | CP30: =CP10/CO10-1 -> 0.040707965 | CQ30: 0.04 | CR30: -0.32 | CS30: -0.28 | CT30: 0.06 | CU30: 0.055 | CV30: 0.0525 | CW30: 0.05 | CX30: 0.0475 | CY30: 0.045 | CZ30: 0.0425
B31: Rapid Diagnostics Growth Y/y | AY31: =AY11/AU11-1 -> 3.0285714 | AZ31: =AZ11/AV11-1 -> 1.8566038 | BA31: =BA11/AW11-1 -> 1.4457143 | BB31: =BB11/AX11-1 -> 0.096225633 | BC31: =BC11/AY11-1 -> 0.5625 | BD31: =BD11/AZ11-1 -> 0.79788639 | BE31: =BE11/BA11-1 -> -0.013084112 | BF31: =BF11/BB11-1 -> -0.35603481 | ... BT31: =BT11/BP11-1 -> 0.21875 | CM31: =CM11/CL11-1 -> 0.95452468 | CN31: =CN11/CM11-1 -> 0.17631241 | CO31: =CO11/CN11-1 -> -0.63323725 | CP31: =CP11/CO11-1 -> -0.18780488 | CQ31: -0.11 | CR31: 0.17 | CS31: 0.21 | CT31: 0.22 | CU31: 0.18 | CV31: 0.16 | CW31: 0.15 | CX31: 0.14 | CY31: 0.13 | CZ31: 0.12
B32: Ttl Diagnostics Growth Y/y | AY32: =AY12/AU12-1 -> 1.1982475 | AZ32: =AZ12/AV12-1 -> 0.62838516 | BA32: =BA12/AW12-1 -> 0.48181818 | BB32: =BB12/AX12-1 -> 0.028998849 | BC32: =BC12/AY12-1 -> 0.30966617 | BD32: =BD12/AZ12-1 -> 0.32245149 | BE32: =BE12/BA12-1 -> -0.069274029 | BF32: =BF12/BB12-1 -> -0.26705435 | ... BT32: =BT12/BP12-1 -> 0.003221353 | CM32: =CM12/CL12-1 -> 0.44784822 | CN32: =CN12/CM12-1 -> 0.052735873 | CO32: =CO12/CN12-1 -> -0.39352723 | CP32: =CP12/CO12-1 -> -0.064777733 | CQ32: =CQ12/CP12-1 -> -0.043250187 | CR32: =CR12/CQ12-1 -> 0.058121293 | CS32: =CS12/CR12-1 -> 0.072341264 | CT32: =CT12/CS12-1 -> 0.096639247 | ... CZ32: =CZ12/CY12-1 -> 0.078018465
B33: Rhythm Management Growth Y/y | AY33: =AY13/AU13-1 -> 0.094936709 | AZ33: =AZ13/AV13-1 -> 0.41396509 | BA33: =BA13/AW13-1 -> 0.12623274 | BB33: =BB13/AX13-1 -> 0.016917293 | BC33: =BC13/AY13-1 -> 0.0096339114 | BD33: =BD13/AZ13-1 -> -0.0335097 | BE33: =BE13/BA13-1 -> -0.066549912 | BF33: =BF13/BB13-1 -> -0.049907579 | ... BT33: =BT13/BP13-1 -> 0.016344725 | CM33: =CM13/CL13-1 -> 0.14838036 | CN33: =CN13/CM13-1 -> -0.035941765 | CO33: =CO13/CN13-1 -> 0.064181218 | CP33: =CP13/CO13-1 -> 0.059866962 | CQ33: 0.105 | CR33: 0.1325 | CS33: 0.12 | CT33: 0.11 | CU33: 0.105 | CV33: 0.09 | CW33: 0.075 | CX33: 0.06 | CY33: 0.05 | CZ33: 0.04
B34: Electrophysiology Growth Y/y | AY34: =AY14/AU14-1 -> 0.11082474 | AZ34: =AZ14/AV14-1 -> 0.62876254 | BA34: =BA14/AW14-1 -> 0.099773243 | BB34: =BB14/AX14-1 -> 0.12 | BC34: =BC14/AY14-1 -> 0.12529002 | BD34: =BD14/AZ14-1 -> -0.0020533881 | BE34: =BE14/BA14-1 -> -0.032989691 | BF34: =BF14/BB14-1 -> -0.033730159 | ... BT34: =BT14/BP14-1 -> 0.12571429 | CM34: =CM14/CL14-1 -> 0.20849176 | CN34: =CN14/CM14-1 -> 0.010487677 | CO34: =CO14/CN14-1 -> 0.13907628 | CP34: =CP14/CO14-1 -> 0.123918 | CQ34: 0.12 | CR34: 0.22 | CS34: 0.17 | CT34: 0.16 | CU34: 0.155 | CV34: 0.145 | CW34: 0.13 | CX34: 0.11 | CY34: 0.085 | CZ34: 0.065
B35: Heart Failure Growth Y/y | AY35: =AY15/AU15-1 -> -0.044334975 | AZ35: =AZ15/AV15-1 -> 0.43670886 | BA35: =BA15/AW15-1 -> 0.20526316 | BB35: =BB15/AX15-1 -> 0.26455026 | BC35: =BC15/AY15-1 -> 0.28865979 | BD35: =BD15/AZ15-1 -> 0.18502203 | BE35: =BE15/BA15-1 -> 0.12663755 | BF35: =BF15/BB15-1 -> 0.079497908 | ... BT35: =BT15/BP15-1 -> 0.057065217 | CM35: =CM15/CL15-1 -> 0.20135135 | CN35: =CN15/CM15-1 -> 0.16422947 | CO35: =CO15/CN15-1 -> 0.12173913 | CP35: =CP15/CO15-1 -> 0.10163652 | CQ35: 0.132 | CR35: 0.125 | CS35: 0.1 | CT35: 0.08 | CU35: 0.06 | CV35: 0.05 | CW35: 0.04 | CX35: 0.03 | CY35: 0.02 | CZ35: 0.015
B36: Vascular Growth Y/y | AY36: =AY16/AU16-1 -> 0.016 | AZ36: =AZ16/AV16-1 -> 0.44906445 | BA36: =BA16/AW16-1 -> 0.022222222 | BB36: =BB16/AX16-1 -> 0.12437811 | BC36: =BC16/AY16-1 -> -0.02519685 | BD36: =BD16/AZ16-1 -> -0.06312769 | BE36: =BE16/BA16-1 -> -0.059006211 | BF36: =BF16/BB16-1 -> -0.10766962 | ... BT36: =BT16/BP16-1 -> 0.026420079 | CM36: =CM16/CL16-1 -> 0.13467294 | CN36: =CN16/CM16-1 -> -0.064431047 | CO36: =CO16/CN16-1 -> 0.079742247 | CP36: =CP16/CO16-1 -> 0.058187244 | CQ36: 0.0475 | CR36: 0.09 | CS36: 0.08 | CT36: 0.07 | CU36: 0.06 | CV36: 0.05 | CW36: 0.04 | CX36: 0.03 | CY36: 0.02 | CZ36: 0.01
B37: Structural Heart Revenue Growth Y/y | AY37: =AY17/AU17-1 -> 0.18553459 | AZ37: =AZ17/AV17-1 -> 0.89237668 | BA37: =BA17/AW17-1 -> 0.11048159 | BB37: =BB17/AX17-1 -> 0.18696884 | BC37: =BC17/AY17-1 -> 0.090185676 | BD37: =BD17/AZ17-1 -> 0.042654028 | BE37: =BE17/BA17-1 -> 0.071428571 | BF37: =BF17/BB17-1 -> 0.052505967 | ... BT37: =BT17/BP17-1 -> -0.091194969 | CM37: =CM17/CL17-1 -> 0.29109864 | CN37: =CN17/CM17-1 -> 0.063354037 | CO37: =CO17/CN17-1 -> 0.13551402 | CP37: =CP17/CO17-1 -> 0.15534979 | CQ37: 0.13 | CR37: -0.04 | CS37: -0.01 | CT37: 0.07 | CU37: 0.09 | CV37: 0.105 | CW37: 0.09 | CX37: 0.075 | CY37: 0.06 | CZ37: 0.045
B38: Neuromodulation Revenue Growth Y/y | AY38: =AY18/AU18-1 -> 0.039548023 | AZ38: =AZ18/AV18-1 -> 0.98113208 | BA38: =BA18/AW18-1 -> -0.077669903 | BB38: =BB18/AX18-1 -> -0.075117371 | BC38: =BC18/AY18-1 -> -0.027173913 | BD38: =BD18/AZ18-1 -> -0.061904762 | BE38: =BE18/BA18-1 -> 0.010526316 | BF38: =BF18/BB18-1 -> 0.025380711 | ... BT38: =BT18/BP18-1 -> -0.043307087 | CM38: =CM18/CL18-1 -> 0.11253561 | CN38: =CN18/CM18-1 -> -0.014084507 | CO38: =CO18/CN18-1 -> 0.15584416 | CP38: =CP18/CO18-1 -> 0.080898876 | CQ38: 0.04 | CR38: 0.03 | CS38: 0.045 | CT38: 0.06 | CU38: 0.065 | CV38: 0.06 | CW38: 0.055 | CX38: 0.045 | CY38: 0.035 | CZ38: 0.025
B39: Diabetes Care Revenue Growth Y/y | AY39: =AY19/AU19-1 -> 0.30319149 | AZ39: =AZ19/AV19-1 -> 0.3986755 | BA39: =BA19/AW19-1 -> 0.32977461 | BB39: =BB19/AX19-1 -> 0.27699019 | BC39: =BC19/AY19-1 -> 0.14897959 | BD39: =BD19/AZ19-1 -> 0.12878788 | BE39: =BE19/BA19-1 -> 0.04103479 | BF39: =BF19/BB19-1 -> 0.085397096 | ... BT39: =BT19/BP19-1 -> 0.04997476 | CM39: =CM19/CL19-1 -> 0.32476278 | CN39: =CN19/CM19-1 -> 0.098890943 | CO39: =CO19/CN19-1 -> 0.21131203 | CP39: =CP19/CO19-1 -> 0.18121854 | CQ39: 0.195 | CR39: 0.14 | CS39: 0.175 | CT39: 0.18 | CU39: 0.15 | CV39: 0.13 | CW39: 0.11 | CX39: 0.09 | CY39: 0.07 | CZ39: 0.06
B40: Ttl Med Device Revenues Revenue Growth Y/y | AY40: =AY20/AU20-1 -> 0.13040518 | AZ40: =AZ20/AV20-1 -> 0.51300041 | BA40: =BA20/AW20-1 -> 0.14574132 | BB40: =BB20/AX20-1 -> 0.15105926 | BC40: =BC20/AY20-1 -> 0.08253012 | BD40: =BD20/AZ20-1 -> 0.032460447 | BE40: =BE20/BA20-1 -> 0.0035792952 | BF40: =BF20/BB20-1 -> 0.0077353961 | ... BT40: =BT20/BP20-1 -> 0.031663252 | CM40: =CM20/CL20-1 -> 0.21888521 | CN40: =CN20/CM20-1 -> 0.03027772 | CO40: =CO20/CN20-1 -> 0.14085934 | CP40: =CP20/CO20-1 -> 0.1242968 | CQ40: =CQ20/CP20-1 -> 0.1264616 | CR40: =CR20/CQ20-1 -> 0.11496341 | CS40: =CS20/CR20-1 -> 0.12478173 | CT40: =CT20/CS20-1 -> 0.13245026 | ... CZ40: =CZ20/CY20-1 -> 0.04915788
B41: Other Revenues Revenue Growth Y/y | AY41: =AY21/AU21-1 -> 0.066666667 | AZ41: =AZ21/AV21-1 -> 0.46666667 | BA41: =BA21/AW21-1 -> -0.45 | BB41: =BB21/AX21-1 -> -0.8125 | BC41: =BC21/AY21-1 -> -0.8125 | BD41: =BD21/AZ21-1 -> -0.90909091 | BE41: =BE21/BA21-1 -> -0.72727273 | BF41: =BF21/BB21-1 -> 0 | ... BT41: =BT21/BP21-1 -> -0.6 | CM41: =CM21/CL21-1 -> -0.21212121 | CN41: =CN21/CM21-1 -> -0.78846154 | CO41: =CO21/CN21-1 -> 0.27272727 | CP41: =CP21/CO21-1 -> 0.14285714 | CQ41: 0.15 | CR41: -0.5 | CS41: 0.1 | CT41: 0.11 | CU41: 0.13 | CV41: 0.15 | CW41: 0.15 | CX41: 0.15 | CY41: 0.15 | CZ41: 0.15
...

Sheet Notes | Quant Analysis
CB1: 0
H2: Employee Scope: | AE2: General Notes/Observations
I32: Notes: | J32: [X]
J33: [Y]
J34: [Z]
H36: Institutional Ownership Snapshot Q2'25
I66: Notes: | J66: [X]
J67: [Y]
J68: [Z]
AE69: Financial Stmts. Notes/Observations
H70: Revenue Breakdown by Segment | AE70: Revenues:
I102: Notes: | J102: [X]
J103: [Y]
J104: [Z]
H106: Revenue Breakdown of Diagnostics Segment | AE106: Earnings Scope:
I138: Notes: | J138: [X]
J139: [Y]
J140: [Z]
H142: Revenue Breakdown of Med-Devices Segment | AE142: Balance Sheet Scope:
I174: Notes: | J174: [X]
J175: [Y]
J176: [Z]
H178: Q/q Total Revenues, Net Income, FCF | AE178: [Equity Preformance Compared to Peers]
A192: 1256 Trading Days? (From: 9/12/2020 - 9/12/2025)
A193: Close | B193: High | C193: Low | D193: Open | E193: Volume | F193: UTC Date | G193: Change
A194: 133.73 | B194: 134.96 | C194: 131.4 | D194: 131.82 | E194: 5675032 | F194: Fri, 12 Sep 2025 00:00:00 GMT | G194: =A194/D194-1 -> 0.014489455
A195: 132.65 | B195: 132.68 | C195: 129.3975 | D195: 129.69 | E195: 5500357 | F195: Thu, 11 Sep 2025 00:00:00 GMT | G195: =A195/D195-1 -> 0.022823656
A196: 129.36 | B196: 131.85 | C196: 127.445 | D196: 131.85 | E196: 7363965 | F196: Wed, 10 Sep 2025 00:00:00 GMT | G196: =A196/D196-1 -> -0.018885097
A197: 131.95 | B197: 133.1679 | C197: 131.645 | D197: 132.3 | E197: 4635380 | F197: Tue, 09 Sep 2025 00:00:00 GMT | G197: =A197/D197-1 -> -0.0026455026
A198: 132.2 | B198: 133.09 | C198: 131.61 | D198: 132.26 | E198: 5014159 | F198: Mon, 08 Sep 2025 00:00:00 GMT | G198: =A198/D198-1 -> -0.0004536519
A199: 132.94 | B199: 134.325 | C199: 132.445 | D199: 132.515 | E199: 3225545 | F199: Fri, 05 Sep 2025 00:00:00 GMT | G199: =A199/D199-1 -> 0.0032071841
A200: 132.81 | B200: 133.84 | C200: 131.7 | D200: 132.18 | E200: 5063771 | F200: Thu, 04 Sep 2025 00:00:00 GMT | G200: =A200/D200-1 -> 0.0047662279
A201: 132.18 | B201: 132.19 | C201: 130.21 | D201: 131.15 | E201: 4753690 | F201: Wed, 03 Sep 2025 00:00:00 GMT | G201: =A201/D201-1 -> 0.0078536027
A202: 131.46 | B202: 133.395 | C202: 130.84 | D202: 132.685 | E202: 5696208 | F202: Tue, 02 Sep 2025 00:00:00 GMT | G202: =A202/D202-1 -> -0.0092323925
A203: 132.66 | B203: 132.845 | C203: 131.17 | D203: 132.015 | E203: 4426895 | F203: Fri, 29 Aug 2025 00:00:00 GMT | G203: =A203/D203-1 -> 0.0048858084
A204: 131.37 | B204: 131.635 | C204: 130.14 | D204: 130.92 | E204: 4668414 | F204: Thu, 28 Aug 2025 00:00:00 GMT | G204: =A204/D204-1 -> 0.0034372136
A205: 131.46 | B205: 131.75 | C205: 130.5616 | D205: 131.47 | E205: 4758097 | F205: Wed, 27 Aug 2025 00:00:00 GMT | G205: =A205/D205-1 -> -7.606298e-05
A206: 131.59 | B206: 132.35 | C206: 131.38 | D206: 131.86 | E206: 6076213 | F206: Tue, 26 Aug 2025 00:00:00 GMT | G206: =A206/D206-1 -> -0.0020476263
A207: 131.87 | B207: 132.96 | C207: 131.49 | D207: 132.72 | E207: 4695123 | F207: Mon, 25 Aug 2025 00:00:00 GMT | G207: =A207/D207-1 -> -0.0064044605 | I207: Notes: | J207: [X]
A208: 132.59 | B208: 133.62 | C208: 131.34 | D208: 132.77 | E208: 4130123 | F208: Fri, 22 Aug 2025 00:00:00 GMT | G208: =A208/D208-1 -> -0.001355728 | J208: [Y]
...

Sheet Management

Sheet M&A
B2: Abbott M&A Acquirees | G2: Announced | H2: Price (in $M) | I2: Description | W2: Abbott Subsidiaries | AD2: Description
B3: Bigfoot Biomedical | H3: – | W3: Domestic Subsidiaries: | AB3: Incorporated:
B4: Cardiovascular Systems | H4: 890
B5: Walk Vascular | H5: – | W5: Abbott Biologicals, LLC | AB5: Delaware
B6: Cephea Valve Technologies | H6: – | W6: Abbott Cardiovascular Inc. | AB6: Delaware
B7: St Jude Medical | H7: 25000 | W7: Abbott Cardiovascular Systems Inc. | AB7: California
B8: Kalila Medical | H8: – | W8: Abbott Delaware LLC | AB8: Delaware
B9: Alere | H9: 5300 | W9: Abbott Diabetes Care Inc. | AB9: Delaware
B10: Tendyne Holdings | H10: 250 | W10: Abbott Diabetes Care Sales Corporation | AB10: Delaware
B11: Veropharm | H11: 305 | W11: Abbott Diagnostics Scarborough, Inc. | AB11: Delaware
B12: Topera | H12: 250 | W12: Abbott Equity Investments LLC | AB12: Delaware
B13: Cfr Pharmaceuticals | H13: 2900 | W13: Abbott Finance LLC | AB13: Delaware
B14: Unelab | H14: – | W14: Abbott Global LLC | AB14: Delaware
B15: Idev Technologies | H15: 310 | W15: Abbott Health Products, LLC | AB15: Delaware
B16: Optimedica | H16: 400 | W16: Abbott Informatics Corporation | AB16: Florida
B17: Piramal Healthcare Solutions | H17: 3700 | W17: Abbott International LLC | AB17: Delaware
B18: Facet Biotech | H18: 450 | W18: Abbott Laboratories Inc. | AB18: Delaware
B19: Pangenetics | H19: 190 | W19: Abbott Laboratories International LLC | AB19: Illinois
B20: Solvay Pharmaceuticals | H20: 6600 | W20: Abbott Laboratories Pacific Ltd. | AB20: Illinois
B21: Evalve | H21: 410 | W21: Abbott Laboratories Residential Development Fund, Inc. | AB21: Illinois
B22: Visiogen | H22: 400 | W22: Abbott Laboratories Services LLC | AB22: Illinois
B23: Ibis Biosciences | H23: – | W23: Abbott Management LLC | AB23: Delaware
B24: Nova Science | H24: 10 | W24: Abbott Molecular Inc. | AB24: Delaware
B25: Kos Pharmaceuticals | H25: 3700 | W25: Abbott Nutrition Manufacturing Inc. | AB25: Delaware
B26: Spine Next | H26: 81 | W26: Abbott Point of Care Inc. | AB26: Delaware
B27: Experimental And Applied Sciences | H27: 320 | W27: Abbott Procurement LLC | AB27: Delaware
B28: Therasense | H28: 1200 | W28: Abbott Products Operations, LLC | AB28: Delaware
B29: I-Stat Corp | H29: 394 | W29: Abbott Rapid Diagnostics Informatics, Inc. | AB29: Virginia
B30: Integrated Vascular Systems | H30: 65 | W30: Abbott Rapid Dx North America, LLC | AB30: Delaware
B31: Zoneperfect Nutrition | H31: 160 | W31: Abbott Resources Inc. | AB31: Delaware
B32: Woodside Biomedical | H32: – | W32: Abbott Resources International Inc. | AB32: Delaware
B33: Spinal Concepts | H33: 166 | W33: Abbott Universal LLC | AB33: Delaware
B34: Vysis | H34: 362 | W34: Abbott Vascular Inc. | AB34: Delaware
B35: Abbott India | H35: 6900 | W35: Abbott Vascular Solutions Inc. | AB35: Indiana
B36: Glaxo Wellcome – Anesthesia Business | H36: 217 | W36: Abbott Ventures Inc. | AB36: Delaware
B37: Perclose Inc | H37: 680 | W37: Advanced Neuromodulation Systems, Inc. | AB37: Texas
B38: Alza Corp | H38: – | W38: AGA Medical Corporation | AB38: Minnesota
B39: International Murex Technologies | H39: 234 | W39: AGA Medical Holdings, Inc. | AB39: Delaware
B40: Sanofi – Parenteral Products Businesses | H40: 200 | W40: Alere Connect, LLC | AB40: Delaware
B41: Medisense Inc | H41: 876 | W41: Alere Holdco, Inc. | AB41: Delaware
...

Sheet Med-Devices
A2: Vascular
B3: Abbott expanded peripheral vascular offerings with acquisition of Walk Vascular in 2021
C4: Peripheral Thrombectomy Devices
C5: Jeti–6 Fr
D6: Mode of Operation: Internal saline jet just within the catheter tip breaks up thrombus and soft emboli while removing the thrombus through aspiration
D7: FDA Indicated Use: For all peripheral venous and arterial vasculature
C8: Jeti–8 Fr
D9: Mode of Operation: Internal saline jet just within the catheter tip breaks up thrombus and soft emboli while removing the thrombus through aspiration
D10: FDA Indicated Use: For all peripheral venous and arterial vasculature
C11: Jeti line competes directly with Penumbra's peripheral Indigo Lightning & Bolt CAVT Systems
D12: Jeti uses a "hydrodynamic" approach. It shoots a high-speed jet of saline at the tip to break up the clot before sucking it in (maceration + aspiration)
E13: This is designed to prevent clogging and reduce blood loss by breaking the clot into smaller pieces first
A18: CGMs / Diabetes Care
B19: Abbott’s diabetes franchise is a dominant growth driver in The Company's overall medical devices portfolio
B20: CGM Monitor - FreeStyle Libre
C21: FreeStyle Libre 3 System
D22: Abbott's flagship CGM product - Disposable sensor device (Libre 3 / Libre 3 Plus) and reader for viewing sensor outputs … Requires perscription from healthcare provider
D23: The Libre 3 or Libre 3 Plus sensor streams real-time glucose data every minute directly to a reader device or dedicated smartphone app via Bluetooth, with no need to scan the sensor manually
E24: Intended patients are all people with Type 1, Type 2 (on insulin), or gestational diabetes
E25: Libre 3 Plus has a 15-day wear time and is approved for children as young as 2 years old … Standard Libre 3 sensor has 14-day wear time and is approved for children 4 and older
E26: Most advanced censor technology … Includes features necessary for intensive diabetes management … alarms, data sharing with healthcare providers, compatibility with insulin pumps
F27: World's smallest and thinnest CGM sensor (size of two stacked pennies)
F28: Huge development for diabetes patients ... eliminates the need for frequent patient fingerstick pricks which have traditionally been required for blood glucose monitoring (BGM)
C29: FreeStyle Libre 2 System
D30: Abbott's Budget CGM product - Disposable sensor device (Libre 2 / Libre 2 Plus) and reader for viewing sensor outputs … Requires perscription from healthcare provider
D31: The Libre 2 or Libre 2 Plus sensor requires manual scanning ("Flash monitoring") meaning the user must actively hold a reader or smartphone near the sensor on their arm to get a current glucose reading
E32: The sensor only stores 8 hours of data. If the user does not scan at least every eight hours, there will be gaps (broken lines) in the historical glucose graph
E33: Intended patients are all people with Type 1, Type 2 (on insulin), or gestational diabetes
E34: Libre 2 Plus has a 15-day wear time and is approved for children as young as 2 years old … Standard Libre 2 sensor has 14-day wear time and is approved for children 4 and older
B35: CGM Monitor - Libre Rio
D36: Abbott's over-the-counter (OTC) continuous glucose monitoring (CGM) system - Disposable sensor device and reader for viewing sensor outputs
D37: The Libre Rio sensor streams real-time glucose data every minute directly to a reader device or dedicated smartphone app via Bluetooth, with no need to scan the sensor manually
E38: Intended for patients with type 2 diabetes who do not use insulin and manage their condition primarily through diet and lifestyle
E39: Libre Rio has a 14-day wear time and is approved for adults 18 and older
E40: Based on the FreeStyle Libre technology … Focuses on providing glucose data and personalized insights for lifestyle management … does not include certain clinical features
C41: CGM Monitor - Libre Lingo
D42: Abbott's over-the-counter (OTC) continuous glucose monitoring (CGM) system - Disposable sensor device and reader for viewing sensor outputs
D43: The Libre Lingo sensor streams real-time glucose data every minute directly to a reader device or dedicated smartphone app via Bluetooth, with no need to scan the sensor manually
E44: Intended for general consumers without diabetes (same market as DXCM's Stelo) for general health and wellness purposes
E45: Libre Lingo has a 14-day wear time and is approved for adults 18 and older
...

Sheet Diagnostics

Sheet Table Formatting
B2: [Bold Title] | G2: [Bold Title]
B3: Line Titles | G3: <-- General
B4: Line Titles | G4: <-- Info
B5: Line Titles | G5: <-- General
B6: Line Titles | G6: <-- Info
B7: Line Titles | G7: <-- General
B8: Line Titles | G8: <-- Info
