Workbook

Sheet Main
B2: AVGO
B3: Price | C3: 334.85 | D3: 8/13/2026
B4: SO | C4: 4773.629 | D4: Q2'26
B5: MC | C5: =C3*C4 -> 1598449.7
B6: Cash | C6: 23.975 | D6: Q2'26
B7: Debt | C7: =2252+57167 -> 59419 | D7: Q2'26
B8: EV | C8: =C5-C6+C7 -> 1657844.7
B10: Broadcom Inc.
B12: Founder(s): Henry Samueli and Henry Nicholas | F12: Registered Exchange: NASDAQ | N12: Resources:
B13: Founded: 1991 | F13: Address: 3421 Hillview Ave, Palo Alto, CA 94304 U.S. | N13: SEC filings | Q13: https://www.sec.gov/edgar/browse/?CIK=1730168&owner=exclude
B14: Headquarters: Palo Alto, CA | F14: Investor Relations Contact: | N14: Company Homepage | Q14: https://www.broadcom.com/
B15: Current CEO: Hock Tan | F15: Investors Relation Department | O15: Company IR Page | R15: https://investors.broadcom.com/
B16: Employees: 33,000 | F16: Phone: | G16: (650) 427 - 6000 | I16: Email: | N16: Earnings Calls | Q16: https://seekingalpha.com/symbol/AVGO/earnings/transcripts
B17: Industry: Semiconductors | N17: Equity Analysis | Q17: https://stockanalysis.com/stocks/avgo/company/
B18: Sector: Technology | N18: MacroTrends | Q18: https://www.macrotrends.net/stocks/charts/AVGO/broadcom/financial-statements
B19: IPO: Aug 9th, 2009 -- | N19: ROIC, WACC | Q19: https://www.gurufocus.com/term/wacc/AVGO
B20: Fiscal Year: [December - November] | N20: Godel Terminal | Q20: https://app.godelterminal.com/
A22: Company Overview:
B23: Broadcom Inc. designs, develops, and supplies various semiconductor devices and infrastructure software solutions internationally
B24: The Company operates in two segments: Semiconductor Solutions and Infrastructure Software
C25: The company offers networking connectivity, such as custom silicon solutions, ethernet switching & routing, ethernet NIC controllers, physical layer devices, and fiber optic components; wireless device connectivity, including RF semiconductor devices, connectivity solutions, custom touch controllers, and inductive charging ASICS
C26: Also offers servers and storage system solutions, such as PCIE switches, SAS & raid products, fibre channel products, and HDD & SSD solutions; broadband solutions, includes set-top box, and broadband access; and industrial
C27: The company also offers a private cloud software portfolio, including the VMware Cloud Foundation, Edge, vSphere foundation, telco cloud platform, private AI, live recovery, application networking and security, application development and data services
C28: mainframe software, such as AIOPS & automation, database & data management, DEVX & DEVOPS, cybersecurity & compliance management, beyond code programs, foundational & open mainframe solutions; cybersecurity, such as endpoint, network, information, application security, and identity & access management; enterprise software; and fc san management
B29: Its products are used in various applications in enterprise and data center networking, including artificial intelligence networking and connectivity, home connectivity, set-top boxes, broadband access, telecommunication equipment, wireless device and base stations, data center servers and storage systems, factory automation, power generation and alternative energy systems, and electronic displays
B30: Broadcom Inc. was founded in 1961 and is headquartered in Palo Alto, California
A33: Business Segments and Geographical Info:
B34: [Begin researching fundamentals / core business … begin with SEC filings, but expand and use all public resources available]

Sheet Model
B1: [Use for Graphing] | AY1: Q1 2020 | BC1: Q1 2021 | BG1: Q1 2022 | BK1: Q1 2023 | BO1: Q1 2024 | BS1: Q1 2025 | BW1: Q1 2026
B2: Quarterly
B3: Revenues | C3: {="Q"&MOD(_xlfn.SEQUENCE(1,76)-1,4)+1&" "&(2008+INT((_xlfn.SEQUENCE(1,76)-1)/4))} -> Q1 2008 | D3: Q2 2008 | E3: Q3 2008 | F3: Q4 2008 | G3: Q1 2009 | H3: Q2 2009 | I3: Q3 2009 | J3: Q4 2009 | K3: Q1 2010 | L3: Q2 2010 | M3: Q3 2010 | N3: Q4 2010 | O3: Q1 2011 | P3: Q2 2011 | Q3: Q3 2011 | R3: Q4 2011 | S3: Q1 2012 | T3: Q2 2012 | U3: Q3 2012 | V3: Q4 2012 | W3: Q1 2013 | X3: Q2 2013 | Y3: Q3 2013 | Z3: Q4 2013 | AA3: Q1 2014 | AB3: Q2 2014 | AC3: Q3 2014 | AD3: Q4 2014 | AE3: Q1 2015 | AF3: Q2 2015 | AG3: Q3 2015 | AH3: Q4 2015 | AI3: Q1 2016 | AJ3: Q2 2016 | AK3: Q3 2016 | AL3: Q4 2016 | AM3: Q1 2017 | AN3: Q2 2017 | AO3: Q3 2017 | AP3: Q4 2017 | AQ3: Q1 2018 | AR3: Q2 2018 | AS3: Q3 2018 | AT3: Q4 2018 | AU3: Q1 2019 | AV3: Q2 2019 | AW3: Q3 2019 | AX3: Q4 2019 | AY3: Q1 2020 | AZ3: Q2 2020 | BA3: Q3 2020 | BB3: Q4 2020 | BC3: Q1 2021 | BD3: Q2 2021 | BE3: Q3 2021 | BF3: Q4 2021 | BG3: Q1 2022 | BH3: Q2 2022 | BI3: Q3 2022 | BJ3: Q4 2022 | BK3: Q1 2023 | BL3: Q2 2023 | BM3: Q3 2023 | BN3: Q4 2023 | BO3: Q1 2024 | BP3: Q2 2024 | BQ3: Q3 2024 | BR3: Q4 2024 | BS3: Q1 2025 | BT3: Q2 2025 | BU3: Q3 2025 | BV3: Q4 2025 | BW3: Q1 2026 | BX3: Q2 2026 | BY3: Q3 2026 | BZ3: Q4 2026 | CI3: 2008 | CJ3: =CI3+1 -> 2009 | CK3: =CJ3+1 -> 2010 | CL3: =CK3+1 -> 2011 | CM3: =CL3+1 -> 2012 | CN3: =CM3+1 -> 2013 | CO3: =CN3+1 -> 2014 | CP3: =CO3+1 -> 2015 | CQ3: =CP3+1 -> 2016 | ... FH3: =FG3+1 -> 2085
B4: Product A | BO4: 7412 | BP4: 7192 | BQ4: 7439 | BR4: 8316 | BS4: 8171 | BT4: 11173 | BU4: 9257 | BV4: =1000-SUM(BS4:BU4) -> -27601 | BX4: 24279 | CI4: =SUM(C4:F4) -> 0 | CJ4: =SUM(G4:J4) -> 0 | CK4: =SUM(K4:N4) -> 0 | CL4: =SUM(O4:R4) -> 0 | CM4: =SUM(S4:V4) -> 0 | CN4: =SUM(W4:Z4) -> 0 | CO4: =SUM(AA4:AD4) -> 0 | CP4: =SUM(AE4:AH4) -> 0 | CQ4: =SUM(AI4:AL4) -> 0 | CR4: =SUM(AM4:AP4) -> 0 | CS4: =SUM(AQ4:AT4) -> 0 | CT4: =SUM(AU4:AX4) -> 0 | CU4: =SUM(AY4:BB4) -> 0 | CV4: =SUM(BC4:BF4) -> 0 | CW4: =SUM(BG4:BJ4) -> 0 | CX4: =SUM(BK4:BN4) -> 0 | CY4: =SUM(BO4:BR4) -> 30359 | CZ4: =SUM(BS4:BV4) -> 1000 | DA4: =CZ4*(1+DA8) -> 2000 | DB4: =DA4*(1+DB8) -> 4000 | DC4: =DB4*(1+DC8) -> 8000 | DD4: =DC4*(1+DD8) -> 16000 | DE4: =DD4*(1+DE8) -> 32000 | DF4: =DE4*(1+DF8) -> 64000 | DG4: =DF4*(1+DG8) -> 128000 | DH4: =DG4*(1+DH8) -> 256000 | ... DJ4: =DI4*(1+DJ8) -> 1024000
B5: Product B | BO5: 4549 | BP5: 5295 | BQ5: 5633 | BR5: 5738 | BS5: 6745 | BT5: 4779 | BU5: 6695 | BV5: =1000-SUM(BS5:BU5) -> -17219 | BX5: 5312 | CI5: =SUM(C5:F5) -> 0 | CJ5: =SUM(G5:J5) -> 0 | CK5: =SUM(K5:N5) -> 0 | CL5: =SUM(O5:R5) -> 0 | CM5: =SUM(S5:V5) -> 0 | CN5: =SUM(W5:Z5) -> 0 | CO5: =SUM(AA5:AD5) -> 0 | CP5: =SUM(AE5:AH5) -> 0 | CQ5: =SUM(AI5:AL5) -> 0 | CR5: =SUM(AM5:AP5) -> 0 | CS5: =SUM(AQ5:AT5) -> 0 | CT5: =SUM(AU5:AX5) -> 0 | CU5: =SUM(AY5:BB5) -> 0 | CV5: =SUM(BC5:BF5) -> 0 | CW5: =SUM(BG5:BJ5) -> 0 | CX5: =SUM(BK5:BN5) -> 0 | CY5: =SUM(BO5:BR5) -> 21215 | CZ5: =SUM(BS5:BV5) -> 1000 | DA5: =CZ5*(1+DA9) -> 2000 | DB5: =DA5*(1+DB9) -> 4000 | DC5: =DB5*(1+DC9) -> 8000 | DD5: =DC5*(1+DD9) -> 16000 | DE5: =DD5*(1+DE9) -> 32000 | DF5: =DE5*(1+DF9) -> 64000 | DG5: =DF5*(1+DG9) -> 128000 | DH5: =DG5*(1+DH9) -> 256000 | ... DJ5: =DI5*(1+DJ9) -> 1024000
B6: Ttl Revenues | BC6: =SUM(BC4:BC5) -> 0 | BD6: =SUM(BD4:BD5) -> 0 | BE6: =SUM(BE4:BE5) -> 0 | BF6: =SUM(BF4:BF5) -> 0 | BG6: =SUM(BG4:BG5) -> 0 | BH6: =SUM(BH4:BH5) -> 0 | BI6: =SUM(BI4:BI5) -> 0 | BJ6: =SUM(BJ4:BJ5) -> 0 | ... BX6: =SUM(BX4:BX5) -> 29591 | CI6: =SUM(C6:F6) -> 0 | CJ6: =SUM(G6:J6) -> 0 | CK6: =SUM(K6:N6) -> 0 | CL6: =SUM(O6:R6) -> 0 | CM6: =SUM(S6:V6) -> 0 | CN6: =SUM(W6:Z6) -> 0 | CO6: =SUM(AA6:AD6) -> 0 | CP6: =SUM(AE6:AH6) -> 0 | CQ6: =SUM(AI6:AL6) -> 0 | CR6: =SUM(AM6:AP6) -> 0 | CS6: =SUM(AQ6:AT6) -> 0 | CT6: =SUM(AU6:AX6) -> 0 | CU6: =SUM(AY6:BB6) -> 0 | CV6: =SUM(BC6:BF6) -> 0 | CW6: =SUM(BG6:BJ6) -> 0 | CX6: =SUM(BK6:BN6) -> 0 | CY6: =SUM(BO6:BR6) -> 51574 | CZ6: =SUM(BS6:BV6) -> 2000 | DA6: =SUM(DA4:DA5) -> 4000 | DB6: =SUM(DB4:DB5) -> 8000 | DC6: =SUM(DC4:DC5) -> 16000 | DD6: =SUM(DD4:DD5) -> 32000 | DE6: =SUM(DE4:DE5) -> 64000 | DF6: =SUM(DF4:DF5) -> 128000 | DG6: =SUM(DG4:DG5) -> 256000 | DH6: =SUM(DH4:DH5) -> 512000 | ... DJ6: =SUM(DJ4:DJ5) -> 2048000
B8: Product A Growth Y/y | BC8: =BC4/AY4-1 -> #DIV/0! | BD8: =BD4/AZ4-1 -> #DIV/0! | BE8: =BE4/BA4-1 -> #DIV/0! | BF8: =BF4/BB4-1 -> #DIV/0! | BG8: =BG4/BC4-1 -> #DIV/0! | BH8: =BH4/BD4-1 -> #DIV/0! | BI8: =BI4/BE4-1 -> #DIV/0! | BJ8: =BJ4/BF4-1 -> #DIV/0! | ... BX8: =BX4/BT4-1 -> 1.1730064 | CJ8: =CJ4/CI4-1 -> #DIV/0! | CK8: =CK4/CJ4-1 -> #DIV/0! | CL8: =CL4/CK4-1 -> #DIV/0! | CM8: =CM4/CL4-1 -> #DIV/0! | CN8: =CN4/CM4-1 -> #DIV/0! | CO8: =CO4/CN4-1 -> #DIV/0! | CP8: =CP4/CO4-1 -> #DIV/0! | CQ8: =CQ4/CP4-1 -> #DIV/0! | ... CZ8: =CZ4/CY4-1 -> -0.96706084 | DA8: 1 | DB8: 1 | DC8: 1 | DD8: 1 | DE8: 1 | DF8: 1 | DG8: 1 | DH8: 1 | DI8: 1 | DJ8: 1
B9: Product B Growth Y/y | BC9: =BC5/AY5-1 -> #DIV/0! | BD9: =BD5/AZ5-1 -> #DIV/0! | BE9: =BE5/BA5-1 -> #DIV/0! | BF9: =BF5/BB5-1 -> #DIV/0! | BG9: =BG5/BC5-1 -> #DIV/0! | BH9: =BH5/BD5-1 -> #DIV/0! | BI9: =BI5/BE5-1 -> #DIV/0! | BJ9: =BJ5/BF5-1 -> #DIV/0! | ... BX9: =BX5/BT5-1 -> 0.11152961 | CJ9: =CJ5/CI5-1 -> #DIV/0! | CK9: =CK5/CJ5-1 -> #DIV/0! | CL9: =CL5/CK5-1 -> #DIV/0! | CM9: =CM5/CL5-1 -> #DIV/0! | CN9: =CN5/CM5-1 -> #DIV/0! | CO9: =CO5/CN5-1 -> #DIV/0! | CP9: =CP5/CO5-1 -> #DIV/0! | CQ9: =CQ5/CP5-1 -> #DIV/0! | ... CZ9: =CZ5/CY5-1 -> -0.95286354 | DA9: 1 | DB9: 1 | DC9: 1 | DD9: 1 | DE9: 1 | DF9: 1 | DG9: 1 | DH9: 1 | DI9: 1 | DJ9: 1
B10: Ttl Revenue Growth Y/y | BC10: =BC6/AY6-1 -> #DIV/0! | BD10: =BD6/AZ6-1 -> #DIV/0! | BE10: =BE6/BA6-1 -> #DIV/0! | BF10: =BF6/BB6-1 -> #DIV/0! | BG10: =BG6/BC6-1 -> #DIV/0! | BH10: =BH6/BD6-1 -> #DIV/0! | BI10: =BI6/BE6-1 -> #DIV/0! | BJ10: =BJ6/BF6-1 -> #DIV/0! | ... BX10: =BX6/BT6-1 -> 0.85500251 | CJ10: =CJ6/CI6-1 -> #DIV/0! | CK10: =CK6/CJ6-1 -> #DIV/0! | CL10: =CL6/CK6-1 -> #DIV/0! | CM10: =CM6/CL6-1 -> #DIV/0! | CN10: =CN6/CM6-1 -> #DIV/0! | CO10: =CO6/CN6-1 -> #DIV/0! | CP10: =CP6/CO6-1 -> #DIV/0! | CQ10: =CQ6/CP6-1 -> #DIV/0! | ... DJ10: =DJ6/DI6-1 -> 1
B12: [Segment A] % of Ttl Revenues | BV12: =BV4/BV6 -> 0.61581883 | BW12: =BW4/BW6 -> #DIV/0! | BX12: =BX4/BX6 -> 0.82048596 | CY12: =CY4/CY6 -> 0.58864932 | CZ12: =CZ4/CZ6 -> 0.5
B13: [Segment B] % of Ttl Revenues | BV13: =BV5/BV6 -> 0.38418117 | BW13: =BW5/BW6 -> #DIV/0! | BX13: =BX5/BX6 -> 0.17951404
B15: Americas | CI15: =SUM(C15:F15) -> 0 | CJ15: =SUM(G15:J15) -> 0 | CK15: =SUM(K15:N15) -> 0 | CL15: =SUM(O15:R15) -> 0 | CM15: =SUM(S15:V15) -> 0 | CN15: =SUM(W15:Z15) -> 0 | CO15: =SUM(AA15:AD15) -> 0 | CP15: =SUM(AE15:AH15) -> 0 | CQ15: =SUM(AI15:AL15) -> 0 | CR15: =SUM(AM15:AP15) -> 0 | CS15: =SUM(AQ15:AT15) -> 0 | CT15: =SUM(AU15:AX15) -> 0 | CU15: =SUM(AY15:BB15) -> 0 | CV15: =SUM(BC15:BF15) -> 0 | CW15: =SUM(BG15:BJ15) -> 0 | CX15: =SUM(BK15:BN15) -> 0 | CY15: =SUM(BO15:BR15) -> 0 | CZ15: =SUM(BS15:BV15) -> 0
B16: APAC | CI16: =SUM(C16:F16) -> 0 | CJ16: =SUM(G16:J16) -> 0 | CK16: =SUM(K16:N16) -> 0 | CL16: =SUM(O16:R16) -> 0 | CM16: =SUM(S16:V16) -> 0 | CN16: =SUM(W16:Z16) -> 0 | CO16: =SUM(AA16:AD16) -> 0 | CP16: =SUM(AE16:AH16) -> 0 | CQ16: =SUM(AI16:AL16) -> 0 | CR16: =SUM(AM16:AP16) -> 0 | CS16: =SUM(AQ16:AT16) -> 0 | CT16: =SUM(AU16:AX16) -> 0 | CU16: =SUM(AY16:BB16) -> 0 | CV16: =SUM(BC16:BF16) -> 0 | CW16: =SUM(BG16:BJ16) -> 0 | CX16: =SUM(BK16:BN16) -> 0 | CY16: =SUM(BO16:BR16) -> 0 | CZ16: =SUM(BS16:BV16) -> 0
B17: EMEA | CI17: =SUM(C17:F17) -> 0 | CJ17: =SUM(G17:J17) -> 0 | CK17: =SUM(K17:N17) -> 0 | CL17: =SUM(O17:R17) -> 0 | CM17: =SUM(S17:V17) -> 0 | CN17: =SUM(W17:Z17) -> 0 | CO17: =SUM(AA17:AD17) -> 0 | CP17: =SUM(AE17:AH17) -> 0 | CQ17: =SUM(AI17:AL17) -> 0 | CR17: =SUM(AM17:AP17) -> 0 | CS17: =SUM(AQ17:AT17) -> 0 | CT17: =SUM(AU17:AX17) -> 0 | CU17: =SUM(AY17:BB17) -> 0 | CV17: =SUM(BC17:BF17) -> 0 | CW17: =SUM(BG17:BJ17) -> 0 | CX17: =SUM(BK17:BN17) -> 0 | CY17: =SUM(BO17:BR17) -> 0 | CZ17: =SUM(BS17:BV17) -> 0
B18: Ttl Revenues | CI18: =SUM(C18:F18) -> 0 | CJ18: =SUM(G18:J18) -> 0 | CK18: =SUM(K18:N18) -> 0 | CL18: =SUM(O18:R18) -> 0 | CM18: =SUM(S18:V18) -> 0 | CN18: =SUM(W18:Z18) -> 0 | CO18: =SUM(AA18:AD18) -> 0 | CP18: =SUM(AE18:AH18) -> 0 | CQ18: =SUM(AI18:AL18) -> 0 | CR18: =SUM(AM18:AP18) -> 0 | CS18: =SUM(AQ18:AT18) -> 0 | CT18: =SUM(AU18:AX18) -> 0 | CU18: =SUM(AY18:BB18) -> 0 | CV18: =SUM(BC18:BF18) -> 0 | CW18: =SUM(BG18:BJ18) -> 0 | CX18: =SUM(BK18:BN18) -> 0 | CY18: =SUM(BO18:BR18) -> 0 | CZ18: =SUM(BS18:BV18) -> 0
B20: Americas Growth Y/y | BC20: =BC15/AY15-1 -> #DIV/0! | BD20: =BD15/AZ15-1 -> #DIV/0! | BE20: =BE15/BA15-1 -> #DIV/0! | BF20: =BF15/BB15-1 -> #DIV/0! | BG20: =BG15/BC15-1 -> #DIV/0! | BH20: =BH15/BD15-1 -> #DIV/0! | BI20: =BI15/BE15-1 -> #DIV/0! | BJ20: =BJ15/BF15-1 -> #DIV/0! | ... BX20: =BX15/BT15-1 -> #DIV/0!
B21: APAC Growth Y/y | BC21: =BC16/AY16-1 -> #DIV/0! | BD21: =BD16/AZ16-1 -> #DIV/0! | BE21: =BE16/BA16-1 -> #DIV/0! | BF21: =BF16/BB16-1 -> #DIV/0! | BG21: =BG16/BC16-1 -> #DIV/0! | BH21: =BH16/BD16-1 -> #DIV/0! | BI21: =BI16/BE16-1 -> #DIV/0! | BJ21: =BJ16/BF16-1 -> #DIV/0! | ... BX21: =BX16/BT16-1 -> #DIV/0!
B22: EMEA Growth Y/y | BC22: =BC17/AY17-1 -> #DIV/0! | BD22: =BD17/AZ17-1 -> #DIV/0! | BE22: =BE17/BA17-1 -> #DIV/0! | BF22: =BF17/BB17-1 -> #DIV/0! | BG22: =BG17/BC17-1 -> #DIV/0! | BH22: =BH17/BD17-1 -> #DIV/0! | BI22: =BI17/BE17-1 -> #DIV/0! | BJ22: =BJ17/BF17-1 -> #DIV/0! | ... BX22: =BX17/BT17-1 -> #DIV/0!
B23: Ttl Revenue Growth Y/y | BC23: =BC19/AY19-1 -> #DIV/0! | BD23: =BD19/AZ19-1 -> #DIV/0! | BE23: =BE19/BA19-1 -> #DIV/0! | BF23: =BF19/BB19-1 -> #DIV/0! | BG23: =BG19/BC19-1 -> #DIV/0! | BH23: =BH19/BD19-1 -> #DIV/0! | BI23: =BI19/BE19-1 -> #DIV/0! | BJ23: =BJ19/BF19-1 -> #DIV/0! | ... BX23: =BX19/BT19-1 -> #DIV/0!
B25: Americas % of Revenues
B26: APAC % of Revenues
B27: EMEA % of Revenues
B29: Revenues | AY29: =AY6 -> 0 | AZ29: =AZ6 -> 0 | BA29: =BA6 -> 0 | BB29: =BB6 -> 0 | BC29: =BC6 -> 0 | BD29: =BD6 -> 0 | BE29: =BE6 -> 0 | BF29: =BF6 -> 0 | ... BX29: =BX6 -> 29591 | CI29: =SUM(C29:F29) -> 0 | CJ29: =SUM(G29:J29) -> 0 | CK29: =SUM(K29:N29) -> 0 | CL29: =SUM(O29:R29) -> 0 | CM29: =SUM(S29:V29) -> 0 | CN29: =SUM(W29:Z29) -> 0 | CO29: =SUM(AA29:AD29) -> 0 | CP29: =SUM(AE29:AH29) -> 0 | CQ29: =SUM(AI29:AL29) -> 0 | CR29: =SUM(AM29:AP29) -> 0 | CS29: =SUM(AQ29:AT29) -> 0 | CT29: =SUM(AU29:AX29) -> 0 | CU29: =SUM(AY29:BB29) -> 0 | CV29: =SUM(BC29:BF29) -> 0 | CW29: =SUM(BG29:BJ29) -> 0 | CX29: =SUM(BK29:BN29) -> 0 | CY29: =SUM(BO29:BR29) -> 51574 | CZ29: =SUM(BS29:BV29) -> 2000
B30: COGS | CI30: =SUM(C30:F30) -> 0 | CJ30: =SUM(G30:J30) -> 0 | CK30: =SUM(K30:N30) -> 0 | CL30: =SUM(O30:R30) -> 0 | CM30: =SUM(S30:V30) -> 0 | CN30: =SUM(W30:Z30) -> 0 | CO30: =SUM(AA30:AD30) -> 0 | CP30: =SUM(AE30:AH30) -> 0 | CQ30: =SUM(AI30:AL30) -> 0 | CR30: =SUM(AM30:AP30) -> 0 | CS30: =SUM(AQ30:AT30) -> 0 | CT30: =SUM(AU30:AX30) -> 0 | CU30: =SUM(AY30:BB30) -> 0 | CV30: =SUM(BC30:BF30) -> 0 | CW30: =SUM(BG30:BJ30) -> 0 | CX30: =SUM(BK30:BN30) -> 0 | CY30: =SUM(BO30:BR30) -> 0 | CZ30: =SUM(BS30:BV30) -> 0
B31: GP | AY31: =AY29-AY30 -> 0 | AZ31: =AZ29-AZ30 -> 0 | BA31: =BA29-BA30 -> 0 | BB31: =BB29-BB30 -> 0 | BC31: =BC29-BC30 -> 0 | BD31: =BD29-BD30 -> 0 | BE31: =BE29-BE30 -> 0 | BF31: =BF29-BF30 -> 0 | ... BX31: =BX29-BX30 -> 29591
B45: Net Income
B46: SC
B47: EPS
B49: Gross Profit Margin
B50: R&D as % of Revenue
B51: SG&A as % of Revenue
B52: Operating Profit Margin
B53: Effective Tax Rate
B54: Net Profit Margin
B55: EPS Growth
B57: Cash & CEs | CI57: =F57 -> 0 | CJ57: =J57 -> 0 | CK57: =N57 -> 0 | CL57: =R57 -> 0 | CM57: =V57 -> 0 | CN57: =Z57 -> 0 | CO57: =AD57 -> 0 | CP57: =AH57 -> 0 | CQ57: =AL57 -> 0 | CR57: =AP57 -> 0 | CS57: =AT57 -> 0 | CT57: =AX57 -> 0 | CU57: =BB57 -> 0 | CV57: =BF57 -> 0 | CW57: =BJ57 -> 0 | CX57: =BN57 -> 0 | CY57: =BR57 -> 0 | CZ57: =BS57 -> 0
B58: ST Investments
B59: Marketable Securities
DB60: Invested Capital | DE60: Avg. (2024-2025) | DG60: Projected ROIC: | DI60: ROIC | DJ60: 0.092
DB61: 2024 | DC61: 2025 | DE61: 2024-2025 | DG61: 2025 | DI61: Terminal | DJ61: 0.015
...

Sheet Notes | Quant Analysis
CL1: 0
P2: Employee Scope: | AO2: General Notes/Observations (Updated Q1'26)
AO35: Financial Stmts. Notes/Observations (Updated Q1'26)
P36: Institutional Ownership Snapshot Q4'25 | AO36: Revenues:
Q37: [Godel Snapshot] | AO37: [Godel Snapshot of projected sales]
P69: Revenue Breakdown by Segment (Build graph for this section if applicable…. See example below) | AO69: Earnings Scope:
AO70: [Godel Snapshot of projected earnings/EPS + CFFO]
Q101: Notes: | R101: [X]
R102: [Y]
R103: [Z]
P105: Q/q Total Revenues, Net Income, FCF | AO105: Balance Sheet Scope:
AO106: [Godel Snapshot of projected balances (assets, liabilities, equity)]
Q134: Notes: | R134: [X]
R135: [Y]
R136: [Z]
P138: Y/y Total Revenues, Net Income, FCF | AO138: [Equity Preformance Compared to Peers]
AO139: Use Godel CMS command
Q167: Notes: | R167: [X]
R168: [Y]
R169: [Z]
A184: VOO Historical Returns
A185: n # of Trading Days? (From: date the data snapshot was collected) | I185: n # of Trading Days? (From: date the data snapshot was collected)
A186: Close | B186: High | C186: Low | D186: Open | E186: Volume | F186: UTC Date | G186: Change | I186: Close | J186: High | K186: Low | L186: Open | M186: Volume | N186: UTC Date | O186: Change
G187: =A187/D187-1 -> #DIV/0! | O187: =I187/L187-1 -> #DIV/0!
R209: Min | S209: =MIN(O181:O1143) -> #DIV/0!
R210: Max | S210: =MAX(O181:O1143) -> #DIV/0!
R211: Mean μ | S211: =AVERAGE(O181:O1143) -> #DIV/0!
R212: Median | S212: =MEDIAN(O181:O1143) -> #DIV/0!
R213: SD σ | S213: =_xlfn.STDEV.P(O181:O1143) -> #DIV/0!
R214: 3σ 1-Day Δ: ± | S214: =3*S213 -> #DIV/0! | U214: <- Sharpe Ratio (Risk Adjusted Return)
R215: β (1-year avg.) | S215: =_xlfn.COVARIANCE.P(O132:O380,G132:G380)/_xlfn.VAR.P(G132:G380) -> #DIV/0! | U215: <- Sortino Ratio (Downside Risk Adjusted Return)
T218: n = | U218: 1014
T219: Histogram Data | W219: Distribution Overlay | AA219: SD Lines
T220: Bin | U220: Frequency | W220: (X) 1-Day Δ | X220: (Y) Pop. Density | AA220: X | AB220: Y
R221: =R222-0.001 -> -0.031 | Z221: Mean | AA221: =S211 -> #DIV/0!
R222: =R223-0.001 -> -0.03 | AA222: =S211 -> #DIV/0!
R223: =R224-0.001 -> -0.029 | Z223: -3σ | AA223: =($S$213*-3)+$S$211 -> #DIV/0!
R224: =R225-0.001 -> -0.028 | AA224: =($S$213*-3)+$S$211 -> #DIV/0!
R225: =R226-0.001 -> -0.027 | Z225: -2σ | AA225: =($S$213*-2)+$S$211 -> #DIV/0!
R226: =R227-0.001 -> -0.026 | AA226: =($S$213*-2)+$S$211 -> #DIV/0!
...

Sheet Product Lines

Sheet Economics

Sheet Management

Sheet Table Formatting
B2: [Bold Title] | G2: [Bold Title]
B3: Line Titles | G3: <-- General
B4: Line Titles | G4: <-- Info
B5: Line Titles | G5: <-- General
B6: Line Titles | G6: <-- Info
B7: Line Titles | G7: <-- General
B8: Line Titles | G8: <-- Info
