Workbook

Sheet Main
A1: Master | AP1: 1
B2: BSX
B3: Price | C3: 43.79 | D3: 46236
B4: SO | C4: 1470.2 | D4: Q2'26
B5: MC | C5: =C3*C4 -> 64380.058
B6: Cash | C6: 1453 | D6: Q2'26
B7: Debt | C7: 10988 | D7: Q2'26
B8: EV | C8: =C5-C6+C7 -> 73915.058 | O8: Resources:
O9: SEC filings | R9: https://www.sec.gov/edgar/browse/?CIK=885725&owner=exclude
B10: Boston Scientific Corp. (BSX) | O10: Boston Scientific Homepage | R10: https://www.bostonscientific.com/en-US/home.html
P11: BSX IR Page | S11: https://investors.bostonscientific.com/
B12: Founder(s): John Abele, Peter Nicholas | G12: Registered Exchange: NYSE | O12: Earnings Calls | R12: https://seekingalpha.com/symbol/BSX/earnings/transcripts
B13: Founded: 1979 | G13: Address: 300 Boston Scientific Way Marlborough, MA 01752-1234 U.S. | O13: Godel Terminal | R13: https://app.godelterminal.com/
B14: Headquarted: Marlborough, MA | G14: Investor Relations Contact: | O14: FDA Med Device Reporting's | R14: https://www.fda.gov/medical-devices
B15: Current CEO: Michael F. Mahoney (since 2012) | G15: Investors Relation Department | O15: U.S. Patent Office Search | R15: https://ppubs.uspto.gov/pubThe Companybapp/static/pages/ppubsbasic.html
B16: Employees: 53,000 (Q4'24) | G16: Phone: | J16: Email: | K16: BSXInvestorRelations@bsci.com | P16: BSX IP Catalog | S16: https://www.bostonscientific.com/content/dam/bostonscientific/corporate/patent-marking-spreadsheet-6feb-2025.pdf
B17: Sector: Healthcare | O17: Thrombecotomy News | R17: https://evtoday.com/
B18: Industry: Medical Devices | O18: MedTech News | R18: https://www.medtechdive.com/
B19: IPO: May 19, 1992 -- $1.6B valuation | O19: MacroTrends | R19: https://www.macrotrends.net/stocks/charts/BSX/boston-scientific/income-statement?freq=Q
B20: Fiscal Year: [January - December] | O20: ROIC, WACC | R20: https://www.gurufocus.com/term/wacc/BSX
A22: Overview:
B23: Boston Scientific Corporation is a global developer, manufacturer and marketer of medical devices that are used in a broad range of interventional medical specialties for both domestic and international markets
C24: The Company operates through three segments:
D25: MedSurg: | F25: Minimally invasive devices for endoscopy, urology, and pelvic health
D26: Rhythm and Neuro: | F26: Solutions for cardiac rhythm management (CRM), electrophysiology (EP), and neuromodulation
D27: Cardiovascular: | F27: Devices for interventional cardiology, peripheral interventions, and structural heart
B28: The Company states that they operate pursuant to five strategic imperatives
C29: Strengthen Category Leadership, Expand into High Growth Adjacencies, Drive Global Expansion, Fund the Journey to Fuel Growth and Develop Key Capabilities
B30: Management expects to continue to invest in our core businesses and pursue opportunities to diversify and further expand our presence in strategic, high-growth adjacencies and new global markets, including growth within the countries we define as emerging markets
C31: Maintaining and expanding our international presence is an important component of our long-term growth strategy
C32: Through our international presence, we seek to increase net sales and market share, leverage our relationships with leading physicians and their clinical research programs, accelerate the time to bring new products to market and gain access to worldwide technological developments that we can implement across our product lines
B33: Our research and development efforts are focused largely on the development of next-generation and novel technology offerings across multiple programs and all divisions
C34: !Check into R&D projects, product pipelines, and create useful life schedules for current assets!
B35: In the past several years, The Company has completed numerous acquisitions in support of its growth strategy, both strengthening the core businesses and expanding into high growth adjacent markets
A96: Product Offerings
B98: The Company's core businesses are organized into two reportable segments: MedSurg and Cardiovascular. The following describes our key product offerings and new product innovations by reportable segment and business unit
C99: Rhythm and Neuro operating segment is consolidated into the Cardiovascular segment on financial filings
B101: [Build table here]

Sheet Model
AU1: Q1 2020 | AY1: Q1 2021 | BC1: Q1 2022 | BG1: Q1 2023 | BK1: Q1 2024 | BO1: Q1 2025 | BS1: Q1 2026
B2: Quarterly | C2: Apr | D2: July | E2: Oct | F2: Jan | G2: Apr | H2: July | I2: Oct | J2: Jan | K2: Apr | L2: July | M2: Oct | N2: Jan | O2: Apr | P2: July | Q2: Oct | R2: Jan | S2: Apr | T2: July | U2: Oct | V2: Jan | W2: Apr | X2: July | Y2: Oct | Z2: Jan | AA2: Apr | AB2: July | AC2: Oct | AD2: Jan | AE2: Apr | AF2: July | AG2: Oct | AH2: Jan | AI2: Apr | AJ2: July | AK2: Oct | AL2: Jan | AM2: Apr | AN2: July | AO2: Oct | AP2: Jan | AQ2: Apr | AR2: July | AS2: Oct | AT2: Jan | AU2: Apr | AV2: July | AW2: Oct | AX2: Jan | AY2: Apr | AZ2: July | BA2: Oct | BB2: Jan | BC2: Apr | BD2: July | BE2: Oct | BF2: Jan | BG2: Apr | BH2: July | BI2: Oct | BJ2: Jan | BK2: Apr | BL2: July | BM2: Oct | BN2: Jan | BO2: Apr | BP2: July | BQ2: Oct | BR2: Jan | BS2: Apr | BT2: July | BU2: Oct | BV2: Jan
B3: Revenues | C3: {="Q"&MOD(_xlfn.SEQUENCE(1,72)-1,4)+1&" "&(2009+INT((_xlfn.SEQUENCE(1,72)-1)/4))} -> Q1 2009 | D3: Q2 2009 | E3: Q3 2009 | F3: Q4 2009 | G3: Q1 2010 | H3: Q2 2010 | I3: Q3 2010 | J3: Q4 2010 | K3: Q1 2011 | L3: Q2 2011 | M3: Q3 2011 | N3: Q4 2011 | O3: Q1 2012 | P3: Q2 2012 | Q3: Q3 2012 | R3: Q4 2012 | S3: Q1 2013 | T3: Q2 2013 | U3: Q3 2013 | V3: Q4 2013 | W3: Q1 2014 | X3: Q2 2014 | Y3: Q3 2014 | Z3: Q4 2014 | AA3: Q1 2015 | AB3: Q2 2015 | AC3: Q3 2015 | AD3: Q4 2015 | AE3: Q1 2016 | AF3: Q2 2016 | AG3: Q3 2016 | AH3: Q4 2016 | AI3: Q1 2017 | AJ3: Q2 2017 | AK3: Q3 2017 | AL3: Q4 2017 | AM3: Q1 2018 | AN3: Q2 2018 | AO3: Q3 2018 | AP3: Q4 2018 | AQ3: Q1 2019 | AR3: Q2 2019 | AS3: Q3 2019 | AT3: Q4 2019 | AU3: Q1 2020 | AV3: Q2 2020 | AW3: Q3 2020 | AX3: Q4 2020 | AY3: Q1 2021 | AZ3: Q2 2021 | BA3: Q3 2021 | BB3: Q4 2021 | BC3: Q1 2022 | BD3: Q2 2022 | BE3: Q3 2022 | BF3: Q4 2022 | BG3: Q1 2023 | BH3: Q2 2023 | BI3: Q3 2023 | BJ3: Q4 2023 | BK3: Q1 2024 | BL3: Q2 2024 | BM3: Q3 2024 | BN3: Q4 2024 | BO3: Q1 2025 | BP3: Q2 2025 | BQ3: Q3 2025 | BR3: Q4 2025 | BS3: Q1 2026 | BT3: Q2 2026 | BU3: Q3 2026 | BV3: Q4 2026 | CA3: 2009 | CB3: =CA3+1 -> 2010 | CC3: =CB3+1 -> 2011 | CD3: =CC3+1 -> 2012 | CE3: =CD3+1 -> 2013 | CF3: =CE3+1 -> 2014 | CG3: =CF3+1 -> 2015 | CH3: =CG3+1 -> 2016 | CI3: =CH3+1 -> 2017 | ... EO3: =EN3+1 -> 2075
B4: Endoscopy | AU4: 442 | AV4: 348 | AW4: 475 | AX4: =1780-SUM(AU4:AW4) -> 515 | AY4: 499 | AZ4: 551 | BA4: 533 | BB4: =2141-SUM(AY4:BA4) -> 558 | BC4: 532 | BD4: 561 | BE4: 559 | BF4: =2221-SUM(BC4:BE4) -> 569 | BG4: 577 | BH4: 630 | BI4: 629 | BJ4: =2482-SUM(BG4:BI4) -> 646 | BK4: 642 | BL4: 675 | BM4: 678 | BN4: =2687-SUM(BK4:BM4) -> 692 | BO4: 673 | BP4: 737 | BQ4: 747 | BR4: 760 | BS4: 736 | BT4: 793 | CK4: 1894 | CL4: =SUM(AU4:AX4) -> 1780 | CM4: =SUM(AY4:BB4) -> 2141 | CN4: =SUM(BC4:BF4) -> 2221 | CO4: =SUM(BG4:BJ4) -> 2482 | CP4: =SUM(BK4:BN4) -> 2687 | CQ4: =SUM(BO4:BR4) -> 2917 | CR4: =CQ4*(1+CR17) -> 3179.53 | CS4: =CR4*(1+CS17) -> 3386.1995 | CT4: =CS4*(1+CT17) -> 3562.2818 | CU4: =CT4*(1+CU17) -> 3711.8977 | CV4: =CU4*(1+CV17) -> 3860.3736 | CW4: =CV4*(1+CW17) -> 4003.2074 | CX4: =CW4*(1+CX17) -> 4143.3196 | CY4: =CX4*(1+CY17) -> 4275.9059 | ... DA4: =CZ4*(1+DA17) -> 4540.7127
B5: Urology | AU5: 332 | AV5: 228 | AW5: 350 | AX5: =1286-SUM(AU5:AW5) -> 376 | AY5: 361 | AZ5: 397 | BA5: 384 | BB5: =1583-SUM(AY5:BA5) -> 441 | BC5: 413 | BD5: 450 | BE5: 433 | BF5: =1773-SUM(BC5:BE5) -> 477 | BG5: 469 | BH5: 485 | BI5: 483 | BJ5: =1964-SUM(BG5:BI5) -> 527 | BK5: 513 | BL5: 525 | BM5: 532 | BN5: =2200-SUM(BK5:BM5) -> 630 | BO5: 633 | BP5: 676 | BQ5: 682 | BR5: 717 | BS5: 646 | BT5: 684 | CK5: 1413 | CL5: =SUM(AU5:AX5) -> 1286 | CM5: =SUM(AY5:BB5) -> 1583 | CN5: =SUM(BC5:BF5) -> 1773 | CO5: =SUM(BG5:BJ5) -> 1964 | CP5: =SUM(BK5:BN5) -> 2200 | CQ5: =SUM(BO5:BR5) -> 2708 | CR5: =CQ5*(1+CR18) -> 2870.48 | CS5: =CR5*(1+CS18) -> 2985.2992 | CT5: =CS5*(1+CT18) -> 3194.2701 | CU5: =CT5*(1+CU18) -> 3449.8118 | CV5: =CU5*(1+CV18) -> 3656.8005 | CW5: =CV5*(1+CW18) -> 3839.6405 | CX5: =CW5*(1+CX18) -> 4012.4243 | CY5: =CX5*(1+CY18) -> 4172.9213 | ... DA5: =CZ5*(1+DA18) -> 4459.3402
B6: Neuromodulation | AU6: 191 | AV6: 122 | AW6: 216 | AX6: =761-SUM(AU6:AW6) -> 232 | AY6: 198 | AZ6: 247 | BA6: 221 | BB6: =909-SUM(AY6:BA6) -> 243 | BC6: 209 | BD6: 238 | BE6: 221 | BF6: =917-SUM(BC6:BE6) -> 249 | BG6: 234 | BH6: 244 | BI6: 229 | BJ6: =976-SUM(BG6:BI6) -> 269 | BK6: 256 | BL6: 282 | BM6: 268 | BN6: =1106-SUM(BK6:BM6) -> 300 | BO6: 271 | BP6: 303 | BQ6: 293 | BR6: 332 | BS6: 319 | BT6: 341 | CK6: 873 | CL6: =SUM(AU6:AX6) -> 761 | CM6: =SUM(AY6:BB6) -> 909 | CN6: =SUM(BC6:BF6) -> 917 | CO6: =SUM(BG6:BJ6) -> 976 | CP6: =SUM(BK6:BN6) -> 1106 | CQ6: =SUM(BO6:BR6) -> 1199 | CR6: =CQ6*(1+CR19) -> 1366.86 | CS6: =CR6*(1+CS19) -> 1530.8832 | CT6: =CS6*(1+CT19) -> 1699.2804 | CU6: =CT6*(1+CU19) -> 1869.2084 | CV6: =CU6*(1+CV19) -> 2037.4371 | CW6: =CV6*(1+CW19) -> 2200.4321 | CX6: =CW6*(1+CX19) -> 2354.4624 | CY6: =CX6*(1+CY19) -> 2495.7301 | ... DA6: =CZ6*(1+DA19) -> 2725.3373
B7: MedSurg Ttl Revenues | AU7: =SUM(AU4:AU6) -> 965 | AV7: =SUM(AV4:AV6) -> 698 | AW7: =SUM(AW4:AW6) -> 1041 | AX7: =SUM(AX4:AX6) -> 1123 | AY7: =SUM(AY4:AY6) -> 1058 | AZ7: =SUM(AZ4:AZ6) -> 1195 | BA7: =SUM(BA4:BA6) -> 1138 | BB7: =SUM(BB4:BB6) -> 1242 | ... BT7: =SUM(BT4:BT6) -> 1818 | CK7: =SUM(CK4:CK6) -> 4180 | CL7: =SUM(CL4:CL6) -> 3827 | CM7: =SUM(CM4:CM6) -> 4633 | CN7: =SUM(CN4:CN6) -> 4911 | CO7: =SUM(CO4:CO6) -> 5422 | CP7: =SUM(CP4:CP6) -> 5993 | CQ7: =SUM(BO7:BR7) -> 6824 | CR7: =SUM(CR4:CR6) -> 7416.87 | CS7: =SUM(CS4:CS6) -> 7902.3818 | CT7: =SUM(CT4:CT6) -> 8455.8323 | CU7: =SUM(CU4:CU6) -> 9030.9178 | CV7: =SUM(CV4:CV6) -> 9554.6112 | CW7: =SUM(CW4:CW6) -> 10043.28 | CX7: =SUM(CX4:CX6) -> 10510.206 | CY7: =SUM(CY4:CY6) -> 10944.557 | ... DA7: =SUM(DA4:DA6) -> 11725.39
B8: Interventional Cardiology | AU8: 633 | AV8: 495 | AW8: 586 | AX8: =2299-SUM(AU8:AW8) -> 585 | AY8: 526 | AZ8: 574 | BA8: 534 | BB8: =2209-SUM(AY8:BA8) -> 575 | BC8: 544 | BD8: 574 | BE8: 549 | BF8: =2228-SUM(BC8:BE8) -> 561 | BG8: 591 | BH8: 629 | BI8: 583 | BJ8: =2417-SUM(BG8:BI8) -> 614 | BK8: 652 | BL8: 665 | BM8: 661 | BN8: =2645-SUM(BK8:BM8) -> 667 | BO8: 697 | BP8: 731 | BQ8: 686 | BR8: 732 | BS8: 764 | BT8: 833 | CK8: 2816 | CL8: =SUM(AU8:AX8) -> 2299 | CM8: =SUM(AY8:BB8) -> 2209 | CN8: =SUM(BC8:BF8) -> 2228 | CO8: =SUM(BG8:BJ8) -> 2417 | CP8: =SUM(BK8:BN8) -> 2645 | CQ8: =SUM(BO8:BR8) -> 2846 | CR8: =CQ8*(1+CR21) -> 3116.37 | CS8: =CR8*(1+CS21) -> 3459.1707 | CT8: =CS8*(1+CT21) -> 3701.3126 | CU8: =CT8*(1+CU21) -> 3886.3783 | CV8: =CU8*(1+CV21) -> 4061.2653 | CW8: =CV8*(1+CW21) -> 4223.7159 | CX8: =CW8*(1+CX21) -> 4371.546 | CY8: =CX8*(1+CY21) -> 4502.6924 | ... DA8: =CZ8*(1+DA21) -> 4719.103
B9: Watchman | AU9: 41 | AV9: 68 | AW9: 74 | AX9: =219-SUM(AU9:AW9) -> 36 | AY9: 170 | AZ9: 216 | BA9: 210 | BB9: =829-SUM(AY9:BA9) -> 233 | BC9: 226 | BD9: 250 | BE9: 262 | BF9: =1019-SUM(BC9:BE9) -> 281 | BG9: 291 | BH9: 317 | BI9: 323 | BJ9: =1274-SUM(BG9:BI9) -> 343 | BK9: 344 | BL9: 379 | BM9: 380 | BN9: =1516-SUM(BK9:BM9) -> 413 | BO9: 425 | BP9: 486 | BQ9: 512 | BR9: 541 | BS9: 506 | BT9: 507 | CK9: 81 | CL9: =SUM(AU9:AX9) -> 219 | CM9: =SUM(AY9:BB9) -> 829 | CN9: =SUM(BC9:BF9) -> 1019 | CO9: =SUM(BG9:BJ9) -> 1274 | CP9: =SUM(BK9:BN9) -> 1516 | CQ9: =SUM(BO9:BR9) -> 1964 | CR9: =CQ9*(1+CR22) -> 2278.24 | CS9: =CR9*(1+CS22) -> 2585.8024 | CT9: =CS9*(1+CT22) -> 2973.6728 | CU9: =CT9*(1+CU22) -> 3330.5135 | CV9: =CU9*(1+CV22) -> 3713.5225 | CW9: =CV9*(1+CW22) -> 4084.8748 | CX9: =CW9*(1+CX22) -> 4432.0892 | CY9: =CX9*(1+CY22) -> 4764.4958 | ... DA9: =CZ9*(1+DA22) -> 5429.3812
B10: Cardiac Rhythm | AU10: 437 | AV10: 351 | AW10: 465 | AX10: =1704-SUM(AU10:AW10) -> 451 | AY10: 469 | AZ10: 524 | BA10: 512 | BB10: =2019-SUM(AY10:BA10) -> 514 | BC10: 519 | BD10: 541 | BE10: 519 | BF10: =2100-SUM(BC10:BE10) -> 521 | BG10: 548 | BH10: 566 | BI10: 552 | BJ10: =2218-SUM(BG10:BI10) -> 552 | BK10: 575 | BL10: 576 | BM10: 561 | BN10: =2279-SUM(BK10:BM10) -> 567 | BO10: 578 | BP10: 590 | BQ10: 578 | BR10: 607 | BS10: 906 | BT10: 585 | CK10: 1939 | CL10: =SUM(AU10:AX10) -> 1704 | CM10: =SUM(AY10:BB10) -> 2019 | CN10: =SUM(BC10:BF10) -> 2100 | CO10: =SUM(BG10:BJ10) -> 2218 | CP10: =SUM(BK10:BN10) -> 2279 | CQ10: =SUM(BO10:BR10) -> 2353 | CR10: =CQ10*(1+CR23) -> 3176.55 | CS10: =CR10*(1+CS23) -> 3811.86 | CT10: =CS10*(1+CT23) -> 3926.2158 | CU10: =CT10*(1+CU23) -> 4024.3712 | CV10: =CU10*(1+CV23) -> 4114.9195 | CW10: =CV10*(1+CW23) -> 4197.2179 | CX10: =CW10*(1+CX23) -> 4270.6693 | CY10: =CX10*(1+CY23) -> 4334.7293 | ... DA10: =CZ10*(1+DA23) -> 4432.8025
B11: Electrophysiology | AU11: 74 | AV11: 51 | AW11: 76 | AX11: =287-SUM(AU11:AW11) -> 86 | AY11: 83 | AZ11: 95 | BA11: 86 | BB11: =365-SUM(AY11:BA11) -> 101 | BC11: 118 | BD11: 152 | BE11: 148 | BF11: =585-SUM(BC11:BE11) -> 167 | BG11: 177 | BH11: 193 | BI11: 190 | BJ11: =800-SUM(BG11:BI11) -> 240 | BK11: 300 | BL11: 428 | BM11: 527 | BN11: =1904-SUM(BK11:BM11) -> 649 | BO11: 729 | BP11: 840 | BQ11: 865 | BR11: 889 | BS11: 578 | BT11: 916 | CK11: 329 | CL11: =SUM(AU11:AX11) -> 287 | CM11: =SUM(AY11:BB11) -> 365 | CN11: =SUM(BC11:BF11) -> 585 | CO11: =SUM(BG11:BJ11) -> 800 | CP11: =SUM(BK11:BN11) -> 1904 | CQ11: =SUM(BO11:BR11) -> 3323 | CR11: =CQ11*(1+CR24) -> 2591.94 | CS11: =CR11*(1+CS24) -> 2332.746 | CT11: =CS11*(1+CT24) -> 2659.3304 | CU11: =CT11*(1+CU24) -> 2951.8568 | CV11: =CU11*(1+CV24) -> 3217.5239 | CW11: =CV11*(1+CW24) -> 3474.9258 | CX11: =CW11*(1+CX24) -> 3718.1706 | CY11: =CX11*(1+CY24) -> 3941.2609 | ... DA11: =CZ11*(1+DA24) -> 4303.8569
B12: Cardiology Ttl | AU12: =SUM(AU8:AU11) -> 1185 | AV12: =SUM(AV8:AV11) -> 965 | AW12: =SUM(AW8:AW11) -> 1201 | AX12: =SUM(AX8:AX11) -> 1158 | AY12: =SUM(AY8:AY11) -> 1248 | AZ12: =SUM(AZ8:AZ11) -> 1409 | BA12: =SUM(BA8:BA11) -> 1342 | BB12: =SUM(BB8:BB11) -> 1423 | ... BT12: =SUM(BT8:BT11) -> 2841 | CK12: =SUM(CK8:CK11) -> 5165 | CL12: =SUM(CL8:CL11) -> 4509 | CM12: =SUM(CM8:CM11) -> 5422 | CN12: =SUM(CN8:CN11) -> 5932 | CO12: =SUM(CO8:CO11) -> 6709 | CP12: =SUM(CP8:CP11) -> 8344 | CQ12: =SUM(BO12:BR12) -> 10486 | CR12: =SUM(CR8:CR11) -> 11163.1 | CS12: =SUM(CS8:CS11) -> 12189.579 | CT12: =SUM(CT8:CT11) -> 13260.532 | CU12: =SUM(CU8:CU11) -> 14193.12 | CV12: =SUM(CV8:CV11) -> 15107.231 | CW12: =SUM(CW8:CW11) -> 15980.734 | CX12: =SUM(CX8:CX11) -> 16792.475 | CY12: =SUM(CY8:CY11) -> 17543.178 | ... DA12: =SUM(DA8:DA11) -> 18885.144
B13: Peripheral Interventions | AU13: 393 | AV13: 340 | AW13: 417 | AX13: =1577-SUM(AU13:AW13) -> 427 | AY13: =433 -> 433 | AZ13: 473 | BA13: 452 | BB13: =1820-SUM(AY13:BA13) -> 462 | BC13: 465 | BD13: 478 | BE13: 479 | BF13: =1899-SUM(BC13:BE13) -> 477 | BG13: 502 | BH13: 535 | BI13: 538 | BJ13: =2109-SUM(BG13:BI13) -> 534 | BK13: 575 | BL13: 590 | BM13: 602 | BN13: =2410-SUM(BK13:BM13) -> 643 | BO13: 657 | BP13: 698 | BQ13: 702 | BR13: 708 | BS13: 749 | BT13: 783 | CK13: 1390 | CL13: =SUM(AU13:AX13) -> 1577 | CM13: =SUM(AY13:BB13) -> 1820 | CN13: =SUM(BC13:BF13) -> 1899 | CO13: =SUM(BG13:BJ13) -> 2109 | CP13: =SUM(BK13:BN13) -> 2410 | CQ13: =SUM(BO13:BR13) -> 2765 | CR13: =CQ13*(1+CR26) -> 3138.275 | CS13: =CR13*(1+CS26) -> 3514.868 | CT13: =CS13*(1+CT26) -> 3919.0778 | CU13: =CT13*(1+CU26) -> 4350.1764 | CV13: =CU13*(1+CV26) -> 4785.194 | CW13: =CV13*(1+CW26) -> 5215.8615 | CX13: =CW13*(1+CX26) -> 5633.1304 | CY13: =CX13*(1+CY26) -> 6027.4495 | ... DA13: =CZ13*(1+DA26) -> 6644.6604
B14: Cardiovascular Ttl Revenues | AU14: =SUM(AU12:AU13) -> 1578 | AV14: =SUM(AV12:AV13) -> 1305 | AW14: =SUM(AW12:AW13) -> 1618 | AX14: =SUM(AX12:AX13) -> 1585 | AY14: =SUM(AY12:AY13) -> 1681 | AZ14: =SUM(AZ12:AZ13) -> 1882 | BA14: =SUM(BA12:BA13) -> 1794 | BB14: =SUM(BB12:BB13) -> 1885 | ... BT14: =SUM(BT12:BT13) -> 3624 | CK14: =CK12+CK13 -> 6555 | CL14: =CL12+CL13 -> 6086 | CM14: =CM12+CM13 -> 7242 | CN14: =CN12+CN13 -> 7831 | CO14: =CO12+CO13 -> 8818 | CP14: =CP12+CP13 -> 10754 | CQ14: =SUM(BO14:BR14) -> 13251 | CR14: =CR12+CR13 -> 14301.375 | CS14: =CS12+CS13 -> 15704.447 | CT14: =CT12+CT13 -> 17179.609 | CU14: =CU12+CU13 -> 18543.296 | CV14: =CV12+CV13 -> 19892.425 | CW14: =CW12+CW13 -> 21196.596 | CX14: =CX12+CX13 -> 22425.605 | CY14: =CY12+CY13 -> 23570.628 | ... DA14: =DA12+DA13 -> 25529.804
B15: Ttl Revenues | AU15: =AU7+AU14 -> 2543 | AV15: =AV7+AV14 -> 2003 | AW15: =AW7+AW14 -> 2659 | AX15: =AX7+AX14 -> 2708 | AY15: =AY7+AY14+13 -> 2752 | AZ15: =AZ7+AZ14 -> 3077 | BA15: =BA7+BA14 -> 2932 | BB15: =BB7+BB14 -> 3127 | BC15: =BC7+BC14 -> 3026 | BD15: =BD7+BD14 -> 3244 | BE15: =BE7+BE14 -> 3170 | BF15: =BF7+BF14-60 -> 3242 | BG15: =BG7+BG14 -> 3389 | BH15: =BH7+BH14 -> 3599 | BI15: =BI7+BI14 -> 3527 | BJ15: =BJ7+BJ14 -> 3725 | BK15: =BK7+BK14 -> 3857 | BL15: =BL7+BL14 -> 4120 | BM15: =BM7+BM14 -> 4209 | BN15: =BN7+BN14 -> 4561 | ... BT15: =BT7+BT14 -> 5442 | CK15: =CK7+CK14 -> 10735 | CL15: =CL7+CL14 -> 9913 | CM15: =CM7+CM14+13 -> 11888 | CN15: =CN7+CN14-60 -> 12682 | CO15: =CO7+CO14 -> 14240 | CP15: =CP7+CP14 -> 16747 | CQ15: =SUM(BO15:BR15) -> 20075 | CR15: =CR7+CR14 -> 21718.245 | CS15: =CS7+CS14 -> 23606.829 | CT15: =CT7+CT14 -> 25635.442 | CU15: =CU7+CU14 -> 27574.214 | CV15: =CV7+CV14 -> 29447.036 | CW15: =CW7+CW14 -> 31239.876 | CX15: =CX7+CX14 -> 32935.812 | CY15: =CY7+CY14 -> 34515.185 | ... DA15: =DA7+DA14 -> 37255.194
B17: Endoscopy Growth Y/y | AY17: =AY4/AU4-1 -> 0.12895928 | AZ17: =AZ4/AV4-1 -> 0.58333333 | BA17: =BA4/AW4-1 -> 0.12210526 | BB17: =BB4/AX4-1 -> 0.083495146 | BC17: =BC4/AY4-1 -> 0.066132265 | BD17: =BD4/AZ4-1 -> 0.01814882 | BE17: =BE4/BA4-1 -> 0.048780488 | BF17: =BF4/BB4-1 -> 0.019713262 | ... BT17: =BT4/BP4-1 -> 0.075983718 | CL17: =CL4/CK4-1 -> -0.060190074 | CM17: =CM4/CL4-1 -> 0.20280899 | CN17: =CN4/CM4-1 -> 0.037365717 | CO17: =CO4/CN4-1 -> 0.11751463 | CP17: =CP4/CO4-1 -> 0.082594682 | CQ17: =CQ4/CP4-1 -> 0.08559732 | CR17: 0.09 | CS17: 0.065 | CT17: 0.052 | CU17: 0.042 | CV17: 0.04 | CW17: 0.037 | CX17: 0.035 | CY17: 0.032 | CZ17: 0.031 | DA17: 0.03
B18: Urology Growth Y/y | AY18: =AY5/AU5-1 -> 0.087349398 | AZ18: =AZ5/AV5-1 -> 0.74122807 | BA18: =BA5/AW5-1 -> 0.097142857 | BB18: =BB5/AX5-1 -> 0.17287234 | BC18: =BC5/AY5-1 -> 0.14404432 | BD18: =BD5/AZ5-1 -> 0.13350126 | BE18: =BE5/BA5-1 -> 0.12760417 | BF18: =BF5/BB5-1 -> 0.081632653 | ... BT18: =BT5/BP5-1 -> 0.01183432 | CL18: =CL5/CK5-1 -> -0.089879689 | CM18: =CM5/CL5-1 -> 0.23094868 | CN18: =CN5/CM5-1 -> 0.12002527 | CO18: =CO5/CN5-1 -> 0.10772702 | CP18: =CP5/CO5-1 -> 0.12016293 | CQ18: =CQ5/CP5-1 -> 0.23090909 | CR18: 0.06 | CS18: 0.04 | CT18: 0.07 | CU18: 0.08 | CV18: 0.06 | CW18: 0.05 | CX18: 0.045 | CY18: 0.04 | CZ18: 0.035 | DA18: 0.0325
B19: Neuro Growth Y/y | AY19: =AY6/AU6-1 -> 0.036649215 | AZ19: =AZ6/AV6-1 -> 1.0245902 | BA19: =BA6/AW6-1 -> 0.023148148 | BB19: =BB6/AX6-1 -> 0.047413793 | BC19: =BC6/AY6-1 -> 0.055555556 | BD19: =BD6/AZ6-1 -> -0.036437247 | BE19: =BE6/BA6-1 -> 0 | BF19: =BF6/BB6-1 -> 0.024691358 | ... BT19: =BT6/BP6-1 -> 0.12541254 | CL19: =CL6/CK6-1 -> -0.12829324 | CM19: =CM6/CL6-1 -> 0.19448095 | CN19: =CN6/CM6-1 -> 0.0088008801 | CO19: =CO6/CN6-1 -> 0.06434024 | CP19: =CP6/CO6-1 -> 0.13319672 | CQ19: =CQ6/CP6-1 -> 0.084086799 | CR19: 0.14 | CS19: 0.12 | CT19: 0.11 | CU19: 0.1 | CV19: 0.09 | CW19: 0.08 | CX19: 0.07 | CY19: 0.06 | CZ19: 0.05 | DA19: 0.04
B20: MedSurg Growth Y/y | AY20: =AY7/AU7-1 -> 0.096373057 | AZ20: =AZ7/AV7-1 -> 0.71203438 | BA20: =BA7/AW7-1 -> 0.093179635 | BB20: =BB7/AX7-1 -> 0.10596616 | BC20: =BC7/AY7-1 -> 0.09073724 | BD20: =BD7/AZ7-1 -> 0.045188285 | BE20: =BE7/BA7-1 -> 0.065905097 | BF20: =BF7/BB7-1 -> 0.042673108 | ... BT20: =BT7/BP7-1 -> 0.059440559 | CL20: =CL7/CK7-1 -> -0.084449761 | CM20: =CM7/CL7-1 -> 0.21060883 | CN20: =CN7/CM7-1 -> 0.060004317 | CO20: =CO7/CN7-1 -> 0.10405213 | CP20: =CP7/CO7-1 -> 0.10531169 | CQ20: =CQ7/CP7-1 -> 0.13866177 | CR20: =CR7/CQ7-1 -> 0.086880129 | CS20: =CS7/CR7-1 -> 0.065460477 | ... DA20: =DA7/CZ7-1 -> 0.03326073
B21: Interventional Growth Y/y | AY21: =AY8/AU8-1 -> -0.16903633 | AZ21: =AZ8/AV8-1 -> 0.15959596 | BA21: =BA8/AW8-1 -> -0.088737201 | BB21: =BB8/AX8-1 -> -0.017094017 | BC21: =BC8/AY8-1 -> 0.034220532 | BD21: =BD8/AZ8-1 -> 0 | BE21: =BE8/BA8-1 -> 0.028089888 | BF21: =BF8/BB8-1 -> -0.024347826 | ... BT21: =BT8/BP8-1 -> 0.13953488 | CL21: =CL8/CK8-1 -> -0.18359375 | CM21: =CM8/CL8-1 -> -0.039147455 | CN21: =CN8/CM8-1 -> 0.008601177 | CO21: =CO8/CN8-1 -> 0.084829443 | CP21: =CP8/CO8-1 -> 0.094331816 | CQ21: =CQ8/CP8-1 -> 0.075992439 | CR21: 0.095 | CS21: 0.11 | CT21: 0.07 | CU21: 0.05 | CV21: 0.045 | CW21: 0.04 | CX21: 0.035 | CY21: 0.03 | CZ21: 0.025 | DA21: 0.0225
B22: Watchman Growth Y/y | AY22: =AY9/AU9-1 -> 3.1463415 | AZ22: =AZ9/AV9-1 -> 2.1764706 | BA22: =BA9/AW9-1 -> 1.8378378 | BB22: =BB9/AX9-1 -> 5.4722222 | BC22: =BC9/AY9-1 -> 0.32941176 | BD22: =BD9/AZ9-1 -> 0.15740741 | BE22: =BE9/BA9-1 -> 0.24761905 | BF22: =BF9/BB9-1 -> 0.20600858 | ... BT22: =BT9/BP9-1 -> 0.043209877 | CL22: =CL9/CK9-1 -> 1.7037037 | CM22: =CM9/CL9-1 -> 2.7853881 | CN22: =CN9/CM9-1 -> 0.2291918 | CO22: =CO9/CN9-1 -> 0.25024534 | CP22: =CP9/CO9-1 -> 0.1899529 | CQ22: =CQ9/CP9-1 -> 0.29551451 | CR22: 0.16 | CS22: 0.135 | CT22: 0.15 | CU22: 0.12 | CV22: 0.115 | CW22: 0.1 | CX22: 0.085 | CY22: 0.075 | CZ22: 0.07 | DA22: 0.065
B23: Rhythm Growth Y/y | AY23: =AY10/AU10-1 -> 0.073226545 | AZ23: =AZ10/AV10-1 -> 0.49287749 | BA23: =BA10/AW10-1 -> 0.10107527 | BB23: =BB10/AX10-1 -> 0.13968958 | BC23: =BC10/AY10-1 -> 0.10660981 | BD23: =BD10/AZ10-1 -> 0.032442748 | BE23: =BE10/BA10-1 -> 0.013671875 | BF23: =BF10/BB10-1 -> 0.013618677 | ... BT23: =BT10/BP10-1 -> -0.0084745763 | CL23: =CL10/CK10-1 -> -0.12119649 | CM23: =CM10/CL10-1 -> 0.18485915 | CN23: =CN10/CM10-1 -> 0.040118871 | CO23: =CO10/CN10-1 -> 0.056190476 | CP23: =CP10/CO10-1 -> 0.027502254 | CQ23: =CQ10/CP10-1 -> 0.032470382 | CR23: 0.35 | CS23: 0.2 | CT23: 0.03 | CU23: 0.025 | CV23: 0.0225 | CW23: 0.02 | CX23: 0.0175 | CY23: 0.015 | CZ23: 0.0125 | DA23: 0.01
B24: Electrophysiology Growth Y/y | AY24: =AY11/AU11-1 -> 0.12162162 | AZ24: =AZ11/AV11-1 -> 0.8627451 | BA24: =BA11/AW11-1 -> 0.13157895 | BB24: =BB11/AX11-1 -> 0.1744186 | BC24: =BC11/AY11-1 -> 0.42168675 | BD24: =BD11/AZ11-1 -> 0.6 | BE24: =BE11/BA11-1 -> 0.72093023 | BF24: =BF11/BB11-1 -> 0.65346535 | ... BT24: =BT11/BP11-1 -> 0.09047619 | CL24: =CL11/CK11-1 -> -0.12765957 | CM24: =CM11/CL11-1 -> 0.271777 | CN24: =CN11/CM11-1 -> 0.60273973 | CO24: =CO11/CN11-1 -> 0.36752137 | CP24: =CP11/CO11-1 -> 1.38 | CQ24: =CQ11/CP11-1 -> 0.74527311 | CR24: -0.22 | CS24: -0.1 | CT24: 0.14 | CU24: 0.11 | CV24: 0.09 | CW24: 0.08 | CX24: 0.07 | CY24: 0.06 | CZ24: 0.05 | DA24: 0.04
B25: Cardiology Growth Y/y | AY25: =AY12/AU12-1 -> 0.053164557 | AZ25: =AZ12/AV12-1 -> 0.46010363 | BA25: =BA12/AW12-1 -> 0.11740216 | BB25: =BB12/AX12-1 -> 0.22884283 | BC25: =BC12/AY12-1 -> 0.12740385 | BD25: =BD12/AZ12-1 -> 0.076650106 | BE25: =BE12/BA12-1 -> 0.10134128 | BF25: =BF12/BB12-1 -> 0.075193254 | ... BT25: =BT12/BP12-1 -> 0.073290518 | CL25: =CL12/CK12-1 -> -0.12700871 | CM25: =CM12/CL12-1 -> 0.20248392 | CN25: =CN12/CM12-1 -> 0.094061232 | CO25: =CO12/CN12-1 -> 0.13098449 | CP25: =CP12/CO12-1 -> 0.24370249 | CQ25: =CQ12/CP12-1 -> 0.25671141 | CR25: =CR13/CQ13-1 -> 0.135 | CS25: =CS13/CR13-1 -> 0.12 | CT25: =CT13/CS13-1 -> 0.115 | CU25: =CU13/CT13-1 -> 0.11 | CV25: =CV13/CU13-1 -> 0.1 | CW25: =CW13/CV13-1 -> 0.09 | CX25: =CX13/CW13-1 -> 0.08 | CY25: =CY13/CX13-1 -> 0.07 | ... DA25: =DA13/CZ13-1 -> 0.04
B26: Peripheral Growth Y/y | AY26: =AY13/AU13-1 -> 0.10178117 | AZ26: =AZ13/AV13-1 -> 0.39117647 | BA26: =BA13/AW13-1 -> 0.083932854 | BB26: =BB13/AX13-1 -> 0.081967213 | BC26: =BC13/AY13-1 -> 0.073903002 | BD26: =BD13/AZ13-1 -> 0.010570825 | BE26: =BE13/BA13-1 -> 0.059734513 | BF26: =BF13/BB13-1 -> 0.032467532 | ... BT26: =BT13/BP13-1 -> 0.1217765 | CL26: =CL13/CK13-1 -> 0.13453237 | CM26: =CM13/CL13-1 -> 0.15409004 | CN26: =CN13/CM13-1 -> 0.043406593 | CO26: =CO13/CN13-1 -> 0.11058452 | CP26: =CP13/CO13-1 -> 0.14272167 | CQ26: =CQ13/CP13-1 -> 0.1473029 | CR26: 0.135 | CS26: 0.12 | CT26: 0.115 | CU26: 0.11 | CV26: 0.1 | CW26: 0.09 | CX26: 0.08 | CY26: 0.07 | CZ26: 0.06 | DA26: 0.04
B27: Cardiovascular Y/y | AY27: =AY14/AU14-1 -> 0.065272497 | AZ27: =AZ14/AV14-1 -> 0.44214559 | BA27: =BA14/AW14-1 -> 0.10877627 | BB27: =BB14/AX14-1 -> 0.18927445 | BC27: =BC14/AY14-1 -> 0.11362284 | BD27: =BD14/AZ14-1 -> 0.060042508 | BE27: =BE14/BA14-1 -> 0.090858417 | BF27: =BF14/BB14-1 -> 0.064721485 | ... BT27: =BT14/BP14-1 -> 0.083408072 | CL27: =CL14/CK14-1 -> -0.071548436 | CM27: =CM14/CL14-1 -> 0.18994413 | CN27: =CN14/CM14-1 -> 0.081331124 | CO27: =CO14/CN14-1 -> 0.12603754 | CP27: =CP14/CO14-1 -> 0.21955092 | CQ27: =CQ14/CP14-1 -> 0.23219267 | CR27: =CR14/CQ14-1 -> 0.079267602 | CS27: =CS14/CR14-1 -> 0.098107497 | ... DA27: =DA14/CZ14-1 -> 0.036549511
B28: Ttl Revenue Growth Y/y | AY28: =AY15/AU15-1 -> 0.082186394 | AZ28: =AZ15/AV15-1 -> 0.53619571 | BA28: =BA15/AW15-1 -> 0.10267018 | BB28: =BB15/AX15-1 -> 0.15472674 | BC28: =BC15/AY15-1 -> 0.099563953 | BD28: =BD15/AZ15-1 -> 0.054273643 | BE28: =BE15/BA15-1 -> 0.081173261 | BF28: =BF15/BB15-1 -> 0.036776463 | ... BT28: =BT15/BP15-1 -> 0.075281565 | CL28: =CL15/CK15-1 -> -0.076571961 | CM28: =CM15/CL15-1 -> 0.19923333 | CN28: =CN15/CM15-1 -> 0.06679004 | CO28: =CO15/CN15-1 -> 0.12285129 | CP28: =CP15/CO15-1 -> 0.17605337 | CQ28: =CQ15/CP15-1 -> 0.19872216 | CR28: =CR15/CQ15-1 -> 0.081855293 | CS28: =CS15/CR15-1 -> 0.086958405 | ... DA28: =DA15/CZ15-1 -> 0.035512172
B30: MedSurg % of Ttl Revenues | AU30: =AU7/AU15 -> 0.37947306 | AV30: =AV7/AV15 -> 0.34847728 | AW30: =AW7/AW15 -> 0.39150056 | AX30: =AX7/AX15 -> 0.41469719 | AY30: =AY7/AY15 -> 0.38444767 | AZ30: =AZ7/AZ15 -> 0.38836529 | BA30: =BA7/BA15 -> 0.38813097 | BB30: =BB7/BB15 -> 0.3971858 | ... BT30: =BT7/BT15 -> 0.33406836 | CK30: =CK7/CK15 -> 0.38938053 | CL30: =CL7/CL15 -> 0.38605871 | CM30: =CM7/CM15 -> 0.38972073 | CN30: =CN7/CN15 -> 0.38724176 | CO30: =CO7/CO15 -> 0.38075843 | CP30: =CP7/CP15 -> 0.35785514 | CQ30: =CQ7/CQ15 -> 0.33992528 | CR30: =CR7/CR15 -> 0.34150411 | ... DA30: =DA7/DA15 -> 0.31473169
B31: Cardiovasc % of Ttl Revenues | AU31: =AU14/AU15 -> 0.62052694 | AV31: =AV14/AV15 -> 0.65152272 | AW31: =AW14/AW15 -> 0.60849944 | AX31: =AX14/AX15 -> 0.58530281 | AY31: =AY14/AY15 -> 0.61082849 | AZ31: =AZ14/AZ15 -> 0.61163471 | BA31: =BA14/BA15 -> 0.61186903 | BB31: =BB14/BB15 -> 0.6028142 | ... BT31: =BT14/BT15 -> 0.66593164 | CK31: =CK14/CK15 -> 0.61061947 | CL31: =CL14/CL15 -> 0.61394129 | CM31: =CM14/CM15 -> 0.60918573 | CN31: =CN14/CN15 -> 0.61748935 | CO31: =CO14/CO15 -> 0.61924157 | CP31: =CP14/CP15 -> 0.64214486 | CQ31: =CQ14/CQ15 -> 0.66007472 | CR31: =CR14/CR15 -> 0.65849589 | ... DA31: =DA14/DA15 -> 0.68526831
B33: U.S. Revenues | AU33: 1452 | AV33: 1058 | AW33: 1496 | AX33: =5508-SUM(AU33:AW33) -> 1502 | AY33: 1577 | AZ33: 1800 | BA33: 1726 | BB33: =6901-SUM(AY33:BA33) -> 1798 | BC33: 1778 | BD33: 1934 | BE33: 1934 | BF33: =7632-SUM(BC33:BE33) -> 1986 | BG33: 2003 | BH33: 2110 | BI33: 2099 | BJ33: =8425-SUM(BG33:BI33) -> 2213 | BK33: 2258 | BL33: 2466 | BM33: 2593 | BN33: =10210-SUM(BK33:BM33) -> 2893 | BO33: 2960 | BP33: 3224 | BQ33: 3294 | BR33: 3385 | BS33: 3284 | BT33: 3426 | CK33: 6097 | CL33: =SUM(AU33:AX33) -> 5508 | CM33: =SUM(AY33:BB33) -> 6901 | CN33: =SUM(BC33:BF33) -> 7632 | CO33: =SUM(BG33:BJ33) -> 8425 | CP33: =SUM(BK33:BN33) -> 10210 | CQ33: =SUM(BO33:BR33) -> 12863
B34: Euro, Mid. East, Afr | AU34: 552 | AV34: 416 | AW34: 540 | AX34: =2097-SUM(AU34:AW34) -> 589 | AY34: 604 | AZ34: 662 | BA34: 590 | BB34: =2518-SUM(AY34:BA34) -> 662 | BC34: 624 | BD34: 660 | BE34: 585 | BF34: =2526-SUM(BC34:BE34) -> 657 | BG34: 712 | BH34: 723 | BI34: 671 | BJ34: =2856-SUM(BG34:BI34) -> 750 | BK34: 803 | BL34: 822 | BM34: 773 | BN34: =3228-SUM(BK34:BM34) -> 830 | BO34: 846 | BP34: 878 | BQ34: 793 | BR34: 933 | BS34: 932 | BT34: 932 | CK34: 2264 | CL34: =SUM(AU34:AX34) -> 2097 | CM34: =SUM(AY34:BB34) -> 2518 | CN34: =SUM(BC34:BF34) -> 2526 | CO34: =SUM(BG34:BJ34) -> 2856 | CP34: =SUM(BK34:BN34) -> 3228 | CQ34: =SUM(BO34:BR34) -> 3450
B35: A-Pac | AU35: 409 | AV35: 410 | AW35: 472 | AX35: =1781-SUM(AU35:AW35) -> 490 | AY35: 473 | AZ35: 520 | BA35: 517 | BB35: =2070-SUM(AY35:BA35) -> 560 | BC35: 517 | BD35: 530 | BE35: 532 | BF35: =2116-SUM(BC35:BE35) -> 537 | BG35: 548 | BH35: 626 | BI35: 611 | BJ35: =2400-SUM(BG35:BI35) -> 615 | BK35: 647 | BL35: 670 | BM35: 684 | BN35: =2686-SUM(BK35:BM35) -> 685 | BO35: 701 | BP35: 790 | BQ35: 803 | BR35: 789 | BS35: 803 | BT35: 878 | CK35: 1898 | CL35: =SUM(AU35:AX35) -> 1781 | CM35: =SUM(AY35:BB35) -> 2070 | CN35: =SUM(BC35:BF35) -> 2116 | CO35: =SUM(BG35:BJ35) -> 2400 | CP35: =SUM(BK35:BN35) -> 2686 | CQ35: =SUM(BO35:BR35) -> 3083
B36: Lat Am + Canada | AU36: 89 | AV36: 51 | AW36: 77 | AX36: =307-SUM(AU36:AW36) -> 90 | AY36: 85 | AZ36: 95 | BA36: 99 | BB36: =386-SUM(AY36:BA36) -> 107 | BC36: 107 | BD36: 120 | BE36: 119 | BF36: =469-SUM(BC36:BE36) -> 123 | BG36: 126 | BH36: 140 | BI36: 146 | BJ36: =559-SUM(BG36:BI36) -> 147 | BK36: 149 | BL36: 162 | BM36: 159 | BN36: =623-SUM(BK36:BM36) -> 153 | BO36: 156 | BP36: 169 | BQ36: 175 | BR36: 179 | BS36: 185 | BT36: 206 | CK36: 395 | CL36: =SUM(AU36:AX36) -> 307 | CM36: =SUM(AY36:BB36) -> 386 | CN36: =SUM(BC36:BF36) -> 469 | CO36: =SUM(BG36:BJ36) -> 559 | CP36: =SUM(BK36:BN36) -> 623 | CQ36: =SUM(BO36:BR36) -> 679
B37: Ttl Revenues | AU37: =SUM(AU33:AU36)+41 -> 2543 | AV37: =SUM(AV33:AV36)+68 -> 2003 | AW37: =SUM(AW33:AW36)+74 -> 2659 | AX37: =SUM(AX33:AX36)+220-41-68-74 -> 2708 | AY37: =SUM(AY33:AY36)+13 -> 2752 | AZ37: =SUM(AZ33:AZ36) -> 3077 | BA37: =SUM(BA33:BA36) -> 2932 | BB37: =SUM(BB33:BB36) -> 3127 | BC37: =SUM(BC33:BC36) -> 3026 | BD37: =SUM(BD33:BD36) -> 3244 | BE37: =SUM(BE33:BE36) -> 3170 | BF37: =SUM(BF33:BF36)-61 -> 3242 | BG37: =SUM(BG33:BG36) -> 3389 | BH37: =SUM(BH33:BH36) -> 3599 | BI37: =SUM(BI33:BI36) -> 3527 | BJ37: =SUM(BJ33:BJ36) -> 3725 | BK37: =SUM(BK33:BK36) -> 3857 | BL37: =SUM(BL33:BL36) -> 4120 | BM37: =SUM(BM33:BM36) -> 4209 | BN37: =SUM(BN33:BN36) -> 4561 | ... BT37: =SUM(BT33:BT36) -> 5442 | CK37: =SUM(CK33:CK36)+81 -> 10735 | CL37: =SUM(CL33:CL36)+220 -> 9913 | CM37: =SUM(CM33:CM36)+13 -> 11888 | CN37: =SUM(CN33:CN36)-61 -> 12682 | CO37: =SUM(CO33:CO36) -> 14240 | CP37: =SUM(CP33:CP36) -> 16747 | CQ37: =SUM(BO37:BR37) -> 20075
B39: U.S. Revenue Growth Y/y | AY39: =AY33/AU33-1 -> 0.086088154 | AZ39: =AZ33/AV33-1 -> 0.70132325 | BA39: =BA33/AW33-1 -> 0.15374332 | BB39: =BB33/AX33-1 -> 0.19707057 | BC39: =BC33/AY33-1 -> 0.1274572 | BD39: =BD33/AZ33-1 -> 0.074444444 | BE39: =BE33/BA33-1 -> 0.12050985 | BF39: =BF33/BB33-1 -> 0.10456062 | ... BT39: =BT33/BP33-1 -> 0.062655087 | CL39: =CL33/CK33-1 -> -0.096604888 | CM39: =CM33/CL33-1 -> 0.25290487 | CN39: =CN33/CM33-1 -> 0.10592668 | CO39: =CO33/CN33-1 -> 0.10390461 | CP39: =CP33/CO33-1 -> 0.21186944 | CQ39: =CQ33/CP33-1 -> 0.25984329
B40: Euro, Mid. East, Afr Revenue Growth Y/y | AY40: =AY34/AU34-1 -> 0.094202899 | AZ40: =AZ34/AV34-1 -> 0.59134615 | BA40: =BA34/AW34-1 -> 0.092592593 | BB40: =BB34/AX34-1 -> 0.12393888 | BC40: =BC34/AY34-1 -> 0.033112583 | BD40: =BD34/AZ34-1 -> -0.003021148 | BE40: =BE34/BA34-1 -> -0.0084745763 | BF40: =BF34/BB34-1 -> -0.0075528701 | ... BT40: =BT34/BP34-1 -> 0.061503417 | CL40: =CL34/CK34-1 -> -0.073763251 | CM40: =CM34/CL34-1 -> 0.20076299 | CN40: =CN34/CM34-1 -> 0.0031771247 | CO40: =CO34/CN34-1 -> 0.13064133 | CP40: =CP34/CO34-1 -> 0.1302521 | CQ40: =CQ34/CP34-1 -> 0.068773234
B41: A-Pac Revenue Growth Y/y | AY41: =AY35/AU35-1 -> 0.15647922 | AZ41: =AZ35/AV35-1 -> 0.26829268 | BA41: =BA35/AW35-1 -> 0.095338983 | BB41: =BB35/AX35-1 -> 0.14285714 | BC41: =BC35/AY35-1 -> 0.093023256 | BD41: =BD35/AZ35-1 -> 0.019230769 | BE41: =BE35/BA35-1 -> 0.02901354 | BF41: =BF35/BB35-1 -> -0.041071429 | ... BT41: =BT35/BP35-1 -> 0.11139241 | CL41: =CL35/CK35-1 -> -0.061643836 | CM41: =CM35/CL35-1 -> 0.16226839 | CN41: =CN35/CM35-1 -> 0.022222222 | CO41: =CO35/CN35-1 -> 0.1342155 | CP41: =CP35/CO35-1 -> 0.11916667 | CQ41: =CQ35/CP35-1 -> 0.14780343
B42: Lat Am + Canada Revenue Growth Y/y | AY42: =AY36/AU36-1 -> -0.04494382 | AZ42: =AZ36/AV36-1 -> 0.8627451 | BA42: =BA36/AW36-1 -> 0.28571429 | BB42: =BB36/AX36-1 -> 0.18888889 | BC42: =BC36/AY36-1 -> 0.25882353 | BD42: =BD36/AZ36-1 -> 0.26315789 | BE42: =BE36/BA36-1 -> 0.2020202 | BF42: =BF36/BB36-1 -> 0.14953271 | ... BT42: =BT36/BP36-1 -> 0.21893491 | CL42: =CL36/CK36-1 -> -0.22278481 | CM42: =CM36/CL36-1 -> 0.25732899 | CN42: =CN36/CM36-1 -> 0.21502591 | CO42: =CO36/CN36-1 -> 0.19189765 | CP42: =CP36/CO36-1 -> 0.11449016 | CQ42: =CQ36/CP36-1 -> 0.08988764
B43: Ttl Revenue Growth Y/y | AY43: =AY37/AU37-1 -> 0.082186394 | AZ43: =AZ37/AV37-1 -> 0.53619571 | BA43: =BA37/AW37-1 -> 0.10267018 | BB43: =BB37/AX37-1 -> 0.15472674 | BC43: =BC37/AY37-1 -> 0.099563953 | BD43: =BD37/AZ37-1 -> 0.054273643 | BE43: =BE37/BA37-1 -> 0.081173261 | BF43: =BF37/BB37-1 -> 0.036776463 | ... BT43: =BT37/BP37-1 -> 0.075281565 | CL43: =CL37/CK37-1 -> -0.076571961 | CM43: =CM37/CL37-1 -> 0.19923333 | CN43: =CN37/CM37-1 -> 0.06679004 | CO43: =CO37/CN37-1 -> 0.12285129 | CP43: =CP37/CO37-1 -> 0.17605337 | CQ43: =CQ37/CP37-1 -> 0.19872216
B45: U.S. % of Revenues | AU45: =AU33/AU37 -> 0.57097916 | AV45: =AV33/AV37 -> 0.52820769 | AW45: =AW33/AW37 -> 0.56261753 | AX45: =AX33/AX37 -> 0.55465288 | AY45: =AY33/AY37 -> 0.57303779 | AZ45: =AZ33/AZ37 -> 0.58498538 | BA45: =BA33/BA37 -> 0.58867667 | BB45: =BB33/BB37 -> 0.57499201 | ... BT45: =BT33/BT37 -> 0.62954796 | CK45: =CK33/CK37 -> 0.56795529 | CL45: =CL33/CL37 -> 0.55563402 | CM45: =CM33/CM37 -> 0.58050135 | CN45: =CN33/CN37 -> 0.60179782 | CO45: =CO33/CO37 -> 0.59164326 | CP45: =CP33/CP37 -> 0.60966143 | CQ45: =CQ33/CQ37 -> 0.6407472
...

Sheet PEN Acquisition
AU1: Q1 2020 | AY1: Q1 2021 | BC1: Q1 2022 | BG1: Q1 2023 | BK1: Q1 2024 | BO1: Q1 2025 | BS1: Q1 2026
B2: Quarterly | C2: Apr | D2: July | E2: Oct | F2: Jan | G2: Apr | H2: July | I2: Oct | J2: Jan | K2: Apr | L2: July | M2: Oct | N2: Jan | O2: Apr | P2: July | Q2: Oct | R2: Jan | S2: Apr | T2: July | U2: Oct | V2: Jan | W2: Apr | X2: July | Y2: Oct | Z2: Jan | AA2: Apr | AB2: July | AC2: Oct | AD2: Jan | AE2: Apr | AF2: July | AG2: Oct | AH2: Jan | AI2: Apr | AJ2: July | AK2: Oct | AL2: Jan | AM2: Apr | AN2: July | AO2: Oct | AP2: Jan | AQ2: Apr | AR2: July | AS2: Oct | AT2: Jan | AU2: Apr | AV2: July | AW2: Oct | AX2: Jan | AY2: Apr | AZ2: July | BA2: Oct | BB2: Jan | BC2: Apr | BD2: July | BE2: Oct | BF2: Jan | BG2: Apr | BH2: July | BI2: Oct | BJ2: Jan | BK2: Apr | BL2: July | BM2: Oct | BN2: Jan | BO2: Apr | BP2: July | BQ2: Oct | BR2: Jan | BS2: Apr | BT2: July | BU2: Oct | BV2: Jan
B3: Revenues | C3: {="Q"&MOD(_xlfn.SEQUENCE(1,72)-1,4)+1&" "&(2009+INT((_xlfn.SEQUENCE(1,72)-1)/4))} -> Q1 2009 | D3: Q2 2009 | E3: Q3 2009 | F3: Q4 2009 | G3: Q1 2010 | H3: Q2 2010 | I3: Q3 2010 | J3: Q4 2010 | K3: Q1 2011 | L3: Q2 2011 | M3: Q3 2011 | N3: Q4 2011 | O3: Q1 2012 | P3: Q2 2012 | Q3: Q3 2012 | R3: Q4 2012 | S3: Q1 2013 | T3: Q2 2013 | U3: Q3 2013 | V3: Q4 2013 | W3: Q1 2014 | X3: Q2 2014 | Y3: Q3 2014 | Z3: Q4 2014 | AA3: Q1 2015 | AB3: Q2 2015 | AC3: Q3 2015 | AD3: Q4 2015 | AE3: Q1 2016 | AF3: Q2 2016 | AG3: Q3 2016 | AH3: Q4 2016 | AI3: Q1 2017 | AJ3: Q2 2017 | AK3: Q3 2017 | AL3: Q4 2017 | AM3: Q1 2018 | AN3: Q2 2018 | AO3: Q3 2018 | AP3: Q4 2018 | AQ3: Q1 2019 | AR3: Q2 2019 | AS3: Q3 2019 | AT3: Q4 2019 | AU3: Q1 2020 | AV3: Q2 2020 | AW3: Q3 2020 | AX3: Q4 2020 | AY3: Q1 2021 | AZ3: Q2 2021 | BA3: Q3 2021 | BB3: Q4 2021 | BC3: Q1 2022 | BD3: Q2 2022 | BE3: Q3 2022 | BF3: Q4 2022 | BG3: Q1 2023 | BH3: Q2 2023 | BI3: Q3 2023 | BJ3: Q4 2023 | BK3: Q1 2024 | BL3: Q2 2024 | BM3: Q3 2024 | BN3: Q4 2024 | BO3: Q1 2025 | BP3: Q2 2025 | BQ3: Q3 2025 | BR3: Q4 2025 | BS3: Q1 2026 | BT3: Q2 2026 | BU3: Q3 2026 | BV3: Q4 2026 | CA3: 2009 | CB3: =CA3+1 -> 2010 | CC3: =CB3+1 -> 2011 | CD3: =CC3+1 -> 2012 | CE3: =CD3+1 -> 2013 | CF3: =CE3+1 -> 2014 | CG3: =CF3+1 -> 2015 | CH3: =CG3+1 -> 2016 | CI3: =CH3+1 -> 2017 | ... EO3: =EN3+1 -> 2075
B4: Endoscopy | AU4: 442 | AV4: 348 | AW4: 475 | AX4: =1780-SUM(AU4:AW4) -> 515 | AY4: 499 | AZ4: 551 | BA4: 533 | BB4: =2141-SUM(AY4:BA4) -> 558 | BC4: 532 | BD4: 561 | BE4: 559 | BF4: =2221-SUM(BC4:BE4) -> 569 | BG4: 577 | BH4: 630 | BI4: 629 | BJ4: =2482-SUM(BG4:BI4) -> 646 | BK4: 642 | BL4: 675 | BM4: 678 | BN4: =2687-SUM(BK4:BM4) -> 692 | BO4: 673 | BP4: 737 | BQ4: 747 | BR4: 760 | BS4: 736 | BT4: 793 | CK4: 1894 | CL4: =SUM(AU4:AX4) -> 1780 | CM4: =SUM(AY4:BB4) -> 2141 | CN4: =SUM(BC4:BF4) -> 2221 | CO4: =SUM(BG4:BJ4) -> 2482 | CP4: =SUM(BK4:BN4) -> 2687 | CQ4: =SUM(BO4:BR4) -> 2917 | CR4: =CQ4*(1+CR17) -> 3194.115 | CS4: =CR4*(1+CS17) -> 3401.7325 | CT4: =CS4*(1+CT17) -> 3578.6226 | CU4: =CT4*(1+CU17) -> 3728.9247 | CV4: =CU4*(1+CV17) -> 3878.0817 | CW4: =CV4*(1+CW17) -> 4021.5707 | CX4: =CW4*(1+CX17) -> 4162.3257 | CY4: =CX4*(1+CY17) -> 4295.5201 | ... DA4: =CZ4*(1+DA17) -> 4561.5417
B5: Urology | AU5: 332 | AV5: 228 | AW5: 350 | AX5: =1286-SUM(AU5:AW5) -> 376 | AY5: 361 | AZ5: 397 | BA5: 384 | BB5: =1583-SUM(AY5:BA5) -> 441 | BC5: 413 | BD5: 450 | BE5: 433 | BF5: =1773-SUM(BC5:BE5) -> 477 | BG5: 469 | BH5: 485 | BI5: 483 | BJ5: =1964-SUM(BG5:BI5) -> 527 | BK5: 513 | BL5: 525 | BM5: 532 | BN5: =2200-SUM(BK5:BM5) -> 630 | BO5: 633 | BP5: 676 | BQ5: 682 | BR5: 717 | BS5: 646 | BT5: 684 | CK5: 1413 | CL5: =SUM(AU5:AX5) -> 1286 | CM5: =SUM(AY5:BB5) -> 1583 | CN5: =SUM(BC5:BF5) -> 1773 | CO5: =SUM(BG5:BJ5) -> 1964 | CP5: =SUM(BK5:BN5) -> 2200 | CQ5: =SUM(BO5:BR5) -> 2708 | CR5: =CQ5*(1+CR18) -> 2789.24 | CS5: =CR5*(1+CS18) -> 2900.8096 | CT5: =CS5*(1+CT18) -> 3103.8663 | CU5: =CT5*(1+CU18) -> 3352.1756 | CV5: =CU5*(1+CV18) -> 3553.3061 | CW5: =CV5*(1+CW18) -> 3730.9714 | CX5: =CW5*(1+CX18) -> 3898.8651 | CY5: =CX5*(1+CY18) -> 4054.8197 | ... DA5: =CZ5*(1+DA18) -> 4333.1324
B6: Neuromodulation | AU6: 191 | AV6: 122 | AW6: 216 | AX6: =761-SUM(AU6:AW6) -> 232 | AY6: 198 | AZ6: 247 | BA6: 221 | BB6: =909-SUM(AY6:BA6) -> 243 | BC6: 209 | BD6: 238 | BE6: 221 | BF6: =917-SUM(BC6:BE6) -> 249 | BG6: 234 | BH6: 244 | BI6: 229 | BJ6: =976-SUM(BG6:BI6) -> 269 | BK6: 256 | BL6: 282 | BM6: 268 | BN6: =1106-SUM(BK6:BM6) -> 300 | BO6: 271 | BP6: 303 | BQ6: 293 | BR6: 332 | BS6: 319 | BT6: 341 | CK6: 873 | CL6: =SUM(AU6:AX6) -> 761 | CM6: =SUM(AY6:BB6) -> 909 | CN6: =SUM(BC6:BF6) -> 917 | CO6: =SUM(BG6:BJ6) -> 976 | CP6: =SUM(BK6:BN6) -> 1106 | CQ6: =SUM(BO6:BR6) -> 1199 | CR6: =CQ6*(1+CR19) -> 1366.86 | CS6: =CR6*(1+CS19) -> 1530.8832 | CT6: =CS6*(1+CT19) -> 1699.2804 | CU6: =CT6*(1+CU19) -> 1869.2084 | CV6: =CU6*(1+CV19) -> 2037.4371 | CW6: =CV6*(1+CW19) -> 2200.4321 | CX6: =CW6*(1+CX19) -> 2354.4624 | CY6: =CX6*(1+CY19) -> 2495.7301 | ... DA6: =CZ6*(1+DA19) -> 2725.3373
B7: MedSurg Ttl Revenues | AU7: =SUM(AU4:AU6) -> 965 | AV7: =SUM(AV4:AV6) -> 698 | AW7: =SUM(AW4:AW6) -> 1041 | AX7: =SUM(AX4:AX6) -> 1123 | AY7: =SUM(AY4:AY6) -> 1058 | AZ7: =SUM(AZ4:AZ6) -> 1195 | BA7: =SUM(BA4:BA6) -> 1138 | BB7: =SUM(BB4:BB6) -> 1242 | ... BT7: =SUM(BT4:BT6) -> 1818 | CK7: =SUM(CK4:CK6) -> 4180 | CL7: =SUM(CL4:CL6) -> 3827 | CM7: =SUM(CM4:CM6) -> 4633 | CN7: =SUM(CN4:CN6) -> 4911 | CO7: =SUM(CO4:CO6) -> 5422 | CP7: =SUM(CP4:CP6) -> 5993 | CQ7: =SUM(BO7:BR7) -> 6824 | CR7: =SUM(CR4:CR6) -> 7350.215 | CS7: =SUM(CS4:CS6) -> 7833.4253 | CT7: =SUM(CT4:CT6) -> 8381.7692 | CU7: =SUM(CU4:CU6) -> 8950.3087 | CV7: =SUM(CV4:CV6) -> 9468.825 | CW7: =SUM(CW4:CW6) -> 9952.9742 | CX7: =SUM(CX4:CX6) -> 10415.653 | CY7: =SUM(CY4:CY6) -> 10846.07 | ... DA7: =SUM(DA4:DA6) -> 11620.011
B8: Interventional Cardiology | AU8: 633 | AV8: 495 | AW8: 586 | AX8: =2299-SUM(AU8:AW8) -> 585 | AY8: 526 | AZ8: 574 | BA8: 534 | BB8: =2209-SUM(AY8:BA8) -> 575 | BC8: 544 | BD8: 574 | BE8: 549 | BF8: =2228-SUM(BC8:BE8) -> 561 | BG8: 591 | BH8: 629 | BI8: 583 | BJ8: =2417-SUM(BG8:BI8) -> 614 | BK8: 652 | BL8: 665 | BM8: 661 | BN8: =2645-SUM(BK8:BM8) -> 667 | BO8: 697 | BP8: 731 | BQ8: 686 | BR8: 732 | BS8: 764 | BT8: 833 | CK8: 2816 | CL8: =SUM(AU8:AX8) -> 2299 | CM8: =SUM(AY8:BB8) -> 2209 | CN8: =SUM(BC8:BF8) -> 2228 | CO8: =SUM(BG8:BJ8) -> 2417 | CP8: =SUM(BK8:BN8) -> 2645 | CQ8: =SUM(BO8:BR8) -> 2846 | CR8: =CQ8*(1+CR21) -> 3201.75 | CS8: =CR8*(1+CS21) -> 3457.89 | CT8: =CS8*(1+CT21) -> 3699.9423 | CU8: =CT8*(1+CU21) -> 3884.9394 | CV8: =CU8*(1+CV21) -> 4059.7617 | CW8: =CV8*(1+CW21) -> 4222.1522 | CX8: =CW8*(1+CX21) -> 4369.9275 | CY8: =CX8*(1+CY21) -> 4501.0253 | ... DA8: =CZ8*(1+DA21) -> 4717.3558
B9: Watchman | AU9: 41 | AV9: 68 | AW9: 74 | AX9: =219-SUM(AU9:AW9) -> 36 | AY9: 170 | AZ9: 216 | BA9: 210 | BB9: =829-SUM(AY9:BA9) -> 233 | BC9: 226 | BD9: 250 | BE9: 262 | BF9: =1019-SUM(BC9:BE9) -> 281 | BG9: 291 | BH9: 317 | BI9: 323 | BJ9: =1274-SUM(BG9:BI9) -> 343 | BK9: 344 | BL9: 379 | BM9: 380 | BN9: =1516-SUM(BK9:BM9) -> 413 | BO9: 425 | BP9: 486 | BQ9: 512 | BR9: 541 | BS9: 506 | BT9: 507 | CK9: 81 | CL9: =SUM(AU9:AX9) -> 219 | CM9: =SUM(AY9:BB9) -> 829 | CN9: =SUM(BC9:BF9) -> 1019 | CO9: =SUM(BG9:BJ9) -> 1274 | CP9: =SUM(BK9:BN9) -> 1516 | CQ9: =SUM(BO9:BR9) -> 1964 | CR9: =CQ9*(1+CR22) -> 2238.96 | CS9: =CR9*(1+CS22) -> 2440.4664 | CT9: =CS9*(1+CT22) -> 2806.5364 | CU9: =CT9*(1+CU22) -> 3143.3207 | CV9: =CU9*(1+CV22) -> 3504.8026 | CW9: =CV9*(1+CW22) -> 3855.2829 | CX9: =CW9*(1+CX22) -> 4182.9819 | CY9: =CX9*(1+CY22) -> 4496.7056 | ... DA9: =CZ9*(1+DA22) -> 5124.2208
B10: Cardiac Rhythm | AU10: 437 | AV10: 351 | AW10: 465 | AX10: =1704-SUM(AU10:AW10) -> 451 | AY10: 469 | AZ10: 524 | BA10: 512 | BB10: =2019-SUM(AY10:BA10) -> 514 | BC10: 519 | BD10: 541 | BE10: 519 | BF10: =2100-SUM(BC10:BE10) -> 521 | BG10: 548 | BH10: 566 | BI10: 552 | BJ10: =2218-SUM(BG10:BI10) -> 552 | BK10: 575 | BL10: 576 | BM10: 561 | BN10: =2279-SUM(BK10:BM10) -> 567 | BO10: 578 | BP10: 590 | BQ10: 578 | BR10: 607 | BS10: 906 | BT10: 585 | CK10: 1939 | CL10: =SUM(AU10:AX10) -> 1704 | CM10: =SUM(AY10:BB10) -> 2019 | CN10: =SUM(BC10:BF10) -> 2100 | CO10: =SUM(BG10:BJ10) -> 2218 | CP10: =SUM(BK10:BN10) -> 2279 | CQ10: =SUM(BO10:BR10) -> 2353 | CR10: =CQ10*(1+CR23) -> 3176.55 | CS10: =CR10*(1+CS23) -> 3430.674 | CT10: =CS10*(1+CT23) -> 3533.5942 | CU10: =CT10*(1+CU23) -> 3621.9341 | CV10: =CU10*(1+CV23) -> 3703.4276 | CW10: =CV10*(1+CW23) -> 3777.4961 | CX10: =CW10*(1+CX23) -> 3843.6023 | CY10: =CX10*(1+CY23) -> 3901.2564 | ... DA10: =CZ10*(1+DA23) -> 3989.5223
B11: Electrophysiology | AU11: 74 | AV11: 51 | AW11: 76 | AX11: =287-SUM(AU11:AW11) -> 86 | AY11: 83 | AZ11: 95 | BA11: 86 | BB11: =365-SUM(AY11:BA11) -> 101 | BC11: 118 | BD11: 152 | BE11: 148 | BF11: =585-SUM(BC11:BE11) -> 167 | BG11: 177 | BH11: 193 | BI11: 190 | BJ11: =800-SUM(BG11:BI11) -> 240 | BK11: 300 | BL11: 428 | BM11: 527 | BN11: =1904-SUM(BK11:BM11) -> 649 | BO11: 729 | BP11: 840 | BQ11: 865 | BR11: 889 | BS11: 578 | BT11: 916 | CK11: 329 | CL11: =SUM(AU11:AX11) -> 287 | CM11: =SUM(AY11:BB11) -> 365 | CN11: =SUM(BC11:BF11) -> 585 | CO11: =SUM(BG11:BJ11) -> 800 | CP11: =SUM(BK11:BN11) -> 1904 | CQ11: =SUM(BO11:BR11) -> 3323 | CR11: =CQ11*(1+CR24) -> 2591.94 | CS11: =CR11*(1+CS24) -> 2332.746 | CT11: =CS11*(1+CT24) -> 2659.3304 | CU11: =CT11*(1+CU24) -> 2951.8568 | CV11: =CU11*(1+CV24) -> 3217.5239 | CW11: =CV11*(1+CW24) -> 3474.9258 | CX11: =CW11*(1+CX24) -> 3718.1706 | CY11: =CX11*(1+CY24) -> 3941.2609 | ... DA11: =CZ11*(1+DA24) -> 4303.8569
B12: Cardiology Ttl | AU12: =SUM(AU8:AU11) -> 1185 | AV12: =SUM(AV8:AV11) -> 965 | AW12: =SUM(AW8:AW11) -> 1201 | AX12: =SUM(AX8:AX11) -> 1158 | AY12: =SUM(AY8:AY11) -> 1248 | AZ12: =SUM(AZ8:AZ11) -> 1409 | BA12: =SUM(BA8:BA11) -> 1342 | BB12: =SUM(BB8:BB11) -> 1423 | ... BT12: =SUM(BT8:BT11) -> 2841 | CK12: =SUM(CK8:CK11) -> 5165 | CL12: =SUM(CL8:CL11) -> 4509 | CM12: =SUM(CM8:CM11) -> 5422 | CN12: =SUM(CN8:CN11) -> 5932 | CO12: =SUM(CO8:CO11) -> 6709 | CP12: =SUM(CP8:CP11) -> 8344 | CQ12: =SUM(BO12:BR12) -> 10486 | CR12: =SUM(CR8:CR11) -> 11209.2 | CS12: =SUM(CS8:CS11) -> 11661.776 | CT12: =SUM(CT8:CT11) -> 12699.403 | CU12: =SUM(CU8:CU11) -> 13602.051 | CV12: =SUM(CV8:CV11) -> 14485.516 | CW12: =SUM(CW8:CW11) -> 15329.857 | CX12: =SUM(CX8:CX11) -> 16114.682 | CY12: =SUM(CY8:CY11) -> 16840.248 | ... DA12: =SUM(DA8:DA11) -> 18134.956
B13: Peripheral Interventions | AU13: 393 | AV13: 340 | AW13: 417 | AX13: =1577-SUM(AU13:AW13) -> 427 | AY13: =433 -> 433 | AZ13: 473 | BA13: 452 | BB13: =1820-SUM(AY13:BA13) -> 462 | BC13: 465 | BD13: 478 | BE13: 479 | BF13: =1899-SUM(BC13:BE13) -> 477 | BG13: 502 | BH13: 535 | BI13: 538 | BJ13: =2109-SUM(BG13:BI13) -> 534 | BK13: 575 | BL13: 590 | BM13: 602 | BN13: =2410-SUM(BK13:BM13) -> 643 | BO13: 657 | BP13: 698 | BQ13: 702 | BR13: 708 | BS13: 749 | BT13: 783 | CK13: 1390 | CL13: =SUM(AU13:AX13) -> 1577 | CM13: =SUM(AY13:BB13) -> 1820 | CN13: =SUM(BC13:BF13) -> 1899 | CO13: =SUM(BG13:BJ13) -> 2109 | CP13: =SUM(BK13:BN13) -> 2410 | CQ13: =SUM(BO13:BR13) -> 2765 | CR13: =CQ13*(1+CR26) -> 3138.275 | CS13: =CR13*(1+CS26) -> 3514.868 | CT13: =CS13*(1+CT26) -> 3919.0778 | CU13: =CT13*(1+CU26) -> 4350.1764 | CV13: =CU13*(1+CV26) -> 4785.194 | CW13: =CV13*(1+CW26) -> 5215.8615 | CX13: =CW13*(1+CX26) -> 5633.1304 | CY13: =CX13*(1+CY26) -> 6027.4495 | ... DA13: =CZ13*(1+DA26) -> 6644.6604
B14: Cardiovascular Ttl Revenues | AU14: =SUM(AU12:AU13) -> 1578 | AV14: =SUM(AV12:AV13) -> 1305 | AW14: =SUM(AW12:AW13) -> 1618 | AX14: =SUM(AX12:AX13) -> 1585 | AY14: =SUM(AY12:AY13) -> 1681 | AZ14: =SUM(AZ12:AZ13) -> 1882 | BA14: =SUM(BA12:BA13) -> 1794 | BB14: =SUM(BB12:BB13) -> 1885 | ... BT14: =SUM(BT12:BT13) -> 3624 | CK14: =CK12+CK13 -> 6555 | CL14: =CL12+CL13 -> 6086 | CM14: =CM12+CM13 -> 7242 | CN14: =CN12+CN13 -> 7831 | CO14: =CO12+CO13 -> 8818 | CP14: =CP12+CP13 -> 10754 | CQ14: =SUM(BO14:BR14) -> 13251 | CR14: =CR12+SUM(CR13:CR13) -> 14347.475 | CS14: =CS12+SUM(CS13:CS13) -> 15176.644 | CT14: =CT12+SUM(CT13:CT13) -> 16618.481 | CU14: =CU12+SUM(CU13:CU13) -> 17952.227 | CV14: =CV12+SUM(CV13:CV13) -> 19270.71 | CW14: =CW12+SUM(CW13:CW13) -> 20545.718 | CX14: =CX12+SUM(CX13:CX13) -> 21747.813 | CY14: =CY12+SUM(CY13:CY13) -> 22867.698 | ... DA14: =DA12+SUM(DA13:DA13) -> 24779.616
B15: Ttl Revenues | AU15: =AU7+AU14 -> 2543 | AV15: =AV7+AV14 -> 2003 | AW15: =AW7+AW14 -> 2659 | AX15: =AX7+AX14 -> 2708 | AY15: =AY7+AY14+13 -> 2752 | AZ15: =AZ7+AZ14 -> 3077 | BA15: =BA7+BA14 -> 2932 | BB15: =BB7+BB14 -> 3127 | BC15: =BC7+BC14 -> 3026 | BD15: =BD7+BD14 -> 3244 | BE15: =BE7+BE14 -> 3170 | BF15: =BF7+BF14-60 -> 3242 | BG15: =BG7+BG14 -> 3389 | BH15: =BH7+BH14 -> 3599 | BI15: =BI7+BI14 -> 3527 | BJ15: =BJ7+BJ14 -> 3725 | BK15: =BK7+BK14 -> 3857 | BL15: =BL7+BL14 -> 4120 | BM15: =BM7+BM14 -> 4209 | BN15: =BN7+BN14 -> 4561 | ... BT15: =BT7+BT14 -> 5442 | CK15: =CK7+CK14 -> 10735 | CL15: =CL7+CL14 -> 9913 | CM15: =CM7+CM14+13 -> 11888 | CN15: =CN7+CN14-60 -> 12682 | CO15: =CO7+CO14 -> 14240 | CP15: =CP7+CP14 -> 16747 | CQ15: =SUM(BO15:BR15) -> 20075 | CR15: =CR7+CR14 -> 21697.69 | CS15: =CS7+CS14 -> 23010.07 | CT15: =CT7+CT14 -> 25000.25 | CU15: =CU7+CU14 -> 26902.536 | CV15: =CV7+CV14 -> 28739.535 | CW15: =CW7+CW14 -> 30498.693 | CX15: =CX7+CX14 -> 32163.466 | CY15: =CY7+CY14 -> 33713.768 | ... DA15: =DA7+DA14 -> 36399.628
B17: Endoscopy Growth Y/y | AY17: =AY4/AU4-1 -> 0.12895928 | AZ17: =AZ4/AV4-1 -> 0.58333333 | BA17: =BA4/AW4-1 -> 0.12210526 | BB17: =BB4/AX4-1 -> 0.083495146 | BC17: =BC4/AY4-1 -> 0.066132265 | BD17: =BD4/AZ4-1 -> 0.01814882 | BE17: =BE4/BA4-1 -> 0.048780488 | BF17: =BF4/BB4-1 -> 0.019713262 | ... BT17: =BT4/BP4-1 -> 0.075983718 | CL17: =CL4/CK4-1 -> -0.060190074 | CM17: =CM4/CL4-1 -> 0.20280899 | CN17: =CN4/CM4-1 -> 0.037365717 | CO17: =CO4/CN4-1 -> 0.11751463 | CP17: =CP4/CO4-1 -> 0.082594682 | CQ17: =CQ4/CP4-1 -> 0.08559732 | CR17: 0.095 | CS17: 0.065 | CT17: 0.052 | CU17: 0.042 | CV17: 0.04 | CW17: 0.037 | CX17: 0.035 | CY17: 0.032 | CZ17: 0.031 | DA17: 0.03
B18: Urology Growth Y/y | AY18: =AY5/AU5-1 -> 0.087349398 | AZ18: =AZ5/AV5-1 -> 0.74122807 | BA18: =BA5/AW5-1 -> 0.097142857 | BB18: =BB5/AX5-1 -> 0.17287234 | BC18: =BC5/AY5-1 -> 0.14404432 | BD18: =BD5/AZ5-1 -> 0.13350126 | BE18: =BE5/BA5-1 -> 0.12760417 | BF18: =BF5/BB5-1 -> 0.081632653 | ... BT18: =BT5/BP5-1 -> 0.01183432 | CL18: =CL5/CK5-1 -> -0.089879689 | CM18: =CM5/CL5-1 -> 0.23094868 | CN18: =CN5/CM5-1 -> 0.12002527 | CO18: =CO5/CN5-1 -> 0.10772702 | CP18: =CP5/CO5-1 -> 0.12016293 | CQ18: =CQ5/CP5-1 -> 0.23090909 | CR18: 0.03 | CS18: 0.04 | CT18: 0.07 | CU18: 0.08 | CV18: 0.06 | CW18: 0.05 | CX18: 0.045 | CY18: 0.04 | CZ18: 0.035 | DA18: 0.0325
B19: Neuro Growth Y/y | AY19: =AY6/AU6-1 -> 0.036649215 | AZ19: =AZ6/AV6-1 -> 1.0245902 | BA19: =BA6/AW6-1 -> 0.023148148 | BB19: =BB6/AX6-1 -> 0.047413793 | BC19: =BC6/AY6-1 -> 0.055555556 | BD19: =BD6/AZ6-1 -> -0.036437247 | BE19: =BE6/BA6-1 -> 0 | BF19: =BF6/BB6-1 -> 0.024691358 | ... BT19: =BT6/BP6-1 -> 0.12541254 | CL19: =CL6/CK6-1 -> -0.12829324 | CM19: =CM6/CL6-1 -> 0.19448095 | CN19: =CN6/CM6-1 -> 0.0088008801 | CO19: =CO6/CN6-1 -> 0.06434024 | CP19: =CP6/CO6-1 -> 0.13319672 | CQ19: =CQ6/CP6-1 -> 0.084086799 | CR19: 0.14 | CS19: 0.12 | CT19: 0.11 | CU19: 0.1 | CV19: 0.09 | CW19: 0.08 | CX19: 0.07 | CY19: 0.06 | CZ19: 0.05 | DA19: 0.04
B20: MedSurg Growth Y/y | AY20: =AY7/AU7-1 -> 0.096373057 | AZ20: =AZ7/AV7-1 -> 0.71203438 | BA20: =BA7/AW7-1 -> 0.093179635 | BB20: =BB7/AX7-1 -> 0.10596616 | BC20: =BC7/AY7-1 -> 0.09073724 | BD20: =BD7/AZ7-1 -> 0.045188285 | BE20: =BE7/BA7-1 -> 0.065905097 | BF20: =BF7/BB7-1 -> 0.042673108 | ... BT20: =BT7/BP7-1 -> 0.059440559 | CL20: =CL7/CK7-1 -> -0.084449761 | CM20: =CM7/CL7-1 -> 0.21060883 | CN20: =CN7/CM7-1 -> 0.060004317 | CO20: =CO7/CN7-1 -> 0.10405213 | CP20: =CP7/CO7-1 -> 0.10531169 | CQ20: =CQ7/CP7-1 -> 0.13866177 | CR20: =CR7/CQ7-1 -> 0.077112397 | CS20: =CS7/CR7-1 -> 0.065740972 | ... DA20: =DA7/CZ7-1 -> 0.033263135
B21: Interventional Growth Y/y | AY21: =AY8/AU8-1 -> -0.16903633 | AZ21: =AZ8/AV8-1 -> 0.15959596 | BA21: =BA8/AW8-1 -> -0.088737201 | BB21: =BB8/AX8-1 -> -0.017094017 | BC21: =BC8/AY8-1 -> 0.034220532 | BD21: =BD8/AZ8-1 -> 0 | BE21: =BE8/BA8-1 -> 0.028089888 | BF21: =BF8/BB8-1 -> -0.024347826 | ... BT21: =BT8/BP8-1 -> 0.13953488 | CL21: =CL8/CK8-1 -> -0.18359375 | CM21: =CM8/CL8-1 -> -0.039147455 | CN21: =CN8/CM8-1 -> 0.008601177 | CO21: =CO8/CN8-1 -> 0.084829443 | CP21: =CP8/CO8-1 -> 0.094331816 | CQ21: =CQ8/CP8-1 -> 0.075992439 | CR21: 0.125 | CS21: 0.08 | CT21: 0.07 | CU21: 0.05 | CV21: 0.045 | CW21: 0.04 | CX21: 0.035 | CY21: 0.03 | CZ21: 0.025 | DA21: 0.0225
B22: Watchman Growth Y/y | AY22: =AY9/AU9-1 -> 3.1463415 | AZ22: =AZ9/AV9-1 -> 2.1764706 | BA22: =BA9/AW9-1 -> 1.8378378 | BB22: =BB9/AX9-1 -> 5.4722222 | BC22: =BC9/AY9-1 -> 0.32941176 | BD22: =BD9/AZ9-1 -> 0.15740741 | BE22: =BE9/BA9-1 -> 0.24761905 | BF22: =BF9/BB9-1 -> 0.20600858 | ... BT22: =BT9/BP9-1 -> 0.043209877 | CL22: =CL9/CK9-1 -> 1.7037037 | CM22: =CM9/CL9-1 -> 2.7853881 | CN22: =CN9/CM9-1 -> 0.2291918 | CO22: =CO9/CN9-1 -> 0.25024534 | CP22: =CP9/CO9-1 -> 0.1899529 | CQ22: =CQ9/CP9-1 -> 0.29551451 | CR22: 0.14 | CS22: 0.09 | CT22: 0.15 | CU22: 0.12 | CV22: 0.115 | CW22: 0.1 | CX22: 0.085 | CY22: 0.075 | CZ22: 0.07 | DA22: 0.065
B23: Rhythm Growth Y/y | AY23: =AY10/AU10-1 -> 0.073226545 | AZ23: =AZ10/AV10-1 -> 0.49287749 | BA23: =BA10/AW10-1 -> 0.10107527 | BB23: =BB10/AX10-1 -> 0.13968958 | BC23: =BC10/AY10-1 -> 0.10660981 | BD23: =BD10/AZ10-1 -> 0.032442748 | BE23: =BE10/BA10-1 -> 0.013671875 | BF23: =BF10/BB10-1 -> 0.013618677 | ... BT23: =BT10/BP10-1 -> -0.0084745763 | CL23: =CL10/CK10-1 -> -0.12119649 | CM23: =CM10/CL10-1 -> 0.18485915 | CN23: =CN10/CM10-1 -> 0.040118871 | CO23: =CO10/CN10-1 -> 0.056190476 | CP23: =CP10/CO10-1 -> 0.027502254 | CQ23: =CQ10/CP10-1 -> 0.032470382 | CR23: 0.35 | CS23: 0.08 | CT23: 0.03 | CU23: 0.025 | CV23: 0.0225 | CW23: 0.02 | CX23: 0.0175 | CY23: 0.015 | CZ23: 0.0125 | DA23: 0.01
B24: Electrophysiology Growth Y/y | AY24: =AY11/AU11-1 -> 0.12162162 | AZ24: =AZ11/AV11-1 -> 0.8627451 | BA24: =BA11/AW11-1 -> 0.13157895 | BB24: =BB11/AX11-1 -> 0.1744186 | BC24: =BC11/AY11-1 -> 0.42168675 | BD24: =BD11/AZ11-1 -> 0.6 | BE24: =BE11/BA11-1 -> 0.72093023 | BF24: =BF11/BB11-1 -> 0.65346535 | ... BT24: =BT11/BP11-1 -> 0.09047619 | CL24: =CL11/CK11-1 -> -0.12765957 | CM24: =CM11/CL11-1 -> 0.271777 | CN24: =CN11/CM11-1 -> 0.60273973 | CO24: =CO11/CN11-1 -> 0.36752137 | CP24: =CP11/CO11-1 -> 1.38 | CQ24: =CQ11/CP11-1 -> 0.74527311 | CR24: -0.22 | CS24: -0.1 | CT24: 0.14 | CU24: 0.11 | CV24: 0.09 | CW24: 0.08 | CX24: 0.07 | CY24: 0.06 | CZ24: 0.05 | DA24: 0.04
B25: Cardiology Growth Y/y | AY25: =AY12/AU12-1 -> 0.053164557 | AZ25: =AZ12/AV12-1 -> 0.46010363 | BA25: =BA12/AW12-1 -> 0.11740216 | BB25: =BB12/AX12-1 -> 0.22884283 | BC25: =BC12/AY12-1 -> 0.12740385 | BD25: =BD12/AZ12-1 -> 0.076650106 | BE25: =BE12/BA12-1 -> 0.10134128 | BF25: =BF12/BB12-1 -> 0.075193254 | ... BT25: =BT12/BP12-1 -> 0.073290518 | CL25: =CL12/CK12-1 -> -0.12700871 | CM25: =CM12/CL12-1 -> 0.20248392 | CN25: =CN12/CM12-1 -> 0.094061232 | CO25: =CO12/CN12-1 -> 0.13098449 | CP25: =CP12/CO12-1 -> 0.24370249 | CQ25: =CQ12/CP12-1 -> 0.25671141 | CR25: =CR13/CQ13-1 -> 0.135 | CS25: =CS13/CR13-1 -> 0.12 | CT25: =CT13/CS13-1 -> 0.115 | CU25: =CU13/CT13-1 -> 0.11 | CV25: =CV13/CU13-1 -> 0.1 | CW25: =CW13/CV13-1 -> 0.09 | CX25: =CX13/CW13-1 -> 0.08 | CY25: =CY13/CX13-1 -> 0.07 | ... DA25: =DA13/CZ13-1 -> 0.04
B26: Peripheral Growth Y/y | AY26: =AY13/AU13-1 -> 0.10178117 | AZ26: =AZ13/AV13-1 -> 0.39117647 | BA26: =BA13/AW13-1 -> 0.083932854 | BB26: =BB13/AX13-1 -> 0.081967213 | BC26: =BC13/AY13-1 -> 0.073903002 | BD26: =BD13/AZ13-1 -> 0.010570825 | BE26: =BE13/BA13-1 -> 0.059734513 | BF26: =BF13/BB13-1 -> 0.032467532 | ... BT26: =BT13/BP13-1 -> 0.1217765 | CL26: =CL13/CK13-1 -> 0.13453237 | CM26: =CM13/CL13-1 -> 0.15409004 | CN26: =CN13/CM13-1 -> 0.043406593 | CO26: =CO13/CN13-1 -> 0.11058452 | CP26: =CP13/CO13-1 -> 0.14272167 | CQ26: =CQ13/CP13-1 -> 0.1473029 | CR26: 0.135 | CS26: 0.12 | CT26: 0.115 | CU26: 0.11 | CV26: 0.1 | CW26: 0.09 | CX26: 0.08 | CY26: 0.07 | CZ26: 0.06 | DA26: 0.04
B27: Cardiovascular Y/y | AY27: =AY14/AU14-1 -> 0.065272497 | AZ27: =AZ14/AV14-1 -> 0.44214559 | BA27: =BA14/AW14-1 -> 0.10877627 | BB27: =BB14/AX14-1 -> 0.18927445 | BC27: =BC14/AY14-1 -> 0.11362284 | BD27: =BD14/AZ14-1 -> 0.060042508 | BE27: =BE14/BA14-1 -> 0.090858417 | BF27: =BF14/BB14-1 -> 0.064721485 | ... BT27: =BT14/BP14-1 -> 0.083408072 | CL27: =CL14/CK14-1 -> -0.071548436 | CM27: =CM14/CL14-1 -> 0.18994413 | CN27: =CN14/CM14-1 -> 0.081331124 | CO27: =CO14/CN14-1 -> 0.12603754 | CP27: =CP14/CO14-1 -> 0.21955092 | CQ27: =CQ14/CP14-1 -> 0.23219267 | CR27: =CR14/CQ14-1 -> 0.082746585 | CS27: =CS14/CR14-1 -> 0.057792009 | ... DA27: =DA14/CZ14-1 -> 0.036696955
B28: Ttl Revenue Growth Y/y | AY28: =AY15/AU15-1 -> 0.082186394 | AZ28: =AZ15/AV15-1 -> 0.53619571 | BA28: =BA15/AW15-1 -> 0.10267018 | BB28: =BB15/AX15-1 -> 0.15472674 | BC28: =BC15/AY15-1 -> 0.099563953 | BD28: =BD15/AZ15-1 -> 0.054273643 | BE28: =BE15/BA15-1 -> 0.081173261 | BF28: =BF15/BB15-1 -> 0.036776463 | ... BT28: =BT15/BP15-1 -> 0.075281565 | CL28: =CL15/CK15-1 -> -0.076571961 | CM28: =CM15/CL15-1 -> 0.19923333 | CN28: =CN15/CM15-1 -> 0.06679004 | CO28: =CO15/CN15-1 -> 0.12285129 | CP28: =CP15/CO15-1 -> 0.17605337 | CQ28: =CQ15/CP15-1 -> 0.19872216 | CR28: =CR15/CQ15-1 -> 0.080831382 | CS28: =CS15/CR15-1 -> 0.060484765 | ... DA28: =DA15/CZ15-1 -> 0.035598284
B30: MedSurg % of Ttl Revenues | AU30: =AU7/AU15 -> 0.37947306 | AV30: =AV7/AV15 -> 0.34847728 | AW30: =AW7/AW15 -> 0.39150056 | AX30: =AX7/AX15 -> 0.41469719 | AY30: =AY7/AY15 -> 0.38444767 | AZ30: =AZ7/AZ15 -> 0.38836529 | BA30: =BA7/BA15 -> 0.38813097 | BB30: =BB7/BB15 -> 0.3971858 | ... BT30: =BT7/BT15 -> 0.33406836 | CK30: =CK7/CK15 -> 0.38938053 | CL30: =CL7/CL15 -> 0.38605871 | CM30: =CM7/CM15 -> 0.38972073 | CN30: =CN7/CN15 -> 0.38724176 | CO30: =CO7/CO15 -> 0.38075843 | CP30: =CP7/CP15 -> 0.35785514 | CQ30: =CQ7/CQ15 -> 0.33992528 | CR30: =CR7/CR15 -> 0.33875565 | ... DA30: =DA7/DA15 -> 0.31923435
B31: Cardiovasc % of Ttl Revenues | AU31: =AU14/AU15 -> 0.62052694 | AV31: =AV14/AV15 -> 0.65152272 | AW31: =AW14/AW15 -> 0.60849944 | AX31: =AX14/AX15 -> 0.58530281 | AY31: =AY14/AY15 -> 0.61082849 | AZ31: =AZ14/AZ15 -> 0.61163471 | BA31: =BA14/BA15 -> 0.61186903 | BB31: =BB14/BB15 -> 0.6028142 | ... BT31: =BT14/BT15 -> 0.66593164 | CK31: =CK14/CK15 -> 0.61061947 | CL31: =CL14/CL15 -> 0.61394129 | CM31: =CM14/CM15 -> 0.60918573 | CN31: =CN14/CN15 -> 0.61748935 | CO31: =CO14/CO15 -> 0.61924157 | CP31: =CP14/CP15 -> 0.64214486 | CQ31: =CQ14/CQ15 -> 0.66007472 | CR31: =CR14/CR15 -> 0.66124435 | ... DA31: =DA14/DA15 -> 0.68076565
B33: U.S. Revenues | AU33: 1452 | AV33: 1058 | AW33: 1496 | AX33: =5508-SUM(AU33:AW33) -> 1502 | AY33: 1577 | AZ33: 1800 | BA33: 1726 | BB33: =6901-SUM(AY33:BA33) -> 1798 | BC33: 1778 | BD33: 1934 | BE33: 1934 | BF33: =7632-SUM(BC33:BE33) -> 1986 | BG33: 2003 | BH33: 2110 | BI33: 2099 | BJ33: =8425-SUM(BG33:BI33) -> 2213 | BK33: 2258 | BL33: 2466 | BM33: 2593 | BN33: =10210-SUM(BK33:BM33) -> 2893 | BO33: 2960 | BP33: 3224 | BQ33: 3294 | BR33: 3385 | BS33: 3284 | BT33: 3426 | CK33: 6097 | CL33: =SUM(AU33:AX33) -> 5508 | CM33: =SUM(AY33:BB33) -> 6901 | CN33: =SUM(BC33:BF33) -> 7632 | CO33: =SUM(BG33:BJ33) -> 8425 | CP33: =SUM(BK33:BN33) -> 10210 | CQ33: =SUM(BO33:BR33) -> 12863
B34: Euro, Mid. East, Afr | AU34: 552 | AV34: 416 | AW34: 540 | AX34: =2097-SUM(AU34:AW34) -> 589 | AY34: 604 | AZ34: 662 | BA34: 590 | BB34: =2518-SUM(AY34:BA34) -> 662 | BC34: 624 | BD34: 660 | BE34: 585 | BF34: =2526-SUM(BC34:BE34) -> 657 | BG34: 712 | BH34: 723 | BI34: 671 | BJ34: =2856-SUM(BG34:BI34) -> 750 | BK34: 803 | BL34: 822 | BM34: 773 | BN34: =3228-SUM(BK34:BM34) -> 830 | BO34: 846 | BP34: 878 | BQ34: 793 | BR34: 933 | BS34: 932 | BT34: 932 | CK34: 2264 | CL34: =SUM(AU34:AX34) -> 2097 | CM34: =SUM(AY34:BB34) -> 2518 | CN34: =SUM(BC34:BF34) -> 2526 | CO34: =SUM(BG34:BJ34) -> 2856 | CP34: =SUM(BK34:BN34) -> 3228 | CQ34: =SUM(BO34:BR34) -> 3450
B35: A-Pac | AU35: 409 | AV35: 410 | AW35: 472 | AX35: =1781-SUM(AU35:AW35) -> 490 | AY35: 473 | AZ35: 520 | BA35: 517 | BB35: =2070-SUM(AY35:BA35) -> 560 | BC35: 517 | BD35: 530 | BE35: 532 | BF35: =2116-SUM(BC35:BE35) -> 537 | BG35: 548 | BH35: 626 | BI35: 611 | BJ35: =2400-SUM(BG35:BI35) -> 615 | BK35: 647 | BL35: 670 | BM35: 684 | BN35: =2686-SUM(BK35:BM35) -> 685 | BO35: 701 | BP35: 790 | BQ35: 803 | BR35: 789 | BS35: 803 | BT35: 878 | CK35: 1898 | CL35: =SUM(AU35:AX35) -> 1781 | CM35: =SUM(AY35:BB35) -> 2070 | CN35: =SUM(BC35:BF35) -> 2116 | CO35: =SUM(BG35:BJ35) -> 2400 | CP35: =SUM(BK35:BN35) -> 2686 | CQ35: =SUM(BO35:BR35) -> 3083
B36: Lat Am + Canada | AU36: 89 | AV36: 51 | AW36: 77 | AX36: =307-SUM(AU36:AW36) -> 90 | AY36: 85 | AZ36: 95 | BA36: 99 | BB36: =386-SUM(AY36:BA36) -> 107 | BC36: 107 | BD36: 120 | BE36: 119 | BF36: =469-SUM(BC36:BE36) -> 123 | BG36: 126 | BH36: 140 | BI36: 146 | BJ36: =559-SUM(BG36:BI36) -> 147 | BK36: 149 | BL36: 162 | BM36: 159 | BN36: =623-SUM(BK36:BM36) -> 153 | BO36: 156 | BP36: 169 | BQ36: 175 | BR36: 179 | BS36: 185 | BT36: 206 | CK36: 395 | CL36: =SUM(AU36:AX36) -> 307 | CM36: =SUM(AY36:BB36) -> 386 | CN36: =SUM(BC36:BF36) -> 469 | CO36: =SUM(BG36:BJ36) -> 559 | CP36: =SUM(BK36:BN36) -> 623 | CQ36: =SUM(BO36:BR36) -> 679
