Workbook

Sheet Main
B2: DIS
B3: Price | C3: 106 | D3: 2/20/26
B4: SO | C4: 1771.519 | D4: Q4'25
B5: MC | C5: =C3*C4 -> 187781.01
B6: Cash | C6: 5678 | D6: Q4'25
B7: Debt | C7: =35821+10819 -> 46640 | D7: Q4'25
B8: EV | C8: =C5-C6+C7 -> 228743.01
B10: The Walt Disney Company (DIS)
B12: Founder(s): Walt Disney & Roy Disney | G12: Registered Exchange: NYSE | N12: Resources:
B13: Founded: October 16, 1923 | G13: Address: 500 South Buena Vista Street Burbank, CA 91521 U.S. | N13: SEC filings | Q13: https://www.sec.gov/edgar/browse/?CIK=1744489&owner=exclude
B14: Headquarters: Burbank, CA | G14: Investor Relations Contact: | N14: Company Homepage | Q14: https://www.disney.com/
B15: Current CEO: Josh D'Amaro | G15: Investors Relation Department | N15: Company Homepage | Q15: https://thewaltdisneycompany.com/
B16: Employees: 231,000 | G16: Phone: | H16: (818) 560 - 1000 | J16: Email: | O16: Company IR Page | R16: https://investors.thewaltdisneycompany.com/
B17: Industry: Entertainment | N17: Earnings Calls | Q17: https://seekingalpha.com/symbol/DIS/earnings/transcripts
B18: Sector: Communication Services | N18: Equity Analysis | Q18: https://stockanalysis.com/stocks/dis/company/
B19: IPO: Nov 12th, 1957 | N19: MacroTrends | Q19: https://www.macrotrends.net/stocks/charts/DIS/disney/net-income
B20: Fiscal Year: [October - September] | N20: ROIC, WACC | Q20: https://www.gurufocus.com/term/wacc/DIS
N21: Godel Terminal | Q21: https://app.godelterminal.com/
A22: Company Overview:
B23: The Walt Disney Company operates as an entertainment company in Americas, Europe, and the Asia Pacific
C24: It operates in three segments: Entertainment (film/TV and streaming), Sports (ESPN), and Experiences (parks, resorts, cruise, and consumer products), with Disney+ as the core of its direct‑to‑consumer infrastructure strategy and Parks as its economic/cashflow engine
C25: Entertainment Segment | F25: Linear Networks: Domestic and international channels including ABC, Disney Channel, FX, Freeform, and National Geographic
F26: Direct-to-Consumer (DTC): Streaming services Disney+, Disney+ Hotstar, Hulu, and Star+
F27: Content Sales/Licensing and Other: Theatrical distribution of films (Disney, Pixar, Marvel, Lucasfilm, 20th Century Studios), licensing to third‑party TV and SVOD platforms, home entertainment, music, and production/post‑production services via Industrial Light & Magic and Skywalker Sound
C28: Sports Segment (ESPN) | F28: Domestic and international ESPN branded networks (ESPN, ESPN2, ESPNU, SEC Network, etc.), ESPN+ streaming, and sports content on Hulu
G29: ESPN is being repositioned around a long‑planned standalone ESPN streaming app, with bundling alongside Disney+ and Hulu to anchor the sports piece of the DTC portfolio
C30: Disney+ and Streaming: | F30: Disney+ sits at the center of the company’s effort to pivot from linear TV to subscription streaming
G31: Disney executives have put a great deal of time, effort, and capital into this segment in hopes of developing it into the underpinning for The Company's content distrubution
G32: The strategic objective: reach sustainable profitability in streaming while maintaining scale, shifting investor focus from net adds to ARPU and engagement
G33: Management has already signaled it will de‑emphasize subscriber numbers and instead track profitability and engagement, similar to Netflix
F34: The Company is focuesed on wider penetration with Disney+ and subsidiary distributors … There is a plan to consolidate streaming platforms (Disney+, ESPN, Hulu) into a package offering … They literally just recreated cable packages under new management (No more Dish or DirectTV)
C35: Experiences Segment: | F35: Disney’s Experiences segment is The Company’s money printing, economic powerhouse ... Generates the majority of The Firm's operating income on the financial statements … milking Disney adults is the real business driver
G36: Domestic parks in California and Florida … International parks in Paris, Hong Kong, Shanghai, and a specialized deal in Tokoyo
C37: Entertainment is ~45% of The Company's revenues, Sports is ~35% of The Company's revenues, Entertainment is ~20% of The Company's revenues
B38: The Company was founded in 1923 as the Disney Brothers Cartoon Studio; the modern company traces its start to an October 16, 1923 distribution deal for the Alice Comedies
C39: Over the decades, Disney expanded from animation into feature films, TV, consumer products, and theme parks (Disneyland 1955; Walt Disney World 1971), and later into cable networks (ABC/ESPN), studios (Pixar, Marvel, Lucasfilm, 21st Century Fox assets), and streaming
C40: Bob Iger stepped down as CEO of The Company on March 18th, 2026
A42: Business Segments and Geographical Info:

Sheet Model
B1: [Use for Graphing] | AA1: Q1 2020 | AE1: Q1 2021 | AI1: Q1 2022 | AM1: Q1 2023 | AQ1: Q1 2024 | AU1: Q1 2025 | AY1: Q1 2026
B2: Quarterly
B3: Revenues | C3: {="Q"&MOD(_xlfn.SEQUENCE(1,52)-1,4)+1&" "&(2014+INT((_xlfn.SEQUENCE(1,52)-1)/4))} -> Q1 2014 | D3: Q2 2014 | E3: Q3 2014 | F3: Q4 2014 | G3: Q1 2015 | H3: Q2 2015 | I3: Q3 2015 | J3: Q4 2015 | K3: Q1 2016 | L3: Q2 2016 | M3: Q3 2016 | N3: Q4 2016 | O3: Q1 2017 | P3: Q2 2017 | Q3: Q3 2017 | R3: Q4 2017 | S3: Q1 2018 | T3: Q2 2018 | U3: Q3 2018 | V3: Q4 2018 | W3: Q1 2019 | X3: Q2 2019 | Y3: Q3 2019 | Z3: Q4 2019 | AA3: Q1 2020 | AB3: Q2 2020 | AC3: Q3 2020 | AD3: Q4 2020 | AE3: Q1 2021 | AF3: Q2 2021 | AG3: Q3 2021 | AH3: Q4 2021 | AI3: Q1 2022 | AJ3: Q2 2022 | AK3: Q3 2022 | AL3: Q4 2022 | AM3: Q1 2023 | AN3: Q2 2023 | AO3: Q3 2023 | AP3: Q4 2023 | AQ3: Q1 2024 | AR3: Q2 2024 | AS3: Q3 2024 | AT3: Q4 2024 | AU3: Q1 2025 | AV3: Q2 2025 | AW3: Q3 2025 | AX3: Q4 2025 | AY3: Q1 2026 | AZ3: Q2 2026 | BA3: Q3 2026 | BB3: Q4 2026 | BG3: 2014 | BH3: =BG3+1 -> 2015 | BI3: =BH3+1 -> 2016 | BJ3: =BI3+1 -> 2017 | BK3: =BJ3+1 -> 2018 | BL3: =BK3+1 -> 2019 | BM3: =BL3+1 -> 2020 | BN3: =BM3+1 -> 2021 | BO3: =BN3+1 -> 2022 | ... DZ3: =DY3+1 -> 2085
B4: Entertainment | AQ4: 9981 | AR4: 9796 | AS4: 10580 | AT4: =41186-SUM(AQ4:AS4) -> 10829 | AU4: 10872 | AV4: 10682 | AW4: 10704 | AX4: =42466-SUM(AU4:AW4) -> 10208 | AY4: 11609 | BQ4: =SUM(AQ4:AT4) -> 41186 | BR4: =SUM(AU4:AX4) -> 42466 | BS4: =BR4*(1+BS9) -> 44164.64 | BT4: =BS4*(1+BT9) -> 46372.872 | BU4: =BT4*(1+BU9) -> 48227.787 | BV4: =BU4*(1+BV9) -> 49674.62 | BW4: =BV4*(1+BW9) -> 51040.673 | BX4: =BW4*(1+BX9) -> 52316.689 | BY4: =BX4*(1+BY9) -> 53493.815 | BZ4: =BY4*(1+BZ9) -> 54563.691 | ... CB4: =CA4*(1+CB9) -> 56351.334
B5: Sports | AQ5: 4835 | AR5: 4312 | AS5: 4558 | AT5: =17619-SUM(AQ5:AS5) -> 3914 | AU5: 4850 | AV5: 4534 | AW5: 4308 | AX5: =17672-SUM(AU5:AW5) -> 3980 | AY5: 4909 | BQ5: =SUM(AQ5:AT5) -> 17619 | BR5: =SUM(AU5:AX5) -> 17672 | BS5: =BR5*(1+BS10) -> 18555.6 | BT5: =BS5*(1+BT10) -> 19854.492 | BU5: =BT5*(1+BU10) -> 21045.762 | BV5: =BU5*(1+BV10) -> 22413.736 | BW5: =BV5*(1+BW10) -> 23982.698 | BX5: =BW5*(1+BX10) -> 25301.746 | BY5: =BX5*(1+BY10) -> 26566.833 | BZ5: =BY5*(1+BZ10) -> 27762.341 | ... CB5: =CA5*(1+CB10) -> 30099.93
B6: Experiences | AQ6: =9132-399 -> 8733 | AR6: =8393-418 -> 7975 | AS6: =8386-369 -> 8017 | AT6: =34151-1595-SUM(AQ6:AS6) -> 7831 | AU6: =9415-447 -> 8968 | AV6: =8889-484 -> 8405 | AW6: =9086-448 -> 8638 | AX6: =36156-1869-SUM(AU6:AW6) -> 8276 | AY6: =10006-543 -> 9463 | BQ6: =SUM(AQ6:AT6) -> 32556 | BR6: =SUM(AU6:AX6) -> 34287 | BS6: =BR6*(1+BS11) -> 36344.22 | BT6: =BS6*(1+BT11) -> 38161.431 | BU6: =BT6*(1+BU11) -> 38924.66 | BV6: =BU6*(1+BV11) -> 40092.399 | BW6: =BV6*(1+BW11) -> 40493.323 | BX6: =BW6*(1+BX11) -> 42517.99 | BY6: =BX6*(1+BY11) -> 45069.069 | BZ6: =BY6*(1+BZ11) -> 46871.832 | ... CB6: =CA6*(1+CB11) -> 49243.546
B7: Ttl Revenues | AQ7: =SUM(AQ4:AQ6) -> 23549 | AR7: =SUM(AR4:AR6) -> 22083 | AS7: =SUM(AS4:AS6) -> 23155 | AT7: =SUM(AT4:AT6) -> 22574 | AU7: =SUM(AU4:AU6) -> 24690 | AV7: =SUM(AV4:AV6) -> 23621 | AW7: =SUM(AW4:AW6) -> 23650 | AX7: =SUM(AX4:AX6) -> 22464 | AY7: =SUM(AY4:AY6) -> 25981 | BQ7: =SUM(AQ7:AT7) -> 91361 | BR7: =SUM(AU7:AX7) -> 94425 | BS7: =SUM(BS4:BS6) -> 99064.46 | BT7: =SUM(BT4:BT6) -> 104388.8 | BU7: =SUM(BU4:BU6) -> 108198.21 | BV7: =SUM(BV4:BV6) -> 112180.76 | BW7: =SUM(BW4:BW6) -> 115516.69 | BX7: =SUM(BX4:BX6) -> 120136.42 | BY7: =SUM(BY4:BY6) -> 125129.72 | BZ7: =SUM(BZ4:BZ6) -> 129197.86 | ... CB7: =SUM(CB4:CB6) -> 135694.81
B9: Entertainment Growth Y/y | AU9: =AU4/AQ4-1 -> 0.089269612 | AV9: =AV4/AR4-1 -> 0.09044508 | AW9: =AW4/AS4-1 -> 0.011720227 | AX9: =AX4/AT4-1 -> -0.057346015 | AY9: =AY4/AU4-1 -> 0.067788815 | BR9: =BR4/BQ4-1 -> 0.031078522 | BS9: 0.04 | BT9: 0.05 | BU9: 0.04 | BV9: 0.03 | BW9: 0.0275 | BX9: 0.025 | BY9: 0.0225 | BZ9: 0.02 | CA9: 0.0175 | CB9: 0.015
B10: Sports Growth Y/y | AU10: =AU5/AQ5-1 -> 0.0031023785 | AV10: =AV5/AR5-1 -> 0.05148423 | AW10: =AW5/AS5-1 -> -0.054848618 | AX10: =AX5/AT5-1 -> 0.016862545 | AY10: =AY5/AU5-1 -> 0.012164948 | BR10: =BR5/BQ5-1 -> 0.0030081162 | BS10: 0.05 | BT10: 0.07 | BU10: 0.06 | BV10: 0.065 | BW10: 0.07 | BX10: 0.055 | BY10: 0.05 | BZ10: 0.045 | CA10: 0.0425 | CB10: 0.04
B11: Experiences Growth Y/y | AU11: =AU6/AQ6-1 -> 0.026909424 | AV11: =AV6/AR6-1 -> 0.053918495 | AW11: =AW6/AS6-1 -> 0.077460397 | AX11: =AX6/AT6-1 -> 0.056825437 | AY11: =AY6/AU6-1 -> 0.055196253 | BR11: =BR6/BQ6-1 -> 0.053169923 | BS11: 0.06 | BT11: 0.05 | BU11: 0.02 | BV11: 0.03 | BW11: 0.01 | BX11: 0.05 | BY11: 0.06 | BZ11: 0.04 | CA11: 0.03 | CB11: 0.02
B12: Ttl Revenue Growth Y/y | AU12: =AU7/AQ7-1 -> 0.048452164 | AV12: =AV7/AR7-1 -> 0.069646334 | AW12: =AW7/AS7-1 -> 0.021377672 | AX12: =AX7/AT7-1 -> -0.0048728626 | AY12: =AY7/AU7-1 -> 0.052288376 | BR12: =BR7/BQ7-1 -> 0.033537286 | BS12: =BS7/BR7-1 -> 0.04913381 | BT12: =BT7/BS7-1 -> 0.053746167 | BU12: =BU7/BT7-1 -> 0.036492547 | BV12: =BV7/BU7-1 -> 0.036807891 | BW12: =BW7/BV7-1 -> 0.029737164 | BX12: =BX7/BW7-1 -> 0.039991894 | BY12: =BY7/BX7-1 -> 0.041563516 | ... CB12: =CB7/CA7-1 -> 0.02226951
B14: Entertainment % of Ttl Revenues | AQ14: =AQ4/AQ7 -> 0.42383965 | AR14: =AR4/AR7 -> 0.44359915 | AS14: =AS4/AS7 -> 0.45692075 | AT14: =AT4/AT7 -> 0.47971117 | AU14: =AU4/AU7 -> 0.44034022 | AV14: =AV4/AV7 -> 0.45222472 | AW14: =AW4/AW7 -> 0.45260042 | AX14: =AX4/AX7 -> 0.45441595 | AY14: =AY4/AY7 -> 0.44682653 | BQ14: =BQ4/BQ7 -> 0.45080505 | BR14: =BR4/BR7 -> 0.44973259 | BS14: =BS4/BS7 -> 0.4458172 | BT14: =BT4/BT7 -> 0.44423228 | BU14: =BU4/BU7 -> 0.44573554 | BV14: =BV4/BV7 -> 0.44280875 | BW14: =BW4/BW7 -> 0.44184672 | BX14: =BX4/BX7 -> 0.43547733 | ... CB14: =CB4/CB7 -> 0.41527995
B15: Sports % of Ttl Revenues | AQ15: =AQ5/AQ7 -> 0.20531657 | AR15: =AR5/AR7 -> 0.19526332 | AS15: =AS5/AS7 -> 0.19684733 | AT15: =AT5/AT7 -> 0.17338531 | AU15: =AU5/AU7 -> 0.1964358 | AV15: =AV5/AV7 -> 0.19194784 | AW15: =AW5/AW7 -> 0.18215645 | AX15: =AX5/AX7 -> 0.17717236 | AY15: =AY5/AY7 -> 0.18894577 | BQ15: =BQ5/BQ7 -> 0.19285034 | BR15: =BR5/BR7 -> 0.18715383 | BS15: =BS5/BS7 -> 0.18730834 | BT15: =BT5/BT7 -> 0.19019754 | BU15: =BU5/BU7 -> 0.19451118 | BV15: =BV5/BV7 -> 0.19980019 | BW15: =BW5/BW7 -> 0.2076124 | BX15: =BX5/BX7 -> 0.21060845 | ... CB15: =CB5/CB7 -> 0.22182079
B16: Experiences % of Ttl Revenues | AQ16: =AQ6/AQ7 -> 0.37084377 | AR16: =AR6/AR7 -> 0.36113753 | AS16: =AS6/AS7 -> 0.34623192 | AT16: =AT6/AT7 -> 0.34690352 | AU16: =AU6/AU7 -> 0.36322398 | AV16: =AV6/AV7 -> 0.35582744 | AW16: =AW6/AW7 -> 0.36524313 | AX16: =AX6/AX7 -> 0.36841168 | AY16: =AY6/AY7 -> 0.3642277 | BQ16: =BQ6/BQ7 -> 0.35634461 | BR16: =BR6/BR7 -> 0.36311358 | BS16: =BS6/BS7 -> 0.36687446 | BT16: =BT6/BT7 -> 0.36557018 | BU16: =BU6/BU7 -> 0.35975327 | BV16: =BV6/BV7 -> 0.35739106 | BW16: =BW6/BW7 -> 0.35054088 | BX16: =BX6/BX7 -> 0.35391422 | ... CB16: =CB6/CB7 -> 0.36289926
B18: Entertainment | AQ18: 874 | AR18: 781 | AS18: 1201 | AT18: =3923-SUM(AQ18:AS18) -> 1067 | AU18: 1703 | AV18: 1258 | AW18: 1201 | AX18: =4674-SUM(AU18:AW18) -> 512 | AY18: 1100 | BQ18: =SUM(AQ18:AT18) -> 3923 | BR18: =SUM(AU18:AX18) -> 4674 | BS18: =BR18*(1+BS23) -> 5562.06 | BT18: =BS18*(1+BT23) -> 6624.4135 | BU18: =BT18*(1+BU23) -> 7916.1741 | BV18: =BU18*(1+BV23) -> 9467.7442 | BW18: =BV18*(1+BW23) -> 11332.89 | BX18: =BW18*(1+BX23) -> 13599.468 | BY18: =BX18*(1+BY23) -> 16346.56 | BZ18: =BY18*(1+BZ23) -> 19681.259 | ... CB18: =CA18*(1+CB23) -> 28601.395
B19: Sports | AQ19: -103 | AR19: 778 | AS19: 802 | AT19: =2406-SUM(AQ19:AS19) -> 929 | AU19: 247 | AV19: 687 | AW19: 802 | AX19: =2882-SUM(AU19:AW19) -> 1146 | AY19: 191 | BQ19: =SUM(AQ19:AT19) -> 2406 | BR19: =SUM(AU19:AX19) -> 2882 | BS19: =BR19*(1+BS24) -> 3461.282 | BT19: =BS19*(1+BT24) -> 4167.3835 | BU19: =BT19*(1+BU24) -> 5025.8645 | BV19: =BU19*(1+BV24) -> 6071.2444 | BW19: =BV19*(1+BW24) -> 7291.5645 | BX19: =BW19*(1+BX24) -> 8786.3352 | BY19: =BX19*(1+BY24) -> 10609.5 | BZ19: =BY19*(1+BZ24) -> 12837.495 | ... CB19: =CA19*(1+CB24) -> 18842.002
B20: Experiences | AQ20: 3105 | AR20: 2286 | AS20: 2222 | AT20: =9272-SUM(AQ20:AS20) -> 1659 | AU20: 3110 | AV20: 2491 | AW20: 2222 | AX20: =9995-SUM(AU20:AW20) -> 2172 | AY20: 3309 | BQ20: =SUM(AQ20:AT20) -> 9272 | BR20: =SUM(AU20:AX20) -> 9995 | BS20: =BR20*(1+BS25) -> 10794.6 | BT20: =BS20*(1+BT25) -> 11766.114 | BU20: =BT20*(1+BU25) -> 12942.725 | BV20: =BU20*(1+BV25) -> 14301.712 | BW20: =BV20*(1+BW25) -> 15874.9 | BX20: =BW20*(1+BX25) -> 17700.513 | BY20: =BX20*(1+BY25) -> 19780.324 | BZ20: =BY20*(1+BZ25) -> 22153.962 | ... CB20: =CA20*(1+CB25) -> 27789.931
B21: Ttl Operating Income | AQ21: =SUM(AQ18:AQ20) -> 3876 | AR21: =SUM(AR18:AR20) -> 3845 | AS21: =SUM(AS18:AS20) -> 4225 | AT21: =SUM(AT18:AT20) -> 3655 | AU21: =SUM(AU18:AU20) -> 5060 | AV21: =SUM(AV18:AV20) -> 4436 | AW21: =SUM(AW18:AW20) -> 4225 | AX21: =SUM(AX18:AX20) -> 3830 | AY21: =SUM(AY18:AY20) -> 4600 | BQ21: =SUM(AQ21:AT21) -> 15601 | BR21: =SUM(AU21:AX21) -> 17551 | BS21: =SUM(BS18:BS20) -> 19817.942 | BT21: =SUM(BT18:BT20) -> 22557.911 | BU21: =SUM(BU18:BU20) -> 25884.764 | BV21: =SUM(BV18:BV20) -> 29840.7 | BW21: =SUM(BW18:BW20) -> 34499.354 | BX21: =SUM(BX18:BX20) -> 40086.316 | BY21: =SUM(BY18:BY20) -> 46736.384 | BZ21: =SUM(BZ18:BZ20) -> 54672.716 | ... CB21: =SUM(CB18:CB20) -> 75233.328
B23: Entertainment Growth Y/y | AU23: =AU18/AQ18-1 -> 0.94851259 | AV23: =AV18/AR18-1 -> 0.61075544 | AW23: =AW18/AS18-1 -> 0 | AX23: =AX18/AT18-1 -> -0.52014995 | AY23: =AY18/AU18-1 -> -0.35408103 | BR23: =BR18/BQ18-1 -> 0.19143513 | BS23: 0.19 | BT23: 0.191 | BU23: 0.195 | BV23: 0.196 | BW23: 0.197 | BX23: 0.2 | BY23: 0.202 | BZ23: 0.204 | CA23: 0.205 | CB23: 0.206
B24: Sports Growth Y/y | AU24: =AU19/AQ19-1 -> -3.3980583 | AV24: =AV19/AR19-1 -> -0.11696658 | AW24: =AW19/AS19-1 -> 0 | AX24: =AX19/AT19-1 -> 0.2335845 | AY24: =AY19/AU19-1 -> -0.22672065 | BR24: =BR19/BQ19-1 -> 0.19783874 | BS24: 0.201 | BT24: 0.204 | BU24: 0.206 | BV24: 0.208 | BW24: 0.201 | BX24: 0.205 | BY24: 0.2075 | BZ24: 0.21 | CA24: 0.211 | CB24: 0.212
B25: Experiences Growth Y/y | AU25: =AU20/AQ20-1 -> 0.001610306 | AV25: =AV20/AR20-1 -> 0.08967629 | AW25: =AW20/AS20-1 -> 0 | AX25: =AX20/AT20-1 -> 0.30922242 | AY25: =AY20/AU20-1 -> 0.063987138 | BR25: =BR20/BQ20-1 -> 0.077976704 | BS25: 0.08 | BT25: 0.09 | BU25: 0.1 | BV25: 0.105 | BW25: 0.11 | BX25: 0.115 | BY25: 0.1175 | BZ25: 0.12 | CA25: 0.12 | CB25: 0.12
B26: Ttl Operating Income Growth Y/y | AU26: =AU21/AQ21-1 -> 0.30546956 | AV26: =AV21/AR21-1 -> 0.15370611 | AW26: =AW21/AS21-1 -> 0 | AX26: =AX21/AT21-1 -> 0.047879617 | AY26: =AY21/AU21-1 -> -0.090909091 | BR26: =BR21/BQ21-1 -> 0.12499199 | BS26: =BS21/BR21-1 -> 0.12916312 | BT26: =BT21/BS21-1 -> 0.13825699 | BU26: =BU21/BT21-1 -> 0.14748055 | BV26: =BV21/BU21-1 -> 0.15282875 | BW26: =BW21/BV21-1 -> 0.15611745 | BX26: =BX21/BW21-1 -> 0.16194396 | BY26: =BY21/BX21-1 -> 0.1658937 | ... CB26: =CB21/CA21-1 -> 0.17415285
B28: Entertainment % of Operating Income | AQ28: =AQ18/AQ21 -> 0.2254902 | AR28: =AR18/AR21 -> 0.20312094 | AS28: =AS18/AS21 -> 0.28426036 | AT28: =AT18/AT21 -> 0.29192886 | AU28: =AU18/AU21 -> 0.33656126 | AV28: =AV18/AV21 -> 0.28358882 | AW28: =AW18/AW21 -> 0.28426036 | AX28: =AX18/AX21 -> 0.13368146 | AY28: =AY18/AY21 -> 0.23913043 | BQ28: =BQ18/BQ21 -> 0.25145824 | BR28: =BR18/BR21 -> 0.26630961
B29: Sports % of Operating Income | AQ29: =AQ19/AQ21 -> -0.026573787 | AR29: =AR19/AR21 -> 0.2023407 | AS29: =AS19/AS21 -> 0.18982249 | AT29: =AT19/AT21 -> 0.25417237 | AU29: =AU19/AU21 -> 0.048814229 | AV29: =AV19/AV21 -> 0.15486925 | AW29: =AW19/AW21 -> 0.18982249 | AX29: =AX19/AX21 -> 0.29921671 | AY29: =AY19/AY21 -> 0.041521739 | BQ29: =BQ19/BQ21 -> 0.15422088 | BR29: =BR19/BR21 -> 0.16420717
B30: Experiences % of Operating Income | AQ30: =AQ20/AQ21 -> 0.80108359 | AR30: =AR20/AR21 -> 0.59453836 | AS30: =AS20/AS21 -> 0.52591716 | AT30: =AT20/AT21 -> 0.45389877 | AU30: =AU20/AU21 -> 0.61462451 | AV30: =AV20/AV21 -> 0.56154193 | AW30: =AW20/AW21 -> 0.52591716 | AX30: =AX20/AX21 -> 0.56710183 | AY30: =AY20/AY21 -> 0.71934783 | BQ30: =BQ20/BQ21 -> 0.59432088 | BR30: =BR20/BR21 -> 0.56948322
B32: Americas Revenues | AQ32: 18584 | AR32: 17641 | AS32: 18293 | AT32: =72162-SUM(AQ32:AS32) -> 17644 | AU32: 19882 | AV32: 19485 | AW32: 19163 | AX32: =76430-SUM(AU32:AW32) -> 17900 | AY32: 20862 | BQ32: =SUM(AQ32:AT32) -> 72162 | BR32: =SUM(AU32:AX32) -> 76430
B33: Euro Revenues | AQ33: 2610 | AR33: 2281 | AS33: 2572 | AT33: =10279-SUM(AQ33:AS33) -> 2816 | AU33: 2855 | AV33: 2450 | AW33: 2829 | AX33: =11090-SUM(AU33:AW33) -> 2956 | AY33: 3079 | BQ33: =SUM(AQ33:AT33) -> 10279 | BR33: =SUM(AU33:AX33) -> 11090
B34: APac Revenues | AQ34: 2355 | AR34: 2161 | AS34: 2290 | AT34: =8920-SUM(AQ34:AS34) -> 2114 | AU34: 1953 | AV34: 1686 | AW34: 1658 | AX34: =6905-SUM(AU34:AW34) -> 1608 | AY34: 2040 | BQ34: =SUM(AQ34:AT34) -> 8920 | BR34: =SUM(AU34:AX34) -> 6905
B35: Ttl Revenues | AQ35: =SUM(AQ32:AQ34) -> 23549 | AR35: =SUM(AR32:AR34) -> 22083 | AS35: =SUM(AS32:AS34) -> 23155 | AT35: =SUM(AT32:AT34) -> 22574 | AU35: =SUM(AU32:AU34) -> 24690 | AV35: =SUM(AV32:AV34) -> 23621 | AW35: =SUM(AW32:AW34) -> 23650 | AX35: =SUM(AX32:AX34) -> 22464 | AY35: =SUM(AY32:AY34) -> 25981 | BQ35: =SUM(AQ35:AT35) -> 91361 | BR35: =SUM(AU35:AX35) -> 94425
B37: Americas Revenue Growth Y/y | AU37: =AU32/AQ32-1 -> 0.069845028 | AV37: =AV32/AR32-1 -> 0.10452922 | AW37: =AW32/AS32-1 -> 0.047559176 | AX37: =AX32/AT32-1 -> 0.014509182 | AY37: =AY32/AU32-1 -> 0.049290816 | BR37: =BR32/BQ32-1 -> 0.059144702
B38: Euro Revenue Growth Y/y | AU38: =AU33/AQ33-1 -> 0.093869732 | AV38: =AV33/AR33-1 -> 0.074090311 | AW38: =AW33/AS33-1 -> 0.09992224 | AX38: =AX33/AT33-1 -> 0.049715909 | AY38: =AY33/AU33-1 -> 0.078458844 | BR38: =BR33/BQ33-1 -> 0.078898726
B39: APac Revenue Growth Y/y | AU39: =AU34/AQ34-1 -> -0.17070064 | AV39: =AV34/AR34-1 -> -0.21980565 | AW39: =AW34/AS34-1 -> -0.27598253 | AX39: =AX34/AT34-1 -> -0.23935667 | AY39: =AY34/AU34-1 -> 0.044546851 | BR39: =BR34/BQ34-1 -> -0.22589686
B40: Ttl Revenue Growth Y/y | AU40: =AU35/AQ35-1 -> 0.048452164 | AV40: =AV35/AR35-1 -> 0.069646334 | AW40: =AW35/AS35-1 -> 0.021377672 | AX40: =AX35/AT35-1 -> -0.0048728626 | AY40: =AY35/AU35-1 -> 0.052288376 | BR40: =BR35/BQ35-1 -> 0.033537286
B42: U.S. % of Revenues | AQ42: =AQ32/AQ35 -> 0.78916302 | AR42: =AR32/AR35 -> 0.79884979 | AS42: =AS32/AS35 -> 0.79002375 | AT42: =AT32/AT35 -> 0.78160716 | AU42: =AU32/AU35 -> 0.80526529 | AV42: =AV32/AV35 -> 0.82490157 | AW42: =AW32/AW35 -> 0.81027484 | AX42: =AX32/AX35 -> 0.79683048 | AY42: =AY32/AY35 -> 0.8029714 | BQ42: =BQ32/BQ35 -> 0.78985563 | BR42: =BR32/BR35 -> 0.80942547
B43: Euro Revenues % of Revenues | AQ43: =AQ33/AQ35 -> 0.11083273 | AR43: =AR33/AR35 -> 0.10329213 | AS43: =AS33/AS35 -> 0.11107752 | AT43: =AT33/AT35 -> 0.12474528 | AU43: =AU33/AU35 -> 0.11563386 | AV43: =AV33/AV35 -> 0.10372126 | AW43: =AW33/AW35 -> 0.11961945 | AX43: =AX33/AX35 -> 0.13158832 | AY43: =AY33/AY35 -> 0.11850968 | BQ43: =BQ33/BQ35 -> 0.11250971 | BR43: =BR33/BR35 -> 0.11744771
B44: APac Revenues % of Revenues | AQ44: =AQ34/AQ35 -> 0.10000425 | AR44: =AR34/AR35 -> 0.097858081 | AS44: =AS34/AS35 -> 0.098898726 | AT44: =AT34/AT35 -> 0.093647559 | AU44: =AU34/AU35 -> 0.079100851 | AV44: =AV34/AV35 -> 0.071377164 | AW44: =AW34/AW35 -> 0.070105708 | AX44: =AX34/AX35 -> 0.071581197 | AY44: =AY34/AY35 -> 0.078518918 | BQ44: =BQ34/BQ35 -> 0.097634658 | BR44: =BR34/BR35 -> 0.07312682
B46: Revenues | C46: 12309 | D46: 11649 | E46: 12466 | F46: 12389 | G46: 13391 | H46: 12461 | I46: 13101 | J46: 13512 | K46: 15244 | L46: 12969 | M46: 14277 | N46: 13142 | O46: 14784 | P46: 13336 | Q46: 14238 | R46: 12779 | S46: 15351 | T46: 14548 | U46: 15229 | V46: 14306 | W46: 15303 | X46: 14922 | Y46: 20262 | Z46: 19120 | AA46: 20877 | AB46: 18025 | AC46: 11779 | AD46: 14707 | AE46: 16249 | AF46: 15613 | AG46: 17022 | AH46: 18534 | AI46: 21819 | AJ46: 19249 | AK46: 21504 | AL46: 20150 | AM46: 23512 | AN46: 21815 | AO46: 22330 | AP46: 21241 | AQ46: 23549 | AR46: 22083 | AS46: 23155 | AT46: 22574 | AU46: 24690 | AV46: 23621 | AW46: 23650 | AX46: 22464 | AY46: 25981 | BG46: =SUM(C46:F46) -> 48813 | BH46: =SUM(G46:J46) -> 52465 | BI46: =SUM(K46:N46) -> 55632 | BJ46: =SUM(O46:R46) -> 55137 | BK46: =SUM(S46:V46) -> 59434 | BL46: =SUM(W46:Z46) -> 69607 | BM46: =SUM(AA46:AD46) -> 65388 | BN46: =SUM(AE46:AH46) -> 67418 | BO46: =SUM(AI46:AL46) -> 82722 | BP46: =SUM(AM46:AP46) -> 88898 | BQ46: =SUM(AQ46:AT46) -> 91361 | BR46: =SUM(AU46:AX46) -> 94425 | BS46: =BS7 -> 99064.46 | BT46: =BT7 -> 104388.8 | BU46: =BU7 -> 108198.21 | BV46: =BV7 -> 112180.76 | BW46: =BW7 -> 115516.69 | BX46: =BX7 -> 120136.42 | BY46: =BY7 -> 125129.72 | BZ46: =BZ7 -> 129197.86 | ... CB46: =CB7 -> 135694.81
B47: COGS | C47: 7065 | D47: 5972 | E47: 6364 | F47: 7019 | G47: 7656 | H47: 6690 | I47: 6663 | J47: 7355 | K47: 8623 | L47: 6864 | M47: 7201 | N47: 7305 | O47: 8406 | P47: 6969 | Q47: 7717 | R47: 7214 | S47: 8729 | T47: 7541 | U47: 8348 | V47: 8108 | W47: 9001 | X47: 8376 | Y47: 12837 | Z47: 11847 | AA47: 13034 | AB47: 11937 | AC47: 7896 | AD47: 11013 | AE47: 11775 | AF47: 9782 | AG47: 11233 | AH47: 12341 | AI47: 14567 | AJ47: 12594 | AK47: 13682 | AL47: 13558 | AM47: 16386 | AN47: 14616 | AO47: 14471 | AP47: 13728 | AQ47: 15587 | AR47: 14172 | AS47: 14709 | AT47: 14230 | AU47: 15406 | AV47: 14810 | AW47: 14532 | AX47: 14018 | AY47: 16669 | BG47: =SUM(C47:F47) -> 26420 | BH47: =SUM(G47:J47) -> 28364 | BI47: =SUM(K47:N47) -> 29993 | BJ47: =SUM(O47:R47) -> 30306 | BK47: =SUM(S47:V47) -> 32726 | BL47: =SUM(W47:Z47) -> 42061 | BM47: =SUM(AA47:AD47) -> 43880 | BN47: =SUM(AE47:AH47) -> 45131 | BO47: =SUM(AI47:AL47) -> 54401 | BP47: =SUM(AM47:AP47) -> 59201 | BQ47: =SUM(AQ47:AT47) -> 58698 | BR47: =SUM(AU47:AX47) -> 58766 | BS47: =BS46*(1-BS65) -> 61653.397 | BT47: =BT46*(1-BT65) -> 64967.031 | BU47: =BU46*(1-BU65) -> 67337.844 | BV47: =BV46*(1-BV65) -> 69816.408 | BW47: =BW46*(1-BW65) -> 71892.55 | BX47: =BX46*(1-BX65) -> 74767.669 | BY47: =BY46*(1-BY65) -> 77875.276 | BZ47: =BZ46*(1-BZ65) -> 80407.113 | ... CB47: =CB46*(1-CB65) -> 84450.529
B48: GP | C48: =C46-C47 -> 5244 | D48: =D46-D47 -> 5677 | E48: =E46-E47 -> 6102 | F48: =F46-F47 -> 5370 | G48: =G46-G47 -> 5735 | H48: =H46-H47 -> 5771 | I48: =I46-I47 -> 6438 | J48: =J46-J47 -> 6157 | ... AY48: =AY46-AY47 -> 9312 | BG48: =SUM(C48:F48) -> 22393 | BH48: =SUM(G48:J48) -> 24101 | BI48: =SUM(K48:N48) -> 25639 | BJ48: =SUM(O48:R48) -> 24831 | BK48: =SUM(S48:V48) -> 26708 | BL48: =SUM(W48:Z48) -> 27546 | BM48: =SUM(AA48:AD48) -> 21508 | BN48: =SUM(AE48:AH48) -> 22287 | BO48: =SUM(AI48:AL48) -> 28321 | BP48: =SUM(AM48:AP48) -> 29697 | BQ48: =SUM(AQ48:AT48) -> 32663 | BR48: =SUM(AU48:AX48) -> 35659 | BS48: =BS46-BS47 -> 37411.063 | BT48: =BT46-BT47 -> 39421.764 | BU48: =BU46-BU47 -> 40860.364 | BV48: =BV46-BV47 -> 42364.348 | BW48: =BW46-BW47 -> 43624.144 | BX48: =BX46-BX47 -> 45368.756 | BY48: =BY46-BY47 -> 47254.441 | BZ48: =BZ46-BZ47 -> 48790.751 | ... CB48: =CB46-CB47 -> 51244.281
B49: SG&A | C49: 2018 | D49: 2116 | E49: 2047 | F49: 2384 | G49: 1935 | H49: 2081 | I49: 2101 | J49: 2406 | K49: 2025 | L49: 2137 | M49: 2305 | N49: 2287 | O49: 1985 | P49: 1941 | Q49: 2022 | R49: 2228 | S49: 2087 | T49: 2239 | U49: 2213 | V49: 2321 | W49: 2152 | X49: 2330 | Y49: 3368 | Z49: 3699 | AA49: 3709 | AB49: 3393 | AC49: 2455 | AD49: 2812 | AE49: 2917 | AF49: 3113 | AG49: 3168 | AH49: 4319 | AI49: 3787 | AJ49: 3768 | AK49: 4100 | AL49: 4733 | AM49: 3827 | AN49: 3614 | AO49: 3874 | AP49: 4021 | AQ49: 3783 | AR49: 3790 | AS49: 3872 | AT49: 4314 | AU49: 3930 | AV49: 3981 | AW49: 4141 | AX49: 4449 | AY49: 4121 | BG49: =SUM(C49:F49) -> 8565 | BH49: =SUM(G49:J49) -> 8523 | BI49: =SUM(K49:N49) -> 8754 | BJ49: =SUM(O49:R49) -> 8176 | BK49: =SUM(S49:V49) -> 8860 | BL49: =SUM(W49:Z49) -> 11549 | BM49: =SUM(AA49:AD49) -> 12369 | BN49: =SUM(AE49:AH49) -> 13517 | BO49: =SUM(AI49:AL49) -> 16388 | BP49: =SUM(AM49:AP49) -> 15336 | BQ49: =SUM(AQ49:AT49) -> 15759 | BR49: =SUM(AU49:AX49) -> 16501 | BS49: =BS46*BS66 -> 17336.281 | BT49: =BT46*BT66 -> 16702.207 | BU49: =BU46*BU66 -> 17041.218 | BV49: =BV46*BV66 -> 17388.017 | BW49: =BW46*BW66 -> 17789.571 | BX49: =BX46*BX66 -> 18380.873 | BY49: =BY46*BY66 -> 19019.717 | BZ49: =BZ46*BZ66 -> 19508.877 | ... CB49: =CB46*CB66 -> 20354.222
...

Sheet Notes | Quant Analysis
CI1: 0
P2: Employee Scope: | AL2: General Notes/Observations (Updated Q1'26)
AL35: Financial Stmts. Notes/Observations (Updated Q1'26)
P36: Institutional Ownership Snapshot Q1'26 | AL36: Revenues:
AL37: [Godel Snapshot of projected sales]
Q65: Notes: | R65: [X]
R66: [Y]
R67: [Z]
P69: Revenue Breakdown by Segment | AL69: Earnings Scope:
AL70: [Godel Snapshot of projected earnings/EPS + CFFO]
Q101: Notes: | R101: [X]
R102: [Y]
R103: [Z]
P105: Q/q Total Revenues, Net Income, FCF | AL105: Balance Sheet Scope:
AL106: [Godel Snapshot of projected balances (assets, liabilities, equity)]
Q134: Notes: | R134: [X]
R135: [Y]
R136: [Z]
P138: Y/y Total Revenues, Net Income, FCF | AL138: [Equity Preformance Compared to Peers]
AL139: Use Godel CMS command
Q167: Notes: | R167: [X]
R168: [Y]
R169: [Z]
A184: VOO Historical Returns | I184: DIS Historical Returns
A185: 753 Trading Days (From: 2/20/2023 - 2/20/2026) | I185: 753 Trading Days (From: 2/20/2023 - 2/20/2026)
A186: Close | B186: High | C186: Low | D186: Open | E186: Volume | F186: UTC Date | G186: Change | I186: Close | J186: High | K186: Low | L186: Open | M186: Volume | N186: UTC Date | O186: Change
A187: 635.24 | B187: 636.72 | C187: 626.2 | D187: 626.72 | E187: 12959420 | F187: Fri, 06 Feb 2026 00:00:00 GMT | G187: =A187/D187-1 -> 0.013594588 | I187: 108.7 | J187: 108.9551 | K187: 105.37 | L187: 106.13 | M187: 11923379 | N187: Fri, 06 Feb 2026 00:00:00 GMT | O187: =I187/L187-1 -> 0.024215585
A188: 623.1 | B188: 628.75 | C188: 621.5 | D188: 626.24 | E188: 11506981 | F188: Thu, 05 Feb 2026 00:00:00 GMT | G188: =A188/D188-1 -> -0.0050140521 | I188: 104.97 | J188: 108.33 | K188: 104.81 | L188: 107.05 | M188: 11663806 | N188: Thu, 05 Feb 2026 00:00:00 GMT | O188: =I188/L188-1 -> -0.019430173
A189: 630.91 | B189: 635.92 | C189: 627 | D189: 634.93 | E189: 11228241 | F189: Wed, 04 Feb 2026 00:00:00 GMT | G189: =A189/D189-1 -> -0.0063314066 | I189: 107.05 | J189: 108.6 | K189: 103.63 | L189: 104.2 | M189: 19051573 | N189: Wed, 04 Feb 2026 00:00:00 GMT | O189: =I189/L189-1 -> 0.027351248
A190: 634.15 | B190: 641 | C190: 629.105 | D190: 640.33 | E190: 9644195 | F190: Tue, 03 Feb 2026 00:00:00 GMT | G190: =A190/D190-1 -> -0.0096512736 | I190: 104.22 | J190: 104.99 | K190: 102.34 | L190: 104.78 | M190: 24538397 | N190: Tue, 03 Feb 2026 00:00:00 GMT | O190: =I190/L190-1 -> -0.0053445314
A191: 639.68 | B191: 640.96 | C191: 634.07 | D191: 634.18 | E191: 9124531 | F191: Mon, 02 Feb 2026 00:00:00 GMT | G191: =A191/D191-1 -> 0.0086726166 | I191: 104.45 | J191: 108.61 | K191: 103.75 | L191: 104.01 | M191: 37475239 | N191: Mon, 02 Feb 2026 00:00:00 GMT | O191: =I191/L191-1 -> 0.0042303625
A192: 636.22 | B192: 638.45 | C192: 631.95 | D192: 636.25 | E192: 6519552 | F192: Fri, 30 Jan 2026 00:00:00 GMT | G192: =A192/D192-1 -> -4.7151277e-05 | I192: 112.8 | J192: 112.945 | K192: 110.99 | L192: 111.36 | M192: 17790464 | N192: Fri, 30 Jan 2026 00:00:00 GMT | O192: =I192/L192-1 -> 0.012931034
A193: 638.27 | B193: 641.04 | C193: 629.82 | D193: 640.43 | E193: 8485857 | F193: Thu, 29 Jan 2026 00:00:00 GMT | G193: =A193/D193-1 -> -0.0033727339 | I193: 111.58 | J193: 111.67 | K193: 108.76 | L193: 109.63 | M193: 10775531 | N193: Thu, 29 Jan 2026 00:00:00 GMT | O193: =I193/L193-1 -> 0.017787102
A194: 639.6 | B194: 641.81 | C194: 638.22 | D194: 641.05 | E194: 5488373 | F194: Wed, 28 Jan 2026 00:00:00 GMT | G194: =A194/D194-1 -> -0.002261914 | I194: 109.56 | J194: 111.4299 | K194: 109 | L194: 110.28 | M194: 8980383 | N194: Wed, 28 Jan 2026 00:00:00 GMT | O194: =I194/L194-1 -> -0.0065288357
A195: 639.7 | B195: 640.5959 | C195: 637.87 | D195: 638.42 | E195: 4308306 | F195: Tue, 27 Jan 2026 00:00:00 GMT | G195: =A195/D195-1 -> 0.0020049497 | I195: 110.61 | J195: 111.8 | K195: 110.03 | L195: 111.5 | M195: 8889788 | N195: Tue, 27 Jan 2026 00:00:00 GMT | O195: =I195/L195-1 -> -0.0079820628
A196: 637.09 | B196: 638.39 | C196: 634.52 | D196: 635.03 | E196: 8976388 | F196: Mon, 26 Jan 2026 00:00:00 GMT | G196: =A196/D196-1 -> 0.0032439412 | I196: 111.31 | J196: 112.41 | K196: 111.13 | L196: 111.68 | M196: 8654452 | N196: Mon, 26 Jan 2026 00:00:00 GMT | O196: =I196/L196-1 -> -0.0033130372
A197: 633.83 | B197: 635.4705 | C197: 631.97 | D197: 632.88 | E197: 5827254 | F197: Fri, 23 Jan 2026 00:00:00 GMT | G197: =A197/D197-1 -> 0.0015010745 | I197: 110.98 | J197: 112.9476 | K197: 110.55 | L197: 112.685 | M197: 10634570 | N197: Fri, 23 Jan 2026 00:00:00 GMT | O197: =I197/L197-1 -> -0.015130674
A198: 633.57 | B198: 635.62 | C198: 631.75 | D198: 634.43 | E198: 6057784 | F198: Thu, 22 Jan 2026 00:00:00 GMT | G198: =A198/D198-1 -> -0.0013555475 | I198: 113.21 | J198: 114.29 | K198: 112.17 | L198: 113.165 | M198: 12224987 | N198: Thu, 22 Jan 2026 00:00:00 GMT | O198: =I198/L198-1 -> 0.00039764945
A199: 630.29 | B199: 633.4 | C199: 623.65 | D199: 625.02 | E199: 10354978 | F199: Wed, 21 Jan 2026 00:00:00 GMT | G199: =A199/D199-1 -> 0.0084317302 | I199: 113.19 | J199: 113.25 | K199: 110.5 | L199: 110.57 | M199: 10001042 | N199: Wed, 21 Jan 2026 00:00:00 GMT | O199: =I199/L199-1 -> 0.023695397 | Q199: Notes: | R199: [X]
A200: 623.15 | B200: 629.7599 | C200: 622.22 | D200: 626.76 | E200: 14877629 | F200: Tue, 20 Jan 2026 00:00:00 GMT | G200: =A200/D200-1 -> -0.0057597805 | I200: 110.34 | J200: 111.09 | K200: 108.8 | L200: 109.66 | M200: 9818195 | N200: Tue, 20 Jan 2026 00:00:00 GMT | O200: =I200/L200-1 -> 0.0062009849 | R200: [Y]
...

Sheet Product Lines

Sheet Management

Sheet Table Formatting
B2: [Bold Title] | G2: [Bold Title]
B3: Line Titles | G3: <-- General
B4: Line Titles | G4: <-- Info
B5: Line Titles | G5: <-- General
B6: Line Titles | G6: <-- Info
B7: Line Titles | G7: <-- General
B8: Line Titles | G8: <-- Info
