Workbook

Sheet Main
A1: Master
B2: DXCM
B3: Price | C3: 78.3 | D3: 9/21/2026
B4: SO | C4: 382.2 | D4: Q2'26
B5: MC | C5: =C3*C4 -> 29926.26
B6: Cash | C6: =1105+842 -> 1947 | D6: Q2'26
B7: Debt | C7: =82.6 -> 82.6 | D7: Q2'26
B8: EV | C8: =C5-C6+C7 -> 28061.86
B10: DexCom, Inc. (DXCM)
B12: Founder(s): Scott Glenn, John Burd, Lauren Otsuki, Ellen Preston, and Bret Megargel | M12: Resources:
B13: Founded: 1999 | M13: SEC filings | P13: https://www.sec.gov/edgar/browse/?CIK=310764&owner=exclude
B14: Headquarters: San Diego, CA | F14: Registered Exchange: NASDAQ | M14: Company Homepage | P14: dexcom.com/en-us
B15: Current CEO: Kevin Sayer | F15: Address: 6340 Sequence Drive San Diego, CA 92121 U.S. | N15: Company IR Page | Q15: https://investors.dexcom.com/overview/default.aspx
B16: Employees: 10,300 | F16: Investor Relations Contact: | M16: Earnings Calls | P16: https://seekingalpha.com/symbol/DXCM/earnings/transcripts
B17: Industry: CGMS - Medical Devices | F17: Investors Relation Department | M17: Equity Analysis | P17: https://stockanalysis.com/stocks/dxcm/company/
B18: Sector: Healthcare | F18: Phone: | G18: (858) 410-1560 | I18: Email: | J18: IR@dexcom.com | M18: MacroTrends | P18: https://www.macrotrends.net/stocks/charts/DXCM/dexcom/cash-flow-statement?freq=Q
B19: IPO: Apr 14, 2005 | M19: ROIC, WACC | P19: https://www.gurufocus.com/term/wacc/DXCM
B20: Fiscal Year: [January - December] | M20: Godel Terminal | P20: https://app.godelterminal.com/
A22: Company Overview:
B23: DexCom, Inc., a medical device company, focuses on the design, development, and commercialization of continuous glucose monitoring (CGM) systems in the United States and internationally
B24: The Company provides its systems for the management of diabetes and metabolic health by patients, caregivers, and clinicians
B25: Its products include:
C26: Dexcom G6 and Dexcom G7, integrated CGM systems for diabetes management
C27: Dexcom Share, a remote monitoring system; Dexcom Real-Time API, which enables authorized third-party software developers to integrate real-time CGM data into their digital health apps and devices
C28: Dexcom ONE, that is designed to replace finger stick blood glucose testing for diabetes treatment decisions
C29: Stelo, a new over-the-counter glucose biosensor designed for adults with prediabetes and Type 2 diabetes
D30: Stelo is a new offering put out by Dexcom and Oura, fitting into the Oura ring software ecosystem
D31: Stelo is an over-the-counter (OTC) continuous glucose monitor (iCGM)—the first in its class FDA-cleared for adults (18+) not on insulin, available without a prescription
D32: Designed for the wellness, prediabetic, and health-optimization population—not intended for diabetics on insulin or those with problematic hypoglycemia … Health nut target
B33: The Company has a collaboration and license agreement with Verily Life Sciences LLC and Verily Ireland Limited to develop blood-based or interstitial glucose monitoring products
C34: Verily Life Sciences LLC is a subsidiary of Alphabet (GOOG) which operates in the wider healthcare market
B35: It markets its products directly to endocrinologists, physicians, and diabetes educators
B36: The Company was incorporated in 1999 and is headquartered in San Diego, California
A38: Business Segments and Geographical Info:

Sheet Model
B1: [Use for Graphing] | AM1: Q1 2020 | AQ1: Q1 2021 | AU1: Q1 2022 | AY1: Q1 2023 | BC1: Q1 2024 | BG1: Q1 2025 | BK1: Q1 2026
B2: Quarterly
B3: Revenues | C3: {="Q"&MOD(_xlfn.SEQUENCE(1,64)-1,4)+1&" "&(2011+INT((_xlfn.SEQUENCE(1,64)-1)/4))} -> Q1 2011 | D3: Q2 2011 | E3: Q3 2011 | F3: Q4 2011 | G3: Q1 2012 | H3: Q2 2012 | I3: Q3 2012 | J3: Q4 2012 | K3: Q1 2013 | L3: Q2 2013 | M3: Q3 2013 | N3: Q4 2013 | O3: Q1 2014 | P3: Q2 2014 | Q3: Q3 2014 | R3: Q4 2014 | S3: Q1 2015 | T3: Q2 2015 | U3: Q3 2015 | V3: Q4 2015 | W3: Q1 2016 | X3: Q2 2016 | Y3: Q3 2016 | Z3: Q4 2016 | AA3: Q1 2017 | AB3: Q2 2017 | AC3: Q3 2017 | AD3: Q4 2017 | AE3: Q1 2018 | AF3: Q2 2018 | AG3: Q3 2018 | AH3: Q4 2018 | AI3: Q1 2019 | AJ3: Q2 2019 | AK3: Q3 2019 | AL3: Q4 2019 | AM3: Q1 2020 | AN3: Q2 2020 | AO3: Q3 2020 | AP3: Q4 2020 | AQ3: Q1 2021 | AR3: Q2 2021 | AS3: Q3 2021 | AT3: Q4 2021 | AU3: Q1 2022 | AV3: Q2 2022 | AW3: Q3 2022 | AX3: Q4 2022 | AY3: Q1 2023 | AZ3: Q2 2023 | BA3: Q3 2023 | BB3: Q4 2023 | BC3: Q1 2024 | BD3: Q2 2024 | BE3: Q3 2024 | BF3: Q4 2024 | BG3: Q1 2025 | BH3: Q2 2025 | BI3: Q3 2025 | BJ3: Q4 2025 | BK3: Q1 2026 | BL3: Q2 2026 | BM3: Q3 2026 | BN3: Q4 2026 | BS3: 2011 | BT3: =BS3+1 -> 2012 | BU3: =BT3+1 -> 2013 | BV3: =BU3+1 -> 2014 | BW3: =BV3+1 -> 2015 | BX3: =BW3+1 -> 2016 | BY3: =BX3+1 -> 2017 | BZ3: =BY3+1 -> 2018 | CA3: =BZ3+1 -> 2019 | ... EO3: =EN3+1 -> 2085
B4: Distributor Revenues | AM4: 286.1 | AN4: 331.7 | AO4: 382.4 | AP4: =1437.6-SUM(AM4:AO4) -> 437.4 | AQ4: 390.7 | AR4: 495.9 | AS4: 552.3 | AT4: =1849.4-SUM(AQ4:AS4) -> 410.5 | AU4: 527.1 | AV4: 585.1 | AW4: 656.2 | AX4: =2470.8-SUM(AU4:AW4) -> 702.4 | AY4: 618.9 | AZ4: 738.8 | BA4: 713.6 | BB4: =3095.6-SUM(AY4:BA4) -> 1024.3 | BC4: 778.8 | BD4: 860.1 | BE4: 843.3 | BF4: =3430.1-SUM(BC4:BE4) -> 947.9 | BG4: 880 | BH4: 977.8 | BI4: 1026 | BJ4: =3959-SUM(BG4:BI4) -> 1075.2 | BK4: 1010.3 | BL4: 1102.4 | CB4: =SUM(AM4:AP4) -> 1437.6 | CC4: =SUM(AQ4:AT4) -> 1849.4 | CD4: =SUM(AU4:AX4) -> 2470.8 | CE4: =SUM(AY4:BB4) -> 3095.6 | CF4: =SUM(BC4:BF4) -> 3430.1 | CG4: =SUM(BG4:BJ4) -> 3959 | CH4: =CG4*(1+CH8) -> 4501.383 | CI4: =CH4*(1+CI8) -> 5145.0808 | CJ4: =CI4*(1+CJ8) -> 5865.3921 | CK4: =CJ4*(1+CK8) -> 6657.22 | CL4: =CK4*(1+CL8) -> 7509.3442 | CM4: =CL4*(1+CM8) -> 8410.4655 | CN4: =CM4*(1+CN8) -> 9377.669 | CO4: =CN4*(1+CO8) -> 10409.213 | ... CQ4: =CP4*(1+CQ8) -> 12652.398
B5: Direct Revenues | AM5: 119 | AN5: 120.1 | AO5: 118.5 | AP5: =489.1-SUM(AM5:AO5) -> 131.5 | AQ5: 114.3 | AR5: 99.2 | AS5: 97.9 | AT5: =599.1-SUM(AQ5:AS5) -> 287.7 | AU5: 101.7 | AV5: 111.1 | AW5: 113.4 | AX5: =439-SUM(AU5:AW5) -> 112.8 | AY5: 122.6 | AZ5: 132.5 | BA5: 261.4 | BB5: =526.7-SUM(AY5:BA5) -> 10.2 | BC5: 142.5 | BD5: 144.2 | BE5: 150.9 | BF5: =602.9-SUM(BC5:BE5) -> 165.3 | BG5: 156 | BH5: 179.3 | BI5: 183.3 | BJ5: =703-SUM(BG5:BI5) -> 184.4 | BK5: 181.6 | BL5: 206 | CB5: =SUM(AM5:AP5) -> 489.1 | CC5: =SUM(AQ5:AT5) -> 599.1 | CD5: =SUM(AU5:AX5) -> 439 | CE5: =SUM(AY5:BB5) -> 526.7 | CF5: =SUM(BC5:BF5) -> 602.9 | CG5: =SUM(BG5:BJ5) -> 703 | CH5: =CG5*(1+CH9) -> 811.965 | CI5: =CH5*(1+CI9) -> 932.13582 | CJ5: =CI5*(1+CJ9) -> 1053.3135 | CK5: =CJ5*(1+CK9) -> 1174.4445 | CL5: =CK5*(1+CL9) -> 1303.6334 | CM5: =CL5*(1+CM9) -> 1440.5149 | CN5: =CM5*(1+CN9) -> 1588.1677 | CO5: =CN5*(1+CO9) -> 1746.9845 | ... CQ5: =CP5*(1+CQ9) -> 2085.1133
B6: Ttl Revenues | AM6: =SUM(AM4:AM5) -> 405.1 | AN6: =SUM(AN4:AN5) -> 451.8 | AO6: =SUM(AO4:AO5) -> 500.9 | AP6: =SUM(AP4:AP5) -> 568.9 | AQ6: =SUM(AQ4:AQ5) -> 505 | AR6: =SUM(AR4:AR5) -> 595.1 | AS6: =SUM(AS4:AS5) -> 650.2 | AT6: =SUM(AT4:AT5) -> 698.2 | ... BL6: =SUM(BL4:BL5) -> 1308.4 | CB6: =SUM(AM6:AP6) -> 1926.7 | CC6: =SUM(AQ6:AT6) -> 2448.5 | CD6: =SUM(AU6:AX6) -> 2909.8 | CE6: =SUM(AY6:BB6) -> 3622.3 | CF6: =SUM(BC6:BF6) -> 4033 | CG6: =SUM(BG6:BJ6) -> 4662 | CH6: =SUM(CH4:CH5) -> 5313.348 | CI6: =SUM(CI4:CI5) -> 6077.2166 | CJ6: =SUM(CJ4:CJ5) -> 6918.7056 | CK6: =SUM(CK4:CK5) -> 7831.6645 | CL6: =SUM(CL4:CL5) -> 8812.9776 | CM6: =SUM(CM4:CM5) -> 9850.9804 | CN6: =SUM(CN4:CN5) -> 10965.837 | CO6: =SUM(CO4:CO5) -> 12156.197 | ... CQ6: =SUM(CQ4:CQ5) -> 14737.511
B8: Distributor Revenue Growth Y/y | AQ8: =AQ4/AM4-1 -> 0.36560643 | AR8: =AR4/AN4-1 -> 0.49502563 | AS8: =AS4/AO4-1 -> 0.44429916 | AT8: =AT4/AP4-1 -> -0.061499771 | AU8: =AU4/AQ4-1 -> 0.34911697 | AV8: =AV4/AR4-1 -> 0.17987497 | AW8: =AW4/AS4-1 -> 0.1881224 | AX8: =AX4/AT4-1 -> 0.71108404 | ... BL8: =BL4/BH4-1 -> 0.12742892 | CC8: =CC4/CB4-1 -> 0.28644964 | CD8: =CD4/CC4-1 -> 0.33600087 | CE8: =CE4/CD4-1 -> 0.25287356 | CF8: =CF4/CE4-1 -> 0.1080566 | CG8: =CG4/CF4-1 -> 0.15419376 | CH8: 0.137 | CI8: 0.143 | CJ8: 0.14 | CK8: 0.135 | CL8: 0.128 | CM8: 0.12 | CN8: 0.115 | CO8: 0.11 | CP8: 0.105 | CQ8: 0.1
B9: Direct Revenue Growth Y/y | AQ9: =AQ5/AM5-1 -> -0.039495798 | AR9: =AR5/AN5-1 -> -0.17402165 | AS9: =AS5/AO5-1 -> -0.17383966 | AT9: =AT5/AP5-1 -> 1.1878327 | AU9: =AU5/AQ5-1 -> -0.11023622 | AV9: =AV5/AR5-1 -> 0.11995968 | AW9: =AW5/AS5-1 -> 0.15832482 | AX9: =AX5/AT5-1 -> -0.60792492 | ... BL9: =BL5/BH5-1 -> 0.14891244 | CC9: =CC5/CB5-1 -> 0.22490288 | CD9: =CD5/CC5-1 -> -0.26723418 | CE9: =CE5/CD5-1 -> 0.19977221 | CF9: =CF5/CE5-1 -> 0.14467439 | CG9: =CG5/CF5-1 -> 0.16603085 | CH9: 0.155 | CI9: 0.148 | CJ9: 0.13 | CK9: 0.115 | CL9: 0.11 | CM9: 0.105 | CN9: 0.1025 | CO9: 0.1 | CP9: 0.095 | CQ9: 0.09
B10: Ttl Revenue Growth Y/y | G10: =G26/C26-1 -> 0.41549296 | H10: =H26/D26-1 -> 0.093457944 | I10: =I26/E26-1 -> 0.26229508 | J10: =J26/F26-1 -> 0.48 | K10: =K26/G26-1 -> 0.47263682 | L10: =L26/H26-1 -> 0.52991453 | M10: =M26/I26-1 -> 0.85714286 | N10: =N26/J26-1 -> 0.55255255 | ... AP10: =AP26/AL26-1 -> 0.2292567 | AQ10: =AQ6/AM6-1 -> 0.24660578 | AR10: =AR6/AN6-1 -> 0.31717574 | AS10: =AS6/AO6-1 -> 0.29806349 | AT10: =AT6/AP6-1 -> 0.22728072 | AU10: =AU6/AQ6-1 -> 0.24514851 | AV10: =AV6/AR6-1 -> 0.16988741 | AW10: =AW6/AS6-1 -> 0.1836358 | AX10: =AX6/AT6-1 -> 0.16757376 | ... BL10: =BL6/BH6-1 -> 0.13075793 | BT10: =BT26/BS26-1 -> 0.30759162 | BU10: =BU26/BT26-1 -> 0.6016016 | BV10: =BV26/BU26-1 -> 0.62 | BW10: =BW26/BV26-1 -> 0.55092593 | BX10: =BX26/BW26-1 -> 0.4261194 | BY10: =BY26/BX26-1 -> 0.25327054 | BZ10: =BZ26/BY26-1 -> 0.43576896 | CA10: =CA26/BZ26-1 -> 0.43078713 | CB10: =CB26/CA26-1 -> 0.3053523 | CC10: =CC6/CB6-1 -> 0.27082576 | CD10: =CD6/CC6-1 -> 0.18840106 | CE10: =CE6/CD6-1 -> 0.24486219 | CF10: =CF6/CE6-1 -> 0.113381 | CG10: =CG6/CF6-1 -> 0.1559633 | CH10: =CH6/CG6-1 -> 0.13971429 | CI10: =CI6/CH6-1 -> 0.14376408 | CJ10: =CJ6/CI6-1 -> 0.13846618 | ... CQ10: =CQ6/CP6-1 -> 0.098574037
B12: Distributor % of Ttl Revenues | AM12: =AM4/AM6 -> 0.70624537 | AN12: =AN4/AN6 -> 0.73417441 | AO12: =AO4/AO6 -> 0.76342583 | AP12: =AP4/AP6 -> 0.76885217 | AQ12: =AQ4/AQ6 -> 0.77366337 | AR12: =AR4/AR6 -> 0.83330533 | AS12: =AS4/AS6 -> 0.84943094 | AT12: =AT4/AT6 -> 0.58794042 | ... BL12: =BL4/BL6 -> 0.84255579 | CB12: =CB4/CB6 -> 0.74614626 | CC12: =CC4/CC6 -> 0.75531958 | CD12: =CD4/CD6 -> 0.84913052 | CE12: =CE4/CE6 -> 0.85459515 | CF12: =CF4/CF6 -> 0.85050831 | CG12: =CG4/CG6 -> 0.84920635 | CH12: =CH4/CH6 -> 0.84718392 | CI12: =CI4/CI6 -> 0.84661797 | ... CQ12: =CQ4/CQ6 -> 0.85851659
B13: Direct % of Ttl Revenues | AM13: =AM5/AM6 -> 0.29375463 | AN13: =AN5/AN6 -> 0.26582559 | AO13: =AO5/AO6 -> 0.23657417 | AP13: =AP5/AP6 -> 0.23114783 | AQ13: =AQ5/AQ6 -> 0.22633663 | AR13: =AR5/AR6 -> 0.16669467 | AS13: =AS5/AS6 -> 0.15056906 | AT13: =AT5/AT6 -> 0.41205958 | ... BL13: =BL5/BL6 -> 0.15744421 | CB13: =CB5/CB6 -> 0.25385374 | CC13: =CC5/CC6 -> 0.24468042 | CD13: =CD5/CD6 -> 0.15086948 | CE13: =CE5/CE6 -> 0.14540485 | CF13: =CF5/CF6 -> 0.14949169 | CG13: =CG5/CG6 -> 0.15079365 | CH13: =CH5/CH6 -> 0.15281608 | CI13: =CI5/CI6 -> 0.15338203 | ... CQ13: =CQ5/CQ6 -> 0.14148341
B15: U.S. Revenues | AM15: 292.3 | AN15: 367.1 | AO15: 398.6 | AP15: =1509.5-SUM(AM15:AO15) -> 451.5 | AQ15: 381.2 | AR15: 461.5 | AS15: 489.6 | AT15: =2024.3-SUM(AQ15:AS15) -> 692 | AU15: 451.2 | AV15: 511 | AW15: 573.4 | AX15: =2142-SUM(AU15:AW15) -> 606.4 | AY15: 526 | AZ15: 616.6 | BA15: 713.6 | BB15: =2625.3-SUM(AY15:BA15) -> 769.1 | BC15: 653.2 | BD15: 731.9 | BE15: 701.9 | BF15: =2889.8-SUM(BC15:BE15) -> 802.8 | BG15: 750.5 | BH15: 841 | BI15: 851.9 | BJ15: =3334.9-SUM(BG15:BI15) -> 891.5 | BK15: 832.3 | BL15: 933.4 | CB15: =SUM(AM15:AP15) -> 1509.5 | CC15: =SUM(AQ15:AT15) -> 2024.3 | CD15: =SUM(AU15:AX15) -> 2142 | CE15: =SUM(AY15:BB15) -> 2625.3 | CF15: =SUM(BC15:BF15) -> 2889.8 | CG15: =SUM(BG15:BJ15) -> 3334.9
B16: Intl. Revenues | AM16: 112.8 | AN16: 84.7 | AO16: 102.3 | AP16: =417.2-SUM(AM16:AO16) -> 117.4 | AQ16: 123.8 | AR16: 133.6 | AS16: 160.6 | AT16: =424.2-SUM(AQ16:AS16) -> 6.2 | AU16: 177.6 | AV16: 185.2 | AW16: 196.2 | AX16: =767.8-SUM(AU16:AW16) -> 208.8 | AY16: 215.5 | AZ16: 254.7 | BA16: 261.4 | BB16: =997-SUM(AY16:BA16) -> 265.4 | BC16: 267.8 | BD16: 272.4 | BE16: 292.3 | BF16: =1143.2-SUM(BC16:BE16) -> 310.7 | BG16: 285.5 | BH16: 316.1 | BI16: 357.4 | BJ16: =1327.1-SUM(BG16:BI16) -> 368.1 | BK16: 359.6 | BL16: 375 | CB16: =SUM(AM16:AP16) -> 417.2 | CC16: =SUM(AQ16:AT16) -> 424.2 | CD16: =SUM(AU16:AX16) -> 767.8 | CE16: =SUM(AY16:BB16) -> 997 | CF16: =SUM(BC16:BF16) -> 1143.2 | CG16: =SUM(BG16:BJ16) -> 1327.1
B17: Ttl Revenues | AM17: =SUM(AM15:AM16) -> 405.1 | AN17: =SUM(AN15:AN16) -> 451.8 | AO17: =SUM(AO15:AO16) -> 500.9 | AP17: =SUM(AP15:AP16) -> 568.9 | AQ17: =SUM(AQ15:AQ16) -> 505 | AR17: =SUM(AR15:AR16) -> 595.1 | AS17: =SUM(AS15:AS16) -> 650.2 | AT17: =SUM(AT15:AT16) -> 698.2 | ... BL17: =SUM(BL15:BL16) -> 1308.4 | CB17: =SUM(AM17:AP17) -> 1926.7 | CC17: =SUM(AQ17:AT17) -> 2448.5 | CD17: =SUM(AU17:AX17) -> 2909.8 | CE17: =SUM(AY17:BB17) -> 3622.3 | CF17: =SUM(BC17:BF17) -> 4033 | CG17: =SUM(BG17:BJ17) -> 4662
B19: U.S. Revenue Growth Y/y | AQ19: =AQ15/AM15-1 -> 0.30413958 | AR19: =AR15/AN15-1 -> 0.25715064 | AS19: =AS15/AO15-1 -> 0.22829905 | AT19: =AT15/AP15-1 -> 0.53266888 | AU19: =AU15/AQ15-1 -> 0.18363064 | AV19: =AV15/AR15-1 -> 0.10725894 | AW19: =AW15/AS15-1 -> 0.17116013 | AX19: =AX15/AT15-1 -> -0.12369942 | ... BL19: =BL15/BH15-1 -> 0.1098692 | CC19: =CC15/CB15-1 -> 0.34104008 | CD19: =CD15/CC15-1 -> 0.058143556 | CE19: =CE15/CD15-1 -> 0.22563025 | CF19: =CF15/CE15-1 -> 0.10075039 | CG19: =CG15/CF15-1 -> 0.1540245
B20: Intl. Revenue Growth Y/y | AQ20: =AQ16/AM16-1 -> 0.09751773 | AR20: =AR16/AN16-1 -> 0.57733176 | AS20: =AS16/AO16-1 -> 0.56989247 | AT20: =AT16/AP16-1 -> -0.9471891 | AU20: =AU16/AQ16-1 -> 0.43457189 | AV20: =AV16/AR16-1 -> 0.38622754 | AW20: =AW16/AS16-1 -> 0.22166874 | AX20: =AX16/AT16-1 -> 32.677419 | ... BL20: =BL16/BH16-1 -> 0.18633344 | CC20: =CC16/CB16-1 -> 0.016778523 | CD20: =CD16/CC16-1 -> 0.80999529 | CE20: =CE16/CD16-1 -> 0.29851524 | CF20: =CF16/CE16-1 -> 0.14663992 | CG20: =CG16/CF16-1 -> 0.16086424
B21: Ttl Revenue Growth Y/y | AQ21: =AQ17/AM17-1 -> 0.24660578 | AR21: =AR17/AN17-1 -> 0.31717574 | AS21: =AS17/AO17-1 -> 0.29806349 | AT21: =AT17/AP17-1 -> 0.22728072 | AU21: =AU17/AQ17-1 -> 0.24514851 | AV21: =AV17/AR17-1 -> 0.16988741 | AW21: =AW17/AS17-1 -> 0.1836358 | AX21: =AX17/AT17-1 -> 0.16757376 | ... BL21: =BL17/BH17-1 -> 0.13075793 | CC21: =CC17/CB17-1 -> 0.27082576 | CD21: =CD17/CC17-1 -> 0.18840106 | CE21: =CE17/CD17-1 -> 0.24486219 | CF21: =CF17/CE17-1 -> 0.113381 | CG21: =CG17/CF17-1 -> 0.1559633
B23: U.S. % of Revenues | AM23: =AM15/AM17 -> 0.72155023 | AN23: =AN15/AN17 -> 0.81252767 | AO23: =AO15/AO17 -> 0.79576762 | AP23: =AP15/AP17 -> 0.79363684 | AQ23: =AQ15/AQ17 -> 0.75485149 | AR23: =AR15/AR17 -> 0.77549992 | AS23: =AS15/AS17 -> 0.75299908 | AT23: =AT15/AT17 -> 0.99112002 | ... BL23: =BL15/BL17 -> 0.7133904 | CB23: =CB15/CB17 -> 0.78346395 | CC23: =CC15/CC17 -> 0.82675107 | CD23: =CD15/CD17 -> 0.73613307 | CE23: =CE15/CE17 -> 0.72476051 | CF23: =CF15/CF17 -> 0.71653856 | CG23: =CG15/CG17 -> 0.71533677
B24: Intl. % of Revenues | AM24: =AM16/AM17 -> 0.27844977 | AN24: =AN16/AN17 -> 0.18747233 | AO24: =AO16/AO17 -> 0.20423238 | AP24: =AP16/AP17 -> 0.20636316 | AQ24: =AQ16/AQ17 -> 0.24514851 | AR24: =AR16/AR17 -> 0.22450008 | AS24: =AS16/AS17 -> 0.24700092 | AT24: =AT16/AT17 -> 0.0088799771 | ... BL24: =BL16/BL17 -> 0.2866096 | CB24: =CB16/CB17 -> 0.21653605 | CC24: =CC16/CC17 -> 0.17324893 | CD24: =CD16/CD17 -> 0.26386693 | CE24: =CE16/CE17 -> 0.27523949 | CF24: =CF16/CF17 -> 0.28346144 | CG24: =CG16/CG17 -> 0.28466323
B26: Revenues | C26: 14.2 | D26: 21.4 | E26: 18.3 | F26: 22.5 | G26: 20.1 | H26: 23.4 | I26: 23.1 | J26: 33.3 | K26: 29.6 | L26: 35.8 | M26: 42.9 | N26: 51.7 | O26: 47.1 | P26: 58.8 | Q26: 69 | R26: 84.3 | S26: 72.8 | T26: 93.2 | U26: 105.2 | V26: 130.8 | W26: 116.2 | X26: 137.3 | Y26: 148.6 | Z26: 171.2 | AA26: 142.3 | AB26: 170.6 | AC26: 184.6 | AD26: 221 | AE26: 184.4 | AF26: 242.5 | AG26: 266.7 | AH26: 338 | AI26: 280.5 | AJ26: 336.4 | AK26: 396.3 | AL26: 462.8 | AM26: =AM6 -> 405.1 | AN26: =AN6 -> 451.8 | AO26: =AO6 -> 500.9 | AP26: =AP6 -> 568.9 | AQ26: =AQ6 -> 505 | AR26: =AR6 -> 595.1 | AS26: =AS6 -> 650.2 | AT26: =AT6 -> 698.2 | ... BL26: =BL6 -> 1308.4 | BS26: =SUM(C26:F26) -> 76.4 | BT26: =SUM(G26:J26) -> 99.9 | BU26: =SUM(K26:N26) -> 160 | BV26: =SUM(O26:R26) -> 259.2 | BW26: =SUM(S26:V26) -> 402 | BX26: =SUM(W26:Z26) -> 573.3 | BY26: =SUM(AA26:AD26) -> 718.5 | BZ26: =SUM(AE26:AH26) -> 1031.6 | CA26: =SUM(AI26:AL26) -> 1476 | CB26: =SUM(AM26:AP26) -> 1926.7 | CC26: =SUM(AQ26:AT26) -> 2448.5 | CD26: =SUM(AU26:AX26) -> 2909.8 | CE26: =SUM(AY26:BB26) -> 3622.3 | CF26: =SUM(BC26:BF26) -> 4033 | CG26: =SUM(BG26:BJ26) -> 4662 | CH26: =CH6 -> 5313.348 | CI26: =CI6 -> 6077.2166 | CJ26: =CJ6 -> 6918.7056 | CK26: =CK6 -> 7831.6645 | CL26: =CL6 -> 8812.9776 | CM26: =CM6 -> 9850.9804 | CN26: =CN6 -> 10965.837 | CO26: =CO6 -> 12156.197 | ... CQ26: =CQ6 -> 14737.511
B27: COGS | C27: 9.1 | D27: 9.5 | E27: 10.1 | F27: 11.7 | G27: 10.7 | H27: 12.2 | I27: 14.7 | J27: 15.7 | K27: 13.1 | L27: 13.9 | M27: 15.3 | N27: 17.6 | O27: 17.3 | P27: 18.9 | Q27: 21.8 | R27: 24.9 | S27: 26.3 | T27: 27.2 | U27: 30.5 | V27: 39.6 | W27: 41.1 | X27: 51.8 | Y27: 47.5 | Z27: 54.5 | AA27: 48.2 | AB27: 53.1 | AC27: 57.6 | AD27: 67.5 | AE27: 65.5 | AF27: 88.9 | AG27: 98.1 | AH27: 115.2 | AI27: 111.7 | AJ27: 129.9 | AK27: 149.4 | AL27: 153.5 | AM27: 148.6 | AN27: 167.7 | AO27: 160.5 | AP27: 169.8 | AQ27: 161.1 | AR27: 178 | AS27: 203.3 | AT27: 225.6 | AU27: 230.7 | AV27: 246.7 | AW27: 275.4 | AX27: 273.9 | AY27: 278.9 | AZ27: 324.9 | BA27: 351.7 | BB27: 377.9 | BC27: 359.1 | BD27: 377.6 | BE27: 400.4 | BF27: 457.7 | BG27: 447 | BH27: 468.3 | BI27: 477.9 | BJ27: =1860.1-SUM(BG27:BI27) -> 466.9 | BK27: 441.6 | BL27: 478.4 | BS27: =SUM(C27:F27) -> 40.4 | BT27: =SUM(G27:J27) -> 53.3 | BU27: =SUM(K27:N27) -> 59.9 | BV27: =SUM(O27:R27) -> 82.9 | BW27: =SUM(S27:V27) -> 123.6 | BX27: =SUM(W27:Z27) -> 194.9 | BY27: =SUM(AA27:AD27) -> 226.4 | BZ27: =SUM(AE27:AH27) -> 367.7 | CA27: =SUM(AI27:AL27) -> 544.5 | CB27: =SUM(AM27:AP27) -> 646.6 | CC27: =SUM(AQ27:AT27) -> 768 | CD27: =SUM(AU27:AX27) -> 1026.7 | CE27: =SUM(AY27:BB27) -> 1333.4 | CF27: =SUM(BC27:BF27) -> 1594.8 | CG27: =SUM(BG27:BJ27) -> 1860.1 | CH27: =CH26*(1-CH39) -> 1992.5055 | CI27: =CI26*(1-CI39) -> 2263.7632 | CJ27: =CJ26*(1-CJ39) -> 2546.0836 | CK27: =CK26*(1-CK39) -> 2858.5576 | CL27: =CL26*(1-CL39) -> 3172.6719 | CM27: =CM26*(1-CM39) -> 3447.8431 | CN27: =CN26*(1-CN39) -> 3783.2137 | CO27: =CO26*(1-CO39) -> 4133.107 | ... CQ27: =CQ26*(1-CQ39) -> 4863.3787
B28: GP | C28: =C26-C27 -> 5.1 | D28: =D26-D27 -> 11.9 | E28: =E26-E27 -> 8.2 | F28: =F26-F27 -> 10.8 | G28: =G26-G27 -> 9.4 | H28: =H26-H27 -> 11.2 | I28: =I26-I27 -> 8.4 | J28: =J26-J27 -> 17.6 | ... BL28: =BL26-BL27 -> 830 | BS28: =SUM(C28:F28) -> 36 | BT28: =SUM(G28:J28) -> 46.6 | BU28: =SUM(K28:N28) -> 100.1 | BV28: =SUM(O28:R28) -> 176.3 | BW28: =SUM(S28:V28) -> 278.4 | BX28: =SUM(W28:Z28) -> 378.4 | BY28: =SUM(AA28:AD28) -> 492.1 | BZ28: =SUM(AE28:AH28) -> 663.9 | CA28: =SUM(AI28:AL28) -> 931.5 | CB28: =SUM(AM28:AP28) -> 1280.1 | CC28: =SUM(AQ28:AT28) -> 1680.5 | CD28: =SUM(AU28:AX28) -> 1883.1 | CE28: =SUM(AY28:BB28) -> 2288.9 | CF28: =SUM(BC28:BF28) -> 2438.2 | CG28: =SUM(BG28:BJ28) -> 2801.9 | CH28: =CH26-CH27 -> 3320.8425 | CI28: =CI26-CI27 -> 3813.4534 | CJ28: =CJ26-CJ27 -> 4372.6219 | CK28: =CK26-CK27 -> 4973.107 | CL28: =CL26-CL27 -> 5640.3057 | CM28: =CM26-CM27 -> 6403.1373 | CN28: =CN26-CN27 -> 7182.623 | CO28: =CO26-CO27 -> 8023.0901 | ... CQ28: =CQ26-CQ27 -> 9874.1325
B29: R&D | C29: 10.7 | D29: 12.2 | E29: 13.2 | F29: 14.9 | G29: 15.4 | H29: 15.9 | I29: 15.4 | J29: 17.3 | K29: 18.1 | L29: 20.7 | M29: 21.6 | N29: 23.8 | O29: 27.6 | P29: 30.9 | Q29: 33.7 | R29: 36.2 | S29: 39.4 | T29: 45.2 | U29: 52.3 | V29: 61.1 | W29: 62.1 | X29: 69.3 | Y29: 75.7 | Z29: 79.1 | AA29: 86.4 | AB29: 85.8 | AC29: 84.2 | AD29: 92.8 | AE29: 104.8 | AF29: 111.3 | AG29: 104.6 | AH29: 112.1 | AI29: 124.2 | AJ29: 138.3 | AK29: 124.2 | AL29: 129 | AM29: 73.1 | AN29: 79.9 | AO29: 87.7 | AP29: 119.2 | AQ29: 109.4 | AR29: 129.1 | AS29: 128.8 | AT29: 236.9 | AU29: 135.9 | AV29: 121.7 | AW29: 110.3 | AX29: 116.3 | AY29: 119 | AZ29: 119.3 | BA29: 131.4 | BB29: 136.1 | BC29: 141.5 | BD29: 136 | BE29: 135.4 | BF29: 139.5 | BG29: 145.2 | BH29: 148.2 | BI29: 157.5 | BJ29: =599.1-SUM(BG29:BI29) -> 148.2 | BK29: 145.3 | BL29: 153 | BS29: =SUM(C29:F29) -> 51 | BT29: =SUM(G29:J29) -> 64 | BU29: =SUM(K29:N29) -> 84.2 | BV29: =SUM(O29:R29) -> 128.4 | BW29: =SUM(S29:V29) -> 198 | BX29: =SUM(W29:Z29) -> 286.2 | BY29: =SUM(AA29:AD29) -> 349.2 | BZ29: =SUM(AE29:AH29) -> 432.8 | CA29: =SUM(AI29:AL29) -> 515.7 | CB29: =SUM(AM29:AP29) -> 359.9 | CC29: =SUM(AQ29:AT29) -> 604.2 | CD29: =SUM(AU29:AX29) -> 484.2 | CE29: =SUM(AY29:BB29) -> 505.8 | CF29: =SUM(BC29:BF29) -> 552.4 | CG29: =SUM(BG29:BJ29) -> 599.1 | CH29: =CH26*CH40 -> 642.91511 | CI29: =CI26*CI40 -> 717.11156 | CJ29: =CJ26*CJ40 -> 802.56984 | CK29: =CK26*CK40 -> 892.80976 | CL29: =CL26*CL40 -> 1022.3054 | CM29: =CM26*CM40 -> 1132.8627 | CN29: =CN26*CN40 -> 1250.1054 | CO29: =CO26*CO40 -> 1373.6503 | ... CQ29: =CQ26*CQ40 -> 1635.8637
B30: SG&A | C30: 6.3 | D30: 7 | E30: 8.2 | F30: 8.1 | G30: 9.4 | H30: 10 | I30: 10.3 | J30: 8.6 | K30: 9.3 | L30: 11.1 | M30: 11.8 | N30: 12.6 | O30: 14.5 | P30: 14.8 | Q30: 18.5 | R30: 21.6 | S30: 19.8 | T30: 24.4 | U30: 64.8 | V30: 28.5 | W30: 32.2 | X30: 36.3 | Y30: 43.9 | Z30: 43.7 | AA30: 48.1 | AB30: 45.3 | AC30: 43.3 | AD30: 48.7 | AE30: 44.8 | AF30: 47.2 | AG30: 50.1 | AH30: 275.3 | AI30: 59 | AJ30: 69 | AK30: 66.7 | AL30: 78.8 | AM30: 149.8 | AN30: 136.4 | AO30: 158.6 | AP30: 173.4 | AQ30: 188.6 | AR30: 186.5 | AS30: 198.5 | AT30: 236.9 | AU30: 218.9 | AV30: 248.9 | AW30: 234.6 | AX30: 305.3 | AY30: 296.4 | AZ30: 299 | BA30: 286.4 | BB30: 303.6 | BC30: 319.3 | BD30: 332.7 | BE30: 306.4 | BF30: 327.4 | BG30: 310.1 | BH30: 328 | BI30: 331.4 | BJ30: =1291-SUM(BG30:BI30) -> 321.5 | BK30: 349.7 | BL30: 358.7 | BS30: =SUM(C30:F30) -> 29.6 | BT30: =SUM(G30:J30) -> 38.3 | BU30: =SUM(K30:N30) -> 44.8 | BV30: =SUM(O30:R30) -> 69.4 | BW30: =SUM(S30:V30) -> 137.5 | BX30: =SUM(W30:Z30) -> 156.1 | BY30: =SUM(AA30:AD30) -> 185.4 | BZ30: =SUM(AE30:AH30) -> 417.4 | CA30: =SUM(AI30:AL30) -> 273.5 | CB30: =SUM(AM30:AP30) -> 618.2 | CC30: =SUM(AQ30:AT30) -> 810.5 | CD30: =SUM(AU30:AX30) -> 1007.7 | CE30: =SUM(AY30:BB30) -> 1185.4 | CF30: =SUM(BC30:BF30) -> 1285.8 | CG30: =SUM(BG30:BJ30) -> 1291 | CH30: =CH26*CH41 -> 1514.3042 | CI30: =CI26*CI41 -> 1671.2346 | CJ30: =CJ26*CJ41 -> 1868.0505 | CK30: =CK26*CK41 -> 2075.3911 | CL30: =CL26*CL41 -> 2322.2196 | CM30: =CM26*CM41 -> 2561.2549 | CN30: =CN26*CN41 -> 2823.703 | CO30: =CO26*CO41 -> 3099.8303 | ... CQ30: =CQ26*CQ41 -> 3610.6903
B31: Operating Income | C31: =C28-SUM(C29:C30) -> -11.9 | D31: =D28-SUM(D29:D30) -> -7.3 | E31: =E28-SUM(E29:E30) -> -13.2 | F31: =F28-SUM(F29:F30) -> -12.2 | G31: =G28-SUM(G29:G30) -> -15.4 | H31: =H28-SUM(H29:H30) -> -14.7 | I31: =I28-SUM(I29:I30) -> -17.3 | J31: =J28-SUM(J29:J30) -> -8.3 | ... BL31: =BL28-SUM(BL29:BL30) -> 318.3 | BS31: =SUM(C31:F31) -> -44.6 | BT31: =SUM(G31:J31) -> -55.7 | BU31: =SUM(K31:N31) -> -28.9 | BV31: =SUM(O31:R31) -> -21.5 | BW31: =SUM(S31:V31) -> -57.1 | BX31: =SUM(W31:Z31) -> -63.9 | BY31: =SUM(AA31:AD31) -> -42.5 | BZ31: =SUM(AE31:AH31) -> -186.3 | CA31: =SUM(AI31:AL31) -> 142.3 | CB31: =SUM(AM31:AP31) -> 302 | CC31: =SUM(AQ31:AT31) -> 265.8 | CD31: =SUM(AU31:AX31) -> 391.2 | CE31: =SUM(AY31:BB31) -> 597.7 | CF31: =SUM(BC31:BF31) -> 600 | CG31: =SUM(BG31:BJ31) -> 911.8 | CH31: =CH28-SUM(CH29:CH30) -> 1163.6232 | CI31: =CI28-SUM(CI29:CI30) -> 1425.1073 | CJ31: =CJ28-SUM(CJ29:CJ30) -> 1702.0016 | CK31: =CK28-SUM(CK29:CK30) -> 2004.9061 | CL31: =CL28-SUM(CL29:CL30) -> 2295.7807 | CM31: =CM28-SUM(CM29:CM30) -> 2709.0196 | CN31: =CN28-SUM(CN29:CN30) -> 3108.8147 | CO31: =CO28-SUM(CO29:CO30) -> 3549.6095 | ... CQ31: =CQ28-SUM(CQ29:CQ30) -> 4627.5785
B32: Other Income | C32: 0 | D32: 0 | E32: 0 | F32: 0 | G32: 0 | H32: 0 | I32: 0 | J32: -0.1 | K32: -0.2 | L32: -0.2 | M32: -0.2 | N32: -0.3 | O32: -0.2 | P32: -0.2 | Q32: -0.2 | R32: -0.2 | S32: -0.2 | T32: -0.1 | U32: -0.1 | V32: 0 | W32: 0 | X32: 0 | Y32: -0.1 | Z32: -0.9 | AA32: 0.1 | AB32: -0.8 | AC32: -2 | AD32: -3.4 | AE32: 6.7 | AF32: 34.5 | AG32: 30.9 | AH32: -12.3 | AI32: -12.2 | AJ32: -8.5 | AK32: -10.2 | AL32: -7.2 | AM32: -11.2 | AN32: -21.6 | AO32: -19 | AP32: 50.2 | AQ32: -4.6 | AR32: -3.9 | AS32: -6.3 | AT32: 5.8 | AU32: -5.2 | AV32: -1.7 | AW32: -1.3 | AX32: 7.8 | AY32: 17.3 | AZ32: 31.2 | BA32: 34.9 | BB32: 29.3 | BC32: 31.4 | BD32: 29.8 | BE32: 25.4 | BF32: 22.4 | BG32: 20.6 | BH32: 28.5 | BI32: 109.8 | BJ32: =176.6-SUM(BG32:BI32) -> 17.7 | BK32: 14.2 | BL32: -0.8 | BS32: =SUM(C32:F32) -> 0 | BT32: =SUM(G32:J32) -> -0.1 | BU32: =SUM(K32:N32) -> -0.9 | BV32: =SUM(O32:R32) -> -0.8 | BW32: =SUM(S32:V32) -> -0.4 | BX32: =SUM(W32:Z32) -> -1 | BY32: =SUM(AA32:AD32) -> -6.1 | BZ32: =SUM(AE32:AH32) -> 59.8 | CA32: =SUM(AI32:AL32) -> -38.1 | CB32: =SUM(AM32:AP32) -> -1.6 | CC32: =SUM(AQ32:AT32) -> -9 | CD32: =SUM(AU32:AX32) -> -0.4 | CE32: =SUM(AY32:BB32) -> 112.7 | CF32: =SUM(BC32:BF32) -> 109 | CG32: =SUM(BG32:BJ32) -> 176.6 | CH32: =CG32*(1+$CQ$49) -> 216.9531 | CI32: =CH32*(1+$CQ$49) -> 266.52688 | CJ32: =CI32*(1+$CQ$49) -> 327.42828 | CK32: =CJ32*(1+$CQ$49) -> 402.24564 | CL32: =CK32*(1+$CQ$49) -> 494.15877 | CM32: =CL32*(1+$CQ$49) -> 607.07404 | CN32: =CM32*(1+$CQ$49) -> 745.79046 | CO32: =CN32*(1+$CQ$49) -> 916.20358 | ... CQ32: =CP32*(1+$CQ$49) -> 1382.7457
B33: Pretax Income | C33: =C31+C32 -> -11.9 | D33: =D31+D32 -> -7.3 | E33: =E31+E32 -> -13.2 | F33: =F31+F32 -> -12.2 | G33: =G31+G32 -> -15.4 | H33: =H31+H32 -> -14.7 | I33: =I31+I32 -> -17.3 | J33: =J31+J32 -> -8.4 | ... BL33: =BL31+BL32 -> 317.5 | BS33: =SUM(C33:F33) -> -44.6 | BT33: =SUM(G33:J33) -> -55.8 | BU33: =SUM(K33:N33) -> -29.8 | BV33: =SUM(O33:R33) -> -22.3 | BW33: =SUM(S33:V33) -> -57.5 | BX33: =SUM(W33:Z33) -> -64.9 | BY33: =SUM(AA33:AD33) -> -48.6 | BZ33: =SUM(AE33:AH33) -> -126.5 | CA33: =SUM(AI33:AL33) -> 104.2 | CB33: =SUM(AM33:AP33) -> 300.4 | CC33: =SUM(AQ33:AT33) -> 256.8 | CD33: =SUM(AU33:AX33) -> 390.8 | CE33: =SUM(AY33:BB33) -> 710.4 | CF33: =SUM(BC33:BF33) -> 709 | CG33: =SUM(BG33:BJ33) -> 1088.4 | CH33: =CH31+CH32 -> 1380.5763 | CI33: =CI31+CI32 -> 1691.6342 | CJ33: =CJ31+CJ32 -> 2029.4298 | CK33: =CK31+CK32 -> 2407.1518 | CL33: =CL31+CL32 -> 2789.9394 | CM33: =CM31+CM32 -> 3316.0937 | CN33: =CN31+CN32 -> 3854.6052 | CO33: =CO31+CO32 -> 4465.8131 | ... CQ33: =CQ31+CQ32 -> 6010.3242
B34: Taxes | C34: 0 | D34: 0 | E34: 0 | F34: 0 | G34: -1.3 | H34: 0 | I34: 0 | J34: 0 | K34: 0 | L34: 0 | M34: 0 | N34: 0 | O34: 0 | P34: 0 | Q34: 0 | R34: 0 | S34: 0 | T34: 0 | U34: 0 | V34: 0 | W34: 0 | X34: 0.1 | Y34: 0.2 | Z34: 0.4 | AA34: 1.4 | AB34: -17.3 | AC34: -0.5 | AD34: 18 | AE34: 0.2 | AF34: -0.6 | AG34: -1.8 | AH34: 2.8 | AI34: 0.3 | AJ34: 1.2 | AK34: 0 | AL34: 1.6 | AM34: 2.5 | AN34: -0.1 | AO34: 2.9 | AP34: -257.1 | AQ34: -15.2 | AR34: 18.7 | AS34: 24.7 | AT34: 11.7 | AU34: -61.2 | AV34: 24.4 | AW34: 45 | AX34: 41.4 | AY34: 15.9 | AZ34: 43.4 | BA34: 119.7 | BB34: -10.1 | BC34: -13.9 | BD34: 44.3 | BE34: 42.8 | BF34: 59.6 | BG34: 48.9 | BH34: 61.3 | BI34: 68.5 | BJ34: =252.1-SUM(BG34:BI34) -> 73.4 | BK34: 70 | BL34: 68.4 | BS34: =SUM(C34:F34) -> 0 | BT34: =SUM(G34:J34) -> -1.3 | BU34: =SUM(K34:N34) -> 0 | BV34: =SUM(O34:R34) -> 0 | BW34: =SUM(S34:V34) -> 0 | BX34: =SUM(W34:Z34) -> 0.7 | BY34: =SUM(AA34:AD34) -> 1.6 | BZ34: =SUM(AE34:AH34) -> 0.6 | CA34: =SUM(AI34:AL34) -> 3.1 | CB34: =SUM(AM34:AP34) -> -251.8 | CC34: =SUM(AQ34:AT34) -> 39.9 | CD34: =SUM(AU34:AX34) -> 49.6 | CE34: =SUM(AY34:BB34) -> 168.9 | CF34: =SUM(BC34:BF34) -> 132.8 | CG34: =SUM(BG34:BJ34) -> 252.1 | CH34: =CH33*CH43 -> 303.72679 | CI34: =CI33*CI43 -> 355.24318 | CJ34: =CJ33*CJ43 -> 405.88597 | CK34: =CK33*CK43 -> 481.43035 | CL34: =CL33*CL43 -> 557.98789 | CM34: =CM33*CM43 -> 696.37967 | CN34: =CN33*CN43 -> 809.46709 | CO34: =CO33*CO43 -> 937.82076 | ... CQ34: =CQ33*CQ43 -> 1262.1681
B35: NI | C35: =C33-C34 -> -11.9 | D35: =D33-D34 -> -7.3 | E35: =E33-E34 -> -13.2 | F35: =F33-F34 -> -12.2 | G35: =G33-G34 -> -14.1 | H35: =H33-H34 -> -14.7 | I35: =I33-I34 -> -17.3 | J35: =J33-J34 -> -8.4 | ... BL35: =BL33-BL34 -> 249.1 | BS35: =SUM(C35:F35) -> -44.6 | BT35: =SUM(G35:J35) -> -54.5 | BU35: =SUM(K35:N35) -> -29.8 | BV35: =SUM(O35:R35) -> -22.3 | BW35: =SUM(S35:V35) -> -57.5 | BX35: =SUM(W35:Z35) -> -65.6 | BY35: =SUM(AA35:AD35) -> -50.2 | BZ35: =SUM(AE35:AH35) -> -127.1 | CA35: =SUM(AI35:AL35) -> 101.1 | CB35: =SUM(AM35:AP35) -> 552.2 | CC35: =SUM(AQ35:AT35) -> 216.9 | CD35: =SUM(AU35:AX35) -> 341.2 | CE35: =SUM(AY35:BB35) -> 541.5 | CF35: =SUM(BC35:BF35) -> 576.2 | CG35: =SUM(BG35:BJ35) -> 836.3 | CH35: =CH33-CH34 -> 1076.8495 | CI35: =CI33-CI34 -> 1336.391 | CJ35: =CJ33-CJ34 -> 1623.5439 | CK35: =CK33-CK34 -> 1925.7214 | CL35: =CL33-CL34 -> 2231.9515 | CM35: =CM33-CM34 -> 2619.714 | CN35: =CN33-CN34 -> 3045.1381 | CO35: =CO33-CO34 -> 3527.9924 | ... CQ35: =CQ33-CQ34 -> 4748.1561 | CR35: =CQ35*(1+$CQ$50) -> 4854.9896 | CS35: =CR35*(1+$CQ$50) -> 4964.2269 | CT35: =CS35*(1+$CQ$50) -> 5075.922 | CU35: =CT35*(1+$CQ$50) -> 5190.1302 | CV35: =CU35*(1+$CQ$50) -> 5306.9082 | CW35: =CV35*(1+$CQ$50) -> 5426.3136 | CX35: =CW35*(1+$CQ$50) -> 5548.4057 | CY35: =CX35*(1+$CQ$50) -> 5673.2448 | ... EO35: =EN35*(1+$CQ$50) -> 14444.111
B36: SC | C36: 249 | D36: 260 | E36: 270 | F36: 262 | G36: 271 | H36: 274 | I36: 276 | J36: 275 | K36: 279 | L36: 284 | M36: 286 | N36: 284 | O36: 293 | P36: 300 | Q36: 303 | R36: 301 | S36: 311 | T36: 311 | U36: 318 | V36: 322 | W36: 319 | X36: 328 | Y36: 334 | Z36: 336 | AA36: 334 | AB36: 341 | AC36: 346 | AD36: 347 | AE36: 345 | AF36: 349 | AG36: 353 | AH36: 354 | AI36: 353 | AJ36: 361 | AK36: 364 | AL36: 365 | AM36: 364 | AN36: 367 | AO36: 375 | AP36: 383 | AQ36: 378 | AR36: 385 | AS36: 387 | AT36: 387 | AU36: 387 | AV36: 389 | AW36: 393 | AX36: 390 | AY36: 689 | AZ36: 687 | BA36: 687 | BB36: 687 | BC36: 386 | BD36: 390 | BE36: 399 | BF36: 394 | BG36: 394 | BH36: 391 | BI36: 391.1 | BJ36: 390.2 | BK36: 385.1 | BL36: 382.2 | BS36: =AVERAGE(C36:F36) -> 260.25 | BT36: =AVERAGE(G36:J36) -> 274 | BU36: =AVERAGE(K36:N36) -> 283.25 | BV36: =AVERAGE(O36:R36) -> 299.25 | BW36: =AVERAGE(S36:V36) -> 315.5 | BX36: =AVERAGE(W36:Z36) -> 329.25 | BY36: =AVERAGE(AA36:AD36) -> 342 | BZ36: =AVERAGE(AE36:AH36) -> 350.25 | CA36: =AVERAGE(AI36:AL36) -> 360.75 | CB36: =AVERAGE(AM36:AP36) -> 372.25 | CC36: =AVERAGE(AQ36:AT36) -> 384.25 | CD36: =AVERAGE(AU36:AX36) -> 389.75 | CE36: =AVERAGE(AY36:BB36) -> 687.5 | CF36: =AVERAGE(BC36:BF36) -> 392.25 | CG36: =AVERAGE(BG36:BJ36) -> 391.575
B37: EPS | C37: =C35/C36 -> -0.047791165 | D37: =D35/D36 -> -0.028076923 | E37: =E35/E36 -> -0.048888889 | F37: =F35/F36 -> -0.046564885 | G37: =G35/G36 -> -0.05202952 | H37: =H35/H36 -> -0.053649635 | I37: =I35/I36 -> -0.062681159 | J37: =J35/J36 -> -0.030545455 | ... BL37: =BL35/BL36 -> 0.65175301 | BS37: =SUM(D37:G37) -> -0.17556022 | BT37: =SUM(H37:K37) -> -0.1866612 | BU37: =SUM(L37:O37) -> -0.10835945 | BV37: =SUM(P37:S37) -> -0.073989653 | BW37: =SUM(T37:W37) -> -0.20076405 | BX37: =SUM(X37:AA37) -> -0.2647469 | BY37: =SUM(AB37:AE37) -> -0.094510213 | BZ37: =SUM(AF37:AI37) -> -0.3652868 | CA37: =SUM(AJ37:AL37) -> 0.35071091 | CB37: =SUM(AM37:AP37) -> 1.4537795 | CC37: =SUM(AQ37:AT37) -> 0.56500028 | CD37: =SUM(AU37:AX37) -> 0.87517754 | CE37: =SUM(AY37:BB37) -> 0.78800426 | CF37: =SUM(BC37:BF37) -> 1.4696078 | CG37: =SUM(BG37:BJ37) -> 2.1380382
B39: Gross Profit Margin | C39: =C28/C26 -> 0.35915493 | D39: =D28/D26 -> 0.55607477 | E39: =E28/E26 -> 0.44808743 | F39: =F28/F26 -> 0.48 | G39: =G28/G26 -> 0.46766169 | H39: =H28/H26 -> 0.47863248 | I39: =I28/I26 -> 0.36363636 | J39: =J28/J26 -> 0.52852853 | ... BL39: =BL28/BL26 -> 0.63436258 | BS39: =BS28/BS26 -> 0.47120419 | BT39: =BT28/BT26 -> 0.46646647 | BU39: =BU28/BU26 -> 0.625625 | BV39: =BV28/BV26 -> 0.68016975 | BW39: =BW28/BW26 -> 0.69253731 | BX39: =BX28/BX26 -> 0.66003837 | BY39: =BY28/BY26 -> 0.6848991 | BZ39: =BZ28/BZ26 -> 0.6435634 | ... CG39: =CG28/CG26 -> 0.60100815 | CH39: 0.625 | CI39: 0.6275 | CJ39: 0.632 | CK39: 0.635 | CL39: 0.64 | CM39: 0.65 | CN39: 0.655 | CO39: 0.66 | CP39: 0.665 | CQ39: 0.67
B40: R&D as % of Revenue | C40: =C29/C26 -> 0.75352113 | D40: =D29/D26 -> 0.57009346 | E40: =E29/E26 -> 0.72131148 | F40: =F29/F26 -> 0.66222222 | G40: =G29/G26 -> 0.76616915 | H40: =H29/H26 -> 0.67948718 | I40: =I29/I26 -> 0.66666667 | J40: =J29/J26 -> 0.51951952 | ... BL40: =BL29/BL26 -> 0.11693672 | BS40: =BS29/BS26 -> 0.66753927 | BT40: =BT29/BT26 -> 0.64064064 | BU40: =BU29/BU26 -> 0.52625 | BV40: =BV29/BV26 -> 0.49537037 | BW40: =BW29/BW26 -> 0.49253731 | BX40: =BX29/BX26 -> 0.49921507 | BY40: =BY29/BY26 -> 0.48601253 | BZ40: =BZ29/BZ26 -> 0.41954246 | ... CG40: =CG29/CG26 -> 0.12850708 | CH40: 0.121 | CI40: 0.118 | CJ40: 0.116 | CK40: 0.114 | CL40: 0.116 | CM40: 0.115 | CN40: 0.114 | CO40: 0.113 | CP40: 0.112 | CQ40: 0.111
B41: SG&A as % of Revenue | C41: =C30/C26 -> 0.44366197 | D41: =D30/D26 -> 0.3271028 | E41: =E30/E26 -> 0.44808743 | F41: =F30/F26 -> 0.36 | G41: =G30/G26 -> 0.46766169 | H41: =H30/H26 -> 0.42735043 | I41: =I30/I26 -> 0.44588745 | J41: =J30/J26 -> 0.25825826 | ... BL41: =BL30/BL26 -> 0.27415164 | BS41: =BS30/BS26 -> 0.38743455 | BT41: =BT30/BT26 -> 0.38338338 | BU41: =BU30/BU26 -> 0.28 | BV41: =BV30/BV26 -> 0.26774691 | BW41: =BW30/BW26 -> 0.3420398 | BX41: =BX30/BX26 -> 0.27228327 | BY41: =BY30/BY26 -> 0.25803758 | BZ41: =BZ30/BZ26 -> 0.40461419 | ... CG41: =CG30/CG26 -> 0.27691978 | CH41: 0.285 | CI41: 0.275 | CJ41: 0.27 | CK41: 0.265 | CL41: 0.2635 | CM41: 0.26 | CN41: 0.2575 | CO41: 0.255 | CP41: 0.25 | CQ41: 0.245
B42: Operating Profit Margin | C42: =C31/C26 -> -0.83802817 | D42: =D31/D26 -> -0.3411215 | E42: =E31/E26 -> -0.72131148 | F42: =F31/F26 -> -0.54222222 | G42: =G31/G26 -> -0.76616915 | H42: =H31/H26 -> -0.62820513 | I42: =I31/I26 -> -0.74891775 | J42: =J31/J26 -> -0.24924925 | ... BL42: =BL31/BL26 -> 0.24327423 | BS42: =BS31/BS26 -> -0.58376963 | BT42: =BT31/BT26 -> -0.55755756 | BU42: =BU31/BU26 -> -0.180625 | BV42: =BV31/BV26 -> -0.082947531 | BW42: =BW31/BW26 -> -0.1420398 | BX42: =BX31/BX26 -> -0.11145997 | BY42: =BY31/BY26 -> -0.059151009 | BZ42: =BZ31/BZ26 -> -0.18059325 | ... CQ42: =CQ31/CQ26 -> 0.314
B43: Effective Tax Rate | C43: =C34/C33 -> 0 | D43: =D34/D33 -> 0 | E43: =E34/E33 -> 0 | F43: =F34/F33 -> 0 | G43: =G34/G33 -> 0.084415584 | H43: =H34/H33 -> 0 | I43: =I34/I33 -> 0 | J43: =J34/J33 -> 0 | ... BL43: =BL34/BL33 -> 0.21543307 | BS43: =BS34/BS33 -> 0 | BT43: =BT34/BT33 -> 0.023297491 | BU43: =BU34/BU33 -> 0 | BV43: =BV34/BV33 -> 0 | BW43: =BW34/BW33 -> 0 | BX43: =BX34/BX33 -> -0.010785824 | BY43: =BY34/BY33 -> -0.032921811 | BZ43: =BZ34/BZ33 -> -0.004743083 | ... CG43: =CG34/CG33 -> 0.2316244 | CH43: 0.22 | CI43: 0.21 | CJ43: 0.2 | CK43: 0.2 | CL43: 0.2 | CM43: 0.21 | CN43: 0.21 | CO43: 0.21 | CP43: 0.21 | CQ43: 0.21
B44: Net Profit Margin | C44: =C35/C26 -> -0.83802817 | D44: =D35/D26 -> -0.3411215 | E44: =E35/E26 -> -0.72131148 | F44: =F35/F26 -> -0.54222222 | G44: =G35/G26 -> -0.70149254 | H44: =H35/H26 -> -0.62820513 | I44: =I35/I26 -> -0.74891775 | J44: =J35/J26 -> -0.25225225 | ... BL44: =BL35/BL26 -> 0.1903852 | BS44: =BS35/BS26 -> -0.58376963 | BT44: =BT35/BT26 -> -0.54554555 | BU44: =BU35/BU26 -> -0.18625 | BV44: =BV35/BV26 -> -0.086033951 | BW44: =BW35/BW26 -> -0.14303483 | BX44: =BX35/BX26 -> -0.11442526 | BY44: =BY35/BY26 -> -0.06986778 | BZ44: =BZ35/BZ26 -> -0.12320667 | ... CG44: =CG35/CG26 -> 0.17938653 | CH44: 0.14287131 | CI44: 0.14287131 | CJ44: 0.14287131 | CK44: 0.14287131 | CL44: 0.14287131 | CM44: 0.14287131 | CN44: 0.14287131 | CO44: 0.14287131 | CP44: 0.14287131 | CQ44: 0.14287131
B46: Cash & CEs | AP46: 817.6 | AQ46: 733.8 | AR46: 1158.8 | AS46: 1444.3 | AT46: 1052.6 | AU46: 716 | AV46: 735.4 | AW46: 698.1 | AX46: 642.3 | AY46: 623.2 | AZ46: 1194.9 | BA46: 643.7 | BB46: 566.3 | BC46: 851.2 | BD46: 939.2 | BE46: 621.2 | BF46: 606.1 | BG46: 904.9 | BH46: 1159 | BI46: 1159 | BJ46: 917.7 | BK46: 1118.2 | BL46: 1105 | CB46: =AP46 -> 817.6 | CC46: =AT46 -> 1052.6 | CD46: =AX46 -> 642.3 | CE46: =BB46 -> 566.3 | CF46: =BF46 -> 606.1 | CG46: =BJ46 -> 917.7 | CH46: =CG46-CF64+CH35 -> 757.54952 | CI46: =CH46-CH64+CI35 -> 2093.9405 | CJ46: =CI46-CI64+CJ35 -> 3717.4844 | CK46: =CJ46-CJ64+CK35 -> 5643.2058 | CL46: =CK46-CK64+CL35 -> 7875.1573 | CM46: =CL46-CL64+CM35 -> 10494.871 | CN46: =CM46-CM64+CN35 -> 13540.009 | CO46: =CN46-CN64+CO35 -> 17068.002 | CP46: =CO46-CO64+CP35 -> 21168.37 | CQ46: =CP46-CP64+CQ35 -> 25916.526
B47: ST Investments | AP47: 1890.1 | AQ47: 1898.8 | AR47: 1426.1 | AS47: 1253.6 | AT47: 1678.6 | AU47: 1972.2 | AV47: 2019.4 | AW47: 1673.8 | AX47: 1813.9 | AY47: 1943.8 | AZ47: 2441.3 | BA47: 2596.6 | BB47: 2157.8 | BC47: 2045.8 | BD47: 2181.5 | BE47: 1871.1 | BF47: 1973.3 | BG47: 1796.5 | BH47: 1770 | BI47: 1770 | BJ47: 1081 | BK47: 1297 | BL47: 842 | CB47: =AP47 -> 1890.1 | CC47: =AT47 -> 1678.6 | CD47: =AX47 -> 1813.9 | CE47: =BB47 -> 2157.8 | CF47: =BF47 -> 1973.3 | CG47: =BJ47 -> 1081
B48: A/R | AP48: 428.5 | AQ48: 443.4 | AR48: 483.5 | AS48: 529.1 | AT48: 514.3 | AU48: 544.5 | AV48: 560.8 | AW48: 564.1 | AX48: 713.3 | AY48: 636.8 | AZ48: 750.6 | BA48: 785.7 | BB48: 973.9 | BC48: 978.6 | BD48: 945.2 | BE48: 1002 | BF48: 1005.7 | BG48: 1155.2 | BH48: 1348.8 | BI48: 1348.8 | BJ48: 1216.1 | BK48: 1088.6 | BL48: 1257.7 | CB48: =AP48 -> 428.5 | CC48: =AT48 -> 514.3 | CD48: =AX48 -> 713.3 | CE48: =BB48 -> 973.9 | CF48: =BF48 -> 1005.7 | CG48: =BJ48 -> 1216.1
...

Sheet Notes | Quant Analysis
CC1: 0
H2: Employee Scope: | AF2: General Notes/Observations (Updated Q1'25)
I33: Notes: | J33: Kevin Sayer serves as The Company's CEO
J34: [Y]
J35: [Z]
AF36: Financial Stmts. Notes/Observations
H37: Institutional Ownership Snapshot Q2'25 | AF37: Revenues:
I66: Notes: | J66: Alphabet Inc. (GOOG) holds a minority interest in DXCM (~0.27% stake) - just over a million shares … Investigate further … was there an old partnership or spin off?
K67: In August 2015, Dexcom entered a partnership with Google's life sciences team (which later became Verily) to jointly develop next-generation continuous glucose monitoring (CGM) products
K68: The collaboration aimed to combine Google’s miniaturized electronics platform with Dexcom's biometric sensor technologies
L69: This allowed the team to create smaller, less expensive and disposable CGM sensors without finger pricking … This is their patch business which relays data back to the DXCM app
K70: DXCM retained sales and distribution rights but made upfront and milestone payments to Google/Verily as part of the collab and licensing deal
L71: The partnership included Alphabet receiving over a billion shares of Dexcom via stock payments as part of licensing and collaboration agreements
K72: The collaboration involves ongoing joint product development, sharing R&D resources, and expanded options for joint ventures in diabetes technology
J73: [Y]
J74: [Z]
H76: Revenue Breakdown by Segment | AF76: Earnings Scope:
I108: Notes: | J108: [X]
J109: [Y]
J110: [Z]
H112: Q/q Total Revenues, Net Income, FCF | AF112: Balance Sheet Scope:
AF113: [Godel Snapshot of projected balances (assets, liabilities, equity)]
I141: Notes: | J141: [X]
J142: [Y]
J143: [Z]
H145: Y/y Total Revenues, Net Income, FCF | AF145: [Equity Preformance Compared to Peers]
I174: Notes: | J174: [X]
J175: [Y]
J176: [Z]
A192: 1256 Trading Days? (From: 9/13/2020 - 9/13/2025)
A193: Close | B193: High | C193: Low | D193: Open | E193: Volume | F193: UTC Date | G193: Change
A194: 76.22 | B194: 76.69 | C194: 75.39 | D194: 75.77 | E194: 2896173 | F194: Fri, 12 Sep 2025 00:00:00 GMT | G194: =A194/D194-1 -> 0.005939026
A195: 76 | B195: 77.93 | C195: 75.85 | D195: 76.24 | E195: 6307909 | F195: Thu, 11 Sep 2025 00:00:00 GMT | G195: =A195/D195-1 -> -0.0031479538
A196: 76 | B196: 78.28 | C196: 75.555 | D196: 77.97 | E196: 4887541 | F196: Wed, 10 Sep 2025 00:00:00 GMT | G196: =A196/D196-1 -> -0.025266128
A197: 78.4 | B197: 79.2 | C197: 77.61 | D197: 77.61 | E197: 2456957 | F197: Tue, 09 Sep 2025 00:00:00 GMT | G197: =A197/D197-1 -> 0.010179101
A198: 78 | B198: 79.65 | C198: 77.74 | D198: 79.35 | E198: 4033101 | F198: Mon, 08 Sep 2025 00:00:00 GMT | G198: =A198/D198-1 -> -0.017013233
A199: 80.51 | B199: 81.6 | C199: 79.48 | D199: 80.875 | E199: 2672319 | F199: Fri, 05 Sep 2025 00:00:00 GMT | G199: =A199/D199-1 -> -0.0045131376
A200: 80.76 | B200: 81.64 | C200: 78.68 | D200: 79.2 | E200: 4871874 | F200: Thu, 04 Sep 2025 00:00:00 GMT | G200: =A200/D200-1 -> 0.01969697
A201: 78.92 | B201: 79.51 | C201: 74 | D201: 74.32 | E201: 6700804 | F201: Wed, 03 Sep 2025 00:00:00 GMT | G201: =A201/D201-1 -> 0.06189451
A202: 74.3 | B202: 75.1073 | C202: 73.47 | D202: 74.17 | E202: 4415603 | F202: Tue, 02 Sep 2025 00:00:00 GMT | G202: =A202/D202-1 -> 0.0017527302
...

Sheet Product Lines

Sheet Management

Sheet Table Formatting
B2: [Bold Title] | G2: [Bold Title]
B3: Line Titles | G3: <-- General
B4: Line Titles | G4: <-- Info
B5: Line Titles | G5: <-- General
B6: Line Titles | G6: <-- Info
B7: Line Titles | G7: <-- General
B8: Line Titles | G8: <-- Info
