Workbook

Sheet Main
B2: FIG
B3: Price | C3: 23.95 | D3: 10/22/2026
B4: SO | C4: 455.1136 | D4: Q2'26
B5: MC | C5: =C3*C4 -> 10899.971
B6: Cash | C6: =15.82+1221.293+445.845 -> 1682.958 | D6: Q2'26
B7: Debt | C7: 0 | D7: Q2'26
B8: EV | C8: =C5-C6+C7 -> 9217.0127
B10: Figma, Inc. (FIG)
B12: Founder(s): Dylan Field and Evan Wallace | F12: Registered Exchange: NASDAQ | N12: Resources:
B13: Founded: 2012 | F13: Address: 760 Market Street, San Francisco, CA 94102 U.S. | N13: SEC filings | Q13: https://www.sec.gov/edgar/browse/?CIK=1579878&owner=exclude
B14: Headquarters: San Francisco, CA | F14: Investor Relations Contact: | N14: Company Homepage | Q14: https://www.figma.com/
B15: Current CEO: Dylan Field | F15: Investors Relation Department | O15: Company IR Page | R15: https://investor.figma.com/overview/default.aspx
B16: Employees: 1,886 | F16: Phone: | G16: (415) 890 - 5404 | I16: Email: | N16: Earnings Calls | Q16: https://seekingalpha.com/symbol/FIG/earnings/transcripts
B17: Industry: Software Services | N17: Equity Analysis | Q17: https://stockanalysis.com/stocks/fig/company/
B18: Sector: Technology | N18: MacroTrends | Q18: https://www.macrotrends.net/stocks/charts/FIG/figma/income-statement
B19: IPO: Jul 31, 2025 -- $19.3B valuation | N19: ROIC, WACC | Q19: https://www.gurufocus.com/term/wacc/FIG
B20: Fiscal Year: [January - December] | N20: Godel Terminal | Q20: https://app.godelterminal.com/
A22: Company Overview:
B23: Figma, Inc. develops and sells a collaborative, browser-based platform for designing, prototyping, building digital experiences, and subscriptions for access to its platform
B24: The Company offers Figma Design, a collaborative design tool for teams that explore ideas and gather feedback, build realistic prototypes, and streamline product development with design systems
C25: Dev Mode to inspect designs and translate them into code without changing the design file
C26: FigJam to define ideas, align decisions, and move work forward—all in one place
C27: Figma Slides, a presentation tool built for designers and their teams
B28: It also provides Figma Draw to create expressive designs with illustration tools; Figma Buzz, which publishes brand templates to create social media assets, display ads, one-pagers, and others
C29: Figma Sites to design, prototype, and publish; Payload CMS is an open-source, headless content management system and application framework acquired by Figma; Figma Make, an AI tool to design and prompt way to a functional prototype; Figma Weave for AI-powered media generation and editing
B30: The Company was incorporated in 2012 and is headquartered in San Francisco, California
A32: Business Segments and Geographical Info:

Sheet Model
B1: [Use for Graphing] | C1: Q1 2024 | G1: Q1 2025 | K1: Q1 2026
B2: Quarterly
B3: Revenues | C3: {="Q"&MOD(_xlfn.SEQUENCE(1,12)-1,4)+1&" "&(2024+INT((_xlfn.SEQUENCE(1,12)-1)/4))} -> Q1 2024 | D3: Q2 2024 | E3: Q3 2024 | F3: Q4 2024 | G3: Q1 2025 | H3: Q2 2025 | I3: Q3 2025 | J3: Q4 2025 | K3: Q1 2026 | L3: Q2 2026 | M3: Q3 2026 | N3: Q4 2026 | R3: 2023 | S3: 2024 | T3: =S3+1 -> 2025 | U3: =T3+1 -> 2026 | V3: =U3+1 -> 2027 | W3: =V3+1 -> 2028 | X3: =W3+1 -> 2029 | Y3: =X3+1 -> 2030 | Z3: =Y3+1 -> 2031 | AA3: =Z3+1 -> 2032 | ... CB3: =CA3+1 -> 2085
B4: U.S. Revenues | C4: 73 | D4: 85.198 | E4: 94.668 | F4: =359.406-SUM(C4:E4) -> 106.54 | G4: 107.463 | H4: 116.766 | I4: 126.792 | J4: =491.548-SUM(G4:I4) -> 140.527 | K4: 155.051 | L4: 170.794 | R4: 252.289 | S4: =SUM(C4:F4) -> 359.406 | T4: =SUM(G4:J4) -> 491.548 | U4: =T4*(1+U8) -> 712.7446 | V4: =U4*(1+V8) -> 983.58755 | W4: =V4*(1+W8) -> 1308.1714 | X4: =W4*(1+X8) -> 1661.3777 | Y4: =X4*(1+Y8) -> 2043.4946 | Z4: =Y4*(1+Z8) -> 2452.1935 | AA4: =Z4*(1+AA8) -> 2869.0664 | AB4: =AA4*(1+AB8) -> 3270.7357 | ... AD4: =AC4*(1+AD8) -> 3957.2632
B5: International Revenues | C5: 83.2 | D5: 92 | E5: 103.971 | F5: =389.605-SUM(C5:E5) -> 110.434 | G5: 120.736 | H5: 132.874 | I5: 147.381 | J5: =564.24-SUM(G5:I5) -> 163.249 | K5: 178.388 | L5: 199.289 | R5: 252.585 | S5: =SUM(C5:F5) -> 389.605 | T5: =SUM(G5:J5) -> 564.24 | U5: =T5*(1+U9) -> 835.0752 | V5: =U5*(1+V9) -> 1185.8068 | W5: =V5*(1+W9) -> 1612.6972 | X5: =W5*(1+X9) -> 2112.6334 | Y5: =X5*(1+Y9) -> 2661.918 | Z5: =Y5*(1+Z9) -> 3220.9208 | AA5: =Z5*(1+AA9) -> 3800.6866 | AB5: =AA5*(1+AB9) -> 4408.7964 | ... AD5: =AC5*(1+AD9) -> 5629.1513
B6: Ttl Revenues | C6: =SUM(C4:C5) -> 156.2 | D6: =SUM(D4:D5) -> 177.198 | E6: =SUM(E4:E5) -> 198.639 | F6: =SUM(F4:F5) -> 216.974 | G6: =SUM(G4:G5) -> 228.199 | H6: =SUM(H4:H5) -> 249.64 | I6: =SUM(I4:I5) -> 274.173 | J6: =SUM(J4:J5) -> 303.776 | ... L6: =SUM(L4:L5) -> 370.083 | R6: =SUM(R4:R5) -> 504.874 | S6: =SUM(C6:F6) -> 749.011 | T6: =SUM(G6:J6) -> 1055.788 | U6: =U4+U5 -> 1547.8198 | V6: =V4+V5 -> 2169.3943 | W6: =W4+W5 -> 2920.8687 | X6: =X4+X5 -> 3774.0111 | Y6: =Y4+Y5 -> 4705.4126 | Z6: =Z4+Z5 -> 5673.1144 | AA6: =AA4+AA5 -> 6669.753 | AB6: =AB4+AB5 -> 7679.5322 | ... AD6: =AD4+AD5 -> 9586.4144
B8: U.S. Growth Y/y | G8: =G4/C4-1 -> 0.47209589 | H8: =H4/D4-1 -> 0.37052513 | I8: =I4/E4-1 -> 0.33933325 | J8: =J4/F4-1 -> 0.31900695 | K8: =K4/G4-1 -> 0.44283149 | L8: =L4/H4-1 -> 0.46270318 | S8: =S4/R4-1 -> 0.42458054 | T8: =T4/S4-1 -> 0.36766776 | U8: 0.45 | V8: 0.38 | W8: 0.33 | X8: 0.27 | Y8: 0.23 | Z8: 0.2 | AA8: 0.17 | AB8: 0.14 | AC8: 0.11 | AD8: 0.09
B9: International Growth Y/y | G9: =G5/C5-1 -> 0.45115385 | H9: =H5/D5-1 -> 0.44428261 | I9: =I5/E5-1 -> 0.41752027 | J9: =J5/F5-1 -> 0.47824945 | K9: =K5/G5-1 -> 0.47750464 | L9: =L5/H5-1 -> 0.49983443 | S9: =S5/R5-1 -> 0.54247085 | T9: =T5/S5-1 -> 0.44823603 | U9: 0.48 | V9: 0.42 | W9: 0.36 | X9: 0.31 | Y9: 0.26 | Z9: 0.21 | AA9: 0.18 | AB9: 0.16 | AC9: 0.14 | AD9: 0.12
B10: Ttl Revenue Growth Y/y | G10: =G6/C6-1 -> 0.4609411 | H10: =H6/D6-1 -> 0.40881951 | I10: =I6/E6-1 -> 0.38025765 | J10: =J6/F6-1 -> 0.40005715 | K10: =K6/G6-1 -> 0.46117643 | L10: =L6/H6-1 -> 0.48246675 | S10: =S6/R6-1 -> 0.48356025 | T10: =T6/S6-1 -> 0.40957609 | U10: =U6/T6-1 -> 0.46603276 | V10: =V6/U6-1 -> 0.40158068 | W10: =W6/V6-1 -> 0.34639822 | X10: =X6/W6-1 -> 0.29208517 | Y10: =Y6/X6-1 -> 0.24679354 | Z10: =Z6/Y6-1 -> 0.20565714 | ... AD10: =AD6/AC6-1 -> 0.10741813
B12: U.S. % of Revenues | C12: =C4/C6 -> 0.46734955 | D12: =D4/D6 -> 0.48080678 | E12: =E4/E6 -> 0.47658315 | F12: =F4/F6 -> 0.49102657 | G12: =G4/G6 -> 0.47091793 | H12: =H4/H6 -> 0.46773754 | I12: =I4/I6 -> 0.46245254 | J12: =J4/J6 -> 0.46260073 | ... L12: =L4/L6 -> 0.46150188 | R12: =R4/R6 -> 0.49970686 | S12: =S4/S6 -> 0.47984075 | T12: =T4/T6 -> 0.46557453
B13: International % of Revenues | C13: =C5/C6 -> 0.53265045 | D13: =D5/D6 -> 0.51919322 | E13: =E5/E6 -> 0.52341685 | F13: =F5/F6 -> 0.50897343 | G13: =G5/G6 -> 0.52908207 | H13: =H5/H6 -> 0.53226246 | I13: =I5/I6 -> 0.53754746 | J13: =J5/J6 -> 0.53739927 | ... L13: =L5/L6 -> 0.53849812 | R13: =R5/R6 -> 0.50029314 | S13: =S5/S6 -> 0.52015925 | T13: =T5/T6 -> 0.53442547
B15: Revenues | C15: =C6 -> 156.2 | D15: =D6 -> 177.198 | E15: =E6 -> 198.639 | F15: =F6 -> 216.974 | G15: =G6 -> 228.199 | H15: =H6 -> 249.64 | I15: =I6 -> 274.173 | J15: =J6 -> 303.776 | ... L15: =L6 -> 370.083 | R15: =R6 -> 504.874 | S15: =SUM(C15:F15) -> 749.011 | T15: =SUM(G15:J15) -> 1055.788 | U15: =U6 -> 1547.8198 | V15: =V6 -> 2169.3943 | W15: =W6 -> 2920.8687 | X15: =X6 -> 3774.0111 | Y15: =Y6 -> 4705.4126 | Z15: =Z6 -> 5673.1144 | AA15: =AA6 -> 6669.753 | AB15: =AB6 -> 7679.5322 | ... AD15: =AD6 -> 9586.4144
B16: COGS | C16: 12.79 | D16: 39.558 | E16: 18.703 | F16: =87.514-SUM(C16:E16) -> 16.463 | G16: 19.452 | H16: 27.889 | I16: 83.884 | J16: =185.527-SUM(G16:I16) -> 54.302 | K16: 68.666 | L16: 60.472 | R16: 44.5 | S16: =SUM(C16:F16) -> 87.514 | T16: =SUM(G16:J16) -> 185.527 | U16: =U15*(1-U31) -> 271.98866 | V16: =V15*(1-V31) -> 381.21405 | W16: =W15*(1-W31) -> 513.26592 | X16: =X15*(1-X31) -> 663.18329 | Y16: =Y15*(1-Y31) -> 826.85264 | Z16: =Z15*(1-Z31) -> 996.90079 | AA16: =AA15*(1-AA31) -> 1172.0338 | AB16: =AB15*(1-AB31) -> 1349.476 | ... AD16: =AD15*(1-AD31) -> 1684.5605
B17: GP | C17: =C15-C16 -> 143.41 | D17: =D15-D16 -> 137.64 | E17: =E15-E16 -> 179.936 | F17: =F15-F16 -> 200.511 | G17: =G15-G16 -> 208.747 | H17: =H15-H16 -> 221.751 | I17: =I15-I16 -> 190.289 | J17: =J15-J16 -> 249.474 | ... L17: =L15-L16 -> 309.611 | R17: =R15-R16 -> 460.374 | S17: =SUM(C17:F17) -> 661.497 | T17: =SUM(G17:J17) -> 870.261 | U17: =U15*U31 -> 1275.8311 | V17: =V15*V31 -> 1788.1803 | W17: =W15*W31 -> 2407.6027 | X17: =X15*X31 -> 3110.8278 | Y17: =Y15*Y31 -> 3878.56 | Z17: =Z15*Z31 -> 4676.2136 | AA17: =AA15*AA31 -> 5497.7192 | AB17: =AB15*AB31 -> 6330.0562 | ... AD17: =AD15*AD31 -> 7901.854
B18: R&D | C18: 52.711 | D18: 535.676 | E18: 104.182 | F18: =751.12-SUM(C18:E18) -> 58.551 | G18: 69.925 | H18: 83.052 | I18: 680.885 | J18: =1029.7-SUM(G18:I18) -> 195.838 | K18: 172.974 | L18: 167.329 | R18: 164.774 | S18: =SUM(C18:F18) -> 751.12 | T18: =SUM(G18:J18) -> 1029.7 | U18: =U15*U32 -> 742.9535 | V18: =V15*V32 -> 954.53351 | W18: =W15*W32 -> 1197.5562 | X18: =X15*X32 -> 1434.1242 | Y18: =Y15*Y32 -> 1646.8944 | Z18: =Z15*Z32 -> 1928.8589 | AA18: =AA15*AA32 -> 2201.0185 | AB18: =AB15*AB32 -> 2457.4503 | ... AD18: =AD15*AD32 -> 2875.9243
B19: S&M | C19: 55.334 | D19: 276.246 | E19: 79.29 | F19: =472.076-SUM(C19:E19) -> 61.206 | G19: 68.84 | H19: 97.701 | I19: 274.759 | J19: =575.508-SUM(G19:I19) -> 134.208 | K19: 125.568 | L19: 154.856 | R19: 201.377 | S19: =SUM(C19:F19) -> 472.076 | T19: =SUM(G19:J19) -> 575.508 | U19: =U15*U33 -> 588.17152 | V19: =V15*V33 -> 780.98196 | W19: =W15*W33 -> 993.09535 | X19: =X15*X33 -> 1207.6835 | Y19: =Y15*Y33 -> 1411.6238 | Z19: =Z15*Z33 -> 1645.2032 | AA19: =AA15*AA33 -> 1867.5308 | AB19: =AB15*AB33 -> 2073.4737 | ... AD19: =AD15*AD33 -> 2396.6036
B20: G&A | C20: 22.873 | D20: 220.005 | E20: 43.8 | F20: =315.734-SUM(C20:E20) -> 29.056 | G20: 30.233 | H20: 38.922 | I20: 371.425 | J20: =555.51-SUM(G20:I20) -> 114.93 | K20: 103.629 | L20: 104.715 | R20: 167.679 | S20: =SUM(C20:F20) -> 315.734 | T20: =SUM(G20:J20) -> 555.51 | U20: =U15*U34 -> 433.38954 | V20: =V15*V34 -> 542.34858 | W20: =W15*W34 -> 642.59111 | X20: =X15*X34 -> 717.06211 | Y20: =Y15*Y34 -> 799.92015 | Z20: =Z15*Z34 -> 850.96715 | AA20: =AA15*AA34 -> 867.06789 | AB20: =AB15*AB34 -> 921.54386 | ... AD20: =AD15*AD34 -> 958.64144
B21: OI | C21: =C17-SUM(C18:C20) -> 12.492 | D21: =D17-SUM(D18:D20) -> -894.287 | E21: =E17-SUM(E18:E20) -> -47.336 | F21: =F17-SUM(F18:F20) -> 51.698 | G21: =G17-SUM(G18:G20) -> 39.749 | H21: =H17-SUM(H18:H20) -> 2.076 | I21: =I17-SUM(I18:I20) -> -1136.78 | J21: =J17-SUM(J18:J20) -> -195.502 | ... L21: =L17-SUM(L18:L20) -> -117.289 | R21: =R17-SUM(R18:R20) -> -73.456 | S21: =SUM(C21:F21) -> -877.433 | T21: =SUM(G21:J21) -> -1290.457 | U21: =U17-SUM(U18:U20) -> -488.68343 | V21: =V17-SUM(V18:V20) -> -489.68377 | W21: =W17-SUM(W18:W20) -> -425.63986 | X21: =X17-SUM(X18:X20) -> -248.04207 | Y21: =Y17-SUM(Y18:Y20) -> 20.121639 | Z21: =Z17-SUM(Z18:Z20) -> 251.18437 | AA21: =AA17-SUM(AA18:AA20) -> 562.10194 | AB21: =AB17-SUM(AB18:AB20) -> 877.58833 | ... AD21: =AD17-SUM(AD18:AD20) -> 1670.6846
B22: Other Income | C22: 17.185 | D22: 10.139 | E22: 17.91 | F22: =84.362-SUM(C22:E22) -> 39.128 | G22: 7.274 | H22: 36.978 | I22: 29.305 | J22: =64.815-SUM(G22:I22) -> -8.742 | K22: -4.325 | L22: 7.614 | R22: 1019.375 | S22: =SUM(C22:F22) -> 84.362 | T22: =SUM(G22:J22) -> 64.815 | U22: =SUM(T39:T41)*($AN$39) -> 334.3036 | V22: =SUM(U39:U41)*($AN$39) -> 302.81011 | W22: =SUM(V39:V41)*($AN$39) -> 264.68789 | X22: =SUM(W39:W41)*($AN$39) -> 231.85369 | Y22: =SUM(X39:X41)*($AN$39) -> 228.55126 | Z22: =SUM(Y39:Y41)*($AN$39) -> 279.28053 | AA22: =SUM(Z39:Z41)*($AN$39) -> 387.49537 | AB22: =SUM(AA39:AA41)*($AN$39) -> 581.21322 | ... AD22: =SUM(AC39:AC41)*($AN$39) -> 1312.8683
B23: Pretax Income | C23: =C21+C22 -> 29.677 | D23: =D21+D22 -> -884.148 | E23: =E21+E22 -> -29.426 | F23: =F21+F22 -> 90.826 | G23: =G21+G22 -> 47.023 | H23: =H21+H22 -> 39.054 | I23: =I21+I22 -> -1107.475 | J23: =J21+J22 -> -204.244 | ... L23: =L21+L22 -> -109.675 | R23: =R21+R22 -> 945.919 | S23: =SUM(C23:F23) -> -793.071 | T23: =SUM(G23:J23) -> -1225.642 | U23: =U21+U22 -> -154.37983 | V23: =V21+V22 -> -186.87366 | W23: =W21+W22 -> -160.95197 | X23: =X21+X22 -> -16.188381 | Y23: =Y21+Y22 -> 248.6729 | Z23: =Z21+Z22 -> 530.4649 | AA23: =AA21+AA22 -> 949.59731 | AB23: =AB21+AB22 -> 1458.8015 | ... AD23: =AD21+AD22 -> 2983.5529
B24: Taxes | C24: 16.181 | D24: -56.294 | E24: -13.828 | F24: =-60.951-SUM(C24:E24) -> -7.01 | G24: 2.141 | H24: 10.827 | I24: -10.46 | J24: =24.821-SUM(G24:I24) -> 22.313 | K24: 0.678 | L24: 2.477 | R24: 208.078 | S24: =SUM(C24:F24) -> -60.951 | T24: =SUM(G24:J24) -> 24.821 | U24: =U23*U36 -> 3.0875967 | V24: =V23*V36 -> 3.7374731 | W24: =W23*W36 -> 3.2190395 | X24: =X23*X36 -> 0.32376761 | Y24: =Y23*Y36 -> -4.9734579 | Z24: =Z23*Z36 -> -10.609298 | AA24: =AA23*AA36 -> -18.991946 | AB24: =AB23*AB36 -> -29.176031 | ... AD24: =AD23*AD36 -> -59.671057
B25: Net Income | C25: =C23-C24 -> 13.496 | D25: =D23-D24 -> -827.854 | E25: =E23-E24 -> -15.598 | F25: =F23-F24 -> 97.836 | G25: =G23-G24 -> 44.882 | H25: =H23-H24 -> 28.227 | I25: =I23-I24 -> -1097.015 | J25: =J23-J24 -> -226.557 | ... L25: =L23-L24 -> -112.152 | R25: =R23-R24 -> 737.841 | S25: =SUM(C25:F25) -> -732.12 | T25: =SUM(G25:J25) -> -1250.463 | U25: =U23-U24 -> -157.46743 | V25: =V23-V24 -> -190.61113 | W25: =W23-W24 -> -164.17101 | X25: =X23-X24 -> -16.512148 | Y25: =Y23-Y24 -> 253.64635 | Z25: =Z23-Z24 -> 541.0742 | AA25: =AA23-AA24 -> 968.58925 | AB25: =AB23-AB24 -> 1487.9776 | ... AD25: =AD23-AD24 -> 3043.2239
B26: non-controlling interests | C26: -13.525 | D26: 0 | E26: 0 | F26: =0-SUM(C26:E26) -> 13.525 | G26: -36.271 | H26: -27.381 | I26: 0 | J26: =0-SUM(G26:I26) -> 63.652 | K26: 0 | L26: 0 | R26: -451.982 | S26: =SUM(C26:F26) -> 0 | T26: =SUM(G26:J26) -> 0 | U26: 0 | V26: 0 | W26: 0 | X26: 0 | Y26: 0 | Z26: 0 | AA26: 0 | AB26: 0 | AC26: 0 | AD26: 0
B27: Net Income attr to FIG | C27: =C25+C26 -> -0.029 | D27: =D25+D26 -> -827.854 | E27: =E25+E26 -> -15.598 | F27: =F25+F26 -> 111.361 | G27: =G25+G26 -> 8.611 | H27: =H25+H26 -> 0.846 | I27: =I25+I26 -> -1097.015 | J27: =J25+J26 -> -162.905 | ... L27: =L25+L26 -> -112.152 | R27: =R25+R26 -> 285.859 | S27: =SUM(C27:F27) -> -732.12 | T27: =SUM(G27:J27) -> -1250.463 | U27: =U25+U26 -> -157.46743 | V27: =V25+V26 -> -190.61113 | W27: =W25+W26 -> -164.17101 | X27: =X25+X26 -> -16.512148 | Y27: =Y25+Y26 -> 253.64635 | Z27: =Z25+Z26 -> 541.0742 | AA27: =AA25+AA26 -> 968.58925 | AB27: =AB25+AB26 -> 1487.9776 | ... AD27: =AD25+AD26 -> 3043.2239 | AE27: =AD27*(1+$AN$40) -> 3111.6964 | AF27: =AE27*(1+$AN$40) -> 3181.7096 | AG27: =AF27*(1+$AN$40) -> 3253.2981 | AH27: =AG27*(1+$AN$40) -> 3326.4973 | AI27: =AH27*(1+$AN$40) -> 3401.3435 | AJ27: =AI27*(1+$AN$40) -> 3477.8737 | AK27: =AJ27*(1+$AN$40) -> 3556.1259 | AL27: =AK27*(1+$AN$40) -> 3636.1387 | ... CB27: =CA27*(1+$AN$40) -> 9257.6283
B28: SC | C28: 180.6 | D28: 188.782 | E28: 210.768 | F28: 195.612 | G28: 214.883 | H28: 215.062 | I28: 403.212 | J28: 337.044 | K28: 523.485 | L28: 527.46 | R28: 168.399 | S28: =AVERAGE(C28:F28) -> 193.9405 | T28: =AVERAGE(G28:J28) -> 292.55025
B29: EPS | C29: =C27/C28 -> -0.00016057586 | D29: =D27/D28 -> -4.385238 | E29: =E27/E28 -> -0.074005542 | F29: =F27/F28 -> 0.56929534 | G29: =G27/G28 -> 0.04007297 | H29: =H27/H28 -> 0.0039337493 | I29: =I27/I28 -> -2.7206904 | J29: =J27/J28 -> -0.48333452 | ... L29: =L27/L28 -> -0.21262655 | R29: =R27/R28 -> 1.6975101 | S29: =SUM(C29:F29) -> -3.8901088 | T29: =SUM(G29:J29) -> -3.1600182
B31: Gross Profit Margin | C31: =C17/C15 -> 0.9181178 | D31: =D17/D15 -> 0.7767582 | E31: =E17/E15 -> 0.90584427 | F31: =F17/F15 -> 0.92412455 | G31: =G17/G15 -> 0.91475861 | H31: =H17/H15 -> 0.88828313 | I31: =I17/I15 -> 0.69404719 | J31: =J17/J15 -> 0.82124328 | ... L31: =L17/L15 -> 0.83659882 | R31: =R17/R15 -> 0.9118592 | S31: =S17/S15 -> 0.88316059 | T31: =T17/T15 -> 0.82427628 | U31: 0.82427628 | V31: 0.82427628 | W31: 0.82427628 | X31: 0.82427628 | Y31: 0.82427628 | Z31: 0.82427628 | AA31: 0.82427628 | AB31: 0.82427628 | AC31: 0.82427628 | AD31: 0.82427628
B32: R&D as % of Revenue | C32: =C18/C15 -> 0.33745839 | D32: =D18/D15 -> 3.0230364 | E32: =E18/E15 -> 0.52447908 | F32: =F18/F15 -> 0.26985261 | G32: =G18/G15 -> 0.30642115 | H32: =H18/H15 -> 0.33268707 | I32: =I18/I15 -> 2.4834138 | J32: =J18/J15 -> 0.64467897 | ... L32: =L18/L15 -> 0.45213911 | R32: =R18/R15 -> 0.32636658 | S32: =S18/S15 -> 1.0028157 | T32: =T18/T15 -> 0.97529049 | U32: 0.48 | V32: 0.44 | W32: 0.41 | X32: 0.38 | Y32: 0.35 | Z32: 0.34 | AA32: 0.33 | AB32: 0.32 | AC32: 0.31 | AD32: 0.3
B33: S&M as % of Revenue | C33: =C19/C15 -> 0.35425096 | D33: =D19/D15 -> 1.5589679 | E33: =E19/E15 -> 0.39916633 | F33: =F19/F15 -> 0.2820891 | G33: =G19/G15 -> 0.30166653 | H33: =H19/H15 -> 0.39136757 | I33: =I19/I15 -> 1.0021373 | J33: =J19/J15 -> 0.44179922 | ... L33: =L19/L15 -> 0.41843586 | R33: =R19/R15 -> 0.39886586 | S33: =S19/S15 -> 0.63026578 | T33: =T19/T15 -> 0.54509807 | U33: 0.38 | V33: 0.36 | W33: 0.34 | X33: 0.32 | Y33: 0.3 | Z33: 0.29 | AA33: 0.28 | AB33: 0.27 | AC33: 0.26 | AD33: 0.25
B34: G&A as % of Revenue | C34: =C20/C15 -> 0.14643406 | D34: =D20/D15 -> 1.2415772 | E34: =E20/E15 -> 0.22050051 | F34: =F20/F15 -> 0.13391466 | G34: =G20/G15 -> 0.13248524 | H34: =H20/H15 -> 0.15591251 | I34: =I20/I15 -> 1.3547103 | J34: =J20/J15 -> 0.37833799 | ... L34: =L20/L15 -> 0.28295004 | R34: =R20/R15 -> 0.33212049 | S34: =S20/S15 -> 0.42153453 | T34: =T20/T15 -> 0.52615677 | U34: 0.28 | V34: 0.25 | W34: 0.22 | X34: 0.19 | Y34: 0.17 | Z34: 0.15 | AA34: 0.13 | AB34: 0.12 | AC34: 0.11 | AD34: 0.1
B35: Operating Profit Margin | C35: =C21/C15 -> 0.079974392 | D35: =D21/D15 -> -5.0468233 | E35: =E21/E15 -> -0.23830164 | F35: =F21/F15 -> 0.23826818 | G35: =G21/G15 -> 0.17418569 | H35: =H21/H15 -> 0.008315975 | I35: =I21/I15 -> -4.1462143 | J35: =J21/J15 -> -0.6435729 | ... L35: =L21/L15 -> -0.3169262 | R35: =R21/R15 -> -0.14549373 | S35: =S21/S15 -> -1.1714554 | T35: =T21/T15 -> -1.2222691 | U35: =U21/U15 -> -0.31572372 | V35: =V21/V15 -> -0.22572372 | W35: =W21/W15 -> -0.14572372 | X35: =X21/X15 -> -0.065723725 | Y35: =Y21/Y15 -> 0.0042762752 | ... AD35: =AD21/AD15 -> 0.17427628
B36: Effective Tax Rate | C36: =C24/C23 -> 0.54523705 | D36: =D24/D23 -> 0.063670336 | E36: =E24/E23 -> 0.46992456 | F36: =F24/F23 -> -0.077180543 | G36: =G24/G23 -> 0.04553091 | H36: =H24/H23 -> 0.27723153 | I36: =I24/I23 -> 0.0094449085 | J36: =J24/J23 -> -0.10924678 | ... L36: =L24/L23 -> -0.02258491 | R36: =R24/R23 -> 0.21997444 | S36: =S24/S23 -> 0.076854405 | T36: =T24/T23 -> -0.020251427 | U36: -0.02 | V36: -0.02 | W36: -0.02 | X36: -0.02 | Y36: -0.02 | Z36: -0.02 | AA36: -0.02 | AB36: -0.02 | AC36: -0.02 | AD36: -0.02
B37: Net Profit Margin | C37: =C27/C15 -> -0.00018565941 | D37: =D27/D15 -> -4.671915 | E37: =E27/E15 -> -0.078524358 | F37: =F27/F15 -> 0.51324583 | G37: =G27/G15 -> 0.037734609 | H37: =H27/H15 -> 0.00338888 | I37: =I27/I15 -> -4.0011781 | J37: =J27/J15 -> -0.53626685 | ... L37: =L27/L15 -> -0.30304553 | R37: =R27/R15 -> 0.5661987 | S37: =S27/S15 -> -0.97744893 | T37: =T27/T15 -> -1.1843883 | U37: =U27/U15 -> -0.10173499 | V37: =V27/V15 -> -0.087863753 | W37: =W27/W15 -> -0.056206229 | X37: =X27/X15 -> -0.0043752252 | Y37: =Y27/Y15 -> 0.053905231 | ... AD37: =AD27/AD15 -> 0.31745174
B39: Cash & CEs | F39: 486.954 | G39: 571 | H39: 621.619 | I39: 340.485 | J39: 403.469 | K39: 405.654 | L39: 445.845 | S39: =F39 -> 486.954 | T39: =J39 -> 403.469 | U39: =SUM(T39:T41)+U27 -> 1514.0506 | V39: =U39+V27 -> 1323.4394 | W39: =V39+W27 -> 1159.2684 | X39: =W39+X27 -> 1142.7563 | Y39: =X39+Y27 -> 1396.4026 | Z39: =Y39+Z27 -> 1937.4768 | AA39: =Z39+AA27 -> 2906.0661 | AB39: =AA39+AB27 -> 4394.0437 | AC39: =AB39+AC27 -> 6564.3413 | AD39: =AC39+AD27 -> 9607.5652 | AF39: Invested Capital | AI39: Avg. (2024-2025) | AK39: Projected ROIC: | AM39: ROIC | AN39: 0.2
B40: ST Investments | F40: 0 | G40: 0 | H40: 30.136 | I40: 30.32 | J40: 15.575 | K40: 15.696 | L40: 15.82 | S40: =F40 -> 0 | T40: =J40 -> 15.575 | AF40: 2024 | AG40: 2025 | AI40: 2024-2025 | AK40: 2025 | AM40: Terminal | AN40: 0.0225
B41: Marketable Securities | F41: 970.883 | G41: 970.8 | H41: 971.719 | I41: 1237.048 | J41: 1252.474 | K41: 1232.81 | L41: 1221.293 | S41: =F41 -> 970.883 | T41: =J41 -> 1252.474 | AF41: =SUM(S39:S43)-S53+S46+S48+S47 -> 1676.577 | AG41: =SUM(T39:T43)-T53+T46+T48+T47 -> 2174.121 | AI41: =AVERAGE(AF41:AG41) -> 1925.349 | AK41: =U21*(1-U36) -> -498.4571 | AM41: RFR (10-year yield) | AN41: =AI50 -> 0.0517
B42: A/R | F42: 131.315 | G42: 373 | H42: 124.721 | I42: 156.004 | J42: 247.915 | K42: 188.351 | L42: 190.876 | S42: =F42 -> 131.315 | T42: =J42 -> 247.915 | AK42: =AK41/AI41 -> -0.25889182 | AM42: ERP (Avg. market return - (less) RFR) | AN42: =9.5%-AN41 -> 0.0433
B43: Other ST Assets | F43: 48.873 | H43: 60.059 | I43: 79.904 | J43: 85.267 | K43: 93.882 | L43: 103.206 | S43: =F43 -> 48.873 | T43: =J43 -> 85.267 | AF43: Capital Structure | AM43: Equity β (1-year avg.) | AN43: ='Notes | Quant Analysis'!S206 -> 1.604688
B44: PP&E | F44: 15.017 | H44: 16.593 | I44: 17.946 | J44: 19.996 | K44: 30.982 | L44: 38.321 | S44: =F44 -> 15.017 | T44: =J44 -> 19.996 | AF44: Mkt Cap | AI44: =Main!C5 -> 10899.971 | AM44: Discount (Cost of Equity) | AN44: =+AN41+(AN42*AN43) -> 0.12118299
B45: LT Investments | F45: 0 | H45: 0 | I45: 0 | J45: 19.083 | K45: 12.663 | L45: 13.371 | S45: =F45 -> 0 | T45: =J45 -> 19.083 | AF45: Debt to Ttl Mkt Cap | AI45: =Main!C7/(Main!C7+AI44) -> 0
...

Sheet Notes | Quant Analysis
CL1: 0
P2: Employee Scope: | AO2: General Notes/Observations
Q32: Notes: | R32: [X]
R33: [Y]
R34: [Z]
AO35: Financial Stmts. Notes/Observations
P36: Institutional Ownership Snapshot | AO36: Revenues:
Q65: Notes: | R65: [X]
R66: [Y]
R67: [Z]
P69: Revenue Breakdown by Segment (Build graph for this section if applicable…. See example below) | AO69: Earnings Scope:
Q101: Notes: | R101: [X]
R102: [Y]
R103: [Z]
P105: Q/q Total Revenues, Net Income, FCF | AO105: Balance Sheet Scope:
Q134: Notes: | R134: [X]
R135: [Y]
R136: [Z]
P138: Y/y Total Revenues, Net Income, FCF | AO138: [Equity Preformance Compared to Peers]
Q167: Notes: | R167: [X]
R168: [Y]
R169: [Z]
A184: VOO Historical Returns | I184: FIG Historical Returns
A185: 252 Trading Days? (From: 10/22/2026 - 10/22/2026) | I185: 252 Trading Days? (From: 10/22/2026 - 10/22/2026)
A186: Close | B186: High | C186: Low | D186: Open | E186: Volume | F186: UTC Date | G186: Change | I186: Close | J186: High | K186: Low | L186: Open | M186: Volume | N186: UTC Date | O186: Change
A187: 702.3 | B187: 705.66 | C187: 699.68 | D187: 704.41 | E187: 6041430.3 | F187: Thu, 22 Oct 2026 00:00:00 GMT | G187: =A187/D187-1 -> -0.0029954146 | I187: 24.1 | J187: 24.38 | K187: 22.95 | L187: 23.18 | M187: 14463544 | N187: Thu, 22 Oct 2026 00:00:00 GMT | O187: =I187/L187-1 -> 0.039689387
A188: 710.72 | B188: 711.83 | C188: 706.33 | D188: 708.84 | E188: 6210315.6 | F188: Wed, 21 Oct 2026 00:00:00 GMT | G188: =A188/D188-1 -> 0.0026522205 | I188: 22.98 | J188: 23.49 | K188: 22.49 | L188: 22.785 | M188: 7603418.2 | N188: Wed, 21 Oct 2026 00:00:00 GMT | O188: =I188/L188-1 -> 0.008558262
A189: 706.8 | B189: 709.81 | C189: 702.49 | D189: 704.01 | E189: 5798006.5 | F189: Tue, 20 Oct 2026 00:00:00 GMT | G189: =A189/D189-1 -> 0.0039630119 | I189: 22.71 | J189: 23.26 | K189: 21.56 | L189: 21.78 | M189: 15122660 | N189: Tue, 20 Oct 2026 00:00:00 GMT | O189: =I189/L189-1 -> 0.042699725
A190: 704.6 | B190: 708.17 | C190: 703.9805 | D190: 705.27 | E190: 5588525.7 | F190: Mon, 19 Oct 2026 00:00:00 GMT | G190: =A190/D190-1 -> -0.00094999078 | I190: 21.54 | J190: 21.845 | K190: 21.14 | L190: 21.3 | M190: 6379348.3 | N190: Mon, 19 Oct 2026 00:00:00 GMT | O190: =I190/L190-1 -> 0.011267606
A191: 701.61 | B191: 710.85 | C191: 699.191 | D191: 710.75 | E191: 6095662.4 | F191: Fri, 16 Oct 2026 00:00:00 GMT | G191: =A191/D191-1 -> -0.012859655 | I191: 21.49 | J191: 23.53 | K191: 21.33 | L191: 23.3 | M191: 9254550.3 | N191: Fri, 16 Oct 2026 00:00:00 GMT | O191: =I191/L191-1 -> -0.077682403
A192: 709.43 | B192: 710.4 | C192: 702.69 | D192: 704.33 | E192: 6035492.3 | F192: Thu, 15 Oct 2026 00:00:00 GMT | G192: =A192/D192-1 -> 0.007240924 | I192: 22.99 | J192: 23.09 | K192: 21.25 | L192: 21.31 | M192: 14702774 | N192: Thu, 15 Oct 2026 00:00:00 GMT | O192: =I192/L192-1 -> 0.078836227
A193: 707.43 | B193: 713.62 | C193: 704.76 | D193: 712.32 | E193: 6228217.1 | F193: Wed, 14 Oct 2026 00:00:00 GMT | G193: =A193/D193-1 -> -0.0068648922 | I193: 21.48 | J193: 21.94 | K193: 21.08 | L193: 21.39 | M193: 12474997 | N193: Wed, 14 Oct 2026 00:00:00 GMT | O193: =I193/L193-1 -> 0.0042075736
A194: 715.2 | B194: 715.835 | C194: 713.27 | D194: 714.54 | E194: 4959098.4 | F194: Tue, 13 Oct 2026 00:00:00 GMT | G194: =A194/D194-1 -> 0.00092367117 | I194: 21.76 | J194: 23.045 | K194: 21.76 | L194: 22.09 | M194: 12282745 | N194: Tue, 13 Oct 2026 00:00:00 GMT | O194: =I194/L194-1 -> -0.014938886
A195: 715.13 | B195: 716.415 | C195: 714.26 | D195: 715.81 | E195: 3635491.2 | F195: Mon, 12 Oct 2026 00:00:00 GMT | G195: =A195/D195-1 -> -0.00094997276 | I195: 21.96 | J195: 22.2863 | K195: 21.385 | L195: 22.23 | M195: 9125955 | N195: Mon, 12 Oct 2026 00:00:00 GMT | O195: =I195/L195-1 -> -0.012145749
A196: 715.59 | B196: 716.435 | C196: 712.54 | D196: 713.54 | E196: 4345835.7 | F196: Fri, 09 Oct 2026 00:00:00 GMT | G196: =A196/D196-1 -> 0.0028729994 | I196: 22.5 | J196: 23.19 | K196: 22.23 | L196: 22.71 | M196: 7799882.4 | N196: Fri, 09 Oct 2026 00:00:00 GMT | O196: =I196/L196-1 -> -0.0092470277
A197: 711.28 | B197: 714.27 | C197: 708.16 | D197: 712.25 | E197: 4763330.7 | F197: Thu, 08 Oct 2026 00:00:00 GMT | G197: =A197/D197-1 -> -0.0013618814 | I197: 22.63 | J197: 22.665 | K197: 21.45 | L197: 21.62 | M197: 10579588 | N197: Thu, 08 Oct 2026 00:00:00 GMT | O197: =I197/L197-1 -> 0.046716004
A198: 714.34 | B198: 715.055 | C198: 711.06 | D198: 713.06 | E198: 4675948.1 | F198: Wed, 07 Oct 2026 00:00:00 GMT | G198: =A198/D198-1 -> 0.0017950804 | I198: 21.62 | J198: 22.293 | K198: 21.24 | L198: 22.02 | M198: 5704414.7 | N198: Wed, 07 Oct 2026 00:00:00 GMT | O198: =I198/L198-1 -> -0.018165304
A199: 716.2 | B199: 718.47 | C199: 715.09 | D199: 715.21 | E199: 4568431.3 | F199: Tue, 06 Oct 2026 00:00:00 GMT | G199: =A199/D199-1 -> 0.0013842088 | I199: 21.93 | J199: 22.315 | K199: 21.8 | L199: 22.21 | M199: 6759920.1 | N199: Tue, 06 Oct 2026 00:00:00 GMT | O199: =I199/L199-1 -> -0.012606934
A200: 712.32 | B200: 713.8583 | C200: 707.42 | D200: 707.44 | E200: 6172916.9 | F200: Mon, 05 Oct 2026 00:00:00 GMT | G200: =A200/D200-1 -> 0.0068981115 | I200: 22.01 | J200: 22.06 | K200: 21.08 | L200: 21.25 | M200: 7726450.3 | N200: Mon, 05 Oct 2026 00:00:00 GMT | O200: =I200/L200-1 -> 0.035764706 | R200: Min | S200: =MIN(O187:O438) -> -0.10444444
A201: 707.54 | B201: 710.2 | C201: 705.12 | D201: 708.31 | E201: 6612533.1 | F201: Fri, 02 Oct 2026 00:00:00 GMT | G201: =A201/D201-1 -> -0.0010870946 | I201: 21.36 | J201: 21.75 | K201: 21.01 | L201: 21.75 | M201: 7927051 | N201: Fri, 02 Oct 2026 00:00:00 GMT | O201: =I201/L201-1 -> -0.017931034 | R201: Max | S201: =MAX(O187:O438) -> 0.11181435
...

Sheet Product Lines

Sheet Economics

Sheet Management

Sheet Table Formatting
B2: [Bold Title] | G2: [Bold Title]
B3: Line Titles | G3: <-- General
B4: Line Titles | G4: <-- Info
B5: Line Titles | G5: <-- General
B6: Line Titles | G6: <-- Info
B7: Line Titles | G7: <-- General
B8: Line Titles | G8: <-- Info
