Workbook

Sheet Main
B2: ILMN
B3: Price | C3: 188.68 | D3: 7/5/2026
B4: SO | C4: 151.3 | D4: Q1'26
B5: MC | C5: =C3*C4 -> 28547.284
B6: Cash | C6: =1089+66 -> 1155 | D6: Q1'26
B7: Debt | C7: =499+1490 -> 1989 | D7: Q1'26
B8: EV | C8: =C5-C6+C7 -> 29381.284
B10: Illumina, Inc. (ILMN)
B12: Founder(s): Larry Bock, John Stuelpnagel, David Walt, Mark Chee, and Anthony Czarnik | F12: Registered Exchange: NASDAQ | M12: Resources:
B13: Founded: April 1998 | F13: Address: 5200 Illumina Way San Diego, CA 92122 U.S. | M13: SEC filings | P13: https://www.sec.gov/edgar/browse/?CIK=1110803&owner=exclude
B14: Headquarters: San Diego, CA | F14: Investor Relations Contact: | M14: Company Homepage | P14: https://www.illumina.com/
B15: Current CEO: Jacob Thaysen | F15: Investors Relation Department | N15: Company IR Page | Q15: https://investor.illumina.com/investors/default.aspx
B16: Employees: 10,080 | F16: Phone: | G16: (858) 202 - 4500 | I16: Email: | M16: Earnings Calls | P16: https://app.godelterminal.com/
B17: Industry: Diagnostics & Research | M17: Equity Analysis | P17: https://stockanalysis.com/stocks/ilmn/company/
B18: Sector: Healthcare | M18: MacroTrends | P18: https://www.macrotrends.net/stocks/charts/ILMN/illumina/revenue
B19: IPO: Jul 28, 2000 -- $500M valuation | M19: ROIC, WACC | P19: https://www.gurufocus.com/term/wacc/ILMN
B20: Fiscal Year: [January - December] | M20: Godel Terminal | P20: https://app.godelterminal.com/
A22: Company Overview:
B23: Illumina, Inc. provides sequencing- and array-based solutions for genetic and genomic analysis in the Americas, Europe, Greater China, the Asia Pacific, the Middle East, and Africa
B24: The Company offers sequencing- and array-based instruments and consumables, which include reagents, flow cells, and library preparation
C25: Whole-genome sequencing kits, which sequence entire genomes of various size and complexity
C26: Targeted resequencing kits, which sequence exomes, specific genes, and RNA or other genomic regions of interest
C27: It also provides whole-genome sequencing, genotyping, noninvasive prenatal testing, and product support services
D28: "Razor and Blade" business model … The Company sells the sequencing hardware (razors) to lock customers in, then relies on continuous sales of high-margin chemical reagents and flow cells (blades)
B29: The Company serves genomic research centers, academic institutions, government laboratories, and hospitals, as well as pharmaceutical, biotechnology, commercial molecular diagnostic laboratories, and consumer genomics companies
C30: The Company markets and distributes its products directly to customers, as well as through life-science distributors
B31: The Company has a collaboration with Labcorp Holdings Inc. for the development of oncology treatments through applications of sequencing solutions across the healthcare ecosystem
C32: Also strategic collaboration with Integrated DNA Technologies to enable a DRAGEN, secondary analysis pipeline for IDT xGena, FFPE and cfDNA next generation sequencing (NGS) library preparation with custom panels, delivering an integrated, end-to-end solution for somatic oncology research
C33: It also has a data partnership with Center for Data-Driven Discovery in Biomedicine to advance research in pediatric cancer and rare disease
B34: Illumina, Inc. was incorporated in 1998 and is headquartered in San Diego, California
A36: Business Segments and Geographical Info:

Sheet Model
B1: [Use for Graphing] | AM1: Q1 2020 | AQ1: Q1 2021 | AU1: Q1 2022 | AY1: Q1 2023 | BC1: Q1 2024 | BG1: Q1 2025 | BK1: Q1 2026
B2: Quarterly
B3: Revenues | C3: {="Q"&MOD(_xlfn.SEQUENCE(1,64)-1,4)+1&" "&(2011+INT((_xlfn.SEQUENCE(1,64)-1)/4))} -> Q1 2011 | D3: Q2 2011 | E3: Q3 2011 | F3: Q4 2011 | G3: Q1 2012 | H3: Q2 2012 | I3: Q3 2012 | J3: Q4 2012 | K3: Q1 2013 | L3: Q2 2013 | M3: Q3 2013 | N3: Q4 2013 | O3: Q1 2014 | P3: Q2 2014 | Q3: Q3 2014 | R3: Q4 2014 | S3: Q1 2015 | T3: Q2 2015 | U3: Q3 2015 | V3: Q4 2015 | W3: Q1 2016 | X3: Q2 2016 | Y3: Q3 2016 | Z3: Q4 2016 | AA3: Q1 2017 | AB3: Q2 2017 | AC3: Q3 2017 | AD3: Q4 2017 | AE3: Q1 2018 | AF3: Q2 2018 | AG3: Q3 2018 | AH3: Q4 2018 | AI3: Q1 2019 | AJ3: Q2 2019 | AK3: Q3 2019 | AL3: Q4 2019 | AM3: Q1 2020 | AN3: Q2 2020 | AO3: Q3 2020 | AP3: Q4 2020 | AQ3: Q1 2021 | AR3: Q2 2021 | AS3: Q3 2021 | AT3: Q4 2021 | AU3: Q1 2022 | AV3: Q2 2022 | AW3: Q3 2022 | AX3: Q4 2022 | AY3: Q1 2023 | AZ3: Q2 2023 | BA3: Q3 2023 | BB3: Q4 2023 | BC3: Q1 2024 | BD3: Q2 2024 | BE3: Q3 2024 | BF3: Q4 2024 | BG3: Q1 2025 | BH3: Q2 2025 | BI3: Q3 2025 | BJ3: Q4 2025 | BK3: Q1 2026 | BL3: Q2 2026 | BM3: Q3 2026 | BN3: Q4 2026 | BS3: 2011 | BT3: =BS3+1 -> 2012 | BU3: =BT3+1 -> 2013 | BV3: =BU3+1 -> 2014 | BW3: =BV3+1 -> 2015 | BX3: =BW3+1 -> 2016 | BY3: =BX3+1 -> 2017 | BZ3: =BY3+1 -> 2018 | CA3: =BZ3+1 -> 2019 | ... EO3: =EN3+1 -> 2085
B4: Consumables | AQ4: 774 | AR4: 778 | AS4: 794 | AT4: =3217-SUM(AQ4:AS4) -> 871 | AU4: 853 | AV4: 813 | AW4: 796 | AX4: =3225-SUM(AU4:AW4) -> 763 | AY4: 764 | AZ4: 804 | BA4: 760 | BB4: =3083-SUM(AY4:BA4) -> 755 | BC4: 762 | BD4: 807 | BE4: 807 | BF4: =3155-SUM(BC4:BE4) -> 779 | BG4: 768 | BH4: 811 | BI4: 816 | BJ4: =3227-SUM(BG4:BI4) -> 832 | BK4: 797 | CC4: =SUM(AQ4:AT4) -> 3217 | CD4: =SUM(AU4:AX4) -> 3225 | CE4: =SUM(AY4:BB4) -> 3083 | CF4: =SUM(BC4:BF4) -> 3155 | CG4: =SUM(BG4:BJ4) -> 3227 | CH4: =CG4*(1+CH10) -> 6454 | CI4: =CH4*(1+CI10) -> 12908 | CJ4: =CI4*(1+CJ10) -> 25816 | CK4: =CJ4*(1+CK10) -> 51632 | CL4: =CK4*(1+CL10) -> 103264 | CM4: =CL4*(1+CM10) -> 206528 | CN4: =CM4*(1+CN10) -> 413056 | CO4: =CN4*(1+CO10) -> 826112 | ... CQ4: =CP4*(1+CQ10) -> 3304448
B5: Instruments | AQ5: 179 | AR5: 194 | AS5: 184 | AT5: =751-SUM(AQ5:AS5) -> 194 | AU5: 217 | AV5: 193 | AW5: 167 | AX5: =728-SUM(AU5:AW5) -> 151 | AY5: 158 | AZ5: 197 | BA5: 181 | BB5: =704-SUM(AY5:BA5) -> 168 | BC5: 114 | BD5: 120 | BE5: 107 | BF5: =501-SUM(BC5:BE5) -> 160 | BG5: 112 | BH5: 101 | BI5: 111 | BJ5: =482-SUM(BG5:BI5) -> 158 | BK5: 120 | CC5: =SUM(AQ5:AT5) -> 751 | CD5: =SUM(AU5:AX5) -> 728 | CE5: =SUM(AY5:BB5) -> 704 | CF5: =SUM(BC5:BF5) -> 501 | CG5: =SUM(BG5:BJ5) -> 482 | CH5: =CG5*(1+CH11) -> 964 | CI5: =CH5*(1+CI11) -> 1928 | CJ5: =CI5*(1+CJ11) -> 3856 | CK5: =CJ5*(1+CK11) -> 7712 | CL5: =CK5*(1+CL11) -> 15424 | CM5: =CL5*(1+CM11) -> 30848 | CN5: =CM5*(1+CN11) -> 61696 | CO5: =CN5*(1+CO11) -> 123392 | ... CQ5: =CP5*(1+CQ11) -> 493568
B6: Ttl Product Revenues | AQ6: =AQ4+AQ5 -> 953 | AR6: =AR4+AR5 -> 972 | AS6: =AS4+AS5 -> 978 | AT6: =AT4+AT5 -> 1065 | AU6: =AU4+AU5 -> 1070 | AV6: =AV4+AV5 -> 1006 | AW6: =AW4+AW5 -> 963 | AX6: =AX4+AX5 -> 914 | ... BK6: =BK4+BK5 -> 917 | CC6: =SUM(AQ6:AT6) -> 3968 | CD6: =SUM(AU6:AX6) -> 3953 | CE6: =SUM(AY6:BB6) -> 3787 | CF6: =SUM(BC6:BF6) -> 3656 | CG6: =SUM(BG6:BJ6) -> 3709 | CH6: =CG6*(1+CH12) -> 7418 | CI6: =CH6*(1+CI12) -> 14836 | CJ6: =CI6*(1+CJ12) -> 29672 | CK6: =CJ6*(1+CK12) -> 59344 | CL6: =CK6*(1+CL12) -> 118688 | CM6: =CL6*(1+CM12) -> 237376 | CN6: =CM6*(1+CN12) -> 474752 | CO6: =CN6*(1+CO12) -> 949504 | ... CQ6: =CP6*(1+CQ12) -> 3798016
B7: Services | AQ7: 140 | AR7: 154 | AS7: 130 | AT7: =558-SUM(AQ7:AS7) -> 134 | AU7: 153 | AV7: 156 | AW7: 152 | AX7: =631-SUM(AU7:AW7) -> 170 | AY7: 165 | AZ7: 175 | BA7: 178 | BB7: =717-SUM(AY7:BA7) -> 199 | BC7: 200 | BD7: 185 | BE7: 166 | BF7: =716-SUM(BC7:BE7) -> 165 | BG7: 161 | BH7: 147 | BI7: 157 | BJ7: =634-SUM(BG7:BI7) -> 169 | BK7: 174 | CC7: =SUM(AQ7:AT7) -> 558 | CD7: =SUM(AU7:AX7) -> 631 | CE7: =SUM(AY7:BB7) -> 717 | CF7: =SUM(BC7:BF7) -> 716 | CG7: =SUM(BG7:BJ7) -> 634 | CH7: =CG7*(1+CH13) -> 1268 | CI7: =CH7*(1+CI13) -> 2536 | CJ7: =CI7*(1+CJ13) -> 5072 | CK7: =CJ7*(1+CK13) -> 10144 | CL7: =CK7*(1+CL13) -> 20288 | CM7: =CL7*(1+CM13) -> 40576 | CN7: =CM7*(1+CN13) -> 81152 | CO7: =CN7*(1+CO13) -> 162304 | ... CQ7: =CP7*(1+CQ13) -> 649216
B8: Ttl Revenues | AQ8: =AQ6+AQ7 -> 1093 | AR8: =AR6+AR7 -> 1126 | AS8: =AS6+AS7 -> 1108 | AT8: =AT6+AT7 -> 1199 | AU8: =AU6+AU7 -> 1223 | AV8: =AV6+AV7 -> 1162 | AW8: =AW6+AW7 -> 1115 | AX8: =AX6+AX7 -> 1084 | ... BK8: =BK6+BK7 -> 1091 | CC8: =SUM(AQ8:AT8) -> 4526 | CD8: =SUM(AU8:AX8) -> 4584 | CE8: =SUM(AY8:BB8) -> 4504 | CF8: =SUM(BC8:BF8) -> 4372 | CG8: =SUM(BG8:BJ8) -> 4343 | CH8: =SUM(CH4:CH7) -> 16104 | CI8: =SUM(CI4:CI7) -> 32208 | CJ8: =SUM(CJ4:CJ7) -> 64416 | CK8: =SUM(CK4:CK7) -> 128832 | CL8: =SUM(CL4:CL7) -> 257664 | CM8: =SUM(CM4:CM7) -> 515328 | CN8: =SUM(CN4:CN7) -> 1030656 | CO8: =SUM(CO4:CO7) -> 2061312 | ... CQ8: =SUM(CQ4:CQ7) -> 8245248
B10: Consumables Growth Y/y | AU10: =AU4/AQ4-1 -> 0.10206718 | AV10: =AV4/AR4-1 -> 0.044987147 | AW10: =AW4/AS4-1 -> 0.0025188917 | AX10: =AX4/AT4-1 -> -0.12399541 | AY10: =AY4/AU4-1 -> -0.10433763 | AZ10: =AZ4/AV4-1 -> -0.011070111 | BA10: =BA4/AW4-1 -> -0.045226131 | BB10: =BB4/AX4-1 -> -0.010484928 | ... BK10: =BK4/BG4-1 -> 0.037760417 | CD10: =CD4/CC4-1 -> 0.0024867889 | CE10: =CE4/CD4-1 -> -0.044031008 | CF10: =CF4/CE4-1 -> 0.023353876 | CG10: =CG4/CF4-1 -> 0.022820919 | CH10: 1 | CI10: 1 | CJ10: 1 | CK10: 1 | CL10: 1 | CM10: 1 | CN10: 1 | CO10: 1 | CP10: 1 | CQ10: 1
B11: Instruments Growth Y/y | AU11: =AU5/AQ5-1 -> 0.2122905 | AV11: =AV5/AR5-1 -> -0.0051546392 | AW11: =AW5/AS5-1 -> -0.092391304 | AX11: =AX5/AT5-1 -> -0.22164948 | AY11: =AY5/AU5-1 -> -0.2718894 | AZ11: =AZ5/AV5-1 -> 0.020725389 | BA11: =BA5/AW5-1 -> 0.083832335 | BB11: =BB5/AX5-1 -> 0.11258278 | ... BK11: =BK5/BG5-1 -> 0.071428571 | CD11: =CD5/CC5-1 -> -0.030625832 | CE11: =CE5/CD5-1 -> -0.032967033 | CF11: =CF5/CE5-1 -> -0.28835227 | CG11: =CG5/CF5-1 -> -0.037924152 | CH11: 1 | CI11: 1 | CJ11: 1 | CK11: 1 | CL11: 1 | CM11: 1 | CN11: 1 | CO11: 1 | CP11: 1 | CQ11: 1
B12: Ttl Product Revenues Growth Y/y | AU12: =AU6/AQ6-1 -> 0.1227702 | AV12: =AV6/AR6-1 -> 0.034979424 | AW12: =AW6/AS6-1 -> -0.015337423 | AX12: =AX6/AT6-1 -> -0.14178404 | AY12: =AY6/AU6-1 -> -0.13831776 | AZ12: =AZ6/AV6-1 -> -0.0049701789 | BA12: =BA6/AW6-1 -> -0.022845275 | BB12: =BB6/AX6-1 -> 0.0098468271 | ... BK12: =BK6/BG6-1 -> 0.042045455 | CD12: =CD6/CC6-1 -> -0.0037802419 | CE12: =CE6/CD6-1 -> -0.041993423 | CF12: =CF6/CE6-1 -> -0.034592025 | CG12: =CG6/CF6-1 -> 0.014496718 | CH12: 1 | CI12: 1 | CJ12: 1 | CK12: 1 | CL12: 1 | CM12: 1 | CN12: 1 | CO12: 1 | CP12: 1 | CQ12: 1
B13: Services Growth Y/y | AU13: =AU7/AQ7-1 -> 0.092857143 | AV13: =AV7/AR7-1 -> 0.012987013 | AW13: =AW7/AS7-1 -> 0.16923077 | AX13: =AX7/AT7-1 -> 0.26865672 | AY13: =AY7/AU7-1 -> 0.078431373 | AZ13: =AZ7/AV7-1 -> 0.12179487 | BA13: =BA7/AW7-1 -> 0.17105263 | BB13: =BB7/AX7-1 -> 0.17058824 | ... BK13: =BK7/BG7-1 -> 0.080745342 | CD13: =CD7/CC7-1 -> 0.13082437 | CE13: =CE7/CD7-1 -> 0.1362916 | CF13: =CF7/CE7-1 -> -0.0013947001 | CG13: =CG7/CF7-1 -> -0.11452514 | CH13: 1 | CI13: 1 | CJ13: 1 | CK13: 1 | CL13: 1 | CM13: 1 | CN13: 1 | CO13: 1 | CP13: 1 | CQ13: 1
B14: Ttl Revenue Growth Y/y | AU14: =AU8/AQ8-1 -> 0.1189387 | AV14: =AV8/AR8-1 -> 0.031971581 | AW14: =AW8/AS8-1 -> 0.0063176895 | AX14: =AX8/AT8-1 -> -0.095913261 | AY14: =AY8/AU8-1 -> -0.11120196 | AZ14: =AZ8/AV8-1 -> 0.012048193 | BA14: =BA8/AW8-1 -> 0.0035874439 | BB14: =BB8/AX8-1 -> 0.035055351 | ... BK14: =BK8/BG8-1 -> 0.04803074 | CD14: =CD8/CC8-1 -> 0.012814848 | CE14: =CE8/CD8-1 -> -0.017452007 | CF14: =CF8/CE8-1 -> -0.029307282 | CG14: =CG8/CF8-1 -> -0.0066331199 | CH14: =CH8/CG8-1 -> 2.7080359 | CI14: =CI8/CH8-1 -> 1 | CJ14: =CJ8/CI8-1 -> 1 | CK14: =CK8/CJ8-1 -> 1 | ... CQ14: =CQ8/CP8-1 -> 1
B16: Consumables % of Ttl Revenues | AQ16: =AQ4/AQ8 -> 0.70814273 | AR16: =AR4/AR8 -> 0.69094139 | AS16: =AS4/AS8 -> 0.7166065 | AT16: =AT4/AT8 -> 0.7264387 | AU16: =AU4/AU8 -> 0.69746525 | AV16: =AV4/AV8 -> 0.69965577 | AW16: =AW4/AW8 -> 0.71390135 | AX16: =AX4/AX8 -> 0.70387454 | ... BK16: =BK4/BK8 -> 0.73052246 | CC16: =CC4/CC8 -> 0.71078215 | CD16: =CD4/CD8 -> 0.70353403 | CE16: =CE4/CE8 -> 0.68450266 | CF16: =CF4/CF8 -> 0.72163769 | CG16: =CG4/CG8 -> 0.74303477
B17: Instruments % of Ttl Revenues | AQ17: =AQ5/AQ8 -> 0.16376944 | AR17: =AR5/AR8 -> 0.1722913 | AS17: =AS5/AS8 -> 0.16606498 | AT17: =AT5/AT8 -> 0.1618015 | AU17: =AU5/AU8 -> 0.17743254 | AV17: =AV5/AV8 -> 0.16609294 | AW17: =AW5/AW8 -> 0.14977578 | AX17: =AX5/AX8 -> 0.13929889 | ... BK17: =BK5/BK8 -> 0.10999083 | CC17: =CC5/CC8 -> 0.16593018 | CD17: =CD5/CD8 -> 0.15881326 | CE17: =CE5/CE8 -> 0.15630551 | CF17: =CF5/CF8 -> 0.11459286 | CG17: =CG5/CG8 -> 0.11098319
B18: Product % of Ttl Revenues | AQ18: =AQ6/AQ8 -> 0.87191217 | AR18: =AR6/AR8 -> 0.86323268 | AS18: =AS6/AS8 -> 0.88267148 | AT18: =AT6/AT8 -> 0.8882402 | AU18: =AU6/AU8 -> 0.87489779 | AV18: =AV6/AV8 -> 0.86574871 | AW18: =AW6/AW8 -> 0.86367713 | AX18: =AX6/AX8 -> 0.84317343 | ... BK18: =BK6/BK8 -> 0.84051329 | CC18: =CC6/CC8 -> 0.87671233 | CD18: =CD6/CD8 -> 0.86234729 | CE18: =CE6/CE8 -> 0.84080817 | CF18: =CF6/CF8 -> 0.83623056 | CG18: =CG6/CG8 -> 0.85401796
B19: Services % of Ttl Revenues | AQ19: =AQ7/AQ8 -> 0.12808783 | AR19: =AR7/AR8 -> 0.13676732 | AS19: =AS7/AS8 -> 0.11732852 | AT19: =AT7/AT8 -> 0.1117598 | AU19: =AU7/AU8 -> 0.12510221 | AV19: =AV7/AV8 -> 0.13425129 | AW19: =AW7/AW8 -> 0.13632287 | AX19: =AX7/AX8 -> 0.15682657 | ... BK19: =BK7/BK8 -> 0.15948671 | CC19: =CC7/CC8 -> 0.12328767 | CD19: =CD7/CD8 -> 0.13765271 | CE19: =CE7/CE8 -> 0.15919183 | CF19: =CF7/CF8 -> 0.16376944 | CG19: =CG7/CG8 -> 0.14598204
B21: Sequencing | AQ21: 1109 | AR21: 1021 | AS21: 1015 | AT21: =4109-SUM(AQ21:AS21) -> 964 | AU21: 1109 | AV21: 1065 | AW21: 1015 | AX21: =4171-SUM(AU21:AW21) -> 982 | AY21: 976 | AZ21: 1083 | BA21: 1029 | BB21: =4112-SUM(AY21:BA21) -> 1024 | BC21: 979 | BD21: 1016 | BE21: 995 | BF21: =3993-SUM(BC21:BE21) -> 1003 | BG21: 947 | BH21: 972 | BI21: 1001 | BJ21: =3985-SUM(BG21:BI21) -> 1065 | BK21: 995 | CC21: =SUM(AQ21:AT21) -> 4109 | CD21: =SUM(AU21:AX21) -> 4171 | CE21: =SUM(AY21:BB21) -> 4112 | CF21: =SUM(BC21:BF21) -> 3993 | CG21: =SUM(BG21:BJ21) -> 3985 | CH21: =CG21*(1+CH25) -> 7970 | CI21: =CH21*(1+CI25) -> 15940 | CJ21: =CI21*(1+CJ25) -> 31880 | CK21: =CJ21*(1+CK25) -> 63760 | CL21: =CK21*(1+CL25) -> 127520 | CM21: =CL21*(1+CM25) -> 255040 | CN21: =CM21*(1+CN25) -> 510080 | CO21: =CN21*(1+CO25) -> 1020160 | ... CQ21: =CP21*(1+CQ25) -> 4080640
B22: Microarray | AQ22: 114 | AR22: 105 | AS22: 93 | AT22: =417-SUM(AQ22:AS22) -> 105 | AU22: 114 | AV22: 97 | AW22: 100 | AX22: =413-SUM(AU22:AW22) -> 102 | AY22: 111 | AZ22: 93 | BA22: 90 | BB22: =392-SUM(AY22:BA22) -> 98 | BC22: 97 | BD22: 96 | BE22: 85 | BF22: =379-SUM(BC22:BE22) -> 101 | BG22: 94 | BH22: 87 | BI22: 83 | BJ22: =358-SUM(BG22:BI22) -> 94 | BK22: 96 | CC22: =SUM(AQ22:AT22) -> 417 | CD22: =SUM(AU22:AX22) -> 413 | CE22: =SUM(AY22:BB22) -> 392 | CF22: =SUM(BC22:BF22) -> 379 | CG22: =SUM(BG22:BJ22) -> 358 | CH22: =CG22*(1+CH26) -> 716 | CI22: =CH22*(1+CI26) -> 1432 | CJ22: =CI22*(1+CJ26) -> 2864 | CK22: =CJ22*(1+CK26) -> 5728 | CL22: =CK22*(1+CL26) -> 11456 | CM22: =CL22*(1+CM26) -> 22912 | CN22: =CM22*(1+CN26) -> 45824 | CO22: =CN22*(1+CO26) -> 91648 | ... CQ22: =CP22*(1+CQ26) -> 366592
B23: Ttl Revenues | AQ23: =AQ21+AQ22 -> 1223 | AR23: =AR21+AR22 -> 1126 | AS23: =AS21+AS22 -> 1108 | AT23: =AT21+AT22 -> 1069 | AU23: =AU21+AU22 -> 1223 | AV23: =AV21+AV22 -> 1162 | AW23: =AW21+AW22 -> 1115 | AX23: =AX21+AX22 -> 1084 | ... BK23: =BK21+BK22 -> 1091 | CC23: =SUM(AQ23:AT23) -> 4526 | CD23: =SUM(AU23:AX23) -> 4584 | CE23: =SUM(AY23:BB23) -> 4504 | CF23: =SUM(BC23:BF23) -> 4372 | CG23: =SUM(BG23:BJ23) -> 4343 | CH23: =CG23*(1+CH27) -> 8686 | CI23: =CH23*(1+CI27) -> 17372 | CJ23: =CI23*(1+CJ27) -> 34744 | CK23: =CJ23*(1+CK27) -> 69488 | CL23: =CK23*(1+CL27) -> 138976 | CM23: =CL23*(1+CM27) -> 277952 | CN23: =CM23*(1+CN27) -> 555904 | CO23: =CN23*(1+CO27) -> 1111808 | ... CQ23: =CP23*(1+CQ27) -> 4447232
B25: Sequencing Growth Y/y | AU25: =AU21/AQ21-1 -> 0 | AV25: =AV21/AR21-1 -> 0.043095005 | AW25: =AW21/AS21-1 -> 0 | AX25: =AX21/AT21-1 -> 0.018672199 | AY25: =AY21/AU21-1 -> -0.11992786 | AZ25: =AZ21/AV21-1 -> 0.016901408 | BA25: =BA21/AW21-1 -> 0.013793103 | BB25: =BB21/AX21-1 -> 0.042769857 | ... BK25: =BK21/BG21-1 -> 0.050686378 | CD25: =CD21/CC21-1 -> 0.015088829 | CE25: =CE21/CD21-1 -> -0.014145289 | CF25: =CF21/CE21-1 -> -0.028939689 | CG25: =CG21/CF21-1 -> -0.0020035061 | CH25: 1 | CI25: 1 | CJ25: 1 | CK25: 1 | CL25: 1 | CM25: 1 | CN25: 1 | CO25: 1 | CP25: 1 | CQ25: 1
B26: Microarray Growth Y/y | AU26: =AU22/AQ22-1 -> 0 | AV26: =AV22/AR22-1 -> -0.076190476 | AW26: =AW22/AS22-1 -> 0.075268817 | AX26: =AX22/AT22-1 -> -0.028571429 | AY26: =AY22/AU22-1 -> -0.026315789 | AZ26: =AZ22/AV22-1 -> -0.041237113 | BA26: =BA22/AW22-1 -> -0.1 | BB26: =BB22/AX22-1 -> -0.039215686 | ... BK26: =BK22/BG22-1 -> 0.021276596 | CD26: =CD22/CC22-1 -> -0.0095923261 | CE26: =CE22/CD22-1 -> -0.050847458 | CF26: =CF22/CE22-1 -> -0.033163265 | CG26: =CG22/CF22-1 -> -0.055408971 | CH26: 1 | CI26: 1 | CJ26: 1 | CK26: 1 | CL26: 1 | CM26: 1 | CN26: 1 | CO26: 1 | CP26: 1 | CQ26: 1
B27: Ttl Revenues Growth Y/y | AU27: =AU23/AQ23-1 -> 0 | AV27: =AV23/AR23-1 -> 0.031971581 | AW27: =AW23/AS23-1 -> 0.0063176895 | AX27: =AX23/AT23-1 -> 0.014031805 | AY27: =AY23/AU23-1 -> -0.11120196 | AZ27: =AZ23/AV23-1 -> 0.012048193 | BA27: =BA23/AW23-1 -> 0.0035874439 | BB27: =BB23/AX23-1 -> 0.035055351 | ... BK27: =BK23/BG23-1 -> 0.04803074 | CD27: =CD23/CC23-1 -> 0.012814848 | CE27: =CE23/CD23-1 -> -0.017452007 | CF27: =CF23/CE23-1 -> -0.029307282 | CG27: =CG23/CF23-1 -> -0.0066331199 | CH27: 1 | CI27: 1 | CJ27: 1 | CK27: 1 | CL27: 1 | CM27: 1 | CN27: 1 | CO27: 1 | CP27: 1 | CQ27: 1
B29: Sequencing % of Ttl Revenues | AQ29: =AQ21/AQ23 -> 0.90678659 | AR29: =AR21/AR23 -> 0.90674956 | AS29: =AS21/AS23 -> 0.91606498 | AT29: =AT21/AT23 -> 0.90177736 | AU29: =AU21/AU23 -> 0.90678659 | AV29: =AV21/AV23 -> 0.91652324 | AW29: =AW21/AW23 -> 0.9103139 | AX29: =AX21/AX23 -> 0.90590406 | ... BK29: =BK21/BK23 -> 0.91200733 | CC29: =CC21/CC23 -> 0.90786567 | CD29: =CD21/CD23 -> 0.90990401 | CE29: =CE21/CE23 -> 0.91296625 | CF29: =CF21/CF23 -> 0.91331199 | CG29: =CG21/CG23 -> 0.9175685
B30: Microarray % of Ttl Revenues | AQ30: =AQ22/AQ23 -> 0.09321341 | AR30: =AR22/AR23 -> 0.093250444 | AS30: =AS22/AS23 -> 0.083935018 | AT30: =AT22/AT23 -> 0.098222638 | AU30: =AU22/AU23 -> 0.09321341 | AV30: =AV22/AV23 -> 0.083476764 | AW30: =AW22/AW23 -> 0.089686099 | AX30: =AX22/AX23 -> 0.094095941 | ... BK30: =BK22/BK23 -> 0.087992667 | CC30: =CC22/CC23 -> 0.092134335 | CD30: =CD22/CD23 -> 0.090095986 | CE30: =CE22/CE23 -> 0.087033748 | CF30: =CF22/CF23 -> 0.086688015 | CG30: =CG22/CG23 -> 0.082431499
B32: U.S. Revenues | AQ32: 562 | AR32: 589 | AS32: 583 | AT32: =2358-SUM(AQ32:AS32) -> 624 | AU32: 648 | AV32: 639 | AW32: 597 | AX32: =2479-SUM(AU32:AW32) -> 595 | AY32: 616 | AZ32: 640 | BA32: 663 | BB32: =2521-SUM(AY32:BA32) -> 602 | BC32: 603 | BD32: 640 | BE32: 609 | BF32: =2441-SUM(BC32:BE32) -> 589 | BG32: 555 | BH32: 586 | BI32: 612 | BJ32: =2406-SUM(BG32:BI32) -> 653 | BK32: 590 | CC32: =SUM(AQ32:AT32) -> 2358 | CD32: =SUM(AU32:AX32) -> 2479 | CE32: =SUM(AY32:BB32) -> 2521 | CF32: =SUM(BC32:BF32) -> 2441 | CG32: =SUM(BG32:BJ32) -> 2406
B33: Euro, Mid-East, Africa, LatAm Revenues | AQ33: 305 | AR33: 320 | AS33: 313 | AT33: =1149-SUM(AQ33:AS33) -> 211 | AU33: 316 | AV33: 274 | AW33: 259 | AX33: =1089-SUM(AU33:AW33) -> 240 | AY33: 261 | AZ33: 303 | BA33: 260 | BB33: =1140-SUM(AY33:BA33) -> 316 | BC33: 279 | BD33: 289 | BE33: 291 | BF33: =1185-SUM(BC33:BE33) -> 326 | BG33: 332 | BH33: 310 | BI33: 309 | BJ33: =1264-SUM(BG33:BI33) -> 313 | BK33: 356 | CC33: =SUM(AQ33:AT33) -> 1149 | CD33: =SUM(AU33:AX33) -> 1089 | CE33: =SUM(AY33:BB33) -> 1140 | CF33: =SUM(BC33:BF33) -> 1185 | CG33: =SUM(BG33:BJ33) -> 1264
B34: Taiwan, China Revenues | AQ34: 127 | AR34: 132 | AS34: 122 | AT34: =502-SUM(AQ34:AS34) -> 121 | AU34: 127 | AV34: 118 | AW34: 133 | AX34: =472-SUM(AU34:AW34) -> 94 | AY34: 91 | AZ34: 115 | BA34: 98 | BB34: =384-SUM(AY34:BA34) -> 80 | BC34: 78 | BD34: 75 | BE34: 75 | BF34: =308-SUM(BC34:BE34) -> 80 | BG34: 72 | BH34: 63 | BI34: 52 | BJ34: =243-SUM(BG34:BI34) -> 56 | BK34: 52 | CC34: =SUM(AQ34:AT34) -> 502 | CD34: =SUM(AU34:AX34) -> 472 | CE34: =SUM(AY34:BB34) -> 384 | CF34: =SUM(BC34:BF34) -> 308 | CG34: =SUM(BG34:BJ34) -> 243
B35: APAC Revenues | AQ35: 99 | AR35: 85 | AS35: 90 | AT35: =517-SUM(AQ35:AS35) -> 243 | AU35: 132 | AV35: 131 | AW35: 126 | AX35: =544-SUM(AU35:AW35) -> 155 | AY35: 119 | AZ35: 118 | BA35: 98 | BB35: =459-SUM(AY35:BA35) -> 124 | BC35: 116 | BD35: 108 | BE35: 105 | BF35: =438-SUM(BC35:BE35) -> 109 | BG35: 82 | BH35: 100 | BI35: 111 | BJ35: =430-SUM(BG35:BI35) -> 137 | BK35: 93 | CC35: =SUM(AQ35:AT35) -> 517 | CD35: =SUM(AU35:AX35) -> 544 | CE35: =SUM(AY35:BB35) -> 459 | CF35: =SUM(BC35:BF35) -> 438 | CG35: =SUM(BG35:BJ35) -> 430
B36: Ttl Revenues | AQ36: =SUM(AQ32:AQ35) -> 1093 | AR36: =SUM(AR32:AR35) -> 1126 | AS36: =SUM(AS32:AS35) -> 1108 | AT36: =SUM(AT32:AT35) -> 1199 | AU36: =SUM(AU32:AU35) -> 1223 | AV36: =SUM(AV32:AV35) -> 1162 | AW36: =SUM(AW32:AW35) -> 1115 | AX36: =SUM(AX32:AX35) -> 1084 | ... BK36: =SUM(BK32:BK35) -> 1091 | CC36: =SUM(AQ36:AT36) -> 4526 | CD36: =SUM(AU36:AX36) -> 4584 | CE36: =SUM(AY36:BB36) -> 4504 | CF36: =SUM(BC36:BF36) -> 4372 | CG36: =SUM(BG36:BJ36) -> 4343
B38: U.S. Revenues Growth Y/y | AU38: =AU32/AQ32-1 -> 0.15302491 | AV38: =AV32/AR32-1 -> 0.084889643 | AW38: =AW32/AS32-1 -> 0.024013722 | AX38: =AX32/AT32-1 -> -0.046474359 | AY38: =AY32/AU32-1 -> -0.049382716 | AZ38: =AZ32/AV32-1 -> 0.0015649452 | BA38: =BA32/AW32-1 -> 0.11055276 | BB38: =BB32/AX32-1 -> 0.011764706 | ... BK38: =BK32/BG32-1 -> 0.063063063 | CD38: =CD32/CC32-1 -> 0.051314673 | CE38: =CE32/CD32-1 -> 0.016942315 | CF38: =CF32/CE32-1 -> -0.031733439 | CG38: =CG32/CF32-1 -> -0.014338386
B39: Euro, Mid-East, Africa, LatAm Revenues Growth Y/y | AU39: =AU33/AQ33-1 -> 0.036065574 | AV39: =AV33/AR33-1 -> -0.14375 | AW39: =AW33/AS33-1 -> -0.17252396 | AX39: =AX33/AT33-1 -> 0.13744076 | AY39: =AY33/AU33-1 -> -0.17405063 | AZ39: =AZ33/AV33-1 -> 0.10583942 | BA39: =BA33/AW33-1 -> 0.0038610039 | BB39: =BB33/AX33-1 -> 0.31666667 | ... BK39: =BK33/BG33-1 -> 0.072289157 | CD39: =CD33/CC33-1 -> -0.052219321 | CE39: =CE33/CD33-1 -> 0.046831956 | CF39: =CF33/CE33-1 -> 0.039473684 | CG39: =CG33/CF33-1 -> 0.066666667
B40: Taiwan, China Revenues Growth Y/y | AU40: =AU34/AQ34-1 -> 0 | AV40: =AV34/AR34-1 -> -0.10606061 | AW40: =AW34/AS34-1 -> 0.090163934 | AX40: =AX34/AT34-1 -> -0.2231405 | AY40: =AY34/AU34-1 -> -0.28346457 | AZ40: =AZ34/AV34-1 -> -0.025423729 | BA40: =BA34/AW34-1 -> -0.26315789 | BB40: =BB34/AX34-1 -> -0.14893617 | ... BK40: =BK34/BG34-1 -> -0.27777778 | CD40: =CD34/CC34-1 -> -0.059760956 | CE40: =CE34/CD34-1 -> -0.18644068 | CF40: =CF34/CE34-1 -> -0.19791667 | CG40: =CG34/CF34-1 -> -0.21103896
B41: APAC Revenues Growth Y/y | AU41: =AU35/AQ35-1 -> 0.33333333 | AV41: =AV35/AR35-1 -> 0.54117647 | AW41: =AW35/AS35-1 -> 0.4 | AX41: =AX35/AT35-1 -> -0.36213992 | AY41: =AY35/AU35-1 -> -0.098484848 | AZ41: =AZ35/AV35-1 -> -0.099236641 | BA41: =BA35/AW35-1 -> -0.22222222 | BB41: =BB35/AX35-1 -> -0.2 | ... BK41: =BK35/BG35-1 -> 0.13414634 | CD41: =CD35/CC35-1 -> 0.052224371 | CE41: =CE35/CD35-1 -> -0.15625 | CF41: =CF35/CE35-1 -> -0.045751634 | CG41: =CG35/CF35-1 -> -0.01826484
B42: Ttl Revenues Growth Y/y | AU42: =AU36/AQ36-1 -> 0.1189387 | AV42: =AV36/AR36-1 -> 0.031971581 | AW42: =AW36/AS36-1 -> 0.0063176895 | AX42: =AX36/AT36-1 -> -0.095913261 | AY42: =AY36/AU36-1 -> -0.11120196 | AZ42: =AZ36/AV36-1 -> 0.012048193 | BA42: =BA36/AW36-1 -> 0.0035874439 | BB42: =BB36/AX36-1 -> 0.035055351 | ... BK42: =BK36/BG36-1 -> 0.04803074 | CD42: =CD36/CC36-1 -> 0.012814848 | CE42: =CE36/CD36-1 -> -0.017452007 | CF42: =CF36/CE36-1 -> -0.029307282 | CG42: =CG36/CF36-1 -> -0.0066331199
B44: U.S. Revenues % of Revenues | AQ44: =AQ32/AQ36 -> 0.51418115 | AR44: =AR32/AR36 -> 0.52309059 | AS44: =AS32/AS36 -> 0.52617329 | AT44: =AT32/AT36 -> 0.52043369 | AU44: =AU32/AU36 -> 0.52984464 | AV44: =AV32/AV36 -> 0.54991394 | AW44: =AW32/AW36 -> 0.53542601 | AX44: =AX32/AX36 -> 0.54889299 | ... BK44: =BK32/BK36 -> 0.54078827 | CC44: =CC32/CC36 -> 0.52098984 | CD44: =CD32/CD36 -> 0.54079407 | CE44: =CE32/CE36 -> 0.55972469 | CF44: =CF32/CF36 -> 0.55832571 | CG44: =CG32/CG36 -> 0.55399493
B45: Euro, Mid-East, Africa, LatAm Revenues % of Revenues | AQ45: =AQ33/AQ36 -> 0.27904849 | AR45: =AR33/AR36 -> 0.28419183 | AS45: =AS33/AS36 -> 0.28249097 | AT45: =AT33/AT36 -> 0.17597998 | AU45: =AU33/AU36 -> 0.25838103 | AV45: =AV33/AV36 -> 0.23580034 | AW45: =AW33/AW36 -> 0.232287 | AX45: =AX33/AX36 -> 0.22140221 | ... BK45: =BK33/BK36 -> 0.32630614 | CC45: =CC33/CC36 -> 0.25386655 | CD45: =CD33/CD36 -> 0.23756545 | CE45: =CE33/CE36 -> 0.25310835 | CF45: =CF33/CF36 -> 0.271043 | CG45: =CG33/CG36 -> 0.29104306
B46: Taiwan, China Revenues % of Revenues | AQ46: =AQ34/AQ36 -> 0.11619396 | AR46: =AR34/AR36 -> 0.11722913 | AS46: =AS34/AS36 -> 0.1101083 | AT46: =AT34/AT36 -> 0.10091743 | AU46: =AU34/AU36 -> 0.10384301 | AV46: =AV34/AV36 -> 0.10154905 | AW46: =AW34/AW36 -> 0.11928251 | AX46: =AX34/AX36 -> 0.086715867 | ... BK46: =BK34/BK36 -> 0.047662695 | CC46: =CC34/CC36 -> 0.11091471 | CD46: =CD34/CD36 -> 0.10296684 | CE46: =CE34/CE36 -> 0.085257549 | CF46: =CF34/CF36 -> 0.070448307 | CG46: =CG34/CG36 -> 0.055952107
B47: APAC Revenues % of Revenues | AQ47: =AQ35/AQ36 -> 0.090576395 | AR47: =AR35/AR36 -> 0.075488455 | AS47: =AS35/AS36 -> 0.081227437 | AT47: =AT35/AT36 -> 0.20266889 | AU47: =AU35/AU36 -> 0.10793132 | AV47: =AV35/AV36 -> 0.11273666 | AW47: =AW35/AW36 -> 0.11300448 | AX47: =AX35/AX36 -> 0.14298893 | ... BK47: =BK35/BK36 -> 0.085242896 | CC47: =CC35/CC36 -> 0.1142289 | CD47: =CD35/CD36 -> 0.11867365 | CE47: =CE35/CE36 -> 0.10190941 | CF47: =CF35/CF36 -> 0.10018298 | CG47: =CG35/CG36 -> 0.099009901
B49: Revenues | C49: 282.515 | D49: 287.45 | E49: 235.499 | F49: 250.071 | G49: 272.77 | H49: 280.607 | I49: 285.874 | J49: 309.265 | K49: 330.958 | L49: 346.094 | M49: 356.8 | N49: 387.326 | O49: 420.781 | P49: 447.568 | Q49: 480.63 | R49: 512.379 | S49: 538.565 | T49: 539.378 | U49: 550.271 | V49: 591.786 | W49: 572 | X49: 600 | Y49: 607 | Z49: 619 | AA49: 598 | AB49: 662 | AC49: 714 | AD49: 778 | AE49: 154 | AF49: 830 | AG49: 853 | AH49: 1496 | AI49: 846 | AJ49: 838 | AK49: 907 | AL49: 952 | AM49: 859 | AN49: 633 | AO49: 794 | AP49: 953 | AQ49: =AQ8 -> 1093 | AR49: =AR8 -> 1126 | AS49: =AS8 -> 1108 | AT49: =AT8 -> 1199 | AU49: =AU8 -> 1223 | AV49: =AV8 -> 1162 | AW49: =AW8 -> 1115 | AX49: =AX8 -> 1084 | ... BK49: =BK8 -> 1091 | BS49: =SUM(C49:F49) -> 1055.535 | BT49: =SUM(G49:J49) -> 1148.516 | BU49: =SUM(K49:N49) -> 1421.178 | BV49: =SUM(O49:R49) -> 1861.358 | BW49: =SUM(S49:V49) -> 2220 | BX49: =SUM(W49:Z49) -> 2398 | BY49: =SUM(AA49:AD49) -> 2752 | BZ49: =SUM(AE49:AH49) -> 3333 | CA49: =SUM(AI49:AL49) -> 3543 | CB49: =SUM(AM49:AP49) -> 3239 | CC49: =SUM(AQ49:AT49) -> 4526 | CD49: =SUM(AU49:AX49) -> 4584 | CE49: =SUM(AY49:BB49) -> 4504 | CF49: =SUM(BC49:BF49) -> 4372 | CG49: =SUM(BG49:BJ49) -> 4343
...

Sheet Notes | Quant Analysis
CI1: 0
P2: Employee Scope: | AL2: General Notes/Observations (Updated Q1'26)
Q32: Notes: | R32: [X]
R33: [Y]
R34: [Z]
AL35: Financial Stmts. Notes/Observations (Updated Q1'26)
P36: Institutional Ownership Snapshot Q4'25 | AL36: Revenues:
AL37: [Godel Snapshot of projected sales]
Q65: Notes: | R65: [X]
R66: [Y]
R67: [Z]
P69: Revenue Breakdown by Segment (Build graph for this section if applicable…. See example below) | AL69: Earnings Scope:
AL70: [Godel Snapshot of projected earnings/EPS + CFFO]
Q101: Notes: | R101: [X]
R102: [Y]
R103: [Z]
P105: Q/q Total Revenues, Net Income, FCF | AL105: Balance Sheet Scope:
AL106: [Godel Snapshot of projected balances (assets, liabilities, equity)]
Q134: Notes: | R134: [X]
R135: [Y]
R136: [Z]
P138: Y/y Total Revenues, Net Income, FCF | AL138: [Equity Preformance Compared to Peers]
AL139: Use Godel CMS command
Q167: Notes: | R167: [X]
R168: [Y]
R169: [Z]
A184: VOO Historical Returns
A185: 1506 Trading Days? (From: 7/4/2020 - 7/4/2026) | I185: 1506 Trading Days? (From: 7/4/2020 - 7/4/2026)
A186: Close | B186: High | C186: Low | D186: Open | E186: Volume | F186: UTC Date | G186: Change | I186: Close | J186: High | K186: Low | L186: Open | M186: Volume | N186: UTC Date | O186: Change
A187: 684.84 | B187: 690.5 | C187: 680.215 | D187: 686.98 | E187: 6980816.8 | F187: Thu, 02 Jul 2026 00:00:00 GMT | G187: =A187/D187-1 -> -0.0031150834 | I187: 188.68 | J187: 189.46 | K187: 184.4 | L187: 186.755 | M187: 2941433.1 | N187: Thu, 02 Jul 2026 00:00:00 GMT | O187: =I187/L187-1 -> 0.010307622
A188: 685.46 | B188: 688.83 | C188: 682.3 | D188: 684.73 | E188: 8627875 | F188: Wed, 01 Jul 2026 00:00:00 GMT | G188: =A188/D188-1 -> 0.0010661137 | I188: 183.89 | J188: 184.9 | K188: 175.6 | L188: 175.83 | M188: 2125399.7 | N188: Wed, 01 Jul 2026 00:00:00 GMT | O188: =I188/L188-1 -> 0.045839732
A189: 686.81 | B189: 687.529 | C189: 680.99 | D189: 681.32 | E189: 9853712.9 | F189: Tue, 30 Jun 2026 00:00:00 GMT | G189: =A189/D189-1 -> 0.0080578876 | I189: 175.83 | J189: 181 | K189: 174.78 | L189: 180.97 | M189: 1753585.7 | N189: Tue, 30 Jun 2026 00:00:00 GMT | O189: =I189/L189-1 -> -0.028402498
A190: 681.01 | B190: 681.565 | C190: 672.93 | D190: 677.01 | E190: 5649228.8 | F190: Mon, 29 Jun 2026 00:00:00 GMT | G190: =A190/D190-1 -> 0.0059083322 | I190: 181.1 | J190: 181.28 | K190: 175.13 | L190: 177.39 | M190: 1506842.1 | N190: Mon, 29 Jun 2026 00:00:00 GMT | O190: =I190/L190-1 -> 0.020914369
A191: 670.26 | B191: 676.955 | C191: 668.1 | D191: 669.96 | E191: 5935648.6 | F191: Fri, 26 Jun 2026 00:00:00 GMT | G191: =A191/D191-1 -> 0.00044778793 | I191: 176.55 | J191: 179.9255 | K191: 173.235 | L191: 176.065 | M191: 2183494.9 | N191: Fri, 26 Jun 2026 00:00:00 GMT | O191: =I191/L191-1 -> 0.0027546645
A192: 673.7478 | B192: 679.56087 | C192: 670.62689 | D192: 679.16203 | E192: 23355606 | F192: Thu, 25 Jun 2026 00:00:00 GMT | G192: =A192/D192-1 -> -0.0079719294 | I192: 177.65 | J192: 182.84 | K192: 176.54 | L192: 178.24 | M192: 2910070.7 | N192: Thu, 25 Jun 2026 00:00:00 GMT | O192: =I192/L192-1 -> -0.0033101436
A193: 673.72786 | B193: 680.08933 | C193: 671.72369 | D193: 675.71208 | E193: 9593615.8 | F193: Wed, 24 Jun 2026 00:00:00 GMT | G193: =A193/D193-1 -> -0.0029364892 | I193: 175.09 | J193: 177.76 | K193: 166.04 | L193: 166.12 | M193: 2643618.1 | N193: Wed, 24 Jun 2026 00:00:00 GMT | O193: =I193/L193-1 -> 0.053997111
A194: 674.37597 | B194: 679.74912 | C194: 673.0598 | D194: 674.39093 | E194: 17263981 | F194: Tue, 23 Jun 2026 00:00:00 GMT | G194: =A194/D194-1 -> -2.2177703e-05 | I194: 164.93 | J194: 166.63 | K194: 159.98 | L194: 160.6 | M194: 2055863 | N194: Tue, 23 Jun 2026 00:00:00 GMT | O194: =I194/L194-1 -> 0.026961395
A195: 684.10763 | B195: 689.49195 | C195: 683.01082 | D195: 687.16871 | E195: 13365185 | F195: Mon, 22 Jun 2026 00:00:00 GMT | G195: =A195/D195-1 -> -0.0044546338 | I195: 161.38 | J195: 163.79 | K195: 158.91 | L195: 161.83 | M195: 1790688 | N195: Mon, 22 Jun 2026 00:00:00 GMT | O195: =I195/L195-1 -> -0.0027806958
A196: 686.11179 | B196: 687.69717 | C196: 683.70879 | D196: 687.29834 | E196: 17768872 | F196: Thu, 18 Jun 2026 00:00:00 GMT | G196: =A196/D196-1 -> -0.0017263891 | I196: 161.93 | J196: 162.78 | K196: 159.51 | L196: 161.31 | M196: 3079550.2 | N196: Thu, 18 Jun 2026 00:00:00 GMT | O196: =I196/L196-1 -> 0.0038435311
A197: 679.43125 | B197: 689.52186 | C197: 677.66639 | D197: 688.7541 | E197: 15004527 | F197: Wed, 17 Jun 2026 00:00:00 GMT | G197: =A197/D197-1 -> -0.013535816 | I197: 159.09 | J197: 165.4 | K197: 157.63 | L197: 163.24 | M197: 1591874.5 | N197: Wed, 17 Jun 2026 00:00:00 GMT | O197: =I197/L197-1 -> -0.025422691
...

Sheet Product Lines

Sheet Management

Sheet Table Formatting
B2: [Bold Title] | G2: [Bold Title]
B3: Line Titles | G3: <-- General
B4: Line Titles | G4: <-- Info
B5: Line Titles | G5: <-- General
B6: Line Titles | G6: <-- Info
B7: Line Titles | G7: <-- General
B8: Line Titles | G8: <-- Info
