Workbook

Sheet Main
A1: Master
A2: Capital Structure Snapshot:
B4: ISRG
B5: Price | C5: 407.34 | D5: 10/21/2026
B6: SO | C6: 349 | D6: Q2'26
B7: MC | C7: =C5*C6 -> 142161.66
B8: Cash | C8: 6800.4 | D8: Q2'26
B9: Debt | C9: 0 | D9: Q2'26
B10: EV | C10: =C7-C8+C9 -> 135361.26
B12: Intuitive Surgical, Inc. (ISRG)
B14: Founder(s): Frederic Moll, John Freund, and Robert Younge | H14: Registered Exchange: NASDAQ | P14: Resources:
B15: Founded: 1995 | H15: Address: 1020 Kifer Road, Sunnyvale, California 94086 | P15: SEC filings | S15: https://www.sec.gov/edgar/browse/?CIK=1035267&owner=exclude
B16: Headquarters: Sunnyvale, CA | H16: Investor Relations Contact: | P16: Intuitive Homepage | S16: https://www.intuitive.com/en-us
B17: Current CEO: David Rosa (Succeeding Gary Guthart who stepped back into Chairman role July 1st, 2025) | H17: Investors Relation Department | Q17: Intuitive IR Page | T17: https://isrg.intuitive.com/
B18: Employees: 15,638 (Q4'24) | H18: Phone: (408) 523-2161 | K18: Email: | L18: investor.relations@intusurg.com | P18: Earnings Calls | S18: https://seekingalpha.com/symbol/ISRG/earnings/transcripts
B19: Industry: Medical Instruments & Supplies | P19: Equity Analysis | S19: https://stockanalysis.com/stocks/isrg/company/
B20: Sector: Healthcare | P20: MacroTrends | S20: https://www.macrotrends.net/stocks/charts/ISRG/intuitive-surgical/cash-flow-statement?freq=Q
B21: IPO: June 13, 2000 -- ~$116M valuation | P21: ROIC, WACC | S21: https://www.gurufocus.com/term/wacc/ISRG
B22: Fiscal Year: [January - December] | P22: Godel Terminal | S22: https://app.godelterminal.com/
A24: Company Overview:
B25: Intuitive Surgical, Inc. develops, manufactures, and markets products that enable physicians and healthcare providers to enhance the quality of and access to minimally invasive care in the United States and internationally
B26: The Company offers the Da Vinci Surgical System that enables surgical procedures using a minimally invasive approach; and Ion endoluminal system, which extends its commercial offerings beyond surgery into diagnostic endoluminal procedures enabling minimally invasive biopsies in the lung
B27: It also provides a suite of stapling, energy, and core instrumentation for its multi-port da Vinci surgical systems; progressive learning pathways to support the use of its technology
C28: Infrastructure of service and support specialists, a complement of services to its customers
C29: Including installation, repair, maintenance, 24/7 technical support, and proactive system health monitoring
C30: Integrated digital capabilities providing connected offerings, streamlining performance for hospitals with program-enhancing insights
B31: The Company sells its products through direct sales organizations, such as capital and clinical sales teams
C32: Intuitive Surgical, Inc. was incorporated in 1995 and is headquartered in Sunnyvale, California
B33: They did surgery on a grape
A35: Business Segments and Geographical Info:

Sheet Model
B1: [Use for Graphing] | AU1: Q1 2020 | AY1: Q1 2021 | BC1: Q1 2022 | BG1: Q1 2023 | BK1: Q1 2024 | BO1: Q1 2025 | BS1: Q1 2026
B2: Quarterly
B3: Revenues | C3: Q1 2009 | D3: Q2 2009 | E3: Q3 2009 | F3: Q4 2009 | G3: Q1 2010 | H3: Q2 2010 | I3: Q3 2010 | J3: Q4 2010 | K3: Q1 2011 | L3: Q2 2011 | M3: Q3 2011 | N3: Q4 2011 | O3: Q1 2012 | P3: Q2 2012 | Q3: Q3 2012 | R3: Q4 2012 | S3: Q1 2013 | T3: Q2 2013 | U3: Q3 2013 | V3: Q4 2013 | W3: Q1 2014 | X3: Q2 2014 | Y3: Q3 2014 | Z3: Q4 2014 | AA3: Q1 2015 | AB3: Q2 2015 | AC3: Q3 2015 | AD3: Q4 2015 | AE3: Q1 2016 | AF3: Q2 2016 | AG3: Q3 2016 | AH3: Q4 2016 | AI3: Q1 2017 | AJ3: Q2 2017 | AK3: Q3 2017 | AL3: Q4 2017 | AM3: Q1 2018 | AN3: Q2 2018 | AO3: Q3 2018 | AP3: Q4 2018 | AQ3: Q1 2019 | AR3: Q2 2019 | AS3: Q3 2019 | AT3: Q4 2019 | AU3: Q1 2020 | AV3: Q2 2020 | AW3: Q3 2020 | AX3: Q4 2020 | AY3: Q1 2021 | AZ3: Q2 2021 | BA3: Q3 2021 | BB3: Q4 2021 | BC3: Q1 2022 | BD3: Q2 2022 | BE3: Q3 2022 | BF3: Q4 2022 | BG3: Q1 2023 | BH3: Q2 2023 | BI3: Q3 2023 | BJ3: Q4 2023 | BK3: Q1 2024 | BL3: Q2 2024 | BM3: Q3 2024 | BN3: Q4 2024 | BO3: Q1 2025 | BP3: Q2 2025 | BQ3: Q3 2025 | BR3: Q4 2025 | BS3: Q1 2026 | BT3: Q2 2026 | BU3: Q3 2026 | BV3: Q4 2026 | CA3: =CB3-1 -> 2009 | CB3: =CC3-1 -> 2010 | CC3: =CD3-1 -> 2011 | CD3: =CE3-1 -> 2012 | CE3: =CF3-1 -> 2013 | CF3: =CG3-1 -> 2014 | CG3: =CH3-1 -> 2015 | CH3: =CI3-1 -> 2016 | ... CK3: =CL3-1 -> 2019 | CL3: 2020 | CM3: =CL3+1 -> 2021 | CN3: =CM3+1 -> 2022 | CO3: =CN3+1 -> 2023 | CP3: =CO3+1 -> 2024 | CQ3: =CP3+1 -> 2025 | CR3: =CQ3+1 -> 2026 | CS3: =CR3+1 -> 2027 | CT3: =CS3+1 -> 2028 | ... EY3: =EX3+1 -> 2085
B4: Instruments & Accessories | AU4: 617.5 | AV4: 460.8 | AW4: 630.5 | AX4: =2455.7-SUM(AU4:AW4) -> 746.9 | AY4: 705.9 | AZ4: 796.4 | BA4: 755.4 | BB4: =3100.5-SUM(AY4:BA4) -> 842.8 | BC4: 810.3 | BD4: 895.3 | BE4: 871.6 | BF4: =3517.9-SUM(BC4:BE4) -> 940.7 | BG4: 985.6 | BH4: 1075.9 | BI4: 1071.4 | BJ4: =4276.6-SUM(BG4:BI4) -> 1143.7 | BK4: 1158.9 | BL4: 1244.4 | BM4: 1264.2 | BN4: =5079-SUM(BK4:BM4) -> 1411.5 | BO4: 1367.7 | BP4: =2841.8-BO4 -> 1474.1 | BQ4: 1518.8 | BR4: 1658.3 | BS4: 1686.4 | BT4: 1734.9 | BU4: 1797.4 | CL4: =SUM(AU4:AX4) -> 2455.7 | CM4: =SUM(AY4:BB4) -> 3100.5 | CN4: =SUM(BC4:BF4) -> 3517.9 | CO4: =SUM(BG4:BJ4) -> 4276.6 | CP4: =SUM(BK4:BN4) -> 5079 | CQ4: =SUM(BO4:BR4) -> 6018.9 | CR4: =CQ4*(1+CR9) -> 7102.302 | CS4: =CR4*(1+CS9) -> 8096.6243 | CT4: =CS4*(1+CT9) -> 9149.1854 | CU4: =CT4*(1+CU9) -> 10247.088 | CV4: =CU4*(1+CV9) -> 11374.267 | CW4: =CV4*(1+CW9) -> 12511.694 | CX4: =CW4*(1+CX9) -> 13637.747 | CY4: =CX4*(1+CY9) -> 14592.389 | ... DA4: =CZ4*(1+DA9) -> 16473.348
B5: Systems | AU5: 283.3 | AV5: 261 | AW5: 267.8 | AX5: =1178.9-SUM(AU5:AW5) -> 366.8 | AY5: 368.7 | AZ5: 439.6 | BA5: 415.2 | BB5: =1693.4-SUM(AY5:BA5) -> 469.9 | BC5: 428.1 | BD5: 375.1 | BE5: 425.9 | BF5: =1680.1-SUM(BC5:BE5) -> 451 | BG5: 427.4 | BH5: 392.7 | BI5: 379.4 | BJ5: =1679.7-SUM(BG5:BI5) -> 480.2 | BK5: 418.2 | BL5: 448.2 | BM5: 445 | BN5: =1966-SUM(BK5:BM5) -> 654.6 | BO5: 522.7 | BP5: =1097.4-BO5 -> 574.7 | BQ5: 590.4 | BR5: 785.9 | BS5: 650.7 | BT5: 685 | BU5: 769.1 | CL5: =SUM(AU5:AX5) -> 1178.9 | CM5: =SUM(AY5:BB5) -> 1693.4 | CN5: =SUM(BC5:BF5) -> 1680.1 | CO5: =SUM(BG5:BJ5) -> 1679.7 | CP5: =SUM(BK5:BN5) -> 1966 | CQ5: =SUM(BO5:BR5) -> 2473.7 | CR5: =CQ5*(1+CR10) -> 2993.177 | CS5: =CR5*(1+CS10) -> 3382.29 | CT5: =CS5*(1+CT10) -> 3788.1648 | CU5: =CT5*(1+CU10) -> 4337.4487 | CV5: =CU5*(1+CV10) -> 4944.6915 | CW5: =CV5*(1+CW10) -> 5612.2249 | CX5: =CW5*(1+CX10) -> 6229.5696 | CY5: =CX5*(1+CY10) -> 6868.1005 | ... DA5: =CZ5*(1+DA10) -> 7899.9038
B6: Services | AU6: 198.7 | AV6: 130.3 | AW6: 179.4 | AX6: =723.8-SUM(AU6:AW6) -> 215.4 | AY6: 217.5 | AZ6: 228 | BA6: 232.7 | BB6: =916.2-SUM(AY6:BA6) -> 238 | BC6: 249.3 | BD6: 251.7 | BE6: 259.9 | BF6: =1024.2-SUM(BC6:BE6) -> 263.3 | BG6: 283.2 | BH6: 287.3 | BI6: 292.9 | BJ6: =1167.8-SUM(BG6:BI6) -> 304.4 | BK6: 313.5 | BL6: 317.3 | BM6: 328.9 | BN6: =1307.1-SUM(BK6:BM6) -> 347.4 | BO6: 363 | BP6: =754.2-BO6 -> 391.2 | BQ6: 395 | BR6: 423 | BS6: 433.7 | BT6: 472.4 | BU6: 482.2 | CL6: =SUM(AU6:AX6) -> 723.8 | CM6: =SUM(AY6:BB6) -> 916.2 | CN6: =SUM(BC6:BF6) -> 1024.2 | CO6: =SUM(BG6:BJ6) -> 1167.8 | CP6: =SUM(BK6:BN6) -> 1307.1 | CQ6: =SUM(BO6:BR6) -> 1572.2 | CR6: =CQ6*(1+CR11) -> 1823.752 | CS6: =CR6*(1+CS11) -> 2097.3148 | CT6: =CS6*(1+CT11) -> 2401.4254 | CU6: =CT6*(1+CU11) -> 2737.625 | CV6: =CU6*(1+CV11) -> 3107.2044 | CW6: =CV6*(1+CW11) -> 3511.141 | CX6: =CW6*(1+CX11) -> 3897.3665 | CY6: =CX6*(1+CY11) -> 4267.6163 | ... DA6: =CZ6*(1+DA11) -> 4885.8872
B7: Ttl Revenues | AU7: =SUM(AU4:AU6) -> 1099.5 | AV7: =SUM(AV4:AV6) -> 852.1 | AW7: =SUM(AW4:AW6) -> 1077.7 | AX7: =SUM(AX4:AX6) -> 1329.1 | AY7: =SUM(AY4:AY6) -> 1292.1 | AZ7: =SUM(AZ4:AZ6) -> 1464 | BA7: =SUM(BA4:BA6) -> 1403.3 | BB7: =SUM(BB4:BB6) -> 1550.7 | ... BU7: =SUM(BU4:BU6) -> 3048.7 | CL7: =SUM(AU7:AX7) -> 4358.4 | CM7: =SUM(AY7:BB7) -> 5710.1 | CN7: =SUM(BC7:BF7) -> 6222.2 | CO7: =SUM(BG7:BJ7) -> 7124.1 | CP7: =SUM(BK7:BN7) -> 8352.1 | CQ7: =SUM(BO7:BR7) -> 10064.8 | CR7: =SUM(CR4:CR6) -> 11919.231 | CS7: =SUM(CS4:CS6) -> 13576.229 | CT7: =SUM(CT4:CT6) -> 15338.776 | CU7: =SUM(CU4:CU6) -> 17322.161 | CV7: =SUM(CV4:CV6) -> 19426.163 | CW7: =SUM(CW4:CW6) -> 21635.06 | CX7: =SUM(CX4:CX6) -> 23764.683 | CY7: =SUM(CY4:CY6) -> 25728.106 | ... DA7: =SUM(DA4:DA6) -> 29259.139
B9: Instruments & Accessories Growth Y/y | AY9: =AY4/AU4-1 -> 0.14315789 | AZ9: =AZ4/AV4-1 -> 0.72829861 | BA9: =BA4/AW4-1 -> 0.19809675 | BB9: =BB4/AX4-1 -> 0.12839738 | BC9: =BC4/AY4-1 -> 0.1478963 | BD9: =BD4/AZ4-1 -> 0.12418383 | BE9: =BE4/BA4-1 -> 0.15382579 | BF9: =BF4/BB4-1 -> 0.11616042 | ... BU9: =BU4/BQ4-1 -> 0.18343429 | CM9: =CM4/CL4-1 -> 0.26257279 | CN9: =CN4/CM4-1 -> 0.13462345 | CO9: =CO4/CN4-1 -> 0.21566844 | CP9: =CP4/CO4-1 -> 0.18762568 | CQ9: =CQ4/CP4-1 -> 0.18505611 | CR9: 0.18 | CS9: 0.14 | CT9: 0.13 | CU9: 0.12 | CV9: 0.11 | CW9: 0.1 | CX9: 0.09 | CY9: 0.07 | CZ9: 0.065 | DA9: 0.06
B10: Systems Growth Y/y | AY10: =AY5/AU5-1 -> 0.30144723 | AZ10: =AZ5/AV5-1 -> 0.68429119 | BA10: =BA5/AW5-1 -> 0.55041075 | BB10: =BB5/AX5-1 -> 0.28107961 | BC10: =BC5/AY5-1 -> 0.16110659 | BD10: =BD5/AZ5-1 -> -0.14672429 | BE10: =BE5/BA5-1 -> 0.025770713 | BF10: =BF5/BB5-1 -> -0.040221324 | ... BU10: =BU5/BQ5-1 -> 0.30267615 | CM10: =CM5/CL5-1 -> 0.43642378 | CN10: =CN5/CM5-1 -> -0.0078540215 | CO10: =CO5/CN5-1 -> -0.00023808107 | CP10: =CP5/CO5-1 -> 0.1704471 | CQ10: =CQ5/CP5-1 -> 0.25824008 | CR10: 0.21 | CS10: 0.13 | CT10: 0.12 | CU10: 0.145 | CV10: 0.14 | CW10: 0.135 | CX10: 0.11 | CY10: 0.1025 | CZ10: 0.0775 | DA10: 0.0675
B11: Services Growth Y/y | AY11: =AY6/AU6-1 -> 0.094614997 | AZ11: =AZ6/AV6-1 -> 0.74980814 | BA11: =BA6/AW6-1 -> 0.29710145 | BB11: =BB6/AX6-1 -> 0.10492108 | BC11: =BC6/AY6-1 -> 0.1462069 | BD11: =BD6/AZ6-1 -> 0.10394737 | BE11: =BE6/BA6-1 -> 0.1168887 | BF11: =BF6/BB6-1 -> 0.10630252 | ... BU11: =BU6/BQ6-1 -> 0.22075949 | CM11: =CM6/CL6-1 -> 0.26581929 | CN11: =CN6/CM6-1 -> 0.11787819 | CO11: =CO6/CN6-1 -> 0.14020699 | CP11: =CP6/CO6-1 -> 0.11928412 | CQ11: =CQ6/CP6-1 -> 0.20281539 | CR11: 0.16 | CS11: 0.15 | CT11: 0.145 | CU11: 0.14 | CV11: 0.135 | CW11: 0.13 | CX11: 0.11 | CY11: 0.095 | CZ11: 0.075 | DA11: 0.065
B12: Ttl Revenue Growth Y/y | AY12: =AY7/AU7-1 -> 0.17517053 | AZ12: =AZ7/AV7-1 -> 0.7181082 | BA12: =BA7/AW7-1 -> 0.3021249 | BB12: =BB7/AX7-1 -> 0.16672937 | BC12: =BC7/AY7-1 -> 0.15138147 | BD12: =BD7/AZ7-1 -> 0.039685792 | BE12: =BE7/BA7-1 -> 0.10981258 | BF12: =BF7/BB7-1 -> 0.067259947 | ... BU12: =BU7/BQ7-1 -> 0.21743471 | CM12: =CM7/CL7-1 -> 0.31013675 | CN12: =CN7/CM7-1 -> 0.089683193 | CO12: =CO7/CN7-1 -> 0.14494873 | CP12: =CP7/CO7-1 -> 0.17237265 | CQ12: =CQ7/CP7-1 -> 0.2050622 | CR12: =CR7/CQ7-1 -> 0.18424917 | CS12: =CS7/CR7-1 -> 0.13901888 | CT12: =CT7/CS7-1 -> 0.12982593 | ... DA12: =DA7/CZ7-1 -> 0.062849409
B14: Instrument & Acc. % of Ttl Revenues | AU14: =AU4/AU7 -> 0.56161892 | AV14: =AV4/AV7 -> 0.5407816 | AW14: =AW4/AW7 -> 0.58504222 | AX14: =AX4/AX7 -> 0.56195922 | AY14: =AY4/AY7 -> 0.54631994 | AZ14: =AZ4/AZ7 -> 0.54398907 | BA14: =BA4/BA7 -> 0.53830257 | BB14: =BB4/BB7 -> 0.54349649 | ... BU14: =BU4/BU7 -> 0.58956276 | CL14: =CL4/CL7 -> 0.56344071 | CM14: =CM4/CM7 -> 0.54298524 | CN14: =CN4/CN7 -> 0.5653788 | CO14: =CO4/CO7 -> 0.60030039 | CP14: =CP4/CP7 -> 0.60811054 | CQ14: =CQ4/CQ7 -> 0.59801486
B15: Systems % of Ttl Revenues | AU15: =AU5/AU7 -> 0.25766257 | AV15: =AV5/AV7 -> 0.30630208 | AW15: =AW5/AW7 -> 0.24849216 | AX15: =AX5/AX7 -> 0.27597622 | AY15: =AY5/AY7 -> 0.28534943 | AZ15: =AZ5/AZ7 -> 0.30027322 | BA15: =BA5/BA7 -> 0.29587401 | BB15: =BB5/BB7 -> 0.30302444 | ... BU15: =BU5/BU7 -> 0.25227146 | CL15: =CL5/CL7 -> 0.27048917 | CM15: =CM5/CM7 -> 0.29656223 | CN15: =CN5/CN7 -> 0.27001704 | CO15: =CO5/CO7 -> 0.23577715 | CP15: =CP5/CP7 -> 0.2353899 | CQ15: =CQ5/CQ7 -> 0.24577736
B16: Services % of Ttl Revenues | AU16: =AU6/AU7 -> 0.18071851 | AV16: =AV6/AV7 -> 0.15291632 | AW16: =AW6/AW7 -> 0.16646562 | AX16: =AX6/AX7 -> 0.16206455 | AY16: =AY6/AY7 -> 0.16833062 | AZ16: =AZ6/AZ7 -> 0.1557377 | BA16: =BA6/BA7 -> 0.16582342 | BB16: =BB6/BB7 -> 0.15347907 | ... BU16: =BU6/BU7 -> 0.15816578 | CL16: =CL6/CL7 -> 0.16607012 | CM16: =CM6/CM7 -> 0.16045253 | CN16: =CN6/CN7 -> 0.16460416 | CO16: =CO6/CO7 -> 0.16392246 | CP16: =CP6/CP7 -> 0.15649956 | CQ16: =CQ6/CQ7 -> 0.15620777
B18: Ttl Revenues | C18: 188.4 | D18: 260.6 | E18: 280.1 | F18: 323.1 | G18: 328.6 | H18: 350.7 | I18: 344.4 | J18: 389.3 | K18: 388.1 | L18: 425.7 | M18: 446.7 | N18: 496.8 | O18: 495.2 | P18: 536.5 | Q18: 537.8 | R18: 609.3 | S18: 611.4 | T18: 578.5 | U18: 499 | V18: 576.2 | W18: 464.7 | X18: 512.2 | Y18: 550.1 | Z18: 604.7 | AA18: 532.1 | AB18: 586.1 | AC18: 589.7 | AD18: 676.5 | AE18: 594.5 | AF18: 670.1 | AG18: 682.9 | AH18: 759 | AI18: 679.6 | AJ18: 758.8 | AK18: 807.8 | AL18: 892 | AM18: 847.5 | AN18: 909.3 | AO18: 920.9 | AP18: 1046.5 | AQ18: 973.7 | AR18: 1098.9 | AS18: 1128.2 | AT18: 1277.7 | AU18: =AU7 -> 1099.5 | AV18: =AV7 -> 852.1 | AW18: =AW7 -> 1077.7 | AX18: =AX7 -> 1329.1 | AY18: =AY7 -> 1292.1 | AZ18: =AZ7 -> 1464 | BA18: =BA7 -> 1403.3 | BB18: =BB7 -> 1550.7 | ... BU18: =BU7 -> 3048.7 | CA18: =SUM(C18:F18) -> 1052.2 | CB18: =SUM(G18:J18) -> 1413 | CC18: =SUM(K18:N18) -> 1757.3 | CD18: =SUM(O18:R18) -> 2178.8 | CE18: =SUM(S18:V18) -> 2265.1 | CF18: =SUM(W18:Z18) -> 2131.7 | CG18: =SUM(AA18:AD18) -> 2384.4 | CH18: =SUM(AE18:AH18) -> 2706.5 | CI18: =SUM(AI18:AL18) -> 3138.2 | CJ18: =SUM(AM18:AP18) -> 3724.2 | CK18: =SUM(AQ18:AT18) -> 4478.5 | CL18: =SUM(AU18:AX18) -> 4358.4 | CM18: =SUM(AY18:BB18) -> 5710.1 | CN18: =SUM(BC18:BF18) -> 6222.2 | CO18: =SUM(BG18:BJ18) -> 7124.1 | CP18: =SUM(BK18:BN18) -> 8352.1 | CQ18: =SUM(BO18:BR18) -> 10064.8 | CR18: =CR7 -> 11919.231 | CS18: =CS7 -> 13576.229 | CT18: =CT7 -> 15338.776 | CU18: =CU7 -> 17322.161 | CV18: =CV7 -> 19426.163 | CW18: =CW7 -> 21635.06 | CX18: =CX7 -> 23764.683 | CY18: =CY7 -> 25728.106 | ... DA18: =DA7 -> 29259.139
B19: COGS | C19: 59.7 | D19: 70.4 | E19: 81.1 | F19: 89.9 | G19: 88.1 | H19: 93.9 | I19: 93.8 | J19: 107.2 | K19: 109.3 | L19: 119.1 | M19: 121.2 | N19: 133.9 | O19: 139.3 | P19: 150.1 | Q19: 147.7 | R19: 171.4 | S19: 177.1 | T19: 173.3 | U19: 142.3 | V19: 178.2 | W19: 149.3 | X19: 167.8 | Y19: 189.5 | Z19: 211.3 | AA19: 195.3 | AB19: 199.6 | AC19: 193.9 | AD19: 217.7 | AE19: 189.5 | AF19: 199.2 | AG19: 195.9 | AH19: 229 | AI19: 209.8 | AJ19: 228.7 | AK19: 239.7 | AL19: 258 | AM19: 253.7 | AN19: 277 | AO19: 278.6 | AP19: 310.8 | AQ19: 304.1 | AR19: 339.9 | AS19: 342.6 | AT19: 381.7 | AU19: 361.3 | AV19: 349.2 | AW19: 353.4 | AX19: =1497.2-SUM(AU19:AW19) -> 433.3 | AY19: 389.5 | AZ19: 440.3 | BA19: 431.9 | BB19: =1751.6-SUM(AY19:BA19) -> 489.9 | BC19: 478 | BD19: 498.8 | BE19: 505.3 | BF19: =2026.2-SUM(BC19:BE19) -> 544.1 | BG19: 583.2 | BH19: 584 | BI19: 576.5 | BJ19: =2394.6-SUM(BG19:BI19) -> 650.9 | BK19: 645.2 | BL19: 637.2 | BM19: 664.2 | BN19: =2717.9-SUM(BK19:BM19) -> 771.3 | BO19: 795.7 | BP19: 822.1 | BQ19: 842.7 | BR19: 961.9 | BS19: 940.3 | BT19: 931.9 | BU19: 964.4 | CA19: =SUM(C19:F19) -> 301.1 | CB19: =SUM(G19:J19) -> 383 | CC19: =SUM(K19:N19) -> 483.5 | CD19: =SUM(O19:R19) -> 608.5 | CE19: =SUM(S19:V19) -> 670.9 | CF19: =SUM(W19:Z19) -> 717.9 | CG19: =SUM(AA19:AD19) -> 806.5 | CH19: =SUM(AE19:AH19) -> 813.6 | CI19: =SUM(AI19:AL19) -> 936.2 | CJ19: =SUM(AM19:AP19) -> 1120.1 | CK19: =SUM(AQ19:AT19) -> 1368.3 | CL19: =SUM(AU19:AX19) -> 1497.2 | CM19: =SUM(AY19:BB19) -> 1751.6 | CN19: =SUM(BC19:BF19) -> 2026.2 | CO19: =SUM(BG19:BJ19) -> 2394.6 | CP19: =SUM(BK19:BN19) -> 2717.9 | CQ19: =SUM(BO19:BR19) -> 3422.4 | CR19: =CR18*(1-CR33) -> 3921.427 | CS19: =CS18*(1-CS33) -> 4507.3081 | CT19: =CT18*(1-CT33) -> 5061.796 | CU19: =CU18*(1-CU33) -> 5698.9911 | CV19: =CV18*(1-CV33) -> 6371.7815 | CW19: =CW18*(1-CW33) -> 7053.0295 | CX19: =CX18*(1-CX33) -> 7723.5218 | CY19: =CY18*(1-CY33) -> 8361.6343 | ... DA19: =DA18*(1-DA33) -> 9509.2201
B20: GP | C20: =C18-C19 -> 128.7 | D20: =D18-D19 -> 190.2 | E20: =E18-E19 -> 199 | F20: =F18-F19 -> 233.2 | G20: =G18-G19 -> 240.5 | H20: =H18-H19 -> 256.8 | I20: =I18-I19 -> 250.6 | J20: =J18-J19 -> 282.1 | ... BU20: =BU18-BU19 -> 2084.3 | CA20: =SUM(C20:F20) -> 751.1 | CB20: =SUM(G20:J20) -> 1030 | CC20: =SUM(K20:N20) -> 1273.8 | CD20: =SUM(O20:R20) -> 1570.3 | CE20: =SUM(S20:V20) -> 1594.2 | CF20: =SUM(W20:Z20) -> 1413.8 | CG20: =SUM(AA20:AD20) -> 1577.9 | CH20: =SUM(AE20:AH20) -> 1892.9 | CI20: =SUM(AI20:AL20) -> 2202 | CJ20: =SUM(AM20:AP20) -> 2604.1 | CK20: =SUM(AQ20:AT20) -> 3110.2 | CL20: =SUM(AU20:AX20) -> 2861.2 | CM20: =SUM(AY20:BB20) -> 3958.5 | CN20: =SUM(BC20:BF20) -> 4196 | CO20: =SUM(BG20:BJ20) -> 4729.5 | CP20: =SUM(BK20:BN20) -> 5634.2 | CQ20: =SUM(BO20:BR20) -> 6642.4 | CR20: =CR18*CR33 -> 7997.804 | CS20: =CS18*CS33 -> 9068.921 | CT20: =CT18*CT33 -> 10276.98 | CU20: =CU18*CU33 -> 11623.17 | CV20: =CV18*CV33 -> 13054.382 | CW20: =CW18*CW33 -> 14582.03 | CX20: =CX18*CX33 -> 16041.161 | CY20: =CY18*CY33 -> 17366.471 | ... DA20: =DA18*DA33 -> 19749.919
B21: SG&A | C21: 62.4 | D21: 67.3 | E21: 69.9 | F21: 79 | G21: 82.8 | H21: 88.6 | I21: 91.6 | J21: 95.8 | K21: 99.1 | L21: 106.5 | M21: 111.2 | N21: 122 | O21: 124.2 | P21: 120.9 | Q21: 129 | R21: 148.1 | S21: 141.5 | T21: 145.5 | U21: 139.3 | V21: 147.7 | W21: 215.8 | X21: 161.2 | Y21: 154 | Z21: 160 | AA21: 162 | AB21: 163.3 | AC21: 154.9 | AD21: 160.3 | AE21: 172.8 | AF21: 170.8 | AG21: 168 | AH21: 192 | AI21: 202.9 | AJ21: 185.6 | AK21: 204.1 | AL21: 217.9 | AM21: 221.6 | AN21: 259.8 | AO21: 221.4 | AP21: 283.8 | AQ21: 273.4 | AR21: 279.2 | AS21: 284 | AT21: 341.8 | AU21: 308.1 | AV21: 279.1 | AW21: 298.9 | AX21: =1216.3-SUM(AU21:AW21) -> 330.2 | AY21: 326 | AZ21: 350.2 | BA21: 363.3 | BB21: =1466.5-SUM(AY21:BA21) -> 427 | BC21: 391.1 | BD21: 418.4 | BE21: 436.1 | BF21: =1739.9-SUM(BC21:BE21) -> 494.3 | BG21: 480.5 | BH21: 464.3 | BI21: 452 | BJ21: =1963.9-SUM(BG21:BI21) -> 567.1 | BK21: 491.5 | BL21: 525.3 | BM21: 510.6 | BN21: =2140-SUM(BK21:BM21) -> 612.6 | BO21: 563.4 | BP21: 561.2 | BQ21: 573.3 | BR21: 687.1 | BS21: 613.3 | BT21: 617.9 | BU21: 1083.4 | CA21: =SUM(C21:F21) -> 278.6 | CB21: =SUM(G21:J21) -> 358.8 | CC21: =SUM(K21:N21) -> 438.8 | CD21: =SUM(O21:R21) -> 522.2 | CE21: =SUM(S21:V21) -> 574 | CF21: =SUM(W21:Z21) -> 691 | CG21: =SUM(AA21:AD21) -> 640.5 | CH21: =SUM(AE21:AH21) -> 703.6 | CI21: =SUM(AI21:AL21) -> 810.5 | CJ21: =SUM(AM21:AP21) -> 986.6 | CK21: =SUM(AQ21:AT21) -> 1178.4 | CL21: =SUM(AU21:AX21) -> 1216.3 | CM21: =SUM(AY21:BB21) -> 1466.5 | CN21: =SUM(BC21:BF21) -> 1739.9 | CO21: =SUM(BG21:BJ21) -> 1963.9 | CP21: =SUM(BK21:BN21) -> 2140 | CQ21: =SUM(BO21:BR21) -> 2385 | CR21: =CR18*CR34 -> 2598.3924 | CS21: =CS18*CS34 -> 2932.4655 | CT21: =CT18*CT34 -> 3297.8368 | CU21: =CU18*CU34 -> 3706.9425 | CV21: =CV18*CV34 -> 4137.7728 | CW21: =CW18*CW34 -> 4586.6327 | CX21: =CX18*CX34 -> 5014.348 | CY21: =CY18*CY34 -> 5402.9022 | ... DA21: =DA18*DA34 -> 6144.4191
B22: R&D | C22: 21.3 | D22: 23.4 | E22: 24.6 | F22: 25.8 | G22: 28 | H22: 28.5 | I22: 26.9 | J22: 32.6 | K22: 31.4 | L22: 32 | M22: 35.4 | N22: 41.4 | O22: 38.4 | P22: 40.2 | Q22: 49.7 | R22: 41.7 | S22: 41.6 | T22: 41.2 | U22: 43.2 | V22: 41.7 | W22: 43 | X22: 40.2 | Y22: 47.5 | Z22: 47.3 | AA22: 44.4 | AB22: 49.4 | AC22: 51 | AD22: 52.6 | AE22: 53.2 | AF22: 54.7 | AG22: 62.6 | AH22: 69.1 | AI22: 73.5 | AJ22: 84.6 | AK22: 83.4 | AL22: 87.1 | AM22: 95.5 | AN22: 95.1 | AO22: 107.6 | AP22: 119.9 | AQ22: 144 | AR22: 120.8 | AS22: 135.9 | AT22: 156.6 | AU22: 147.1 | AV22: 143.2 | AW22: 155 | AX22: =595.1-SUM(AU22:AW22) -> 149.8 | AY22: 159.8 | AZ22: 162.3 | BA22: 165.5 | BB22: =671-SUM(AY22:BA22) -> 183.4 | BC22: 210.5 | BD22: 207.3 | BE22: 217.1 | BF22: =879-SUM(BC22:BE22) -> 244.1 | BG22: 244.9 | BH22: 244.4 | BI22: 249.4 | BJ22: =998.8-SUM(BG22:BI22) -> 260.1 | BK22: 284.5 | BL22: 280.1 | BM22: 286 | BN22: =1145.3-SUM(BK22:BM22) -> 294.7 | BO22: 316.2 | BP22: 313.3 | BQ22: 329.1 | BR22: 352 | BS22: 361.9 | BT22: 370.6 | BU22: 408.3 | CA22: =SUM(C22:F22) -> 95.1 | CB22: =SUM(G22:J22) -> 116 | CC22: =SUM(K22:N22) -> 140.2 | CD22: =SUM(O22:R22) -> 170 | CE22: =SUM(S22:V22) -> 167.7 | CF22: =SUM(W22:Z22) -> 178 | CG22: =SUM(AA22:AD22) -> 197.4 | CH22: =SUM(AE22:AH22) -> 239.6 | CI22: =SUM(AI22:AL22) -> 328.6 | CJ22: =SUM(AM22:AP22) -> 418.1 | CK22: =SUM(AQ22:AT22) -> 557.3 | CL22: =SUM(AU22:AX22) -> 595.1 | CM22: =SUM(AY22:BB22) -> 671 | CN22: =SUM(BC22:BF22) -> 879 | CO22: =SUM(BG22:BJ22) -> 998.8 | CP22: =SUM(BK22:BN22) -> 1145.3 | CQ22: =SUM(BO22:BR22) -> 1310.6 | CR22: =CR18*CR35 -> 1549.5 | CS22: =CS18*CS35 -> 1792.0622 | CT22: =CT18*CT35 -> 1994.0408 | CU22: =CU18*CU35 -> 2234.5588 | CV22: =CV18*CV35 -> 2486.5489 | CW22: =CW18*CW35 -> 2747.6526 | CX22: =CX18*CX35 -> 2994.35 | CY22: =CY18*CY35 -> 3216.0132 | ... DA22: =DA18*DA35 -> 3657.3923
B23: Operating Income | C23: =C20-SUM(C21:C22) -> 45 | D23: =D20-SUM(D21:D22) -> 99.5 | E23: =E20-SUM(E21:E22) -> 104.5 | F23: =F20-SUM(F21:F22) -> 128.4 | G23: =G20-SUM(G21:G22) -> 129.7 | H23: =H20-SUM(H21:H22) -> 139.7 | I23: =I20-SUM(I21:I22) -> 132.1 | J23: =J20-SUM(J21:J22) -> 153.7 | ... BU23: =BU20-SUM(BU21:BU22) -> 592.6 | CA23: =SUM(C23:F23) -> 377.4 | CB23: =SUM(G23:J23) -> 555.2 | CC23: =SUM(K23:N23) -> 694.8 | CD23: =SUM(O23:R23) -> 878.1 | CE23: =SUM(S23:V23) -> 852.5 | CF23: =SUM(W23:Z23) -> 544.8 | CG23: =SUM(AA23:AD23) -> 740 | CH23: =SUM(AE23:AH23) -> 949.7 | CI23: =SUM(AI23:AL23) -> 1062.9 | CJ23: =SUM(AM23:AP23) -> 1199.4 | CK23: =SUM(AQ23:AT23) -> 1374.5 | CL23: =SUM(AU23:AX23) -> 1049.8 | CM23: =SUM(AY23:BB23) -> 1821 | CN23: =SUM(BC23:BF23) -> 1577.1 | CO23: =SUM(BG23:BJ23) -> 1766.8 | CP23: =SUM(BK23:BN23) -> 2348.9 | CQ23: =SUM(BO23:BR23) -> 2946.8 | CR23: =CR20-SUM(CR21:CR22) -> 3849.9116 | CS23: =CS20-SUM(CS21:CS22) -> 4344.3933 | CT23: =CT20-SUM(CT21:CT22) -> 4985.1021 | CU23: =CU20-SUM(CU21:CU22) -> 5681.6689 | CV23: =CV20-SUM(CV21:CV22) -> 6430.06 | CW23: =CW20-SUM(CW21:CW22) -> 7247.7451 | CX23: =CX20-SUM(CX21:CX22) -> 8032.4627 | CY23: =CY20-SUM(CY21:CY22) -> 8747.5559 | ... DA23: =DA20-SUM(DA21:DA22) -> 9948.1072
B24: Interest Income | C24: 5 | D24: 5.2 | E24: 4.3 | F24: 4.2 | G24: 4.1 | H24: 4.5 | I24: 5 | J24: 3.5 | K24: 5.3 | L24: 4.1 | M24: 1.9 | N24: 3.6 | O24: 3.8 | P24: 4 | Q24: 4.3 | R24: 3.7 | S24: 4.3 | T24: 4.3 | U24: 3.9 | V24: 5.9 | W24: 3.9 | X24: -0.4 | Y24: 2 | Z24: -1.3 | AA24: 4.3 | AB24: 4.6 | AC24: 3.7 | AD24: 5.9 | AE24: 5.5 | AF24: 8 | AG24: 10.4 | AH24: 11.7 | AI24: 8.7 | AJ24: 10.1 | AK24: 10.8 | AL24: 12.3 | AM24: 13.2 | AN24: 18.2 | AO24: 21.9 | AP24: 26.8 | AQ24: 27.5 | AR24: 32.8 | AS24: 33.3 | AT24: 34.1 | AU24: 25 | AV24: 26.6 | AW24: 84.8 | AX24: =157.2-SUM(AU24:AW24) -> 20.8 | AY24: 32 | AZ24: 15 | BA24: 18.5 | BB24: =69.3-SUM(AY24:BA24) -> 3.8 | BC24: -5.7 | BD24: 9.3 | BE24: 3.9 | BF24: =29.7-SUM(BC24:BE24) -> 22.2 | BG24: 34.2 | BH24: 36 | BI24: 56.2 | BJ24: =192.1-SUM(BG24:BI24) -> 65.7 | BK24: 69.1 | BL24: 87.2 | BM24: 93.7 | BN24: =324.9-SUM(BK24:BM24) -> 74.9 | BO24: 90.4 | BP24: 88.7 | BQ24: 95.5 | BR24: 91 | BS24: 85.1 | BT24: 82.7 | BU24: 75.8 | CA24: =SUM(C24:F24) -> 18.7 | CB24: =SUM(G24:J24) -> 17.1 | CC24: =SUM(K24:N24) -> 14.9 | CD24: =SUM(O24:R24) -> 15.8 | CE24: =SUM(S24:V24) -> 18.4 | CF24: =SUM(W24:Z24) -> 4.2 | CG24: =SUM(AA24:AD24) -> 18.5 | CH24: =SUM(AE24:AH24) -> 35.6 | CI24: =SUM(AI24:AL24) -> 41.9 | CJ24: =SUM(AM24:AP24) -> 80.1 | CK24: =SUM(AQ24:AT24) -> 127.7 | CL24: =SUM(AU24:AX24) -> 157.2 | CM24: =SUM(AY24:BB24) -> 69.3 | CN24: =SUM(BC24:BF24) -> 29.7 | CO24: =SUM(BG24:BJ24) -> 192.1 | CP24: =SUM(BK24:BN24) -> 324.9 | CQ24: =SUM(BO24:BR24) -> 365.6 | CR24: =CQ40*$DA$43 -> 907.676 | CS24: =CR40*$DA$43 -> 1991.1095 | CT24: =CS40*$DA$43 -> 3425.3407 | CU24: =CT40*$DA$43 -> 5306.6306 | CV24: =CU40*$DA$43 -> 7749.7416 | CW24: =CV40*$DA$43 -> 10883.336 | CX24: =CW40*$DA$43 -> 14890.124 | CY24: =CX40*$DA$43 -> 19955.786 | ... DA24: =CZ40*$DA$43 -> 34179.172
B25: Pretax Income | C25: =C23+C24 -> 50 | D25: =D23+D24 -> 104.7 | E25: =E23+E24 -> 108.8 | F25: =F23+F24 -> 132.6 | G25: =G23+G24 -> 133.8 | H25: =H23+H24 -> 144.2 | I25: =I23+I24 -> 137.1 | J25: =J23+J24 -> 157.2 | ... BU25: =BU23+BU24 -> 668.4 | CA25: =SUM(C25:F25) -> 396.1 | CB25: =SUM(G25:J25) -> 572.3 | CC25: =SUM(K25:N25) -> 709.7 | CD25: =SUM(O25:R25) -> 893.9 | CE25: =SUM(S25:V25) -> 870.9 | CF25: =SUM(W25:Z25) -> 549 | CG25: =SUM(AA25:AD25) -> 758.5 | CH25: =SUM(AE25:AH25) -> 985.3 | CI25: =SUM(AI25:AL25) -> 1104.8 | CJ25: =SUM(AM25:AP25) -> 1279.5 | CK25: =SUM(AQ25:AT25) -> 1502.2 | CL25: =SUM(AU25:AX25) -> 1207 | CM25: =SUM(AY25:BB25) -> 1890.3 | CN25: =SUM(BC25:BF25) -> 1606.8 | CO25: =SUM(BG25:BJ25) -> 1958.9 | CP25: =SUM(BK25:BN25) -> 2673.8 | CQ25: =SUM(BO25:BR25) -> 3312.4 | CR25: =CR23+CR24 -> 4757.5876 | CS25: =CS23+CS24 -> 6335.5028 | CT25: =CT23+CT24 -> 8410.4428 | CU25: =CU23+CU24 -> 10988.299 | CV25: =CV23+CV24 -> 14179.802 | CW25: =CW23+CW24 -> 18131.081 | CX25: =CX23+CX24 -> 22922.586 | CY25: =CY23+CY24 -> 28703.342 | ... DA25: =DA23+DA24 -> 44127.279
B26: Taxes | C26: 21.9 | D26: 42.3 | E26: 44.3 | F26: 55 | G26: 48.5 | H26: 55.5 | I26: 50.5 | J26: 36 | K26: 49.5 | L26: 54.8 | M26: 58.4 | N26: 51.9 | O26: 53.6 | P26: 74.4 | Q26: 32.4 | R26: 76.9 | S26: 66.6 | T26: 63.7 | U26: 21.3 | V26: 48.3 | W26: 16.2 | X26: 38.6 | Y26: 37.4 | Z26: 38 | AA26: 37.7 | AB26: 43.9 | AC26: 26.3 | AD26: 61.8 | AE26: 48.1 | AF26: 68.9 | AG26: 55.8 | AH26: 74.2 | AI26: 21.3 | AJ26: 47 | AK26: -7.2 | AL26: 372.8 | AM26: 2.6 | AN26: 41 | AO26: 43.4 | AP26: 67.5 | AQ26: -24.3 | AR26: 75.4 | AS26: 0.3 | AT26: 69 | AU26: -8 | AV26: 37 | AW26: 38.4 | AX26: =140.2-SUM(AU26:AW26) -> 72.8 | AY26: 13.6 | AZ26: 3.2 | BA26: 73.9 | BB26: =162.2-SUM(AY26:BA26) -> 71.5 | BC26: 33 | BD26: 93.3 | BE26: 78.1 | BF26: =262.4-SUM(BC26:BE26) -> 58 | BG26: 61 | BH26: 73.2 | BI26: 102.2 | BJ26: =141.6-SUM(BG26:BI26) -> -94.8 | BK26: -8.9 | BL26: 123 | BM26: 100.4 | BN26: =336.3-SUM(BK26:BM26) -> 121.8 | BO26: -35.2 | BP26: 167.9 | BQ26: 146 | BR26: 156 | BS26: 114.4 | BT26: 231.4 | BU26: 144 | CA26: =SUM(C26:F26) -> 163.5 | CB26: =SUM(G26:J26) -> 190.5 | CC26: =SUM(K26:N26) -> 214.6 | CD26: =SUM(O26:R26) -> 237.3 | CE26: =SUM(S26:V26) -> 199.9 | CF26: =SUM(W26:Z26) -> 130.2 | CG26: =SUM(AA26:AD26) -> 169.7 | CH26: =SUM(AE26:AH26) -> 247 | CI26: =SUM(AI26:AL26) -> 433.9 | CJ26: =SUM(AM26:AP26) -> 154.5 | CK26: =SUM(AQ26:AT26) -> 120.4 | CL26: =SUM(AU26:AX26) -> 140.2 | CM26: =SUM(AY26:BB26) -> 162.2 | CN26: =SUM(BC26:BF26) -> 262.4 | CO26: =SUM(BG26:BJ26) -> 141.6 | CP26: =SUM(BK26:BN26) -> 336.3 | CQ26: =SUM(BO26:BR26) -> 434.7 | CR26: =CR25*CR37 -> 737.42608 | CS26: =CS25*CS37 -> 1013.6805 | CT26: =CT25*CT37 -> 1429.7753 | CU26: =CU25*CU37 -> 1922.9524 | CV26: =CV25*CV37 -> 2552.3643 | CW26: =CW25*CW37 -> 3263.5946 | CX26: =CX25*CX37 -> 4126.0655 | CY26: =CY25*CY37 -> 5166.6015 | ... DA26: =DA25*DA37 -> 7942.9103
B27: Net Income | C27: =C25-C26 -> 28.1 | D27: =D25-D26 -> 62.4 | E27: =E25-E26 -> 64.5 | F27: =F25-F26 -> 77.6 | G27: =G25-G26 -> 85.3 | H27: =H25-H26 -> 88.7 | I27: =I25-I26 -> 86.6 | J27: =J25-J26 -> 121.2 | ... BU27: =BU25-BU26 -> 524.4 | CA27: =SUM(C27:F27) -> 232.6 | CB27: =SUM(G27:J27) -> 381.8 | CC27: =SUM(K27:N27) -> 495.1 | CD27: =SUM(O27:R27) -> 656.6 | CE27: =SUM(S27:V27) -> 671 | CF27: =SUM(W27:Z27) -> 418.8 | CG27: =SUM(AA27:AD27) -> 588.8 | CH27: =SUM(AE27:AH27) -> 738.3 | CI27: =SUM(AI27:AL27) -> 670.9 | CJ27: =SUM(AM27:AP27) -> 1125 | CK27: =SUM(AQ27:AT27) -> 1381.8 | CL27: =SUM(AU27:AX27) -> 1066.8 | CM27: =SUM(AY27:BB27) -> 1728.1 | CN27: =SUM(BC27:BF27) -> 1344.4 | CO27: =SUM(BG27:BJ27) -> 1817.3 | CP27: =SUM(BK27:BN27) -> 2337.5 | CQ27: =SUM(BO27:BR27) -> 2877.7 | CR27: =CR25-CR26 -> 4020.1615 | CS27: =CS25-CS26 -> 5321.8224 | CT27: =CT25-CT26 -> 6980.6675 | CU27: =CU25-CU26 -> 9065.3471 | CV27: =CV25-CV26 -> 11627.437 | CW27: =CW25-CW26 -> 14867.486 | CX27: =CX25-CX26 -> 18796.521 | CY27: =CY25-CY26 -> 23536.74 | ... DA27: =DA25-DA26 -> 36184.369 | DB27: =DA27*(1+$DA$44) -> 36817.595 | DC27: =DB27*(1+$DA$44) -> 37461.903 | DD27: =DC27*(1+$DA$44) -> 38117.487 | DE27: =DD27*(1+$DA$44) -> 38784.543 | DF27: =DE27*(1+$DA$44) -> 39463.272 | DG27: =DF27*(1+$DA$44) -> 40153.879 | DH27: =DG27*(1+$DA$44) -> 40856.572 | DI27: =DH27*(1+$DA$44) -> 41571.562 | ... EY27: =EX27*(1+$DA$44) -> 86147.345
B28: Less: Joint Venture | AU28: 2.7 | AV28: 2 | AW28: 2.9 | AX28: =6.2-SUM(AU28:AW28) -> -1.4 | AY28: 8.9 | AZ28: 5.8 | BA28: 6.7 | BB28: =23.5-SUM(AY28:BA28) -> 2.1 | BC28: 3.8 | BD28: 5.8 | BE28: 0.7 | BF28: =22.1-SUM(BC28:BE28) -> 11.8 | BG28: 5.5 | BH28: 5.2 | BI28: 4.1 | BJ28: =19.3-SUM(BG28:BI28) -> 4.5 | BK28: 2.5 | BL28: 4.6 | BM28: 5.5 | BN28: =14.9-SUM(BK28:BM28) -> 2.3 | BO28: 5.3 | BP28: 5.8 | BQ28: 4.8 | BR28: 4.7 | BS28: 4.5 | BT28: 5.1 | BU28: 1.6 | CA28: =SUM(C28:F28) -> 0 | CB28: =SUM(G28:J28) -> 0 | CC28: =SUM(K28:N28) -> 0 | CD28: =SUM(O28:R28) -> 0 | CE28: =SUM(S28:V28) -> 0 | CF28: =SUM(W28:Z28) -> 0 | CG28: =SUM(AA28:AD28) -> 0 | CH28: =SUM(AE28:AH28) -> 0 | CI28: =SUM(AI28:AL28) -> 0 | CJ28: =SUM(AM28:AP28) -> 0 | CK28: =SUM(AQ28:AT28) -> 0 | CL28: =SUM(AU28:AX28) -> 6.2 | CM28: =SUM(AY28:BB28) -> 23.5 | CN28: =SUM(BC28:BF28) -> 22.1 | CO28: =SUM(BG28:BJ28) -> 19.3 | CP28: =SUM(BK28:BN28) -> 14.9 | CQ28: =SUM(BO28:BR28) -> 20.6
B29: Attributable Income | C29: =C27-C28 -> 28.1 | D29: =D27-D28 -> 62.4 | E29: =E27-E28 -> 64.5 | F29: =F27-F28 -> 77.6 | G29: =G27-G28 -> 85.3 | H29: =H27-H28 -> 88.7 | I29: =I27-I28 -> 86.6 | J29: =J27-J28 -> 121.2 | ... BU29: =BU27-BU28 -> 522.8 | CA29: =SUM(C29:F29) -> 232.6 | CB29: =SUM(G29:J29) -> 381.8 | CC29: =SUM(K29:N29) -> 495.1 | CD29: =SUM(O29:R29) -> 656.6 | CE29: =SUM(S29:V29) -> 671 | CF29: =SUM(W29:Z29) -> 418.8 | CG29: =SUM(AA29:AD29) -> 588.8 | CH29: =SUM(AE29:AH29) -> 738.3 | CI29: =SUM(AI29:AL29) -> 670.9 | CJ29: =SUM(AM29:AP29) -> 1125 | CK29: =SUM(AQ29:AT29) -> 1381.8 | CL29: =SUM(AU29:AX29) -> 1060.6 | CM29: =SUM(AY29:BB29) -> 1704.6 | CN29: =SUM(BC29:BF29) -> 1322.3 | CO29: =SUM(BG29:BJ29) -> 1798 | CP29: =SUM(BK29:BN29) -> 2322.6 | CQ29: =SUM(BO29:BR29) -> 2857.1
B30: SC | C30: 355 | D30: 355 | E30: 355 | F30: 354 | G30: 354 | H30: 353 | I30: 352 | J30: 352 | K30: 352 | L30: 353 | M30: 352 | N30: 353 | O30: 356 | P30: 359 | Q30: 359 | R30: 358 | S30: 363 | T30: 359 | U30: 347 | V30: 353 | W30: 345 | X30: 332 | Y30: 325 | Z30: 332 | AA30: 330 | AB30: 332 | AC30: 336 | AD30: 334 | AE30: 339 | AF30: 345 | AG30: 348 | AH30: 345 | AI30: 336 | AJ30: 333 | AK30: 335 | AL30: 335 | AM30: 338 | AN30: 341 | AO30: 342 | AP30: 341 | AQ30: 345 | AR30: 346 | AS30: 346 | AT30: 346 | AU30: 349.2 | AV30: 350.4 | AW30: 352 | AX30: 351.1 | AY30: 354.2 | AZ30: 355.7 | BA30: 356.8 | BB30: 356.1 | BC30: 358.4 | BD30: 358.1 | BE30: 355.3 | BF30: 355.7 | BG30: 350.2 | BH30: 350.9 | BI30: 351.7 | BJ30: 351.2 | BK30: 353.5 | BL30: 355 | BM30: 355.8 | BN30: 355.2 | BO30: 357.5 | BP30: 358.5 | BQ30: 356.6 | BR30: 355.13 | BS30: 354.9 | BT30: 354.1 | BU30: 349 | CA30: =AVERAGE(C30:F30) -> 354.75 | CB30: =AVERAGE(G30:J30) -> 352.75 | CC30: =AVERAGE(K30:N30) -> 352.5 | CD30: =AVERAGE(O30:R30) -> 358 | CE30: =AVERAGE(S30:V30) -> 355.5 | CF30: =AVERAGE(W30:Z30) -> 333.5 | CG30: =AVERAGE(AA30:AD30) -> 333 | CH30: =AVERAGE(AE30:AH30) -> 344.25 | CI30: =AVERAGE(AI30:AL30) -> 334.75 | CJ30: =AVERAGE(AM30:AP30) -> 340.5 | CK30: =AVERAGE(AQ30:AT30) -> 345.75 | CL30: =AVERAGE(AU30:AX30) -> 350.675 | CM30: =AVERAGE(AY30:BB30) -> 355.7 | CN30: =AVERAGE(BC30:BF30) -> 356.875 | CO30: =AVERAGE(BG30:BJ30) -> 351 | CP30: =AVERAGE(BK30:BN30) -> 354.875 | CQ30: =AVERAGE(BO30:BR30) -> 356.9325
B31: EPS | C31: =C27/C30 -> 0.07915493 | D31: =D27/D30 -> 0.17577465 | E31: =E27/E30 -> 0.18169014 | F31: =F27/F30 -> 0.21920904 | G31: =G27/G30 -> 0.24096045 | H31: =H27/H30 -> 0.25127479 | I31: =I27/I30 -> 0.24602273 | J31: =J27/J30 -> 0.34431818 | ... BU31: =BU27/BU30 -> 1.5025788 | CA31: =SUM(C31:F31) -> 0.65582876 | CB31: =SUM(G31:J31) -> 1.0825761 | CC31: =SUM(K31:N31) -> 1.4043724 | CD31: =SUM(O31:R31) -> 1.8336987 | CE31: =SUM(S31:V31) -> 1.8862559 | CF31: =SUM(W31:Z31) -> 1.2644429 | CG31: =SUM(AA31:AD31) -> 1.7658388 | CH31: =SUM(AE31:AH31) -> 2.1417252 | CI31: =SUM(AI31:AL31) -> 2.0050783 | CJ31: =SUM(AM31:AP31) -> 3.3040961 | CK31: =SUM(AQ31:AT31) -> 3.9961883 | CL31: =SUM(AU31:AX31) -> 3.04144 | CM31: =SUM(AY31:BB31) -> 4.8589244 | CN31: =SUM(BC31:BF31) -> 3.7668848 | CO31: =SUM(BG31:BJ31) -> 5.1768157 | CP31: =SUM(BK31:BN31) -> 6.5863448 | CQ31: =SUM(BO31:BR31) -> 8.0642869
B33: Gross Profit Margin | C33: =C20/C18 -> 0.68312102 | D33: =D20/D18 -> 0.72985418 | E33: =E20/E18 -> 0.71046055 | F33: =F20/F18 -> 0.72175797 | G33: =G20/G18 -> 0.73189288 | H33: =H20/H18 -> 0.73224979 | I33: =I20/I18 -> 0.72764228 | J33: =J20/J18 -> 0.72463396 | ... BU33: =BU20/BU18 -> 0.68366845 | CL33: =CL20/CL18 -> 0.65647944 | CM33: =CM20/CM18 -> 0.6932453 | CN33: =CN20/CN18 -> 0.67435955 | CO33: =CO20/CO18 -> 0.66387333 | CP33: =CP20/CP18 -> 0.67458483 | CQ33: =CQ20/CQ18 -> 0.65996344 | CR33: 0.671 | CS33: 0.668 | CT33: 0.67 | CU33: 0.671 | CV33: 0.672 | CW33: 0.674 | CX33: 0.675 | CY33: 0.675 | CZ33: 0.675 | DA33: 0.675
B34: SG&A as % of Revenue | C34: =C21/C18 -> 0.33121019 | D34: =D21/D18 -> 0.25825019 | E34: =E21/E18 -> 0.24955373 | F34: =F21/F18 -> 0.24450634 | G34: =G21/G18 -> 0.25197809 | H34: =H21/H18 -> 0.25263758 | I34: =I21/I18 -> 0.2659698 | J34: =J21/J18 -> 0.24608271 | ... BU34: =BU21/BU18 -> 0.35536458 | CL34: =CL21/CL18 -> 0.2790703 | CM34: =CM21/CM18 -> 0.25682562 | CN34: =CN21/CN18 -> 0.27962778 | CO34: =CO21/CO18 -> 0.27566991 | CP34: =CP21/CP18 -> 0.25622299 | CQ34: =CQ21/CQ18 -> 0.23696447 | CR34: 0.218 | CS34: 0.216 | CT34: 0.215 | CU34: 0.214 | CV34: 0.213 | CW34: 0.212 | CX34: 0.211 | CY34: 0.21 | CZ34: 0.21 | DA34: 0.21
B35: R&D as % of Revenue | C35: =C22/C18 -> 0.11305732 | D35: =D22/D18 -> 0.089792786 | E35: =E22/E18 -> 0.087825777 | F35: =F22/F18 -> 0.079851439 | G35: =G22/G18 -> 0.085209982 | H35: =H22/H18 -> 0.081266039 | I35: =I22/I18 -> 0.078106852 | J35: =J22/J18 -> 0.083740046 | ... BU35: =BU22/BU18 -> 0.13392594 | CL35: =CL22/CL18 -> 0.13654093 | CM35: =CM22/CM18 -> 0.11751108 | CN35: =CN22/CN18 -> 0.14126836 | CO35: =CO22/CO18 -> 0.14020017 | CP35: =CP22/CP18 -> 0.13712719 | CQ35: =CQ22/CQ18 -> 0.1302162 | CR35: 0.13 | CS35: 0.132 | CT35: 0.13 | CU35: 0.129 | CV35: 0.128 | CW35: 0.127 | CX35: 0.126 | CY35: 0.125 | CZ35: 0.125 | DA35: 0.125
B36: Operating Profit Margin | C36: =C23/C18 -> 0.2388535 | D36: =D23/D18 -> 0.3818112 | E36: =E23/E18 -> 0.37308104 | F36: =F23/F18 -> 0.39740019 | G36: =G23/G18 -> 0.39470481 | H36: =H23/H18 -> 0.39834616 | I36: =I23/I18 -> 0.38356562 | J36: =J23/J18 -> 0.3948112 | ... BU36: =BU23/BU18 -> 0.19437793 | CL36: =CL23/CL18 -> 0.24086821 | CM36: =CM23/CM18 -> 0.3189086 | CN36: =CN23/CN18 -> 0.25346341 | CO36: =CO23/CO18 -> 0.24800326 | CP36: =CP23/CP18 -> 0.28123466 | CQ36: =CQ23/CQ18 -> 0.29278277 | CR36: =CR23/CR18 -> 0.323 | CS36: =CS23/CS18 -> 0.32 | ... DA36: =DA23/DA18 -> 0.34
B37: Effective Tax Rate | C37: =C26/C25 -> 0.438 | D37: =D26/D25 -> 0.40401146 | E37: =E26/E25 -> 0.40716912 | F37: =F26/F25 -> 0.4147813 | G37: =G26/G25 -> 0.36248132 | H37: =H26/H25 -> 0.38488211 | I37: =I26/I25 -> 0.36834427 | J37: =J26/J25 -> 0.22900763 | ... BU37: =BU26/BU25 -> 0.21543986 | CL37: =CL26/CL25 -> 0.11615576 | CM37: =CM26/CM25 -> 0.085806486 | CN37: =CN26/CN25 -> 0.16330595 | CO37: =CO26/CO25 -> 0.072285466 | CP37: =CP26/CP25 -> 0.12577605 | CQ37: =CQ26/CQ25 -> 0.13123415 | CR37: 0.155 | CS37: 0.16 | CT37: 0.17 | CU37: 0.175 | CV37: 0.18 | CW37: 0.18 | CX37: 0.18 | CY37: 0.18 | CZ37: 0.18 | DA37: 0.18
B38: Net Profit Margin | C38: =C27/C18 -> 0.14915074 | D38: =D27/D18 -> 0.23944743 | E38: =E27/E18 -> 0.2302749 | F38: =F27/F18 -> 0.24017332 | G38: =G27/G18 -> 0.25958612 | H38: =H27/H18 -> 0.25292273 | I38: =I27/I18 -> 0.2514518 | J38: =J27/J18 -> 0.31132802 | ... BU38: =BU27/BU18 -> 0.17200774 | CL38: =CL27/CL18 -> 0.24476872 | CM38: =CM27/CM18 -> 0.30263918 | CN38: =CN27/CN18 -> 0.21606506 | CO38: =CO27/CO18 -> 0.25509187 | CP38: =CP27/CP18 -> 0.27986973 | CQ38: =CQ27/CQ18 -> 0.28591726 | CR38: =CR27/CR18 -> 0.33728363 | CS38: =CS27/CS18 -> 0.39199562 | ... DA38: =DA27/DA18 -> 1.2366861
B40: Cash & CEs | AY40: 1401.8 | AZ40: 1615.5 | BA40: 1346.7 | BB40: 1290.9 | BC40: 1103.1 | BD40: 1536.1 | BE40: 1538 | BF40: 1581.2 | BG40: 2143 | BH40: 3435.4 | BI40: 3602 | BJ40: 2750.1 | BK40: 2839.5 | BL40: 3036.7 | BM40: 2413.3 | BN40: 2027.4 | BO40: 2573.8 | BP40: 3403.1 | BQ40: 2806.6 | BR40: 3368 | BS40: 2006.5 | BT40: 2760.4 | BU40: 2978.1 | CM40: =BB40 -> 1290.9 | CN40: =BF40 -> 1581.2 | CO40: =BJ40 -> 2750.1 | CP40: =BN40 -> 2027.4 | CQ40: =BR40 -> 3368 | CR40: =CQ40+CR27 -> 7388.1615 | CS40: =CR40+CS27 -> 12709.984 | CT40: =CS40+CT27 -> 19690.651 | CU40: =CT40+CU27 -> 28755.999 | CV40: =CU40+CV27 -> 40383.436 | CW40: =CV40+CW27 -> 55250.922 | CX40: =CW40+CX27 -> 74047.443 | CY40: =CX40+CY27 -> 97584.183 | ... DA40: =CZ40+DA27 -> 163008.75
B41: ST Investments | AY41: 3155.7 | AZ41: 2823.7 | BA41: 2741.5 | BB41: 2913 | BC41: 2882.5 | BD41: 2901.3 | BE41: 2775.9 | BF41: 2536.7 | BG41: 2549.2 | BH41: 2363.8 | BI41: 2873.7 | BJ41: 2473.1 | BK41: 1960.6 | BL41: 1720.5 | BM41: 1818.4 | BN41: 1985.9 | BO41: 1937.5 | BP41: 1923.4 | BQ41: 2102.2 | BR41: 2566.9 | BS41: 2510.8 | BT41: 2455.8 | BU41: 1064.4 | CM41: =BB41 -> 2913 | CN41: =BF41 -> 2536.7 | CO41: =BJ41 -> 2473.1 | CP41: =BN41 -> 1985.9 | CQ41: =BR41 -> 2566.9
B42: A/R | AY42: 654.3 | AZ42: 699.9 | BA42: 695 | BB42: 782.7 | BC42: 906.1 | BD42: 838.5 | BE42: 849.6 | BF42: 942.1 | BG42: 925.3 | BH42: 904.2 | BI42: 962.7 | BJ42: 1130 | BK42: 1127.9 | BL42: 1109.1 | BM42: 1153 | BN42: 1225.4 | BO42: 1221.5 | BP42: 1269.2 | BQ42: 1259.7 | BR42: 1527.3 | BS42: 1595.6 | BT42: 1673.2 | BU42: 1721.3 | CM42: =BB42 -> 782.7 | CN42: =BF42 -> 942.1 | CO42: =BJ42 -> 1130 | CP42: =BN42 -> 1225.4 | CQ42: =BR42 -> 1527.3
B43: Inventories | AY43: 576.8 | AZ43: 569.7 | BA43: 584.9 | BB43: 587.1 | BC43: 653 | BD43: 724 | BE43: 837.1 | BF43: 893.2 | BG43: 946.6 | BH43: 1005.2 | BI43: 1147.5 | BJ43: 1220.6 | BK43: 1299.3 | BL43: 1383.9 | BM43: 1481.7 | BN43: 1487.2 | BO43: 1553.6 | BP43: 1667 | BQ43: 1781.9 | BR43: 1840 | BS43: 1945.1 | BT43: 2028.7 | BU43: 2128.2 | CM43: =BB43 -> 587.1 | CN43: =BF43 -> 893.2 | CO43: =BJ43 -> 1220.6 | CP43: =BN43 -> 1487.2 | CQ43: =BR43 -> 1840 | CS43: Invested Capital | CV43: Avg. (2023-2024) | CX43: Projected ROIC: | CZ43: ROIC | DA43: 0.2695
B44: Prepaid Expenses | AY44: 277.8 | AZ44: 307.8 | BA44: 359.9 | BB44: 271 | BC44: 258.5 | BD44: 292.6 | BE44: 292.5 | BF44: 299.8 | BG44: 312.9 | BH44: 323.2 | BI44: 317 | BJ44: 314 | BK44: 405.4 | BL44: 404.1 | BM44: 349.2 | BN44: 385.1 | BO44: 371.4 | BP44: 483.2 | BQ44: 574.9 | BR44: 477.3 | BS44: 751.5 | BT44: 624.6 | BU44: 536.3 | CM44: =BB44 -> 271 | CN44: =BF44 -> 299.8 | CO44: =BJ44 -> 314 | CP44: =BN44 -> 385.1 | CQ44: =BR44 -> 477.3 | CS44: 2023 | CT44: 2024 | CV44: 2023-2024 | CX44: 2025 | CZ44: Terminal | DA44: 0.0175
B45: PP&E | AY45: 1592.9 | AZ45: 1651.2 | BA45: 1737.9 | BB45: 1876.4 | BC45: 1968 | BD45: 2109.3 | BE45: 2243.7 | BF45: 2374.2 | BG45: 2580.2 | BH45: 2830.8 | BI45: 3077 | BJ45: 3537.6 | BK45: 3799.6 | BL45: 4116.8 | BM45: 4433 | BN45: 4646.6 | BO45: 4799 | BP45: 4985.3 | BQ45: 5150.9 | BR45: 5342.4 | BS45: 5447.9 | BT45: 5551.5 | BU45: 5676.2 | CM45: =BB45 -> 1876.4 | CN45: =BF45 -> 2374.2 | CO45: =BJ45 -> 3537.6 | CP45: =BN45 -> 4646.6 | CQ45: =BR45 -> 5342.4 | CS45: =SUM(CO40:CO43)-CO51+CO45+CO48 -> 11908.1 | CT45: =SUM(CP40:CP43)-CP51+CP45+CP48 -> 12300.5 | CV45: =AVERAGE(CS45:CT45) -> 12104.3 | CX45: =AVERAGE(CR23)*(1-CR37) -> 3253.1753 | CZ45: RFR (10-year yield) | DA45: =CV54 -> 0.0517
...

Sheet Notes | Quant Analysis
Q2: Employee Scope: | AM2: Financial Stmts. Notes/Observations | CJ2: 0
R32: Notes: | S32: In Q2'25 Dr. Gary Guthart stepped down as CEO after 15 years of service… He announced he will now be serving as chairman of the board ... David Rosa is taking on the CEO role
S33: [Y]
S34: [Z]
Q36: Institutional Ownership Snapshot (4/14/2025) | AM36: Revenues:
R67: Notes: | S67: [X]
S68: [Y]
S69: [Z]
Q71: Revenue Breakdown by Segment | AM71: Earnings Scope:
R103: Notes: | S103: [X]
S104: [Y]
S105: [Z]
Q107: Total Revenues, Net Income, FCF | AM107: Balance Sheet Scope:
R136: Notes: | S136: [X]
S137: [Y]
S138: [Z]
Q140: Total Revenues, Net Income, FCF
R169: Notes: | S169: [X]
S170: [Y]
S171: [Z]
Q173: [ISRG] Historical Return Histogram (8/3/2025) | AM173: [Equity Preformance Compared to Peers]
B190: VOO Historical Returns | J190: ISRG Historical Returns
B191: 1004 Trading Days? (From: 4/30/21 - 4/29/25) | J191: 1256 Trading Days (From: 5/11/2020-5/11/2025)
B192: Close | C192: High | D192: Low | E192: Open | F192: Volume | G192: UTC Date | H192: Change | J192: Close | K192: High | L192: Low | M192: Open | N192: Volume | O192: UTC Date | P192: Change
B193: 626.89 | C193: 631.17 | D193: 623.115 | E193: 626.93 | F193: 9248752 | G193: Fri, 13 Feb 2026 00:00:00 GMT | H193: =B193/E193-1 -> -6.3802976e-05 | J193: 485.84 | K193: 495.57 | L193: 479.61 | M193: 480.5 | N193: 1981065 | O193: Fri, 13 Feb 2026 00:00:00 GMT | P193: =J193/M193-1 -> 0.011113424
B194: 626.49 | C194: 639.52 | D194: 625.76 | E194: 638.51 | F194: 8866872 | G194: Thu, 12 Feb 2026 00:00:00 GMT | H194: =B194/E194-1 -> -0.018825077 | J194: 478.6 | K194: 497.84 | L194: 475.83 | M194: 496.12 | N194: 2962887 | O194: Thu, 12 Feb 2026 00:00:00 GMT | P194: =J194/M194-1 -> -0.035314037
B195: 636.35 | C195: 641.15 | D195: 633.84 | E195: 640.49 | F195: 5317092 | G195: Wed, 11 Feb 2026 00:00:00 GMT | H195: =B195/E195-1 -> -0.0064638012 | J195: 496.12 | K195: 500.34 | L195: 490.66 | M195: 492.75 | N195: 1926402 | O195: Wed, 11 Feb 2026 00:00:00 GMT | P195: =J195/M195-1 -> 0.0068391679
B196: 636.44 | C196: 640.62 | D196: 636.08 | E196: 639.14 | F196: 13619951 | G196: Tue, 10 Feb 2026 00:00:00 GMT | H196: =B196/E196-1 -> -0.0042244266 | J196: 495.15 | K196: 500.3756 | L196: 493.5258 | M196: 494.22 | N196: 1805098 | O196: Tue, 10 Feb 2026 00:00:00 GMT | P196: =J196/M196-1 -> 0.0018817531
B197: 638.23 | C197: 639.99 | D197: 633.11 | E197: 634.07 | F197: 8885179 | G197: Mon, 09 Feb 2026 00:00:00 GMT | H197: =B197/E197-1 -> 0.0065607898 | J197: 492.84 | K197: 493.54 | L197: 483.9 | M197: 486.05 | N197: 2180867 | O197: Mon, 09 Feb 2026 00:00:00 GMT | P197: =J197/M197-1 -> 0.013969756
B198: 635.24 | C198: 636.72 | D198: 626.2 | E198: 626.72 | F198: 12959420 | G198: Fri, 06 Feb 2026 00:00:00 GMT | H198: =B198/E198-1 -> 0.013594588 | J198: 488.15 | K198: 491.65 | L198: 480.07 | M198: 482.165 | N198: 2518023 | O198: Fri, 06 Feb 2026 00:00:00 GMT | P198: =J198/M198-1 -> 0.012412763
B199: 623.1 | C199: 628.75 | D199: 621.5 | E199: 626.24 | F199: 11506981 | G199: Thu, 05 Feb 2026 00:00:00 GMT | H199: =B199/E199-1 -> -0.0050140521 | J199: 476.32 | K199: 489.51 | L199: 475.17 | M199: 482.78 | N199: 2694556 | O199: Thu, 05 Feb 2026 00:00:00 GMT | P199: =J199/M199-1 -> -0.013380836
B200: 630.91 | C200: 635.92 | D200: 627 | E200: 634.93 | F200: 11228241 | G200: Wed, 04 Feb 2026 00:00:00 GMT | H200: =B200/E200-1 -> -0.0063314066 | J200: 478.49 | K200: 481.19 | L200: 465.689 | M200: 480.105 | N200: 3402220 | O200: Wed, 04 Feb 2026 00:00:00 GMT | P200: =J200/M200-1 -> -0.0033638475
B201: 634.15 | C201: 641 | D201: 629.105 | E201: 640.33 | F201: 9644195 | G201: Tue, 03 Feb 2026 00:00:00 GMT | H201: =B201/E201-1 -> -0.0096512736 | J201: 478.88 | K201: 499 | L201: 476.79 | M201: 495.21 | N201: 3781824 | O201: Tue, 03 Feb 2026 00:00:00 GMT | P201: =J201/M201-1 -> -0.032975909
B202: 639.68 | C202: 640.96 | D202: 634.07 | E202: 634.18 | F202: 9124531 | G202: Mon, 02 Feb 2026 00:00:00 GMT | H202: =B202/E202-1 -> 0.0086726166 | J202: 496.73 | K202: 504.2 | L202: 496.15 | M202: 502 | N202: 2108426 | O202: Mon, 02 Feb 2026 00:00:00 GMT | P202: =J202/M202-1 -> -0.010498008
B203: 636.22 | C203: 638.45 | D203: 631.95 | E203: 636.25 | F203: 6519552 | G203: Fri, 30 Jan 2026 00:00:00 GMT | H203: =B203/E203-1 -> -4.7151277e-05 | J203: 504.22 | K203: 511.03 | L203: 501.385 | M203: 506.7 | N203: 1696613 | O203: Fri, 30 Jan 2026 00:00:00 GMT | P203: =J203/M203-1 -> -0.0048944148
B204: 638.27 | C204: 641.04 | D204: 629.82 | E204: 640.43 | F204: 8485857 | G204: Thu, 29 Jan 2026 00:00:00 GMT | H204: =B204/E204-1 -> -0.0033727339 | J204: 507.55 | K204: 522 | L204: 502.48 | M204: 521.17 | N204: 2127431 | O204: Thu, 29 Jan 2026 00:00:00 GMT | P204: =J204/M204-1 -> -0.026133507
B205: 639.6 | C205: 641.81 | D205: 638.22 | E205: 641.05 | F205: 5488373 | G205: Wed, 28 Jan 2026 00:00:00 GMT | H205: =B205/E205-1 -> -0.002261914 | J205: 522.04 | K205: 529.36 | L205: 520.24 | M205: 523.91 | N205: 1848874 | O205: Wed, 28 Jan 2026 00:00:00 GMT | P205: =J205/M205-1 -> -0.0035693153
B206: 639.7 | C206: 640.5959 | D206: 637.87 | E206: 638.42 | F206: 4308306 | G206: Tue, 27 Jan 2026 00:00:00 GMT | H206: =B206/E206-1 -> 0.0020049497 | J206: 525.04 | K206: 535 | L206: 523.54 | M206: 532.61 | N206: 1477091 | O206: Tue, 27 Jan 2026 00:00:00 GMT | P206: =J206/M206-1 -> -0.014213026 | R206: Notes: | S206: [X]
B207: 637.09 | C207: 638.39 | D207: 634.52 | E207: 635.03 | F207: 8976388 | G207: Mon, 26 Jan 2026 00:00:00 GMT | H207: =B207/E207-1 -> 0.0032439412 | J207: 528.81 | K207: 533.97 | L207: 518.65 | M207: 523.945 | N207: 2492449 | O207: Mon, 26 Jan 2026 00:00:00 GMT | P207: =J207/M207-1 -> 0.0092853257 | S207: [Y]
B208: 633.83 | C208: 635.4705 | D208: 631.97 | E208: 632.88 | F208: 5827254 | G208: Fri, 23 Jan 2026 00:00:00 GMT | H208: =B208/E208-1 -> 0.0015010745 | J208: 523.99 | K208: 540 | L208: 521.18 | M208: 530 | N208: 2763321 | O208: Fri, 23 Jan 2026 00:00:00 GMT | P208: =J208/M208-1 -> -0.011339623 | S208: [Z]
...

Sheet Product Lines
A2: https://www.intuitive.com/en-gb/-/media/ISI/Intuitive/Pdf/intuitive-company-press-facts-europe-1096203.pdf

Sheet Management

Sheet Table Formatting
B2: [Bold Title] | G2: [Bold Title]
B3: Line Titles | G3: <-- General
B4: Line Titles | G4: <-- Info
B5: Line Titles | G5: <-- General
B6: Line Titles | G6: <-- Info
B7: Line Titles | G7: <-- General
B8: Line Titles | G8: <-- Info
