Workbook

Sheet Main
B2: LHX
B3: Price | C3: 254.23 | D3: 10/22/2026
B4: SO | C4: 186.214 | D4: Q2'26
B5: MC | C5: =C3*C4 -> 47341.185
B6: Cash | C6: =1521 -> 1521 | D6: Q2'26
B7: Debt | C7: =1815+9184 -> 10999 | D7: Q2'26
B8: EV | C8: =C5-C6+C7 -> 56819.185
B10: L3Harris Technologies, Inc. (LHX)
B12: Founder(s): L3 Technologies & Harris Corporation | F12: Registered Exchange: NYSE | N12: Resources:
B13: Founded: 1895 - 2019 merger of equals | F13: Address: 1025 West NASA Boulevard, Melbourne, FL 32919 U.S. | N13: SEC filings | Q13: https://www.sec.gov/edgar/browse/?CIK=202058&owner=exclude
B14: Headquarters: Melbourne, FL | F14: Investor Relations Contact: | N14: Company Homepage | Q14: https://www.l3harris.com/
B15: Current CEO: Samir Mehta | F15: Investors Relation Department | O15: Company IR Page | R15: https://investors.l3harris.com/overview/default.aspx
B16: Employees: 45,000 | F16: Phone: | G16: (321) 727 - 9100 | I16: Email: | N16: Earnings Calls | Q16: https://seekingalpha.com/symbol/LHX/earnings/transcripts
B17: Industry: Aerospace & Defense | N17: Equity Analysis | Q17: https://stockanalysis.com/stocks/lhx/company/
B18: Sector: Industrials | N18: MacroTrends | Q18: https://www.macrotrends.net/stocks/charts/LHX/l3harris-technologies-inc/income-statement
B19: IPO: 2019 | N19: ROIC, WACC | Q19: https://www.gurufocus.com/term/wacc/LHX
B20: Fiscal Year: [February - January] | N20: Godel Terminal | Q20: https://app.godelterminal.com/
A22: Company Overview:
B23: L3Harris Technologies, Inc. provides mission-critical solutions for government and commercial customers worldwide
B24: The Company operates through three segments: Space & Mission Systems (SMS), Communications & Spectrum Dominance (CSD), and Missile Solutions (MSL)
C25: The SMS segment integrates satellite and payload capabilities, including missile warning and defense, with maritime, air special missions, and other global defense and civil government programs
C26: The CSD segment provides tactical radios, software, waveforms, satellite terminals, and end-to-end battlefield systems for the U.S. Department of Defense, international, federal, and state agency customers
C27: Its MSL segment unites propulsion, hypersonic, and other advanced missile technologies
D28: broadband communications; integrated vision solutions, such as helmet-mounted integrated night vision goggles with image intensifier tubes and weapon-mounted sights, aiming lasers, and range finders; and public safety radios and system applications and equipment
B29: The Company was formerly known as Harris Corporation and changed its name to L3Harris Technologies, Inc. in June 2019
B30: L3Harris Technologies, Inc. was founded in 1895 and is headquartered in Melbourne, Florida
A32: Business Segments and Geographical Info:
B33: L3Harris is a trusted US defense prime with end-to-end tech solutions connectiong the psace, air, land and cyber domains for national security interests … Primarily US based but support clients in over 100 countries worldwide
C34: The Company's capabilities have defense and civil government applications, as well as commercial applications
B35: The Company operates through three segments: Space & Mission Systems (SMS), Communications & Spectrum Dominance (CSD), and Missile Solutions (MSL)
C36: Communication Systems (“CS”) | G36: Enables warfighters across all domains with solutions critical to mission success even in the most contested environments
G37: Leading provider of resilient communication solutions for the U.S. Department of War (“DoW”) and international, federal, and state agency customers in the following business sectors:
G38: - | H38: Tactical Communications: Design, manufacture and sustainment of resilient and interoperable secure communication solutions that include tactical radios, software, waveforms, satellite terminals and end-to-end battlefield systems
G39: - | H39: Broadband Communications: Design, manufacture and sustainment of resilient and secure communication solutions that include intelligence, reconnaissance and surveillance (“ISR”) and tactical data links, software and integrated broadband networks
G40: - | H40: Integrated Vision Solutions: Design, manufacture and sustainment of a full suite of helmet-mounted integrated night vision goggles with leading-edge image intensifier tubes, as well as weapon-mounted sights, aiming lasers, and range finders
G41: - | H41: Public Safety and Professional Communications (“PSPC”): State-of-the-art communication equipment, systems and applications for federal agencies, state and local government first responders, utilities and transit agencies
C42: Integrated Mission Systems (“IMS”) | G42: Delivers differentiated mission capabilities and prime systems integration to support multi-mission ISR, passive sensing and targeting, electronic attack, autonomy, power and communications, networks and sensors
G43: IMS specializes in system design, development, integration, production, modernization and sustainment for national security and international customers in the following business sectors
G44: - | H44: ISR: Airborne passive sensing and targeting, mission systems development, integration and life-cycle management for strategic reconnaissance and air superiority platforms, national command and control, tactical surveillance, electronic attack, agile strike, mobility, and classified platforms
G45: - | H45: Maritime: Power, electrical, imaging, communication and sensor systems for naval platforms; integrated autonomous vessels for surface and undersea operations; fleet management; in-service support; missionization prototyping; and naval integration
...

Sheet Model
B1: [Use for Graphing] | C1: Q1 2020 | G1: Q1 2021 | K1: Q1 2022 | O1: Q1 2023 | S1: Q1 2024 | W1: Q1 2025 | AA1: Q1 2026
B2: Quarterly
B3: Revenues | C3: {="Q"&MOD(_xlfn.SEQUENCE(1,28)-1,4)+1&" "&(2020+INT((_xlfn.SEQUENCE(1,28)-1)/4))} -> Q1 2020 | D3: Q2 2020 | E3: Q3 2020 | F3: Q4 2020 | G3: Q1 2021 | H3: Q2 2021 | I3: Q3 2021 | J3: Q4 2021 | K3: Q1 2022 | L3: Q2 2022 | M3: Q3 2022 | N3: Q4 2022 | O3: Q1 2023 | P3: Q2 2023 | Q3: Q3 2023 | R3: Q4 2023 | S3: Q1 2024 | T3: Q2 2024 | U3: Q3 2024 | V3: Q4 2024 | W3: Q1 2025 | X3: Q2 2025 | Y3: Q3 2025 | Z3: Q4 2025 | AA3: Q1 2026 | AB3: Q2 2026 | AC3: Q3 2026 | AD3: Q4 2026 | AI3: 2020 | AJ3: =AI3+1 -> 2021 | AK3: =AJ3+1 -> 2022 | AL3: =AK3+1 -> 2023 | AM3: =AL3+1 -> 2024 | AN3: =AM3+1 -> 2025 | AO3: =AN3+1 -> 2026 | AP3: =AO3+1 -> 2027 | AQ3: =AP3+1 -> 2028 | ... CV3: =CU3+1 -> 2085
B4: Space & Mission Systems | W4: 2411 | X4: 2770 | Y4: =1462+1700 -> 3162 | Z4: =2995+8357-SUM(W4:Y4) -> 3009 | AA4: 2990 | AB4: 2966 | AN4: =SUM(W4:Z4) -> 11352 | AO4: =AN4*(1+AO10) -> 13054.8 | AP4: =AO4*(1+AP10) -> 14621.376 | AQ4: =AP4*(1+AQ10) -> 16229.727 | AR4: =AQ4*(1+AR10) -> 17852.7 | AS4: =AR4*(1+AS10) -> 19459.443 | AT4: =AS4*(1+AT10) -> 21016.199 | AU4: =AT4*(1+AU10) -> 22487.332 | AV4: =AU4*(1+AV10) -> 23836.572 | ... AX4: =AW4*(1+AX10) -> 26279.821
B5: Communication & Spectrum Dominance | W5: 1809 | X5: 1861 | Y5: 1809 | Z5: =7330-SUM(W5:Y5) -> 1851 | AA5: 1855 | AB5: 1943 | AN5: =SUM(W5:Z5) -> 7330 | AO5: =AN5*(1+AO11) -> 7549.9 | AP5: =AO5*(1+AP11) -> 7700.898 | AQ5: =AP5*(1+AQ11) -> 7931.9249 | AR5: =AQ5*(1+AR11) -> 8249.2019 | AS5: =AR5*(1+AS11) -> 8661.662 | AT5: =AS5*(1+AT11) -> 9008.1285 | AU5: =AT5*(1+AU11) -> 9278.3724 | AV5: =AU5*(1+AV11) -> 9510.3317 | ... AX5: =AW5*(1+AX11) -> 9846.0464
B6: Missile Solutions | W6: 840 | X6: 925 | Y6: 755 | Z6: =3392-SUM(W6:Y6) -> 872 | AA6: 990 | AB6: 1054 | AN6: =SUM(W6:Z6) -> 3392 | AO6: =AN6*(1+AO12) -> 3900.8 | AP6: =AO6*(1+AP12) -> 4388.4 | AQ6: =AP6*(1+AQ12) -> 4827.24 | AR6: =AQ6*(1+AR12) -> 5261.6916 | AS6: =AR6*(1+AS12) -> 5682.6269 | AT6: =AS6*(1+AT12) -> 6080.4108 | AU6: =AT6*(1+AU12) -> 6445.2355 | AV6: =AU6*(1+AV12) -> 6799.7234 | ... AX6: =AW6*(1+AX12) -> 7425.298
B7: Intersegment | W7: -60 | X7: -72 | Y7: -67 | Z7: =-209-SUM(W7:Y7) -> -10 | AA7: -91 | AB7: -82 | AN7: =SUM(W7:Z7) -> -209 | AO7: =AN7*(1+AO13) -> -275.88 | AP7: =AO7*(1+AP13) -> -344.85 | AQ7: =AP7*(1+AQ13) -> -420.717 | AR7: =AQ7*(1+AR13) -> -488.03172 | AS7: =AR7*(1+AS13) -> -546.59553 | AT7: =AS7*(1+AT13) -> -601.25508 | AU7: =AT7*(1+AU13) -> -661.38059 | AV7: =AU7*(1+AV13) -> -727.51865 | ... AX7: =AW7*(1+AX13) -> -880.29756
B8: Ttl Revenues | W8: =SUM(W4:W6)+W7 -> 5000 | X8: =SUM(X4:X6)+X7 -> 5484 | Y8: =SUM(Y4:Y6)+Y7 -> 5659 | Z8: =SUM(Z4:Z6)+Z7 -> 5722 | AA8: =SUM(AA4:AA6)+AA7 -> 5744 | AB8: =SUM(AB4:AB6)+AB7 -> 5881 | AN8: =SUM(W8:Z8) -> 21865 | AO8: =SUM(AO4:AO6)+AO7 -> 24229.62 | AP8: =SUM(AP4:AP6)+AP7 -> 26365.824 | AQ8: =SUM(AQ4:AQ6)+AQ7 -> 28568.175 | AR8: =SUM(AR4:AR6)+AR7 -> 30875.562 | AS8: =SUM(AS4:AS6)+AS7 -> 33257.137 | AT8: =SUM(AT4:AT6)+AT7 -> 35503.483 | AU8: =SUM(AU4:AU6)+AU7 -> 37549.56 | AV8: =SUM(AV4:AV6)+AV7 -> 39419.109 | ... AX8: =SUM(AX4:AX6)+AX7 -> 42670.868
B10: SMS Growth Y/y | AA10: =AA4/W4-1 -> 0.24014932 | AB10: =AB4/X4-1 -> 0.070758123 | AN10: =AN4/AM4-1 -> #DIV/0! | AO10: 0.15 | AP10: 0.12 | AQ10: 0.11 | AR10: 0.1 | AS10: 0.09 | AT10: 0.08 | AU10: 0.07 | AV10: 0.06 | AW10: 0.05 | AX10: 0.05
B11: CSD Growth Y/y | AA11: =AA5/W5-1 -> 0.025428413 | AB11: =AB5/X5-1 -> 0.044062332 | AN11: =AN5/AM5-1 -> #DIV/0! | AO11: 0.03 | AP11: 0.02 | AQ11: 0.03 | AR11: 0.04 | AS11: 0.05 | AT11: 0.04 | AU11: 0.03 | AV11: 0.025 | AW11: 0.02 | AX11: 0.015
B12: MSL Growth Y/y | AA12: =AA6/W6-1 -> 0.17857143 | AB12: =AB6/X6-1 -> 0.13945946 | AN12: =AN6/AM6-1 -> #DIV/0! | AO12: 0.15 | AP12: 0.125 | AQ12: 0.1 | AR12: 0.09 | AS12: 0.08 | AT12: 0.07 | AU12: 0.06 | AV12: 0.055 | AW12: 0.05 | AX12: 0.04
B13: Intersegment | AA13: =AA7/W7-1 -> 0.51666667 | AB13: =AB7/X7-1 -> 0.13888889 | AN13: =AN7/AM7-1 -> #DIV/0! | AO13: 0.32 | AP13: 0.25 | AQ13: 0.22 | AR13: 0.16 | AS13: 0.12 | AT13: 0.1 | AU13: 0.1 | AV13: 0.1 | AW13: 0.1 | AX13: 0.1
B14: Ttl Revenue Growth Y/y | AA14: =AA8/W8-1 -> 0.1488 | AB14: =AB8/X8-1 -> 0.072392414 | AN14: =AN8/AM8-1 -> #DIV/0! | AO14: =AO8/AN8-1 -> 0.10814635 | AP14: =AP8/AO8-1 -> 0.088164982 | AQ14: =AQ8/AP8-1 -> 0.083530532 | AR14: =AR8/AQ8-1 -> 0.080767728 | AS14: =AS8/AR8-1 -> 0.077134616 | AT14: =AT8/AS8-1 -> 0.067544789 | AU14: =AU8/AT8-1 -> 0.057630315 | ... AX14: =AX8/AW8-1 -> 0.039020032
B16: SMS % of Revenues | W16: =W4/W8 -> 0.4822 | X16: =X4/X8 -> 0.50510576 | Y16: =Y4/Y8 -> 0.55875596 | Z16: =Z4/Z8 -> 0.52586508 | AA16: =AA4/AA8 -> 0.52054318 | AB16: =AB4/AB8 -> 0.504336 | AN16: =AN4/AN8 -> 0.51918591
B17: CSD % of Revenues | W17: =W5/W8 -> 0.3618 | X17: =X5/X8 -> 0.33935084 | Y17: =Y5/Y8 -> 0.31966779 | Z17: =Z5/Z8 -> 0.32348829 | AA17: =AA5/AA8 -> 0.32294568 | AB17: =AB5/AB8 -> 0.33038599 | AN17: =AN5/AN8 -> 0.33523897
B18: MSL % of Revenues | W18: =W6/W8 -> 0.168 | X18: =X6/X8 -> 0.1686725 | Y18: =Y6/Y8 -> 0.1334158 | Z18: =Z6/Z8 -> 0.15239427 | AA18: =AA6/AA8 -> 0.17235376 | AB18: =AB6/AB8 -> 0.17922122 | AN18: =AN6/AN8 -> 0.15513378
B20: U.S. Revenues | X20: 2380 | Z20: =1000-SUM(W20:Y20) -> -1380 | AA20: 2540 | AB20: =2505+1076+922 -> 4503 | AM20: =SUM(S20:V20) -> 0 | AN20: =SUM(W20:Z20) -> 1000
B21: International Revenues | X21: 362 | Z21: =1000-SUM(W21:Y21) -> 638 | AA21: 427 | AB21: =439+819+120 -> 1378 | AM21: =SUM(S21:V21) -> 0 | AN21: =SUM(W21:Z21) -> 1000
B22: Intersegment Revenues | X22: 28 | Z22: =1000-SUM(W22:Y22) -> 972 | AA22: 23 | AB22: =22+48+12 -> 82 | AM22: =SUM(S22:V22) -> 0 | AN22: =SUM(W22:Z22) -> 1000
B23: Ttl Revenues | W23: =SUM(W20:W22) -> 0 | X23: =SUM(X20:X22) -> 2770 | Y23: =SUM(Y20:Y22) -> 0 | Z23: =SUM(Z20:Z22) -> 230 | AA23: =SUM(AA20:AA22) -> 2990 | AB23: =SUM(AB20:AB22) -> 5963 | AM23: =SUM(S23:V23) -> 0 | AN23: =SUM(W23:Z23) -> 3000
B25: U.S. Growth Y/y | W25: =W19/S19-1 -> #DIV/0! | X25: =X19/T19-1 -> #DIV/0! | Y25: =Y19/U19-1 -> #DIV/0! | Z25: =Z19/V19-1 -> #DIV/0! | AA25: =AA19/W19-1 -> #DIV/0! | AB25: =AB19/X19-1 -> #DIV/0! | AM25: =AM20/AL20-1 -> #DIV/0! | AN25: =AN20/AM20-1 -> #DIV/0!
B26: International Growth Y/y | W26: =W20/S20-1 -> #DIV/0! | X26: =X20/T20-1 -> #DIV/0! | Y26: =Y20/U20-1 -> #DIV/0! | Z26: =Z20/V20-1 -> #DIV/0! | AA26: =AA20/W20-1 -> #DIV/0! | AB26: =AB20/X20-1 -> 0.89201681 | AM26: =AM21/AL21-1 -> #DIV/0! | AN26: =AN21/AM21-1 -> #DIV/0!
B27: Intersegment Growth Y/y | W27: =W21/S21-1 -> #DIV/0! | X27: =X21/T21-1 -> #DIV/0! | Y27: =Y21/U21-1 -> #DIV/0! | Z27: =Z21/V21-1 -> #DIV/0! | AA27: =AA21/W21-1 -> #DIV/0! | AB27: =AB21/X21-1 -> 2.8066298 | AM27: =AM22/AL22-1 -> #DIV/0! | AN27: =AN22/AM22-1 -> #DIV/0!
B28: Ttl Revenue Growth Y/y | W28: =W23/S23-1 -> #DIV/0! | X28: =X23/T23-1 -> #DIV/0! | Y28: =Y23/U23-1 -> #DIV/0! | Z28: =Z23/V23-1 -> #DIV/0! | AA28: =AA23/W23-1 -> #DIV/0! | AB28: =AB23/X23-1 -> 1.1527076 | AM28: =AM23/AL23-1 -> #DIV/0! | AN28: =AN23/AM23-1 -> #DIV/0!
B30: U.S. % of Revenues | W30: =W19/W23 -> #DIV/0! | X30: =X19/X23 -> 0 | Y30: =Y19/Y23 -> #DIV/0! | Z30: =Z19/Z23 -> 0 | AA30: =AA19/AA23 -> 0 | AB30: =AB19/AB23 -> 0 | AM30: =AM20/AM23 -> #DIV/0! | AN30: =AN20/AN23 -> 0.33333333
B31: International % of Revenues | W31: =W20/W23 -> #DIV/0! | X31: =X20/X23 -> 0.85920578 | Y31: =Y20/Y23 -> #DIV/0! | Z31: =Z20/Z23 -> -6 | AA31: =AA20/AA23 -> 0.84949833 | AB31: =AB20/AB23 -> 0.7551568 | AM31: =AM21/AM23 -> #DIV/0! | AN31: =AN21/AN23 -> 0.33333333
B32: Intersegment % of Revenues | W32: =W21/W23 -> #DIV/0! | X32: =X21/X23 -> 0.13068592 | Y32: =Y21/Y23 -> #DIV/0! | Z32: =Z21/Z23 -> 2.773913 | AA32: =AA21/AA23 -> 0.14280936 | AB32: =AB21/AB23 -> 0.23109173 | AM32: =AM22/AM23 -> #DIV/0! | AN32: =AN22/AN23 -> 0.33333333
B34: Revenues | C34: 4626 | D34: 4445 | E34: 4463 | F34: 4660 | G34: 4567 | H34: 4668 | I34: 4229 | J34: 4350 | K34: 4103 | L34: 4135 | M34: 4246 | N34: 4578 | O34: 4471 | P34: 4693 | Q34: 4915 | R34: 5340 | S34: 5211 | T34: 5299 | U34: 5292 | V34: 5523 | W34: 5132 | X34: 5426 | Y34: 5659 | Z34: 5648 | AA34: 5744 | AB34: 5881 | AI34: =SUM(C34:F34) -> 18194 | AJ34: =SUM(G34:J34) -> 17814 | AK34: =SUM(K34:N34) -> 17062 | AL34: =SUM(O34:R34) -> 19419 | AM34: =SUM(S34:V34) -> 21325 | AN34: =SUM(W34:Z34) -> 21865 | AO34: =AO8 -> 24229.62 | AP34: =AP8 -> 26365.824 | AQ34: =AQ8 -> 28568.175 | AR34: =AR8 -> 30875.562 | AS34: =AS8 -> 33257.137 | AT34: =AT8 -> 35503.483 | AU34: =AU8 -> 37549.56 | AV34: =AV8 -> 39419.109 | ... AX34: =AX8 -> 42670.868
B35: COGS | C35: 3298 | D35: 3175 | E35: 3152 | F35: 3261 | G35: 3213 | H35: 3251 | I35: 2921 | J35: 3053 | K35: 2860 | L35: 2907 | M35: 3052 | N35: 3316 | O35: 3305 | P35: 3506 | Q35: 3608 | R35: 3887 | S35: 3863 | T35: 3939 | U35: 3873 | V35: 4126 | W35: 3782 | X35: 4091 | Y35: 4165 | Z35: 4202 | AA35: 4342 | AB35: 4379 | AI35: =SUM(C35:F35) -> 12886 | AJ35: =SUM(G35:J35) -> 12438 | AK35: =SUM(K35:N35) -> 12135 | AL35: =SUM(O35:R35) -> 14306 | AM35: =SUM(S35:V35) -> 15801 | AN35: =SUM(W35:Z35) -> 16240 | AO35: =AO34*(1-AO49) -> 17996.297 | AP35: =AP34*(1-AP49) -> 19582.94 | AQ35: =AQ34*(1-AQ49) -> 21218.713 | AR35: =AR34*(1-AR49) -> 22932.501 | AS35: =AS34*(1-AS49) -> 24701.39 | AT35: =AT34*(1-AT49) -> 26369.84 | AU35: =AU34*(1-AU49) -> 27889.543 | AV35: =AV34*(1-AV49) -> 29278.131 | ... AX35: =AX34*(1-AX49) -> 31693.341
B36: GP | C36: =C34-C35 -> 1328 | D36: =D34-D35 -> 1270 | E36: =E34-E35 -> 1311 | F36: =F34-F35 -> 1399 | G36: =G34-G35 -> 1354 | H36: =H34-H35 -> 1417 | I36: =I34-I35 -> 1308 | J36: =J34-J35 -> 1297 | ... AB36: =AB34-AB35 -> 1502 | AI36: =SUM(C36:F36) -> 5308 | AJ36: =SUM(G36:J36) -> 5376 | AK36: =SUM(K36:N36) -> 4927 | AL36: =SUM(O36:R36) -> 5113 | AM36: =SUM(S36:V36) -> 5524 | AN36: =SUM(W36:Z36) -> 5625 | AO36: =AO34*AO49 -> 6233.3232 | AP36: =AP34*AP49 -> 6782.8841 | AQ36: =AQ34*AQ49 -> 7349.462 | AR36: =AR34*AR49 -> 7943.0613 | AS36: =AS34*AS49 -> 8555.7463 | AT36: =AT34*AT49 -> 9133.6424 | AU36: =AU34*AU49 -> 9660.0171 | AV36: =AV34*AV49 -> 10140.978 | ... AX36: =AX34*AX49 -> 10977.527
B37: G&A | C37: 812 | D37: 855 | E37: 817 | F37: 831 | G37: 863 | H37: 1036 | I37: 793 | J37: 575 | K37: 745 | L37: 744 | M37: 1544 | N37: 767 | O37: 773 | P37: 787 | Q37: 828 | R37: 1299 | S37: 970 | T37: 884 | U37: 924 | V37: 790 | W37: 825 | X37: 764 | Y37: 873 | Z37: 1053 | AA37: 750 | AB37: 848 | AI37: =SUM(C37:F37) -> 3315 | AJ37: =SUM(G37:J37) -> 3267 | AK37: =SUM(K37:N37) -> 3800 | AL37: =SUM(O37:R37) -> 3687 | AM37: =SUM(S37:V37) -> 3568 | AN37: =SUM(W37:Z37) -> 3515 | AO37: =AO34*AO50 -> 3634.443 | AP37: =AP34*AP50 -> 3954.8736 | AQ37: =AQ34*AQ50 -> 4285.2263 | AR37: =AR34*AR50 -> 4631.3343 | AS37: =AS34*AS50 -> 4988.5705 | AT37: =AT34*AT50 -> 5325.5224 | AU37: =AU34*AU50 -> 5632.434 | AV37: =AV34*AV50 -> 5912.8663 | ... AX37: =AX34*AX50 -> 6400.6302
B38: OI | C38: =C36-C37 -> 516 | D38: =D36-D37 -> 415 | E38: =E36-E37 -> 494 | F38: =F36-F37 -> 568 | G38: =G36-G37 -> 491 | H38: =H36-H37 -> 381 | I38: =I36-I37 -> 515 | J38: =J36-J37 -> 722 | ... AB38: =AB36-AB37 -> 654 | AI38: =SUM(C38:F38) -> 1993 | AJ38: =SUM(G38:J38) -> 2109 | AK38: =SUM(K38:N38) -> 1127 | AL38: =SUM(O38:R38) -> 1426 | AM38: =SUM(S38:V38) -> 1956 | AN38: =SUM(W38:Z38) -> 2110 | AO38: =AO36-AO37 -> 2598.8802 | AP38: =AP36-AP37 -> 2828.0105 | AQ38: =AQ36-AQ37 -> 3064.2357 | AR38: =AR36-AR37 -> 3311.727 | AS38: =AS36-AS37 -> 3567.1758 | AT38: =AT36-AT37 -> 3808.12 | AU38: =AU36-AU37 -> 4027.5831 | AV38: =AV36-AV37 -> 4228.1118 | ... AX38: =AX36-AX37 -> 4576.897
B39: Non-service Pension & Other Income | C39: 0 | D39: 0 | E39: 0 | F39: 0 | G39: 0 | H39: 0 | I39: 0 | J39: 0 | K39: 0 | L39: 0 | M39: 0 | N39: 0 | O39: 0 | P39: 0 | Q39: 0 | R39: 0 | S39: 0 | T39: 0 | U39: 0 | V39: 0 | W39: 0 | X39: 0 | Y39: 0 | Z39: 0 | AA39: 0 | AB39: 0 | AI39: =SUM(C39:F39) -> 0 | AJ39: =SUM(G39:J39) -> 0 | AK39: =SUM(K39:N39) -> 0 | AL39: =SUM(O39:R39) -> 0 | AM39: =SUM(S39:V39) -> 0 | AN39: =SUM(W39:Z39) -> 0 | AO39: =AN55*$BH$55 -> 46.5015 | AP39: =AO55*$BH$55 -> 119.21604 | AQ39: =AP55*$BH$55 -> 204.7227 | AR39: =AQ55*$BH$55 -> 303.65075 | AS39: =AR55*$BH$55 -> 416.81386 | AT39: =AS55*$BH$55 -> 544.93991 | AU39: =AT55*$BH$55 -> 687.95915 | AV39: =AU55*$BH$55 -> 845.54697 | ... AX39: =AW55*$BH$55 -> 1203.3021
B40: Interest Income (Expense) | C40: -295 | D40: -79 | E40: 24 | F40: -321 | G40: -26 | H40: 201 | I40: 71 | J40: -134 | K40: 38 | L40: 41 | M40: 29 | N40: 38 | O40: -20 | P40: -28 | Q40: -79 | R40: -78 | S40: -88 | T40: -86 | U40: -65 | V40: -120 | W40: -66 | X40: -47 | Y40: -54 | Z40: -11 | AA40: -63 | AB40: 56 | AI40: =SUM(C40:F40) -> -671 | AJ40: =SUM(G40:J40) -> 112 | AK40: =SUM(K40:N40) -> 146 | AL40: =SUM(O40:R40) -> -205 | AM40: =SUM(S40:V40) -> -359 | AN40: =SUM(W40:Z40) -> -178 | AO40: =AN74*(-$BC$72) -> -678.795 | AP40: =AO74*(-$BC$72) -> -634.67332 | AQ40: =AP74*(-$BC$72) -> -593.41956 | AR40: =AQ74*(-$BC$72) -> -554.84729 | AS40: =AR74*(-$BC$72) -> -518.78221 | AT40: =AS74*(-$BC$72) -> -485.06137 | AU40: =AT74*(-$BC$72) -> -453.53238 | AV40: =AU74*(-$BC$72) -> -424.05278 | ... AX40: =AW74*(-$BC$72) -> -370.71754
B41: Pretax Income | C41: =C38+SUM(C39:C40) -> 221 | D41: =D38+SUM(D39:D40) -> 336 | E41: =E38+SUM(E39:E40) -> 518 | F41: =F38+SUM(F39:F40) -> 247 | G41: =G38+SUM(G39:G40) -> 465 | H41: =H38+SUM(H39:H40) -> 582 | I41: =I38+SUM(I39:I40) -> 586 | J41: =J38+SUM(J39:J40) -> 588 | ... AB41: =AB38+SUM(AB39:AB40) -> 710 | AI41: =SUM(C41:F41) -> 1322 | AJ41: =SUM(G41:J41) -> 2221 | AK41: =SUM(K41:N41) -> 1273 | AL41: =SUM(O41:R41) -> 1221 | AM41: =SUM(S41:V41) -> 1597 | AN41: =SUM(W41:Z41) -> 1932 | AO41: =AO38+SUM(AO39:AO40) -> 1966.5867 | AP41: =AP38+SUM(AP39:AP40) -> 2312.5532 | AQ41: =AQ38+SUM(AQ39:AQ40) -> 2675.5388 | AR41: =AR38+SUM(AR39:AR40) -> 3060.5305 | AS41: =AS38+SUM(AS39:AS40) -> 3465.2075 | AT41: =AT38+SUM(AT39:AT40) -> 3867.9985 | AU41: =AU38+SUM(AU39:AU40) -> 4262.0099 | AV41: =AV38+SUM(AV39:AV40) -> 4649.606 | ... AX41: =AX38+SUM(AX39:AX40) -> 5409.4816
B42: Taxes | C42: 26 | D42: 58 | E42: 87 | F42: 63 | G42: 60 | H42: 169 | I42: 107 | J42: 104 | K42: 61 | L42: 55 | M42: -20 | N42: 116 | O42: 34 | P42: 21 | Q42: 18 | R42: -50 | S42: 5 | T42: 23 | U42: 26 | V42: 31 | W42: 73 | X42: 66 | Y42: 105 | Z42: 82 | AA42: 77 | AB42: 110 | AI42: =SUM(C42:F42) -> 234 | AJ42: =SUM(G42:J42) -> 440 | AK42: =SUM(K42:N42) -> 212 | AL42: =SUM(O42:R42) -> 23 | AM42: =SUM(S42:V42) -> 85 | AN42: =SUM(W42:Z42) -> 326 | AO42: =AO41*AO52 -> 294.98801 | AP42: =AP41*AP52 -> 346.88298 | AQ42: =AQ41*AQ52 -> 401.33082 | AR42: =AR41*AR52 -> 459.07957 | AS42: =AS41*AS52 -> 519.78112 | AT42: =AT41*AT52 -> 580.19978 | AU42: =AU41*AU52 -> 639.30148 | AV42: =AV41*AV52 -> 697.4409 | ... AX42: =AX41*AX52 -> 811.42224
B43: Net Income | C43: =C41-C42 -> 195 | D43: =D41-D42 -> 278 | E43: =E41-E42 -> 431 | F43: =F41-F42 -> 184 | G43: =G41-G42 -> 405 | H43: =H41-H42 -> 413 | I43: =I41-I42 -> 479 | J43: =J41-J42 -> 484 | ... AB43: =AB41-AB42 -> 600 | AI43: =SUM(C43:F43) -> 1088 | AJ43: =SUM(G43:J43) -> 1781 | AK43: =SUM(K43:N43) -> 1061 | AL43: =SUM(O43:R43) -> 1198 | AM43: =SUM(S43:V43) -> 1512 | AN43: =SUM(W43:Z43) -> 1606 | AO43: =AO41-AO42 -> 1671.5987 | AP43: =AP41-AP42 -> 1965.6702 | AQ43: =AQ41-AQ42 -> 2274.208 | AR43: =AR41-AR42 -> 2601.4509 | AS43: =AS41-AS42 -> 2945.4264 | AT43: =AT41-AT42 -> 3287.7987 | AU43: =AU41-AU42 -> 3622.7084 | AV43: =AV41-AV42 -> 3952.1651 | ... AX43: =AX41-AX42 -> 4598.0594
B44: non-controlling interest | C44: 0 | D44: 0 | E44: 0 | F44: 0 | G44: 0 | H44: 0 | I44: 0 | J44: 0 | K44: 0 | L44: 0 | M44: 0 | N44: 0 | O44: 0 | P44: 0 | Q44: 0 | R44: 0 | S44: 0 | T44: 0 | U44: 4 | V44: 0 | W44: 0 | X44: 0 | Y44: 0 | Z44: 0 | AA44: 0 | AB44: 14 | AI44: =SUM(C44:F44) -> 0 | AJ44: =SUM(G44:J44) -> 0 | AK44: =SUM(K44:N44) -> 0 | AL44: =SUM(O44:R44) -> 0 | AM44: =SUM(S44:V44) -> 4 | AN44: =SUM(W44:Z44) -> 0 | AO44: 0 | AP44: 0 | AQ44: 0 | AR44: 0 | AS44: 0 | AT44: 0 | AU44: 0 | AV44: 0 | AW44: 0 | AX44: 0
B45: Net Income attr to LHX | C45: =C43-C44 -> 195 | D45: =D43-D44 -> 278 | E45: =E43-E44 -> 431 | F45: =F43-F44 -> 184 | G45: =G43-G44 -> 405 | H45: =H43-H44 -> 413 | I45: =I43-I44 -> 479 | J45: =J43-J44 -> 484 | ... AB45: =AB43-AB44 -> 586 | AI45: =SUM(C45:F45) -> 1088 | AJ45: =SUM(G45:J45) -> 1781 | AK45: =SUM(K45:N45) -> 1061 | AL45: =SUM(O45:R45) -> 1198 | AM45: =SUM(S45:V45) -> 1508 | AN45: =SUM(W45:Z45) -> 1606 | AO45: =AO43-AO44 -> 1671.5987 | AP45: =AP43-AP44 -> 1965.6702 | AQ45: =AQ43-AQ44 -> 2274.208 | AR45: =AR43-AR44 -> 2601.4509 | AS45: =AS43-AS44 -> 2945.4264 | AT45: =AT43-AT44 -> 3287.7987 | AU45: =AU43-AU44 -> 3622.7084 | AV45: =AV43-AV44 -> 3952.1651 | ... AX45: =AX43-AX44 -> 4598.0594 | AY45: =AX45*(1+$BH$56) -> 4655.5351 | AZ45: =AY45*(1+$BH$56) -> 4713.7293 | BA45: =AZ45*(1+$BH$56) -> 4772.6509 | BB45: =BA45*(1+$BH$56) -> 4832.309 | BC45: =BB45*(1+$BH$56) -> 4892.7129 | BD45: =BC45*(1+$BH$56) -> 4953.8718 | BE45: =BD45*(1+$BH$56) -> 5015.7952 | BF45: =BE45*(1+$BH$56) -> 5078.4926 | ... CV45: =CU45*(1+$BH$56) -> 8557.0913
B46: SC | C46: 217 | D46: 216 | E46: 213 | F46: 214 | G46: 207 | H46: 204 | I46: 200 | J46: 201 | K46: 193 | L46: 192 | M46: 191 | N46: 192 | O46: 190 | P46: 189 | Q46: 189 | R46: 190 | S46: 190 | T46: 190 | U46: 190 | V46: 190 | W46: 188 | X46: 187.1 | Y46: 187 | Z46: 187 | AA46: 187 | AB46: 186.214 | AI46: =AVERAGE(C46:F46) -> 215 | AJ46: =AVERAGE(G46:J46) -> 203 | AK46: =AVERAGE(K46:N46) -> 192 | AL46: =AVERAGE(O46:R46) -> 189.5 | AM46: =AVERAGE(S46:V46) -> 190 | AN46: =AVERAGE(W46:Z46) -> 187.275
...

Sheet Notes | Quant Analysis
CK1: 0
P2: Employee Scope: | AN2: General Notes/Observations
Q32: Notes: | R32: [X]
R33: [Y]
R34: [Z]
AN35: Financial Stmts. Notes/Observations
P36: Institutional Ownership Snapshot | AN36: Revenues:
Q65: Notes: | R65: [X]
R66: [Y]
R67: [Z]
P69: Revenue Breakdown by Segment (Build graph for this section if applicable…. See example below) | AN69: Earnings Scope:
Q101: Notes: | R101: [X]
R102: [Y]
R103: [Z]
P105: Q/q Total Revenues, Net Income, FCF | AN105: Balance Sheet Scope:
Q134: Notes: | R134: [X]
R135: [Y]
R136: [Z]
P138: Y/y Total Revenues, Net Income, FCF | AN138: [Equity Preformance Compared to Peers]
Q167: Notes: | R167: [X]
R168: [Y]
R169: [Z]
A184: VOO Historical Returns | I184: LHX Historical Returns
A185: 753 Trading Days? (From: 10/22/2023 - 10/22/2026) | I185: 753 Trading Days? (From: 10/22/2023 - 10/22/2026)
A186: Close | B186: High | C186: Low | D186: Open | E186: Volume | F186: UTC Date | G186: Change | I186: Close | J186: High | K186: Low | L186: Open | M186: Volume | N186: UTC Date | O186: Change
A187: 702.3 | B187: 705.66 | C187: 699.68 | D187: 704.41 | E187: 6041430.3 | F187: Thu, 22 Oct 2026 00:00:00 GMT | G187: =A187/D187-1 -> -0.0029954146 | I187: 254.23 | J187: 254.785 | K187: 249.16 | L187: 249.16 | M187: 1889117.4 | N187: Thu, 22 Oct 2026 00:00:00 GMT | O187: =I187/L187-1 -> 0.020348371
A188: 710.72 | B188: 711.83 | C188: 706.33 | D188: 708.84 | E188: 6210315.6 | F188: Wed, 21 Oct 2026 00:00:00 GMT | G188: =A188/D188-1 -> 0.0026522205 | I188: 247.55 | J188: 251.54 | K188: 246.72 | L188: 249.5 | M188: 1050418.4 | N188: Wed, 21 Oct 2026 00:00:00 GMT | O188: =I188/L188-1 -> -0.0078156313
A189: 706.8 | B189: 709.81 | C189: 702.49 | D189: 704.01 | E189: 5798006.5 | F189: Tue, 20 Oct 2026 00:00:00 GMT | G189: =A189/D189-1 -> 0.0039630119 | I189: 248.77 | J189: 250.19 | K189: 243.6 | L189: 244.97 | M189: 1900703.3 | N189: Tue, 20 Oct 2026 00:00:00 GMT | O189: =I189/L189-1 -> 0.015512104
A190: 704.6 | B190: 708.17 | C190: 703.9805 | D190: 705.27 | E190: 5588525.7 | F190: Mon, 19 Oct 2026 00:00:00 GMT | G190: =A190/D190-1 -> -0.00094999078 | I190: 243.84 | J190: 246.89 | K190: 242.95 | L190: 245.16 | M190: 1235212.8 | N190: Mon, 19 Oct 2026 00:00:00 GMT | O190: =I190/L190-1 -> -0.0053842389
A191: 701.61 | B191: 710.85 | C191: 699.191 | D191: 710.75 | E191: 6095662.4 | F191: Fri, 16 Oct 2026 00:00:00 GMT | G191: =A191/D191-1 -> -0.012859655 | I191: 248.51 | J191: 248.63 | K191: 242.01 | L191: 243.54 | M191: 3372290.9 | N191: Fri, 16 Oct 2026 00:00:00 GMT | O191: =I191/L191-1 -> 0.020407325
A192: 709.43 | B192: 710.4 | C192: 702.69 | D192: 704.33 | E192: 6035492.3 | F192: Thu, 15 Oct 2026 00:00:00 GMT | G192: =A192/D192-1 -> 0.007240924 | I192: 240.5 | J192: 242.2 | K192: 238.88 | L192: 241.48 | M192: 3008243.3 | N192: Thu, 15 Oct 2026 00:00:00 GMT | O192: =I192/L192-1 -> -0.0040583071
A193: 707.43 | B193: 713.62 | C193: 704.76 | D193: 712.32 | E193: 6228217.1 | F193: Wed, 14 Oct 2026 00:00:00 GMT | G193: =A193/D193-1 -> -0.0068648922 | I193: 237.5 | J193: 239.44 | K193: 236.09 | L193: 237.88 | M193: 2427008.1 | N193: Wed, 14 Oct 2026 00:00:00 GMT | O193: =I193/L193-1 -> -0.0015974441
A194: 715.2 | B194: 715.835 | C194: 713.27 | D194: 714.54 | E194: 4959098.4 | F194: Tue, 13 Oct 2026 00:00:00 GMT | G194: =A194/D194-1 -> 0.00092367117 | I194: 234.72 | J194: 238.89 | K194: 233.61 | L194: 238.75 | M194: 1558201.5 | N194: Tue, 13 Oct 2026 00:00:00 GMT | O194: =I194/L194-1 -> -0.016879581
A195: 715.13 | B195: 716.415 | C195: 714.26 | D195: 715.81 | E195: 3635491.2 | F195: Mon, 12 Oct 2026 00:00:00 GMT | G195: =A195/D195-1 -> -0.00094997276 | I195: 238.25 | J195: 238.39 | K195: 236.01 | L195: 237.08 | M195: 1077026.2 | N195: Mon, 12 Oct 2026 00:00:00 GMT | O195: =I195/L195-1 -> 0.004935043
A196: 715.59 | B196: 716.435 | C196: 712.54 | D196: 713.54 | E196: 4345835.7 | F196: Fri, 09 Oct 2026 00:00:00 GMT | G196: =A196/D196-1 -> 0.0028729994 | I196: 236.97 | J196: 238.08 | K196: 235.0748 | L196: 237 | M196: 973952.31 | N196: Fri, 09 Oct 2026 00:00:00 GMT | O196: =I196/L196-1 -> -0.00012658228
A197: 711.28 | B197: 714.27 | C197: 708.16 | D197: 712.25 | E197: 4763330.7 | F197: Thu, 08 Oct 2026 00:00:00 GMT | G197: =A197/D197-1 -> -0.0013618814 | I197: 236.92 | J197: 237.15 | K197: 232.3427 | L197: 233.5 | M197: 1203427.4 | N197: Thu, 08 Oct 2026 00:00:00 GMT | O197: =I197/L197-1 -> 0.014646681
A198: 714.34 | B198: 715.055 | C198: 711.06 | D198: 713.06 | E198: 4675948.1 | F198: Wed, 07 Oct 2026 00:00:00 GMT | G198: =A198/D198-1 -> 0.0017950804 | I198: 233.63 | J198: 238.669 | K198: 233.01 | L198: 237.17 | M198: 978954.72 | N198: Wed, 07 Oct 2026 00:00:00 GMT | O198: =I198/L198-1 -> -0.014926002
A199: 716.2 | B199: 718.47 | C199: 715.09 | D199: 715.21 | E199: 4568431.3 | F199: Tue, 06 Oct 2026 00:00:00 GMT | G199: =A199/D199-1 -> 0.0013842088 | I199: 237.9 | J199: 239.4599 | K199: 235.3 | L199: 236.3 | M199: 1139704 | N199: Tue, 06 Oct 2026 00:00:00 GMT | O199: =I199/L199-1 -> 0.0067710537
A200: 712.32 | B200: 713.8583 | C200: 707.42 | D200: 707.44 | E200: 6172916.9 | F200: Mon, 05 Oct 2026 00:00:00 GMT | G200: =A200/D200-1 -> 0.0068981115 | I200: 236.88 | J200: 239.22 | K200: 235.545 | L200: 237.04 | M200: 1273649.3 | N200: Mon, 05 Oct 2026 00:00:00 GMT | O200: =I200/L200-1 -> -0.00067499156 | R200: Min | S200: =MIN(O187:O939) -> -0.064419904
A201: 707.54 | B201: 710.2 | C201: 705.12 | D201: 708.31 | E201: 6612533.1 | F201: Fri, 02 Oct 2026 00:00:00 GMT | G201: =A201/D201-1 -> -0.0010870946 | I201: 236.6 | J201: 238.62 | K201: 234.66 | L201: 238.22 | M201: 1528992.9 | N201: Fri, 02 Oct 2026 00:00:00 GMT | O201: =I201/L201-1 -> -0.0068004366 | R201: Max | S201: =MAX(O187:O939) -> 0.084383063
...

Sheet Product Lines

Sheet Management

Sheet Table Formatting
B2: [Bold Title] | G2: [Bold Title]
B3: Line Titles | G3: <-- General
B4: Line Titles | G4: <-- Info
B5: Line Titles | G5: <-- General
B6: Line Titles | G6: <-- Info
B7: Line Titles | G7: <-- General
B8: Line Titles | G8: <-- Info
