Workbook

Sheet Main
B2: LULU
B3: Price | C3: 147.03 | D3: 2/18/2025
B4: SO | C4: 118.981 | D4: Q3'25
B5: MC | C5: =C3*C4 -> 17493.776
B6: Cash | C6: 1807.2 | D6: Q3'25
B7: Debt | C7: 0 | D7: Q3'25
B8: EV | C8: =C5-C6+C7 -> 15686.576
B10: Lululemon Athletica Inc. (LULU)
B12: Founder(s): Dennis "Chip" Wilson | G12: Registered Exchange: NASDAQ | O12: Resources:
B13: Founded: 1998 | G13: Address: 1818 Cornwall Avenue, Vancouver, BC V6J 1C7 CA | O13: SEC filings | R13: https://www.sec.gov/edgar/browse/?CIK=1397187&owner=exclude
B14: Headquarters: Vancouver, BC, Canada | G14: Investor Relations Contact: | O14: Company Homepage | R14: https://shop.lululemon.com/
B15: Current CEO: Calvin McDonald | G15: Investors Relation Department | P15: Company IR Page | S15: https://corporate.lululemon.com/investors
B16: Employees: 39,000 | G16: Phone: | H16: (604) 732 - 6124 | J16: Email: | K16: investors@lululemon.com | O16: Earnings Calls | R16: https://seekingalpha.com/symbol/LULU/earnings/transcripts
B17: Industry: Clothing Apparel - Retail | O17: Equity Analysis | R17: https://stockanalysis.com/stocks/lulu/company/
B18: Sector: Consumer Discretionary | O18: MacroTrends | R18: https://www.macrotrends.net/stocks/charts/LULU/lululemon-athletica-inc/income-statement?freq=A
B19: IPO: July 27, 2007 | O19: ROIC, WACC | R19: https://www.gurufocus.com/term/wacc/LULU
B20: Fiscal Year: [March - February] | O20: Godel Terminal | R20: https://app.godelterminal.com/
A22: Company Overview:
B23: Lululemon is a leading global retailer specializing in athletic apparel, footwear, and accessories
C24: The Company has a strong North American and growing international presence
C25: Management recent implementation of cost-saving programs and inventory discipline in response to tariff and U.S. market headwinds
B26: Founded in 1998 and headquartered in Vancouver, Canada, Lululemon has built a strong brand in premium athleisure and activewear, recognized for its innovation, retail experience, and community engagement
C27: The Company offers pants, shorts, tops, and jackets for athletic activities, such as yoga, running, training, and other activities … The Company also offers fitness-inspired accessories
C28: Strong brand loyalty and premium positioning in athleisure/activewear
B29: Business Segments
B30: Product Segments:
C31: Women’s apparel (core yoga, training, running, lifestyle), men’s athletic wear (rapidly expanding), footwear, and accessories (bags, yoga mats, and more)
C32: Retail Channels:
D33: Physical company-operated stores (784 globally as of Q2 2025), direct-to-consumer (DTC, including digital sales), and wholesale/partnered retail
C34: Digital Channels:
D35: Digital (e-commerce) has grown rapidly since pandemic … strong omni-channel strategy
C36: Integrated omni-channel presence, blending engaging physical retail with high-penetration digital
A38: Business Segments and Geographical Info:

Sheet Model
AM1: Q1 2020 | AQ1: Q1 2021 | AU1: Q1 2022 | AY1: Q1 2023 | BC1: Q1 2024 | BG1: Q1 2025
B2: Quarterly | C2: June | D2: Sept. | E2: Dec. | F2: Mar. | G2: June | H2: Sept. | I2: Dec. | J2: Mar. | K2: June | L2: Sept. | M2: Dec. | N2: Mar. | O2: June | P2: Sept. | Q2: Dec. | R2: Mar. | S2: June | T2: Sept. | U2: Dec. | V2: Mar. | W2: June | X2: Sept. | Y2: Dec. | Z2: Mar. | AA2: June | AB2: Sept. | AC2: Dec. | AD2: Mar. | AE2: June | AF2: Sept. | AG2: Dec. | AH2: Mar. | AI2: June | AJ2: Sept. | AK2: Dec. | AL2: Mar. | AM2: June | AN2: Sept. | AO2: Dec. | AP2: Mar. | AQ2: June | AR2: Sept. | AS2: Dec. | AT2: Mar. | AU2: June | AV2: Sept. | AW2: Dec. | AX2: Mar. | AY2: June | AZ2: Sept. | BA2: Dec. | BB2: Mar. | BC2: June | BD2: Sept. | BE2: Dec. | BF2: Mar. | BG2: June | BH2: Sept. | BI2: Dec. | BJ2: Mar. | BK2: June | BL2: Sept. | BM2: Dec. | BN2: Mar.
B3: Revenues | C3: Q1 2011 | D3: Q2 2011 | E3: Q3 2011 | F3: Q4 2011 | G3: Q1 2012 | H3: Q2 2012 | I3: Q3 2012 | J3: Q4 2012 | K3: Q1 2013 | L3: Q2 2013 | M3: Q3 2013 | N3: Q4 2013 | O3: Q1 2014 | P3: Q2 2014 | Q3: Q3 2014 | R3: Q4 2014 | S3: Q1 2015 | T3: Q2 2015 | U3: Q3 2015 | V3: Q4 2015 | W3: Q1 2016 | X3: Q2 2016 | Y3: Q3 2016 | Z3: Q4 2016 | AA3: Q1 2017 | AB3: Q2 2017 | AC3: Q3 2017 | AD3: Q4 2017 | AE3: Q1 2018 | AF3: Q2 2018 | AG3: Q3 2018 | AH3: Q4 2018 | AI3: Q1 2019 | AJ3: Q2 2019 | AK3: Q3 2019 | AL3: Q4 2019 | AM3: Q1 2020 | AN3: Q2 2020 | AO3: Q3 2020 | AP3: Q4 2020 | AQ3: Q1 2021 | AR3: Q2 2021 | AS3: Q3 2021 | AT3: Q4 2021 | AU3: Q1 2022 | AV3: Q2 2022 | AW3: Q3 2022 | AX3: Q4 2022 | AY3: Q1 2023 | AZ3: Q2 2023 | BA3: Q3 2023 | BB3: Q4 2023 | BC3: Q1 2024 | BD3: Q2 2024 | BE3: Q3 2024 | BF3: Q4 2024 | BG3: Q1 2025 | BH3: Q2 2025 | BI3: Q3 2025 | BJ3: Q4 2025 | BK3: Q1 2026 | BL3: Q2 2026 | BM3: Q3 2026 | BN3: Q4 2026 | BS3: 2011 | BT3: =BS3+1 -> 2012 | BU3: =BT3+1 -> 2013 | BV3: =BU3+1 -> 2014 | BW3: =BV3+1 -> 2015 | BX3: =BW3+1 -> 2016 | BY3: =BX3+1 -> 2017 | BZ3: =BY3+1 -> 2018 | CA3: =BZ3+1 -> 2019 | ... EO3: =EN3+1 -> 2085
B4: Women's Apparel | AM4: 477.627 | AN4: 647.198 | AO4: 787.402 | AP4: =3049.906-SUM(AM4:AO4) -> 1137.679 | AQ4: 849.645 | AR4: 968.951 | AS4: 984.952 | AT4: =4171.762-SUM(AQ4:AS4) -> 1368.214 | AU4: 1073.92 | AV4: 1205.636 | AW4: 1204.835 | AX4: =5259.803-SUM(AU4:AW4) -> 1775.412 | AY4: 1308.828 | AZ4: 1396.32 | BA4: 1433.92 | BB4: =6147.37-SUM(AY4:BA4) -> 2008.302 | BC4: 1435.24 | BD4: 1476.121 | BE4: 1555.68 | BF4: =6692.63-SUM(BC4:BE4) -> 2225.589 | BG4: 1535.172 | BH4: 1547.32 | BI4: 1644.95 | BJ4: =6995.36-SUM(BG4:BI4) -> 2267.918 | CB4: =SUM(AM4:AP4) -> 3049.906 | CC4: =SUM(AQ4:AT4) -> 4171.762 | CD4: =SUM(AU4:AX4) -> 5259.803 | CE4: =SUM(AY4:BB4) -> 6147.37 | CF4: =SUM(BC4:BF4) -> 6692.63 | CG4: =SUM(BG4:BJ4) -> 6995.36 | CH4: =CG4*(1+CH9) -> 7240.1976 | CI4: =CH4*(1+CI9) -> 7529.8055 | CJ4: =CI4*(1+CJ9) -> 7868.6468 | CK4: =CJ4*(1+CK9) -> 8262.0791 | CL4: =CK4*(1+CL9) -> 8633.8726 | CM4: =CL4*(1+CM9) -> 9000.8122 | CN4: =CM4*(1+CN9) -> 9360.8447 | CO4: =CN4*(1+CO9) -> 9711.8764 | ... CQ4: =CP4*(1+CQ9) -> 10393.553
B5: Men's Apparel | AM5: 128.391 | AN5: 190.381 | AO5: 238.05 | AP5: =953.183-SUM(AM5:AO5) -> 396.361 | AQ5: 274.307 | AR5: 363.06 | AS5: 343.26 | AT5: =1535.85-SUM(AQ5:AS5) -> 555.223 | AU5: 374.998 | AV5: 461.31 | AW5: 440.56 | AX5: =1956.602-SUM(AU5:AW5) -> 679.734 | AY5: 438.165 | AZ5: 530.72 | BA5: 504.828 | BB5: =2252.75-SUM(AY5:BA5) -> 779.037 | BC5: 505.698 | BD5: 587.525 | BE5: 551.43 | BF5: =2558.38-SUM(BC5:BE5) -> 913.727 | BG5: 544.788 | BH5: 624.59 | BI5: 596.24 | BJ5: =2663.98-SUM(BG5:BI5) -> 898.362 | CB5: =SUM(AM5:AP5) -> 953.183 | CC5: =SUM(AQ5:AT5) -> 1535.85 | CD5: =SUM(AU5:AX5) -> 1956.602 | CE5: =SUM(AY5:BB5) -> 2252.75 | CF5: =SUM(BC5:BF5) -> 2558.38 | CG5: =SUM(BF5:BI5) -> 2679.345 | CH5: =CG5*(1+CH10) -> 2834.747 | CI5: =CH5*(1+CI10) -> 3019.0056 | CJ5: =CI5*(1+CJ10) -> 3207.6934 | CK5: =CJ5*(1+CK10) -> 3416.1935 | CL5: =CK5*(1+CL10) -> 3612.6246 | CM5: =CL5*(1+CM10) -> 3829.3821 | CN5: =CM5*(1+CN10) -> 4039.9981 | CO5: =CN5*(1+CO10) -> 4241.998 | ... CQ5: =CP5*(1+CQ10) -> 4610.2034
B6: Acccessories & Other | AM6: 45.94 | AN6: 65.363 | AO6: 91.97 | AP6: =398.79-SUM(AM6:AO6) -> 195.517 | AQ6: 102.513 | AR6: 118.604 | AS6: 122.206 | AT6: =549.005-SUM(AQ6:AS6) -> 205.682 | AU6: 164.54 | AV6: 201.382 | AW6: 211.49 | AX6: =894.113-SUM(AU6:AW6) -> 316.701 | AY6: 253.799 | AZ6: 282.11 | BA6: 265.46 | BB6: =1219.15-SUM(AY6:BA6) -> 417.781 | BC6: 267.95 | BD6: 307.43 | BE6: 289.54 | BF6: =1337.116-SUM(BC6:BE6) -> 472.196 | BG6: 290.7 | BH6: 353.3 | BI6: 324.727 | BJ6: =1443.24-SUM(BG6:BI6) -> 474.513 | CB6: =SUM(AM6:AP6) -> 398.79 | CC6: =SUM(AQ6:AT6) -> 549.005 | CD6: =SUM(AU6:AX6) -> 894.113 | CE6: =SUM(AY6:BB6) -> 1219.15 | CF6: =SUM(BC6:BF6) -> 1337.116 | CG6: =SUM(BF6:BI6) -> 1440.923 | CH6: =CG6*(1+CH11) -> 1534.583 | CI6: =CH6*(1+CI11) -> 1642.0038 | CJ6: =CI6*(1+CJ11) -> 1765.1541 | CK6: =CJ6*(1+CK11) -> 1879.8891 | CL6: =CK6*(1+CL11) -> 1997.3822 | CM6: =CL6*(1+CM11) -> 2117.2251 | CN6: =CM6*(1+CN11) -> 2233.6725 | CO6: =CN6*(1+CO11) -> 2345.3561 | ... CQ6: =CP6*(1+CQ11) -> 2524.424
B7: Ttl Revenues | AM7: =SUM(AM4:AM6) -> 651.958 | AN7: =SUM(AN4:AN6) -> 902.942 | AO7: =SUM(AO4:AO6) -> 1117.422 | AP7: =SUM(AP4:AP6) -> 1729.557 | AQ7: =SUM(AQ4:AQ6) -> 1226.465 | AR7: =SUM(AR4:AR6) -> 1450.615 | AS7: =SUM(AS4:AS6) -> 1450.418 | AT7: =SUM(AT4:AT6) -> 2129.119 | ... BJ7: =SUM(BJ4:BJ6) -> 3640.793 | CB7: =SUM(AM7:AP7) -> 4401.879 | CC7: =SUM(AQ7:AT7) -> 6256.617 | CD7: =SUM(AU7:AX7) -> 8110.518 | CE7: =SUM(AY7:BB7) -> 9619.27 | CF7: =SUM(BC7:BF7) -> 10588.126 | CG7: =SUM(BF7:BI7) -> 11073.299 | CH7: =SUM(CH4:CH6) -> 11609.528 | CI7: =SUM(CI4:CI6) -> 12190.815 | CJ7: =SUM(CJ4:CJ6) -> 12841.494 | CK7: =SUM(CK4:CK6) -> 13558.162 | CL7: =SUM(CL4:CL6) -> 14243.879 | CM7: =SUM(CM4:CM6) -> 14947.419 | CN7: =SUM(CN4:CN6) -> 15634.515 | CO7: =SUM(CO4:CO6) -> 16299.231 | ... CQ7: =SUM(CQ4:CQ6) -> 17528.18
B9: Women's Apparel Growth Y/y | AQ9: =AQ4/AM4-1 -> 0.77888813 | AR9: =AR4/AN4-1 -> 0.4971477 | AS9: =AS4/AO4-1 -> 0.25088836 | AT9: =AT4/AP4-1 -> 0.20263624 | AU9: =AU4/AQ4-1 -> 0.26396318 | AV9: =AV4/AR4-1 -> 0.24426932 | AW9: =AW4/AS4-1 -> 0.22324235 | AX9: =AX4/AT4-1 -> 0.2976128 | ... BJ9: =BJ4/BF4-1 -> 0.019019235 | CC9: =CC4/CB4-1 -> 0.36783298 | CD9: =CD4/CC4-1 -> 0.2608109 | CE9: =CE4/CD4-1 -> 0.16874529 | CF9: =CF4/CE4-1 -> 0.088698094 | CG9: =CG4/CF4-1 -> 0.045233339 | CH9: 0.035 | CI9: 0.04 | CJ9: 0.045 | CK9: 0.05 | CL9: 0.045 | CM9: 0.0425 | CN9: 0.04 | CO9: 0.0375 | CP9: 0.035 | CQ9: 0.034
B10: Men's Apparel Growth Y/y | AQ10: =AQ5/AM5-1 -> 1.1364971 | AR10: =AR5/AN5-1 -> 0.90701803 | AS10: =AS5/AO5-1 -> 0.44196597 | AT10: =AT5/AP5-1 -> 0.40080129 | AU10: =AU5/AQ5-1 -> 0.36707412 | AV10: =AV5/AR5-1 -> 0.27061643 | AW10: =AW5/AS5-1 -> 0.2834586 | AX10: =AX5/AT5-1 -> 0.22425404 | ... BJ10: =BJ5/BF5-1 -> -0.016815745 | CC10: =CC5/CB5-1 -> 0.61128556 | CD10: =CD5/CC5-1 -> 0.27395384 | CE10: =CE5/CD5-1 -> 0.15135832 | CF10: =CF5/CE5-1 -> 0.13566974 | CG10: =CG5/CF5-1 -> 0.047281874 | CH10: 0.058 | CI10: 0.065 | CJ10: 0.0625 | CK10: 0.065 | CL10: 0.0575 | CM10: 0.06 | CN10: 0.055 | CO10: 0.05 | CP10: 0.045 | CQ10: 0.04
B11: Acccessories & Other Growth Y/y | AQ11: =AQ6/AM6-1 -> 1.2314541 | AR11: =AR6/AN6-1 -> 0.8145434 | AS11: =AS6/AO6-1 -> 0.32875938 | AT11: =AT6/AP6-1 -> 0.051990364 | AU11: =AU6/AQ6-1 -> 0.60506472 | AV11: =AV6/AR6-1 -> 0.69793599 | AW11: =AW6/AS6-1 -> 0.73060243 | AX11: =AX6/AT6-1 -> 0.53976041 | ... BJ11: =BJ6/BF6-1 -> 0.0049068607 | CC11: =CC6/CB6-1 -> 0.37667695 | CD11: =CD6/CC6-1 -> 0.6286063 | CE11: =CE6/CD6-1 -> 0.36353011 | CF11: =CF6/CE6-1 -> 0.096760858 | CG11: =CG6/CF6-1 -> 0.077635 | CH11: 0.065 | CI11: 0.07 | CJ11: 0.075 | CK11: 0.065 | CL11: 0.0625 | CM11: 0.06 | CN11: 0.055 | CO11: 0.05 | CP11: 0.045 | CQ11: 0.03
B12: Ttl Revenue Growth Y/y | G12: =G38/C38-1 -> 0.52944325 | H12: =H38/D38-1 -> 0.33301887 | I12: =I38/E38-1 -> 0.3748914 | J12: =J38/F38-1 -> 0.30679371 | K12: =K38/G38-1 -> 0.21036052 | L12: =L38/H38-1 -> 0.21903751 | M12: =M38/I38-1 -> 0.20031596 | N12: =N38/J38-1 -> 0.073120494 | ... AP12: =AP38/AL38-1 -> 0.23760787 | AQ12: =AQ7/AM7-1 -> 0.88120247 | AR12: =AR7/AN7-1 -> 0.60654283 | AS12: =AS7/AO7-1 -> 0.2980038 | AT12: =AT7/AP7-1 -> 0.23101985 | AU12: =AU7/AQ7-1 -> 0.3155353 | AV12: =AV7/AR7-1 -> 0.2879558 | AW12: =AW7/AS7-1 -> 0.28024128 | AX12: =AX7/AT7-1 -> 0.30187509 | ... BJ12: =BJ7/BF7-1 -> 0.0081076845 | BT12: =BT38/BS38-1 -> 0.36958781 | BU12: =BU38/BT38-1 -> 0.16120558 | BV12: =BV38/BU38-1 -> 0.12946204 | BW12: =BW38/BV38-1 -> 0.14650568 | BX12: =BX38/BW38-1 -> 0.13773356 | BY12: =BY38/BX38-1 -> 0.13006015 | BZ12: =BZ38/BY38-1 -> 0.24128039 | CA12: =CA38/BZ38-1 -> 0.21010218 | CB12: =CB38/CA38-1 -> 0.10619431 | CC12: =CC7/CB7-1 -> 0.42135143 | CD12: =CD7/CC7-1 -> 0.29631045 | CE12: =CE7/CD7-1 -> 0.18602412 | CF12: =CF7/CE7-1 -> 0.10072032 | CG12: =CG7/CF7-1 -> 0.045822367 | CH12: =CH7/CG7-1 -> 0.04842537 | CI12: =CI7/CH7-1 -> 0.050069847 | CJ12: =CJ7/CI7-1 -> 0.05337456 | ... CQ12: =CQ7/CP7-1 -> 0.034991625
B14: Women's Apparel % of Ttl Revenues | AM14: =AM4/AM7 -> 0.73260394 | AN14: =AN4/AN7 -> 0.71676586 | AO14: =AO4/AO7 -> 0.70465948 | AP14: =AP4/AP7 -> 0.65778636 | AQ14: =AQ4/AQ7 -> 0.69275927 | AR14: =AR4/AR7 -> 0.66795876 | AS14: =AS4/AS7 -> 0.67908148 | AT14: =AT4/AT7 -> 0.64261979 | ... BJ14: =BJ4/BJ7 -> 0.62291869 | CB14: =CB4/CB7 -> 0.69286457 | CC14: =CC4/CC7 -> 0.66677599 | CD14: =CD4/CD7 -> 0.64851628 | CE14: =CE4/CE7 -> 0.63906825 | CF14: =CF4/CF7 -> 0.63208825 | CG14: =CG4/CG7 -> 0.63173224
B15: Men's Apparel % of Ttl Revenues | AM15: =AM5/AM7 -> 0.1969314 | AN15: =AN5/AN7 -> 0.21084521 | AO15: =AO5/AO7 -> 0.213035 | AP15: =AP5/AP7 -> 0.22916909 | AQ15: =AQ5/AQ7 -> 0.22365661 | AR15: =AR5/AR7 -> 0.25028005 | AS15: =AS5/AS7 -> 0.23666281 | AT15: =AT5/AT7 -> 0.26077594 | ... BJ15: =BJ5/BJ7 -> 0.24674899 | CB15: =CB5/CB7 -> 0.21654003 | CC15: =CC5/CC7 -> 0.24547611 | CD15: =CD5/CD7 -> 0.24124254 | CE15: =CE5/CE7 -> 0.23419137 | CF15: =CF5/CF7 -> 0.24162727 | CG15: =CG5/CG7 -> 0.24196448
B16: Acccessories & Other % of Ttl Revenues | AM16: =AM6/AM7 -> 0.070464662 | AN16: =AN6/AN7 -> 0.072388924 | AO16: =AO6/AO7 -> 0.082305521 | AP16: =AP6/AP7 -> 0.11304455 | AQ16: =AQ6/AQ7 -> 0.083584122 | AR16: =AR6/AR7 -> 0.081761184 | AS16: =AS6/AS7 -> 0.084255711 | AT16: =AT6/AT7 -> 0.096604276 | ... BJ16: =BJ6/BJ7 -> 0.13033232 | CB16: =CB6/CB7 -> 0.090595403 | CC16: =CC6/CC7 -> 0.0877479 | CD16: =CD6/CD7 -> 0.11024117 | CE16: =CE6/CE7 -> 0.12674039 | CF16: =CF6/CF7 -> 0.12628448 | CG16: =CG6/CG7 -> 0.1301259
B18: U.S. Revenues | AU18: 1098.32 | AV18: 1278.361 | AW18: 1268.51 | AX18: =5654.34-SUM(AU18:AW18) -> 2009.149 | AY18: 1314.39 | AZ18: 1424.926 | BA18: 1423.57 | BB18: =6346-SUM(AY18:BA18) -> 2183.114 | BC18: 1340.4 | BD18: 1421.98 | BE18: 1424.23 | BF18: =6483.18-SUM(BC18:BE18) -> 2296.57 | BG18: 1362.52 | BH18: 1415.002 | BI18: 1380.97 | BJ18: =6328.38-SUM(BG18:BI18) -> 2169.888 | CD18: =SUM(AU18:AX18) -> 5654.34 | CE18: =SUM(AY18:BB18) -> 6346 | CF18: =SUM(BC18:BF18) -> 6483.18 | CG18: =SUM(BG18:BJ18) -> 6328.38
B19: Canada Revenues | AU19: 244.944 | AV19: 268.62 | AW19: 271.82 | AX19: =1163.11-SUM(AU19:AW19) -> 377.726 | AY19: 253.34 | AZ19: 294.847 | BA19: 308.82 | BB19: =1285.25-SUM(AY19:BA19) -> 428.243 | BC19: 281.86 | BD19: 319.453 | BE19: 335.48 | BF19: =1411.67-SUM(BC19:BE19) -> 474.877 | BG19: 292.82 | BH19: 321.29 | BI19: 331.596 | BJ19: =1423.17-SUM(BG19:BI19) -> 477.464 | CD19: =SUM(AU19:AX19) -> 1163.11 | CE19: =SUM(AY19:BB19) -> 1285.25 | CF19: =SUM(BC19:BF19) -> 1411.67 | CG19: =SUM(BG19:BJ19) -> 1423.17
B20: Mexico Revenues | AU20: 0 | AV20: 0 | AW20: 0 | AX20: =0-SUM(AU20:AW20) -> 0 | AY20: 0 | AZ20: 0 | BA20: 0 | BB20: =0-SUM(AY20:BA20) -> 0 | BC20: 0 | BD20: 0 | BE20: 10.66 | BF20: =33.3-SUM(BC20:BE20) -> 22.64 | BG20: 19.214 | BH20: 21.92 | BI20: 20.81 | BJ20: =95.48-SUM(BG20:BI20) -> 33.536 | CD20: =SUM(AU20:AX20) -> 0 | CE20: =SUM(AY20:BB20) -> 0 | CF20: =SUM(BC20:BF20) -> 33.3 | CG20: =SUM(BG20:BJ20) -> 95.48
B21: China Revenues | AU21: 139.427 | AV21: 172.02 | AW21: 174.15 | AX21: =681.63-SUM(AU21:AW21) -> 196.033 | AY21: 249.68 | AZ21: 277.5 | BA21: 266.891 | BB21: =1134.29-SUM(AY21:BA21) -> 340.219 | BC21: 346.05 | BD21: 356.224 | BE21: 359.388 | BF21: =1541.42-SUM(BC21:BE21) -> 479.758 | BG21: 412.205 | BH21: 440.532 | BI21: 511.82 | BJ21: =1754.79+199.07-SUM(BG21:BI21) -> 589.303 | CD21: =SUM(AU21:AX21) -> 681.63 | CE21: =SUM(AY21:BB21) -> 1134.29 | CF21: =SUM(BC21:BF21) -> 1541.42 | CG21: =SUM(BG21:BJ21) -> 1953.86
B22: Other Revenues | AU22: 130.763 | AV22: 149.325 | AW22: 142.4 | AX22: =611.43-SUM(AU22:AW22) -> 188.942 | AY22: 183.36 | AZ22: 211.892 | BA22: 204.929 | BB22: =853.338-SUM(AY22:BA22) -> 253.157 | BC22: 240.57 | BD22: 273.42 | BE22: 266.89 | BF22: =1118.54-SUM(BC22:BE22) -> 337.66 | BG22: 283.897 | BH22: 326.47 | BI22: 320.71 | BJ22: =1301.67-SUM(BG22:BI22) -> 370.593 | CD22: =SUM(AU22:AX22) -> 611.43 | CE22: =SUM(AY22:BB22) -> 853.338 | CF22: =SUM(BC22:BF22) -> 1118.54 | CG22: =SUM(BG22:BJ22) -> 1301.67
B23: Ttl Revenues | AU23: =SUM(AU18:AU22) -> 1613.454 | AV23: =SUM(AV18:AV22) -> 1868.326 | AW23: =SUM(AW18:AW22) -> 1856.88 | AX23: =SUM(AX18:AX22) -> 2771.85 | AY23: =SUM(AY18:AY22) -> 2000.77 | AZ23: =SUM(AZ18:AZ22) -> 2209.165 | BA23: =SUM(BA18:BA22) -> 2204.21 | BB23: =SUM(BB18:BB22) -> 3204.733 | ... BJ23: =SUM(BJ18:BJ22) -> 3640.784 | CD23: =SUM(CD18:CD22) -> 8110.51 | CE23: =SUM(CE18:CE22) -> 9618.878 | CF23: =SUM(CF18:CF22) -> 10588.11 | CG23: =SUM(BG23:BJ23) -> 11102.56
B25: U.S. Revenue Growth Y/y | AY25: =AY18/AU18-1 -> 0.19672773 | AZ25: =AZ18/AV18-1 -> 0.11465071 | BA25: =BA18/AW18-1 -> 0.1222379 | BB25: =BB18/AX18-1 -> 0.08658641 | BC25: =BC18/AY18-1 -> 0.019788647 | BD25: =BD18/AZ18-1 -> -0.0020674758 | BE25: =BE18/BA18-1 -> 0.00046362314 | BF25: =BF18/BB18-1 -> 0.051969801 | ... BJ25: =BJ18/BF18-1 -> -0.055161393 | CE25: =CE18/CD18-1 -> 0.12232374 | CF25: =CF18/CE18-1 -> 0.021616766 | CG25: =CG18/CF18-1 -> -0.023877171
B26: Canada Revenue Growth Y/y | AY26: =AY19/AU19-1 -> 0.034277223 | AZ26: =AZ19/AV19-1 -> 0.097636066 | BA26: =BA19/AW19-1 -> 0.13611949 | BB26: =BB19/AX19-1 -> 0.1337398 | BC26: =BC19/AY19-1 -> 0.11257598 | BD26: =BD19/AZ19-1 -> 0.083453452 | BE26: =BE19/BA19-1 -> 0.086328606 | BF26: =BF19/BB19-1 -> 0.10889612 | ... BJ26: =BJ19/BF19-1 -> 0.0054477265 | CE26: =CE19/CD19-1 -> 0.10501156 | CF26: =CF19/CE19-1 -> 0.098362186 | CG26: =CG19/CF19-1 -> 0.0081463798
B27: Mexico Revenue Growth Y/y | AY27: 0 | AZ27: 0 | BA27: 0 | BB27: 0 | BC27: 0 | BD27: 0 | BE27: 0 | BF27: 0 | BG27: 0 | BH27: 0 | BI27: 0 | BJ27: 0 | CE27: 0 | CF27: 0 | CG27: 0
B28: China Revenue Growth Y/y | AY28: =AY21/AU21-1 -> 0.79075789 | AZ28: =AZ21/AV21-1 -> 0.61318451 | BA28: =BA21/AW21-1 -> 0.53253517 | BB28: =BB21/AX21-1 -> 0.73551902 | BC28: =BC21/AY21-1 -> 0.38597405 | BD28: =BD21/AZ21-1 -> 0.28369009 | BE28: =BE21/BA21-1 -> 0.3465722 | BF28: =BF21/BB21-1 -> 0.41014464 | ... BJ28: =BJ21/BF21-1 -> 0.22833387 | CE28: =CE21/CD21-1 -> 0.66408462 | CF28: =CF21/CE21-1 -> 0.35892937 | CG28: =CG21/CF21-1 -> 0.26757146
B29: Other Revenue Growth Y/y | AY29: =AY22/AU22-1 -> 0.40223152 | AZ29: =AZ22/AV22-1 -> 0.41899883 | BA29: =BA22/AW22-1 -> 0.43910815 | BB29: =BB22/AX22-1 -> 0.3398662 | BC29: =BC22/AY22-1 -> 0.31200916 | BD29: =BD22/AZ22-1 -> 0.29037434 | BE29: =BE22/BA22-1 -> 0.3023535 | BF29: =BF22/BB22-1 -> 0.33379681 | ... BJ29: =BJ22/BF22-1 -> 0.097533021 | CE29: =CE22/CD22-1 -> 0.395643 | CF29: =CF22/CE22-1 -> 0.31078189 | CG29: =CG22/CF22-1 -> 0.16372235
B30: Ttl Revenue Growth Y/y | AY30: =AY23/AU23-1 -> 0.24005395 | AZ30: =AZ23/AV23-1 -> 0.18243015 | BA30: =BA23/AW23-1 -> 0.18705032 | BB30: =BB23/AX23-1 -> 0.15617115 | BC30: =BC23/AY23-1 -> 0.10401495 | BD30: =BD23/AZ23-1 -> 0.07329104 | BE30: =BE23/BA23-1 -> 0.087304749 | BF30: =BF23/BB23-1 -> 0.12692851 | ... BJ30: =BJ23/BF23-1 -> 0.0081071465 | CE30: =CE23/CD23-1 -> 0.18597696 | CF30: =CF23/CE23-1 -> 0.10076352 | CG30: =CG23/CF23-1 -> 0.048587519
B32: U.S. % of Revenues | AU32: =AU18/$BH$23 -> 0.43494136 | AV32: =AV18/$BH$23 -> 0.50623868 | AW32: =AW18/$BH$23 -> 0.50233762 | AX32: =AX18/$BH$23 -> 0.79563514 | AY32: =AY18/$BH$23 -> 0.52050638 | AZ32: =AZ18/$BH$23 -> 0.5642793 | BA32: =BA18/$BH$23 -> 0.56374232 | BB32: =BB18/$BH$23 -> 0.86452633 | ... BJ32: =BJ18/$BH$23 -> 0.85928876 | CD32: =CD18/$BH$23 -> 2.2391528 | CE32: =CE18/$BH$23 -> 2.5130543 | CF32: =CF18/$BH$23 -> 2.5673784 | CG32: =CG18/$BH$23 -> 2.5060767
B33: Canada % of Revenues | AU33: =AU19/$BH$23 -> 0.096999304 | AV33: =AV19/$BH$23 -> 0.10637514 | AW33: =AW19/$BH$23 -> 0.10764236 | AX33: =AX19/$BH$23 -> 0.14958178 | AY33: =AY19/$BH$23 -> 0.10032417 | AZ33: =AZ19/$BH$23 -> 0.11676119 | BA33: =BA19/$BH$23 -> 0.12229459 | BB33: =BB19/$BH$23 -> 0.16958682 | ... BJ33: =BJ19/$BH$23 -> 0.18907863 | CD33: =CD19/$BH$23 -> 0.46059859 | CE33: =CE19/$BH$23 -> 0.50896676 | CF33: =CF19/$BH$23 -> 0.55902985 | CG33: =CG19/$BH$23 -> 0.56358392
B34: Mexico % of Revenues | AU34: =AU20/$BH$23 -> 0 | AV34: =AV20/$BH$23 -> 0 | AW34: =AW20/$BH$23 -> 0 | AX34: =AX20/$BH$23 -> 0 | AY34: =AY20/$BH$23 -> 0 | AZ34: =AZ20/$BH$23 -> 0 | BA34: =BA20/$BH$23 -> 0 | BB34: =BB20/$BH$23 -> 0 | ... BJ34: =BJ20/$BH$23 -> 0.013280459 | CD34: =CD20/$BH$23 -> 0 | CE34: =CE20/$BH$23 -> 0 | CF34: =CF20/$BH$23 -> 0.013187001 | CG34: =CG20/$BH$23 -> 0.037810657
B35: China % of Revenues | AU35: =AU21/$BH$23 -> 0.055213934 | AV35: =AV21/$BH$23 -> 0.068120959 | AW35: =AW21/$BH$23 -> 0.068964452 | AX35: =AX21/$BH$23 -> 0.077630252 | AY35: =AY21/$BH$23 -> 0.098874788 | AZ35: =AZ21/$BH$23 -> 0.10989168 | BA35: =BA21/$BH$23 -> 0.10569045 | BB35: =BB21/$BH$23 -> 0.13472878 | ... BJ35: =BJ21/$BH$23 -> 0.23336755 | CD35: =CD21/$BH$23 -> 0.2699296 | CE35: =CE21/$BH$23 -> 0.44918569 | CF35: =CF21/$BH$23 -> 0.61041163 | CG35: =CG21/$BH$23 -> 0.77374036
B36: Other % of Revenues | AU36: =AU22/$BH$23 -> 0.051782938 | AV36: =AV22/$BH$23 -> 0.059133602 | AW36: =AW22/$BH$23 -> 0.05639126 | AX36: =AX22/$BH$23 -> 0.074822173 | AY36: =AY22/$BH$23 -> 0.072611668 | AZ36: =AZ22/$BH$23 -> 0.083910512 | BA36: =BA22/$BH$23 -> 0.081153122 | BB36: =BB22/$BH$23 -> 0.1002517 | ... BJ36: =BJ22/$BH$23 -> 0.14675707 | CD36: =CD22/$BH$23 -> 0.24212997 | CE36: =CE22/$BH$23 -> 0.337927 | CF36: =CF22/$BH$23 -> 0.4429486 | CG36: =CG22/$BH$23 -> 0.51546918
B38: Revenues | C38: 186.8 | D38: 212 | E38: 230.2 | F38: 371.52 | G38: 285.7 | H38: 282.6 | I38: 316.5 | J38: 485.5 | K38: 345.8 | L38: 344.5 | M38: 379.9 | N38: 521 | O38: 384.6 | P38: 390.7 | Q38: 419.4 | R38: 602.5 | S38: 423.5 | T38: 453 | U38: 479.7 | V38: 704.3 | W38: 495.5 | X38: 514.5 | Y38: 544.4 | Z38: 789.9 | AA38: 520.3 | AB38: 581.1 | AC38: 619 | AD38: 928.8 | AE38: 649.7 | AF38: 723.5 | AG38: 747.7 | AH38: 1167.5 | AI38: 782.3 | AJ38: 883.4 | AK38: 916.1 | AL38: 1397.5 | AM38: =AM7 -> 651.958 | AN38: =AN7 -> 902.942 | AO38: =AO7 -> 1117.422 | AP38: =AP7 -> 1729.557 | AQ38: =AQ7 -> 1226.465 | AR38: =AR7 -> 1450.615 | AS38: =AS7 -> 1450.418 | AT38: =AT7 -> 2129.119 | ... BJ38: =BJ7 -> 3640.793 | BS38: =SUM(C38:F38) -> 1000.52 | BT38: =SUM(G38:J38) -> 1370.3 | BU38: =SUM(K38:N38) -> 1591.2 | BV38: =SUM(O38:R38) -> 1797.2 | BW38: =SUM(S38:V38) -> 2060.5 | BX38: =SUM(W38:Z38) -> 2344.3 | BY38: =SUM(AA38:AD38) -> 2649.2 | BZ38: =SUM(AE38:AH38) -> 3288.4 | CA38: =SUM(AI38:AL38) -> 3979.3 | CB38: =SUM(AM38:AP38) -> 4401.879 | CC38: =SUM(AQ38:AT38) -> 6256.617 | CD38: =SUM(AU38:AX38) -> 8110.518 | CE38: =SUM(AY38:BB38) -> 9619.27 | CF38: =SUM(BC38:BF38) -> 10588.126 | CG38: =SUM(BG38:BJ38) -> 11102.58 | CH38: =CH7 -> 11609.528 | CI38: =CI7 -> 12190.815 | CJ38: =CJ7 -> 12841.494 | CK38: =CK7 -> 13558.162 | CL38: =CL7 -> 14243.879 | CM38: =CM7 -> 14947.419 | CN38: =CN7 -> 15634.515 | CO38: =CO7 -> 16299.231 | ... CQ38: =CQ7 -> 17528.18
B39: COGS | C39: 77.1 | D39: 90.3 | E39: 101.7 | F39: 162.47 | G39: 128.4 | H39: 126.9 | I39: 141.2 | J39: 211 | K39: 175.1 | L39: 158.6 | M39: 175.3 | N39: 242.2 | O39: 188.9 | P39: 193.4 | Q39: 208.3 | R39: 292.4 | S39: 217.7 | T39: 241 | U39: 254.9 | V39: 349.8 | W39: 256.4 | X39: 260.4 | Y39: 266 | Z39: 362 | AA39: 263.4 | AB39: 283.6 | AC39: 297.1 | AD39: 406.3 | AE39: 305 | AF39: 327.3 | AG39: 340.9 | AH39: 498.9 | AI39: 360.6 | AJ39: 397.6 | AK39: 411.1 | AL39: 586.7 | AM39: 317.6 | AN39: 413.4 | AO39: 490.1 | AP39: 716.8 | AQ39: 526.2 | AR39: 607.9 | AS39: 621 | AT39: 892.9 | AU39: 743.1 | AV39: 812.9 | AW39: 818 | AX39: 1244.2 | AY39: 850 | AZ39: 910.7 | BA39: 947.6 | BB39: 1301.7 | BC39: 933.8 | BD39: 958.9 | BE39: 995.1 | BF39: 1429.5 | BG39: 987.5 | BH39: 1048 | BI39: 1140 | BJ39: 1642.9 | BS39: =SUM(C39:F39) -> 431.57 | BT39: =SUM(G39:J39) -> 607.5 | BU39: =SUM(K39:N39) -> 751.2 | BV39: =SUM(O39:R39) -> 883 | BW39: =SUM(S39:V39) -> 1063.4 | BX39: =SUM(W39:Z39) -> 1144.8 | BY39: =SUM(AA39:AD39) -> 1250.4 | BZ39: =SUM(AE39:AH39) -> 1472.1 | CA39: =SUM(AI39:AL39) -> 1756 | CB39: =SUM(AM39:AP39) -> 1937.9 | CC39: =SUM(AQ39:AT39) -> 2648 | CD39: =SUM(AU39:AX39) -> 3618.2 | CE39: =SUM(AY39:BB39) -> 4010 | CF39: =SUM(BC39:BF39) -> 4317.3 | CG39: =SUM(BG39:BJ39) -> 4818.4 | CH39: =CH38*(1-CH51) -> 5061.754 | CI39: =CI38*(1-CI51) -> 5266.432 | CJ39: =CJ38*(1-CJ51) -> 5534.684 | CK39: =CK38*(1-CK51) -> 5830.0095 | CL39: =CL38*(1-CL51) -> 6053.6488 | CM39: =CM38*(1-CM51) -> 6277.9162 | CN39: =CN38*(1-CN51) -> 6488.3239 | CO39: =CO38*(1-CO51) -> 6682.6845 | ... CQ39: =CQ38*(1-CQ51) -> 7055.0926
B40: GP | C40: =C38-C39 -> 109.7 | D40: =D38-D39 -> 121.7 | E40: =E38-E39 -> 128.5 | F40: =F38-F39 -> 209.05 | G40: =G38-G39 -> 157.3 | H40: =H38-H39 -> 155.7 | I40: =I38-I39 -> 175.3 | J40: =J38-J39 -> 274.5 | ... BJ40: =BJ38-BJ39 -> 1997.893 | BS40: =SUM(C40:F40) -> 568.95 | BT40: =SUM(G40:J40) -> 762.8 | BU40: =SUM(K40:N40) -> 840 | BV40: =SUM(O40:R40) -> 914.2 | BW40: =SUM(S40:V40) -> 997.1 | BX40: =SUM(W40:Z40) -> 1199.5 | BY40: =SUM(AA40:AD40) -> 1398.8 | BZ40: =SUM(AE40:AH40) -> 1816.3 | CA40: =SUM(AI40:AL40) -> 2223.3 | CB40: =SUM(AM40:AP40) -> 2463.979 | CC40: =SUM(AQ40:AT40) -> 3608.617 | CD40: =SUM(AU40:AX40) -> 4492.318 | CE40: =SUM(AY40:BB40) -> 5609.27 | CF40: =SUM(BC40:BF40) -> 6270.826 | CG40: =SUM(BG40:BJ40) -> 6284.18 | CH40: =CH38-CH39 -> 6547.7736 | CI40: =CI38-CI39 -> 6924.3828 | CJ40: =CJ38-CJ39 -> 7306.8102 | CK40: =CK38-CK39 -> 7728.1522 | CL40: =CL38-CL39 -> 8190.2307 | CM40: =CM38-CM39 -> 8669.5033 | CN40: =CN38-CN39 -> 9146.1915 | CO40: =CO38-CO39 -> 9616.546 | ... CQ40: =CQ38-CQ39 -> 10473.088
B41: SG&A | C41: 58 | D41: 63 | E41: 68.8 | F41: 92.97 | G41: 84.2 | H41: 85.6 | I41: 94.7 | J41: 121.9 | K41: 104.8 | L41: 107 | M41: 112.3 | N41: 124.6 | O41: 125.9 | P41: 129.4 | Q41: 129.9 | R41: 152.9 | S41: 137.8 | T41: 145.4 | U41: 156.6 | V41: 188.2 | W41: 181.5 | X41: 180.2 | Y41: 185.5 | Z41: 231.3 | AA41: 199.1 | AB41: 225.5 | AC41: 215.4 | AD41: 264.2 | AE41: 240.4 | AF41: 262 | AG41: 270.9 | AH41: 337.1 | AI41: 292.9 | AJ41: 317.8 | AK41: 329.2 | AL41: 394.3 | AM41: 299.6 | AN41: 352.9 | AO41: 411.7 | AP41: 544.8 | AQ41: 496.6 | AR41: 541.3 | AS41: 545.1 | AT41: 642 | AU41: 607.9 | AV41: 662.3 | AW41: 684.2 | AX41: 803.1 | AY41: 747.5 | AZ41: 817.4 | BA41: 842.8 | BB41: 989.5 | BC41: 842.4 | BD41: 872 | BE41: 909.8 | BF41: 1138.2 | BG41: 942.9 | BH41: 951.7 | BI41: 988.25 | BJ41: 1183.8 | BS41: =SUM(C41:F41) -> 282.77 | BT41: =SUM(G41:J41) -> 386.4 | BU41: =SUM(K41:N41) -> 448.7 | BV41: =SUM(O41:R41) -> 538.1 | BW41: =SUM(S41:V41) -> 628 | BX41: =SUM(W41:Z41) -> 778.5 | BY41: =SUM(AA41:AD41) -> 904.2 | BZ41: =SUM(AE41:AH41) -> 1110.4 | CA41: =SUM(AI41:AL41) -> 1334.2 | CB41: =SUM(AM41:AP41) -> 1609 | CC41: =SUM(AQ41:AT41) -> 2225 | CD41: =SUM(AU41:AX41) -> 2757.5 | CE41: =SUM(AY41:BB41) -> 3397.2 | CF41: =SUM(BC41:BF41) -> 3762.4 | CG41: =SUM(BG41:BJ41) -> 4066.65 | CH41: =CH38*CH52 -> 4208.4538 | CI41: =CI38*CI52 -> 4388.6934 | CJ41: =CJ38*CJ52 -> 4494.523 | CK41: =CK38*CK52 -> 4474.1934 | CL41: =CL38*CL52 -> 4664.8705 | CM41: =CM38*CM52 -> 4857.9113 | CN41: =CN38*CN52 -> 5042.1312 | CO41: =CO38*CO52 -> 5215.7538 | ... CQ41: =CQ38*CQ52 -> 5609.0178
B42: Amortization of Intangibles | D42: 0 | E42: 0 | F42: 1 | G42: 0 | H42: 0 | I42: 0 | J42: 0 | K42: 0 | L42: 0 | M42: 0 | N42: 0 | O42: 0 | P42: 1 | Q42: 1 | R42: 0 | S42: 0 | T42: 0 | U42: 0 | V42: 0 | W42: 0 | X42: 0 | Y42: 0 | Z42: 0 | AA42: 13 | AB42: 4 | AC42: 22 | AD42: 3 | AE42: 0 | AF42: 0 | AG42: 0 | AH42: 1 | AI42: 0 | AJ42: 0 | AK42: 0 | AL42: 0 | AM42: 3 | AN42: 13 | AO42: 11 | AP42: 10 | AQ42: 11 | AR42: 10 | AS42: 27 | AT42: 3 | AU42: 2 | AV42: -8 | AW42: 1 | AX42: 411 | AY42: 2 | AZ42: 2 | BA42: 76 | BB42: 0 | BC42: 0 | BD42: 0 | BE42: 1 | BF42: 2 | BG42: 2 | BH42: 2 | BI42: 1.776 | BJ42: 2 | BS42: =SUM(C42:F42) -> 1 | BT42: =SUM(G42:J42) -> 0 | BU42: =SUM(K42:N42) -> 0 | BV42: =SUM(O42:R42) -> 2 | BW42: =SUM(S42:V42) -> 0 | BX42: =SUM(W42:Z42) -> 0 | BY42: =SUM(AA42:AD42) -> 42 | BZ42: =SUM(AE42:AH42) -> 1 | CA42: =SUM(AI42:AL42) -> 0 | CB42: =SUM(AM42:AP42) -> 37 | CC42: =SUM(AQ42:AT42) -> 51 | CD42: =SUM(AU42:AX42) -> 406 | CE42: =SUM(AY42:BB42) -> 80 | CF42: =SUM(BC42:BF42) -> 3 | CG42: =SUM(BG42:BJ42) -> 7.776 | CH42: 0 | CI42: 0 | CJ42: 0 | CK42: 0 | CL42: 0 | CM42: 0 | CN42: 0 | CO42: 0 | CP42: 0 | CQ42: 0
B43: OI | C43: =C40-SUM(C41:C42) -> 51.7 | D43: =D40-SUM(D41:D42) -> 58.7 | E43: =E40-SUM(E41:E42) -> 59.7 | F43: =F40-SUM(F41:F42) -> 115.08 | G43: =G40-SUM(G41:G42) -> 73.1 | H43: =H40-SUM(H41:H42) -> 70.1 | I43: =I40-SUM(I41:I42) -> 80.6 | J43: =J40-SUM(J41:J42) -> 152.6 | ... BJ43: =BJ40-SUM(BJ41:BJ42) -> 812.093 | BS43: =SUM(C43:F43) -> 285.18 | BT43: =SUM(G43:J43) -> 376.4 | BU43: =SUM(K43:N43) -> 391.3 | BV43: =SUM(O43:R43) -> 374.1 | BW43: =SUM(S43:V43) -> 369.1 | BX43: =SUM(W43:Z43) -> 421 | BY43: =SUM(AA43:AD43) -> 452.6 | BZ43: =SUM(AE43:AH43) -> 704.9 | CA43: =SUM(AI43:AL43) -> 889.1 | CB43: =SUM(AM43:AP43) -> 817.979 | CC43: =SUM(AQ43:AT43) -> 1332.617 | CD43: =SUM(AU43:AX43) -> 1328.818 | CE43: =SUM(AY43:BB43) -> 2132.07 | CF43: =SUM(BC43:BF43) -> 2505.426 | CG43: =SUM(BG43:BJ43) -> 2209.754 | CH43: =CH40-SUM(CH41:CH42) -> 2339.3198 | CI43: =CI40-SUM(CI41:CI42) -> 2535.6895 | CJ43: =CJ40-SUM(CJ41:CJ42) -> 2812.2872 | CK43: =CK40-SUM(CK41:CK42) -> 3253.9588 | CL43: =CL40-SUM(CL41:CL42) -> 3525.3602 | CM43: =CM40-SUM(CM41:CM42) -> 3811.592 | CN43: =CN40-SUM(CN41:CN42) -> 4104.0603 | CO43: =CO40-SUM(CO41:CO42) -> 4400.7922 | ... CQ43: =CQ40-SUM(CQ41:CQ42) -> 4864.0701
B44: Other Income | C44: 0.9 | D44: 1 | E44: 0.6 | F44: 1.6 | G44: 0.9 | H44: 1.2 | I44: 1.4 | J44: 1.5 | K44: 1.5 | L44: 1.3 | M44: 1.5 | N44: 1.5 | O44: 1.6 | P44: 1.9 | Q44: 1.8 | R44: 1.8 | S44: 0.5 | T44: 0.8 | U44: -2.9 | V44: 0.9 | W44: -0.5 | X44: 0.6 | Y44: 0.6 | Z44: 0.9 | AA44: 0.9 | AB44: 0.8 | AC44: 1.1 | AD44: 1.2 | AE44: 2.9 | AF44: 1.6 | AG44: 2 | AH44: 2.9 | AI44: 2.4 | AJ44: 1.8 | AK44: 1.9 | AL44: 2.1 | AM44: 1.2 | AN44: -0.3 | AO44: -0.6 | AP44: -0.9 | AQ44: 0.2 | AR44: 0.1 | AS44: 0 | AT44: 0.2 | AU44: 0 | AV44: 0.1 | AW44: 0.3 | AX44: 3.7 | AY44: 8 | AZ44: 7.4 | BA44: 9.8 | BB44: 17.8 | BC44: 23.3 | BD44: 18 | BE44: 13.7 | BF44: 15.4 | BG44: 11.8 | BH44: 10 | BI44: 5.854 | BJ44: 1 | BS44: =SUM(C44:F44) -> 4.1 | BT44: =SUM(G44:J44) -> 5 | BU44: =SUM(K44:N44) -> 5.8 | BV44: =SUM(O44:R44) -> 7.1 | BW44: =SUM(S44:V44) -> -0.7 | BX44: =SUM(W44:Z44) -> 1.6 | BY44: =SUM(AA44:AD44) -> 4 | BZ44: =SUM(AE44:AH44) -> 9.4 | CA44: =SUM(AI44:AL44) -> 8.2 | CB44: =SUM(AM44:AP44) -> -0.6 | CC44: =SUM(AQ44:AT44) -> 0.5 | CD44: =SUM(AU44:AX44) -> 4.1 | CE44: =SUM(AY44:BB44) -> 43 | CF44: =SUM(BC44:BF44) -> 70.4 | CG44: =SUM(BG44:BJ44) -> 28.654 | CH44: =CG44*(1+$CQ$60) -> 36.82039 | CI44: =CH44*(1+$CQ$60) -> 47.314201 | CJ44: =CI44*(1+$CQ$60) -> 60.798748 | CK44: =CJ44*(1+$CQ$60) -> 78.126392 | CL44: =CK44*(1+$CQ$60) -> 100.39241 | CM44: =CL44*(1+$CQ$60) -> 129.00425 | CN44: =CM44*(1+$CQ$60) -> 165.77046 | CO44: =CN44*(1+$CQ$60) -> 213.01504 | ... CQ44: =CP44*(1+$CQ$60) -> 351.73577
B45: Pretax Income | C45: =C43+C44 -> 52.6 | D45: =D43+D44 -> 59.7 | E45: =E43+E44 -> 60.3 | F45: =F43+F44 -> 116.68 | G45: =G43+G44 -> 74 | H45: =H43+H44 -> 71.3 | I45: =I43+I44 -> 82 | J45: =J43+J44 -> 154.1 | ... BJ45: =BJ43+BJ44 -> 813.093 | BS45: =SUM(C45:F45) -> 289.28 | BT45: =SUM(G45:J45) -> 381.4 | BU45: =SUM(K45:N45) -> 397.1 | BV45: =SUM(O45:R45) -> 381.2 | BW45: =SUM(S45:V45) -> 368.4 | BX45: =SUM(W45:Z45) -> 422.6 | BY45: =SUM(AA45:AD45) -> 456.6 | BZ45: =SUM(AE45:AH45) -> 714.3 | CA45: =SUM(AI45:AL45) -> 897.3 | CB45: =SUM(AM45:AP45) -> 817.379 | CC45: =SUM(AQ45:AT45) -> 1333.117 | CD45: =SUM(AU45:AX45) -> 1332.918 | CE45: =SUM(AY45:BB45) -> 2175.07 | CF45: =SUM(BC45:BF45) -> 2575.826 | CG45: =SUM(BG45:BJ45) -> 2238.408 | CH45: =CH43+CH44 -> 2376.1402 | CI45: =CI43+CI44 -> 2583.0037 | CJ45: =CJ43+CJ44 -> 2873.086 | CK45: =CK43+CK44 -> 3332.0852 | CL45: =CL43+CL44 -> 3625.7526 | CM45: =CM43+CM44 -> 3940.5962 | CN45: =CN43+CN44 -> 4269.8307 | CO45: =CO43+CO44 -> 4613.8073 | ... CQ45: =CQ43+CQ44 -> 5215.8059
B46: Taxes | C46: 19.1 | D46: 21.46 | E46: 21.4 | F46: 42.55 | G46: 27 | H46: 13.7 | I46: 24.7 | J46: 44.7 | K46: 20.1 | L46: 23.8 | M46: 27.7 | N46: 46 | O46: 52.5 | P46: 21 | Q46: 22.5 | R46: 48.1 | S46: 20.8 | T46: 19.8 | U46: 12.1 | V46: 49.8 | W46: 11.8 | X46: 20.9 | Y46: 25.3 | Z46: 61.4 | AA46: 15.1 | AB46: 20.8 | AC46: 27.7 | AD46: 137.7 | AE46: 32.1 | AF46: 40 | AG46: 43.5 | AH46: 115.8 | AI46: 34.6 | AJ46: 44.8 | AK46: 51.8 | AL46: 120.6 | AM46: 5.3 | AN46: 37.3 | AO46: 60.7 | AP46: 127.2 | AQ46: 49.1 | AR46: 83.1 | AS46: 70.2 | AT46: 156.2 | AU46: 70.3 | AV46: 111.8 | AW46: 97.3 | AX46: 198.3 | AY46: 119 | AZ46: 145 | BA46: 99.2 | BB46: 262.3 | BC46: 134.5 | BD46: 165.3 | BE46: 152.5 | BF46: 309.1 | BG46: 135.8 | BH46: 161 | BI46: 134.905 | BJ46: 226.4 | BS46: =SUM(C46:F46) -> 104.51 | BT46: =SUM(G46:J46) -> 110.1 | BU46: =SUM(K46:N46) -> 117.6 | BV46: =SUM(O46:R46) -> 144.1 | BW46: =SUM(S46:V46) -> 102.5 | BX46: =SUM(W46:Z46) -> 119.4 | BY46: =SUM(AA46:AD46) -> 201.3 | BZ46: =SUM(AE46:AH46) -> 231.4 | CA46: =SUM(AI46:AL46) -> 251.8 | CB46: =SUM(AM46:AP46) -> 230.5 | CC46: =SUM(AQ46:AT46) -> 358.6 | CD46: =SUM(AU46:AX46) -> 477.7 | CE46: =SUM(AY46:BB46) -> 625.5 | CF46: =SUM(BC46:BF46) -> 761.4 | CG46: =SUM(BG46:BJ46) -> 658.105 | CH46: =CH45*CH54 -> 712.84206 | CI46: =CI45*CI54 -> 774.90111 | CJ46: =CJ45*CJ54 -> 861.9258 | CK46: =CK45*CK54 -> 999.62556 | CL46: =CL45*CL54 -> 1087.7258 | CM46: =CM45*CM54 -> 1182.1789 | CN46: =CN45*CN54 -> 1280.9492 | CO46: =CO45*CO54 -> 1384.1422 | ... CQ46: =CQ45*CQ54 -> 1564.7418
...

Sheet Notes | Quant Analysis
CD1: 0
I2: Employee Scope: | AG2: General Notes/Observations
J33: Notes: | K33: [X]
K34: [Y]
K35: [Z] | AG35: Financial Stmts. Notes/Observations
AG36: Revenues:
I37: Institutional Ownership Snapshot Q2'25
J65: Notes: | K65: [X]
K66: [Y]
K67: [Z]
I69: Revenue Breakdown by Segment | AG69: Earnings Scope:
J101: Notes: | K101: [X]
K102: [Y]
K103: [Z]
I105: Q/q Total Revenues, Net Income, FCF | AG105: Balance Sheet Scope:
J134: Notes: | K134: [X]
K135: [Y]
K136: [Z]
I138: Y/y Total Revenues, Net Income, FCF | AG138: [Equity Preformance Compared to Peers]
J167: Notes: | K167: [X] | AG167: Notes: | AH167: Clothing / Consumer Discretionary has really been hammered the last year … LEVI is an outpreformer, but even their management team has ste tampered expectations for future earnings in the coming quarters
K168: [Y] | AH168: [Y]
K169: [Z] | AH169: [Z]
B185: 1256 Trading Days? (From: 9/22/2020 - 9/22/2025)
B186: Close | C186: High | D186: Low | E186: Open | F186: Volume | G186: UTC Date | H186: Change
B187: 169.62 | C187: 170.8998 | D187: 167.5342 | E187: 169.7 | F187: 7885914 | G187: Fri, 19 Sep 2025 00:00:00 GMT | H187: =B187/E187-1 -> -0.00047142015
B188: 169.76 | C188: 170.72 | D188: 166.52 | E188: 169.02 | F188: 7061041 | G188: Thu, 18 Sep 2025 00:00:00 GMT | H188: =B188/E188-1 -> 0.0043781801
B189: 163.48 | C189: 165.69 | D189: 162.22 | E189: 162.34 | F189: 4339919 | G189: Wed, 17 Sep 2025 00:00:00 GMT | H189: =B189/E189-1 -> 0.0070222989
B190: 162.34 | C190: 163.64 | D190: 159.75 | E190: 160 | F190: 5069165 | G190: Tue, 16 Sep 2025 00:00:00 GMT | H190: =B190/E190-1 -> 0.014625
B191: 159.98 | C191: 162.165 | D191: 159.2515 | E191: 160.73 | F191: 5535418 | G191: Mon, 15 Sep 2025 00:00:00 GMT | H191: =B191/E191-1 -> -0.0046662104
B192: 159.865 | C192: 165.93 | D192: 159.75 | E192: 165.26 | F192: 7922053 | G192: Fri, 12 Sep 2025 00:00:00 GMT | H192: =B192/E192-1 -> -0.032645528
B193: 165.78 | C193: 168.59 | D193: 163.34 | E193: 163.955 | F193: 6620102 | G193: Thu, 11 Sep 2025 00:00:00 GMT | H193: =B193/E193-1 -> 0.011131103
B194: 163.9 | C194: 167.3522 | D194: 163.2 | E194: 164.7 | F194: 5737178 | G194: Wed, 10 Sep 2025 00:00:00 GMT | H194: =B194/E194-1 -> -0.0048573163
B195: 165.69 | C195: 169.15 | D195: 164.38 | E195: 167.83 | F195: 8578585 | G195: Tue, 09 Sep 2025 00:00:00 GMT | H195: =B195/E195-1 -> -0.012750998
B196: 168.1 | C196: 169.61 | D196: 162.8 | E196: 167.76 | F196: 13808121 | G196: Mon, 08 Sep 2025 00:00:00 GMT | H196: =B196/E196-1 -> 0.0020267048
B197: 167.8 | C197: 176.1785 | D197: 163.98 | E197: 165.14 | F197: 36663712 | G197: Fri, 05 Sep 2025 00:00:00 GMT | H197: =B197/E197-1 -> 0.016107545
B198: 206.09 | C198: 206.6399 | D198: 197.67 | E198: 200.9 | F198: 11429740 | G198: Thu, 04 Sep 2025 00:00:00 GMT | H198: =B198/E198-1 -> 0.025833748
B199: 198.53 | C199: 203.0099 | D199: 197.6101 | E199: 201.3 | F199: 4023399 | G199: Wed, 03 Sep 2025 00:00:00 GMT | H199: =B199/E199-1 -> -0.013760556
B200: 200.21 | C200: 201.27 | D200: 195.58 | E200: 199.81 | F200: 4359898 | G200: Tue, 02 Sep 2025 00:00:00 GMT | H200: =B200/E200-1 -> 0.0020019018 | K200: Min | L200: =MIN(H187:H1442) -> -0.080917561
B201: 202.2 | C201: 205.8 | D201: 200.71 | E201: 204.62 | F201: 3121633 | G201: Fri, 29 Aug 2025 00:00:00 GMT | H201: =B201/E201-1 -> -0.011826801 | K201: Max | L201: =MAX(H187:H1442) -> 0.12227208
B202: 205.08 | C202: 206.605 | D202: 202.38 | E202: 206.05 | F202: 2778977 | G202: Thu, 28 Aug 2025 00:00:00 GMT | H202: =B202/E202-1 -> -0.0047075952 | K202: Mean μ | L202: =AVERAGE(H187:H1442) -> -0.00046874586
...

Sheet Product Lines

Sheet Management

Sheet Table Formatting
B2: [Bold Title] | G2: [Bold Title]
B3: Line Titles | G3: <-- General
B4: Line Titles | G4: <-- Info
B5: Line Titles | G5: <-- General
B6: Line Titles | G6: <-- Info
B7: Line Titles | G7: <-- General
B8: Line Titles | G8: <-- Info
