Workbook

Sheet Main
B2: NFLX
B3: Price | C3: 91.29 | D3: 2/18/2026
B4: SO | C4: 4222 | D4: Q4'25
B5: MC | C5: =C3*C4 -> 385426.38
B6: Cash | C6: =9033.68+28.67 -> 9062.35 | D6: Q4'25
B7: Debt | C7: =998.86+13463.97 -> 14462.83 | D7: Q4'25
B8: EV | C8: =C5-C6+C7 -> 390826.86
B10: Netflix, Inc. (NFLX)
B12: Founder(s): Reed Hastings & Marc Randolph | G12: Registered Exchange: NASDAQ | N12: Resources:
B13: Founded: 1997 | G13: Address: 121 Albright Way Los Gatos, CA 95032 U.S. | N13: SEC filings | Q13: https://www.sec.gov/edgar/browse/?CIK=1065280&owner=exclude
B14: Headquarters: Los Gatos, CA | G14: Investor Relations Contact: | N14: Company Homepage | Q14: https://www.netflix.com/
B15: Current CEOs: Gregory Peters & Theodore Sarandos | G15: Investors Relation Department | O15: Company IR Page | R15: https://ir.netflix.net/ir-overview/profile/default.aspx
B16: Employees: 16,000 | G16: Phone: | H16: (408) 540-3700 | J16: Email: | K16: ir@netflix.com | N16: Earnings Calls | Q16: https://seekingalpha.com/symbol/NFLX/earnings/transcripts
B17: Industry: Entertainment - Digital Media | N17: Equity Analysis | Q17: https://stockanalysis.com/stocks/nflx/company/
B18: Sector: Communication Services | N18: MacroTrends | Q18: https://www.macrotrends.net/stocks/charts/NFLX/netflix/income-statement
B19: IPO: May 23, 2002 -- $82.5M valuation | N19: ROIC, WACC | Q19: https://www.gurufocus.com/term/wacc/NFLX
B20: Fiscal Year: [January - December] | N20: Godel Terminal | Q20: https://app.godelterminal.com/
A22: Company Overview:
B23: Netflix, Inc. provides entertainment services worldwide
C24: The Company offers television (TV) series, documentaries, feature films, games, and live programming across various genres and languages
C25: The Company also provides members the ability to receive streaming content through a host of internet-connected devices, including TVs, digital video players, TV set-top boxes, and mobile devices
B26: Netflix, Inc. was incorporated in 1997 and is headquartered in Los Gatos, California
A33: Business Segments and Geographical Info:
B34: [Begin researching fundamentals / core business … begin with SEC filings, but expand and use all public resources available]

Sheet Model
B1: [Use for Graphing] | AU1: Q1 2020 | AY1: Q1 2021 | BC1: Q1 2022 | BG1: Q1 2023 | BK1: Q1 2024 | BO1: Q1 2025
B2: Quarterly
B3: Revenues | C3: {="Q"&MOD(_xlfn.SEQUENCE(1,72)-1,4)+1&" "&(2009+INT((_xlfn.SEQUENCE(1,72)-1)/4))} -> Q1 2009 | D3: Q2 2009 | E3: Q3 2009 | F3: Q4 2009 | G3: Q1 2010 | H3: Q2 2010 | I3: Q3 2010 | J3: Q4 2010 | K3: Q1 2011 | L3: Q2 2011 | M3: Q3 2011 | N3: Q4 2011 | O3: Q1 2012 | P3: Q2 2012 | Q3: Q3 2012 | R3: Q4 2012 | S3: Q1 2013 | T3: Q2 2013 | U3: Q3 2013 | V3: Q4 2013 | W3: Q1 2014 | X3: Q2 2014 | Y3: Q3 2014 | Z3: Q4 2014 | AA3: Q1 2015 | AB3: Q2 2015 | AC3: Q3 2015 | AD3: Q4 2015 | AE3: Q1 2016 | AF3: Q2 2016 | AG3: Q3 2016 | AH3: Q4 2016 | AI3: Q1 2017 | AJ3: Q2 2017 | AK3: Q3 2017 | AL3: Q4 2017 | AM3: Q1 2018 | AN3: Q2 2018 | AO3: Q3 2018 | AP3: Q4 2018 | AQ3: Q1 2019 | AR3: Q2 2019 | AS3: Q3 2019 | AT3: Q4 2019 | AU3: Q1 2020 | AV3: Q2 2020 | AW3: Q3 2020 | AX3: Q4 2020 | AY3: Q1 2021 | AZ3: Q2 2021 | BA3: Q3 2021 | BB3: Q4 2021 | BC3: Q1 2022 | BD3: Q2 2022 | BE3: Q3 2022 | BF3: Q4 2022 | BG3: Q1 2023 | BH3: Q2 2023 | BI3: Q3 2023 | BJ3: Q4 2023 | BK3: Q1 2024 | BL3: Q2 2024 | BM3: Q3 2024 | BN3: Q4 2024 | BO3: Q1 2025 | BP3: Q2 2025 | BQ3: Q3 2025 | BR3: Q4 2025 | BS3: Q1 2026 | BT3: Q2 2026 | BU3: Q3 2026 | BV3: Q4 2026 | CA3: 2009 | CB3: =CA3+1 -> 2010 | CC3: =CB3+1 -> 2011 | CD3: =CC3+1 -> 2012 | CE3: =CD3+1 -> 2013 | CF3: =CE3+1 -> 2014 | CG3: =CF3+1 -> 2015 | CH3: =CG3+1 -> 2016 | CI3: =CH3+1 -> 2017 | ... EY3: =EX3+1 -> 2085
B4: U.S. / Canada Revenues | BJ4: =14873.78-SUM(BG4:BI4) -> 14873.78 | BK4: 4224.31 | BL4: 4295.56 | BM4: 4322.47 | BN4: =17359.36-SUM(BK4:BM4) -> 4517.02 | BO4: 4617.09 | BP4: 4929.003 | BQ4: 5071.78 | BR4: =19957.15-SUM(BO4:BQ4) -> 5339.277 | CO4: =SUM(BG4:BJ4) -> 14873.78 | CP4: =SUM(BK4:BN4) -> 17359.36 | CQ4: =SUM(BL4:BO4) -> 17752.14 | CR4: =CQ4*(1+CR10) -> 20237.44 | CS4: =CR4*(1+CS10) -> 22463.558 | CT4: =CS4*(1+CT10) -> 24485.278 | CU4: =CT4*(1+CU10) -> 26444.1 | CV4: =CU4*(1+CV10) -> 28295.187 | CW4: =CV4*(1+CW10) -> 29992.899 | CX4: =CW4*(1+CX10) -> 31492.544 | CY4: =CX4*(1+CY10) -> 32909.708 | ... DA4: =CZ4*(1+DA10) -> 35424.01
B5: Euro, Mid-East, Africa Revenues | BJ5: =10556.48-SUM(BG5:BI5) -> 10556.48 | BK5: 2958.19 | BL5: 3007 | BM5: 3133.46 | BN5: =12387.03-SUM(BK5:BM5) -> 3288.38 | BO5: 3404.67 | BP5: 3538.17 | BQ5: 3699.05 | BR5: =14514.646-SUM(BO5:BQ5) -> 3872.756 | CO5: =SUM(BG5:BJ5) -> 10556.48 | CP5: =SUM(BK5:BN5) -> 12387.03 | CQ5: =SUM(BL5:BO5) -> 12833.51 | CR5: =CQ5*(1+CR11) -> 14245.196 | CS5: =CR5*(1+CS11) -> 15527.264 | CT5: =CS5*(1+CT11) -> 16614.172 | CU5: =CT5*(1+CU11) -> 17611.023 | CV5: =CU5*(1+CV11) -> 18491.574 | CW5: =CV5*(1+CW11) -> 19231.237 | CX5: =CW5*(1+CX11) -> 19904.33 | CY5: =CX5*(1+CY11) -> 20551.221 | ... DA5: =CZ5*(1+DA11) -> 21591.112
B6: LatAm Revenues | BJ6: =4446.46-SUM(BG6:BI6) -> 4446.46 | BK6: 1165 | BL6: 1204.14 | BM6: 1240.89 | BN6: =4839.81-SUM(BK6:BM6) -> 1229.78 | BO6: 1261.93 | BP6: 1306.73 | BQ6: 1370.91 | BR6: =5357.52-SUM(BO6:BQ6) -> 1417.95 | CO6: =SUM(BG6:BJ6) -> 4446.46 | CP6: =SUM(BK6:BN6) -> 4839.81 | CQ6: =SUM(BL6:BO6) -> 4936.74 | CR6: =CQ6*(1+CR12) -> 5726.6184 | CS6: =CR6*(1+CS12) -> 6356.5464 | CT6: =CS6*(1+CT12) -> 6928.6356 | CU6: =CT6*(1+CU12) -> 7482.9265 | CV6: =CU6*(1+CV12) -> 8006.7313 | CW6: =CV6*(1+CW12) -> 8487.1352 | CX6: =CW6*(1+CX12) -> 8911.4919 | CY6: =CX6*(1+CY12) -> 9312.5091 | ... DA6: =CZ6*(1+DA12) -> 10023.985
B7: APac Revenues | BJ7: =3763.72-SUM(BG7:BI7) -> 3763.72 | BK7: 1022.92 | BL7: 1051.833 | BM7: 1127.86 | BN7: =4414.74-SUM(BK7:BM7) -> 1212.127 | BO7: 1259.09 | BP7: 1305.25 | BQ7: 1368.56 | BR7: =5353.717-SUM(BO7:BQ7) -> 1420.817 | CO7: =SUM(BG7:BJ7) -> 3763.72 | CP7: =SUM(BK7:BN7) -> 4414.74 | CQ7: =SUM(BL7:BO7) -> 4650.91 | CR7: =CQ7*(1+CR13) -> 5627.6011 | CS7: =CR7*(1+CS13) -> 6640.5693 | CT7: =CS7*(1+CT13) -> 7636.6547 | CU7: =CT7*(1+CU13) -> 8629.4198 | CV7: =CU7*(1+CV13) -> 9578.656 | CW7: =CV7*(1+CW13) -> 10440.735 | CX7: =CW7*(1+CX13) -> 11171.586 | CY7: =CX7*(1+CY13) -> 11841.882 | ... DA7: =CZ7*(1+DA13) -> 12931.335
B8: Ttl Revenues | BJ8: =SUM(BJ4:BJ7) -> 33640.44 | BK8: =SUM(BK4:BK7) -> 9370.42 | BL8: =SUM(BL4:BL7) -> 9558.533 | BM8: =SUM(BM4:BM7) -> 9824.68 | BN8: =SUM(BN4:BN7) -> 10247.307 | BO8: =SUM(BO4:BO7) -> 10542.78 | BP8: =SUM(BP4:BP7) -> 11079.153 | BQ8: =SUM(BQ4:BQ7) -> 11510.3 | BR8: =SUM(BR4:BR7) -> 12050.8 | CO8: =SUM(BG8:BJ8) -> 33640.44 | CP8: =SUM(BK8:BN8) -> 39000.94 | CQ8: =SUM(BL8:BO8) -> 40173.3 | CR8: =SUM(CR4:CR7) -> 45836.855 | CS8: =SUM(CS4:CS7) -> 50987.937 | CT8: =SUM(CT4:CT7) -> 55664.741 | CU8: =SUM(CU4:CU7) -> 60167.469 | CV8: =SUM(CV4:CV7) -> 64372.148 | CW8: =SUM(CW4:CW7) -> 68152.006 | CX8: =SUM(CX4:CX7) -> 71479.952 | CY8: =SUM(CY4:CY7) -> 74615.319 | ... DA8: =SUM(DA4:DA7) -> 79970.442
B10: U.S. / Canada Revenues Revenue Growth Y/y | BN10: =BN4/BJ4-1 -> -0.69630988 | BO10: =BO4/BK4-1 -> 0.092980866 | BP10: =BP4/BL4-1 -> 0.14746459 | BQ10: =BQ4/BM4-1 -> 0.17335227 | BR10: =BR4/BN4-1 -> 0.18203528 | CP10: =CP4/CO4-1 -> 0.16711152 | CQ10: =CQ4/CP4-1 -> 0.02262641 | CR10: 0.14 | CS10: 0.11 | CT10: 0.09 | CU10: 0.08 | CV10: 0.07 | CW10: 0.06 | CX10: 0.05 | CY10: 0.045 | CZ10: 0.04 | DA10: 0.035
B11: Euro, Mid-East, Africa Revenue Growth Y/y | BN11: =BN5/BJ5-1 -> -0.68849654 | BO11: =BO5/BK5-1 -> 0.15093013 | BP11: =BP5/BL5-1 -> 0.1766445 | BQ11: =BQ5/BM5-1 -> 0.18050015 | BR11: =BR5/BN5-1 -> 0.17770939 | CP11: =CP5/CO5-1 -> 0.17340534 | CQ11: =CQ5/CP5-1 -> 0.036044153 | CR11: 0.11 | CS11: 0.09 | CT11: 0.07 | CU11: 0.06 | CV11: 0.05 | CW11: 0.04 | CX11: 0.035 | CY11: 0.0325 | CZ11: 0.03 | DA11: 0.02
B12: LatAm Revenue Growth Y/y | BN12: =BN6/BJ6-1 -> -0.72342493 | BO12: =BO6/BK6-1 -> 0.083201717 | BP12: =BP6/BL6-1 -> 0.085197734 | BQ12: =BQ6/BM6-1 -> 0.10477963 | BR12: =BR6/BN6-1 -> 0.15301111 | CP12: =CP6/CO6-1 -> 0.088463632 | CQ12: =CQ6/CP6-1 -> 0.020027646 | CR12: 0.16 | CS12: 0.11 | CT12: 0.09 | CU12: 0.08 | CV12: 0.07 | CW12: 0.06 | CX12: 0.05 | CY12: 0.045 | CZ12: 0.04 | DA12: 0.035
B13: APac Revenue Growth Y/y | BN13: =BN7/BJ7-1 -> -0.67794443 | BO13: =BO7/BK7-1 -> 0.23087827 | BP13: =BP7/BL7-1 -> 0.24092893 | BQ13: =BQ7/BM7-1 -> 0.21341301 | BR13: =BR7/BN7-1 -> 0.17216843 | CP13: =CP7/CO7-1 -> 0.17297248 | CQ13: =CQ7/CP7-1 -> 0.053495789 | CR13: 0.21 | CS13: 0.18 | CT13: 0.15 | CU13: 0.13 | CV13: 0.11 | CW13: 0.09 | CX13: 0.07 | CY13: 0.06 | CZ13: 0.05 | DA13: 0.04
B14: Ttl Revenue Growth Y/y | BN14: =BN8/BJ8-1 -> -0.69538725 | BO14: =BO8/BK8-1 -> 0.12511286 | BP14: =BP8/BL8-1 -> 0.15908508 | BQ14: =BQ8/BM8-1 -> 0.17156996 | BR14: =BR8/BN8-1 -> 0.17599678 | CP14: =CP8/CO8-1 -> 0.15934691 | CQ14: =CQ8/CP8-1 -> 0.030059788 | CR14: =CR8/CQ8-1 -> 0.14097809 | CS14: =CS8/CR8-1 -> 0.11237861 | CT14: =CT8/CS8-1 -> 0.091723719 | CU14: =CU8/CT8-1 -> 0.080890138 | CV14: =CV8/CU8-1 -> 0.069882932 | CW14: =CW8/CV8-1 -> 0.058718828 | ... DA14: =DA8/CZ8-1 -> 0.031705752
B16: U.S. / Canada % of Ttl Revenues | BJ16: =BJ4/BJ8 -> 0.44213988 | BK16: =BK4/BK8 -> 0.4508133 | BL16: =BL4/BL8 -> 0.44939532 | BM16: =BM4/BM8 -> 0.43996039 | BN16: =BN4/BN8 -> 0.44080069 | BO16: =BO4/BO8 -> 0.43793857 | BP16: =BP4/BP8 -> 0.44488988 | BQ16: =BQ4/BQ8 -> 0.4406297 | BR16: =BR4/BR8 -> 0.44306411 | CO16: =CO4/CO8 -> 0.44213988 | CP16: =CP4/CP8 -> 0.44510107 | CQ16: =CQ4/CQ8 -> 0.44188902
B17: Euro, Mid-East, Africa % of Ttl Revenues | BJ17: =BJ5/BJ8 -> 0.31380327 | BK17: =BK5/BK8 -> 0.31569449 | BL17: =BL5/BL8 -> 0.31458802 | BM17: =BM5/BM8 -> 0.31893761 | BN17: =BN5/BN8 -> 0.32090187 | BO17: =BO5/BO8 -> 0.32293854 | BP17: =BP5/BP8 -> 0.31935384 | BQ17: =BQ5/BQ8 -> 0.32136869 | BR17: =BR5/BR8 -> 0.3213692 | CO17: =CO5/CO8 -> 0.31380327 | CP17: =CP5/CP8 -> 0.3176085 | CQ17: =CQ5/CQ8 -> 0.31945372
B18: LatAm % of Ttl Revenues | BJ18: =BJ6/BJ8 -> 0.13217604 | BK18: =BK6/BK8 -> 0.1243274 | BL18: =BL6/BL8 -> 0.1259754 | BM18: =BM6/BM8 -> 0.12630335 | BN18: =BN6/BN8 -> 0.12001007 | BO18: =BO6/BO8 -> 0.11969613 | BP18: =BP6/BP8 -> 0.11794494 | BQ18: =BQ6/BQ8 -> 0.11910289 | BR18: =BR6/BR8 -> 0.11766439 | CO18: =CO6/CO8 -> 0.13217604 | CP18: =CP6/CP8 -> 0.1240947 | CQ18: =CQ6/CQ8 -> 0.1228861
B19: APac % of Ttl Revenues | BJ19: =BJ7/BJ8 -> 0.11188082 | BK19: =BK7/BK8 -> 0.1091648 | BL19: =BL7/BL8 -> 0.11004126 | BM19: =BM7/BM8 -> 0.11479865 | BN19: =BN7/BN8 -> 0.11828737 | BO19: =BO7/BO8 -> 0.11942675 | BP19: =BP7/BP8 -> 0.11781135 | BQ19: =BQ7/BQ8 -> 0.11889873 | BR19: =BR7/BR8 -> 0.1179023 | CO19: =CO7/CO8 -> 0.11188082 | CP19: =CP7/CP8 -> 0.11319573 | CQ19: =CQ7/CQ8 -> 0.11577117
B21: Revenues | C21: 394.1 | D21: 408.5 | E21: 423.1 | F21: 936.9 | G21: 493.7 | H21: 519.8 | I21: 553.2 | J21: 1637.9 | K21: 718.6 | L21: 788.6 | M21: 821.8 | N21: 875.6 | O21: 869.8 | P21: 889.2 | Q21: 905.1 | R21: 945.2 | S21: 1024 | T21: 1069.4 | U21: 1106 | V21: 1175.2 | W21: 1270.1 | X21: 1340.4 | Y21: 1409.4 | Z21: 1484.7 | AA21: 1573.1 | AB21: 1644.7 | AC21: 1738.4 | AD21: 1823.3 | AE21: 1957.7 | AF21: 2105.2 | AG21: 2290.2 | AH21: 2477.5 | AI21: 2636.6 | AJ21: 2785.5 | AK21: 2984.9 | AL21: 3285.8 | AM21: 3700.9 | AN21: 3907.3 | AO21: 3999.4 | AP21: 4186.8 | AQ21: 4521 | AR21: 4923.1 | AS21: 5244.9 | AT21: 5467.4 | AU21: 5767.7 | AV21: 6148.3 | AW21: 6435.6 | AX21: 6644.4 | AY21: 7163.3 | AZ21: 7341.8 | BA21: 7483.5 | BB21: 7709.3 | BC21: 7867.8 | BD21: 7970.1 | BE21: 7925.6 | BF21: 7852.1 | BG21: 8161.5 | BH21: 8187.3 | BI21: 8541.7 | BJ21: 8832.8 | BK21: 9370.4 | BL21: 9559.3 | BM21: 9824.7 | BN21: 10246.5 | BO21: 10542.8 | BP21: 11079.2 | BQ21: 11510.3 | BR21: 12050.8 | CA21: =SUM(C21:F21) -> 2162.6 | CB21: =SUM(G21:J21) -> 3204.6 | CC21: =SUM(K21:N21) -> 3204.6 | CD21: =SUM(O21:R21) -> 3609.3 | CE21: =SUM(S21:V21) -> 4374.6 | CF21: =SUM(W21:Z21) -> 5504.6 | CG21: =SUM(AA21:AD21) -> 6779.5 | CH21: =SUM(AE21:AH21) -> 8830.6 | CI21: =SUM(AI21:AL21) -> 11692.8 | CJ21: =SUM(AM21:AP21) -> 15794.4 | CK21: =SUM(AQ21:AT21) -> 20156.4 | CL21: =SUM(AU21:AX21) -> 24996 | CM21: =SUM(AY21:BB21) -> 29697.9 | CN21: =SUM(BC21:BF21) -> 31615.6 | CO21: =SUM(BG21:BJ21) -> 33723.3 | CP21: =SUM(BK21:BN21) -> 39000.9 | CQ21: =SUM(BO21:BR21) -> 45183.1 | CR21: =CR8 -> 45836.855 | CS21: =CS8 -> 50987.937 | CT21: =CT8 -> 55664.741 | CU21: =CU8 -> 60167.469 | CV21: =CV8 -> 64372.148 | CW21: =CW8 -> 68152.006 | CX21: =CX8 -> 71479.952 | CY21: =CY8 -> 74615.319 | ... DA21: =DA8 -> 79970.442
B22: COGS | C22: 259.3 | D22: 269.2 | E22: 275.3 | F22: 553.6 | G22: 307.2 | H22: 314.9 | I22: 344.5 | J22: 1073.3 | K22: 438.2 | L22: 490 | M22: 536.6 | N22: 575.2 | O22: 623.9 | P22: 643.4 | Q22: 662.6 | R22: 722.1 | S22: 737 | T22: 760.7 | U22: 798.9 | V22: 820.7 | W22: 869.2 | X22: 914.8 | Y22: 954.4 | Z22: 1014.3 | AA22: 1046.4 | AB22: 1121.8 | AC22: 1174 | AD22: 1249.4 | AE22: 1369.5 | AF22: 1473.1 | AG22: 1532.8 | AH22: 1882 | AI22: 1657 | AJ22: 1902.3 | AK22: 1993 | AL22: 2480.7 | AM22: 2300.6 | AN22: 2402.4 | AO22: 2531.1 | AP22: 2733.4 | AQ22: 2870.6 | AR22: 3005.7 | AS22: 3097.9 | AT22: 3466 | AU22: 3599.7 | AV22: 3643.7 | AW22: 3867.8 | AX22: 4165.2 | AY22: 3868.5 | AZ22: 4018 | BA22: 4206.6 | BB22: 5239.6 | BC22: 4284.7 | BD22: 4690.8 | BE22: 4788.7 | BF22: 5404.2 | BG22: 4803.6 | BH22: 4673.5 | BI22: 4930.8 | BJ22: 5307.5 | BK22: 4977.1 | BL22: 5174.1 | BM22: 5119.9 | BN22: 5767.4 | BO22: 5263.1 | BP22: 5325.3 | BQ22: 6164.2 | BR22: 6522.6 | CA22: =SUM(C22:F22) -> 1357.4 | CB22: =SUM(G22:J22) -> 2039.9 | CC22: =SUM(K22:N22) -> 2040 | CD22: =SUM(O22:R22) -> 2652 | CE22: =SUM(S22:V22) -> 3117.3 | CF22: =SUM(W22:Z22) -> 3752.7 | CG22: =SUM(AA22:AD22) -> 4591.6 | CH22: =SUM(AE22:AH22) -> 6257.4 | CI22: =SUM(AI22:AL22) -> 8033 | CJ22: =SUM(AM22:AP22) -> 9967.5 | CK22: =SUM(AQ22:AT22) -> 12440.2 | CL22: =SUM(AU22:AX22) -> 15276.4 | CM22: =SUM(AY22:BB22) -> 17332.7 | CN22: =SUM(BC22:BF22) -> 19168.4 | CO22: =SUM(BG22:BJ22) -> 19715.4 | CP22: =SUM(BK22:BN22) -> 21038.5 | CQ22: =SUM(BO22:BR22) -> 23275.2 | CR22: =CR21*(1-CR37) -> 24330.787 | CS22: =CS21*(1-CS37) -> 27065.047 | CT22: =CT21*(1-CT37) -> 29547.554 | CU22: =CU21*(1-CU37) -> 31937.66 | CV22: =CV21*(1-CV37) -> 34169.557 | CW22: =CW21*(1-CW37) -> 36175.954 | CX22: =CX21*(1-CX37) -> 37942.47 | CY22: =CY21*(1-CY37) -> 39606.763 | ... DA22: =DA21*(1-DA37) -> 42449.33
B23: GP | C23: =C21-C22 -> 134.8 | D23: =D21-D22 -> 139.3 | E23: =E21-E22 -> 147.8 | F23: =F21-F22 -> 383.3 | G23: =G21-G22 -> 186.5 | H23: =H21-H22 -> 204.9 | I23: =I21-I22 -> 208.7 | J23: =J21-J22 -> 564.6 | ... BR23: =BR21-BR22 -> 5528.2 | CA23: =SUM(C23:F23) -> 805.2 | CB23: =SUM(G23:J23) -> 1164.7 | CC23: =SUM(K23:N23) -> 1164.6 | CD23: =SUM(O23:R23) -> 957.3 | CE23: =SUM(S23:V23) -> 1257.3 | CF23: =SUM(W23:Z23) -> 1751.9 | CG23: =SUM(AA23:AD23) -> 2187.9 | CH23: =SUM(AE23:AH23) -> 2573.2 | CI23: =SUM(AI23:AL23) -> 3659.8 | CJ23: =SUM(AM23:AP23) -> 5826.9 | CK23: =SUM(AQ23:AT23) -> 7716.2 | CL23: =SUM(AU23:AX23) -> 9719.6 | CM23: =SUM(AY23:BB23) -> 12365.2 | CN23: =SUM(BC23:BF23) -> 12447.2 | CO23: =SUM(BG23:BJ23) -> 14007.9 | CP23: =SUM(BK23:BN23) -> 17962.4 | CQ23: =SUM(BO23:BR23) -> 21907.9 | CR23: =CR21*CR37 -> 21506.068 | CS23: =CS21*CS37 -> 23922.89 | CT23: =CT21*CT37 -> 26117.186 | CU23: =CU21*CU37 -> 28229.809 | CV23: =CV21*CV37 -> 30202.591 | CW23: =CW21*CW37 -> 31976.052 | CX23: =CX21*CX37 -> 33537.482 | CY23: =CY21*CY37 -> 35008.556 | ... DA23: =DA21*DA37 -> 37521.111
B24: Sales & Marketing | C24: 61.2 | D24: 46.1 | E24: 57 | F24: 129.6 | G24: 75.3 | H24: 74.5 | I24: 81.2 | J24: 171.7 | K24: 104.3 | L24: 94.9 | M24: 89.1 | N24: 92.9 | O24: 129.9 | P24: 114 | Q24: 108.5 | R24: 82.1 | S24: 119.1 | T24: 114.7 | U24: 108.3 | V24: 128.1 | W24: 137.1 | X24: 120.8 | Y24: 145.6 | Z24: 203.7 | AA24: 194.7 | AB24: 197.1 | AC24: 208.1 | AD24: 224.2 | AE24: 208 | AF24: 216 | AG24: 282 | AH24: 391.4 | AI24: 271.3 | AJ24: 274.3 | AK24: 312.6 | AL24: 578.2 | AM24: 536.8 | AN24: 592 | AO24: 510.4 | AP24: 730.4 | AQ24: 616.5 | AR24: 603.1 | AS24: 553.7 | AT24: 878.9 | AU24: 503.8 | AV24: 434.5 | AW24: 527.6 | AX24: 762.6 | AY24: 512.5 | AZ24: 604 | BA24: 635.9 | BB24: 792.7 | BC24: 556 | BD24: 575 | BE24: 568 | BF24: 831.6 | BG24: 555.4 | BH24: 627.1 | BI24: 558.7 | BJ24: 916.6 | BK24: 654.3 | BL24: 644 | BM24: 642.8 | BN24: 976.2 | BO24: 688.4 | BP24: 713.3 | BQ24: 786.3 | BR24: 1113.4 | CA24: =SUM(C24:F24) -> 293.9 | CB24: =SUM(G24:J24) -> 402.7 | CC24: =SUM(K24:N24) -> 381.2 | CD24: =SUM(O24:R24) -> 434.5 | CE24: =SUM(S24:V24) -> 470.2 | CF24: =SUM(W24:Z24) -> 607.2 | CG24: =SUM(AA24:AD24) -> 824.1 | CH24: =SUM(AE24:AH24) -> 1097.4 | CI24: =SUM(AI24:AL24) -> 1436.4 | CJ24: =SUM(AM24:AP24) -> 2369.6 | CK24: =SUM(AQ24:AT24) -> 2652.2 | CL24: =SUM(AU24:AX24) -> 2228.5 | CM24: =SUM(AY24:BB24) -> 2545.1 | CN24: =SUM(BC24:BF24) -> 2530.6 | CO24: =SUM(BG24:BJ24) -> 2657.8 | CP24: =SUM(BK24:BN24) -> 2917.3 | CQ24: =SUM(BO24:BR24) -> 3301.4 | CR24: =CR21*CR38 -> 3437.7641 | CS24: =CS21*CS38 -> 3798.6013 | CT24: =CT21*CT38 -> 4119.1908 | CU24: =CU21*CU38 -> 2617.2849 | CV24: =CV21*CV38 -> 4699.1668 | CW24: =CW21*CW38 -> 4941.0204 | CX24: =CX21*CX38 -> 5146.5565 | CY24: =CY21*CY38 -> 5334.9953 | ... DA24: =DA21*DA38 -> 5597.9309
B25: General & Admin | C25: 13 | D25: 13.3 | E25: 11.5 | F25: 26.7 | G25: 15.5 | H25: 15.1 | I25: 15.9 | J25: 80.3 | K25: 23 | L25: 30.7 | M25: 29.8 | N25: 64.8 | O25: 35.1 | P25: 34.1 | Q25: 35.3 | R25: 39.3 | S25: 44.1 | T25: 43.8 | U25: 46.2 | V25: 46.1 | W25: 55.9 | X25: 60 | Y25: 78 | Z25: 75.8 | AA25: 91.5 | AB25: 95.9 | AC25: 110.9 | AD25: 109 | AE25: 127.2 | AF25: 138.4 | AG25: 153.2 | AH25: -103.1 | AI25: 194.3 | AJ25: 213.9 | AK25: 215.5 | AL25: -192.7 | AM25: 134.6 | AN25: 151.5 | AO25: 168.6 | AP25: 175.5 | AQ25: 202 | AR25: 224.7 | AS25: 233.2 | AT25: 254.6 | AU25: 252.1 | AV25: 277.2 | AW25: 271.6 | AX25: 275.5 | AY25: 297.2 | AZ25: 334.8 | BA25: 321.8 | BB25: 397.8 | BC25: 397.9 | BD25: 409.3 | BE25: 373.2 | BF25: 392.5 | BG25: 400.9 | BH25: 401.5 | BI25: 478.6 | BJ25: 439.3 | BK25: 404 | BL25: 427 | BM25: 417.4 | BN25: 453.7 | BO25: 421.5 | BP25: 441.2 | BQ25: 457.9 | BR25: 567.8 | CA25: =SUM(C25:F25) -> 64.5 | CB25: =SUM(G25:J25) -> 126.8 | CC25: =SUM(K25:N25) -> 148.3 | CD25: =SUM(O25:R25) -> 143.8 | CE25: =SUM(S25:V25) -> 180.2 | CF25: =SUM(W25:Z25) -> 269.7 | CG25: =SUM(AA25:AD25) -> 407.3 | CH25: =SUM(AE25:AH25) -> 315.7 | CI25: =SUM(AI25:AL25) -> 431 | CJ25: =SUM(AM25:AP25) -> 630.2 | CK25: =SUM(AQ25:AT25) -> 914.5 | CL25: =SUM(AU25:AX25) -> 1076.4 | CM25: =SUM(AY25:BB25) -> 1351.6 | CN25: =SUM(BC25:BF25) -> 1572.9 | CO25: =SUM(BG25:BJ25) -> 1720.3 | CP25: =SUM(BK25:BN25) -> 1702.1 | CQ25: =SUM(BO25:BR25) -> 1888.4 | CR25: =CR22*CR39 -> 1041.4684 | CS25: =CS22*CS39 -> 1150.2645 | CT25: =CT22*CT39 -> 1248.3842 | CU25: =CU22*CU39 -> 1341.3817 | CV25: =CV22*CV39 -> 1418.0366 | CW25: =CW22*CW39 -> 1483.2141 | CX25: =CX22*CX39 -> 1536.67 | CY25: =CY22*CY39 -> 1594.1722 | ... DA25: =DA22*DA39 -> 1697.9732
B26: R&D | C26: 24.2 | D26: 27.1 | E26: 30 | F26: 82 | G26: 37.4 | H26: 37.9 | I26: 42.1 | J26: 141.7 | K26: 50.9 | L26: 57.9 | M26: 69.5 | N26: 80.8 | O26: 82.8 | P26: 81.5 | Q26: 82.5 | R26: 82.1 | S26: 92 | T26: 93.1 | U26: 95.5 | V26: 98.1 | W26: 110.3 | X26: 115.2 | Y26: 121 | Z26: 125.9 | AA26: 143.1 | AB26: 155.1 | AC26: 171.8 | AD26: 180.9 | AE26: 203.5 | AF26: 207.3 | AG26: 216.1 | AH26: 153.3 | AI26: 257.1 | AJ26: 267.1 | AK26: 255.2 | AL26: 174.3 | AM26: 282.3 | AN26: 299.1 | AO26: 308.6 | AP26: 331.8 | AQ26: 372.8 | AR26: 383.2 | AS26: 379.8 | AT26: 409.4 | AU26: 453.8 | AV26: 435 | AW26: 453.8 | AX26: 486.9 | AY26: 525.2 | AZ26: 537.3 | BA26: 563.9 | BB26: 647.5 | BC26: 657.5 | BD26: 716.8 | BE26: 662.7 | BF26: 673.9 | BG26: 687.3 | BH26: 658 | BI26: 657.2 | BJ26: 673.3 | BK26: 702.5 | BL26: 711.3 | BM26: 735.1 | BN26: 776.5 | BO26: 822.8 | BP26: 824.7 | BQ26: 853.6 | BR26: 890.3 | CA26: =SUM(C26:F26) -> 163.3 | CB26: =SUM(G26:J26) -> 259.1 | CC26: =SUM(K26:N26) -> 259.1 | CD26: =SUM(O26:R26) -> 328.9 | CE26: =SUM(S26:V26) -> 378.7 | CF26: =SUM(W26:Z26) -> 472.4 | CG26: =SUM(AA26:AD26) -> 650.9 | CH26: =SUM(AE26:AH26) -> 780.2 | CI26: =SUM(AI26:AL26) -> 953.7 | CJ26: =SUM(AM26:AP26) -> 1221.8 | CK26: =SUM(AQ26:AT26) -> 1545.2 | CL26: =SUM(AU26:AX26) -> 1829.5 | CM26: =SUM(AY26:BB26) -> 2273.9 | CN26: =SUM(BC26:BF26) -> 2710.9 | CO26: =SUM(BG26:BJ26) -> 2675.8 | CP26: =SUM(BK26:BN26) -> 2925.4 | CQ26: =SUM(BO26:BR26) -> 3391.4 | CR26: =CR23*CR40 -> 1591.449 | CS26: =CS23*CS40 -> 1746.371 | CT26: =CT23*CT40 -> 1880.4374 | CU26: =CU23*CU40 -> 2004.3165 | CV26: =CV23*CV40 -> 2114.1814 | CW26: =CW23*CW40 -> 2238.3236 | CX26: =CX23*CX40 -> 2347.6237 | CY26: =CY23*CY40 -> 2450.5989 | ... DA26: =DA23*DA40 -> 2626.4778
B27: Ttl Operating Expenses | C27: =SUM(C24:C26) -> 98.4 | D27: =SUM(D24:D26) -> 86.5 | E27: =SUM(E24:E26) -> 98.5 | F27: =SUM(F24:F26) -> 238.3 | G27: =SUM(G24:G26) -> 128.2 | H27: =SUM(H24:H26) -> 127.5 | I27: =SUM(I24:I26) -> 139.2 | J27: =SUM(J24:J26) -> 393.7 | ... BR27: =SUM(BR24:BR26) -> 2571.5 | CA27: =SUM(C27:F27) -> 521.7 | CB27: =SUM(G27:J27) -> 788.6 | CC27: =SUM(K27:N27) -> 788.6 | CD27: =SUM(O27:R27) -> 907.2 | CE27: =SUM(S27:V27) -> 1029.1 | CF27: =SUM(W27:Z27) -> 1349.3 | CG27: =SUM(AA27:AD27) -> 1882.3 | CH27: =SUM(AE27:AH27) -> 2193.3 | CI27: =SUM(AI27:AL27) -> 2821.1 | CJ27: =SUM(AM27:AP27) -> 4221.6 | CK27: =SUM(AQ27:AT27) -> 5111.9 | CL27: =SUM(AU27:AX27) -> 5134.4 | CM27: =SUM(AY27:BB27) -> 6170.6 | CN27: =SUM(BC27:BF27) -> 6814.4 | CO27: =SUM(BG27:BJ27) -> 7053.9 | CP27: =SUM(BK27:BN27) -> 7544.8 | CQ27: =SUM(BO27:BR27) -> 8581.2 | CR27: =SUM(CR24:CR26) -> 6070.6815 | CS27: =SUM(CS24:CS26) -> 6695.2368 | CT27: =SUM(CT24:CT26) -> 7248.0124 | CU27: =SUM(CU24:CU26) -> 5962.9831 | CV27: =SUM(CV24:CV26) -> 8231.3848 | CW27: =SUM(CW24:CW26) -> 8662.5581 | CX27: =SUM(CX24:CX26) -> 9030.8503 | CY27: =SUM(CY24:CY26) -> 9379.7665 | ... DA27: =SUM(DA24:DA26) -> 9922.3819
B28: Operating Income | C28: =C23-C27 -> 36.4 | D28: =D23-D27 -> 52.8 | E28: =E23-E27 -> 49.3 | F28: =F23-F27 -> 145 | G28: =G23-G27 -> 58.3 | H28: =H23-H27 -> 77.4 | I28: =I23-I27 -> 69.5 | J28: =J23-J27 -> 170.9 | ... BR28: =BR23-BR27 -> 2956.7 | CA28: =SUM(C28:F28) -> 283.5 | CB28: =SUM(G28:J28) -> 376.1 | CC28: =SUM(K28:N28) -> 376 | CD28: =SUM(O28:R28) -> 50.1 | CE28: =SUM(S28:V28) -> 228.2 | CF28: =SUM(W28:Z28) -> 402.6 | CG28: =SUM(AA28:AD28) -> 305.6 | CH28: =SUM(AE28:AH28) -> 379.9 | CI28: =SUM(AI28:AL28) -> 838.7 | CJ28: =SUM(AM28:AP28) -> 1605.3 | CK28: =SUM(AQ28:AT28) -> 2604.3 | CL28: =SUM(AU28:AX28) -> 4585.2 | CM28: =SUM(AY28:BB28) -> 6194.6 | CN28: =SUM(BC28:BF28) -> 5632.8 | CO28: =SUM(BG28:BJ28) -> 6954 | CP28: =SUM(BK28:BN28) -> 10417.6 | CQ28: =SUM(BO28:BR28) -> 13326.7 | CR28: =CR23-CR27 -> 15435.386 | CS28: =CS23-CS27 -> 17227.653 | CT28: =CT23-CT27 -> 18869.174 | CU28: =CU23-CU27 -> 22266.826 | CV28: =CV23-CV27 -> 21971.206 | CW28: =CW23-CW27 -> 23313.494 | CX28: =CX23-CX27 -> 24506.632 | CY28: =CY23-CY27 -> 25628.79 | ... DA28: =DA23-DA27 -> 27598.729
B29: Interest Expenses | C29: 0.9 | D29: 0.2 | E29: 1.1 | F29: -18.2 | G29: -4 | H29: -4 | I29: -4.1 | J29: -4.5 | K29: -4 | L29: -4.3 | M29: -3.2 | N29: -5 | O29: -5.1 | P29: -5.5 | Q29: -4.2 | R29: -4.7 | S29: -30.9 | T29: -10.5 | U29: -7.6 | V29: -8.3 | W29: -8.7 | X29: -12.2 | Y29: -12.9 | Z29: -19.5 | AA29: -59 | AB29: -34.3 | AC29: -31.4 | AD29: -39.2 | AE29: -9.6 | AF29: -19.1 | AG29: -26.9 | AH29: -63.7 | AI29: -33.2 | AJ29: -113.8 | AK29: -92.4 | AL29: -114 | AM29: -147 | AN29: -33.6 | AO29: -101.9 | AP29: -96.4 | AQ29: -59.4 | AR29: -205.5 | AS29: 32.1 | AT29: -309.2 | AU29: -162.4 | AV29: -322.3 | AW29: -453.4 | AX29: -447.8 | AY29: 74.6 | AZ29: -253.8 | BA29: -94.3 | BB29: -80.9 | BC29: 8.1 | BD29: 44.8 | BE29: 88.8 | BF29: -510.6 | BG29: -245.4 | BH29: -147.9 | BI29: -7.3 | BJ29: -348 | BK29: -18 | BL29: -89 | BM29: -206.5 | BN29: -138.5 | BO29: -133.3 | BP29: -143 | BQ29: -138.8 | BR29: -188.9 | CA29: =SUM(C29:F29) -> -16 | CB29: =SUM(G29:J29) -> -16.6 | CC29: =SUM(K29:N29) -> -16.5 | CD29: =SUM(O29:R29) -> -19.5 | CE29: =SUM(S29:V29) -> -57.3 | CF29: =SUM(W29:Z29) -> -53.3 | CG29: =SUM(AA29:AD29) -> -163.9 | CH29: =SUM(AE29:AH29) -> -119.3 | CI29: =SUM(AI29:AL29) -> -353.4 | CJ29: =SUM(AM29:AP29) -> -378.9 | CK29: =SUM(AQ29:AT29) -> -542 | CL29: =SUM(AU29:AX29) -> -1385.9 | CM29: =SUM(AY29:BB29) -> -354.4 | CN29: =SUM(BC29:BF29) -> -368.9 | CO29: =SUM(BG29:BJ29) -> -748.6 | CP29: =SUM(BK29:BN29) -> -452 | CQ29: =SUM(BO29:BR29) -> -604 | CR29: =-(CQ57+CQ59)*($DF$52) -> -802.68706 | CS29: =-(CR57+CR59)*($DF$52) -> -758.13793 | CT29: =-(CS57+CS59)*($DF$52) -> -716.06128 | CU29: =-(CT57+CT59)*($DF$52) -> -676.31988 | CV29: =-(CU57+CU59)*($DF$52) -> -638.78412 | CW29: =-(CV57+CV59)*($DF$52) -> -603.3316 | CX29: =-(CW57+CW59)*($DF$52) -> -569.8467 | CY29: =-(CX57+CX59)*($DF$52) -> -538.22021 | ... DA29: =-(CZ57+CZ59)*($DF$52) -> -480.13562
B30: Other Income | C30: 0 | D30: 0 | E30: 0 | F30: 0 | G30: 0 | H30: 0 | I30: 0 | J30: 0 | K30: 0 | L30: 0 | M30: 0 | N30: 0 | O30: 0 | P30: 0 | Q30: 0 | R30: 0 | S30: 0 | T30: 0 | U30: 0 | V30: 0 | W30: 0 | X30: 0 | Y30: 0 | Z30: 0 | AA30: 0 | AB30: 0 | AC30: 0 | AD30: 0 | AE30: 0 | AF30: 0 | AG30: 0 | AH30: 0 | AI30: 0 | AJ30: 0 | AK30: 0 | AL30: 0 | AM30: 0 | AN30: 0 | AO30: 0 | AP30: 0 | AQ30: 0 | AR30: 0 | AS30: 0 | AT30: 0 | AU30: 0 | AV30: 0 | AW30: 0 | AX30: 0 | AY30: 0 | AZ30: 0 | BA30: 0 | BB30: 0 | BC30: 0 | BD30: 0 | BE30: 0 | BF30: 0 | BG30: 0 | BH30: 0 | BI30: 0 | BJ30: 0 | BK30: 0 | BL30: 0 | BM30: 0 | BN30: 0 | BO30: 0 | BP30: 0 | BQ30: 0 | BR30: 0 | CA30: =SUM(C30:F30) -> 0 | CB30: =SUM(G30:J30) -> 0 | CC30: =SUM(K30:N30) -> 0 | CD30: =SUM(O30:R30) -> 0 | CE30: =SUM(S30:V30) -> 0 | CF30: =SUM(W30:Z30) -> 0 | CG30: =SUM(AA30:AD30) -> 0 | CH30: =SUM(AE30:AH30) -> 0 | CI30: =SUM(AI30:AL30) -> 0 | CJ30: =SUM(AM30:AP30) -> 0 | CK30: =SUM(AQ30:AT30) -> 0 | CL30: =SUM(AU30:AX30) -> 0 | CM30: =SUM(AY30:BB30) -> 0 | CN30: =SUM(BC30:BF30) -> 0 | CO30: =SUM(BG30:BJ30) -> 0 | CP30: =SUM(BK30:BN30) -> 0 | CQ30: =SUM(BO30:BR30) -> 0 | CR30: =6000*$DK$38 -> 1845 | CS30: =CR30*(1+$DK$38) -> 2412.3375 | CT30: =CS30*(1+$DK$38) -> 3154.1313 | CU30: =CT30*(1+$DK$38) -> 4124.0267 | CV30: =CU30*(1+$DK$38) -> 5392.1648 | CW30: =CV30*(1+$DK$38) -> 7050.2555 | CX30: =CW30*(1+$DK$38) -> 9218.2091 | CY30: =CX30*(1+$DK$38) -> 12052.808 | CZ30: =CY30*(1+$DK$38) -> 15759.047 | DA30: =CZ30*(1+$DK$38) -> 20604.954
B31: Pretax Income | C31: =C28+SUM(C29:C29) -> 37.3 | D31: =D28+SUM(D29:D29) -> 53 | E31: =E28+SUM(E29:E29) -> 50.4 | F31: =F28+SUM(F29:F29) -> 126.8 | G31: =G28+SUM(G29:G29) -> 54.3 | H31: =H28+SUM(H29:H29) -> 73.4 | I31: =I28+SUM(I29:I29) -> 65.4 | J31: =J28+SUM(J29:J29) -> 166.4 | ... BR31: =BR28+SUM(BR29:BR29) -> 2767.8 | CA31: =SUM(C31:F31) -> 267.5 | CB31: =SUM(G31:J31) -> 359.5 | CC31: =SUM(K31:N31) -> 359.5 | CD31: =SUM(O31:R31) -> 30.6 | CE31: =SUM(S31:V31) -> 170.9 | CF31: =SUM(W31:Z31) -> 349.3 | CG31: =SUM(AA31:AD31) -> 141.7 | CH31: =SUM(AE31:AH31) -> 260.6 | CI31: =SUM(AI31:AL31) -> 485.3 | CJ31: =SUM(AM31:AP31) -> 1226.4 | CK31: =SUM(AQ31:AT31) -> 2062.3 | CL31: =SUM(AU31:AX31) -> 3199.3 | CM31: =SUM(AY31:BB31) -> 5840.2 | CN31: =SUM(BC31:BF31) -> 5263.9 | CO31: =SUM(BG31:BJ31) -> 6205.4 | CP31: =SUM(BK31:BN31) -> 9965.6 | CQ31: =SUM(BO31:BR31) -> 12722.7 | CR31: =CR28+SUM(CR29:CR30) -> 16477.699 | CS31: =CS28+SUM(CS29:CS30) -> 18881.853 | CT31: =CT28+SUM(CT29:CT30) -> 21307.244 | CU31: =CU28+SUM(CU29:CU30) -> 25714.533 | CV31: =CV28+SUM(CV29:CV30) -> 26724.587 | CW31: =CW28+SUM(CW29:CW30) -> 29760.418 | CX31: =CX28+SUM(CX29:CX30) -> 33154.994 | CY31: =CY28+SUM(CY29:CY30) -> 37143.378 | ... DA31: =DA28+SUM(DA29:DA30) -> 47723.548
B32: Taxes | C32: 15 | D32: 20.5 | E32: 20.3 | F32: 50.9 | G32: 22.1 | H32: 29.9 | I32: 27.4 | J32: 54 | K32: 38 | L32: 42.6 | M32: 31.2 | N32: 21.6 | O32: -2.4 | P32: 4.5 | Q32: 4.3 | R32: 7 | S32: -1.8 | T32: 17.2 | U32: 17.7 | V32: 25.6 | W32: 35.8 | X32: 46.4 | Y32: 38.2 | Z32: -37.9 | AA32: 14.7 | AB32: 14.2 | AC32: 12.8 | AD32: -22.4 | AE32: 12.2 | AF32: 10.5 | AG32: 27.6 | AH32: 23.5 | AI32: 45.6 | AJ32: -51.6 | AK32: -13.4 | AL32: -54.2 | AM32: 9.5 | AN32: 44.3 | AO32: -24 | AP32: -14.5 | AQ32: 55.6 | AR32: 230.3 | AS32: 347.1 | AT32: -437.6 | AU32: 86.8 | AV32: 315.4 | AW32: 71.5 | AX32: -35.7 | AY32: 327.8 | AZ32: 240.8 | BA32: 211.9 | BB32: -56.6 | BC32: 382.2 | BD32: 182.1 | BE32: 223.6 | BF32: -15.9 | BG32: 163.8 | BH32: 191.7 | BI32: 231.6 | BJ32: 210.3 | BK32: 282.4 | BL32: 366.6 | BM32: 339.4 | BN32: 265.7 | BO32: 323.4 | BP32: 506.3 | BQ32: 562.5 | BR32: 349.2 | CA32: =SUM(C32:F32) -> 106.7 | CB32: =SUM(G32:J32) -> 133.4 | CC32: =SUM(K32:N32) -> 133.4 | CD32: =SUM(O32:R32) -> 13.4 | CE32: =SUM(S32:V32) -> 58.7 | CF32: =SUM(W32:Z32) -> 82.5 | CG32: =SUM(AA32:AD32) -> 19.3 | CH32: =SUM(AE32:AH32) -> 73.8 | CI32: =SUM(AI32:AL32) -> -73.6 | CJ32: =SUM(AM32:AP32) -> 15.3 | CK32: =SUM(AQ32:AT32) -> 195.4 | CL32: =SUM(AU32:AX32) -> 438 | CM32: =SUM(AY32:BB32) -> 723.9 | CN32: =SUM(BC32:BF32) -> 772 | CO32: =SUM(BG32:BJ32) -> 797.4 | CP32: =SUM(BK32:BN32) -> 1254.1 | CQ32: =SUM(BO32:BR32) -> 1741.4 | CR32: =CR31*CR42 -> 2471.6549 | CS32: =CS31*CS42 -> 3021.0964 | CT32: =CT31*CT42 -> 3409.159 | CU32: =CU31*CU42 -> 4114.3253 | CV32: =CV31*CV42 -> 4275.9339 | CW32: =CW31*CW42 -> 4761.6668 | CX32: =CX31*CX42 -> 5304.799 | CY32: =CY31*CY42 -> 5942.9405 | ... DA32: =DA31*DA42 -> 7635.7676
B33: NI | C33: =C31-C32 -> 22.3 | D33: =D31-D32 -> 32.5 | E33: =E31-E32 -> 30.1 | F33: =F31-F32 -> 75.9 | G33: =G31-G32 -> 32.2 | H33: =H31-H32 -> 43.5 | I33: =I31-I32 -> 38 | J33: =J31-J32 -> 112.4 | ... BR33: =BR31-BR32 -> 2418.6 | CA33: =SUM(C33:F33) -> 160.8 | CB33: =SUM(G33:J33) -> 226.1 | CC33: =SUM(K33:N33) -> 226.1 | CD33: =SUM(O33:R33) -> 17.2 | CE33: =SUM(S33:V33) -> 112.2 | CF33: =SUM(W33:Z33) -> 266.8 | CG33: =SUM(AA33:AD33) -> 122.4 | CH33: =SUM(AE33:AH33) -> 186.8 | CI33: =SUM(AI33:AL33) -> 558.9 | CJ33: =SUM(AM33:AP33) -> 1211.1 | CK33: =SUM(AQ33:AT33) -> 1866.9 | CL33: =SUM(AU33:AX33) -> 2761.3 | CM33: =SUM(AY33:BB33) -> 5116.3 | CN33: =SUM(BC33:BF33) -> 4491.9 | CO33: =SUM(BG33:BJ33) -> 5408 | CP33: =SUM(BK33:BN33) -> 8711.5 | CQ33: =SUM(BO33:BR33) -> 10981.3 | CR33: =CR31-CR32 -> 14006.044 | CS33: =CS31-CS32 -> 15860.756 | CT33: =CT31-CT32 -> 17898.085 | CU33: =CU31-CU32 -> 21600.208 | CV33: =CV31-CV32 -> 22448.653 | CW33: =CW31-CW32 -> 24998.751 | CX33: =CX31-CX32 -> 27850.195 | CY33: =CY31-CY32 -> 31200.437 | ... DA33: =DA31-DA32 -> 40087.78 | DB33: =DA33*(1+$DK$39) -> 41069.931 | DC33: =DB33*(1+$DK$39) -> 42076.144 | DD33: =DC33*(1+$DK$39) -> 43107.01 | DE33: =DD33*(1+$DK$39) -> 44163.131 | DF33: =DE33*(1+$DK$39) -> 45245.128 | DG33: =DF33*(1+$DK$39) -> 46353.634 | DH33: =DG33*(1+$DK$39) -> 47489.298 | DI33: =DH33*(1+$DK$39) -> 48652.785 | ... EY33: =EX33*(1+$DK$39) -> 134465.27
B34: SC | C34: 3735 | D34: 3730 | E34: 3725 | F34: 3720 | G34: 3710 | H34: 3710 | I34: 3700 | J34: 3699 | K34: 3693 | L34: 3673 | M34: 3680 | N34: 3699 | O34: 3882 | P34: 3887 | Q34: 3888 | R34: 3886 | S34: 3918 | T34: 4073 | U34: 4138 | V34: 4074 | W34: 4187 | X34: 4200 | Y34: 4212 | Z34: 4205 | AA34: 4236 | AB34: 4253 | AC34: 4269 | AD34: 4259 | AE34: 4281 | AF34: 4285 | AG34: 4289 | AH34: 4288 | AI34: 4306 | AJ34: 4314 | AK34: 4324 | AL34: 4319 | AM34: 4342 | AN34: 4351 | AO34: 4358 | AP34: 4354 | AQ34: 4369 | AR34: 4376 | AS34: 4381 | AT34: 4378 | AU34: 4394 | AV34: 4406 | AW34: 4415 | AX34: 4409 | AY34: 4432 | AZ34: 4432 | BA34: 4428 | BB34: 4432 | BC34: 4441 | BD34: 4446 | BE34: 4449 | BF34: 4447 | BG34: 4452 | BH34: 4439 | BI34: 4415 | BJ34: 4416 | BK34: 4321 | BL34: 4301 | BM34: 4282 | BN34: 4295 | BO34: 4273 | BP34: 4252 | BQ34: 4245 | BR34: 4250 | CA34: =AVERAGE(C34:F34) -> 3727.5 | CB34: =AVERAGE(G34:J34) -> 3704.75 | CC34: =AVERAGE(K34:N34) -> 3686.25 | CD34: =AVERAGE(O34:R34) -> 3885.75 | CE34: =AVERAGE(S34:V34) -> 4050.75 | CF34: =AVERAGE(W34:Z34) -> 4201 | CG34: =AVERAGE(AA34:AD34) -> 4254.25 | CH34: =AVERAGE(AE34:AH34) -> 4285.75 | CI34: =AVERAGE(AI34:AL34) -> 4315.75 | CJ34: =AVERAGE(AM34:AP34) -> 4351.25 | CK34: =AVERAGE(AQ34:AT34) -> 4376 | CL34: =AVERAGE(AU34:AX34) -> 4406 | CM34: =AVERAGE(AY34:BB34) -> 4431 | CN34: =AVERAGE(BC34:BF34) -> 4445.75 | CO34: =AVERAGE(BG34:BJ34) -> 4430.5 | CP34: =AVERAGE(BK34:BN34) -> 4299.75 | CQ34: =AVERAGE(BO34:BR34) -> 4255
B35: EPS | C35: =C33/C34 -> 0.0059705489 | D35: =D33/D34 -> 0.0087131367 | E35: =E33/E34 -> 0.0080805369 | F35: =F33/F34 -> 0.020403226 | G35: =G33/G34 -> 0.0086792453 | H35: =H33/H34 -> 0.011725067 | I35: =I33/I34 -> 0.01027027 | J35: =J33/J34 -> 0.030386591 | ... BR35: =BR33/BR34 -> 0.56908235 | CA35: =SUM(C35:F35) -> 0.043167448 | CB35: =SUM(G35:J35) -> 0.061061174 | CC35: =SUM(K35:N35) -> 0.06136868 | CD35: =SUM(O35:R35) -> 0.0044234957 | CE35: =SUM(S35:V35) -> 0.027447936 | CF35: =SUM(W35:Z35) -> 0.063499227 | CG35: =SUM(AA35:AD35) -> 0.028761897 | CH35: =SUM(AE35:AH35) -> 0.043577851 | CI35: =SUM(AI35:AL35) -> 0.12951238 | CJ35: =SUM(AM35:AP35) -> 0.27831812 | CK35: =SUM(AQ35:AT35) -> 0.42651369 | CL35: =SUM(AU35:AX35) -> 0.62670392 | CM35: =SUM(AY35:BB35) -> 1.1546952 | CN35: =SUM(BC35:BF35) -> 1.0105136 | CO35: =SUM(BG35:BJ35) -> 1.2205885 | CP35: =SUM(BK35:BN35) -> 2.0259948 | CQ35: =SUM(BO35:BR35) -> 2.5805347 | DC35: Invested Capital | DF35: Avg. (2024-2025) | DH35: Projected ROIC:
DC36: 2024 | DD36: 2025 | DF36: 2024-2025 | DH36: 2025
B37: Gross Profit Margin | C37: =C23/C21 -> 0.34204517 | D37: =D23/D21 -> 0.34100367 | E37: =E23/E21 -> 0.3493264 | F37: =F23/F21 -> 0.40911517 | G37: =G23/G21 -> 0.37775977 | H37: =H23/H21 -> 0.39419007 | I37: =I23/I21 -> 0.37725958 | J37: =J23/J21 -> 0.34470969 | ... BR37: =BR23/BR21 -> 0.45874133 | CA37: =CA23/CA21 -> 0.3723296 | CB37: =CB23/CB21 -> 0.3634463 | CC37: =CC23/CC21 -> 0.36341509 | CD37: =CD23/CD21 -> 0.26523149 | CE37: =CE23/CE21 -> 0.28740913 | CF37: =CF23/CF21 -> 0.31826109 | CG37: =CG23/CG21 -> 0.32272291 | CH37: =CH23/CH21 -> 0.29139583 | ... CQ37: =CQ23/CQ21 -> 0.48486934 | CR37: 0.46918725 | CS37: 0.46918725 | CT37: 0.46918725 | CU37: 0.46918725 | CV37: 0.46918725 | CW37: 0.46918725 | CX37: 0.46918725 | CY37: 0.46918725 | CZ37: 0.46918725 | DA37: 0.46918725 | DC37: =SUM(CP45:CP47)-CP54-CP53+CP48+CP49 -> 41853.003 | DD37: =SUM(CQ45:CQ47)-CQ54-CQ53+CQ48+CQ49 -> 42817.46 | DF37: =AVERAGE(DC37:DD37) -> 42335.231 | DH37: =AVERAGE(CR28)*(1-CR42) -> 13120.078
B38: S&M as % of Revenue | C38: =C24/C21 -> 0.15529054 | D38: =D24/D21 -> 0.1128519 | E38: =E24/E21 -> 0.13471992 | F38: =F24/F21 -> 0.13832853 | G38: =G24/G21 -> 0.15252177 | H38: =H24/H21 -> 0.14332436 | I38: =I24/I21 -> 0.14678236 | J38: =J24/J21 -> 0.10482935 | ... BR38: =BR24/BR21 -> 0.092392206 | CA38: =CA24/CA21 -> 0.13590123 | CB38: =CB24/CB21 -> 0.12566311 | CC38: =CC24/CC21 -> 0.118954 | CD38: =CD24/CD21 -> 0.12038345 | CE38: =CE24/CE21 -> 0.10748411 | CF38: =CF24/CF21 -> 0.11030774 | CG38: =CG24/CG21 -> 0.12155764 | CH38: =CH24/CH21 -> 0.12427242 | ... CQ38: =CQ24/CQ21 -> 0.073067142 | CR38: 0.075 | CS38: 0.0745 | CT38: 0.074 | CU38: 0.0435 | CV38: 0.073 | CW38: 0.0725 | CX38: 0.072 | CY38: 0.0715 | CZ38: 0.071 | DA38: 0.07 | DH38: =DH37/DF37 -> 0.30990922 | DJ38: ROIC | DK38: 0.3075
B39: G&A as % of Revenue | C39: =C25/C21 -> 0.032986552 | D39: =D25/D21 -> 0.03255814 | E39: =E25/E21 -> 0.027180336 | F39: =F25/F21 -> 0.028498239 | G39: =G25/G21 -> 0.031395584 | H39: =H25/H21 -> 0.029049634 | I39: =I25/I21 -> 0.028741866 | J39: =J25/J21 -> 0.049026192 | ... BR39: =BR25/BR21 -> 0.047117204 | CA39: =CA25/CA21 -> 0.02982521 | CB39: =CB25/CB21 -> 0.039568121 | CC39: =CC25/CC21 -> 0.046277226 | CD39: =CD25/CD21 -> 0.039841521 | CE39: =CE25/CE21 -> 0.041192338 | CF39: =CF25/CF21 -> 0.048995386 | CG39: =CG25/CG21 -> 0.060078177 | CH39: =CH25/CH21 -> 0.035750685 | ... CQ39: =CQ25/CQ21 -> 0.041794388 | CR39: 0.042804549 | CS39: 0.0425 | CT39: 0.04225 | CU39: 0.042 | CV39: 0.0415 | CW39: 0.041 | CX39: 0.0405 | CY39: 0.04025 | CZ39: 0.04 | DA39: 0.04 | DC39: Capital Structure | DJ39: Terminal | DK39: 0.0245
B40: R&D as % of Revenue | C40: =C26/C21 -> 0.061405735 | D40: =D26/D21 -> 0.066340269 | E40: =E26/E21 -> 0.070905223 | F40: =F26/F21 -> 0.087522681 | G40: =G26/G21 -> 0.075754507 | H40: =H26/H21 -> 0.072912659 | I40: =I26/I21 -> 0.076102675 | J40: =J26/J21 -> 0.086513218 | ... BR40: =BR26/BR21 -> 0.073878913 | CA40: =CA26/CA21 -> 0.075510959 | CB40: =CB26/CB21 -> 0.080852524 | CC40: =CC26/CC21 -> 0.080852524 | CD40: =CD26/CD21 -> 0.091125703 | CE40: =CE26/CE21 -> 0.086567915 | CF40: =CF26/CF21 -> 0.085819133 | CG40: =CG26/CG21 -> 0.09601003 | CH40: =CH26/CH21 -> 0.088351867 | ... CQ40: =CQ26/CQ21 -> 0.075059038 | CR40: 0.074 | CS40: 0.073 | CT40: 0.072 | CU40: 0.071 | CV40: 0.07 | CW40: 0.07 | CX40: 0.07 | CY40: 0.07 | CZ40: 0.07 | DA40: 0.07 | DC40: Mkt Cap | DF40: =Main!C5 -> 385426.38 | DJ40: RFR (10-year yield) | DK40: =DF46 -> 0.0409
B41: Operating Profit Margin | C41: =C28/C21 -> 0.092362345 | D41: =D28/D21 -> 0.12925337 | E41: =E28/E21 -> 0.11652092 | F41: =F28/F21 -> 0.15476572 | G41: =G28/G21 -> 0.11808791 | H41: =H28/H21 -> 0.14890342 | I41: =I28/I21 -> 0.12563268 | J41: =J28/J21 -> 0.10434092 | ... BR41: =BR28/BR21 -> 0.24535301 | CA41: =CA28/CA21 -> 0.1310922 | CB41: =CB28/CB21 -> 0.11736254 | CC41: =CC28/CC21 -> 0.11733134 | CD41: =CD28/CD21 -> 0.013880808 | CE41: =CE28/CE21 -> 0.052164769 | CF41: =CF28/CF21 -> 0.073138829 | CG41: =CG28/CG21 -> 0.045077071 | CH41: =CH28/CH21 -> 0.043020859 | ... DA41: =DA28/DA21 -> 0.34511163 | DC41: Debt to Ttl Mkt Cap | DF41: =Main!C7/(Main!C7+DF40) -> 0.036167092 | DJ41: ERP (Avg. market return - (less) RFR) | DK41: =8.69%-DK40 -> 0.046
B42: Effective Tax Rate | C42: =C32/C31 -> 0.40214477 | D42: =D32/D31 -> 0.38679245 | E42: =E32/E31 -> 0.40277778 | F42: =F32/F31 -> 0.40141956 | G42: =G32/G31 -> 0.40699816 | H42: =H32/H31 -> 0.40735695 | I42: =I32/I31 -> 0.41896024 | J42: =J32/J31 -> 0.32451923 | ... BR42: =BR32/BR31 -> 0.12616519 | CA42: =CA32/CA31 -> 0.3988785 | CB42: =CB32/CB31 -> 0.37107093 | CC42: =CC32/CC31 -> 0.37107093 | CD42: =CD32/CD31 -> 0.4379085 | CE42: =CE32/CE31 -> 0.34347572 | CF42: =CF32/CF31 -> 0.23618666 | CG42: =CG32/CG31 -> 0.13620325 | CH42: =CH32/CH31 -> 0.28319263 | ... CQ42: =CQ32/CQ31 -> 0.13687346 | CR42: 0.15 | CS42: 0.16 | CT42: 0.16 | CU42: 0.16 | CV42: 0.16 | CW42: 0.16 | CX42: 0.16 | CY42: 0.16 | CZ42: 0.16 | DA42: 0.16 | DC42: Mkt Equity to Ttl Mkt Cap | DF42: =DF40/(DF40+Main!C7) -> 0.96383291 | DJ42: Equity β (1-year avg.) | DK42: ='Notes | Quant Analysis'!S209 -> 1.0345819
B43: Net Profit Margin | C43: =C33/C21 -> 0.056584623 | D43: =D33/D21 -> 0.079559364 | E43: =E33/E21 -> 0.071141574 | F43: =F33/F21 -> 0.081011848 | G43: =G33/G21 -> 0.065221795 | H43: =H33/H21 -> 0.083686033 | I43: =I33/I21 -> 0.068691251 | J43: =J33/J21 -> 0.068624458 | ... BR43: =BR33/BR21 -> 0.20070037 | CA43: =CA33/CA21 -> 0.074354943 | CB43: =CB33/CB21 -> 0.070554827 | CC43: =CC33/CC21 -> 0.070554827 | CD43: =CD33/CD21 -> 0.004765467 | CE43: =CE33/CE21 -> 0.025648059 | CF43: =CF33/CF21 -> 0.048468554 | CG43: =CG33/CG21 -> 0.018054429 | CH43: =CH33/CH21 -> 0.021153715 | ... DA43: =DA33/DA21 -> 0.50128246 | DC43: LT Debt / Equity | DF43: =(CQ59+CQ57)/CQ62 -> 0.54339902 | DJ43: Discount (Cost of Equity) | DK43: =+DK40+(DK41*DK42) -> 0.088490767
...

Sheet Notes | Quant Analysis
CI1: 0
P2: Employee Scope: | AL2: General Notes/Observations (Updated Q1'26)
P36: Institutional Ownership Snapshot Q4'25
AL37: Financial Stmts. Notes/Observations (Updated Q1'26)
AL38: Revenues:
Q65: Notes: | R65: [X]
R66: [Y]
R67: [Z]
P69: Revenue Breakdown by Segment (Build graph for this section if applicable…. See example below) | AL69: Earnings Scope:
Q101: Notes: | R101: [X]
R102: [Y]
R103: [Z]
P105: Q/q Total Revenues, Net Income, FCF | AL105: Balance Sheet Scope:
Q134: Notes: | R134: [X]
R135: [Y]
R136: [Z]
P138: Y/y Total Revenues, Net Income, FCF | AL138: [Equity Preformance Compared to Peers]
Q167: Notes: | R167: [X]
R168: [Y]
R169: [Z]
A184: VOO Historical Returns | I184: NFLX Historical Returns
A185: 753 Trading Days (From: 2/19/2022 - 2/19/2026) | I185: 753 Trading Days (From: 2/19/2022 - 2/19/2026)
A186: Close | B186: High | C186: Low | D186: Open | E186: Volume | F186: UTC Date | G186: Change | I186: Close | J186: High | K186: Low | L186: Open | M186: Volume | N186: UTC Date | O186: Change
A187: 630.48 | B187: 632.98 | C187: 629.48 | D187: 630.3 | E187: 5007553 | F187: Fri, 05 Dec 2025 00:00:00 GMT | G187: =A187/D187-1 -> 0.0002855783 | I187: 100.24 | J187: 104.79 | K187: 97.74 | L187: 98.775 | M187: 132389043 | N187: Fri, 05 Dec 2025 00:00:00 GMT | O187: =I187/L187-1 -> 0.014831688
A188: 629.3 | B188: 630.18 | C188: 626.48 | D188: 630.13 | E188: 5114434 | F188: Thu, 04 Dec 2025 00:00:00 GMT | G188: =A188/D188-1 -> -0.0013171885 | I188: 103.22 | J188: 103.8 | K188: 101.77 | L188: 103.57 | M188: 51328769 | N188: Thu, 04 Dec 2025 00:00:00 GMT | O188: =I188/L188-1 -> -0.003379357
A189: 628.77 | B189: 629.78 | C189: 624.95 | D189: 625.77 | E189: 5149531 | F189: Wed, 03 Dec 2025 00:00:00 GMT | G189: =A189/D189-1 -> 0.0047940937 | I189: 103.96 | J189: 106.87 | K189: 102.03 | L189: 106.59 | M189: 52928334 | N189: Wed, 03 Dec 2025 00:00:00 GMT | O189: =I189/L189-1 -> -0.024673984
A190: 626.58 | B190: 628.77 | C190: 624.62 | D190: 627.01 | E190: 5256797 | F190: Tue, 02 Dec 2025 00:00:00 GMT | G190: =A190/D190-1 -> -0.00068579448 | I190: 109.35 | J190: 109.73 | K190: 107.52 | L190: 109.205 | M190: 24894150 | N190: Tue, 02 Dec 2025 00:00:00 GMT | O190: =I190/L190-1 -> 0.001327778
A191: 625.52 | B191: 628.01 | C191: 624.1 | D191: 624.17 | E191: 8381362 | F191: Mon, 01 Dec 2025 00:00:00 GMT | G191: =A191/D191-1 -> 0.0021628723 | I191: 109.13 | J191: 109.335 | K191: 106.31 | L191: 106.51 | M191: 24049038 | N191: Mon, 01 Dec 2025 00:00:00 GMT | O191: =I191/L191-1 -> 0.024598629
A192: 628.41 | B192: 628.63 | C192: 625.705 | D192: 626.025 | E192: 2949167 | F192: Fri, 28 Nov 2025 00:00:00 GMT | G192: =A192/D192-1 -> 0.003809752 | I192: 107.58 | J192: 107.94 | K192: 106.24 | L192: 106.435 | M192: 15011024 | N192: Fri, 28 Nov 2025 00:00:00 GMT | O192: =I192/L192-1 -> 0.010757739
A193: 624.95 | B193: 626.81 | C193: 622.26 | D193: 623.06 | E193: 5292533 | F193: Wed, 26 Nov 2025 00:00:00 GMT | G193: =A193/D193-1 -> 0.0030334157 | I193: 106.14 | J193: 106.95 | K193: 105.22 | L193: 105.74 | M193: 27859165 | N193: Wed, 26 Nov 2025 00:00:00 GMT | O193: =I193/L193-1 -> 0.0037828636
A194: 620.66 | B194: 621.75 | C194: 610.99 | D194: 614.78 | E194: 7289905 | F194: Tue, 25 Nov 2025 00:00:00 GMT | G194: =A194/D194-1 -> 0.009564397 | I194: 104.4 | J194: 106.3 | K194: 103.82 | L194: 106.12 | M194: 34376260 | N194: Tue, 25 Nov 2025 00:00:00 GMT | O194: =I194/L194-1 -> -0.016208066
A195: 614.94 | B195: 616.09 | C195: 608.305 | D195: 609.28 | E195: 6218559 | F195: Mon, 24 Nov 2025 00:00:00 GMT | G195: =A195/D195-1 -> 0.0092896534 | I195: 106.97 | J195: 108.04 | K195: 103.32 | L195: 104.25 | M195: 62152616 | N195: Mon, 24 Nov 2025 00:00:00 GMT | O195: =I195/L195-1 -> 0.026091127
A196: 605.93 | B196: 611.01 | C196: 598.38 | D196: 602.25 | E196: 9789866 | F196: Fri, 21 Nov 2025 00:00:00 GMT | G196: =A196/D196-1 -> 0.0061104193 | I196: 104.31 | J196: 106.53 | K196: 103.81 | L196: 105.13 | M196: 40853314 | N196: Fri, 21 Nov 2025 00:00:00 GMT | O196: =I196/L196-1 -> -0.0077998668
A197: 599.96 | B197: 621.1288 | C197: 599.36 | D197: 618.72 | E197: 13857655 | F197: Thu, 20 Nov 2025 00:00:00 GMT | G197: =A197/D197-1 -> -0.030320662 | I197: 105.67 | J197: 111.1 | K197: 105.39 | L197: 111 | M197: 36618387 | N197: Thu, 20 Nov 2025 00:00:00 GMT | O197: =I197/L197-1 -> -0.048018018
A198: 609.2 | B198: 613.5699 | C198: 605.67 | D198: 607.52 | E198: 7297298 | F198: Wed, 19 Nov 2025 00:00:00 GMT | G198: =A198/D198-1 -> 0.0027653411 | I198: 110 | J198: 113.34 | K198: 108.61 | L198: 113 | M198: 30905213 | N198: Wed, 19 Nov 2025 00:00:00 GMT | O198: =I198/L198-1 -> -0.026548673
A199: 607 | B199: 611.51 | C199: 603 | D199: 608.72 | E199: 8485565 | F199: Tue, 18 Nov 2025 00:00:00 GMT | G199: =A199/D199-1 -> -0.0028256013 | I199: 114.09 | J199: 115.25 | K199: 109.2 | L199: 110.29 | M199: 43257053 | N199: Tue, 18 Nov 2025 00:00:00 GMT | O199: =I199/L199-1 -> 0.03445462 | Q199: Notes: | R199: [X]
A200: 612.04 | B200: 619.4485 | C200: 608.81 | D200: 615.74 | E200: 8858869 | F200: Mon, 17 Nov 2025 00:00:00 GMT | G200: =A200/D200-1 -> -0.0060090298 | I200: 110.29 | J200: 111.85 | K200: 109.55 | L200: 110.75 | M200: 25704297 | N200: Mon, 17 Nov 2025 00:00:00 GMT | O200: =I200/L200-1 -> -0.0041534989 | R200: [Y]
A201: 617.83 | B201: 621.2199 | C201: 609.83 | D201: 611.75 | E201: 9651895 | F201: Fri, 14 Nov 2025 00:00:00 GMT | G201: =A201/D201-1 -> 0.0099387004 | I201: 111.217 | J201: 114.273 | K201: 110.721 | L201: 114.273 | M201: 47202170 | N201: Fri, 14 Nov 2025 00:00:00 GMT | O201: =I201/L201-1 -> -0.026742975 | R201: [Z]
A202: 617.99 | B202: 626.02 | C202: 616.51 | D202: 625.67 | E202: 10526401 | F202: Thu, 13 Nov 2025 00:00:00 GMT | G202: =A202/D202-1 -> -0.012274841 | I202: 115.423 | J202: 116.733 | K202: 114.569 | L202: 115.85 | M202: 39706350 | N202: Thu, 13 Nov 2025 00:00:00 GMT | O202: =I202/L202-1 -> -0.0036858006
A203: 628.22 | B203: 629.77 | C203: 626.1 | D203: 629.65 | E203: 6065826 | F203: Wed, 12 Nov 2025 00:00:00 GMT | G203: =A203/D203-1 -> -0.002271103 | I203: 115.75 | J203: 116.43399 | K203: 112.826 | L203: 113.817 | M203: 39042490 | N203: Wed, 12 Nov 2025 00:00:00 GMT | O203: =I203/L203-1 -> 0.016983403 | R203: Min | S203: =MIN(O181:O1143) -> -0.068479635
...

Sheet Product Lines

Sheet Management

Sheet Table Formatting
B2: [Bold Title] | G2: [Bold Title]
B3: Line Titles | G3: <-- General
B4: Line Titles | G4: <-- Info
B5: Line Titles | G5: <-- General
B6: Line Titles | G6: <-- Info
B7: Line Titles | G7: <-- General
B8: Line Titles | G8: <-- Info
