Workbook

Sheet Main
B2: NOC
B3: Price | C3: 530.4 | D3: 10/21/2026
B4: SO | C4: 142.1 | D4: Q3'26
B5: MC | C5: =C3*C4 -> 75369.84
B6: Cash | C6: 3744 | D6: Q3'26
B7: Debt | C7: 14433 | D7: Q3'26
B8: EV | C8: =C5-C6+C7 -> 86058.84
B10: Northrop Grumman Corporation (NOC)
B12: Founder(s): Merger between Northrop Corp. & Grumman Aircraft Engineering Corp. | F12: Registered Exchange: | N12: Resources:
B13: Founded: Merged April 1994 | F13: Address: | N13: SEC filings | Q13: https://www.sec.gov/edgar/browse/?CIK=1133421&owner=exclude
B14: Headquarters: Falls Church, VA | F14: Investor Relations Contact: | N14: Company Homepage | Q14: https://www.northropgrumman.com/
B15: Current CEO: Kathy Warden | F15: Investors Relation Department | O15: Company IR Page | R15: https://investor.northropgrumman.com/
B16: Employees: 95,000 | F16: Phone: | G16: (703) 280 - 2900 | I16: Email: | N16: Earnings Calls | Q16: https://seekingalpha.com/symbol/NOC/earnings/transcripts
B17: Industry: Industrials | N17: Equity Analysis | Q17: https://stockanalysis.com/stocks/noc/company/
B18: Sector: Aerospace & Defense | N18: MacroTrends | Q18: https://www.macrotrends.net/stocks/charts/NOC/northrop-grumman/financial-statements
B19: IPO: Merged April 1994 | N19: ROIC, WACC | Q19: https://www.gurufocus.com/term/wacc/NOC
B20: Fiscal Year: [January - December] | N20: Godel Terminal | Q20: https://app.godelterminal.com/
A22: Company Overview:
B23: Northrop Grumman Corporation operates as an aerospace and defense technology company in the United States, Asia/Pacific, Europe, and internationally
B24: It operates through four segments: Aeronautics Systems, Defense Systems, Mission Systems and Space Systems …
C25: The Aeronautics Systems segment designs, develops, produces, integrates, sustains, and modernizes aircraft systems.
D26: This segment also offers unmanned autonomous aircraft systems, including high-altitude long-endurance strategic, surveillance and reconnaissance systems; and strategic long-range strike aircraft, tactical fighter and air dominance aircraft, and airborne battle management and command and control systems
E27: B-21 Raider long-range strategic stealth bomber that define sixth-generation technologies
E28: B-2 Spirit strategic stealth bomber
E29: E-130J Phoenix II nuclear command, control and communications (NC3) aircraft
E30: F-35 Lighting II Joint Strike Fighter
E31: F/A-18 Super Hornet
E32: E-2D Advanced Hawkeye AWACS
E33: MQ-4C Triton & RQ-4 Global Hawk (Navy and AF variants) strategic long-range ISR drones
E34: A-10 Warthog
E35: RQ-170 & RQ-180 Stealth ISR UAVs
C36: The Defense Systems segment designs, develops, integrates, and produces strategic deterrent systems, tactical weapons, and missile defense solutions; and provides sustainment, modernization, and training services for manned and unmanned aircraft and electronics systems
D37: This segment also offers strategic missiles; integrated all-domain command and control systems; precision strike weapons; tactical solid rocket motors, and high-speed air-breathing and hypersonic systems; high-performance gun systems, ammunition, precision munitions, and advanced fuzes; and sustainment, operation, and modernization
C38: The Mission Systems segment provides command, control, communication and computer, intelligence, surveillance, and reconnaissance systems; radar, electro-optical/infrared, and acoustic sensors; electronic warfare systems; advanced communications and network systems; microelectronics; navigation and positioning sensors; maritime power, propulsion, and payload launch systems; cyber solutions; and intelligence processing systems
C39: Its Space Systems segment offers satellites, spacecraft systems, subsystems, sensors, and payloads; ground systems; missile defense systems and interceptors; and launch vehicles and related propulsion systems
B40: The Company was founded in 1939 and is based in Falls Church, Virginia
A42: Business Segments and Geographical Info:
B43: [Begin researching fundamentals / core business … begin with SEC filings, but expand and use all public resources available]

Sheet Model
B1: [Use for Graphing] | AE1: Q1 2020 | AI1: Q1 2021 | AM1: Q1 2022 | AQ1: Q1 2023 | AU1: Q1 2024 | AY1: Q1 2025 | BC1: Q1 2026
B2: Quarterly
B3: Revenues | C3: {="Q"&MOD(_xlfn.SEQUENCE(1,56)-1,4)+1&" "&(2013+INT((_xlfn.SEQUENCE(1,56)-1)/4))} -> Q1 2013 | D3: Q2 2013 | E3: Q3 2013 | F3: Q4 2013 | G3: Q1 2014 | H3: Q2 2014 | I3: Q3 2014 | J3: Q4 2014 | K3: Q1 2015 | L3: Q2 2015 | M3: Q3 2015 | N3: Q4 2015 | O3: Q1 2016 | P3: Q2 2016 | Q3: Q3 2016 | R3: Q4 2016 | S3: Q1 2017 | T3: Q2 2017 | U3: Q3 2017 | V3: Q4 2017 | W3: Q1 2018 | X3: Q2 2018 | Y3: Q3 2018 | Z3: Q4 2018 | AA3: Q1 2019 | AB3: Q2 2019 | AC3: Q3 2019 | AD3: Q4 2019 | AE3: Q1 2020 | AF3: Q2 2020 | AG3: Q3 2020 | AH3: Q4 2020 | AI3: Q1 2021 | AJ3: Q2 2021 | AK3: Q3 2021 | AL3: Q4 2021 | AM3: Q1 2022 | AN3: Q2 2022 | AO3: Q3 2022 | AP3: Q4 2022 | AQ3: Q1 2023 | AR3: Q2 2023 | AS3: Q3 2023 | AT3: Q4 2023 | AU3: Q1 2024 | AV3: Q2 2024 | AW3: Q3 2024 | AX3: Q4 2024 | AY3: Q1 2025 | AZ3: Q2 2025 | BA3: Q3 2025 | BB3: Q4 2025 | BC3: Q1 2026 | BD3: Q2 2026 | BE3: Q3 2026 | BF3: Q4 2026 | BM3: 2013 | BN3: =BM3+1 -> 2014 | BO3: =BN3+1 -> 2015 | BP3: =BO3+1 -> 2016 | BQ3: =BP3+1 -> 2017 | BR3: =BQ3+1 -> 2018 | BS3: =BR3+1 -> 2019 | BT3: =BS3+1 -> 2020 | BU3: =BT3+1 -> 2021 | ... EG3: =EF3+1 -> 2085
B4: Aeronautics | AI4: 2990 | AJ4: 2913 | AK4: 2725 | AL4: =11259-SUM(AI4:AK4) -> 2631 | AM4: 2703 | AN4: 2534 | AO4: 2537 | AP4: =10531-SUM(AM4:AO4) -> 2757 | AQ4: 2515 | AR4: 2595 | AS4: 2766 | AT4: =11164-SUM(AQ4:AS4) -> 3288 | AU4: 3044 | AV4: 3060 | AW4: 2961 | AX4: =12396-SUM(AU4:AW4) -> 3331 | AY4: 2814 | AZ4: 3114 | BA4: 3142 | BB4: =12992-SUM(AY4:BA4) -> 3922 | BC4: 3283 | BD4: 3519 | BE4: 3575 | BU4: =SUM(AI4:AL4) -> 11259 | BV4: =SUM(AM4:AP4) -> 10531 | BW4: =SUM(AQ4:AT4) -> 11164 | BX4: =SUM(AU4:AX4) -> 12396 | BY4: =SUM(AY4:BB4) -> 12992 | BZ4: =BY4*(1+BZ11) -> 14810.88 | CA4: =BZ4*(1+CA11) -> 16440.077 | CB4: =CA4*(1+CB11) -> 17426.481 | CC4: =CB4*(1+CC11) -> 17949.276 | CD4: =CC4*(1+CD11) -> 18398.008 | CE4: =CD4*(1+CE11) -> 18811.963 | CF4: =CE4*(1+CF11) -> 19188.202 | CG4: =CF4*(1+CG11) -> 19523.996 | ... CI4: =CH4*(1+CI11) -> 20183.526
B5: Defense | AI5: 1562 | AJ5: 1427 | AK5: 1409 | AL5: =5776-SUM(AI5:AK5) -> 1378 | AM5: 1283 | AN5: 1294 | AO5: 1345 | AP5: =5579-SUM(AM5:AO5) -> 1657 | AQ5: 1376 | AR5: 1420 | AS5: 2050 | AT5: =7185-SUM(AQ5:AS5) -> 2339 | AU5: 1737 | AV5: 1859 | AW5: 1800 | AX5: =7399-SUM(AU5:AW5) -> 2003 | AY5: 1805 | AZ5: 1991 | BA5: 2059 | BB5: =8002-SUM(AY5:BA5) -> 2147 | BC5: 1899 | BD5: 2093 | BE5: 2307 | BU5: =SUM(AI5:AL5) -> 5776 | BV5: =SUM(AM5:AP5) -> 5579 | BW5: =SUM(AQ5:AT5) -> 7185 | BX5: =SUM(AU5:AX5) -> 7399 | BY5: =SUM(AY5:BB5) -> 8002 | BZ5: =BY5*(1+BZ12) -> 8602.15 | CA5: =BZ5*(1+CA12) -> 9032.2575 | CB5: =CA5*(1+CB12) -> 9393.5478 | CC5: =CB5*(1+CC12) -> 9722.322 | CD5: =CC5*(1+CD12) -> 10013.992 | CE5: =CD5*(1+CE12) -> 10289.376 | CF5: =CE5*(1+CF12) -> 10546.611 | CG5: =CF5*(1+CG12) -> 10783.91 | ... CI5: =CH5*(1+CI12) -> 11219.58
B6: Mission Systems | AI6: 2589 | AJ6: 2588 | AK6: 2436 | AL6: =10134-SUM(AI6:AK6) -> 2521 | AM6: 2497 | AN6: 2516 | AO6: 2456 | AP6: =10396-SUM(AM6:AO6) -> 2927 | AQ6: 2563 | AR6: 2641 | AS6: 2628 | AT6: =10895-SUM(AQ6:AS6) -> 3063 | AU6: 2659 | AV6: 2773 | AW6: 2823 | AX6: =11399-SUM(AU6:AW6) -> 3144 | AY6: 2807 | AZ6: 3157 | BA6: 3093 | BB6: =12506-SUM(AY6:BA6) -> 3449 | BC6: 2861 | BD6: 3250 | BE6: 3155 | BU6: =SUM(AI6:AL6) -> 10134 | BV6: =SUM(AM6:AP6) -> 10396 | BW6: =SUM(AQ6:AT6) -> 10895 | BX6: =SUM(AU6:AX6) -> 11399 | BY6: =SUM(AY6:BB6) -> 12506 | BZ6: =BY6*(1+BZ13) -> 12881.18 | CA6: =BZ6*(1+CA13) -> 13254.734 | CB6: =CA6*(1+CB13) -> 13625.867 | CC6: =CB6*(1+CC13) -> 13993.765 | CD6: =CC6*(1+CD13) -> 14357.603 | CE6: =CD6*(1+CE13) -> 14716.543 | CF6: =CE6*(1+CF13) -> 15069.74 | CG6: =CF6*(1+CG13) -> 15416.344 | ... CI6: =CH6*(1+CI13) -> 16086.369
B7: Space Systems | AI7: 2521 | AJ7: 2748 | AK7: 2681 | AL7: =10608-SUM(AI7:AK7) -> 2658 | AM7: 2855 | AN7: 2979 | AO7: 3163 | AP7: =12275-SUM(AM7:AO7) -> 3278 | AQ7: 3350 | AR7: 3488 | AS7: 2953 | AT7: =11873-SUM(AQ7:AS7) -> 2082 | AU7: 3149 | AV7: 3002 | AW7: 2870 | AX7: =11731-SUM(AU7:AW7) -> 2710 | AY7: 2568 | AZ7: 2646 | BA7: 2698 | BB7: =10771-SUM(AY7:BA7) -> 2859 | BC7: 2480 | BD7: 2753 | BE7: 2749 | BU7: =SUM(AI7:AL7) -> 10608 | BV7: =SUM(AM7:AP7) -> 12275 | BW7: =SUM(AQ7:AT7) -> 11873 | BX7: =SUM(AU7:AX7) -> 11731 | BY7: =SUM(AY7:BB7) -> 10771 | BZ7: =BY7*(1+BZ14) -> 10878.71 | CA7: =BZ7*(1+CA14) -> 11205.071 | CB7: =CA7*(1+CB14) -> 11765.325 | CC7: =CB7*(1+CC14) -> 12294.764 | CD7: =CC7*(1+CD14) -> 12786.555 | CE7: =CD7*(1+CE14) -> 13234.084 | CF7: =CE7*(1+CF14) -> 13631.107 | CG7: =CF7*(1+CG14) -> 13971.885 | ... CI7: =CH7*(1+CI14) -> 14465.092
B8: Intersegment Eliminations | AI8: =-44-185-237-39 -> -505 | AJ8: =-45-195-254-31 -> -525 | AK8: =-48-206-244-33 -> -531 | AL8: =-189-789-993-139-SUM(AI8:AK8) -> -549 | AM8: =-65-199-246-31 -> -541 | AN8: =-58-174-259-31 -> -522 | AO8: =-58-194-250-28 -> -530 | AP8: =-239-806-1015-119-SUM(AM8:AO8) -> -586 | AQ8: =-65-169-237-32 -> -503 | AR8: =-64-195-283-26 -> -568 | AS8: =-54-197-263-108 -> -622 | AT8: =-139-151-1054-483-SUM(AQ8:AS8) -> -134 | AU8: =-32-42-277-105 -> -456 | AV8: =-34-45-297-100 -> -476 | AW8: =-33-43-275-107 -> -458 | AX8: =-132-171-1177-412-SUM(AU8:AW8) -> -502 | AY8: =-41-45-335-105 -> -526 | AZ8: =-38-53-341-125 -> -557 | BA8: =-42-51-339-137 -> -569 | BB8: =-167-210-1434-506-SUM(AY8:BA8) -> -665 | BC8: =-34-52-385-171 -> -642 | BD8: =-41-55-464-179 -> -739 | BE8: -664 | BU8: =SUM(AI8:AL8) -> -2110 | BV8: =SUM(AM8:AP8) -> -2179 | BW8: =SUM(AQ8:AT8) -> -1827 | BX8: =SUM(AU8:AX8) -> -1892 | BY8: =SUM(AY8:BB8) -> -2317 | BZ8: =BY8*(1+BZ15) -> -2896.25 | CA8: =BZ8*(1+CA15) -> -2954.175 | CB8: =CA8*(1+CB15) -> -3013.2585 | CC8: =CB8*(1+CC15) -> -3073.5237 | CD8: =CC8*(1+CD15) -> -3134.9941 | CE8: =CD8*(1+CE15) -> -3197.694 | CF8: =CE8*(1+CF15) -> -3261.6479 | CG8: =CF8*(1+CG15) -> -3326.8809 | ... CI8: =CH8*(1+CI15) -> -3461.2869
B9: Ttl Revenues | AI9: =SUM(AI4:AI7)+AI8 -> 9157 | AJ9: =SUM(AJ4:AJ7)+AJ8 -> 9151 | AK9: =SUM(AK4:AK7)+AK8 -> 8720 | AL9: =SUM(AL4:AL7)+AL8 -> 8639 | AM9: =SUM(AM4:AM7)+AM8 -> 8797 | AN9: =SUM(AN4:AN7)+AN8 -> 8801 | AO9: =SUM(AO4:AO7)+AO8 -> 8971 | AP9: =SUM(AP4:AP7)+AP8 -> 10033 | ... BE9: =SUM(BE4:BE7)+BE8 -> 11122 | BU9: =SUM(AI9:AL9) -> 35667 | BV9: =SUM(AM9:AP9) -> 36602 | BW9: =SUM(AQ9:AT9) -> 39290 | BX9: =SUM(AU9:AX9) -> 41033 | BY9: =SUM(AY9:BB9) -> 41954 | BZ9: =SUM(BZ4:BZ8) -> 44276.67 | CA9: =SUM(CA4:CA8) -> 46977.965 | CB9: =SUM(CB4:CB8) -> 49197.962 | CC9: =SUM(CC4:CC8) -> 50886.604 | CD9: =SUM(CD4:CD8) -> 52421.163 | CE9: =SUM(CE4:CE8) -> 53854.273 | CF9: =SUM(CF4:CF8) -> 55174.012 | CG9: =SUM(CG4:CG8) -> 56369.253 | ... CI9: =SUM(CI4:CI8) -> 58493.28
B11: Aeronautics Growth Y/y | AM11: =AM4/AI4-1 -> -0.095986622 | AN11: =AN4/AJ4-1 -> -0.13010642 | AO11: =AO4/AK4-1 -> -0.068990826 | AP11: =AP4/AL4-1 -> 0.047890536 | AQ11: =AQ4/AM4-1 -> -0.069552349 | AR11: =AR4/AN4-1 -> 0.024072612 | AS11: =AS4/AO4-1 -> 0.090264091 | AT11: =AT4/AP4-1 -> 0.19260065 | ... BE11: =BE4/BA4-1 -> 0.13781031 | BV11: =BV4/BU4-1 -> -0.064659384 | BW11: =BW4/BV4-1 -> 0.060108252 | BX11: =BX4/BW4-1 -> 0.11035471 | BY11: =BY4/BX4-1 -> 0.048080026 | BZ11: 0.14 | CA11: 0.11 | CB11: 0.06 | CC11: 0.03 | CD11: 0.025 | CE11: 0.0225 | CF11: 0.02 | CG11: 0.0175 | CH11: 0.017 | CI11: 0.0165
B12: Defense Growth Y/y | AM12: =AM5/AI5-1 -> -0.17861716 | AN12: =AN5/AJ5-1 -> -0.093202523 | AO12: =AO5/AK5-1 -> -0.045422285 | AP12: =AP5/AL5-1 -> 0.20246734 | AQ12: =AQ5/AM5-1 -> 0.07248636 | AR12: =AR5/AN5-1 -> 0.097372488 | AS12: =AS5/AO5-1 -> 0.52416357 | AT12: =AT5/AP5-1 -> 0.41158721 | ... BE12: =BE5/BA5-1 -> 0.12044682 | BV12: =BV5/BU5-1 -> -0.034106648 | BW12: =BW5/BV5-1 -> 0.28786521 | BX12: =BX5/BW5-1 -> 0.029784273 | BY12: =BY5/BX5-1 -> 0.0814975 | BZ12: 0.075 | CA12: 0.05 | CB12: 0.04 | CC12: 0.035 | CD12: 0.03 | CE12: 0.0275 | CF12: 0.025 | CG12: 0.0225 | CH12: 0.02 | CI12: 0.02
B13: Mission Systems Growth Y/y | AM13: =AM6/AI6-1 -> -0.035534956 | AN13: =AN6/AJ6-1 -> -0.027820711 | AO13: =AO6/AK6-1 -> 0.0082101806 | AP13: =AP6/AL6-1 -> 0.1610472 | AQ13: =AQ6/AM6-1 -> 0.026431718 | AR13: =AR6/AN6-1 -> 0.049682035 | AS13: =AS6/AO6-1 -> 0.070032573 | AT13: =AT6/AP6-1 -> 0.046463956 | ... BE13: =BE6/BA6-1 -> 0.020045263 | BV13: =BV6/BU6-1 -> 0.025853562 | BW13: =BW6/BV6-1 -> 0.04799923 | BX13: =BX6/BW6-1 -> 0.046259752 | BY13: =BY6/BX6-1 -> 0.097113782 | BZ13: 0.03 | CA13: 0.029 | CB13: 0.028 | CC13: 0.027 | CD13: 0.026 | CE13: 0.025 | CF13: 0.024 | CG13: 0.023 | CH13: 0.022 | CI13: 0.021
B14: Space Systems Growth Y/y | AM14: =AM7/AI7-1 -> 0.13248711 | AN14: =AN7/AJ7-1 -> 0.084061135 | AO14: =AO7/AK7-1 -> 0.17978366 | AP14: =AP7/AL7-1 -> 0.23325809 | AQ14: =AQ7/AM7-1 -> 0.17338004 | AR14: =AR7/AN7-1 -> 0.17086271 | AS14: =AS7/AO7-1 -> -0.066392665 | AT14: =AT7/AP7-1 -> -0.36485662 | ... BE14: =BE7/BA7-1 -> 0.018902891 | BV14: =BV7/BU7-1 -> 0.15714555 | BW14: =BW7/BV7-1 -> -0.032749491 | BX14: =BX7/BW7-1 -> -0.011959909 | BY14: =BY7/BX7-1 -> -0.081834456 | BZ14: 0.01 | CA14: 0.03 | CB14: 0.05 | CC14: 0.045 | CD14: 0.04 | CE14: 0.035 | CF14: 0.03 | CG14: 0.025 | CH14: 0.02 | CI14: 0.015
B15: Intersegment Eliminations Growth Y/y | AM15: =AM8/AI8-1 -> 0.071287129 | AN15: =AN8/AJ8-1 -> -0.0057142857 | AO15: =AO8/AK8-1 -> -0.0018832392 | AP15: =AP8/AL8-1 -> 0.067395264 | AQ15: =AQ8/AM8-1 -> -0.070240296 | AR15: =AR8/AN8-1 -> 0.088122605 | AS15: =AS8/AO8-1 -> 0.17358491 | AT15: =AT8/AP8-1 -> -0.77133106 | ... BE15: =BE8/BA8-1 -> 0.16695958 | BV15: =BV8/BU8-1 -> 0.032701422 | BW15: =BW8/BV8-1 -> -0.16154199 | BX15: =BX8/BW8-1 -> 0.035577449 | BY15: =BY8/BX8-1 -> 0.22463002 | BZ15: 0.25 | CA15: 0.02 | CB15: 0.02 | CC15: 0.02 | CD15: 0.02 | CE15: 0.02 | CF15: 0.02 | CG15: 0.02 | CH15: 0.02 | CI15: 0.02
B16: Ttl Revenue Growth Y/y | AM16: =AM9/AI9-1 -> -0.039314186 | AN16: =AN9/AJ9-1 -> -0.038247186 | AO16: =AO9/AK9-1 -> 0.028784404 | AP16: =AP9/AL9-1 -> 0.16136127 | AQ16: =AQ9/AM9-1 -> 0.057292259 | AR16: =AR9/AN9-1 -> 0.088058175 | AS16: =AS9/AO9-1 -> 0.089622116 | AT16: =AT9/AP9-1 -> 0.060301007 | ... BE16: =BE9/BA9-1 -> 0.067063226 | BV16: =BV9/BU9-1 -> 0.026214708 | BW16: =BW9/BV9-1 -> 0.07343861 | BX16: =BX9/BW9-1 -> 0.044362433 | BY16: =BY9/BX9-1 -> 0.022445349 | BZ16: =BZ9/BY9-1 -> 0.055362302 | CA16: =CA9/BZ9-1 -> 0.06100944 | CB16: =CB9/CA9-1 -> 0.047256145 | CC16: =CC9/CB9-1 -> 0.034323403 | ... CI16: =CI9/CH9-1 -> 0.017824967
B18: Aeronautics % of Ttl Revenues | AI18: =AI4/AI9 -> 0.32652615 | AJ18: =AJ4/AJ9 -> 0.31832587 | AK18: =AK4/AK9 -> 0.3125 | AL18: =AL4/AL9 -> 0.30454914 | AM18: =AM4/AM9 -> 0.30726384 | AN18: =AN4/AN9 -> 0.28792183 | AO18: =AO4/AO9 -> 0.28280013 | AP18: =AP4/AP9 -> 0.27479318 | ... BE18: =BE4/BE9 -> 0.32143499 | BU18: =BU4/BU9 -> 0.31566995 | BV18: =BV4/BV9 -> 0.28771652 | BW18: =BW4/BW9 -> 0.28414355 | BX18: =BX4/BX9 -> 0.30209831 | BY18: =BY4/BY9 -> 0.3096725
B19: Defense % of Ttl Revenues | AI19: =AI5/AI9 -> 0.17057988 | AJ19: =AJ5/AJ9 -> 0.15593924 | AK19: =AK5/AK9 -> 0.16158257 | AL19: =AL5/AL9 -> 0.1595092 | AM19: =AM5/AM9 -> 0.14584517 | AN19: =AN5/AN9 -> 0.14702875 | AO19: =AO5/AO9 -> 0.14992754 | AP19: =AP5/AP9 -> 0.16515499 | ... BE19: =BE5/BE9 -> 0.20742672 | BU19: =BU5/BU9 -> 0.16194241 | BV19: =BV5/BV9 -> 0.15242336 | BW19: =BW5/BW9 -> 0.18287096 | BX19: =BX5/BX9 -> 0.18031828 | BY19: =BY5/BY9 -> 0.19073271
B20: Mission Systems % of Ttl Revenues | AI20: =AI6/AI9 -> 0.28273452 | AJ20: =AJ6/AJ9 -> 0.28281062 | AK20: =AK6/AK9 -> 0.2793578 | AL20: =AL6/AL9 -> 0.29181618 | AM20: =AM6/AM9 -> 0.28384677 | AN20: =AN6/AN9 -> 0.2858766 | AO20: =AO6/AO9 -> 0.27377104 | AP20: =AP6/AP9 -> 0.29173727 | ... BE20: =BE6/BE9 -> 0.283672 | BU20: =BU6/BU9 -> 0.28412819 | BV20: =BV6/BV9 -> 0.2840282 | BW20: =BW6/BW9 -> 0.27729702 | BX20: =BX6/BX9 -> 0.27780079 | BY20: =BY6/BY9 -> 0.29808838
B21: Space Systems % of Ttl Revenues | AI21: =AI7/AI9 -> 0.27530851 | AJ21: =AJ7/AJ9 -> 0.30029505 | AK21: =AK7/AK9 -> 0.30745413 | AL21: =AL7/AL9 -> 0.3076745 | AM21: =AM7/AM9 -> 0.32454246 | AN21: =AN7/AN9 -> 0.33848426 | AO21: =AO7/AO9 -> 0.35258054 | AP21: =AP7/AP9 -> 0.32672182 | ... BE21: =BE7/BE9 -> 0.24716778 | BU21: =BU7/BU9 -> 0.29741778 | BV21: =BV7/BV9 -> 0.33536419 | BW21: =BW7/BW9 -> 0.30218885 | BX21: =BX7/BX9 -> 0.28589184 | BY21: =BY7/BY9 -> 0.25673357
B22: Intersegment Eliminations % of Revenue | AI22: =AI8/AI9 -> -0.055149066 | AJ22: =AJ8/AJ9 -> -0.057370779 | AK22: =AK8/AK9 -> -0.060894495 | AL22: =AL8/AL9 -> -0.063549022 | AM22: =AM8/AM9 -> -0.061498238 | AN22: =AN8/AN9 -> -0.059311442 | AO22: =AO8/AO9 -> -0.059079255 | AP22: =AP8/AP9 -> -0.058407256 | ... BE22: =BE8/BE9 -> -0.059701493 | BU22: =BU8/BU9 -> -0.059158326 | BV22: =BV8/BV9 -> -0.059532266 | BW22: =BW8/BW9 -> -0.046500382 | BX22: =BX8/BX9 -> -0.046109229 | BY22: =BY8/BY9 -> -0.055227154
B24: U.S. | AI24: 7799 | AJ24: 7943 | AK24: 7535 | AL24: =30685-SUM(AI24:AK24) -> 7408 | AM24: 7656 | AN24: 7646 | AO24: 7761 | AP24: =31754-SUM(AM24:AO24) -> 8691 | AQ24: 8135 | AR24: 8374 | AS24: 8536 | AT24: =34385-SUM(AQ24:AS24) -> 9340 | AU24: 8971 | AV24: 9033 | AW24: 8778 | AX24: =36033-SUM(AU24:AW24) -> 9251 | AY24: 8182 | AZ24: 8950 | BA24: 8820 | BB24: =35964-SUM(AY24:BA24) -> 10012 | BC24: 8600 | BD24: 9333 | BE24: 9639 | BU24: =SUM(AI24:AL24) -> 30685 | BV24: =SUM(AM24:AP24) -> 31754 | BW24: =SUM(AQ24:AT24) -> 34385 | BX24: =SUM(AU24:AX24) -> 36033 | BY24: =SUM(AY24:BB24) -> 35964
B25: APAC | AI25: 558 | AJ25: 441 | AK25: 470 | AL25: =1939-SUM(AI25:AK25) -> 470 | AM25: 463 | AN25: 489 | AO25: 469 | AP25: =1802-SUM(AM25:AO25) -> 381 | AQ25: 376 | AR25: 397 | AS25: 376 | AT25: =1568-SUM(AQ25:AS25) -> 419 | AU25: 359 | AV25: 377 | AW25: 378 | AX25: =1552-SUM(AU25:AW25) -> 438 | AY25: 417 | AZ25: 452 | BA25: 504 | BB25: =1919-SUM(AY25:BA25) -> 546 | BC25: 442 | BD25: 536 | BE25: 483 | BU25: =SUM(AI25:AL25) -> 1939 | BV25: =SUM(AM25:AP25) -> 1802 | BW25: =SUM(AQ25:AT25) -> 1568 | BX25: =SUM(AU25:AX25) -> 1552 | BY25: =SUM(AY25:BB25) -> 1919
B26: Euro | AI26: 533 | AJ26: 537 | AK26: 498 | AL26: =2107-SUM(AI26:AK26) -> 539 | AM26: 503 | AN26: 483 | AO26: 543 | AP26: =2252-SUM(AM26:AO26) -> 723 | AQ26: 547 | AR26: 601 | AS26: 640 | AT26: =2455-SUM(AQ26:AS26) -> 667 | AU26: 676 | AV26: 667 | AW26: 685 | AX26: =2837-SUM(AU26:AW26) -> 809 | AY26: 704 | AZ26: 752 | BA26: 918 | BB26: =3286-SUM(AY26:BA26) -> 912 | BC26: 686 | BD26: 828 | BE26: 810 | BU26: =SUM(AI26:AL26) -> 2107 | BV26: =SUM(AM26:AP26) -> 2252 | BW26: =SUM(AQ26:AT26) -> 2455 | BX26: =SUM(AU26:AX26) -> 2837 | BY26: =SUM(AY26:BB26) -> 3286
B27: Other regions | AI27: 267 | AJ27: 230 | AK27: 217 | AL27: =936-SUM(AI27:AK27) -> 222 | AM27: 175 | AN27: 183 | AO27: 198 | AP27: =794-SUM(AM27:AO27) -> 238 | AQ27: 243 | AR27: 204 | AS27: 223 | AT27: =882-SUM(AQ27:AS27) -> 212 | AU27: 127 | AV27: 141 | AW27: 155 | AX27: =611-SUM(AU27:AW27) -> 188 | AY27: 165 | AZ27: 197 | BA27: 181 | BB27: =785-SUM(AY27:BA27) -> 242 | BC27: 153 | BD27: 179 | BE27: 190 | BU27: =SUM(AI27:AL27) -> 936 | BV27: =SUM(AM27:AP27) -> 794 | BW27: =SUM(AQ27:AT27) -> 882 | BX27: =SUM(AU27:AX27) -> 611 | BY27: =SUM(AY27:BB27) -> 785
B28: Ttl Revenues | AI28: =SUM(AI24:AI27) -> 9157 | AJ28: =SUM(AJ24:AJ27) -> 9151 | AK28: =SUM(AK24:AK27) -> 8720 | AL28: =SUM(AL24:AL27) -> 8639 | AM28: =SUM(AM24:AM27) -> 8797 | AN28: =SUM(AN24:AN27) -> 8801 | AO28: =SUM(AO24:AO27) -> 8971 | AP28: =SUM(AP24:AP27) -> 10033 | ... BE28: =SUM(BE24:BE27) -> 11122 | BU28: =SUM(AI28:AL28) -> 35667 | BV28: =SUM(AM28:AP28) -> 36602 | BW28: =SUM(AQ28:AT28) -> 39290 | BX28: =SUM(AU28:AX28) -> 41033 | BY28: =SUM(AY28:BB28) -> 41954
B30: U.S. Growth Y/y | AM30: =AM24/AI24-1 -> -0.018335684 | AN30: =AN24/AJ24-1 -> -0.037391414 | AO30: =AO24/AK24-1 -> 0.029993364 | AP30: =AP24/AL24-1 -> 0.17319114 | AQ30: =AQ24/AM24-1 -> 0.062565308 | AR30: =AR24/AN24-1 -> 0.095213183 | AS30: =AS24/AO24-1 -> 0.099858266 | AT30: =AT24/AP24-1 -> 0.074674951 | ... BE30: =BE24/BA24-1 -> 0.092857143 | BV30: =BV24/BU24-1 -> 0.034837869 | BW30: =BW24/BV24-1 -> 0.082855703 | BX30: =BX24/BW24-1 -> 0.047927876 | BY30: =BY24/BX24-1 -> -0.0019149113
B31: APAC Growth Y/y | AM31: =AM25/AI25-1 -> -0.1702509 | AN31: =AN25/AJ25-1 -> 0.10884354 | AO31: =AO25/AK25-1 -> -0.0021276596 | AP31: =AP25/AL25-1 -> -0.1893617 | AQ31: =AQ25/AM25-1 -> -0.18790497 | AR31: =AR25/AN25-1 -> -0.18813906 | AS31: =AS25/AO25-1 -> -0.19829424 | AT31: =AT25/AP25-1 -> 0.099737533 | ... BE31: =BE25/BA25-1 -> -0.041666667 | BV31: =BV25/BU25-1 -> -0.070654977 | BW31: =BW25/BV25-1 -> -0.12985572 | BX31: =BX25/BW25-1 -> -0.010204082 | BY31: =BY25/BX25-1 -> 0.23646907
B32: Euro Growth Y/y | AM32: =AM26/AI26-1 -> -0.056285178 | AN32: =AN26/AJ26-1 -> -0.10055866 | AO32: =AO26/AK26-1 -> 0.090361446 | AP32: =AP26/AL26-1 -> 0.34137291 | AQ32: =AQ26/AM26-1 -> 0.087475149 | AR32: =AR26/AN26-1 -> 0.24430642 | AS32: =AS26/AO26-1 -> 0.1786372 | AT32: =AT26/AP26-1 -> -0.077455048 | ... BE32: =BE26/BA26-1 -> -0.11764706 | BV32: =BV26/BU26-1 -> 0.068818225 | BW32: =BW26/BV26-1 -> 0.090142096 | BX32: =BX26/BW26-1 -> 0.15560081 | BY32: =BY26/BX26-1 -> 0.15826577
B33: Other Revenue Growth Y/y | AM33: =AM27/AI27-1 -> -0.34456929 | AN33: =AN27/AJ27-1 -> -0.20434783 | AO33: =AO27/AK27-1 -> -0.087557604 | AP33: =AP27/AL27-1 -> 0.072072072 | AQ33: =AQ27/AM27-1 -> 0.38857143 | AR33: =AR27/AN27-1 -> 0.1147541 | AS33: =AS27/AO27-1 -> 0.12626263 | AT33: =AT27/AP27-1 -> -0.1092437 | ... BE33: =BE27/BA27-1 -> 0.049723757 | BV33: =BV27/BU27-1 -> -0.1517094 | BW33: =BW27/BV27-1 -> 0.11083123 | BX33: =BX27/BW27-1 -> -0.30725624 | BY33: =BY27/BX27-1 -> 0.28477905
B34: Ttl Revenue Growth Y/y | AM34: =AM28/AI28-1 -> -0.039314186 | AN34: =AN28/AJ28-1 -> -0.038247186 | AO34: =AO28/AK28-1 -> 0.028784404 | AP34: =AP28/AL28-1 -> 0.16136127 | AQ34: =AQ28/AM28-1 -> 0.057292259 | AR34: =AR28/AN28-1 -> 0.088058175 | AS34: =AS28/AO28-1 -> 0.089622116 | AT34: =AT28/AP28-1 -> 0.060301007 | ... BE34: =BE28/BA28-1 -> 0.067063226 | BV34: =BV28/BU28-1 -> 0.026214708 | BW34: =BW28/BV28-1 -> 0.07343861 | BX34: =BX28/BW28-1 -> 0.044362433 | BY34: =BY28/BX28-1 -> 0.022445349
B36: U.S. % of Revenues | AI36: =AI24/AI28 -> 0.85169815 | AJ36: =AJ24/AJ28 -> 0.86799257 | AK36: =AK24/AK28 -> 0.8641055 | AL36: =AL24/AL28 -> 0.85750666 | AM36: =AM24/AM28 -> 0.87029669 | AN36: =AN24/AN28 -> 0.86876491 | AO36: =AO24/AO28 -> 0.86512095 | AP36: =AP24/AP28 -> 0.8662414 | ... BE36: =BE24/BE28 -> 0.86666067 | BU36: =BU24/BU28 -> 0.86031906 | BV36: =BV24/BV28 -> 0.86754822 | BW36: =BW24/BW28 -> 0.87515907 | BX36: =BX24/BX28 -> 0.87814686 | BY36: =BY24/BY28 -> 0.85722458
B37: APAC % of Revenues | AI37: =AI25/AI28 -> 0.060936988 | AJ37: =AJ25/AJ28 -> 0.048191454 | AK37: =AK25/AK28 -> 0.053899083 | AL37: =AL25/AL28 -> 0.054404445 | AM37: =AM25/AM28 -> 0.052631579 | AN37: =AN25/AN28 -> 0.055561868 | AO37: =AO25/AO28 -> 0.052279567 | AP37: =AP25/AP28 -> 0.037974684 | ... BE37: =BE25/BE28 -> 0.043427441 | BU37: =BU25/BU28 -> 0.054363978 | BV37: =BV25/BV28 -> 0.049232282 | BW37: =BW25/BW28 -> 0.039908374 | BX37: =BX25/BX28 -> 0.037823215 | BY37: =BY25/BY28 -> 0.045740573
B38: Euro % of Revenues | AI38: =AI26/AI28 -> 0.058206836 | AJ38: =AJ26/AJ28 -> 0.058682111 | AK38: =AK26/AK28 -> 0.057110092 | AL38: =AL26/AL28 -> 0.06239148 | AM38: =AM26/AM28 -> 0.057178584 | AN38: =AN26/AN28 -> 0.054880127 | AO38: =AO26/AO28 -> 0.060528369 | AP38: =AP26/AP28 -> 0.072062195 | ... BE38: =BE26/BE28 -> 0.072828628 | BU38: =BU26/BU28 -> 0.059074214 | BV38: =BV26/BV28 -> 0.061526693 | BW38: =BW26/BW28 -> 0.062484093 | BX38: =BX26/BX28 -> 0.069139473 | BY38: =BY26/BY28 -> 0.078323879
B39: Other regions % of Revenues | AI39: =AI27/AI28 -> 0.029158021 | AJ39: =AJ27/AJ28 -> 0.025133865 | AK39: =AK27/AK28 -> 0.024885321 | AL39: =AL27/AL28 -> 0.025697419 | AM39: =AM27/AM28 -> 0.019893145 | AN39: =AN27/AN28 -> 0.020793092 | AO39: =AO27/AO28 -> 0.022071118 | AP39: =AP27/AP28 -> 0.023721718 | ... BE39: =BE27/BE28 -> 0.017083258 | BU39: =BU27/BU28 -> 0.026242745 | BV39: =BV27/BV28 -> 0.021692804 | BW39: =BW27/BW28 -> 0.02244846 | BX39: =BX27/BX28 -> 0.014890454 | BY39: =BY27/BY28 -> 0.018710969
B41: Revenues | C41: 6104 | D41: 6294 | E41: 6106 | F41: 6157 | G41: 5848 | H41: 6039 | I41: 5984 | J41: 6108 | K41: 5957 | L41: 5896 | M41: 5979 | N41: 5694 | O41: 5956 | P41: 6000 | Q41: 6155 | R41: 6595 | S41: 6410 | T41: 6473 | U41: 6569 | V41: 6552 | W41: 6735 | X41: 7119 | Y41: 8085 | Z41: 8156 | AA41: 8189 | AB41: 8456 | AC41: 8475 | AD41: 8721 | AE41: 8620 | AF41: 8884 | AG41: 9083 | AH41: 10212 | AI41: 9157 | AJ41: 9151 | AK41: 8720 | AL41: 8639 | AM41: 8797 | AN41: 8801 | AO41: 8971 | AP41: 10033 | AQ41: =AQ9 -> 9301 | AR41: =AR9 -> 9576 | AS41: =AS9 -> 9775 | AT41: =AT9 -> 10638 | AU41: =AU9 -> 10133 | AV41: =AV9 -> 10218 | AW41: =AW9 -> 9996 | AX41: =AX9 -> 10686 | ... BE41: =BE9 -> 11122 | BM41: =SUM(C41:F41) -> 24661 | BN41: =SUM(G41:J41) -> 23979 | BO41: =SUM(K41:N41) -> 23526 | BP41: =SUM(O41:R41) -> 24706 | BQ41: =SUM(S41:V41) -> 26004 | BR41: =SUM(W41:Z41) -> 30095 | BS41: =SUM(AA41:AD41) -> 33841 | BT41: =SUM(AE41:AH41) -> 36799 | BU41: =SUM(AI41:AL41) -> 35667 | BV41: =SUM(AM41:AP41) -> 36602 | BW41: =SUM(AQ41:AT41) -> 39290 | BX41: =SUM(AU41:AX41) -> 41033 | BY41: =SUM(AY41:BB41) -> 41954 | BZ41: =BZ9 -> 44276.67 | CA41: =CA9 -> 46977.965 | CB41: =CB9 -> 49197.962 | CC41: =CC9 -> 50886.604 | CD41: =CD9 -> 52421.163 | CE41: =CE9 -> 53854.273 | CF41: =CF9 -> 55174.012 | CG41: =CG9 -> 56369.253 | ... CI41: =CI9 -> 58493.28
B42: COGS | C42: 4787 | D42: 4906 | E42: 4761 | F42: 4828 | G42: 4461 | H42: 4629 | I42: 4635 | J42: 4653 | K42: 4542 | L42: 4442 | M42: 4522 | N42: 4378 | O42: 4561 | P42: 4583 | Q42: 4667 | R42: 4986 | S42: 4850 | T42: 4914 | U42: 5053 | V42: 5257 | W42: 5176 | X42: 5563 | Y42: 6096 | Z42: 6469 | AA42: 6493 | AB42: 6726 | AC42: 6748 | AD42: 6615 | AE42: 6898 | AF42: 7058 | AG42: 7243 | AH42: 8122 | AI42: 7417 | AJ42: 7108 | AK42: 6786 | AL42: 7088 | AM42: 6924 | AN42: 6842 | AO42: 7153 | AP42: 8209 | AQ42: =5727+1589 -> 7316 | AR42: =5876+1660 -> 7536 | AS42: =6135+1599 -> 7734 | AT42: =26226+6513-SUM(AQ42:AS42) -> 10153 | AU42: =6411+1589 -> 8000 | AV42: =6388+1639 -> 8027 | AW42: =6280+1610 -> 7890 | AX42: =26188+6483-SUM(AU42:AW42) -> 8754 | AY42: =6366+1522 -> 7888 | AZ42: =6526+1615 -> 8141 | BA42: =6631+1565 -> 8196 | BB42: =27280+6361-SUM(AY42:BA42) -> 9416 | BC42: =6433+1488 -> 7921 | BD42: =7155+1600 -> 8755 | BE42: =7198+1572 -> 8770 | BM42: =SUM(C42:F42) -> 19282 | BN42: =SUM(G42:J42) -> 18378 | BO42: =SUM(K42:N42) -> 17884 | BP42: =SUM(O42:R42) -> 18797 | BQ42: =SUM(S42:V42) -> 20074 | BR42: =SUM(W42:Z42) -> 23304 | BS42: =SUM(AA42:AD42) -> 26582 | BT42: =SUM(AE42:AH42) -> 29321 | BU42: =SUM(AI42:AL42) -> 28399 | BV42: =SUM(AM42:AP42) -> 29128 | BW42: =SUM(AQ42:AT42) -> 32739 | BX42: =SUM(AU42:AX42) -> 32671 | BY42: =SUM(AY42:BB42) -> 33641 | BZ42: =BZ41*(1-BZ55) -> 35503.443 | CA42: =CA41*(1-CA55) -> 37347.482 | CB42: =CB41*(1-CB55) -> 38866.39 | CC42: =CC41*(1-CC55) -> 39945.984 | CD42: =CD41*(1-CD55) -> 40888.507 | CE42: =CE41*(1-CE55) -> 41952.479 | CF42: =CF41*(1-CF55) -> 42925.382 | CG42: =CG41*(1-CG55) -> 43798.91 | ... CI42: =CI41*(1-CI55) -> 45332.292
B43: GP | C43: =C41-C42 -> 1317 | D43: =D41-D42 -> 1388 | E43: =E41-E42 -> 1345 | F43: =F41-F42 -> 1329 | G43: =G41-G42 -> 1387 | H43: =H41-H42 -> 1410 | I43: =I41-I42 -> 1349 | J43: =J41-J42 -> 1455 | ... BE43: =BE41-BE42 -> 2352 | BM43: =SUM(C43:F43) -> 5379 | BN43: =SUM(G43:J43) -> 5601 | BO43: =SUM(K43:N43) -> 5642 | BP43: =SUM(O43:R43) -> 5909 | BQ43: =SUM(S43:V43) -> 5930 | BR43: =SUM(W43:Z43) -> 6791 | BS43: =SUM(AA43:AD43) -> 7259 | BT43: =SUM(AE43:AH43) -> 7478 | BU43: =SUM(AI43:AL43) -> 7268 | BV43: =SUM(AM43:AP43) -> 7474 | BW43: =SUM(AQ43:AT43) -> 6551 | BX43: =SUM(AU43:AX43) -> 8362 | BY43: =SUM(AY43:BB43) -> 8313 | BZ43: =BZ41-BZ42 -> 8773.2268 | CA43: =CA41-CA42 -> 9630.4828 | CB43: =CB41-CB42 -> 10331.572 | CC43: =CC41-CC42 -> 10940.62 | CD43: =CD41-CD42 -> 11532.656 | CE43: =CE41-CE42 -> 11901.794 | CF43: =CF41-CF42 -> 12248.631 | CG43: =CG41-CG42 -> 12570.343 | ... CI43: =CI41-CI42 -> 13160.988
B44: G&A | C44: 558 | D44: 582 | E44: 555 | F44: 561 | G44: 542 | H44: 590 | I44: 580 | J44: 693 | K44: 635 | L44: 641 | M44: 663 | N44: 627 | O44: 656 | P44: 620 | Q44: 662 | R44: 694 | S44: 698 | T44: 686 | U44: 679 | V44: 649 | W44: 711 | X44: 739 | Y44: 817 | Z44: 744 | AA44: 760 | AB44: 784 | AC44: 776 | AD44: 970 | AE44: 788 | AF44: 832 | AG44: 855 | AH44: 938 | AI44: 898 | AJ44: 999 | AK44: 891 | AL44: 809 | AM44: 976 | AN44: 1005 | AO44: 974 | AP44: 918 | AQ44: 1038 | AR44: 1073 | AS44: 1025 | AT44: =4014-SUM(AQ44:AS44) -> 878 | AU44: 1062 | AV44: 1101 | AW44: 986 | AX44: =3992-SUM(AU44:AW44) -> 843 | AY44: 1007 | AZ44: 1016 | BA44: 985 | BB44: =4033-SUM(AY44:BA44) -> 1025 | BC44: 971 | BD44: 1025 | BE44: 1083 | BM44: =SUM(C44:F44) -> 2256 | BN44: =SUM(G44:J44) -> 2405 | BO44: =SUM(K44:N44) -> 2566 | BP44: =SUM(O44:R44) -> 2632 | BQ44: =SUM(S44:V44) -> 2712 | BR44: =SUM(W44:Z44) -> 3011 | BS44: =SUM(AA44:AD44) -> 3290 | BT44: =SUM(AE44:AH44) -> 3413 | BU44: =SUM(AI44:AL44) -> 3597 | BV44: =SUM(AM44:AP44) -> 3873 | BW44: =SUM(AQ44:AT44) -> 4014 | BX44: =SUM(AU44:AX44) -> 3992 | BY44: =SUM(AY44:BB44) -> 4033 | BZ44: =BZ41*BZ56 -> 4256.2762 | CA44: =CA41*CA56 -> 4515.9492 | CB44: =CB41*CB56 -> 4729.3555 | CC44: =CC41*CC56 -> 4891.6831 | CD44: =CD41*CD56 -> 5039.1989 | CE44: =CE41*CE56 -> 5176.9625 | CF44: =CF41*CF56 -> 5303.8278 | CG44: =CG41*CG56 -> 5418.7252 | ... CI44: =CI41*CI56 -> 5622.906
B45: OI | C45: =C43-C44 -> 759 | D45: =D43-D44 -> 806 | E45: =E43-E44 -> 790 | F45: =F43-F44 -> 768 | G45: =G43-G44 -> 845 | H45: =H43-H44 -> 820 | I45: =I43-I44 -> 769 | J45: =J43-J44 -> 762 | ... AY45: =AY43-AY44 -> 573 | AZ45: =AZ43-AZ44+231 -> 1425 | BA45: =BA43-BA44 -> 1242 | BB45: =BB43-BB44 -> 1271 | BC45: =BC43-BC44 -> 989 | BD45: =BD43-BD44 -> 1096 | BE45: =BE43-BE44 -> 1269 | BM45: =SUM(C45:F45) -> 3123 | BN45: =SUM(G45:J45) -> 3196 | BO45: =SUM(K45:N45) -> 3076 | BP45: =SUM(O45:R45) -> 3277 | BQ45: =SUM(S45:V45) -> 3218 | BR45: =SUM(W45:Z45) -> 3780 | BS45: =SUM(AA45:AD45) -> 3969 | BT45: =SUM(AE45:AH45) -> 4065 | BU45: =SUM(AI45:AL45) -> 3671 | BV45: =SUM(AM45:AP45) -> 3601 | BW45: =SUM(AQ45:AT45) -> 2537 | BX45: =SUM(AU45:AX45) -> 4370 | BY45: =SUM(AY45:BB45) -> 4511 | BZ45: =BZ43-BZ44 -> 4516.9507 | CA45: =CA43-CA44 -> 5114.5336 | CB45: =CB43-CB44 -> 5602.2166 | CC45: =CC43-CC44 -> 6048.9367 | CD45: =CD43-CD44 -> 6493.457 | CE45: =CE43-CE44 -> 6724.8319 | CF45: =CF43-CF44 -> 6944.8029 | CG45: =CG43-CG44 -> 7151.6183 | ... CI45: =CI43-CI44 -> 7538.082
B46: Interest Expenses | C46: 0 | D46: 0 | E46: 0 | F46: 0 | G46: 0 | H46: 0 | I46: 0 | J46: 0 | K46: 0 | L46: 0 | M46: 0 | N46: 0 | O46: 0 | P46: 0 | Q46: 0 | R46: 0 | S46: 0 | T46: 0 | U46: 0 | V46: 0 | W46: 0 | X46: 0 | Y46: 0 | Z46: 0 | AA46: 0 | AB46: 0 | AC46: 0 | AD46: 0 | AE46: 0 | AF46: 0 | AG46: 0 | AH46: 0 | AI46: 0 | AJ46: 0 | AK46: 0 | AL46: 0 | AM46: 0 | AN46: 0 | AO46: 0 | AP46: 0 | AQ46: -129 | AR46: -147 | AS46: -141 | AT46: =-545-SUM(AQ46:AS46) -> -128 | AU46: -146 | AV46: -154 | AW46: -161 | AX46: =-621-SUM(AU46:AW46) -> -160 | AY46: -156 | AZ46: -173 | BA46: -161 | BB46: =-665-SUM(AY46:BA46) -> -175 | BC46: -162 | BD46: -161 | BE46: -158 | BM46: =SUM(C46:F46) -> 0 | BN46: =SUM(G46:J46) -> 0 | BO46: =SUM(K46:N46) -> 0 | BP46: =SUM(O46:R46) -> 0 | BQ46: =SUM(S46:V46) -> 0 | BR46: =SUM(W46:Z46) -> 0 | BS46: =SUM(AA46:AD46) -> 0 | BT46: =SUM(AE46:AH46) -> 0 | BU46: =SUM(AI46:AL46) -> 0 | BV46: =SUM(AM46:AP46) -> 0 | BW46: =SUM(AQ46:AT46) -> -545 | BX46: =SUM(AU46:AX46) -> -621 | BY46: =SUM(AY46:BB46) -> -665 | BZ46: =(-BY78)*$CN$78 -> -637.515 | CA46: =(-BZ78)*$CN$78 -> -608.82682 | CB46: =(-CA78)*$CN$78 -> -581.42962 | CC46: =(-CB78)*$CN$78 -> -555.26529 | CD46: =(-CC78)*$CN$78 -> -530.27835 | CE46: =(-CD78)*$CN$78 -> -506.41582 | CF46: =(-CE78)*$CN$78 -> -483.62711 | CG46: =(-CF78)*$CN$78 -> -461.86389 | ... CI46: =(-CH78)*$CN$78 -> -421.23141
...

Sheet Notes | Quant Analysis
CI1: 0
P2: Employee Scope: | AL2: General Notes/Observations
AL35: Financial Stmts. Notes/Observations
P36: Institutional Ownership Snapshot | AL36: Revenues:
P69: Revenue Breakdown by Segment | AL69: Earnings Scope:
Q101: Notes: | R101: [X]
R102: [Y]
R103: [Z]
P105: Revenue Breakdown by Segment | AL105: Balance Sheet Scope:
Q137: Notes: | R137: [X]
R138: [Y] | AL138: [Equity Preformance Compared to Peers]
R139: [Z]
P141: Q/q Total Revenues, Net Income, FCF
Q170: Notes: | R170: [X]
R171: [Y]
R172: [Z]
P174: Y/y Total Revenues, Net Income, FCF
Q203: Notes: | R203: [X]
R204: [Y]
R205: [Z]
A220: VOO Historical Returns | I220: NOC Historical Returns
A221: 1256 Trading Days? (From: 9/30/2020 - 9/30/2026) | I221: 1256 Trading Days? (From: 9/30/2020 - 9/30/2026)
A222: Close | B222: High | C222: Low | D222: Open | E222: Volume | F222: UTC Date | G222: Change | I222: Close | J222: High | K222: Low | L222: Open | M222: Volume | N222: UTC Date | O222: Change
A223: 605.40586 | B223: 605.8804 | C223: 601.34267 | D223: 602.48946 | E223: 6556087.5 | F223: Tue, 30 Sep 2025 00:00:00 GMT | G223: =A223/D223-1 -> 0.0048405887 | I223: 599.54549 | J223: 600.33266 | K223: 583.58569 | L223: 583.58569 | M223: 815710.35 | N223: Tue, 30 Sep 2025 00:00:00 GMT | O223: =I223/L223-1 -> 0.027347833
A224: 603.18149 | B224: 604.71384 | C224: 601.55028 | D224: 603.83397 | E224: 5724023.5 | F224: Mon, 29 Sep 2025 00:00:00 GMT | G224: =A224/D224-1 -> -0.0010805678 | I224: 584.46141 | J224: 594.43383 | K224: 582.0212 | L224: 588.71211 | M224: 789810.88 | N224: Mon, 29 Sep 2025 00:00:00 GMT | O224: =I224/L224-1 -> -0.0072203373
A225: 601.49096 | B225: 602.02329 | C225: 597.94704 | D225: 599.39123 | E225: 6531431.3 | F225: Fri, 26 Sep 2025 00:00:00 GMT | G225: =A225/D225-1 -> 0.0035031166 | I225: 584.98291 | J225: 585.41585 | K225: 577.43595 | L225: 580.0336 | M225: 519347.19 | N225: Fri, 26 Sep 2025 00:00:00 GMT | O225: =I225/L225-1 -> 0.0085327995
A226: 597.97168 | B226: 599.29265 | C226: 594.77772 | D226: 598.00126 | E226: 7027592.7 | F226: Thu, 25 Sep 2025 00:00:00 GMT | G226: =A226/D226-1 -> -4.9454354e-05 | I226: 576.37327 | J226: 584.22526 | K226: 573.14097 | L226: 580.53542 | M226: 1062869.2 | N226: Thu, 25 Sep 2025 00:00:00 GMT | O226: =I226/L226-1 -> -0.0071694915
A227: 600.84034 | B227: 604.03431 | C227: 599.54895 | D227: 603.92587 | E227: 24106581 | F227: Wed, 24 Sep 2025 00:00:00 GMT | G227: =A227/D227-1 -> -0.0051091197 | I227: 576.86525 | J227: 580.14184 | K227: 567.74396 | L227: 571.32557 | M227: 796791.87 | N227: Wed, 24 Sep 2025 00:00:00 GMT | O227: =I227/L227-1 -> 0.0096961973
A228: 602.85136 | B228: 606.5185 | C228: 601.66939 | D228: 605.97139 | E228: 10883179 | F228: Tue, 23 Sep 2025 00:00:00 GMT | G228: =A228/D228-1 -> -0.0051488112 | I228: 567.82268 | J228: 571.35017 | K228: 561.91893 | L228: 566.76 | M228: 666890.03 | N228: Tue, 23 Sep 2025 00:00:00 GMT | O228: =I228/L228-1 -> 0.001875
A229: 606.02561 | B229: 606.47907 | C229: 601.83599 | D229: 601.84585 | E229: 11718075 | F229: Mon, 22 Sep 2025 00:00:00 GMT | G229: =A229/D229-1 -> 0.0069448994 | I229: 566.9076 | J229: 568.38107 | K229: 561.11208 | L229: 564.48706 | M229: 547755.92 | N229: Mon, 22 Sep 2025 00:00:00 GMT | O229: =I229/L229-1 -> 0.0042880301
A230: 603.08795 | B230: 603.9653 | C230: 600.19957 | D230: 601.94443 | E230: 6153076.7 | F230: Fri, 19 Sep 2025 00:00:00 GMT | G230: =A230/D230-1 -> 0.0018997085 | I230: 563.83765 | J230: 566.9076 | K230: 556.42844 | L230: 562.73561 | M230: 1502482.3 | N230: Fri, 19 Sep 2025 00:00:00 GMT | O230: =I230/L230-1 -> 0.0019583501
A231: 600.2883 | B231: 602.62462 | C231: 598.44486 | D231: 599.90384 | E231: 11188190 | F231: Thu, 18 Sep 2025 00:00:00 GMT | G231: =A231/D231-1 -> 0.00064086764 | I231: 564.5461 | J231: 567.72428 | K231: 559.2032 | L231: 562.82417 | M231: 795871.1 | N231: Thu, 18 Sep 2025 00:00:00 GMT | O231: =I231/L231-1 -> 0.0030594406
A232: 597.47879 | B232: 599.68696 | C232: 593.00329 | D232: 598.21813 | E232: 11781010 | F232: Wed, 17 Sep 2025 00:00:00 GMT | G232: =A232/D232-1 -> -0.0012359106 | I232: 567.82268 | J232: 575.61563 | K232: 567.14384 | L232: 569.81027 | M232: 803154.94 | N232: Wed, 17 Sep 2025 00:00:00 GMT | O232: =I232/L232-1 -> -0.0034881713
A233: 598.16884 | B233: 599.77568 | C233: 597.4501 | D233: 599.51938 | E233: 6458919.1 | F233: Tue, 16 Sep 2025 00:00:00 GMT | G233: =A233/D233-1 -> -0.0022526967 | I233: 570.0661 | J233: 577.81969 | K233: 566.7108 | L233: 568.72792 | M233: 1122505.9 | N233: Tue, 16 Sep 2025 00:00:00 GMT | O233: =I233/L233-1 -> 0.0023529412
A234: 598.95748 | B234: 599.13492 | C234: 597.58723 | D234: 597.85339 | E234: 7554466.4 | F234: Mon, 15 Sep 2025 00:00:00 GMT | G234: =A234/D234-1 -> 0.0018467525 | I234: 565.32342 | J234: 567.22246 | K234: 561.95337 | L234: 564.79209 | M234: 808521.02 | N234: Mon, 15 Sep 2025 00:00:00 GMT | O234: =I234/L234-1 -> 0.00094076655
A235: 595.85223 | B235: 597.37035 | C235: 595.36919 | D235: 596.0001 | E235: 8225559.2 | F235: Fri, 12 Sep 2025 00:00:00 GMT | G235: =A235/D235-1 -> -0.00024810202 | I235: 566.72064 | J235: 573.77562 | K235: 565.95316 | L235: 572.9983 | M235: 627500.15 | N235: Fri, 12 Sep 2025 00:00:00 GMT | O235: =I235/L235-1 -> -0.010955799
A236: 595.98038 | B236: 596.63101 | C236: 592.35267 | D236: 592.885 | E236: 9217770.3 | F236: Thu, 11 Sep 2025 00:00:00 GMT | G236: =A236/D236-1 -> 0.0052208902 | I236: 573.59851 | J236: 576.36344 | K236: 568.72792 | L236: 570.0169 | M236: 912824.22 | N236: Thu, 11 Sep 2025 00:00:00 GMT | O236: =I236/L236-1 -> 0.0062833371 | R236: Min | S236: =MIN(O223:O1478) -> -0.063566673
A237: 591.15986 | B237: 593.20045 | C237: 589.66146 | D237: 592.38224 | E237: 21852838 | F237: Wed, 10 Sep 2025 00:00:00 GMT | G237: =A237/D237-1 -> -0.0020635026 | I237: 570.56792 | J237: 571.52236 | K237: 560.85625 | L237: 562.07636 | M237: 515502.52 | N237: Wed, 10 Sep 2025 00:00:00 GMT | O237: =I237/L237-1 -> 0.015107485 | R237: Max | S237: =MAX(O223:O1478) -> 0.067171924
A238: 589.45444 | B238: 589.86847 | C238: 586.55621 | D238: 588.13348 | E238: 7892245.5 | F238: Tue, 09 Sep 2025 00:00:00 GMT | G238: =A238/D238-1 -> 0.0022460234 | I238: 562.4601 | J238: 571.17797 | K238: 562.27315 | L238: 571.14846 | M238: 480849.63 | N238: Tue, 09 Sep 2025 00:00:00 GMT | O238: =I238/L238-1 -> -0.015212073 | R238: Mean μ | S238: =AVERAGE(O223:O1478) -> 0.00031000386
A239: 588.02504 | B239: 588.92211 | C239: 586.57593 | D239: 587.83774 | E239: 9584467.3 | F239: Mon, 08 Sep 2025 00:00:00 GMT | G239: =A239/D239-1 -> 0.00031862622 | I239: 572.56536 | J239: 572.79167 | K239: 562.19935 | L239: 565.7662 | M239: 799143.59 | N239: Mon, 08 Sep 2025 00:00:00 GMT | O239: =I239/L239-1 -> 0.0120176 | R239: Median | S239: =MEDIAN(O223:O1478) -> 0.00054112784
...

Sheet Product Lines

Sheet Economics

Sheet Management

Sheet Table Formatting
B2: [Bold Title] | G2: [Bold Title]
B3: Line Titles | G3: <-- General
B4: Line Titles | G4: <-- Info
B5: Line Titles | G5: <-- General
B6: Line Titles | G6: <-- Info
B7: Line Titles | G7: <-- General
B8: Line Titles | G8: <-- Info
