Workbook

Sheet Main
B2: ORCL
B3: Price | C3: 141.4 | D3: 10/9/2026
B4: SO | C4: 2966 | D4: Q2'26
B5: MC | C5: =C3*C4 -> 419392.4
B6: Cash | C6: =36369+708 -> 37077 | D6: Q2'26
B7: Debt | C7: =7625+117712 -> 125337 | D7: Q2'26
B8: EV | C8: =C5-C6+C7 -> 507652.4
B10: Oracle Corporation (ORCL)
B12: Founder(s): Larry Ellison, Bob Miner, and Ed Oates | G12: Registered Exchange: NYSE | N12: Resources:
B13: Founded: 1977 | G13: Address: 2300 Oracle Way, Austin TX 78741 U.S. | N13: SEC filings | Q13: https://www.sec.gov/edgar/browse/?CIK=1341439&owner=exclude
B14: Headquarters: Austin, TX | G14: Investor Relations Contact: | N14: Company Homepage | Q14: https://www.oracle.com/
B15: Current CEO: Safra Catz | G15: Investors Relation Department | O15: Company IR Page | R15: https://investor.oracle.com/home/default.aspx
B16: Employees: 162,000 (Q4'24) | G16: Phone: | H16: (650) 506-4073 | J16: Email: | K16: investor_us@oracle.com | N16: Earnings Calls | Q16: https://seekingalpha.com/symbol/ORCL#source=content_type%3Aall%7Csection%3Asearch_enter%7Csection_asset%3Asearch-basic%7Csearch_item%3Aorcl%7Crow_num%3A0%7CURL_first_level%3Asymbol%7Ctopic%3Akeyword
B17: Industry: Software - Infrastructure | N17: Equity Analysis | Q17: https://stockanalysis.com/stocks/orcl/company/
B18: Sector: Technology | N18: MacroTrends | Q18: https://www.macrotrends.net/stocks/charts/ORCL/oracle/income-statement?freq=Q
B19: IPO: March 12, 1986 | N19: ROIC, WACC | Q19: https://www.gurufocus.com/term/wacc/ORCL
B20: Fiscal Year: [June - May] | N20: Godel Terminal | Q20: https://app.godelterminal.com/
A22: Company Overview:
B23: Oracle operates through three primary business segments, each aligned to a single operating segment:
C24: Cloud and License:
D25: The largest segment, encompassing Oracle’s Fusion Cloud Applications (ERP, HCM, SCM, EPM, and industry solutions), Oracle Cloud Infrastructure (OCI), as well as on‑premise license and support. OCI includes autonomous database, compute, storage, networking, and AI/ML tools.
D26: Strong base of license support contracts and hardware support provides a substantial recurring revenue stream
C27: Hardware:
D28: Sales of Oracle Engineered Systems, servers, storage solutions, and industry‑specific hardware. Most hardware buyers also purchase recurring hardware support contracts
C29: Services:
D30: Professional consulting, advanced customer support, and implementation assistance to maximize customer ROI from Oracle deployments
B31: Oracle Corporation has a strategic alliance with Metron, Inc.
B32: Oracle’s growth strategy centers on Oracle Cloud Services:
C33: Cloud growth is central to long‑term valuation, with multi‑year R&D and acquisition investments directed toward expanding market share
C34: Oracle Cloud Applications (OCA) – Integrated enterprise software suite across ERP, HCM, SCM, EPM, and CRM (Sales, Service, Marketing)
C35: Oracle Cloud Infrastructure (OCI) – Infrastructure‑as‑a‑Service competing with AWS, Microsoft Azure, and Google Cloud
D36: OCI is highly differentiated by its Exadata Cloud@Customer deployments, enabling cloud infrastructure within a customer’s datacenter
C37: Oracle emphasizes flexibility via three deployment models: cloud‑based, on‑premise, or hybrid, giving customers choice in migrating workloads
D38: This interoperability is positioned as a competitive advantage relative to peers with more restrictive models
B39: Oracle serves a diversified global base of customers including Enterprises of all sizes, Government Agencies (that is their roots after all), Academic Institutions, and Resellers & Partners
C40: Use cases span AI companies training generative models on OCI, multinational financial firms migrating banking applications to Oracle Exadata Cloud@Customer, and consumer product companies adopting Fusion ERP for global operations
B41: Oracle competes across enterprise applications (against SAP, Workday, Salesforce, Microsoft Dynamics) and cloud infrastructure (against AWS, Azure, Google Cloud)
A43: Business Segments and Geographical Info:

Sheet Model
B1: Fiscal Year: [June - May] | AM1: Q1 2021 | AQ1: Q1 2022 | AU1: Q1 2023 | AY1: Q1 2024 | BC1: Q1 2025 | BG1: Q1 2026 | BK1: Q1 2027
B2: Quarterly | C2: Sept. | D2: Dec. | E2: Mar. | F2: June | G2: Sept. | H2: Dec. | I2: Mar. | J2: June | K2: Sept. | L2: Dec. | M2: Mar. | N2: June | O2: Sept. | P2: Dec. | Q2: Mar. | R2: June | S2: Sept. | T2: Dec. | U2: Mar. | V2: June | W2: Sept. | X2: Dec. | Y2: Mar. | Z2: June | AA2: Sept. | AB2: Dec. | AC2: Mar. | AD2: June | AE2: Sept. | AF2: Dec. | AG2: Mar. | AH2: June | AI2: Sept. | AJ2: Dec. | AK2: Mar. | AL2: June | AM2: Sept. | AN2: Dec. | AO2: Mar. | AP2: June | AQ2: Sept. | AR2: Dec. | AS2: Mar. | AT2: June | AU2: Sept. | AV2: Dec. | AW2: Mar. | AX2: June | AY2: Sept. | AZ2: Dec. | BA2: Mar. | BB2: June | BC2: Sept. | BD2: Dec. | BE2: Mar. | BF2: June | BG2: Sept. | BH2: Dec. | BI2: Mar. | BJ2: June | BK2: Sept. | BL2: Dec. | BM2: Mar. | BN2: June
B3: Revenues | C3: Q1 2012 | D3: Q2 2012 | E3: Q3 2012 | F3: Q4 2012 | G3: Q1 2013 | H3: Q2 2013 | I3: Q3 2013 | J3: Q4 2013 | K3: Q1 2014 | L3: Q2 2014 | M3: Q3 2014 | N3: Q4 2014 | O3: Q1 2015 | P3: Q2 2015 | Q3: Q3 2015 | R3: Q4 2015 | S3: Q1 2016 | T3: Q2 2016 | U3: Q3 2016 | V3: Q4 2016 | W3: Q1 2017 | X3: Q2 2017 | Y3: Q3 2017 | Z3: Q4 2017 | AA3: Q1 2018 | AB3: Q2 2018 | AC3: Q3 2018 | AD3: Q4 2018 | AE3: Q1 2019 | AF3: Q2 2019 | AG3: Q3 2019 | AH3: Q4 2019 | AI3: Q1 2020 | AJ3: Q2 2020 | AK3: Q3 2020 | AL3: Q4 2020 | AM3: Q1 2021 | AN3: Q2 2021 | AO3: Q3 2021 | AP3: Q4 2021 | AQ3: Q1 2022 | AR3: Q2 2022 | AS3: Q3 2022 | AT3: Q4 2022 | AU3: Q1 2023 | AV3: Q2 2023 | AW3: Q3 2023 | AX3: Q4 2023 | AY3: Q1 2024 | AZ3: Q2 2024 | BA3: Q3 2024 | BB3: Q4 2024 | BC3: Q1 2025 | BD3: Q2 2025 | BE3: Q3 2025 | BF3: Q4 2025 | BG3: Q1 2026 | BH3: Q2 2026 | BI3: Q3 2026 | BJ3: Q4 2026 | BK3: Q1 2027 | BL3: Q2 2027 | BM3: Q3 2027 | BN3: Q4 2027 | BS3: 2012 | BT3: =BS3+1 -> 2013 | BU3: =BT3+1 -> 2014 | BV3: =BU3+1 -> 2015 | BW3: =BV3+1 -> 2016 | BX3: =BW3+1 -> 2017 | BY3: =BX3+1 -> 2018 | BZ3: =BY3+1 -> 2019 | CA3: =BZ3+1 -> 2020 | ... EO3: =EN3+1 -> 2086
B4: Cloud | BC4: 5623 | BD4: 5937 | BE4: 6210 | BF4: =24506-SUM(BC4:BE4) -> 6736 | BG4: 7186 | BH4: 7977 | BI4: 8914 | BJ4: =33989-SUM(BG4:BI4) -> 9912 | BK4: 11607 | CE4: =19774-SUM(AY4:BA4) -> 19774 | CF4: =SUM(BC4:BF4) -> 24506 | CG4: =SUM(BG4:BJ4) -> 33989 | CH4: =CG4*(1+CH10) -> 53872.565 | CI4: =CH4*(1+CI10) -> 93468.9 | CJ4: =CI4*(1+CJ10) -> 126183.02 | CK4: =CJ4*(1+CK10) -> 161514.26 | CL4: =CK4*(1+CL10) -> 197047.4 | CM4: =CL4*(1+CM10) -> 228574.98 | CN4: =CM4*(1+CN10) -> 256003.98 | CO4: =CN4*(1+CO10) -> 276484.3 | ... CQ4: =CP4*(1+CQ10) -> 304796.29
B5: Software | BC5: 5766 | BD5: 6064 | BE5: 5926 | BF5: =24724-SUM(BC5:BE5) -> 6968 | BG5: 5721 | BH5: 5877 | BI5: 6119 | BJ5: =24541-SUM(BG5:BI5) -> 6824 | BK5: 5550 | CE5: =24690-SUM(AY5:BA5) -> 24690 | CF5: =SUM(BC5:BF5) -> 24724 | CG5: =SUM(BG5:BJ5) -> 24541 | CH5: =CG5*(1+CH11) -> 25768.05 | CI5: =CH5*(1+CI11) -> 26283.411 | CJ5: =CI5*(1+CJ11) -> 27597.582 | CK5: =CJ5*(1+CK11) -> 28977.461 | CL5: =CK5*(1+CL11) -> 30426.334 | CM5: =CL5*(1+CM11) -> 31947.65 | CN5: =CM5*(1+CN11) -> 33545.033 | CO5: =CN5*(1+CO11) -> 35222.285 | ... CQ5: =CP5*(1+CQ11) -> 38832.569
B6: Hardware | BC6: 655 | BD6: 728 | BE6: 703 | BF6: =2936-SUM(BC6:BE6) -> 850 | BG6: 670 | BH6: 776 | BI6: 714 | BJ6: =3084-SUM(BG6:BI6) -> 924 | BK6: 774 | CE6: =3066-SUM(AY6:BA6) -> 3066 | CF6: =SUM(BC6:BF6) -> 2936 | CG6: =SUM(BG6:BJ6) -> 3084 | CH6: =CG6*(1+CH12) -> 3284.46 | CI6: =CH6*(1+CI12) -> 3520.9411 | CJ6: =CI6*(1+CJ12) -> 3742.7604 | CK6: =CJ6*(1+CK12) -> 3948.6122 | CL6: =CK6*(1+CL12) -> 4161.8373 | CM6: =CL6*(1+CM12) -> 4378.2528 | CN6: =CM6*(1+CN12) -> 4597.1655 | CO6: =CN6*(1+CO12) -> 4808.6351 | ... CQ6: =CP6*(1+CQ12) -> 5211.0217
B7: Services | BC7: 1263 | BD7: 1330 | BE7: 1291 | BF7: =5233-SUM(BC7:BE7) -> 1349 | BG7: 1349 | BH7: 1428 | BI7: 1443 | BJ7: =5743-SUM(BG7:BI7) -> 1523 | BK7: 1414 | CE7: =5431-SUM(AY7:BA7) -> 5431 | CF7: =SUM(BC7:BF7) -> 5233 | CG7: =SUM(BG7:BJ7) -> 5743 | CH7: =CG7*(1+CH13) -> 6374.73 | CI7: =CH7*(1+CI13) -> 7203.4449 | CJ7: =CI7*(1+CJ13) -> 8283.9616 | CK7: =CJ7*(1+CK13) -> 9443.7163 | CL7: =CK7*(1+CL13) -> 10671.399 | CM7: =CL7*(1+CM13) -> 11845.253 | CN7: =CM7*(1+CN13) -> 12911.326 | CO7: =CN7*(1+CO13) -> 13815.119 | ... CQ7: =CP7*(1+CQ13) -> 14941.051
B8: Ttl Revenues | BC8: =SUM(BC4:BC7) -> 13307 | BD8: =SUM(BD4:BD7) -> 14059 | BE8: =SUM(BE4:BE7) -> 14130 | BF8: =SUM(BF4:BF7) -> 15903 | BG8: =SUM(BG4:BG7) -> 14926 | BH8: =SUM(BH4:BH7) -> 16058 | BI8: =SUM(BI4:BI7) -> 17190 | BJ8: =SUM(BJ4:BJ7) -> 19183 | BK8: =SUM(BK4:BK7) -> 19345 | CE8: =SUM(CE4:CE7) -> 52961 | CF8: =SUM(BC8:BF8) -> 57399 | CG8: =SUM(BG8:BJ8) -> 67357 | CH8: =SUM(CH4:CH7) -> 89299.805 | CI8: =SUM(CI4:CI7) -> 130476.7 | CJ8: =SUM(CJ4:CJ7) -> 165807.32 | CK8: =SUM(CK4:CK7) -> 203884.05 | CL8: =SUM(CL4:CL7) -> 242306.97 | CM8: =SUM(CM4:CM7) -> 276746.14 | CN8: =SUM(CN4:CN7) -> 307057.5 | CO8: =SUM(CO4:CO7) -> 330330.33 | ... CQ8: =SUM(CQ4:CQ7) -> 363780.93
B10: Cloud Growth Y/y | BG10: =BG4/BC4-1 -> 0.2779655 | BH10: =BH4/BD4-1 -> 0.34360788 | BI10: =BI4/BE4-1 -> 0.43542673 | BJ10: =BJ4/BF4-1 -> 0.47149644 | BK10: =BK4/BG4-1 -> 0.61522405 | CF10: =CF4/CE4-1 -> 0.23930414 | CG10: =CG4/CF4-1 -> 0.38696646 | CH10: 0.585 | CI10: 0.735 | CJ10: 0.35 | CK10: 0.28 | CL10: 0.22 | CM10: 0.16 | CN10: 0.12 | CO10: 0.08 | CP10: 0.06 | CQ10: 0.04
B11: Software Growth Y/y | BG11: =BG5/BC5-1 -> -0.0078043704 | BH11: =BH5/BD5-1 -> -0.030837731 | BI11: =BI5/BE5-1 -> 0.032568343 | BJ11: =BJ5/BF5-1 -> -0.020665901 | BK11: =BK5/BG5-1 -> -0.029889879 | CF11: =CF5/CE5-1 -> 0.0013770757 | CG11: =CG5/CF5-1 -> -0.0074017149 | CH11: 0.05 | CI11: 0.02 | CJ11: 0.05 | CK11: 0.05 | CL11: 0.05 | CM11: 0.05 | CN11: 0.05 | CO11: 0.05 | CP11: 0.05 | CQ11: 0.05
B12: Hardware Growth Y/y | BG12: =BG6/BC6-1 -> 0.022900763 | BH12: =BH6/BD6-1 -> 0.065934066 | BI12: =BI6/BE6-1 -> 0.015647226 | BJ12: =BJ6/BF6-1 -> 0.087058824 | BK12: =BK6/BG6-1 -> 0.15522388 | CF12: =CF6/CE6-1 -> -0.042400522 | CG12: =CG6/CF6-1 -> 0.050408719 | CH12: 0.065 | CI12: 0.072 | CJ12: 0.063 | CK12: 0.055 | CL12: 0.054 | CM12: 0.052 | CN12: 0.05 | CO12: 0.046 | CP12: 0.042 | CQ12: 0.04
B13: Services Growth Y/y | BG13: =BG7/BC7-1 -> 0.068091845 | BH13: =BH7/BD7-1 -> 0.073684211 | BI13: =BI7/BE7-1 -> 0.11773819 | BJ13: =BJ7/BF7-1 -> 0.12898443 | BK13: =BK7/BG7-1 -> 0.04818384 | CF13: =CF7/CE7-1 -> -0.036457374 | CG13: =CG7/CF7-1 -> 0.097458437 | CH13: 0.11 | CI13: 0.13 | CJ13: 0.15 | CK13: 0.14 | CL13: 0.13 | CM13: 0.11 | CN13: 0.09 | CO13: 0.07 | CP13: 0.05 | CQ13: 0.03
B14: Ttl Revenue Growth Y/y | BG14: =BG8/BC8-1 -> 0.12166529 | BH14: =BH8/BD8-1 -> 0.1421865 | BI14: =BI8/BE8-1 -> 0.21656051 | BJ14: =BJ8/BF8-1 -> 0.20625039 | BK14: =BK8/BG8-1 -> 0.29606057 | CF14: =CF8/CE8-1 -> 0.083797511 | CG14: =CG8/CF8-1 -> 0.17348734 | CH14: =CH8/CG8-1 -> 0.32576874 | CI14: =CI8/CH8-1 -> 0.46110842 | CJ14: =CJ8/CI8-1 -> 0.27078109 | CK14: =CK8/CJ8-1 -> 0.22964445 | CL14: =CL8/CK8-1 -> 0.18845475 | CM14: =CM8/CL8-1 -> 0.14213033 | ... CQ14: =CQ8/CP8-1 -> 0.040642999
B16: Cloud % of Ttl Revenues | BC16: =BC4/BC8 -> 0.42255956 | BD16: =BD4/BD8 -> 0.42229177 | BE16: =BE4/BE8 -> 0.43949045 | BF16: =BF4/BF8 -> 0.42356788 | BG16: =BG4/BG8 -> 0.48144178 | BH16: =BH4/BH8 -> 0.49676174 | BI16: =BI4/BI8 -> 0.5185573 | BJ16: =BJ4/BJ8 -> 0.5167075 | BK16: =BK4/BK8 -> 0.6 | CE16: =CE4/CE8 -> 0.37336908 | CF16: =CF4/CF8 -> 0.42694124 | CG16: =CG4/CG8 -> 0.50460977
B17: Software % of Ttl Revenues | BC17: =BC5/BC8 -> 0.43330578 | BD17: =BD5/BD8 -> 0.43132513 | BE17: =BE5/BE8 -> 0.41939137 | BF17: =BF5/BF8 -> 0.43815632 | BG17: =BG5/BG8 -> 0.3832909 | BH17: =BH5/BH8 -> 0.3659858 | BI17: =BI5/BI8 -> 0.35596277 | BJ17: =BJ5/BJ8 -> 0.35573164 | BK17: =BK5/BK8 -> 0.28689584 | CE17: =CE5/CE8 -> 0.4661921 | CF17: =CF5/CF8 -> 0.43073921 | CG17: =CG5/CG8 -> 0.36434224
B18: Hardware % of Ttl Revenues | BC18: =BC6/BC8 -> 0.049222214 | BD18: =BD6/BD8 -> 0.051781777 | BE18: =BE6/BE8 -> 0.0497523 | BF18: =BF6/BF8 -> 0.053449035 | BG18: =BG6/BG8 -> 0.044888115 | BH18: =BH6/BH8 -> 0.048324823 | BI18: =BI6/BI8 -> 0.041535777 | BJ18: =BJ6/BJ8 -> 0.048167648 | BK18: =BK6/BK8 -> 0.040010339 | CE18: =CE6/CE8 -> 0.057891656 | CF18: =CF6/CF8 -> 0.051150717 | CG18: =CG6/CG8 -> 0.045785887
B19: Services % of Ttl Revenues | BC19: =BC7/BC8 -> 0.094912452 | BD19: =BD7/BD8 -> 0.094601323 | BE19: =BE7/BE8 -> 0.091365888 | BF19: =BF7/BF8 -> 0.084826762 | BG19: =BG7/BG8 -> 0.090379204 | BH19: =BH7/BH8 -> 0.088927637 | BI19: =BI7/BI8 -> 0.083944154 | BJ19: =BJ7/BJ8 -> 0.079393213 | BK19: =BK7/BK8 -> 0.073093823 | CE19: =CE7/CE8 -> 0.10254716 | CF19: =CF7/CF8 -> 0.091168836 | CG19: =CG7/CG8 -> 0.085262111
B21: Revenues | C21: 8374 | D21: 8792 | E21: 9039 | F21: 10916 | G21: 8181 | H21: 9094 | I21: 8958 | J21: 10947 | K21: 8372 | L21: 9275 | M21: 9307 | N21: 11321 | O21: 8596 | P21: 9598 | Q21: 9327 | R21: 10705 | S21: 8448 | T21: 8993 | U21: 9012 | V21: 10594 | W21: 8595 | X21: 9035 | Y21: 9205 | Z21: 10957 | AA21: 9104 | AB21: 9589 | AC21: 9676 | AD21: 11014 | AE21: 9193 | AF21: 9562 | AG21: 9614 | AH21: 11137 | AI21: 9218 | AJ21: 9614 | AK21: 9796 | AL21: 10441 | AM21: 9367 | AN21: 9800 | AO21: 10086 | AP21: 11227 | AQ21: 9728 | AR21: 10360 | AS21: 10513 | AT21: 11840 | AU21: 11445 | AV21: 12275 | AW21: 12398 | AX21: 13837 | AY21: 12453 | AZ21: 12941 | BA21: 13280 | BB21: 14287 | BC21: 13307 | BD21: 14059 | BE21: 14130 | BF21: 15903 | BG21: 14926 | BH21: 16058 | BI21: 17190 | BJ21: 19183 | BK21: =BK8 -> 19345 | BS21: =SUM(C21:F21) -> 37121 | BT21: =SUM(G21:J21) -> 37180 | BU21: =SUM(K21:N21) -> 38275 | BV21: =SUM(O21:R21) -> 38226 | BW21: =SUM(S21:V21) -> 37047 | BX21: =SUM(W21:Z21) -> 37792 | BY21: =SUM(AA21:AD21) -> 39383 | BZ21: =SUM(AE21:AH21) -> 39506 | CA21: =SUM(AI21:AL21) -> 39069 | CB21: =SUM(AM21:AP21) -> 40480 | CC21: =SUM(AQ21:AT21) -> 42441 | CD21: =SUM(AU21:AX21) -> 49955 | CE21: =SUM(AY21:BB21) -> 52961 | CF21: =SUM(BC21:BF21) -> 57399 | CG21: =SUM(BG21:BJ21) -> 67357 | CH21: =CH8 -> 89299.805 | CI21: =CI8 -> 130476.7 | CJ21: =CJ8 -> 165807.32 | CK21: =CK8 -> 203884.05 | CL21: =CL8 -> 242306.97 | CM21: =CM8 -> 276746.14 | CN21: =CN8 -> 307057.5 | CO21: =CO8 -> 330330.33 | ... CQ21: =CQ8 -> 363780.93
B22: Cloud & Software Op. Ex. | C22: 0 | D22: 0 | E22: 0 | F22: 0 | G22: 0 | H22: 0 | I22: 0 | J22: 0 | K22: 0 | L22: 0 | M22: 0 | N22: 0 | O22: 0 | P22: 0 | Q22: 0 | R22: 0 | S22: 0 | T22: 0 | U22: 0 | V22: 0 | W22: 0 | X22: 0 | Y22: 0 | Z22: 0 | AA22: 0 | AB22: 0 | AC22: 0 | AD22: 0 | AE22: 0 | AF22: 0 | AG22: 0 | AH22: 0 | AI22: 0 | AJ22: 0 | AK22: 0 | AL22: 0 | AM22: 1011 | AN22: 1064 | AO22: 1064 | AP22: =4353-SUM(AM22:AO22) -> 1214 | AQ22: 1214 | AR22: 1259 | AS22: 1305 | AT22: =5213-SUM(AQ22:AS22) -> 1435 | AU22: 1735 | AV22: 1891 | AW22: 1980 | AX22: =7763-SUM(AU22:AW22) -> 2157 | AY22: 2179 | AZ22: 2274 | BA22: 2452 | BB22: =9427-SUM(AY22:BA22) -> 2522 | BC22: 2597 | BD22: 2746 | BE22: 2882 | BF22: =11569-SUM(BC22:BE22) -> 3344 | BG22: 3607 | BH22: 3990 | BI22: 4776 | BJ22: =17597-SUM(BG22:BI22) -> 5224 | BK22: 6400 | BS22: =SUM(C22:F22) -> 0 | BT22: =SUM(G22:J22) -> 0 | BU22: =SUM(K22:N22) -> 0 | BV22: =SUM(O22:R22) -> 0 | BW22: =SUM(S22:V22) -> 0 | BX22: =SUM(W22:Z22) -> 0 | BY22: =SUM(AA22:AD22) -> 0 | BZ22: =SUM(AE22:AH22) -> 0 | CA22: =SUM(AI22:AL22) -> 0 | CB22: =SUM(AM22:AP22) -> 4353 | CC22: =SUM(AQ22:AT22) -> 5213 | CD22: =SUM(AU22:AX22) -> 7763 | CE22: =SUM(AY22:BB22) -> 9427 | CF22: =SUM(BC22:BF22) -> 11569 | CG22: =SUM(BG22:BJ22) -> 17597 | CH22: =CH21*CH42 -> 25003.945 | CI22: =CI21*CI42 -> 37838.242 | CJ22: =CJ21*CJ42 -> 49742.196 | CK22: =CK21*CK42 -> 57087.534 | CL22: =CL21*CL42 -> 65422.881 | CM22: =CM21*CM42 -> 73337.726 | CN22: =CN21*CN42 -> 79834.951 | CO22: =CO21*CO42 -> 84234.235 | ... CQ22: =CQ21*CQ42 -> 89126.328
B23: Hardware Op. Ex. | C23: 0 | D23: 0 | E23: 0 | F23: 0 | G23: 0 | H23: 0 | I23: 0 | J23: 0 | K23: 0 | L23: 0 | M23: 0 | N23: 0 | O23: 0 | P23: 0 | Q23: 0 | R23: 0 | S23: 0 | T23: 0 | U23: 0 | V23: 0 | W23: 0 | X23: 0 | Y23: 0 | Z23: 0 | AA23: 0 | AB23: 0 | AC23: 0 | AD23: 0 | AE23: 0 | AF23: 0 | AG23: 0 | AH23: 0 | AI23: 0 | AJ23: 0 | AK23: 0 | AL23: 0 | AM23: 246 | AN23: 244 | AO23: 230 | AP23: =972-SUM(AM23:AO23) -> 252 | AQ23: 245 | AR23: 229 | AS23: 244 | AT23: =972-SUM(AQ23:AS23) -> 254 | AU23: 249 | AV23: 286 | AW23: 244 | AX23: =1040-SUM(AU23:AW23) -> 261 | AY23: 219 | AZ23: 213 | BA23: 217 | BB23: =891-SUM(AY23:BA23) -> 242 | BC23: 162 | BD23: 172 | BE23: 197 | BF23: =782-SUM(BC23:BE23) -> 251 | BG23: 178 | BH23: 215 | BI23: 183 | BJ23: =868-SUM(BG23:BI23) -> 292 | BK23: 281 | BS23: =SUM(C23:F23) -> 0 | BT23: =SUM(G23:J23) -> 0 | BU23: =SUM(K23:N23) -> 0 | BV23: =SUM(O23:R23) -> 0 | BW23: =SUM(S23:V23) -> 0 | BX23: =SUM(W23:Z23) -> 0 | BY23: =SUM(AA23:AD23) -> 0 | BZ23: =SUM(AE23:AH23) -> 0 | CA23: =SUM(AI23:AL23) -> 0 | CB23: =SUM(AM23:AP23) -> 972 | CC23: =SUM(AQ23:AT23) -> 972 | CD23: =SUM(AU23:AX23) -> 1040 | CE23: =SUM(AY23:BB23) -> 891 | CF23: =SUM(BC23:BF23) -> 782 | CG23: =SUM(BG23:BJ23) -> 868 | CH23: =CH21*CH43 -> 1250.1973 | CI23: =CI21*CI43 -> 1696.1971 | CJ23: =CJ21*CJ43 -> 2155.4951 | CK23: =CK21*CK43 -> 2446.6086 | CL23: =CL21*CL43 -> 2907.6836 | CM23: =CM21*CM43 -> 3044.2075 | CN23: =CN21*CN43 -> 3377.6325 | CO23: =CO21*CO43 -> 3303.3033 | ... CQ23: =CQ21*CQ43 -> 3637.8093
B24: Services Op. Ex. | C24: 0 | D24: 0 | E24: 0 | F24: 0 | G24: 0 | H24: 0 | I24: 0 | J24: 0 | K24: 0 | L24: 0 | M24: 0 | N24: 0 | O24: 0 | P24: 0 | Q24: 0 | R24: 0 | S24: 0 | T24: 0 | U24: 0 | V24: 0 | W24: 0 | X24: 0 | Y24: 0 | Z24: 0 | AA24: 0 | AB24: 0 | AC24: 0 | AD24: 0 | AE24: 0 | AF24: 0 | AG24: 0 | AH24: 0 | AI24: 0 | AJ24: 0 | AK24: 0 | AL24: 0 | AM24: 623 | AN24: 631 | AO24: 621 | AP24: =2530-SUM(AM24:AO24) -> 655 | AQ24: 644 | AR24: 671 | AS24: 669 | AT24: =2692-SUM(AQ24:AS24) -> 708 | AU24: 1053 | AV24: 1181 | AW24: 1215 | AX24: =4761-SUM(AU24:AW24) -> 1312 | AY24: 1212 | AZ24: 1253 | BA24: 1200 | BB24: =4825-SUM(AY24:BA24) -> 1160 | BC24: 1147 | BD24: 1167 | BE24: 1116 | BF24: =4576-SUM(BC24:BE24) -> 1146 | BG24: 1099 | BH24: 1169 | BI24: 1133 | BJ24: =4556-SUM(BG24:BI24) -> 1155 | BK24: 1052 | BS24: =SUM(C24:F24) -> 0 | BT24: =SUM(G24:J24) -> 0 | BU24: =SUM(K24:N24) -> 0 | BV24: =SUM(O24:R24) -> 0 | BW24: =SUM(S24:V24) -> 0 | BX24: =SUM(W24:Z24) -> 0 | BY24: =SUM(AA24:AD24) -> 0 | BZ24: =SUM(AE24:AH24) -> 0 | CA24: =SUM(AI24:AL24) -> 0 | CB24: =SUM(AM24:AP24) -> 2530 | CC24: =SUM(AQ24:AT24) -> 2692 | CD24: =SUM(AU24:AX24) -> 4761 | CE24: =SUM(AY24:BB24) -> 4825 | CF24: =SUM(BC24:BF24) -> 4576 | CG24: =SUM(BG24:BJ24) -> 4556 | CH24: =CH21*CH44 -> 5715.1875 | CI24: =CI21*CI44 -> 8480.9853 | CJ24: =CJ21*CJ44 -> 10445.861 | CK24: =CK21*CK44 -> 12640.811 | CL24: =CL21*CL44 -> 14780.725 | CM24: =CM21*CM44 -> 16604.768 | CN24: =CN21*CN44 -> 18116.393 | CO24: =CO21*CO44 -> 19159.159 | ... CQ24: =CQ21*CQ44 -> 20371.732
B25: S&M | C25: 0 | D25: 0 | E25: 0 | F25: 0 | G25: 0 | H25: 0 | I25: 0 | J25: 0 | K25: 0 | L25: 0 | M25: 0 | N25: 0 | O25: 0 | P25: 0 | Q25: 0 | R25: 0 | S25: 0 | T25: 0 | U25: 0 | V25: 0 | W25: 0 | X25: 0 | Y25: 0 | Z25: 0 | AA25: 0 | AB25: 0 | AC25: 0 | AD25: 0 | AE25: 0 | AF25: 0 | AG25: 0 | AH25: 0 | AI25: 0 | AJ25: 0 | AK25: 0 | AL25: 0 | AM25: 1854 | AN25: 1836 | AO25: 1915 | AP25: =7682-SUM(AM25:AO25) -> 2077 | AQ25: 1854 | AR25: 1954 | AS25: 2004 | AT25: =8047-SUM(AQ25:AS25) -> 2235 | AU25: 2177 | AV25: 2216 | AW25: 2150 | AX25: =8833-SUM(AU25:AW25) -> 2290 | AY25: 2026 | AZ25: 2093 | BA25: 2042 | BB25: =8274-SUM(AY25:BA25) -> 2113 | BC25: 2036 | BD25: 2190 | BE25: 2119 | BF25: =8651-SUM(BC25:BE25) -> 2306 | BG25: 2063 | BH25: 2149 | BI25: 2052 | BJ25: =8331-SUM(BG25:BI25) -> 2067 | BK25: 1811 | BS25: =SUM(C25:F25) -> 0 | BT25: =SUM(G25:J25) -> 0 | BU25: =SUM(K25:N25) -> 0 | BV25: =SUM(O25:R25) -> 0 | BW25: =SUM(S25:V25) -> 0 | BX25: =SUM(W25:Z25) -> 0 | BY25: =SUM(AA25:AD25) -> 0 | BZ25: =SUM(AE25:AH25) -> 0 | CA25: =SUM(AI25:AL25) -> 0 | CB25: =SUM(AM25:AP25) -> 7682 | CC25: =SUM(AQ25:AT25) -> 8047 | CD25: =SUM(AU25:AX25) -> 8833 | CE25: =SUM(AY25:BB25) -> 8274 | CF25: =SUM(BC25:BF25) -> 8651 | CG25: =SUM(BG25:BJ25) -> 8331 | CH25: =CH21*CH45 -> 10626.677 | CI25: =CI21*CI45 -> 15265.774 | CJ25: =CJ21*CJ45 -> 19067.842 | CK25: =CK21*CK45 -> 23242.782 | CL25: =CL21*CL45 -> 27380.687 | CM25: =CM21*CM45 -> 30995.567 | CN25: =CN21*CN45 -> 34083.383 | CO25: =CO21*CO45 -> 36336.337 | ... CQ25: =CQ21*CQ45 -> 40015.902
B26: R&D | C26: 0 | D26: 0 | E26: 0 | F26: 0 | G26: 0 | H26: 0 | I26: 0 | J26: 0 | K26: 0 | L26: 0 | M26: 0 | N26: 0 | O26: 0 | P26: 0 | Q26: 0 | R26: 0 | S26: 0 | T26: 0 | U26: 0 | V26: 0 | W26: 0 | X26: 0 | Y26: 0 | Z26: 0 | AA26: 0 | AB26: 0 | AC26: 0 | AD26: 0 | AE26: 0 | AF26: 0 | AG26: 0 | AH26: 0 | AI26: 0 | AJ26: 0 | AK26: 0 | AL26: 0 | AM26: 1589 | AN26: 1601 | AO26: 1621 | AP26: =6527-SUM(AM26:AO26) -> 1716 | AQ26: 1684 | AR26: 1754 | AS26: 1816 | AT26: =7219-SUM(AQ26:AS26) -> 1965 | AU26: 2093 | AV26: 2158 | AW26: 2146 | AX26: =8623-SUM(AU26:AW26) -> 2226 | AY26: 2216 | AZ26: 2226 | BA26: 2248 | BB26: =8915-SUM(AY26:BA26) -> 2225 | BC26: 2306 | BD26: 2471 | BE26: 2429 | BF26: =9860-SUM(BC26:BE26) -> 2654 | BG26: 2491 | BH26: 2561 | BI26: 2607 | BJ26: =10272-SUM(BG26:BI26) -> 2613 | BK26: 2401 | BS26: =SUM(C26:F26) -> 0 | BT26: =SUM(G26:J26) -> 0 | BU26: =SUM(K26:N26) -> 0 | BV26: =SUM(O26:R26) -> 0 | BW26: =SUM(S26:V26) -> 0 | BX26: =SUM(W26:Z26) -> 0 | BY26: =SUM(AA26:AD26) -> 0 | BZ26: =SUM(AE26:AH26) -> 0 | CA26: =SUM(AI26:AL26) -> 0 | CB26: =SUM(AM26:AP26) -> 6527 | CC26: =SUM(AQ26:AT26) -> 7219 | CD26: =SUM(AU26:AX26) -> 8623 | CE26: =SUM(AY26:BB26) -> 8915 | CF26: =SUM(BC26:BF26) -> 9860 | CG26: =SUM(BG26:BJ26) -> 10272 | CH26: =CH21*CH46 -> 13841.47 | CI26: =CI21*CI46 -> 19897.808 | CJ26: =CJ21*CJ46 -> 25202.712 | CK26: =CK21*CK46 -> 30786.491 | CL26: =CL21*CL46 -> 36346.045 | CM26: =CM21*CM46 -> 41235.174 | CN26: =CN21*CN46 -> 45444.51 | CO26: =CO21*CO46 -> 48558.559 | ... CQ26: =CQ21*CQ46 -> 52748.235
B27: G&A | C27: 0 | D27: 0 | E27: 0 | F27: 0 | G27: 0 | H27: 0 | I27: 0 | J27: 0 | K27: 0 | L27: 0 | M27: 0 | N27: 0 | O27: 0 | P27: 0 | Q27: 0 | R27: 0 | S27: 0 | T27: 0 | U27: 0 | V27: 0 | W27: 0 | X27: 0 | Y27: 0 | Z27: 0 | AA27: 0 | AB27: 0 | AC27: 0 | AD27: 0 | AE27: 0 | AF27: 0 | AG27: 0 | AH27: 0 | AI27: 0 | AJ27: 0 | AK27: 0 | AL27: 0 | AM27: 295 | AN27: 324 | AO27: 330 | AP27: =1254-SUM(AM27:AO27) -> 305 | AQ27: 298 | AR27: 319 | AS27: 335 | AT27: =1317-SUM(AQ27:AS27) -> 365 | AU27: 411 | AV27: 366 | AW27: 402 | AX27: =1579-SUM(AU27:AW27) -> 400 | AY27: 393 | AZ27: 375 | BA27: 377 | BB27: =1548-SUM(AY27:BA27) -> 403 | BC27: 358 | BD27: 387 | BE27: 390 | BF27: =1602-SUM(BC27:BE27) -> 467 | BG27: 376 | BH27: 409 | BI27: 389 | BJ27: =1618-SUM(BG27:BI27) -> 444 | BK27: 376 | BS27: =SUM(C27:F27) -> 0 | BT27: =SUM(G27:J27) -> 0 | BU27: =SUM(K27:N27) -> 0 | BV27: =SUM(O27:R27) -> 0 | BW27: =SUM(S27:V27) -> 0 | BX27: =SUM(W27:Z27) -> 0 | BY27: =SUM(AA27:AD27) -> 0 | BZ27: =SUM(AE27:AH27) -> 0 | CA27: =SUM(AI27:AL27) -> 0 | CB27: =SUM(AM27:AP27) -> 1254 | CC27: =SUM(AQ27:AT27) -> 1317 | CD27: =SUM(AU27:AX27) -> 1579 | CE27: =SUM(AY27:BB27) -> 1548 | CF27: =SUM(BC27:BF27) -> 1602 | CG27: =SUM(BG27:BJ27) -> 1618 | CH27: =CH21*CH47 -> 2145.0938 | CI27: =CI21*CI47 -> 3134.2147 | CJ27: =CJ21*CJ47 -> 3982.9007 | CK27: =CK21*CK47 -> 4689.3331 | CL27: =CL21*CL47 -> 5573.0602 | CM27: =CM21*CM47 -> 6365.1611 | CN27: =CN21*CN47 -> 6755.2651 | CO27: =CO21*CO47 -> 7267.2674 | ... CQ27: =CQ21*CQ47 -> 8003.1805
B28: Ammortization | C28: 0 | D28: 0 | E28: 0 | F28: 0 | G28: 0 | H28: 0 | I28: 0 | J28: 0 | K28: 0 | L28: 0 | M28: 0 | N28: 0 | O28: 0 | P28: 0 | Q28: 0 | R28: 0 | S28: 0 | T28: 0 | U28: 0 | V28: 0 | W28: 0 | X28: 0 | Y28: 0 | Z28: 0 | AA28: 0 | AB28: 0 | AC28: 0 | AD28: 0 | AE28: 0 | AF28: 0 | AG28: 0 | AH28: 0 | AI28: 0 | AJ28: 0 | AK28: 0 | AL28: 0 | AM28: 345 | AN28: 345 | AO28: 347 | AP28: =1379-SUM(AM28:AO28) -> 342 | AQ28: 303 | AR28: 299 | AS28: 279 | AT28: =1150-SUM(AQ28:AS28) -> 269 | AU28: 919 | AV28: 907 | AW28: 886 | AX28: =3582-SUM(AU28:AW28) -> 870 | AY28: 763 | AZ28: 755 | BA28: 749 | BB28: =3010-SUM(AY28:BA28) -> 743 | BC28: 624 | BD28: 591 | BE28: 548 | BF28: =2307-SUM(BC28:BE28) -> 544 | BG28: 420 | BH28: 407 | BI28: 413 | BJ28: =1671-SUM(BG28:BI28) -> 431 | BK28: 202 | BS28: =SUM(C28:F28) -> 0 | BT28: =SUM(G28:J28) -> 0 | BU28: =SUM(K28:N28) -> 0 | BV28: =SUM(O28:R28) -> 0 | BW28: =SUM(S28:V28) -> 0 | BX28: =SUM(W28:Z28) -> 0 | BY28: =SUM(AA28:AD28) -> 0 | BZ28: =SUM(AE28:AH28) -> 0 | CA28: =SUM(AI28:AL28) -> 0 | CB28: =SUM(AM28:AP28) -> 1379 | CC28: =SUM(AQ28:AT28) -> 1150 | CD28: =SUM(AU28:AX28) -> 3582 | CE28: =SUM(AY28:BB28) -> 3010 | CF28: =SUM(BC28:BF28) -> 2307 | CG28: =SUM(BG28:BJ28) -> 1671 | CH28: =CH21*CH48 -> 2215.3596 | CI28: =CI21*CI48 -> 3236.8805 | CJ28: =CJ21*CJ48 -> 4113.3665 | CK28: =CK21*CK48 -> 4893.2172 | CL28: =CL21*CL48 -> 5815.3672 | CM28: =CM21*CM48 -> 6641.9073 | CN28: =CN21*CN48 -> 7062.3226 | CO28: =CO21*CO48 -> 7597.5977 | ... CQ28: =CQ21*CQ48 -> 8366.9614
B29: Restructuring & Other Op. Ex. | C29: 0 | D29: 0 | E29: 0 | F29: 0 | G29: 0 | H29: 0 | I29: 0 | J29: 0 | K29: 0 | L29: 0 | M29: 0 | N29: 0 | O29: 0 | P29: 0 | Q29: 0 | R29: 0 | S29: 0 | T29: 0 | U29: 0 | V29: 0 | W29: 0 | X29: 0 | Y29: 0 | Z29: 0 | AA29: 0 | AB29: 0 | AC29: 0 | AD29: 0 | AE29: 0 | AF29: 0 | AG29: 0 | AH29: 0 | AI29: 0 | AJ29: 0 | AK29: 0 | AL29: 0 | AM29: =19+174 -> 193 | AN29: =76+96 -> 172 | AO29: =13+66 -> 79 | AP29: =138+431-SUM(AM29:AO29) -> 125 | AQ29: =21+38 -> 59 | AR29: =4667+32 -> 4699 | AS29: =20+19 -> 39 | AT29: =4713+191-SUM(AQ29:AS29) -> 107 | AU29: =41+144 -> 185 | AV29: =62+137 -> 199 | AW29: =37+78 -> 115 | AX29: =190+490-SUM(AU29:AW29) -> 181 | AY29: =11+138 -> 149 | AZ29: =47+83 -> 130 | BA29: =155+90 -> 245 | BB29: =718-SUM(AY29:BA29) -> 194 | BC29: =13+73 -> 86 | BD29: =31+84 -> 115 | BE29: =28+63 -> 91 | BF29: =374-SUM(BC29:BE29) -> 82 | BG29: =13+402 -> 415 | BH29: =21+406 -> 427 | BI29: =20+153 -> 173 | BJ29: =1838-SUM(BG29:BI29) -> 823 | BK29: 94 | BS29: =SUM(C29:F29) -> 0 | BT29: =SUM(G29:J29) -> 0 | BU29: =SUM(K29:N29) -> 0 | BV29: =SUM(O29:R29) -> 0 | BW29: =SUM(S29:V29) -> 0 | BX29: =SUM(W29:Z29) -> 0 | BY29: =SUM(AA29:AD29) -> 0 | BZ29: =SUM(AE29:AH29) -> 0 | CA29: =SUM(AI29:AL29) -> 0 | CB29: =SUM(AM29:AP29) -> 569 | CC29: =SUM(AQ29:AT29) -> 4904 | CD29: =SUM(AU29:AX29) -> 680 | CE29: =SUM(AY29:BB29) -> 718 | CF29: =SUM(BC29:BF29) -> 374 | CG29: =SUM(BG29:BJ29) -> 1838 | CH29: =CH21*CH49 -> 4018.4912 | CI29: =CI21*CI49 -> 7176.2184 | CJ29: =CJ21*CJ49 -> 11606.512 | CK29: =CK21*CK49 -> 12233.043 | CL29: =CL21*CL49 -> 12115.348 | CM29: =CM21*CM49 -> 11069.845 | CN29: =CN21*CN49 -> 10747.013 | CO29: =CO21*CO49 -> 10735.736 | ... CQ29: =CQ21*CQ49 -> 10003.976
B30: Ttl Op. Ex. | C30: 5691 | D30: 5681 | E30: 5722 | F30: 6321 | G30: 5302 | H30: 5623 | I30: 5624 | J30: 5947 | K30: 5499 | L30: 5865 | M30: 5740 | N30: 6412 | O30: 5633 | P30: 6056 | Q30: 5944 | R30: 6722 | S30: 5794 | T30: 6038 | U30: 5985 | V30: 6626 | W30: 5954 | X30: 5998 | Y30: 6246 | Z30: 6681 | AA30: 6355 | AB30: 6550 | AC30: 6361 | AD30: 6853 | AE30: 6415 | AF30: 6461 | AG30: 6215 | AH30: 6880 | AI30: 6341 | AJ30: 6431 | AK30: 6268 | AL30: 6132 | AM30: =SUM(AM22:AM29) -> 6156 | AN30: =SUM(AN22:AN29) -> 6217 | AO30: =SUM(AO22:AO29) -> 6207 | AP30: =SUM(AP22:AP29) -> 6686 | AQ30: =SUM(AQ22:AQ29) -> 6301 | AR30: =SUM(AR22:AR29) -> 11184 | AS30: =SUM(AS22:AS29) -> 6691 | AT30: =SUM(AT22:AT29) -> 7338 | ... BK30: =SUM(BK22:BK29) -> 12617 | BS30: =SUM(C30:F30) -> 23415 | BT30: =SUM(G30:J30) -> 22496 | BU30: =SUM(K30:N30) -> 23516 | BV30: =SUM(O30:R30) -> 24355 | BW30: =SUM(S30:V30) -> 24443 | BX30: =SUM(W30:Z30) -> 24879 | BY30: =SUM(AA30:AD30) -> 26119 | BZ30: =SUM(AE30:AH30) -> 25971 | CA30: =SUM(AI30:AL30) -> 25172 | CB30: =SUM(AM30:AP30) -> 25266 | CC30: =SUM(AQ30:AT30) -> 31514 | CD30: =SUM(AU30:AX30) -> 36861 | CE30: =SUM(AY30:BB30) -> 37608 | CF30: =SUM(BC30:BF30) -> 39721 | CG30: =SUM(BG30:BJ30) -> 46751 | CH30: =SUM(CH22:CH29) -> 64816.421 | CI30: =SUM(CI22:CI29) -> 96726.319 | CJ30: =SUM(CJ22:CJ29) -> 126316.89 | CK30: =SUM(CK22:CK29) -> 148019.82 | CL30: =SUM(CL22:CL29) -> 170341.8 | CM30: =SUM(CM22:CM29) -> 189294.36 | CN30: =SUM(CN22:CN29) -> 205421.47 | CO30: =SUM(CO22:CO29) -> 217192.2 | ... CQ30: =SUM(CQ22:CQ29) -> 232274.12
B31: OI | C31: =C21-C30 -> 2683 | D31: =D21-D30 -> 3111 | E31: =E21-E30 -> 3317 | F31: =F21-F30 -> 4595 | G31: =G21-G30 -> 2879 | H31: =H21-H30 -> 3471 | I31: =I21-I30 -> 3334 | J31: =J21-J30 -> 5000 | ... BK31: =BK21-BK30 -> 6728 | BS31: =SUM(C31:F31) -> 13706 | BT31: =SUM(G31:J31) -> 14684 | BU31: =SUM(K31:N31) -> 14759 | BV31: =SUM(O31:R31) -> 13871 | BW31: =SUM(S31:V31) -> 12604 | BX31: =SUM(W31:Z31) -> 12913 | BY31: =SUM(AA31:AD31) -> 13264 | BZ31: =SUM(AE31:AH31) -> 13535 | CA31: =SUM(AI31:AL31) -> 13897 | CB31: =SUM(AM31:AP31) -> 15214 | CC31: =SUM(AQ31:AT31) -> 10927 | CD31: =SUM(AU31:AX31) -> 13094 | CE31: =SUM(AY31:BB31) -> 15353 | CF31: =SUM(BC31:BF31) -> 17678 | CG31: =SUM(BG31:BJ31) -> 20606 | CH31: =CH21-CH30 -> 24483.384 | CI31: =CI21-CI30 -> 33750.378 | CJ31: =CJ21-CJ30 -> 39490.433 | CK31: =CK21-CK30 -> 55864.229 | CL31: =CL21-CL30 -> 71965.169 | CM31: =CM21-CM30 -> 87451.779 | CN31: =CN21-CN30 -> 101636.03 | CO31: =CO21-CO30 -> 113138.14 | ... CQ31: =CQ21-CQ30 -> 131506.81
B32: Interest Expenses | C32: 0 | D32: 0 | E32: 0 | F32: 0 | G32: 0 | H32: 0 | I32: 0 | J32: 0 | K32: 0 | L32: 0 | M32: 0 | N32: 0 | O32: 0 | P32: 0 | Q32: 0 | R32: 0 | S32: 0 | T32: 0 | U32: 0 | V32: 0 | W32: 0 | X32: 0 | Y32: 0 | Z32: 0 | AA32: 0 | AB32: 0 | AC32: 0 | AD32: 0 | AE32: 0 | AF32: 0 | AG32: 0 | AH32: 0 | AI32: 0 | AJ32: 0 | AK32: 0 | AL32: 0 | AM32: -614 | AN32: -600 | AO32: -585 | AP32: =-2496-SUM(AM32:AO32) -> -697 | AQ32: -705 | AR32: -679 | AS32: -667 | AT32: =-2755-SUM(AQ32:AS32) -> -704 | AU32: -787 | AV32: -856 | AW32: -908 | AX32: =-3505-SUM(AU32:AW32) -> -954 | AY32: -872 | AZ32: -888 | BA32: -876 | BB32: =-3514-SUM(AY32:BA32) -> -878 | BC32: -842 | BD32: -866 | BE32: -892 | BF32: =-3578-SUM(BC32:BE32) -> -978 | BG32: -923 | BH32: -1057 | BI32: -1180 | BJ32: =-4599-SUM(BG32:BI32) -> -1439 | BK32: -1428 | BS32: =SUM(C32:F32) -> 0 | BT32: =SUM(G32:J32) -> 0 | BU32: =SUM(K32:N32) -> 0 | BV32: =SUM(O32:R32) -> 0 | BW32: =SUM(S32:V32) -> 0 | BX32: =SUM(W32:Z32) -> 0 | BY32: =SUM(AA32:AD32) -> 0 | BZ32: =SUM(AE32:AH32) -> 0 | CA32: =SUM(AI32:AL32) -> 0 | CB32: =SUM(AM32:AP32) -> -2496 | CC32: =SUM(AQ32:AT32) -> -2755 | CD32: =SUM(AU32:AX32) -> -3505 | CE32: =SUM(AY32:BB32) -> -3514 | CF32: =SUM(BC32:BF32) -> -3578 | CG32: =SUM(BG32:BJ32) -> -4599 | CH32: =CG70*-$CV$71 -> -8869.795 | CI32: =CH70*-$CV$71 -> -8226.7349 | CJ32: =CI70*-$CV$71 -> -7630.2966 | CK32: =CJ70*-$CV$71 -> -7077.1001 | CL32: =CK70*-$CV$71 -> -6564.0103 | CM32: =CL70*-$CV$71 -> -6088.1196 | CN32: =CM70*-$CV$71 -> -5646.7309 | CO32: =CN70*-$CV$71 -> -5237.3429 | ... CQ32: =CP70*-$CV$71 -> -4505.457
B33: Other Income | C33: -212 | D33: -151 | E33: -169 | F33: -212 | G33: -177 | H33: -191 | I33: -244 | J33: -174 | K33: -210 | L33: -207 | M33: -318 | N33: -320 | O33: -245 | P33: -273 | Q33: -233 | R33: -286 | S33: -344 | T33: -287 | U33: -295 | V33: -236 | W33: -268 | X33: -352 | Y33: -261 | Z33: -352 | AA33: -249 | AB33: -213 | AC33: -124 | AD33: -254 | AE33: -238 | AF33: -327 | AG33: -311 | AH33: -391 | AI33: -395 | AJ33: -373 | AK33: -452 | AL33: -613 | AM33: -2 | AN33: -11 | AO33: -17 | AP33: =282-SUM(AM33:AO33) -> 312 | AQ33: -41 | AR33: 7 | AS33: -315 | AT33: =-522-SUM(AQ33:AS33) -> -173 | AU33: -180 | AV33: -71 | AW33: -134 | AX33: =-462-SUM(AU33:AW33) -> -77 | AY33: -49 | AZ33: -14 | BA33: -9 | BB33: =-98-SUM(AY33:BA33) -> -26 | BC33: 20 | BD33: 36 | BE33: -18 | BF33: =60-SUM(BC33:BE33) -> 22 | BG33: 73 | BH33: 2668 | BI33: 132 | BJ33: =3547-SUM(BG33:BI33) -> 674 | BK33: 307 | BS33: =SUM(C33:F33) -> -744 | BT33: =SUM(G33:J33) -> -786 | BU33: =SUM(K33:N33) -> -1055 | BV33: =SUM(O33:R33) -> -1037 | BW33: =SUM(S33:V33) -> -1162 | BX33: =SUM(W33:Z33) -> -1233 | BY33: =SUM(AA33:AD33) -> -840 | BZ33: =SUM(AE33:AH33) -> -1267 | CA33: =SUM(AI33:AL33) -> -1833 | CB33: =SUM(AM33:AP33) -> 282 | CC33: =SUM(AQ33:AT33) -> -522 | CD33: =SUM(AU33:AX33) -> -462 | CE33: =SUM(AY33:BB33) -> -98 | CF33: =SUM(BC33:BF33) -> 60 | CG33: =SUM(BG33:BJ33) -> 3547 | CH33: =CG54*$DA$54 -> 938.67 | CI33: =CH54*$DA$54 -> 1372.5891 | CJ33: =CI54*$DA$54 -> 2077.6764 | CK33: =CJ54*$DA$54 -> 2967.3594 | CL33: =CK54*$DA$54 -> 4324.1084 | CM33: =CL54*$DA$54 -> 6151.963 | CN33: =CM54*$DA$54 -> 8446.1935 | CO33: =CN54*$DA$54 -> 11183.98 | ... CQ33: =CP54*$DA$54 -> 17779.245
B34: Pretax Income | C34: =C31+SUM(C32:C33) -> 2471 | D34: =D31+SUM(D32:D33) -> 2960 | E34: =E31+SUM(E32:E33) -> 3148 | F34: =F31+SUM(F32:F33) -> 4383 | G34: =G31+SUM(G32:G33) -> 2702 | H34: =H31+SUM(H32:H33) -> 3280 | I34: =I31+SUM(I32:I33) -> 3090 | J34: =J31+SUM(J32:J33) -> 4826 | ... BK34: =BK31+SUM(BK32:BK33) -> 5607 | BS34: =SUM(C34:F34) -> 12962 | BT34: =SUM(G34:J34) -> 13898 | BU34: =SUM(K34:N34) -> 13704 | BV34: =SUM(O34:R34) -> 12834 | BW34: =SUM(S34:V34) -> 11442 | BX34: =SUM(W34:Z34) -> 11680 | BY34: =SUM(AA34:AD34) -> 12424 | BZ34: =SUM(AE34:AH34) -> 12268 | CA34: =SUM(AI34:AL34) -> 12064 | CB34: =SUM(AM34:AP34) -> 13000 | CC34: =SUM(AQ34:AT34) -> 7650 | CD34: =SUM(AU34:AX34) -> 9127 | CE34: =SUM(AY34:BB34) -> 11741 | CF34: =SUM(BC34:BF34) -> 14160 | CG34: =SUM(BG34:BJ34) -> 19554 | CH34: =CH31+SUM(CH32:CH33) -> 16552.259 | CI34: =CI31+SUM(CI32:CI33) -> 26896.232 | CJ34: =CJ31+SUM(CJ32:CJ33) -> 33937.813 | CK34: =CK31+SUM(CK32:CK33) -> 51754.489 | CL34: =CL31+SUM(CL32:CL33) -> 69725.267 | CM34: =CM31+SUM(CM32:CM33) -> 87515.623 | CN34: =CN31+SUM(CN32:CN33) -> 104435.5 | CO34: =CO31+SUM(CO32:CO33) -> 119084.78 | ... CQ34: =CQ31+SUM(CQ32:CQ33) -> 144780.59
B35: Taxes | C35: 631 | D35: 768 | E35: 650 | F35: 932 | G35: 668 | H35: 699 | I35: 586 | J35: 1020 | K35: 472 | L35: 650 | M35: 684 | N35: 943 | O35: 534 | P35: 767 | Q35: 655 | R35: 940 | S35: 563 | T35: 471 | U35: 590 | V35: 917 | W35: 541 | X35: 653 | Y35: 459 | Z35: 575 | AA35: 356 | AB35: 612 | AC35: 7238 | AD35: 631 | AE35: 275 | AF35: 441 | AG35: 343 | AH35: 126 | AI35: 345 | AJ35: 499 | AK35: 505 | AL35: 579 | AM35: 344 | AN35: 530 | AO35: 1745 | AP35: =747-SUM(AM35:AO35) -> -1872 | AQ35: 224 | AR35: -249 | AS35: -521 | AT35: =932-SUM(AQ35:AS35) -> 1478 | AU35: 108 | AV35: 403 | AW35: 322 | AX35: =623-SUM(AU35:AW35) -> -210 | AY35: 45 | AZ35: 217 | BA35: 464 | BB35: =1274-SUM(AY35:BA35) -> 548 | BC35: 240 | BD35: 239 | BE35: 512 | BF35: =1717-SUM(BC35:BE35) -> 726 | BG35: 500 | BH35: 207 | BI35: 695 | BJ35: =2467-SUM(BG35:BI35) -> 1065 | BK35: 847 | BS35: =SUM(C35:F35) -> 2981 | BT35: =SUM(G35:J35) -> 2973 | BU35: =SUM(K35:N35) -> 2749 | BV35: =SUM(O35:R35) -> 2896 | BW35: =SUM(S35:V35) -> 2541 | BX35: =SUM(W35:Z35) -> 2228 | BY35: =SUM(AA35:AD35) -> 8837 | BZ35: =SUM(AE35:AH35) -> 1185 | CA35: =SUM(AI35:AL35) -> 1928 | CB35: =SUM(AM35:AP35) -> 747 | CC35: =SUM(AQ35:AT35) -> 932 | CD35: =SUM(AU35:AX35) -> 623 | CE35: =SUM(AY35:BB35) -> 1274 | CF35: =SUM(BC35:BF35) -> 1717 | CG35: =SUM(BG35:BJ35) -> 2467 | CH35: =CH34*CH51 -> 2088.29 | CI35: =CI34*CI51 -> 3393.3213 | CJ35: =CJ34*CJ51 -> 4281.7114 | CK35: =CK34*CK51 -> 6529.5246 | CL35: =CL34*CL51 -> 8796.7799 | CM35: =CM34*CM51 -> 11041.272 | CN35: =CN34*CN51 -> 13175.942 | CO35: =CO34*CO51 -> 15024.146 | ... CQ35: =CQ34*CQ51 -> 18266.019
B36: Net Income | C36: =C34-C35 -> 1840 | D36: =D34-D35 -> 2192 | E36: =E34-E35 -> 2498 | F36: =F34-F35 -> 3451 | G36: =G34-G35 -> 2034 | H36: =H34-H35 -> 2581 | I36: =I34-I35 -> 2504 | J36: =J34-J35 -> 3806 | ... BK36: =BK34-BK35 -> 4760 | BS36: =SUM(C36:F36) -> 9981 | BT36: =SUM(G36:J36) -> 10925 | BU36: =SUM(K36:N36) -> 10955 | BV36: =SUM(O36:R36) -> 9938 | BW36: =SUM(S36:V36) -> 8901 | BX36: =SUM(W36:Z36) -> 9452 | BY36: =SUM(AA36:AD36) -> 3587 | BZ36: =SUM(AE36:AH36) -> 11083 | CA36: =SUM(AI36:AL36) -> 10136 | CB36: =SUM(AM36:AP36) -> 12253 | CC36: =SUM(AQ36:AT36) -> 6718 | CD36: =SUM(AU36:AX36) -> 8504 | CE36: =SUM(AY36:BB36) -> 10467 | CF36: =SUM(BC36:BF36) -> 12443 | CG36: =SUM(BG36:BJ36) -> 17087 | CH36: =CH34-CH35 -> 14463.969 | CI36: =CI34-CI35 -> 23502.911 | CJ36: =CJ34-CJ35 -> 29656.102 | CK36: =CK34-CK35 -> 45224.964 | CL36: =CL34-CL35 -> 60928.487 | CM36: =CM34-CM35 -> 76474.35 | CN36: =CN34-CN35 -> 91259.554 | CO36: =CO34-CO35 -> 104060.63 | ... CQ36: =CQ34-CQ35 -> 126514.58
B37: Preferred Stock Dividends | C37: 0 | D37: 0 | E37: 0 | F37: 0 | G37: 0 | H37: 0 | I37: 0 | J37: 0 | K37: 0 | L37: 0 | M37: 0 | N37: 0 | O37: 0 | P37: 0 | Q37: 0 | R37: 0 | S37: 0 | T37: 0 | U37: 0 | V37: 0 | W37: 0 | X37: 0 | Y37: 0 | Z37: 0 | AA37: 0 | AB37: 0 | AC37: 0 | AD37: 0 | AE37: 0 | AF37: 0 | AG37: 0 | AH37: 0 | AI37: 0 | AJ37: 0 | AK37: 0 | AL37: 0 | AM37: 0 | AN37: 0 | AO37: 0 | AP37: =0-SUM(AM37:AO37) -> 0 | AQ37: 0 | AR37: 0 | AS37: 0 | AT37: =0-SUM(AQ37:AS37) -> 0 | AU37: 0 | AV37: 0 | AW37: 0 | AX37: 0 | AY37: 0 | AZ37: 0 | BA37: 0 | BB37: =0-SUM(AY37:BA37) -> 0 | BC37: 0 | BD37: 0 | BE37: 0 | BF37: =0-SUM(BC37:BE37) -> 0 | BG37: 0 | BH37: 0 | BI37: 22 | BJ37: =103-SUM(BG37:BI37) -> 81 | BK37: 81 | BS37: =SUM(C37:F37) -> 0 | BT37: =SUM(G37:J37) -> 0 | BU37: =SUM(K37:N37) -> 0 | BV37: =SUM(O37:R37) -> 0 | BW37: =SUM(S37:V37) -> 0 | BX37: =SUM(W37:Z37) -> 0 | BY37: =SUM(AA37:AD37) -> 0 | BZ37: =SUM(AE37:AH37) -> 0 | CA37: =SUM(AI37:AL37) -> 0 | CB37: =SUM(AM37:AP37) -> 0 | CC37: =SUM(AQ37:AT37) -> 0 | CD37: =SUM(AU37:AX37) -> 0 | CE37: =SUM(AY37:BB37) -> 0 | CF37: =SUM(BC37:BF37) -> 0 | CG37: =SUM(BG37:BJ37) -> 103
B38: Net Income to CS | C38: =C36-C37 -> 1840 | D38: =D36-D37 -> 2192 | E38: =E36-E37 -> 2498 | F38: =F36-F37 -> 3451 | G38: =G36-G37 -> 2034 | H38: =H36-H37 -> 2581 | I38: =I36-I37 -> 2504 | J38: =J36-J37 -> 3806 | ... BK38: =BK36-BK37 -> 4679 | BS38: =SUM(C38:F38) -> 9981 | BT38: =SUM(G38:J38) -> 10925 | BU38: =SUM(K38:N38) -> 10955 | BV38: =SUM(O38:R38) -> 9938 | BW38: =SUM(S38:V38) -> 8901 | BX38: =SUM(W38:Z38) -> 9452 | BY38: =SUM(AA38:AD38) -> 3587 | BZ38: =SUM(AE38:AH38) -> 11083 | CA38: =SUM(AI38:AL38) -> 10136 | CB38: =SUM(AM38:AP38) -> 12253 | CC38: =SUM(AQ38:AT38) -> 6718 | CD38: =SUM(AU38:AX38) -> 8504 | CE38: =SUM(AY38:BB38) -> 10467 | CF38: =SUM(BC38:BF38) -> 12443 | CG38: =SUM(BG38:BJ38) -> 16984 | CH38: =CH36-CH37 -> 14463.969 | CI38: =CI36-CI37 -> 23502.911 | CJ38: =CJ36-CJ37 -> 29656.102 | CK38: =CK36-CK37 -> 45224.964 | CL38: =CL36-CL37 -> 60928.487 | CM38: =CM36-CM37 -> 76474.35 | CN38: =CN36-CN37 -> 91259.554 | CO38: =CO36-CO37 -> 104060.63 | ... CQ38: =CQ36-CQ37 -> 126514.58 | CR38: =CQ38*(1+$DA$55) -> 128412.29 | CS38: =CR38*(1+$DA$55) -> 130338.48 | CT38: =CS38*(1+$DA$55) -> 132293.56 | CU38: =CT38*(1+$DA$55) -> 134277.96 | CV38: =CU38*(1+$DA$55) -> 136292.13 | CW38: =CV38*(1+$DA$55) -> 138336.51 | CX38: =CW38*(1+$DA$55) -> 140411.56 | CY38: =CX38*(1+$DA$55) -> 142517.73 | ... EO38: =EN38*(1+$DA$55) -> 266343.85
B39: SC | C39: 5020 | D39: 5030 | E39: 5040 | F39: 5060 | G39: 5060 | H39: 5040 | I39: 5010 | J39: 487 | K39: 4790 | L39: 4740 | M39: 4610 | N39: 4540 | O39: 4500 | P39: 4450 | Q39: 4420 | R39: 4390 | S39: 4360 | T39: 4320 | U39: 4240 | V39: 4180 | W39: 4150 | X39: 4120 | Y39: 4100 | Z39: 4110 | AA39: 4130 | AB39: 4155 | AC39: 4160 | AD39: 4120 | AE39: 4050 | AF39: 3900 | AG39: 3720 | AH39: 3530 | AI39: 3390 | AJ39: 3320 | AK39: 3250 | AL39: 3190 | AM39: 3040 | AN39: 2977 | AO39: 2913 | AP39: 2850 | AQ39: 2770 | AR39: 2690 | AS39: 2670 | AT39: 2670 | AU39: 2685 | AV39: 2700 | AW39: 2700 | AX39: 2710 | AY39: 2730 | AZ39: 2750 | BA39: 2750 | BB39: 2750 | BC39: 2760 | BD39: 2791 | BE39: 2806 | BF39: 2830 | BG39: 2860 | BH39: 2874 | BI39: 2876 | BJ39: 2880 | BK39: 2966 | BS39: =SUM(C39:F39) -> 20150 | BT39: =SUM(G39:J39) -> 15597 | BU39: =SUM(K39:N39) -> 18680 | BV39: =SUM(O39:R39) -> 17760 | BW39: =SUM(S39:V39) -> 17100 | BX39: =SUM(W39:Z39) -> 16480 | BY39: =SUM(AA39:AD39) -> 16565 | BZ39: =SUM(AE39:AH39) -> 15200 | CA39: =SUM(AI39:AL39) -> 13150 | CB39: =SUM(AM39:AP39) -> 11780 | CC39: =SUM(AQ39:AT39) -> 10800 | CD39: =SUM(AU39:AX39) -> 10795 | CE39: =SUM(AY39:BB39) -> 10980 | CF39: =SUM(BC39:BF39) -> 11187 | CG39: =SUM(BG39:BJ39) -> 11490
B40: EPS | C40: =C38/C39 -> 0.36653386 | D40: =D38/D39 -> 0.43578529 | E40: =E38/E39 -> 0.49563492 | F40: =F38/F39 -> 0.68201581 | G40: =G38/G39 -> 0.40197628 | H40: =H38/H39 -> 0.51210317 | I40: =I38/I39 -> 0.4998004 | J40: =J38/J39 -> 7.8151951 | ... BK40: =BK38/BK39 -> 1.5775455 | BS40: =SUM(C40:F40) -> 1.9799699 | BT40: =SUM(G40:J40) -> 9.2290749 | BU40: =SUM(K40:N40) -> 2.3555017 | BV40: =SUM(O40:R40) -> 2.2400784 | BW40: =SUM(S40:V40) -> 2.0878865 | BX40: =SUM(W40:Z40) -> 2.2955891 | BY40: =SUM(AA40:AD40) -> 0.87428941 | BZ40: =SUM(AE40:AH40) -> 2.9548577 | CA40: =SUM(AI40:AL40) -> 3.0946607 | CB40: =SUM(AM40:AP40) -> 4.2017554 | CC40: =SUM(AQ40:AT40) -> 2.4863562 | CD40: =SUM(AU40:AX40) -> 3.1482966 | CE40: =SUM(AY40:BB40) -> 3.8123889 | CF40: =SUM(BC40:BF40) -> 4.4475013 | CG40: =SUM(BG40:BJ40) -> 5.9105629
B42: Cloud & Software Op. Ex. | AM42: =AM22/AM21 -> 0.1079321 | AN42: =AN22/AN21 -> 0.10857143 | AO42: =AO22/AO21 -> 0.10549276 | AP42: =AP22/AP21 -> 0.10813218 | AQ42: =AQ22/AQ21 -> 0.12479441 | AR42: =AR22/AR21 -> 0.1215251 | AS42: =AS22/AS21 -> 0.12413203 | AT42: =AT22/AT21 -> 0.12119932 | ... BK42: =BK22/BK21 -> 0.33083484 | CD42: =CD22/CD21 -> 0.15539986 | CE42: =CE22/CE21 -> 0.1779989 | CF42: =CF22/CF21 -> 0.20155403 | CG42: =CG22/CG21 -> 0.26124976 | CH42: 0.28 | CI42: 0.29 | CJ42: 0.3 | CK42: 0.28 | CL42: 0.27 | CM42: 0.265 | CN42: 0.26 | CO42: 0.255 | CP42: 0.25 | CQ42: 0.245
B43: Hardware Op. Ex. | AM43: =AM23/AM21 -> 0.026262411 | AN43: =AN23/AN21 -> 0.024897959 | AO43: =AO23/AO21 -> 0.022803887 | AP43: =AP23/AP21 -> 0.022445889 | AQ43: =AQ23/AQ21 -> 0.025185033 | AR43: =AR23/AR21 -> 0.022104247 | AS43: =AS23/AS21 -> 0.02320936 | AT43: =AT23/AT21 -> 0.021452703 | ... BK43: =BK23/BK21 -> 0.014525717 | CD43: =CD23/CD21 -> 0.020818737 | CE43: =CE23/CE21 -> 0.0168237 | CF43: =CF23/CF21 -> 0.013623931 | CG43: =CG23/CG21 -> 0.01288656 | CH43: 0.014 | CI43: 0.013 | CJ43: 0.013 | CK43: 0.012 | CL43: 0.012 | CM43: 0.011 | CN43: 0.011 | CO43: 0.01 | CP43: 0.01 | CQ43: 0.01
B44: Services Op. Ex. | AM44: =AM24/AM21 -> 0.066510089 | AN44: =AN24/AN21 -> 0.064387755 | AO44: =AO24/AO21 -> 0.061570494 | AP44: =AP24/AP21 -> 0.058341498 | AQ44: =AQ24/AQ21 -> 0.066200658 | AR44: =AR24/AR21 -> 0.06476834 | AS44: =AS24/AS21 -> 0.063635499 | AT44: =AT24/AT21 -> 0.059797297 | ... BK44: =BK24/BK21 -> 0.054380977 | CD44: =CD24/CD21 -> 0.095305775 | CE44: =CE24/CE21 -> 0.091104775 | CF44: =CF24/CF21 -> 0.079722643 | CG44: =CG24/CG21 -> 0.067639592 | CH44: 0.064 | CI44: 0.065 | CJ44: 0.063 | CK44: 0.062 | CL44: 0.061 | CM44: 0.06 | CN44: 0.059 | CO44: 0.058 | CP44: 0.057 | CQ44: 0.056
...

Sheet Notes | Quant Analysis
CI1: 0
P2: Employee Scope: | AL2: General Notes/Observations (Updated Q2'26)
AL35: Financial Stmts. Notes/Observations (Updated Q2'26)
P36: Institutional Ownership Snapshot Q4'25 | AL36: Revenues:
P69: Revenue Breakdown by Segment | AL69: Earnings Scope:
Q101: Notes: | R101: [X]
R102: [Y]
R103: [Z]
P105: Q/q Total Revenues, Net Income, FCF | AL105: Balance Sheet Scope:
Q134: Notes: | R134: [X]
R135: [Y]
R136: [Z]
P138: Y/y Total Revenues, Net Income, FCF | AL138: [Equity Preformance Compared to Peers]
Q167: Notes: | R167: [X]
R168: [Y]
R169: [Z]
A184: VOO Historical Returns | I184: ORCL Historical Returns
A185: 752 Trading Days? (From: 8/12/2023 -8/12/2026) | I185: 752 Trading Days? (From: 8/12/2023 -8/12/2026)
A186: Close | B186: High | C186: Low | D186: Open | E186: Volume | F186: UTC Date | G186: Change | I186: Close | J186: High | K186: Low | L186: Open | M186: Volume | N186: UTC Date | O186: Change
A187: 710.17 | B187: 712.26 | C187: 708.93 | D187: 712.12 | E187: 4871287.5 | F187: Wed, 12 Aug 2026 00:00:00 GMT | G187: =A187/D187-1 -> -0.0027383025 | I187: 153.28 | J187: 154.89 | K187: 147.89 | L187: 152.81 | M187: 43260277 | N187: Wed, 12 Aug 2026 00:00:00 GMT | O187: =I187/L187-1 -> 0.0030757149
A188: 708.42 | B188: 712 | C188: 707 | D188: 711.96 | E188: 5010440 | F188: Tue, 11 Aug 2026 00:00:00 GMT | G188: =A188/D188-1 -> -0.0049721894 | I188: 145.48 | J188: 151.99 | K188: 144.24 | L188: 151.2 | M188: 28220614 | N188: Tue, 11 Aug 2026 00:00:00 GMT | O188: =I188/L188-1 -> -0.037830688
A189: 710.65 | B189: 712.4378 | C189: 709.5 | D189: 710.31 | E189: 6657921.2 | F189: Mon, 10 Aug 2026 00:00:00 GMT | G189: =A189/D189-1 -> 0.00047866425 | I189: 151.05 | J189: 151.99 | K189: 146.62 | L189: 148.26 | M189: 23971967 | N189: Mon, 10 Aug 2026 00:00:00 GMT | O189: =I189/L189-1 -> 0.018818292
A190: 710.71 | B190: 711.37 | C190: 707.44 | D190: 708.73 | E190: 4631469 | F190: Fri, 07 Aug 2026 00:00:00 GMT | G190: =A190/D190-1 -> 0.0027937296 | I190: 147.02 | J190: 147.16 | K190: 142.34 | L190: 145.32 | M190: 21938050 | N190: Fri, 07 Aug 2026 00:00:00 GMT | O190: =I190/L190-1 -> 0.011698321
A191: 706.4 | B191: 709.4619 | C191: 705.43 | D191: 707.93 | E191: 4523037.3 | F191: Thu, 06 Aug 2026 00:00:00 GMT | G191: =A191/D191-1 -> -0.0021612306 | I191: 143.47 | J191: 146.58 | K191: 138.72 | L191: 139.25 | M191: 21885222 | N191: Thu, 06 Aug 2026 00:00:00 GMT | O191: =I191/L191-1 -> 0.030305206
A192: 707.6 | B192: 714.16 | C192: 707.32 | D192: 713.14 | E192: 5187471.1 | F192: Wed, 05 Aug 2026 00:00:00 GMT | G192: =A192/D192-1 -> -0.0077684606 | I192: 144.39 | J192: 146.3899 | K192: 142.5 | L192: 145 | M192: 21661600 | N192: Wed, 05 Aug 2026 00:00:00 GMT | O192: =I192/L192-1 -> -0.0042068966
A193: 708.98 | B193: 710.9083 | C193: 699.07 | D193: 699.16 | E193: 6510852.7 | F193: Tue, 04 Aug 2026 00:00:00 GMT | G193: =A193/D193-1 -> 0.014045426 | I193: 145.74 | J193: 148.7 | K193: 141.01 | L193: 141.01 | M193: 43051564 | N193: Tue, 04 Aug 2026 00:00:00 GMT | O193: =I193/L193-1 -> 0.03354372
A194: 696.4 | B194: 697.31 | C194: 688.61 | D194: 688.83 | E194: 7244316 | F194: Mon, 03 Aug 2026 00:00:00 GMT | G194: =A194/D194-1 -> 0.010989649 | I194: 141.85 | J194: 143.07 | K194: 130.21 | L194: 131.92 | M194: 49139578 | N194: Mon, 03 Aug 2026 00:00:00 GMT | O194: =I194/L194-1 -> 0.075272893
A195: 686.65 | B195: 688.35 | C195: 678.06 | D195: 684.5 | E195: 7661568.2 | F195: Fri, 31 Jul 2026 00:00:00 GMT | G195: =A195/D195-1 -> 0.0031409788 | I195: 129.87 | J195: 132.4 | K195: 125.7 | L195: 130.07 | M195: 34214876 | N195: Fri, 31 Jul 2026 00:00:00 GMT | O195: =I195/L195-1 -> -0.0015376336
A196: 681.79 | B196: 682.4363 | C196: 675.21 | D196: 676.54 | E196: 6009104.5 | F196: Thu, 30 Jul 2026 00:00:00 GMT | G196: =A196/D196-1 -> 0.0077600733 | I196: 127.56 | J196: 128.34 | K196: 121.58 | L196: 122.87 | M196: 36950065 | N196: Thu, 30 Jul 2026 00:00:00 GMT | O196: =I196/L196-1 -> 0.038170424
A197: 670.63 | B197: 682.63 | C197: 670.155 | D197: 680.12 | E197: 7845443.5 | F197: Wed, 29 Jul 2026 00:00:00 GMT | G197: =A197/D197-1 -> -0.01395342 | I197: 117.74 | J197: 121.92 | K197: 116.2 | L197: 119.42 | M197: 27177467 | N197: Wed, 29 Jul 2026 00:00:00 GMT | O197: =I197/L197-1 -> -0.014067995
A198: 680.96 | B198: 682.755 | C198: 676.4801 | D198: 679.45 | E198: 5021080 | F198: Tue, 28 Jul 2026 00:00:00 GMT | G198: =A198/D198-1 -> 0.0022223858 | I198: 119.96 | J198: 122.33 | K198: 114.5 | L198: 118.18 | M198: 28081150 | N198: Tue, 28 Jul 2026 00:00:00 GMT | O198: =I198/L198-1 -> 0.01506177
A199: 679.31 | B199: 685.2391 | C199: 676.395 | D199: 684.69 | E199: 5207757.8 | F199: Mon, 27 Jul 2026 00:00:00 GMT | G199: =A199/D199-1 -> -0.0078575706 | I199: 119.9 | J199: 121.99 | K199: 116.8 | L199: 118 | M199: 36633880 | N199: Mon, 27 Jul 2026 00:00:00 GMT | O199: =I199/L199-1 -> 0.016101695
A200: 679.14 | B200: 683.55 | C200: 677.7 | D200: 678.8 | E200: 6286807 | F200: Fri, 24 Jul 2026 00:00:00 GMT | G200: =A200/D200-1 -> 0.00050088391 | I200: 114.99 | J200: 123.08 | K200: 114.75 | L200: 122.47 | M200: 44922930 | N200: Fri, 24 Jul 2026 00:00:00 GMT | O200: =I200/L200-1 -> -0.061076182 | R200: Min | S200: =MIN(O187:O1149) -> -0.088553383
A201: 678.61 | B201: 682.5495 | C201: 675.755 | D201: 679.55 | E201: 4942804.8 | F201: Thu, 23 Jul 2026 00:00:00 GMT | G201: =A201/D201-1 -> -0.0013832683 | I201: 120.04 | J201: 124.7 | K201: 119.44 | L201: 123.96 | M201: 29200007 | N201: Thu, 23 Jul 2026 00:00:00 GMT | O201: =I201/L201-1 -> -0.031623104 | R201: Max | S201: =MAX(O187:O1149) -> 0.13200972
A202: 687.03 | B202: 689.4 | C202: 686.02 | D202: 686.29 | E202: 3349102.7 | F202: Wed, 22 Jul 2026 00:00:00 GMT | G202: =A202/D202-1 -> 0.0010782614 | I202: 125.84 | J202: 128.84 | K202: 124.7 | L202: 126.18 | M202: 20775642 | N202: Wed, 22 Jul 2026 00:00:00 GMT | O202: =I202/L202-1 -> -0.0026945633 | R202: Mean μ | S202: =AVERAGE(O187:O1149) -> -0.00089280539
A203: 687.87 | B203: 688.485 | C203: 684.03 | D203: 685.95 | E203: 4054717.9 | F203: Tue, 21 Jul 2026 00:00:00 GMT | G203: =A203/D203-1 -> 0.0027990378 | I203: 127.05 | J203: 127.42 | K203: 122.21 | L203: 122.81 | M203: 27409567 | N203: Tue, 21 Jul 2026 00:00:00 GMT | O203: =I203/L203-1 -> 0.034524876 | R203: Median | S203: =MEDIAN(O187:O1149) -> -0.00046218195
A204: 682.21 | B204: 688.2 | C204: 681.57 | D204: 686.67 | E204: 5321985.3 | F204: Mon, 20 Jul 2026 00:00:00 GMT | G204: =A204/D204-1 -> -0.0064951141 | I204: 121.38 | J204: 125.4897 | K204: 120.03 | L204: 124.27 | M204: 36295668 | N204: Mon, 20 Jul 2026 00:00:00 GMT | O204: =I204/L204-1 -> -0.023255814 | R204: SD σ | S204: =_xlfn.STDEV.P(O187:O1149) -> 0.021848969
A205: 683.17 | B205: 686.8653 | C205: 680.92 | D205: 682.12 | E205: 5627641.4 | F205: Fri, 17 Jul 2026 00:00:00 GMT | G205: =A205/D205-1 -> 0.0015393186 | I205: 126.41 | J205: 128.435 | K205: 121.5 | L205: 121.7 | M205: 39690283 | N205: Fri, 17 Jul 2026 00:00:00 GMT | O205: =I205/L205-1 -> 0.038701726 | R205: 3σ 1-Day Δ: ± | S205: =3*S204 -> 0.065546906 | U205: <- Sharpe Ratio (Risk Adjusted Return)
A206: 690.14 | B206: 693.55 | C206: 687.43 | D206: 691.98 | E206: 4722611.2 | F206: Thu, 16 Jul 2026 00:00:00 GMT | G206: =A206/D206-1 -> -0.0026590364 | I206: 124.21 | J206: 131.78 | K206: 123.66 | L206: 131.475 | M206: 54220667 | N206: Thu, 16 Jul 2026 00:00:00 GMT | O206: =I206/L206-1 -> -0.055257654 | R206: β (1-year avg.) | S206: =_xlfn.COVARIANCE.P(O187:O435,G187:G435)/_xlfn.VAR.P(G187:G435) -> 1.916003 | U206: <- Sortino Ratio (Downside Risk Adjusted Return)
A207: 693.8 | B207: 694.5 | C207: 689.58 | D207: 693.27 | E207: 4110059.9 | F207: Wed, 15 Jul 2026 00:00:00 GMT | G207: =A207/D207-1 -> 0.00076449291 | I207: 132.49 | J207: 133.9 | K207: 128.84 | L207: 130.56 | M207: 48228999 | N207: Wed, 15 Jul 2026 00:00:00 GMT | O207: =I207/L207-1 -> 0.014782475
...

Sheet Product Lines

Sheet Management

Sheet Table Formatting
B2: [Bold Title] | G2: [Bold Title]
B3: Line Titles | G3: <-- General
B4: Line Titles | G4: <-- Info
B5: Line Titles | G5: <-- General
B6: Line Titles | G6: <-- Info
B7: Line Titles | G7: <-- General
B8: Line Titles | G8: <-- Info
