Workbook

Sheet Main | Overview
A1: Master | CU1: -
B2: PEN | AN2: Thrombus/I : A clot that forms and remains in place inside a blood vessel
B3: Price | C3: 319.11 | D3: 10/72026 | P3: Resources:
B4: SO | C4: 39.389 | D4: Q2'26 | P4: SEC Filings | S4: https://www.sec.gov/edgar/browse/?CIK=1321732&owner=exclude | AN4: Thrombosis: Thrombosis is the formation of a blood clot (thrombus) inside a blood vessel, obstructing blood flow
B5: MC | C5: =C3*C4 -> 12569.424 | P5: Penumbra Homepage | S5: https://www.penumbrainc.com/ | AP5: Can occur in arteries (arterial thrombosis) or veins (venous thrombosis) <-- Penumbra's product are FDA-approved for arterial cases, but have been used off-label for DVT/PE in some cases
B6: Cash | C6: =205.271+453.52 -> 658.791 | D6: Q2'26 | Q6: Penumbra IR Page | T6: https://www.penumbrainc.com/about-us/leadership/
B7: Debt | C7: 0 | D7: Q2'26 | P7: Comp. + Board structure | S7: https://www.sec.gov/Archives/edgar/data/1321732/000114036125014193/ef20047412_ars.pdf | AN7: Thrombectomy: | AP7: Restores blood flow by clearing a blockage
B8: EV | C8: =C5-C6+C7 -> 11910.633 | P8: U.S. Patent Office Search | S8: https://ppubs.uspto.gov/pubThe Companybapp/static/pages/ppubsbasic.html
Q9: Penumbra IP Catalog | T9: https://www.penumbrainc.com/patents/ | AN9: Embolus/i : a thrombus, or other substance that breaks free and circulates through blood vessels
B10: Penumbra Inc. (PEN) | P10: PubMed/NIH reporting's | S10: https://pubmed.ncbi.nlm.nih.gov/
P11: Clinical Trail.Gov | S11: https://clinicaltrials.gov/ | AN11: Embolism: An embolism occurs when a blood clot (thrombus), air bubble, fat globule, or other foreign material travels through the bloodstream and lodges in a blood vessel, blocking blood flow.
B12: Founders: Arani Bose, Adam Elsesser | G12: Registered Exchange: NYSE | Q12: FDAAA Trail Tracker | T12: https://fdaaa.trialstracker.net/
B13: Founded: 2004 | G13: Address: One Penumbra Place, Alameda, CA 94502 | P13: FDA Med Device reporting's | S13: https://www.fda.gov/medical-devices | AN13: Embolization: | AP13: Stops blood flow to prevent or control bleeding or to cut off supply to abnormal tissue
B14: Headquarted: Alameda, CA | G14: Investor Relations / Corporate Strategy Contacts | P14: EV Today Trade News | S14: https://evtoday.com/
B15: Current CEO: Adam Elsesser (Co-Founder) | H15: Investor Relations | J15: (Cecilia Furlong) | P15: MedTech News | S15: https://www.medtechdive.com/news/stryker-inari-medical-acquisition/736615/
B16: Employees: 4,600 (Q2'25) | H16: Phone: | I16: (510) 995-2461 | K16: Email: | L16: investors@penumbrainc.com | P16: American Heart Association | S16: https://www.heart.org/en/
B17: Sector: Medical Devices | I17: (510) 748-3200 | P17: MacroTrends | S17: https://www.macrotrends.net/stocks/charts/PEN/penumbra/income-statement?freq=Q
B18: Industry: Thrombectomy/Embolization | P18: ROIC, WACC | S18: https://www.gurufocus.com/term/wacc/PEN
B19: IPO: September 18, 2015 -- $895M valuation … Secondary offering May 27, 2020, 1 week after NARIs IPO? | P19: Earnings Calls | S19: https://seekingalpha.com/symbol/PEN/earnings/transcripts
B20: Fiscal Year: [January - December] | P20: Godel Terminal | S20: https://app.godelterminal.com/
A22: Company Overview:
B23: Penumbra, the world’s leading thrombectomy company, is focused on developing the most innovative technologies for challenging medical conditions in the thrombectomy and embolization space
B24: The Company designs, develops, manufactures, and markets medical devices in the United States and internationally
C25: The Company's broad portfolio, which includes computer assisted vacuum thrombectomy (CAVT), centers on removing blood clots from head-to-toe with speed, safety and simplicity
D26: Strong track record of organic product development and commercial expansion that has established a strong foundation for The Company's global operations
E27: Focused and lean portfolio of assets … many individual offerings feed into a system
D28: Company managers state their belief that the cost-effectiveness of The Company's products are attractive to customers
E29: Offerings are cheaper for MT products when compared to almost all other competitors … Economic impact is even greater due to leading edge speed safety and ease of use
B30: The Company has successfully developed, obtained regulatory clearance or approval for, and introduced products into a range of markets which make up a portfolio including:
C31: the Thrombectomy market (entered 2007)
C32: the Access market (entered 2008)
C33: the Embolization market (entered 2011)
C34: the Neurosurgical market (entered 2014)
C35: the Immersive Healthcare market (entered 2020, divested September 2024) <-- Decision to wind down and exit the Immersive Healthcare business, and as a result, incurred a $115.3 million impairment charge at year-end
D36: During year ended December 31, 2024, The Company permanently ceased sales of Immersive Healthcare products and related commercial operations
D37: (important to track/sum the total impairment cost in model) … (see additional comments in Notes tab)
B38: The Company sells its products through direct sales organizations and distributors
C39: The Company sells products to healthcare providers primarily through The Company's direct sales organization in the United States, most of Europe, Canada and Australia, and as a partner with distributors in select international markets (China, APac, LatAm)
D40: Salesforce serves as a consultative ramp of sorts … top notch sales people are necessary to effectively describe the superiority of The Company's offering (CAVT, Ruby, etc.) as well as the clinical and economic impact demonstated from PEN products
C41: A significant portion of the company's inventory is outstanding and in consignment, ready to be used by healthcare providers
...

Sheet Bull Case (30%)
S1: Q1 2019 | W1: Q1 2020 | AA1: Q1 2021 | AE1: Q1 2022 | AI1: Q1 2023 | AM1: Q1 2024 | AQ1: Q1 2025 | AU1: Q1 2026
B2: Quarterly | C2: Apr | D2: July | E2: Oct | F2: Jan | G2: Apr | H2: July | I2: Oct | J2: Jan | K2: Apr | L2: July | M2: Oct | N2: Jan | O2: Apr | P2: July | Q2: Oct | R2: Jan | S2: Apr | T2: July | U2: Oct | V2: Jan | W2: Apr | X2: July | Y2: Oct | Z2: Jan | AA2: Apr | AB2: July | AC2: Oct | AD2: Jan | AE2: Apr | AF2: July | AG2: Oct | AH2: Jan | AI2: Apr | AJ2: July | AK2: Oct | AL2: Jan | AM2: Apr | AN2: July | AO2: Oct | AP2: Jan | AQ2: Apr | AR2: July | AS2: Oct | AT2: Jan | AU2: Apr | AV2: July | AW2: Oct | AX2: Jan | AY2: Apr | AZ2: July | BA2: Oct | BB2: Jan
B3: Revenues | C3: Q1 2015 | D3: Q2 2015 | E3: Q3 2015 | F3: Q4 2015 | G3: Q1 2016 | H3: Q2 2016 | I3: Q3 2016 | J3: Q4 2016 | K3: Q1 2017 | L3: Q2 2017 | M3: Q3 2017 | N3: Q4 2017 | O3: Q1 2018 | P3: Q2 2018 | Q3: Q3 2018 | R3: Q4 2018 | S3: Q1 2019 | T3: Q2 2019 | U3: Q3 2019 | V3: Q4 2019 | W3: Q1 2020 | X3: Q2 2020 | Y3: Q3 2020 | Z3: Q4 2020 | AA3: Q1 2021 | AB3: Q2 2021 | AC3: Q3 2021 | AD3: Q4 2021 | AE3: Q1 2022 | AF3: Q2 2022 | AG3: Q3 2022 | AH3: Q4 2022 | AI3: Q1 2023 | AJ3: Q2 2023 | AK3: Q3 2023 | AL3: Q4 2023 | AM3: Q1 2024 | AN3: Q2 2024 | AO3: Q3 2024 | AP3: Q4 2024 | AQ3: Q1 2025 | AR3: Q2 2025 | AS3: Q3 2025 | AT3: Q4 2025 | AU3: Q1 2026 | AV3: Q2 2026 | AW3: Q3 2026 | AX3: Q4 2026 | AY3: Q1 2027 | AZ3: Q2 2027 | BA3: Q3 2027 | BB3: Q4 2027 | BG3: 2015 | BH3: 2016 | BI3: 2017 | BJ3: 2018 | BK3: 2019 | BL3: 2020 | BM3: 2021 | BN3: 2022 | BO3: =BN3+1 -> 2023 | BP3: =BO3+1 -> 2024 | BQ3: =BP3+1 -> 2025 | BR3: =BQ3+1 -> 2026 | BS3: =BR3+1 -> 2027 | BT3: =BS3+1 -> 2028 | BU3: =BT3+1 -> 2029 | BV3: =BU3+1 -> 2030 | ... DO3: =DN3+1 -> 2075
B4: Thrombectomy (Neuro + Peripheral) | AI4: 145 | AJ4: 162 | AK4: 179 | AL4: =677-SUM(AI4:AK4) -> 191 | AM4: 188 | AN4: 203 | AO4: 204 | AP4: =815-SUM(AM4:AO4) -> 220 | AQ4: 226.544 | AR4: 230.256 | AS4: 236.4 | AT4: =947.918-SUM(AQ4:AS4) -> 254.718 | AU4: 253.917 | AV4: 258.981 | AW4: =AS4*(1+AW8) -> 293.136 | AX4: =AT4*(1+AX8) -> 315.85032 | BO4: =SUM(AI4:AL4) -> 677 | BP4: =SUM(AM4:AP4) -> 815 | BQ4: =SUM(AQ4:AT4) -> 947.918 | BR4: =BQ4*(1+BR8) -> 1123.2828 | BS4: =BR4*(1+BS8) -> 1370.4051 | BT4: =BS4*(1+BT8) -> 1658.1901 | BU4: =BT4*(1+BU8) -> 1964.9553 | BV4: =BU4*(1+BV8) -> 2298.9977 | BW4: =BV4*(1+BW8) -> 2666.8373 | BX4: =BW4*(1+BX8) -> 3066.8629 | BY4: =BX4*(1+BY8) -> 3496.2237 | ... CA4: =BZ4*(1+CA8) -> 4484.0817
B5: Embolization & Access (Peripheral Embolization + Neuro Embolization + Access + Neurosurgical Tools) | AI5: 96 | AJ5: 99 | AK5: 92 | AL5: =381-SUM(AI5:AK5) -> 94 | AM5: 91 | AN5: 96 | AO5: 96.89 | AP5: =379-SUM(AM5:AO5) -> 95.11 | AQ5: 97.596 | AR5: 109.199 | AS5: 118.3 | AT5: =455.747-SUM(AQ5:AS5) -> 130.652 | AU5: 120.841 | AV5: 131.065 | AW5: =AS5*(1+AW9) -> 129.83425 | AX5: =AT5*(1+AX9) -> 143.06394 | BO5: =SUM(AI5:AL5) -> 381 | BP5: =SUM(AM5:AP5) -> 379 | BQ5: =SUM(AQ5:AT5) -> 455.747 | BR5: =BQ5*(1+BR9) -> 524.10905 | BS5: =BR5*(1+BS9) -> 607.9665 | BT5: =BS5*(1+BT9) -> 693.08181 | BU5: =BT5*(1+BU9) -> 776.25162 | BV5: =BU5*(1+BV9) -> 853.87679 | BW5: =BV5*(1+BW9) -> 922.18693 | BX5: =BW5*(1+BX9) -> 986.74002 | BY5: =BX5*(1+BY9) -> 1045.9444 | ... CA5: =BZ5*(1+CA9) -> 1142.1713
B6: Ttl Revenues | AI6: =SUM(AI4:AI5) -> 241 | AJ6: =SUM(AJ4:AJ5) -> 261 | AK6: =SUM(AK4:AK5) -> 271 | AL6: =SUM(AL4:AL5) -> 285 | AM6: =SUM(AM4:AM5) -> 279 | AN6: =SUM(AN4:AN5) -> 299 | AO6: =SUM(AO4:AO5) -> 300.89 | AP6: =SUM(AP4:AP5) -> 315.11 | ... AT6: =SUM(AT4:AT5) -> 385.37 | AU6: =AU4+AU5 -> 374.758 | AV6: =AV4+AV5 -> 390.046 | AW6: =AW4+AW5 -> 422.97025 | AX6: =AX4+AX5 -> 458.91426 | BO6: =BO4+BO5 -> 1058 | BP6: =BP4+BP5 -> 1194 | BQ6: =SUM(AQ6:AT6) -> 1403.665 | BR6: =BR4+BR5 -> 1647.3919 | BS6: =BS4+BS5 -> 1978.3716 | BT6: =BT4+BT5 -> 2351.2719 | BU6: =BU4+BU5 -> 2741.2069 | BV6: =BV4+BV5 -> 3152.8745 | BW6: =BW4+BW5 -> 3589.0242 | BX6: =BX4+BX5 -> 4053.6029 | BY6: =BY4+BY5 -> 4542.1681 | ... CA6: =CA4+CA5 -> 5626.253
B8: Thrombectomy Revenue Growth Y/y | AM8: =AM4/AI4-1 -> 0.29655172 | AN8: =AN4/AJ4-1 -> 0.25308642 | AO8: =AO4/AK4-1 -> 0.1396648 | AP8: =AP4/AL4-1 -> 0.15183246 | AQ8: =AQ4/AM4-1 -> 0.20502128 | AR8: =AR4/AN4-1 -> 0.13426601 | AS8: =AS4/AO4-1 -> 0.15882353 | AT8: =AT4/AP4-1 -> 0.15780909 | AU8: 0.17 | AV8: 0.22 | AW8: 0.24 | AX8: 0.24 | BP8: =BP4/BO4-1 -> 0.20384047 | BQ8: =BQ4/BP4-1 -> 0.16308957 | BR8: 0.185 | BS8: 0.22 | BT8: 0.21 | BU8: 0.185 | BV8: 0.17 | BW8: 0.16 | BX8: 0.15 | BY8: 0.14 | BZ8: 0.135 | CA8: 0.13
B9: E & A Revenue Growth Y/y | AM9: =AM5/AI5-1 -> -0.052083333 | AN9: =AN5/AJ5-1 -> -0.03030303 | AO9: =AO5/AK5-1 -> 0.053152174 | AP9: =AP5/AL5-1 -> 0.011808511 | AQ9: =AQ5/AM5-1 -> 0.072483516 | AR9: =AR5/AN5-1 -> 0.13748958 | AS9: =AS5/AO5-1 -> 0.22097224 | AT9: =AT5/AP5-1 -> 0.37369362 | AU9: 0.16 | AV9: 0.105 | AW9: 0.0975 | AX9: 0.095 | BP9: =BP5/BO5-1 -> -0.0052493438 | BQ9: =BQ5/BP5-1 -> 0.20249868 | BR9: 0.15 | BS9: 0.16 | BT9: 0.14 | BU9: 0.12 | BV9: 0.1 | BW9: 0.08 | BX9: 0.07 | BY9: 0.06 | BZ9: 0.05 | CA9: 0.04
B10: Total Revenue Growth Y/y | AM10: =AM6/AI6-1 -> 0.15767635 | AN10: =AN6/AJ6-1 -> 0.14559387 | AO10: =AO6/AK6-1 -> 0.1102952 | AP10: =AP6/AL6-1 -> 0.10564912 | AQ10: =AQ6/AM6-1 -> 0.16179211 | AR10: =AR6/AN6-1 -> 0.135301 | AS10: =AS6/AO6-1 -> 0.17883612 | AT10: =AT6/AP6-1 -> 0.22296976 | ... AX10: =AX6/AT6-1 -> 0.19084065 | BP10: =BP6/BO6-1 -> 0.12854442 | BQ10: =BQ6/BP6-1 -> 0.17559883 | BR10: =BR6/BQ6-1 -> 0.17363607 | BS10: =BS6/BR6-1 -> 0.20091132 | BT10: =BT6/BS6-1 -> 0.18848854 | BU10: =BU6/BT6-1 -> 0.16584002 | BV10: =BV6/BU6-1 -> 0.15017749 | BW10: =BW6/BV6-1 -> 0.13833401 | ... CA10: =CA6/BZ6-1 -> 0.11049095
B12: Thrombectomy % of Ttl Revenues | AI12: =AI4/AI6 -> 0.60165975 | AJ12: =AJ4/AJ6 -> 0.62068966 | AK12: =AK4/AK6 -> 0.66051661 | AL12: =AL4/AL6 -> 0.67017544 | AM12: =AM4/AM6 -> 0.67383513 | AN12: =AN4/AN6 -> 0.67892977 | AO12: =AO4/AO6 -> 0.67798863 | AP12: =AP4/AP6 -> 0.69816889 | ... AX12: =AX4/AX6 -> 0.68825562 | BO12: =AVERAGE(AI12:AL12) -> 0.63826036 | BP12: =AVERAGE(AM12:AP12) -> 0.6822306 | BQ12: =AVERAGE(AN12:AQ12) -> 0.68849879 | BR12: =BR4/BR6 -> 0.68185527 | BS12: =BS4/BS6 -> 0.69269347 | BT12: =BT4/BT6 -> 0.70523111 | BU12: =BU4/BU6 -> 0.71682122 | BV12: =BV4/BV6 -> 0.72917514 | BW12: =BW4/BW6 -> 0.74305358 | BX12: =BX4/BX6 -> 0.75657704 | BY12: =BY4/BY6 -> 0.76972574 | ... CA12: =CA4/CA6 -> 0.79699255
B13: E & A % of Ttl Revenues | AI13: =AI5/AI6 -> 0.39834025 | AJ13: =AJ5/AJ6 -> 0.37931034 | AK13: =AK5/AK6 -> 0.33948339 | AL13: =AL5/AL6 -> 0.32982456 | AM13: =AM5/AM6 -> 0.32616487 | AN13: =AN5/AN6 -> 0.32107023 | AO13: =AO5/AO6 -> 0.32201137 | AP13: =AP5/AP6 -> 0.30183111 | ... AX13: =AX5/AX6 -> 0.31174438 | BO13: =AVERAGE(AI13:AL13) -> 0.36173964 | BP13: =AVERAGE(AM13:AP13) -> 0.3177694 | BQ13: =AVERAGE(AN13:AQ13) -> 0.31150121 | BR13: =BR5/BR6 -> 0.31814473 | BS13: =BS5/BS6 -> 0.30730653 | BT13: =BT5/BT6 -> 0.29476889 | BU13: =BU5/BU6 -> 0.28317878 | BV13: =BV5/BV6 -> 0.27082486 | BW13: =BW5/BW6 -> 0.25694642 | BX13: =BX5/BX6 -> 0.24342296 | BY13: =BY5/BY6 -> 0.23027426 | ... CA13: =CA5/CA6 -> 0.20300745
B15: U.S. Revenues | S15: 82.511 | T15: 86.374 | U15: 90.272 | V15: =355.22-SUM(S15:U15) -> 96.063 | W15: 96 | X15: 78 | Y15: 110 | Z15: =400-SUM(W15:Y15) -> 116 | AA15: 120 | AB15: 128 | AC15: 135 | AD15: =528-SUM(AA15:AC15) -> 145 | AE15: 144 | AF15: 141 | AG15: 149 | AH15: =592-SUM(AE15:AG15) -> 158 | AI15: 172 | AJ15: 186 | AK15: 195 | AL15: =757-SUM(AI15:AK15) -> 204 | AM15: 210 | AN15: 218 | AO15: 226 | AP15: =902-SUM(AM15:AO15) -> 248 | AQ15: 256.86 | AR15: 260.818 | AS15: 275.029 | AT15: =1091.761-SUM(AQ15:AS15) -> 299.054 | AU15: 296.387 | AV15: 305.445 | BK15: =SUM(S15:V15) -> 355.22 | BL15: =SUM(W15:Z15) -> 400 | BM15: =SUM(AA15:AC15) -> 383 | BN15: =SUM(AE15:AG15) -> 434 | BO15: =SUM(AI15:AL15) -> 757 | BP15: =SUM(AM15:AP15) -> 902 | BQ15: =SUM(AQ15:AT15) -> 1091.761
B16: International Revenues | S16: =9.522+36.406 -> 45.928 | T16: =12.231+35.596 -> 47.827 | U16: =11.214+38.016 -> 49.23 | V16: =42.52+149.663-SUM(S16:U16) -> 49.198 | W16: 41 | X16: 27 | Y16: 41 | Z16: =160-SUM(W16:Y16) -> 51 | AA16: 49 | AB16: 56 | AC16: 55 | AD16: =220-SUM(AA16:AC16) -> 60 | AE16: 60 | AF16: 67 | AG16: 65 | AH16: =255-SUM(AE16:AG16) -> 63 | AI16: 69 | AJ16: 75 | AK16: 76 | AL16: =301-SUM(AI16:AK16) -> 81 | AM16: 69 | AN16: 81 | AO16: 77 | AP16: =292-SUM(AM16:AO16) -> 65 | AQ16: 67.28 | AR16: 78.637 | AS16: 79.656 | AT16: =311.904-SUM(AQ16:AS16) -> 86.331 | AU16: 78.371 | AV16: 84.601 | BK16: =SUM(S16:V16) -> 192.183 | BL16: =SUM(W16:Z16) -> 160 | BM16: =SUM(AA16:AC16) -> 160 | BN16: =SUM(AE16:AG16) -> 192 | BO16: =SUM(AI16:AL16) -> 301 | BP16: =SUM(AM16:AP16) -> 292 | BQ16: =SUM(AQ16:AT16) -> 311.904
B17: Ttl Revenues | S17: =SUM(S15:S16) -> 128.439 | T17: =SUM(T15:T16) -> 134.201 | U17: =SUM(U15:U16) -> 139.502 | V17: =SUM(V15:V16) -> 145.261 | W17: =SUM(W15:W16) -> 137 | X17: =SUM(X15:X16) -> 105 | Y17: =SUM(Y15:Y16) -> 151 | Z17: =SUM(Z15:Z16) -> 167 | ... AV17: =SUM(AV15:AV16) -> 390.046 | BK17: =SUM(S17:V17) -> 547.403 | BL17: =SUM(W17:Z17) -> 560 | BM17: =SUM(AA17:AD17) -> 748 | BN17: =SUM(AE17:AH17) -> 847 | BO17: =SUM(AI17:AL17) -> 1058 | BP17: =SUM(AM17:AP17) -> 1194 | BQ17: =SUM(AQ17:AT17) -> 1403.665
B19: U.S. Revenue Growth Y/y | W19: =W15/S15-1 -> 0.16348123 | X19: =X15/T15-1 -> -0.096950471 | Y19: =Y15/U15-1 -> 0.21853952 | Z19: =Z15/V15-1 -> 0.20754088 | AA19: =AA15/W15-1 -> 0.25 | AB19: =AB15/X15-1 -> 0.64102564 | AC19: =AC15/Y15-1 -> 0.22727273 | AD19: =AD15/Z15-1 -> 0.25 | ... AV19: =AV15/AR15-1 -> 0.17110399 | BL19: =BL15/BK15-1 -> 0.12606272 | BM19: =BM15/BL15-1 -> -0.0425 | BN19: =BN15/BM15-1 -> 0.13315927 | BO19: =BO15/BN15-1 -> 0.74423963 | BP19: =BP15/BO15-1 -> 0.19154557 | BQ19: =BQ15/BP15-1 -> 0.21037805
B20: International Revenue Growth Y/y | W20: =W16/S16-1 -> -0.10729838 | X20: =X16/T16-1 -> -0.43546532 | Y20: =Y16/U16-1 -> -0.16717449 | Z20: =Z16/V16-1 -> 0.036627505 | AA20: =AA16/W16-1 -> 0.19512195 | AB20: =AB16/X16-1 -> 1.0740741 | AC20: =AC16/Y16-1 -> 0.34146341 | AD20: =AD16/Z16-1 -> 0.17647059 | ... AV20: =AV16/AR16-1 -> 0.075842161 | BL20: =BL16/BK16-1 -> -0.16746018 | BM20: =BM16/BL16-1 -> 0 | BN20: =BN16/BM16-1 -> 0.2 | BO20: =BO16/BN16-1 -> 0.56770833 | BP20: =BP16/BO16-1 -> -0.029900332 | BQ20: =BQ16/BP16-1 -> 0.068164384
B21: Total Revenue Growth Y/y | W21: =W17/S17-1 -> 0.066654209 | X21: =X17/T17-1 -> -0.21759152 | Y21: =Y17/U17-1 -> 0.082421757 | Z21: =Z17/V17-1 -> 0.14965476 | AA21: =AA17/W17-1 -> 0.23357664 | AB21: =AB17/X17-1 -> 0.75238095 | AC21: =AC17/Y17-1 -> 0.25827815 | AD21: =AD17/Z17-1 -> 0.22754491 | ... AV21: =AV17/AR17-1 -> 0.14903595 | BL21: =BL17/BK17-1 -> 0.023012296 | BM21: =BM17/BL17-1 -> 0.33571429 | BN21: =BN17/BM17-1 -> 0.13235294 | BO21: =BO17/BN17-1 -> 0.24911452 | BP21: =BP17/BO17-1 -> 0.12854442 | BQ21: =BQ17/BP17-1 -> 0.17559883
B23: U.S. % of Ttl Revenues | S23: =S15/S17 -> 0.64241391 | T23: =T15/T17 -> 0.64361666 | U23: =U15/U17 -> 0.64710183 | V23: =V15/V17 -> 0.66131308 | W23: =W15/W17 -> 0.70072993 | X23: =X15/X17 -> 0.74285714 | Y23: =Y15/Y17 -> 0.72847682 | Z23: =Z15/Z17 -> 0.69461078 | ... AV23: =AV15/AV17 -> 0.78309994 | BK23: =BK15/BK17 -> 0.64891862 | BL23: =BL15/BL17 -> 0.71428571 | BM23: =BM15/BM17 -> 0.51203209 | BN23: =BN15/BN17 -> 0.51239669 | BO23: =BO15/BO17 -> 0.71550095 | BP23: =BP15/BP17 -> 0.75544389 | BQ23: =BQ15/BQ17 -> 0.77779313
B24: International % of Ttl Revenues | S24: =S16/S17 -> 0.35758609 | T24: =T16/T17 -> 0.35638334 | U24: =U16/U17 -> 0.35289817 | V24: =V16/V17 -> 0.33868692 | W24: =W16/W17 -> 0.29927007 | X24: =X16/X17 -> 0.25714286 | Y24: =Y16/Y17 -> 0.27152318 | Z24: =Z16/Z17 -> 0.30538922 | ... AV24: =AV16/AV17 -> 0.21690006 | BK24: =BK16/BK17 -> 0.35108138 | BL24: =BL16/BL17 -> 0.28571429 | BM24: =BM16/BM17 -> 0.21390374 | BN24: =BN16/BN17 -> 0.22668241 | BO24: =BO16/BO17 -> 0.28449905 | BP24: =BP16/BP17 -> 0.24455611 | BQ24: =BQ16/BQ17 -> 0.22220687
B26: Revenues | C26: 39 | D26: 42.3 | E26: 50.4 | F26: 54.4 | G26: 57.9 | H26: 65.1 | I26: 67.2 | J26: 73.1 | K26: 73.2 | L26: 80.6 | M26: 83.9 | N26: 96.1 | O26: 102.7 | P26: 109.6 | Q26: 111.8 | R26: 120.8 | S26: =S17 -> 128.439 | T26: =T17 -> 134.201 | U26: =U17 -> 139.502 | V26: =V17 -> 145.261 | W26: 137.3 | X26: 105.1 | Y26: 151.1 | Z26: =560.412-SUM(W26:Y26) -> 166.912 | AA26: 169.2 | AB26: 184.3 | AC26: 190.1 | AD26: =747.59-SUM(AA26:AC26) -> 203.99 | AE26: 203.9 | AF26: 208.3 | AG26: 213.7 | AH26: =847.133-SUM(AE26:AG26) -> 221.233 | AI26: 241.4 | AJ26: 261.5 | AK26: 270.9 | AL26: =1058.52-SUM(AI26:AK26) -> 284.72 | AM26: 278.7 | AN26: 299.4 | AO26: 301 | AP26: =1194.6-SUM(AM26:AO26) -> 315.5 | AQ26: =AQ17 -> 324.14 | AR26: =AR17 -> 339.455 | AS26: =AS17 -> 354.685 | AT26: =1403.665-SUM(AQ26:AS26) -> 385.385 | AU26: =AU17 -> 374.758 | AV26: =AV17 -> 390.046 | AW26: =AW6 -> 422.97025 | AX26: =AX6 -> 458.91426 | BG26: =SUM(C26:F26) -> 186.1 | BH26: =SUM(G26:J26) -> 263.3 | BI26: =SUM(K26:N26) -> 333.8 | BJ26: =SUM(O26:R26) -> 444.9 | BK26: =SUM(S26:V26) -> 547.403 | BL26: =SUM(W26:Z26) -> 560.412 | BM26: =SUM(AA26:AD26) -> 747.59 | BN26: =SUM(AE26:AH26) -> 847.133 | BO26: =SUM(AI26:AL26) -> 1058.52 | BP26: =SUM(AM26:AP26) -> 1194.6 | BQ26: =SUM(AQ26:AT26) -> 1403.665 | BR26: =BR6 -> 1647.3919 | BS26: =BS6 -> 1978.3716 | BT26: =BT6 -> 2351.2719 | BU26: =BU6 -> 2741.2069 | BV26: =BV6 -> 3152.8745 | BW26: =BW6 -> 3589.0242 | BX26: =BX6 -> 4053.6029 | BY26: =BY6 -> 4542.1681 | ... CA26: =CA6 -> 5626.253
B27: COGS | C27: 12.2 | D27: 14.9 | E27: 16.9 | F27: 18 | G27: 18 | H27: 23.6 | I27: 24.3 | J27: 26.5 | K27: 25.5 | L27: 29.7 | M27: 29.1 | N27: 32.3 | O27: 36.1 | P27: 37.4 | Q27: 36.8 | R27: 42.1 | S27: 44.529 | T27: 40.273 | U27: 43.504 | V27: =175.441-SUM(S27:U27) -> 47.135 | W27: 49.3 | X27: 40.2 | Y27: 60.153 | Z27: =222.237-SUM(W27:Y27) -> 72.584 | AA27: 57.867 | AB27: 65.6 | AC27: 70.2 | AD27: =272.208-SUM(AA27:AC27) -> 78.541 | AE27: 76.5 | AF27: 74.3 | AG27: 78.4 | AH27: =311.926-SUM(AE27:AG27) -> 82.726 | AI27: 90.3 | AJ27: 94.6 | AK27: 93.2 | AL27: =375.9-SUM(AI27:AK27) -> 97.8 | AM27: 97.5 | AN27: 136.6 | AO27: 100.7 | AP27: =439.6-SUM(AM27:AO27) -> 104.8 | AQ27: 108.257 | AR27: 115.445 | AS27: 114.269 | AT27: =461.228-SUM(AQ27:AS27) -> 123.257 | AU27: 121.347 | AV27: 125.102 | AW27: =AW26*(1-AW43) -> 130.27484 | AX27: =AX26*(1-AX43) -> 137.67428 | BG27: =SUM(C27:F27) -> 62 | BH27: =SUM(G27:J27) -> 92.4 | BI27: =SUM(K27:N27) -> 116.6 | BJ27: =SUM(O27:R27) -> 152.4 | BK27: =SUM(S27:V27) -> 175.441 | BL27: =SUM(W27:Z27) -> 222.237 | BM27: =SUM(AA27:AD27) -> 272.208 | BN27: =SUM(AE27:AH27) -> 311.926 | BO27: =SUM(AI27:AL27) -> 375.9 | BP27: =SUM(AM27:AP27) -> 439.6 | BQ27: =SUM(AQ27:AT27) -> 461.228 | BR27: =BR26*(1-BR43) -> 535.40236 | BS27: =BS26*(1-BS43) -> 609.33844 | BT27: =BT26*(1-BT43) -> 698.32776 | BU27: =BU26*(1-BU43) -> 794.95 | BV27: =BV26*(1-BV43) -> 898.56922 | BW27: =BW26*(1-BW43) -> 1004.9268 | BX27: =BX26*(1-BX43) -> 1114.7408 | BY27: =BY26*(1-BY43) -> 1226.3854 | ... CA27: =CA26*(1-CA43) -> 1462.8258
B28: GP | C28: =C26-C27 -> 26.8 | D28: =D26-D27 -> 27.4 | E28: =E26-E27 -> 33.5 | F28: =F26-F27 -> 36.4 | G28: =G26-G27 -> 39.9 | H28: =H26-H27 -> 41.5 | I28: =I26-I27 -> 42.9 | J28: =J26-J27 -> 46.6 | ... AX28: =AX26-AX27 -> 321.23998 | BG28: =SUM(C28:F28) -> 124.1 | BH28: =SUM(G28:J28) -> 170.9 | BI28: =SUM(K28:N28) -> 217.2 | BJ28: =SUM(O28:R28) -> 292.5 | BK28: =BK26-BK27 -> 371.962 | BL28: =BL26-BL27 -> 338.175 | BM28: =BM26-BM27 -> 475.382 | BN28: =BN26-BN27 -> 535.207 | BO28: =BO26-BO27 -> 682.62 | BP28: =BP26-BP27 -> 755 | BQ28: =SUM(AQ28:AT28) -> 942.437 | BR28: =BR26-BR27 -> 1111.9895 | BS28: =BS26-BS27 -> 1369.0331 | BT28: =BT26-BT27 -> 1652.9442 | BU28: =BU26-BU27 -> 1946.2569 | BV28: =BV26-BV27 -> 2254.3052 | BW28: =BW26-BW27 -> 2584.0975 | BX28: =BX26-BX27 -> 2938.8621 | BY28: =BY26-BY27 -> 3315.7827 | ... CA28: =CA26-CA27 -> 4163.4272
B29: R&D | C29: 3.2 | D29: 4.8 | E29: 4.6 | F29: 5.5 | G29: 5 | H29: 6.3 | I29: 6.5 | J29: 6.1 | K29: 7 | L29: 8.1 | M29: 8.1 | N29: 8.4 | O29: 8 | P29: 8.2 | Q29: 39.9 | R29: 10.9 | S29: 11.667 | T29: 13.462 | U29: 13.733 | V29: =51.723-SUM(S29:U29) -> 12.861 | W29: 12.946 | X29: 22.725 | Y29: 34.923 | Z29: =90.049-SUM(W29:Y29) -> 19.455 | AA29: 18.076 | AB29: 17.738 | AC29: 16.73 | AD29: =104.552-SUM(AA29:AC29) -> 52.008 | AE29: 20.56 | AF29: 19.559 | AG29: 21.32 | AH29: =79.407-SUM(AE29:AG29) -> 17.968 | AI29: 19.98 | AJ29: 21.5 | AK29: 21 | AL29: =84.4-SUM(AI29:AK29) -> 21.92 | AM29: 24.6 | AN29: 24.9 | AO29: 25.2 | AP29: =94.8-SUM(AM29:AO29) -> 20.1 | AQ29: 22.077 | AR29: 23.218 | AS29: 22.677 | AT29: =89.766-SUM(AQ29:AS29) -> 21.794 | AU29: 22.382 | AV29: 25.396 | AW29: =AW26*AW44 -> 31.722769 | AX29: =AX26*AX44 -> 34.418569 | BG29: =SUM(C29:F29) -> 18.1 | BH29: =SUM(G29:J29) -> 23.9 | BI29: =SUM(K29:N29) -> 31.6 | BJ29: =SUM(O29:R29) -> 67 | BK29: =SUM(S29:V29) -> 51.723 | BL29: =SUM(W29:Z29) -> 90.049 | BM29: =SUM(AA29:AD29) -> 104.552 | BN29: =SUM(AE29:AH29) -> 79.407 | BO29: =SUM(AI29:AL29) -> 84.4 | BP29: =SUM(AM29:AP29) -> 94.8 | BQ29: =SUM(AQ29:AT29) -> 89.766 | BR29: =BR26*BR44 -> 120.25961 | BS29: =BS26*BS44 -> 148.37787 | BT29: =BT26*BT44 -> 188.10175 | BU29: =BU26*BU44 -> 233.00259 | BV29: =BV26*BV44 -> 283.7587 | BW29: =BW26*BW44 -> 340.9573 | BX29: =BX26*BX44 -> 374.95827 | BY29: =BY26*BY44 -> 408.79513 | ... CA29: =CA26*CA44 -> 506.36277
B30: SG&A | C30: 19.5 | D30: 26.4 | E30: 26.8 | F30: 29.2 | G30: 33.1 | H30: 35.9 | I30: 37.7 | J30: 41.6 | K30: 42.7 | L30: 44.2 | M30: 46 | N30: 51.5 | O30: 54.5 | P30: 54.8 | Q30: 55.9 | R30: 61.2 | S30: 61.091 | T30: 67.665 | U30: 69.289 | V30: =272.733-SUM(S30:U30) -> 74.688 | W30: 74.453 | X30: 59.8 | Y30: 76.2 | Z30: =287.068-SUM(W30:Y30) -> 76.615 | AA30: 79.798 | AB30: 90.63 | AC30: 94.397 | AD30: =378.331-SUM(AA30:AC30) -> 113.506 | AE30: 110.9 | AF30: 114.615 | AG30: 108.57 | AH30: =449.718-SUM(AE30:AG30) -> 115.633 | AI30: 123.07 | AJ30: 127.4 | AK30: 125.9 | AL30: =506.4-SUM(AI30:AK30) -> 130.03 | AM30: 144.4 | AN30: 141.9 | AO30: 139.7 | AP30: =574-SUM(AM30:AO30) -> 148 | AQ30: 153.456 | AR30: 159.964 | AS30: 168.901 | AT30: =663.422-SUM(AQ30:AS30) -> 181.101 | AU30: 192.795 | AV30: 198.509 | AW30: =AW26*AW45 -> 195.41226 | AX30: =AX26*AX45 -> 211.10056 | BG30: =SUM(C30:F30) -> 101.9 | BH30: =SUM(G30:J30) -> 148.3 | BI30: =SUM(K30:N30) -> 184.4 | BJ30: =SUM(O30:R30) -> 226.4 | BK30: =SUM(S30:V30) -> 272.733 | BL30: =SUM(W30:Z30) -> 287.068 | BM30: =SUM(AA30:AD30) -> 378.331 | BN30: =SUM(AE30:AH30) -> 449.718 | BO30: =SUM(AI30:AL30) -> 506.4 | BP30: =SUM(AM30:AP30) -> 574 | BQ30: =SUM(AQ30:AT30) -> 663.422 | BR30: =BR26*BR45 -> 766.03722 | BS30: =BS26*BS45 -> 895.21313 | BT30: =BT26*BT45 -> 1048.6673 | BU30: =BU26*BU45 -> 1203.3898 | BV30: =BV26*BV45 -> 1371.5004 | BW30: =BW26*BW45 -> 1552.253 | BX30: =BX26*BX45 -> 1734.9421 | BY30: =BY26*BY45 -> 1930.4215 | ... CA30: =CA26*CA45 -> 2306.7637
B31: Acquired In-Process R&D | C31: 0 | D31: 0 | E31: 0 | F31: 0 | G31: 0 | H31: 0 | I31: 0 | J31: 0 | K31: 0 | L31: 0 | M31: 0 | N31: 0 | O31: 0 | P31: 0 | Q31: 0 | R31: 0 | S31: 0 | T31: 0 | U31: 0 | V31: =0-SUM(S31:U31) -> 0 | W31: 0 | X31: 0 | Y31: 0 | Z31: =0-SUM(W31:Y31) -> 0 | AA31: 0 | AB31: 0 | AC31: 0 | AD31: =0-SUM(AA31:AC31) -> 0 | AE31: 0 | AF31: 0 | AG31: 0 | AH31: =0-SUM(AE31:AG31) -> 0 | AI31: 0 | AJ31: 0 | AK31: 18.2 | AL31: =18.2-SUM(AI31:AK31) -> 0 | AM31: 0 | AN31: 0 | AO31: 0 | AP31: =0-SUM(AM31:AO31) -> 0 | AQ31: 0 | AR31: 0 | AS31: 0 | AT31: =0-SUM(AQ31:AS31) -> 0 | AU31: 0 | AV31: 0 | AW31: 0 | AX31: 0 | BG31: =SUM(C31:F31) -> 0 | BH31: =SUM(G31:J31) -> 0 | BI31: =SUM(K31:N31) -> 0 | BJ31: =SUM(O31:R31) -> 0 | BK31: =SUM(S31:V31) -> 0 | BL31: =SUM(W31:Z31) -> 0 | BM31: =SUM(AA31:AD31) -> 0 | BN31: =SUM(AE31:AH31) -> 0 | BO31: =SUM(AI31:AL31) -> 18.2 | BP31: =SUM(AM31:AP31) -> 0 | BQ31: =SUM(AQ31:AT31) -> 0 | BR31: 0 | BS31: 0 | BT31: 0 | BU31: 0 | BV31: 0 | BW31: 0 | BX31: 0 | BY31: 0 | BZ31: 0 | CA31: 0
B32: Impairment Charges | C32: 0.1 | D32: =31.2-SUM(D29:D31) -> 0 | E32: =31.3-SUM(E29:E31) -> -0.1 | F32: =34.6-SUM(F29:F31) -> -0.1 | G32: =38.1-SUM(G29:G31) -> 0 | H32: 0 | I32: 0.1 | J32: 0.1 | K32: 0 | L32: -0.1 | M32: 0 | N32: 0 | O32: 0.1 | P32: -0.1 | Q32: 0 | R32: -0.1 | S32: 0 | T32: 0 | U32: 0 | V32: =0-SUM(S32:U32) -> 0 | W32: 0 | X32: 0 | Y32: 0 | Z32: =0-SUM(W32:Y32) -> 0 | AA32: 0 | AB32: 0 | AC32: 0 | AD32: =0-SUM(AA32:AC32) -> 0 | AE32: 0 | AF32: 0 | AG32: 0 | AH32: =0-SUM(AE32:AG32) -> 0 | AI32: 0 | AJ32: 0 | AK32: 0 | AL32: =0-SUM(AI32:AK32) -> 0 | AM32: 0 | AN32: 76.9 | AO32: 0 | AP32: =76.94-SUM(AM32:AO32) -> 0.04 | AQ32: 0 | AR32: 0 | AS32: 0 | AT32: =0-SUM(AQ32:AS32) -> 0 | AU32: 0 | AV32: 0 | AW32: 0 | AX32: 0 | BG32: =SUM(C32:F32) -> -0.1 | BH32: =SUM(G32:J32) -> 0.2 | BI32: =SUM(K32:N32) -> -0.1 | BJ32: =SUM(O32:R32) -> -0.1 | BK32: =SUM(S32:V32) -> 0 | BL32: =SUM(W32:Z32) -> 0 | BM32: =SUM(AA32:AD32) -> 0 | BN32: =SUM(AE32:AH32) -> 0 | BO32: =SUM(AI32:AL32) -> 0 | BP32: =SUM(AM32:AP32) -> 76.94 | BQ32: =SUM(AQ32:AT32) -> 0 | BR32: 0 | BS32: 0 | BT32: 0 | BU32: 0 | BV32: 0 | BW32: 0 | BX32: 0 | BY32: 0 | BZ32: 0 | CA32: 0
B33: Operating Income | C33: =C28-SUM(C29:C32) -> 4 | D33: =D28-SUM(D29:D32) -> -3.8 | E33: =E28-SUM(E29:E32) -> 2.2 | F33: =F28-SUM(F29:F32) -> 1.8 | G33: =G28-SUM(G29:G32) -> 1.8 | H33: =H28-SUM(H29:H32) -> -0.7 | I33: =I28-SUM(I29:I32) -> -1.4 | J33: =J28-SUM(J29:J32) -> -1.2 | ... T33: =T28-SUM(T29:T32) -> 12.801 | U33: 12.976 | V33: =V28-SUM(V29:V32) -> 10.577 | W33: =W28-SUM(W29:W32) -> 0.601 | X33: =X28-SUM(X29:X32) -> -17.625 | Y33: =Y28-SUM(Y29:Y32) -> -20.176 | Z33: =Z28-SUM(Z29:Z32) -> -1.742 | AA33: =AA28-SUM(AA29:AA32) -> 13.459 | AB33: =AB28-SUM(AB29:AB32) -> 10.332 | AC33: =AC28-SUM(AC29:AC32) -> 8.773 | ... AX33: =AX28-SUM(AX29:AX32) -> 75.720853 | BG33: =SUM(C33:F33) -> 4.2 | BH33: =SUM(G33:J33) -> -1.5 | BI33: =SUM(K33:N33) -> 1.3 | BJ33: =SUM(O33:R33) -> -0.8 | BK33: =BK28-SUM(BK29:BK32) -> 47.506 | BL33: =BL28-SUM(BL29:BL32) -> -38.942 | BM33: =BM28-SUM(BM29:BM32) -> -7.501 | BN33: =BN28-SUM(BN29:BN32) -> 6.082 | BO33: =BO28-SUM(BO29:BO32) -> 73.62 | BP33: =BP28-SUM(BP29:BP32) -> 9.26 | BQ33: =SUM(AQ33:AT33) -> 189.249 | BR33: =BR28-SUM(BR29:BR32) -> 225.69269 | BS33: =BS28-SUM(BS29:BS32) -> 325.44212 | BT33: =BT28-SUM(BT29:BT32) -> 416.17513 | BU33: =BU28-SUM(BU29:BU32) -> 509.86449 | BV33: =BV28-SUM(BV29:BV32) -> 599.04615 | BW33: =BW28-SUM(BW29:BW32) -> 690.88717 | BX33: =BX28-SUM(BX29:BX32) -> 828.9618 | BY33: =BY28-SUM(BY29:BY32) -> 976.56615 | ... CA33: =CA28-SUM(CA29:CA32) -> 1350.3007
B34: Interest and Other Income, net | C34: 0.3 | D34: -0.4 | E34: -0.1 | F34: 0.1 | G34: 0.3 | H34: 0.3 | I34: 0.3 | J34: -0.4 | K34: 0.3 | L34: 0.4 | M34: 0.6 | N34: 0 | O34: 0.5 | P34: 0.4 | Q34: 0.9 | R34: 0.7 | S34: =0.733+0.024 -> 0.757 | T34: =0.784-0.071 -> 0.713 | U34: =0.759-0.772 -> -0.013 | V34: =2.854-0.227-SUM(S34:U34) -> 1.17 | W34: =0.299-1.555 -> -1.256 | X34: =0.108+0.508 -> 0.616 | Y34: =0.413+0.014 -> 0.427 | Z34: =1.267-0.243-SUM(W34:Y34) -> 1.237 | AA34: =0.48-1.476 -> -0.996 | AB34: =0.299-0.408 -> -0.109 | AC34: =0.138-1.137 -> -0.999 | AD34: =0.938-3.939-SUM(AA34:AC34) -> -0.897 | AE34: =-0.041-1.01 -> -1.051 | AF34: =-0.07-0.9 -> -0.97 | AG34: =-0.04-2.35 -> -2.39 | AH34: =0.137-2.327-SUM(AE34:AG34) -> 2.221 | AI34: 0.644 | AJ34: 1.6 | AK34: 0.7 | AL34: =6.09-SUM(AI34:AK34) -> 3.146 | AM34: 2.5 | AN34: 3.1 | AO34: 4.4 | AP34: =11.59-SUM(AM34:AO34) -> 1.59 | AQ34: 3.508 | AR34: 4.482 | AS34: 3.487 | AT34: =15.876-SUM(AQ34:AS34) -> 4.399 | AU34: 3.454 | AV34: 5.148 | AW34: =AV50*0.045 -> 9.237195 | AX34: =AW50*0.045 -> 11.409795 | BG34: =SUM(C34:F34) -> -0.1 | BH34: =SUM(G34:J34) -> 0.5 | BI34: =SUM(K34:N34) -> 1.3 | BJ34: =SUM(O34:R34) -> 2.5 | BK34: =SUM(S34:V34) -> 2.627 | BL34: =SUM(W34:Z34) -> 1.024 | BM34: =SUM(AA34:AD34) -> -3.001 | BN34: =SUM(AE34:AH34) -> -2.19 | BO34: =SUM(AI34:AL34) -> 6.09 | BP34: =SUM(AM34:AP34) -> 11.59 | BQ34: =SUM(AQ34:AT34) -> 15.876 | BR34: =BQ50*$CA$53 -> 30.743405 | BS34: =BR50*$CA$53 -> 64.490395 | BT34: =BS50*$CA$53 -> 114.52264 | BU34: =BT50*$CA$53 -> 181.74347 | BV34: =BU50*$CA$53 -> 269.34599 | BW34: =BV50*$CA$53 -> 379.34088 | BX34: =BW50*$CA$53 -> 514.90132 | BY34: =BX50*$CA$53 -> 685.12174 | ... CA34: =BZ50*$CA$53 -> 1153.4326
B35: Pretax Income | C35: =C33+C34 -> 4.3 | D35: =D33+D34 -> -4.2 | E35: =E33+E34 -> 2.1 | F35: =F33+F34 -> 1.9 | G35: =G33+G34 -> 2.1 | H35: =H33+H34 -> -0.4 | I35: =I33+I34 -> -1.1 | J35: =J33+J34 -> -1.6 | ... AX35: =AX33+AX34 -> 87.130648 | BG35: =SUM(C35:F35) -> 4.1 | BH35: =SUM(G35:J35) -> -1 | BI35: =SUM(K35:N35) -> 2.6 | BJ35: =SUM(O35:R35) -> 1.7 | BK35: =BK33+BK34 -> 50.133 | BL35: =BL33+BL34 -> -37.918 | BM35: =BM33+BM34 -> -10.502 | BN35: =BN33+BN34 -> 3.892 | BO35: =BO33+BO34 -> 79.71 | BP35: =BP33+BP34 -> 20.85 | BQ35: =SUM(AQ35:AT35) -> 205.125 | BR35: =BR33+BR34 -> 256.43609 | BS35: =BS33+BS34 -> 389.93251 | BT35: =BT33+BT34 -> 530.69777 | BU35: =BU33+BU34 -> 691.60795 | BV35: =BV33+BV34 -> 868.39214 | BW35: =BW33+BW34 -> 1070.228 | BX35: =BX33+BX34 -> 1343.8631 | BY35: =BY33+BY34 -> 1661.6879 | ... CA35: =CA33+CA34 -> 2503.7333
B36: Tax Expense (Benefit) | C36: 1.7 | D36: -1.5 | E36: 1.2 | F36: 0.2 | G36: -0.2 | H36: -3.4 | I36: -13 | J36: 0.9 | K36: 1.4 | L36: 0.5 | M36: 0.5 | N36: -5.9 | O36: -1.9 | P36: -4.9 | Q36: 1.6 | R36: 0.9 | S36: 1.455 | T36: -2.735 | U36: 1.963 | V36: =3.131-SUM(S36:U36) -> 2.448 | W36: -1.634 | X36: -4.129 | Y36: -9.855 | Z36: =-18.761-SUM(W36:Y36) -> -3.143 | AA36: 1.541 | AB36: 1.9 | AC36: -0.249 | AD36: =-13.125-SUM(AA36:AC36) -> -16.317 | AE36: -5.183 | AF36: 2.52 | AG36: 5.3 | AH36: =5.894-SUM(AE36:AG36) -> 3.257 | AI36: 0.09 | AJ36: 0.5 | AK36: 4.09 | AL36: =-11.3-SUM(AI36:AK36) -> -15.98 | AM36: 3.6 | AN36: -17.6 | AO36: 10.3 | AP36: =6.86-SUM(AM36:AO36) -> 10.56 | AQ36: 4.635 | AR36: 0.04 | AS36: 6.474 | AT36: =27.438-SUM(AQ36:AS36) -> 16.289 | AU36: 9.104 | AV36: 11.376 | AW36: =AW35*AW47 -> 17.203444 | AX36: =AX35*AX47 -> 20.040049 | BG36: =SUM(C36:F36) -> 1.6 | BH36: =SUM(G36:J36) -> -15.7 | BI36: =SUM(K36:N36) -> -3.5 | BJ36: =SUM(O36:R36) -> -4.3 | BK36: =SUM(S36:V36) -> 3.131 | BL36: =SUM(W36:Z36) -> -18.761 | BM36: =SUM(AA36:AD36) -> -13.125 | BN36: =SUM(AE36:AH36) -> 5.894 | BO36: =SUM(AI36:AL36) -> -11.3 | BP36: =SUM(AM36:AP36) -> 6.86 | BQ36: =SUM(AQ36:AT36) -> 27.438 | BR36: =BR35*BR47 -> 51.287219 | BS36: =BS35*BS47 -> 85.785153 | BT36: =BT35*BT47 -> 122.06049 | BU36: =BU35*BU47 -> 159.06983 | BV36: =BV35*BV47 -> 199.73019 | BW36: =BW35*BW47 -> 246.15245 | BX36: =BX35*BX47 -> 309.08852 | BY36: =BY35*BY47 -> 382.18821 | ... CA36: =CA35*CA47 -> 575.85867
B37: Consolidated Net Income | C37: 2.5 | D37: -2.7 | E37: 0.9 | F37: 1.6 | G37: 2.3 | H37: 3 | I37: 11.9 | J37: -2.4 | K37: -3.1 | L37: -1.6 | M37: 0.2 | N37: 9.1 | O37: 5.5 | P37: 13.4 | Q37: -22.4 | R37: 6.5 | S37: =S35-S36 -> 10.454 | T37: =T35-T36 -> 16.249 | U37: =U35-U36 -> 11 | V37: =V35-V36 -> 9.299 | W37: =W35-W36 -> 0.979 | X37: =X35-X36 -> -12.88 | Y37: =Y35-Y36 -> -9.894 | Z37: =Z35-Z36 -> 2.638 | ... AX37: =AX35-AX36 -> 67.090599 | BG37: =SUM(C37:F37) -> 2.3 | BH37: =SUM(G37:J37) -> 14.8 | BI37: =SUM(K37:N37) -> 4.6 | BJ37: =SUM(O37:R37) -> 3 | BK37: =BK35-BK36 -> 47.002 | BL37: =BL35-BL36 -> -19.157 | BM37: =BM35-BM36 -> 2.623 | BN37: =BN35-BN36 -> -2.002 | BO37: =BO35-BO36 -> 91.01 | BP37: =BP35-BP36 -> 13.99 | BQ37: =SUM(AQ37:AT37) -> 177.687 | BR37: =BR35-BR36 -> 205.14887 | BS37: =BS35-BS36 -> 304.14736 | BT37: =BT35-BT36 -> 408.63728 | BU37: =BU35-BU36 -> 532.53812 | BV37: =BV35-BV36 -> 668.66195 | BW37: =BW35-BW36 -> 824.0756 | BX37: =BX35-BX36 -> 1034.7746 | BY37: =BY35-BY36 -> 1279.4997 | ... CA37: =CA35-CA36 -> 1927.8747
B38: Net Income attr to Non-Cont. | C38: 2 | D38: -2.15 | E38: 0.58 | F38: 0.85 | G38: -0.2 | H38: 0 | I38: -0.3 | J38: 0 | K38: 0 | L38: 0 | M38: 0 | N38: 0 | O38: 0 | P38: 0 | Q38: -3.5 | R38: -0.02 | S38: -0.244 | T38: -0.537 | U38: -0.483 | V38: =-1.454-SUM(S38:U38) -> -0.19 | W38: -0.537 | X38: -0.94 | Y38: -1.061 | Z38: =-3.555-SUM(W38:Y38) -> -1.017 | AA38: -0.91 | AB38: -0.932 | AC38: -0.819 | AD38: =-2.641-SUM(AA38:AC38) -> 0.02 | AE38: 0 | AF38: 0 | AG38: 0 | AH38: 0 | AI38: 0 | AJ38: 0 | AK38: 0 | AL38: 0 | AM38: 0 | AN38: 0 | AO38: 0 | AP38: 0 | AQ38: 0 | AR38: 0 | AS38: 0 | AT38: 0 | AU38: 0 | AV38: 0 | AW38: 0 | AX38: 0 | BG38: =SUM(C38:F38) -> 1.28 | BH38: =SUM(G38:J38) -> -0.5 | BI38: =SUM(K38:N38) -> 0 | BJ38: =SUM(O38:R38) -> -3.52 | BK38: =SUM(S38:V38) -> -1.454 | BL38: -3.555 | BM38: -2.661 | BN38: 0 | BO38: 0 | BP38: 0 | BQ38: =SUM(AQ38:AT38) -> 0 | BR38: 0 | BS38: 0 | BT38: 0 | BU38: 0 | BV38: 0 | BW38: 0 | BX38: 0 | BY38: 0 | BZ38: 0 | CA38: 0
B39: Net Income attr to PEN | C39: =C37-C38 -> 0.5 | D39: =D37-D38 -> -0.55 | E39: =E37-E38 -> 0.32 | F39: =F37-F38 -> 0.75 | G39: =G37-G38 -> 2.5 | H39: =H37-H38 -> 3 | I39: =I37-I38 -> 12.2 | J39: =J37-J38 -> -2.4 | ... AV39: =AV37-AV38 -> 34.811 | AW39: 48.28 | AX39: 56.5 | BG39: =SUM(C39:F39) -> 1.02 | BH39: =SUM(G39:J39) -> 15.3 | BI39: =SUM(K39:N39) -> 4.6 | BJ39: =SUM(O39:R39) -> 6.52 | BK39: =BK37-BK38 -> 48.456 | BL39: =BL37-BL38 -> -15.602 | BM39: =BM37-BM38 -> 5.284 | BN39: =BN37-BN38 -> -2.002 | BO39: =BO37-BO38 -> 91.01 | BP39: =BP37-BP38 -> 13.99 | BQ39: =SUM(AQ39:AT39) -> 177.687 | BR39: =BR37-BR38 -> 205.14887 | BS39: =BS37-BS38 -> 304.14736 | BT39: =BT37-BT38 -> 408.63728 | BU39: =BU37-BU38 -> 532.53812 | BV39: =BV37-BV38 -> 668.66195 | BW39: =BW37-BW38 -> 824.0756 | BX39: =BX37-BX38 -> 1034.7746 | BY39: =BY37-BY38 -> 1279.4997 | ... CA39: =CA37-CA38 -> 1927.8747 | CB39: =CA39*(1+$CA$54) -> 1977.0355 | CC39: =CB39*(1+$CA$54) -> 2027.4499 | CD39: =CC39*(1+$CA$54) -> 2079.1499 | CE39: =CD39*(1+$CA$54) -> 2132.1682 | CF39: =CE39*(1+$CA$54) -> 2186.5385 | CG39: =CF39*(1+$CA$54) -> 2242.2952 | CH39: =CG39*(1+$CA$54) -> 2299.4737 | CI39: =CH39*(1+$CA$54) -> 2358.1103 | ... DO39: =DN39*(1+$CA$54) -> 5278.4375
B40: SC | C40: 5 | D40: 5 | E40: 8 | F40: 12 | G40: 30 | H40: 30 | I40: 31 | J40: 30 | K40: 32 | L40: 33 | M40: 33 | N40: 33 | O40: 34 | P40: 34 | Q40: 34 | R40: 34 | S40: 34.507 | T40: 34.694 | U40: 34.84 | V40: 35 | W40: 35 | X40: 35.4 | Y40: 36.207 | Z40: 37.651 | AA40: 36.455 | AB40: 36.523 | AC40: 36.617 | AD40: 36.7 | AE40: 37.646 | AF40: 37.767 | AG40: 37.918 | AH40: 37.841 | AI40: 39.07 | AJ40: 38.15 | AK40: 38.956 | AL40: 38.4 | AM40: 39.3 | AN40: 38.8 | AO40: 38.6 | AP40: 38.63 | AQ40: 38.562 | AR40: 38.834 | AS40: 39.078 | AT40: 38.63 | AU40: 39.275 | AV40: 39.353 | BG40: 12 | BH40: 31 | BI40: 33 | BJ40: 34 | BK40: 34.8 | BL40: 35.5 | BM40: =AD40 -> 36.7 | BN40: =AH40 -> 37.841 | BO40: =AL40 -> 38.4 | BP40: =AP40 -> 38.63 | BQ40: =AVERAGE(AQ40:AT40) -> 38.776 | BR40: =BQ40*1.05 -> 40.7148 | BS40: =BR40*1.05 -> 42.75054 | BT40: =BS40*1.05 -> 44.888067 | BU40: =BT40*1.05 -> 47.13247 | BV40: =BU40*1.05 -> 49.489094 | BW40: =BV40*1.05 -> 51.963549 | BX40: =BW40*1.05 -> 54.561726 | BY40: =BX40*1.05 -> 57.289812 | ... CA40: =BZ40*1.05 -> 63.162018
B41: EPS | C41: =C39/C40 -> 0.1 | D41: =D39/D40 -> -0.11 | E41: =E39/E40 -> 0.04 | F41: =F39/F40 -> 0.0625 | G41: =G39/G40 -> 0.083333333 | H41: =H39/H40 -> 0.1 | I41: =I39/I40 -> 0.39354839 | J41: =J39/J40 -> -0.08 | ... AV41: =AV39/AV40 -> 0.88458313 | BG41: =BG39/BG40 -> 0.085 | BH41: =BH39/BH40 -> 0.49354839 | BI41: =BI39/BI40 -> 0.13939394 | BJ41: =BJ39/BJ40 -> 0.19176471 | BK41: =BK39/BK40 -> 1.3924138 | BL41: =BL39/BL40 -> -0.43949296 | BM41: =BM39/BM40 -> 0.1439782 | BN41: =BN39/BN40 -> -0.052905579 | ... BP41: =BP39/BP40 -> 0.36215377 | BQ41: =SUM(AQ41:AT41) -> 4.5817424 | BR41: =BR39/BR40 -> 5.0386806 | BS41: =BS39/BS40 -> 7.1144683 | BT41: =BT39/BT40 -> 9.1034724 | BU41: =BU39/BU40 -> 11.298753 | BV41: =BV39/BV40 -> 13.511299 | BW41: =BW39/BW40 -> 15.858724 | BX41: =BX39/BX40 -> 18.96521 | BY41: =BY39/BY40 -> 22.333808 | ... CA41: =CA39/CA40 -> 30.52269
B43: Gross Profit Margin | C43: =C28/C26 -> 0.68717949 | D43: =D28/D26 -> 0.64775414 | E43: =E28/E26 -> 0.66468254 | F43: =F28/F26 -> 0.66911765 | G43: =G28/G26 -> 0.68911917 | H43: =H28/H26 -> 0.6374808 | I43: =I28/I26 -> 0.63839286 | J43: =J28/J26 -> 0.6374829 | ... AR43: =AR28/AR26 -> 0.65991074 | AS43: 0.67 | AT43: =AT28/AT26 -> 0.68017178 | AU43: 0.678 | AV43: 0.685 | AW43: 0.692 | AX43: 0.7 | BG43: =BG28/BG26 -> 0.66684578 | BH43: =BH28/BH26 -> 0.6490695 | BI43: =BI28/BI26 -> 0.65068904 | BJ43: =BJ28/BJ26 -> 0.65745111 | BK43: =BK28/BK26 -> 0.67950304 | BL43: =BL28/BL26 -> 0.60343997 | BM43: =BM28/BM26 -> 0.63588598 | BN43: =BN28/BN26 -> 0.63178627 | ... BQ43: =BQ28/BQ26 -> 0.67141163 | BR43: 0.675 | BS43: 0.692 | BT43: 0.703 | BU43: 0.71 | BV43: 0.715 | BW43: 0.72 | BX43: 0.725 | BY43: 0.73 | BZ43: 0.735 | CA43: 0.74
B44: R&D as % of Revenues | C44: =C29/C26 -> 0.082051282 | D44: =D29/D26 -> 0.11347518 | E44: =E29/E26 -> 0.091269841 | F44: =F29/F26 -> 0.10110294 | G44: =G29/G26 -> 0.086355786 | H44: =H29/H26 -> 0.096774194 | I44: =I29/I26 -> 0.09672619 | J44: =J29/J26 -> 0.083447332 | ... AR44: =AR29/AR26 -> 0.068397873 | AS44: 0.068 | AT44: =AT29/AT26 -> 0.056551241 | AU44: 0.073 | AV44: 0.075 | AW44: 0.075 | AX44: 0.075 | BG44: =BG29/BG26 -> 0.097259538 | BH44: =BH29/BH26 -> 0.090770984 | BI44: =BI29/BI26 -> 0.094667466 | BJ44: =BJ29/BJ26 -> 0.15059564 | BK44: =BK29/BK26 -> 0.094487973 | BL44: =BL29/BL26 -> 0.16068357 | BM44: =BM29/BM26 -> 0.13985206 | BN44: =BN29/BN26 -> 0.093736167 | ... BQ44: =BQ29/BQ26 -> 0.063951156 | BR44: 0.073 | BS44: 0.075 | BT44: 0.08 | BU44: 0.085 | BV44: 0.09 | BW44: 0.095 | BX44: 0.0925 | BY44: 0.09 | BZ44: 0.09 | CA44: 0.09
B45: SG&A as % of Revenues | C45: =C30/C26 -> 0.5 | D45: =D30/D26 -> 0.62411348 | E45: =E30/E26 -> 0.53174603 | F45: =F30/F26 -> 0.53676471 | G45: =G30/G26 -> 0.5716753 | H45: =H30/H26 -> 0.55145929 | I45: =I30/I26 -> 0.5610119 | J45: =J30/J26 -> 0.56908345 | ... AR45: =AR30/AR26 -> 0.47123772 | AS45: 0.47 | AT45: =AT30/AT26 -> 0.46992229 | AU45: 0.466 | AV45: 0.464 | AW45: 0.462 | AX45: 0.46 | BG45: =BG30/BG26 -> 0.54755508 | BH45: =BH30/BH26 -> 0.56323585 | BI45: =BI30/BI26 -> 0.5524266 | BJ45: =BJ30/BJ26 -> 0.5088784 | BK45: =BK30/BK26 -> 0.49823074 | BL45: =BL30/BL26 -> 0.51224456 | BM45: =BM30/BM26 -> 0.5060675 | BN45: =BN30/BN26 -> 0.5308706 | ... BQ45: =BQ30/BQ26 -> 0.47263556 | BR45: 0.465 | BS45: 0.4525 | BT45: 0.446 | BU45: 0.439 | BV45: 0.435 | BW45: 0.4325 | BX45: 0.428 | BY45: 0.425 | BZ45: 0.42 | CA45: 0.41
B46: Operating Profit Margin | C46: =C33/C26 -> 0.1025641 | D46: =D33/D26 -> -0.089834515 | E46: =E33/E26 -> 0.043650794 | F46: =F33/F26 -> 0.033088235 | G46: =G33/G26 -> 0.031088083 | H46: =H33/H26 -> -0.010752688 | I46: =I33/I26 -> -0.020833333 | J46: =J33/J26 -> -0.016415869 | ... AX46: =AX33/AX26 -> 0.165 | BG46: =BG33/BG26 -> 0.022568512 | BH46: =BH33/BH26 -> -0.0056969237 | BI46: =BI33/BI26 -> 0.0038945476 | BJ46: =BJ33/BJ26 -> -0.0017981569 | BK46: =BK33/BK26 -> 0.086784325 | BL46: =BL33/BL26 -> -0.069488162 | BM46: =BM33/BM26 -> -0.010033575 | BN46: =BN33/BN26 -> 0.0071795102 | ... CA46: =CA33/CA26 -> 0.24
B47: Effective Tax Rate | C47: =C36/C35 -> 0.39534884 | D47: =D36/D35 -> 0.35714286 | E47: =E36/E35 -> 0.57142857 | F47: =F36/F35 -> 0.10526316 | G47: =G36/G35 -> -0.095238095 | H47: =H36/H35 -> 8.5 | I47: =I36/I35 -> 11.818182 | J47: =J36/J35 -> -0.5625 | ... AR47: =AR36/AR35 -> 0.00088280733 | AS47: 0.2 | AT47: =AT36/AT35 -> 0.25598755 | AU47: 0.23 | AV47: 0.23 | AW47: 0.23 | AX47: 0.23 | BG47: =BG36/BG35 -> 0.3902439 | BH47: =BH36/BH35 -> 15.7 | BI47: =BI36/BI35 -> -1.3461538 | BJ47: =BJ36/BJ35 -> -2.5294118 | BK47: =BK36/BK35 -> 0.062453873 | BL47: =BL36/BL35 -> 0.49477821 | BM47: =BM36/BM35 -> 1.249762 | BN47: =BN36/BN35 -> 1.5143885 | ... BQ47: =BQ36/BQ35 -> 0.13376234 | BR47: 0.2 | BS47: 0.22 | BT47: 0.23 | BU47: 0.23 | BV47: 0.23 | BW47: 0.23 | BX47: 0.23 | BY47: 0.23 | BZ47: 0.23 | CA47: 0.23
...

Sheet Base Case (55%)
S1: Q1 2019 | W1: Q1 2020 | AA1: Q1 2021 | AE1: Q1 2022 | AI1: Q1 2023 | AM1: Q1 2024 | AQ1: Q1 2025 | AU1: Q1 2026
B2: Quarterly | C2: Apr | D2: July | E2: Oct | F2: Jan | G2: Apr | H2: July | I2: Oct | J2: Jan | K2: Apr | L2: July | M2: Oct | N2: Jan | O2: Apr | P2: July | Q2: Oct | R2: Jan | S2: Apr | T2: July | U2: Oct | V2: Jan | W2: Apr | X2: July | Y2: Oct | Z2: Jan | AA2: Apr | AB2: July | AC2: Oct | AD2: Jan | AE2: Apr | AF2: July | AG2: Oct | AH2: Jan | AI2: Apr | AJ2: July | AK2: Oct | AL2: Jan | AM2: Apr | AN2: July | AO2: Oct | AP2: Jan | AQ2: Apr | AR2: July | AS2: Oct | AT2: Jan | AU2: Apr | AV2: July | AW2: Oct | AX2: Jan | AY2: Apr | AZ2: July | BA2: Oct | BB2: Jan
B3: Revenues | C3: Q1 2015 | D3: Q2 2015 | E3: Q3 2015 | F3: Q4 2015 | G3: Q1 2016 | H3: Q2 2016 | I3: Q3 2016 | J3: Q4 2016 | K3: Q1 2017 | L3: Q2 2017 | M3: Q3 2017 | N3: Q4 2017 | O3: Q1 2018 | P3: Q2 2018 | Q3: Q3 2018 | R3: Q4 2018 | S3: Q1 2019 | T3: Q2 2019 | U3: Q3 2019 | V3: Q4 2019 | W3: Q1 2020 | X3: Q2 2020 | Y3: Q3 2020 | Z3: Q4 2020 | AA3: Q1 2021 | AB3: Q2 2021 | AC3: Q3 2021 | AD3: Q4 2021 | AE3: Q1 2022 | AF3: Q2 2022 | AG3: Q3 2022 | AH3: Q4 2022 | AI3: Q1 2023 | AJ3: Q2 2023 | AK3: Q3 2023 | AL3: Q4 2023 | AM3: Q1 2024 | AN3: Q2 2024 | AO3: Q3 2024 | AP3: Q4 2024 | AQ3: Q1 2025 | AR3: Q2 2025 | AS3: Q3 2025 | AT3: Q4 2025 | AU3: Q1 2026 | AV3: Q2 2026 | AW3: Q3 2026 | AX3: Q4 2026 | AY3: Q1 2027 | AZ3: Q2 2027 | BA3: Q3 2027 | BB3: Q4 2027 | BG3: 2015 | BH3: 2016 | BI3: 2017 | BJ3: 2018 | BK3: 2019 | BL3: 2020 | BM3: 2021 | BN3: 2022 | BO3: =BN3+1 -> 2023 | BP3: =BO3+1 -> 2024 | BQ3: =BP3+1 -> 2025 | BR3: =BQ3+1 -> 2026 | BS3: =BR3+1 -> 2027 | BT3: =BS3+1 -> 2028 | BU3: =BT3+1 -> 2029 | BV3: =BU3+1 -> 2030 | ... DO3: =DN3+1 -> 2075
B4: Thrombectomy (Neuro + Peripheral) | AI4: 145 | AJ4: 162 | AK4: 179 | AL4: =677-SUM(AI4:AK4) -> 191 | AM4: 188 | AN4: 203 | AO4: 204 | AP4: =815-SUM(AM4:AO4) -> 220 | AQ4: 226.544 | AR4: 230.256 | AS4: 236.4 | AT4: =947.918-SUM(AQ4:AS4) -> 254.718 | AU4: 253.917 | AV4: 258.981 | AW4: =AS4*(1+AW8) -> 293.136 | AX4: =AT4*(1+AX8) -> 315.85032 | BO4: =SUM(AI4:AL4) -> 677 | BP4: =SUM(AM4:AP4) -> 815 | BQ4: =SUM(AQ4:AT4) -> 947.918 | BR4: =BQ4*(1+BR8) -> 1118.5432 | BS4: =BR4*(1+BS8) -> 1314.2883 | BT4: =BS4*(1+BT8) -> 1537.7173 | BU4: =BT4*(1+BU8) -> 1791.4407 | BV4: =BU4*(1+BV8) -> 2078.0712 | BW4: =BV4*(1+BW8) -> 2389.7819 | BX4: =BW4*(1+BX8) -> 2736.3002 | BY4: =BX4*(1+BY8) -> 3119.3823 | ... CA4: =BZ4*(1+CA8) -> 4000.7637
B5: Embolization & Access (Peripheral Embolization + Neuro Embolization + Access + Neurosurgical Tools) | AI5: 96 | AJ5: 99 | AK5: 92 | AL5: =381-SUM(AI5:AK5) -> 94 | AM5: 91 | AN5: 96 | AO5: 96.89 | AP5: =379-SUM(AM5:AO5) -> 95.11 | AQ5: 97.596 | AR5: 109.199 | AS5: 118.3 | AT5: =455.747-SUM(AQ5:AS5) -> 130.652 | AU5: 120.841 | AV5: 131.065 | AW5: =AS5*(1+AW9) -> 129.83425 | AX5: =AT5*(1+AX9) -> 143.06394 | BO5: =SUM(AI5:AL5) -> 381 | BP5: =SUM(AM5:AP5) -> 379 | BQ5: =SUM(AQ5:AT5) -> 455.747 | BR5: =BQ5*(1+BR9) -> 524.10905 | BS5: =BR5*(1+BS9) -> 597.48432 | BT5: =BS5*(1+BT9) -> 669.18244 | BU5: =BT5*(1+BU9) -> 736.10068 | BV5: =BU5*(1+BV9) -> 794.98873 | BW5: =BV5*(1+BW9) -> 842.68806 | BX5: =BW5*(1+BX9) -> 884.82246 | BY5: =BX5*(1+BY9) -> 920.21536 | ... CA5: =BZ5*(1+CA9) -> 980.99558
B6: Ttl Revenues | AI6: =SUM(AI4:AI5) -> 241 | AJ6: =SUM(AJ4:AJ5) -> 261 | AK6: =SUM(AK4:AK5) -> 271 | AL6: =SUM(AL4:AL5) -> 285 | AM6: =SUM(AM4:AM5) -> 279 | AN6: =SUM(AN4:AN5) -> 299 | AO6: =SUM(AO4:AO5) -> 300.89 | AP6: =SUM(AP4:AP5) -> 315.11 | ... AT6: =SUM(AT4:AT5) -> 385.37 | AU6: =AU4+AU5 -> 374.758 | AV6: =AV4+AV5 -> 390.046 | AW6: =AW4+AW5 -> 422.97025 | AX6: =AX4+AX5 -> 458.91426 | BO6: =BO4+BO5 -> 1058 | BP6: =BP4+BP5 -> 1194 | BQ6: =SUM(AQ6:AT6) -> 1403.665 | BR6: =BR4+BR5 -> 1642.6523 | BS6: =BS4+BS5 -> 1911.7726 | BT6: =BT4+BT5 -> 2206.8998 | BU6: =BU4+BU5 -> 2527.5414 | BV6: =BV4+BV5 -> 2873.0599 | BW6: =BW4+BW5 -> 3232.4699 | BX6: =BX4+BX5 -> 3621.1227 | BY6: =BY4+BY5 -> 4039.5976 | ... CA6: =CA4+CA5 -> 4981.7593
B8: Thrombectomy Revenue Growth Y/y | AM8: =AM4/AI4-1 -> 0.29655172 | AN8: =AN4/AJ4-1 -> 0.25308642 | AO8: =AO4/AK4-1 -> 0.1396648 | AP8: =AP4/AL4-1 -> 0.15183246 | AQ8: =AQ4/AM4-1 -> 0.20502128 | AR8: =AR4/AN4-1 -> 0.13426601 | AS8: =AS4/AO4-1 -> 0.15882353 | AT8: =AT4/AP4-1 -> 0.15780909 | AU8: 0.17 | AV8: 0.22 | AW8: 0.24 | AX8: 0.24 | BP8: =BP4/BO4-1 -> 0.20384047 | BQ8: =BQ4/BP4-1 -> 0.16308957 | BR8: 0.18 | BS8: 0.175 | BT8: 0.17 | BU8: 0.165 | BV8: 0.16 | BW8: 0.15 | BX8: 0.145 | BY8: 0.14 | BZ8: 0.135 | CA8: 0.13
B9: E & A Revenue Growth Y/y | AM9: =AM5/AI5-1 -> -0.052083333 | AN9: =AN5/AJ5-1 -> -0.03030303 | AO9: =AO5/AK5-1 -> 0.053152174 | AP9: =AP5/AL5-1 -> 0.011808511 | AQ9: =AQ5/AM5-1 -> 0.072483516 | AR9: =AR5/AN5-1 -> 0.13748958 | AS9: =AS5/AO5-1 -> 0.22097224 | AT9: =AT5/AP5-1 -> 0.37369362 | AU9: 0.16 | AV9: 0.105 | AW9: 0.0975 | AX9: 0.095 | BP9: =BP5/BO5-1 -> -0.0052493438 | BQ9: =BQ5/BP5-1 -> 0.20249868 | BR9: 0.15 | BS9: 0.14 | BT9: 0.12 | BU9: 0.1 | BV9: 0.08 | BW9: 0.06 | BX9: 0.05 | BY9: 0.04 | BZ9: 0.035 | CA9: 0.03
B10: Total Revenue Growth Y/y | AM10: =AM6/AI6-1 -> 0.15767635 | AN10: =AN6/AJ6-1 -> 0.14559387 | AO10: =AO6/AK6-1 -> 0.1102952 | AP10: =AP6/AL6-1 -> 0.10564912 | AQ10: =AQ6/AM6-1 -> 0.16179211 | AR10: =AR6/AN6-1 -> 0.135301 | AS10: =AS6/AO6-1 -> 0.17883612 | AT10: =AT6/AP6-1 -> 0.22296976 | ... AX10: =AX6/AT6-1 -> 0.19084065 | BP10: =BP6/BO6-1 -> 0.12854442 | BQ10: =BQ6/BP6-1 -> 0.17559883 | BR10: =BR6/BQ6-1 -> 0.17025949 | BS10: =BS6/BR6-1 -> 0.16383281 | BT10: =BT6/BS6-1 -> 0.15437355 | BU10: =BU6/BT6-1 -> 0.14529051 | BV10: =BV6/BU6-1 -> 0.13670145 | BW10: =BW6/BV6-1 -> 0.12509659 | ... CA10: =CA6/BZ6-1 -> 0.1088017
B12: Thrombectomy % of Ttl Revenues | AI12: =AI4/AI6 -> 0.60165975 | AJ12: =AJ4/AJ6 -> 0.62068966 | AK12: =AK4/AK6 -> 0.66051661 | AL12: =AL4/AL6 -> 0.67017544 | AM12: =AM4/AM6 -> 0.67383513 | AN12: =AN4/AN6 -> 0.67892977 | AO12: =AO4/AO6 -> 0.67798863 | AP12: =AP4/AP6 -> 0.69816889 | ... AX12: =AX4/AX6 -> 0.68825562 | BO12: =AVERAGE(AI12:AL12) -> 0.63826036 | BP12: =AVERAGE(AM12:AP12) -> 0.6822306 | BQ12: =AVERAGE(AN12:AQ12) -> 0.68849879 | BR12: =BR4/BR6 -> 0.68093732 | BS12: =BS4/BS6 -> 0.68747104 | BT12: =BT4/BT6 -> 0.69677715 | BU12: =BU4/BU6 -> 0.7087681 | BV12: =BV4/BV6 -> 0.72329546 | BW12: =BW4/BW6 -> 0.73930521 | BX12: =BX4/BX6 -> 0.75564969 | BY12: =BY4/BY6 -> 0.77220123 | ... CA12: =CA4/CA6 -> 0.8030825
B13: E & A % of Ttl Revenues | AI13: =AI5/AI6 -> 0.39834025 | AJ13: =AJ5/AJ6 -> 0.37931034 | AK13: =AK5/AK6 -> 0.33948339 | AL13: =AL5/AL6 -> 0.32982456 | AM13: =AM5/AM6 -> 0.32616487 | AN13: =AN5/AN6 -> 0.32107023 | AO13: =AO5/AO6 -> 0.32201137 | AP13: =AP5/AP6 -> 0.30183111 | ... AX13: =AX5/AX6 -> 0.31174438 | BO13: =AVERAGE(AI13:AL13) -> 0.36173964 | BP13: =AVERAGE(AM13:AP13) -> 0.3177694 | BQ13: =AVERAGE(AN13:AQ13) -> 0.31150121 | BR13: =BR5/BR6 -> 0.31906268 | BS13: =BS5/BS6 -> 0.31252896 | BT13: =BT5/BT6 -> 0.30322285 | BU13: =BU5/BU6 -> 0.2912319 | BV13: =BV5/BV6 -> 0.27670454 | BW13: =BW5/BW6 -> 0.26069479 | BX13: =BX5/BX6 -> 0.24435031 | BY13: =BY5/BY6 -> 0.22779877 | ... CA13: =CA5/CA6 -> 0.1969175
B15: U.S. Revenues | S15: 82.511 | T15: 86.374 | U15: 90.272 | V15: =355.22-SUM(S15:U15) -> 96.063 | W15: 96 | X15: 78 | Y15: 110 | Z15: =400-SUM(W15:Y15) -> 116 | AA15: 120 | AB15: 128 | AC15: 135 | AD15: =528-SUM(AA15:AC15) -> 145 | AE15: 144 | AF15: 141 | AG15: 149 | AH15: =592-SUM(AE15:AG15) -> 158 | AI15: 172 | AJ15: 186 | AK15: 195 | AL15: =757-SUM(AI15:AK15) -> 204 | AM15: 210 | AN15: 218 | AO15: 226 | AP15: =902-SUM(AM15:AO15) -> 248 | AQ15: 256.86 | AR15: 260.818 | AS15: 275.029 | AT15: =1091.761-SUM(AQ15:AS15) -> 299.054 | AU15: 296.387 | AV15: 305.445 | BK15: =SUM(S15:V15) -> 355.22 | BL15: =SUM(W15:Z15) -> 400 | BM15: =SUM(AA15:AC15) -> 383 | BN15: =SUM(AE15:AG15) -> 434 | BO15: =SUM(AI15:AL15) -> 757 | BP15: =SUM(AM15:AP15) -> 902 | BQ15: =SUM(AQ15:AT15) -> 1091.761
B16: International Revenues | S16: =9.522+36.406 -> 45.928 | T16: =12.231+35.596 -> 47.827 | U16: =11.214+38.016 -> 49.23 | V16: =42.52+149.663-SUM(S16:U16) -> 49.198 | W16: 41 | X16: 27 | Y16: 41 | Z16: =160-SUM(W16:Y16) -> 51 | AA16: 49 | AB16: 56 | AC16: 55 | AD16: =220-SUM(AA16:AC16) -> 60 | AE16: 60 | AF16: 67 | AG16: 65 | AH16: =255-SUM(AE16:AG16) -> 63 | AI16: 69 | AJ16: 75 | AK16: 76 | AL16: =301-SUM(AI16:AK16) -> 81 | AM16: 69 | AN16: 81 | AO16: 77 | AP16: =292-SUM(AM16:AO16) -> 65 | AQ16: 67.28 | AR16: 78.637 | AS16: 79.656 | AT16: =311.904-SUM(AQ16:AS16) -> 86.331 | AU16: 78.371 | AV16: 84.601 | BK16: =SUM(S16:V16) -> 192.183 | BL16: =SUM(W16:Z16) -> 160 | BM16: =SUM(AA16:AC16) -> 160 | BN16: =SUM(AE16:AG16) -> 192 | BO16: =SUM(AI16:AL16) -> 301 | BP16: =SUM(AM16:AP16) -> 292 | BQ16: =SUM(AQ16:AT16) -> 311.904
B17: Ttl Revenues | S17: =SUM(S15:S16) -> 128.439 | T17: =SUM(T15:T16) -> 134.201 | U17: =SUM(U15:U16) -> 139.502 | V17: =SUM(V15:V16) -> 145.261 | W17: =SUM(W15:W16) -> 137 | X17: =SUM(X15:X16) -> 105 | Y17: =SUM(Y15:Y16) -> 151 | Z17: =SUM(Z15:Z16) -> 167 | ... AV17: =SUM(AV15:AV16) -> 390.046 | BK17: =SUM(S17:V17) -> 547.403 | BL17: =SUM(W17:Z17) -> 560 | BM17: =SUM(AA17:AD17) -> 748 | BN17: =SUM(AE17:AH17) -> 847 | BO17: =SUM(AI17:AL17) -> 1058 | BP17: =SUM(AM17:AP17) -> 1194 | BQ17: =SUM(AQ17:AT17) -> 1403.665
B19: U.S. Revenue Growth Y/y | W19: =W15/S15-1 -> 0.16348123 | X19: =X15/T15-1 -> -0.096950471 | Y19: =Y15/U15-1 -> 0.21853952 | Z19: =Z15/V15-1 -> 0.20754088 | AA19: =AA15/W15-1 -> 0.25 | AB19: =AB15/X15-1 -> 0.64102564 | AC19: =AC15/Y15-1 -> 0.22727273 | AD19: =AD15/Z15-1 -> 0.25 | ... AV19: =AV15/AR15-1 -> 0.17110399 | BL19: =BL15/BK15-1 -> 0.12606272 | BM19: =BM15/BL15-1 -> -0.0425 | BN19: =BN15/BM15-1 -> 0.13315927 | BO19: =BO15/BN15-1 -> 0.74423963 | BP19: =BP15/BO15-1 -> 0.19154557 | BQ19: =BQ15/BP15-1 -> 0.21037805
B20: International Revenue Growth Y/y | W20: =W16/S16-1 -> -0.10729838 | X20: =X16/T16-1 -> -0.43546532 | Y20: =Y16/U16-1 -> -0.16717449 | Z20: =Z16/V16-1 -> 0.036627505 | AA20: =AA16/W16-1 -> 0.19512195 | AB20: =AB16/X16-1 -> 1.0740741 | AC20: =AC16/Y16-1 -> 0.34146341 | AD20: =AD16/Z16-1 -> 0.17647059 | ... AV20: =AV16/AR16-1 -> 0.075842161 | BL20: =BL16/BK16-1 -> -0.16746018 | BM20: =BM16/BL16-1 -> 0 | BN20: =BN16/BM16-1 -> 0.2 | BO20: =BO16/BN16-1 -> 0.56770833 | BP20: =BP16/BO16-1 -> -0.029900332 | BQ20: =BQ16/BP16-1 -> 0.068164384
B21: Total Revenue Growth Y/y | W21: =W17/S17-1 -> 0.066654209 | X21: =X17/T17-1 -> -0.21759152 | Y21: =Y17/U17-1 -> 0.082421757 | Z21: =Z17/V17-1 -> 0.14965476 | AA21: =AA17/W17-1 -> 0.23357664 | AB21: =AB17/X17-1 -> 0.75238095 | AC21: =AC17/Y17-1 -> 0.25827815 | AD21: =AD17/Z17-1 -> 0.22754491 | ... AV21: =AV17/AR17-1 -> 0.14903595 | BL21: =BL17/BK17-1 -> 0.023012296 | BM21: =BM17/BL17-1 -> 0.33571429 | BN21: =BN17/BM17-1 -> 0.13235294 | BO21: =BO17/BN17-1 -> 0.24911452 | BP21: =BP17/BO17-1 -> 0.12854442 | BQ21: =BQ17/BP17-1 -> 0.17559883
B23: U.S. % of Ttl Revenues | S23: =S15/S17 -> 0.64241391 | T23: =T15/T17 -> 0.64361666 | U23: =U15/U17 -> 0.64710183 | V23: =V15/V17 -> 0.66131308 | W23: =W15/W17 -> 0.70072993 | X23: =X15/X17 -> 0.74285714 | Y23: =Y15/Y17 -> 0.72847682 | Z23: =Z15/Z17 -> 0.69461078 | ... AV23: =AV15/AV17 -> 0.78309994 | BK23: =BK15/BK17 -> 0.64891862 | BL23: =BL15/BL17 -> 0.71428571 | BM23: =BM15/BM17 -> 0.51203209 | BN23: =BN15/BN17 -> 0.51239669 | BO23: =BO15/BO17 -> 0.71550095 | BP23: =BP15/BP17 -> 0.75544389 | BQ23: =BQ15/BQ17 -> 0.77779313
B24: International % of Ttl Revenues | S24: =S16/S17 -> 0.35758609 | T24: =T16/T17 -> 0.35638334 | U24: =U16/U17 -> 0.35289817 | V24: =V16/V17 -> 0.33868692 | W24: =W16/W17 -> 0.29927007 | X24: =X16/X17 -> 0.25714286 | Y24: =Y16/Y17 -> 0.27152318 | Z24: =Z16/Z17 -> 0.30538922 | ... AV24: =AV16/AV17 -> 0.21690006 | BK24: =BK16/BK17 -> 0.35108138 | BL24: =BL16/BL17 -> 0.28571429 | BM24: =BM16/BM17 -> 0.21390374 | BN24: =BN16/BN17 -> 0.22668241 | BO24: =BO16/BO17 -> 0.28449905 | BP24: =BP16/BP17 -> 0.24455611 | BQ24: =BQ16/BQ17 -> 0.22220687
B26: Revenues | C26: 39 | D26: 42.3 | E26: 50.4 | F26: 54.4 | G26: 57.9 | H26: 65.1 | I26: 67.2 | J26: 73.1 | K26: 73.2 | L26: 80.6 | M26: 83.9 | N26: 96.1 | O26: 102.7 | P26: 109.6 | Q26: 111.8 | R26: 120.8 | S26: =S17 -> 128.439 | T26: =T17 -> 134.201 | U26: =U17 -> 139.502 | V26: =V17 -> 145.261 | W26: 137.3 | X26: 105.1 | Y26: 151.1 | Z26: =560.412-SUM(W26:Y26) -> 166.912 | AA26: 169.2 | AB26: 184.3 | AC26: 190.1 | AD26: =747.59-SUM(AA26:AC26) -> 203.99 | AE26: 203.9 | AF26: 208.3 | AG26: 213.7 | AH26: =847.133-SUM(AE26:AG26) -> 221.233 | AI26: 241.4 | AJ26: 261.5 | AK26: 270.9 | AL26: =1058.52-SUM(AI26:AK26) -> 284.72 | AM26: 278.7 | AN26: 299.4 | AO26: 301 | AP26: =1194.6-SUM(AM26:AO26) -> 315.5 | AQ26: =AQ17 -> 324.14 | AR26: =AR17 -> 339.455 | AS26: =AS17 -> 354.685 | AT26: =1403.665-SUM(AQ26:AS26) -> 385.385 | AU26: =AU17 -> 374.758 | AV26: =AV17 -> 390.046 | AW26: =AW6 -> 422.97025 | AX26: =AX6 -> 458.91426 | BG26: =SUM(C26:F26) -> 186.1 | BH26: =SUM(G26:J26) -> 263.3 | BI26: =SUM(K26:N26) -> 333.8 | BJ26: =SUM(O26:R26) -> 444.9 | BK26: =SUM(S26:V26) -> 547.403 | BL26: =SUM(W26:Z26) -> 560.412 | BM26: =SUM(AA26:AD26) -> 747.59 | BN26: =SUM(AE26:AH26) -> 847.133 | BO26: =SUM(AI26:AL26) -> 1058.52 | BP26: =SUM(AM26:AP26) -> 1194.6 | BQ26: =SUM(AQ26:AT26) -> 1403.665 | BR26: =BR6 -> 1642.6523 | BS26: =BS6 -> 1911.7726 | BT26: =BT6 -> 2206.8998 | BU26: =BU6 -> 2527.5414 | BV26: =BV6 -> 2873.0599 | BW26: =BW6 -> 3232.4699 | BX26: =BX6 -> 3621.1227 | BY26: =BY6 -> 4039.5976 | ... CA26: =CA6 -> 4981.7593
B27: COGS | C27: 12.2 | D27: 14.9 | E27: 16.9 | F27: 18 | G27: 18 | H27: 23.6 | I27: 24.3 | J27: 26.5 | K27: 25.5 | L27: 29.7 | M27: 29.1 | N27: 32.3 | O27: 36.1 | P27: 37.4 | Q27: 36.8 | R27: 42.1 | S27: 44.529 | T27: 40.273 | U27: 43.504 | V27: =175.441-SUM(S27:U27) -> 47.135 | W27: 49.3 | X27: 40.2 | Y27: 60.153 | Z27: =222.237-SUM(W27:Y27) -> 72.584 | AA27: 57.867 | AB27: 65.6 | AC27: 70.2 | AD27: =272.208-SUM(AA27:AC27) -> 78.541 | AE27: 76.5 | AF27: 74.3 | AG27: 78.4 | AH27: =311.926-SUM(AE27:AG27) -> 82.726 | AI27: 90.3 | AJ27: 94.6 | AK27: 93.2 | AL27: =375.9-SUM(AI27:AK27) -> 97.8 | AM27: 97.5 | AN27: 136.6 | AO27: 100.7 | AP27: =439.6-SUM(AM27:AO27) -> 104.8 | AQ27: 108.257 | AR27: 115.445 | AS27: 114.269 | AT27: =461.228-SUM(AQ27:AS27) -> 123.257 | AU27: 121.347 | AV27: 125.102 | AW27: =AW26*(1-AW43) -> 130.27484 | AX27: =AX26*(1-AX43) -> 139.96885 | BG27: =SUM(C27:F27) -> 62 | BH27: =SUM(G27:J27) -> 92.4 | BI27: =SUM(K27:N27) -> 116.6 | BJ27: =SUM(O27:R27) -> 152.4 | BK27: =SUM(S27:V27) -> 175.441 | BL27: =SUM(W27:Z27) -> 222.237 | BM27: =SUM(AA27:AD27) -> 272.208 | BN27: =SUM(AE27:AH27) -> 311.926 | BO27: =SUM(AI27:AL27) -> 375.9 | BP27: =SUM(AM27:AP27) -> 439.6 | BQ27: =SUM(AQ27:AT27) -> 461.228 | BR27: =BR26*(1-BR43) -> 542.07526 | BS27: =BS26*(1-BS43) -> 588.82597 | BT27: =BT26*(1-BT43) -> 655.44923 | BU27: =BU26*(1-BU43) -> 732.98699 | BV27: =BV26*(1-BV43) -> 818.82208 | BW27: =BW26*(1-BW43) -> 905.09158 | BX27: =BX26*(1-BX43) -> 995.80874 | BY27: =BY26*(1-BY43) -> 1090.6914 | ... CA27: =CA26*(1-CA43) -> 1295.2574
B28: GP | C28: =C26-C27 -> 26.8 | D28: =D26-D27 -> 27.4 | E28: =E26-E27 -> 33.5 | F28: =F26-F27 -> 36.4 | G28: =G26-G27 -> 39.9 | H28: =H26-H27 -> 41.5 | I28: =I26-I27 -> 42.9 | J28: =J26-J27 -> 46.6 | ... AX28: =AX26-AX27 -> 318.94541 | BG28: =SUM(C28:F28) -> 124.1 | BH28: =SUM(G28:J28) -> 170.9 | BI28: =SUM(K28:N28) -> 217.2 | BJ28: =SUM(O28:R28) -> 292.5 | BK28: =BK26-BK27 -> 371.962 | BL28: =BL26-BL27 -> 338.175 | BM28: =BM26-BM27 -> 475.382 | BN28: =BN26-BN27 -> 535.207 | BO28: =BO26-BO27 -> 682.62 | BP28: =BP26-BP27 -> 755 | BQ28: =SUM(AQ28:AT28) -> 942.437 | BR28: =BR26-BR27 -> 1100.577 | BS28: =BS26-BS27 -> 1322.9467 | BT28: =BT26-BT27 -> 1551.4505 | BU28: =BU26-BU27 -> 1794.5544 | BV28: =BV26-BV27 -> 2054.2378 | BW28: =BW26-BW27 -> 2327.3783 | BX28: =BX26-BX27 -> 2625.314 | BY28: =BY26-BY27 -> 2948.9063 | ... CA28: =CA26-CA27 -> 3686.5019
B29: R&D | C29: 3.2 | D29: 4.8 | E29: 4.6 | F29: 5.5 | G29: 5 | H29: 6.3 | I29: 6.5 | J29: 6.1 | K29: 7 | L29: 8.1 | M29: 8.1 | N29: 8.4 | O29: 8 | P29: 8.2 | Q29: 39.9 | R29: 10.9 | S29: 11.667 | T29: 13.462 | U29: 13.733 | V29: =51.723-SUM(S29:U29) -> 12.861 | W29: 12.946 | X29: 22.725 | Y29: 34.923 | Z29: =90.049-SUM(W29:Y29) -> 19.455 | AA29: 18.076 | AB29: 17.738 | AC29: 16.73 | AD29: =104.552-SUM(AA29:AC29) -> 52.008 | AE29: 20.56 | AF29: 19.559 | AG29: 21.32 | AH29: =79.407-SUM(AE29:AG29) -> 17.968 | AI29: 19.98 | AJ29: 21.5 | AK29: 21 | AL29: =84.4-SUM(AI29:AK29) -> 21.92 | AM29: 24.6 | AN29: 24.9 | AO29: 25.2 | AP29: =94.8-SUM(AM29:AO29) -> 20.1 | AQ29: 22.077 | AR29: 23.218 | AS29: 22.677 | AT29: =89.766-SUM(AQ29:AS29) -> 21.794 | AU29: 22.382 | AV29: 25.396 | AW29: =AW26*AW44 -> 31.722769 | AX29: =AX26*AX44 -> 34.418569 | BG29: =SUM(C29:F29) -> 18.1 | BH29: =SUM(G29:J29) -> 23.9 | BI29: =SUM(K29:N29) -> 31.6 | BJ29: =SUM(O29:R29) -> 67 | BK29: =SUM(S29:V29) -> 51.723 | BL29: =SUM(W29:Z29) -> 90.049 | BM29: =SUM(AA29:AD29) -> 104.552 | BN29: =SUM(AE29:AH29) -> 79.407 | BO29: =SUM(AI29:AL29) -> 84.4 | BP29: =SUM(AM29:AP29) -> 94.8 | BQ29: =SUM(AQ29:AT29) -> 89.766 | BR29: =BR26*BR44 -> 123.19892 | BS29: =BS26*BS44 -> 145.29472 | BT29: =BT26*BT44 -> 178.75888 | BU29: =BU26*BU44 -> 214.84102 | BV29: =BV26*BV44 -> 244.21009 | BW29: =BW26*BW44 -> 282.84112 | BX29: =BX26*BX44 -> 325.90104 | BY29: =BY26*BY44 -> 383.76177 | ... CA29: =CA26*CA44 -> 473.26713
