Workbook

Sheet Main
B2: PL
B3: Price | C3: 17.43 | D3: 7/5/2026
B4: SO | C4: 359.594 | D4: Q1'26
B5: MC | C5: =C3*C4 -> 6267.7234
B6: Cash | C6: =415.13+1.891+450.288 -> 867.309 | D6: Q1'26
B7: Debt | C7: 448.255 | D7: Q1'26
B8: EV | C8: =C5-C6+C7 -> 5848.6694
M9: Resources:
B10: Planet Labs PBC (PL) | M10: SEC filings | P10: https://www.sec.gov/edgar/browse/?CIK=1836833&owner=exclude
M11: Company Homepage | P11: https://www.planet.com/
B12: Founder(s): Will Marshall, Robbie Schingler, and Chris Boshuizen (three former NASA scientists) | F12: Registered Exchange: NYSE | N12: Company IR Page | Q12: https://investors.planet.com/overview/default.aspx
B13: Founded: 2010 | F13: Address: 645 Harrison Street, San Francisco, CA 94107 U.S. | N13: Planet Labs Constellations | Q13: https://www.planet.com/constellations/
B14: Headquarters: San Francisco, CA | F14: Investor Relations Contact: | N14: Comprehensive Dove 1 Space Missions | Q14: https://space.skyrocket.de/doc_sdat/dove-1.htm
B15: Current CEO: William Marshall | F15: Investors Relation Department | M15: Earnings Calls | P15: https://seekingalpha.com/symbol/PL/earnings/transcripts
B16: Employees: 1,000 | F16: Phone: | G16: (415) 829 - 3313 | I16: Email: | M16: Equity Analysis | P16: https://stockanalysis.com/stocks/pl/company/
B17: Industry: Aerospace & Defense | M17: MacroTrends | P17: https://www.macrotrends.net/stocks/charts/PL/planet-labs-pbc/revenue
B18: Sector: Industrials | M18: ROIC, WACC | P18: https://www.gurufocus.com/term/wacc/PL
B19: IPO: December 8th, 2021 (Through SPAC) -- $2.8B valuation | M19: Godel Terminal | P19: https://app.godelterminal.com/
B20: Fiscal Year: [February - January] | M20: SpaceNews | P20: https://spacenews.com/
A22: Company Overview:
B23: Planet is a vertically integrated Earth Observation (EO) enterprise and operates a large fleet of LEO imaging satellites. The Company sells satellite images, analytics, and related services through a cloud platform and APIs ... Their main value is giving customers frequent, updated views of Earth for monitoring change over time
C24: The Company is best viewed as a geospatial data platform, not just a satellite company … Market offerings are strongest where customers need frequent monitoring of large areas rather than one-off high-resolution snapshots … sells daily satellite imagery and analytics through a recurring subscription model
B25: The Company's core asset is the Dove/SuperDove constellation for daily, broad-earth coverage, with SkySat and Pelican for higher-resolution tasking and Tanager for hyperspectral monitoring
C26: The Earth Observation platform enables customers to access, analyze, and act on proprietary data catalogs by discovering image tasking capacity, relevant data layers, extracting useful information, and delivering insights through custom-built solutions or GIS workflows via APIs and browser-based applications
C27: In addition, the company’s satellite services arrangements include designing and manufacturing customer-owned satellites, mission systems engineering, launch procurement, ground station infrastructure, satellite operations, and maintenance, as well as dedicated image tasking capacity on company-owned or customer-owned satellites
B28: Main Satellite Assets:
C29: Dove / SuperDove: daily, medium-resolution global coverage
C30: SkySat: higher-resolution imagery for specific locations
C31: Pelican: next-gen very-high-resolution tasking satellites
C32: Tanager: hyperspectral satellites for more detailed environmental monitoring
B33: The Company reports revenue through a consolidated revenue reporting framework (no segmentation) but frequently destinguishes end customers between Government / National Defense and Enterprise Solutions … Main Customers include: Government, defense, agriculture, forestry, mapping, energy, finance, and insurance customers
C34: Google has maintained a close relationship with Planet Labs, acting as a major partner … similar in nature to PLTR / BKSY partnership … very interesting
B35: Planet Labs was founded in 2010 as a Public Benefit Corporation and is headquartered in San Francisco, California
A37: Business Segments and Geographical Info:
B38: [Begin researching fundamentals / core business … begin with SEC filings, but expand and use all public resources available]

Sheet Bull Case
B1: [Use for Graphing] | C1: Q1 2021 | G1: Q1 2022 | K1: Q1 2023 | O1: Q1 2024 | S1: Q1 2025 | W1: Q1 2026
B2: Quarterly
B3: Revenues | C3: Q1 2021 | D3: Q2 2021 | E3: Q3 2021 | F3: Q4 2021 | G3: Q1 2022 | H3: Q2 2022 | I3: Q3 2022 | J3: Q4 2022 | K3: Q1 2023 | L3: Q2 2023 | M3: Q3 2023 | N3: Q4 2023 | O3: Q1 2024 | P3: Q2 2024 | Q3: Q3 2024 | R3: Q4 2024 | S3: Q1 2025 | T3: Q2 2025 | U3: Q3 2025 | V3: Q4 2025 | W3: Q1 2026 | X3: Q2 2026 | Y3: Q3 2026 | Z3: Q4 2026 | AF3: 2020 | AG3: =AF3+1 -> 2021 | AH3: =AG3+1 -> 2022 | AI3: =AH3+1 -> 2023 | AJ3: =AI3+1 -> 2024 | AK3: =AJ3+1 -> 2025 | AL3: 2026 | AM3: =AL3+1 -> 2027 | AN3: =AM3+1 -> 2028 | AO3: =AN3+1 -> 2029 | AP3: =AO3+1 -> 2030 | AQ3: =AP3+1 -> 2031 | AR3: =AQ3+1 -> 2032 | AS3: =AR3+1 -> 2033 | AT3: =AS3+1 -> 2034 | ... CS3: =CR3+1 -> 2085
B4: Civil Government | O4: 18.049 | P4: 17.179 | Q4: 18.552 | R4: =71.887-SUM(O4:Q4) -> 18.107 | S4: 16.28 | T4: 16.426 | U4: 18.828 | V4: =71.91-SUM(S4:U4) -> 20.376 | W4: 16.169 | X4: 17.498 | AI4: =SUM(O4:R4) -> 71.887 | AJ4: =SUM(P4:S4) -> 70.118 | AK4: =SUM(S4:V4) -> 71.91 | AL4: =AK4*(1+AL9) -> 76.2246 | AM4: =AL4*(1+AM9) -> 81.560322 | AN4: =AM4*(1+AN9) -> 88.085148 | AO4: =AN4*(1+AO9) -> 94.251108 | AP4: =AO4*(1+AP9) -> 99.906175 | AQ4: =AP4*(1+AQ9) -> 104.90148 | AR4: =AQ4*(1+AR9) -> 109.09754 | AS4: =AR4*(1+AS9) -> 112.91596 | ... AU4: =AT4*(1+AU9) -> 119.21102
B5: Commercial | O5: 12.777 | P5: 14.232 | Q5: 14.173 | R5: =56.184-SUM(O5:Q5) -> 15.002 | S5: 13.338 | T5: 15.051 | U5: 13.061 | V5: =55.585-SUM(S5:U5) -> 14.135 | W5: 16.595 | X5: 17.559 | AI5: =SUM(O5:R5) -> 56.184 | AJ5: =SUM(P5:S5) -> 56.745 | AK5: =SUM(S5:V5) -> 55.585 | AL5: =AK5*(1+AL10) -> 68.9254 | AM5: =AL5*(1+AM10) -> 83.399734 | AN5: =AM5*(1+AN10) -> 98.411686 | AO5: =AN5*(1+AO10) -> 114.15756 | AP5: =AO5*(1+AP10) -> 130.13961 | AQ5: =AP5*(1+AQ10) -> 145.75637 | AR5: =AQ5*(1+AR10) -> 160.332 | AS5: =AR5*(1+AS10) -> 173.15856 | ... AU5: =AT5*(1+AU10) -> 190.89
B6: Defense & Intelligence | O6: 29.614 | P6: 29.681 | Q6: 28.541 | R6: =116.281-SUM(O6:Q6) -> 28.445 | S6: 36.647 | T6: 41.909 | U6: 49.365 | V6: =180.232-SUM(S6:U6) -> 52.311 | W6: 61.386 | X6: 80.995 | AI6: =SUM(O6:R6) -> 116.281 | AJ6: =SUM(P6:S6) -> 123.314 | AK6: =SUM(S6:V6) -> 180.232 | AL6: =AK6*(1+AL11) -> 306.3944 | AM6: =AL6*(1+AM11) -> 459.5916 | AN6: =AM6*(1+AN11) -> 652.62007 | AO6: =AN6*(1+AO11) -> 822.30129 | AP6: =AO6*(1+AP11) -> 1060.7687 | AQ6: =AP6*(1+AQ11) -> 1336.5685 | AR6: =AQ6*(1+AR11) -> 1643.9793 | AS6: =AR6*(1+AS11) -> 1972.7751 | ... AU6: =AT6*(1+AU11) -> 2654.3689
B7: Ttl Revenues | O7: =SUM(O4:O6) -> 60.44 | P7: =SUM(P4:P6) -> 61.092 | Q7: =SUM(Q4:Q6) -> 61.266 | R7: =SUM(R4:R6) -> 61.554 | S7: =SUM(S4:S6) -> 66.265 | T7: =SUM(T4:T6) -> 73.386 | U7: =SUM(U4:U6) -> 81.254 | V7: =SUM(V4:V6) -> 86.822 | ... X7: =SUM(X4:X6) -> 116.052 | AI7: =SUM(O7:R7) -> 244.352 | AJ7: =SUM(P7:S7) -> 250.177 | AK7: =SUM(S7:V7) -> 307.727 | AL7: =SUM(AL4:AL6) -> 451.5444 | AM7: =SUM(AM4:AM6) -> 624.55166 | AN7: =SUM(AN4:AN6) -> 839.11691 | AO7: =SUM(AO4:AO6) -> 1030.71 | AP7: =SUM(AP4:AP6) -> 1290.8145 | AQ7: =SUM(AQ4:AQ6) -> 1587.2264 | AR7: =SUM(AR4:AR6) -> 1913.4088 | AS7: =SUM(AS4:AS6) -> 2258.8497 | ... AU7: =SUM(AU4:AU6) -> 2964.47
B9: Civil Government Growth Y/y | S9: =S4/O4-1 -> -0.09801097 | T9: =T4/P4-1 -> -0.043832586 | U9: =U4/Q4-1 -> 0.014877102 | V9: =V4/R4-1 -> 0.12531065 | W9: =W4/S4-1 -> -0.0068181818 | X9: =X4/T4-1 -> 0.065262389 | AJ9: =AJ4/AI4-1 -> -0.024608065 | AK9: =AK4/AJ4-1 -> 0.025556918 | AL9: 0.06 | AM9: 0.07 | AN9: 0.08 | AO9: 0.07 | AP9: 0.06 | AQ9: 0.05 | AR9: 0.04 | AS9: 0.035 | AT9: 0.03 | AU9: 0.025
B10: Commercial Growth Y/y | S10: =S5/O5-1 -> 0.04390702 | T10: =T5/P5-1 -> 0.057546374 | U10: =U5/Q5-1 -> -0.078459042 | V10: =V5/R5-1 -> -0.057792294 | W10: =W5/S5-1 -> 0.24418953 | X10: =X5/T5-1 -> 0.16663345 | AJ10: =AJ5/AI5-1 -> 0.0099850491 | AK10: =AK5/AJ5-1 -> -0.02044233 | AL10: 0.24 | AM10: 0.21 | AN10: 0.18 | AO10: 0.16 | AP10: 0.14 | AQ10: 0.12 | AR10: 0.1 | AS10: 0.08 | AT10: 0.06 | AU10: 0.04
B11: Defense & Intelligence Growth Y/y | S11: =S6/O6-1 -> 0.23748903 | T11: =T6/P6-1 -> 0.41198073 | U11: =U6/Q6-1 -> 0.72961704 | V11: =V6/R6-1 -> 0.83902268 | W11: =W6/S6-1 -> 0.67506208 | X11: =X6/T6-1 -> 0.93263977 | AJ11: =AJ6/AI6-1 -> 0.060482796 | AK11: =AK6/AJ6-1 -> 0.46156965 | AL11: 0.7 | AM11: 0.5 | AN11: 0.42 | AO11: 0.26 | AP11: 0.29 | AQ11: 0.26 | AR11: 0.23 | AS11: 0.2 | AT11: 0.17 | AU11: 0.15
B12: Ttl Revenue Growth Y/y | S12: =S7/O7-1 -> 0.096376572 | T12: =T7/P7-1 -> 0.20123748 | U12: =U7/Q7-1 -> 0.32624947 | V12: =V7/R7-1 -> 0.41050135 | W12: =W7/S7-1 -> 0.42081038 | X12: =X7/T7-1 -> 0.58139155 | AJ12: =AJ7/AI7-1 -> 0.023838561 | AK12: =AK7/AJ7-1 -> 0.23003713 | AL12: =AL7/AK7-1 -> 0.46735386 | AM12: =AM7/AL7-1 -> 0.38314561 | AN12: =AN7/AM7-1 -> 0.34355085 | AO12: =AO7/AN7-1 -> 0.228327 | AP12: =AP7/AO7-1 -> 0.2523547 | AQ12: =AQ7/AP7-1 -> 0.2296317 | ... AU12: =AU7/AT7-1 -> 0.13668396
B14: Civil Government % of Ttl Revenues | O14: =O4/O7 -> 0.29862674 | P14: =P4/P7 -> 0.28119885 | Q14: =Q4/Q7 -> 0.30281069 | R14: =R4/R7 -> 0.29416447 | S14: =S4/S7 -> 0.24568022 | T14: =T4/T7 -> 0.22383016 | U14: =U4/U7 -> 0.23171782 | V14: =V4/V7 -> 0.23468706 | ... X14: =X4/X7 -> 0.15077724 | AI14: =AI4/AI7 -> 0.29419444 | AJ14: =AJ4/AJ7 -> 0.28027357 | AK14: =AK4/AK7 -> 0.23368115
B15: Commercial % of Ttl Revenues | O15: =O5/O7 -> 0.21139974 | P15: =P5/P7 -> 0.23296013 | Q15: =Q5/Q7 -> 0.23133549 | R15: =R5/R7 -> 0.24372096 | S15: =S5/S7 -> 0.20128273 | T15: =T5/T7 -> 0.20509361 | U15: =U5/U7 -> 0.16074286 | V15: =V5/V7 -> 0.16280436 | ... X15: =X5/X7 -> 0.15130286 | AI15: =AI5/AI7 -> 0.22993059 | AJ15: =AJ5/AJ7 -> 0.22681941 | AK15: =AK5/AK7 -> 0.18063088
B16: Defense & Intelligence % of Ttl Revenues | O16: =O6/O7 -> 0.48997353 | P16: =P6/P7 -> 0.48584103 | Q16: =Q6/Q7 -> 0.46585382 | R16: =R6/R7 -> 0.46211457 | S16: =S6/S7 -> 0.55303705 | T16: =T6/T7 -> 0.57107623 | U16: =U6/U7 -> 0.60753932 | V16: =V6/V7 -> 0.60250858 | ... X16: =X6/X7 -> 0.6979199 | AI16: =AI6/AI7 -> 0.47587497 | AJ16: =AJ6/AJ7 -> 0.49290702 | AK16: =AK6/AK7 -> 0.58568796
B18: North America | O18: 32.713 | P18: 30.797 | Q18: 27.038 | R18: =119.35-SUM(O18:Q18) -> 28.802 | S18: 29.533 | T18: 31.093 | U18: 35.148 | V18: =132.01-SUM(S18:U18) -> 36.236 | W18: 37.037 | X18: 39.015 | AI18: =SUM(O18:R18) -> 119.35 | AJ18: =SUM(P18:S18) -> 116.17 | AK18: =SUM(S18:V18) -> 132.01
B19: APAC | O19: 11.142 | P19: 10.298 | Q19: 10.334 | R19: =42.401-SUM(O19:Q19) -> 10.627 | S19: 15.307 | T19: 16.15 | U19: 14.324 | V19: =59.813-SUM(S19:U19) -> 14.032 | W19: 19.307 | X19: 19.094 | AI19: =SUM(O19:R19) -> 42.401 | AJ19: =SUM(P19:S19) -> 46.566 | AK19: =SUM(S19:V19) -> 59.813
B20: Euro, Mid-East & Africa | O20: 13.694 | P20: 17.226 | Q20: 20.011 | R20: =70.085-SUM(O20:Q20) -> 19.154 | S20: 18.849 | T20: 23.467 | U20: 27.613 | V20: =103.674-SUM(S20:U20) -> 33.745 | W20: 35.053 | X20: 55.2 | AI20: =SUM(O20:R20) -> 70.085 | AJ20: =SUM(P20:S20) -> 75.24 | AK20: =SUM(S20:V20) -> 103.674
B21: LATAM | O21: 2.891 | P21: 2.771 | Q21: 3.883 | R21: =12.516-SUM(O21:Q21) -> 2.971 | S21: 2.576 | T21: 2.676 | U21: 4.169 | V21: =12.23-SUM(S21:U21) -> 2.809 | W21: 2.753 | X21: 2.743 | AI21: =SUM(O21:R21) -> 12.516 | AJ21: =SUM(P21:S21) -> 12.201 | AK21: =SUM(S21:V21) -> 12.23
B22: Ttl Revenues | O22: =SUM(O18:O21) -> 60.44 | P22: =SUM(P18:P21) -> 61.092 | Q22: =SUM(Q18:Q21) -> 61.266 | R22: =SUM(R18:R21) -> 61.554 | S22: =SUM(S18:S21) -> 66.265 | T22: =SUM(T18:T21) -> 73.386 | U22: =SUM(U18:U21) -> 81.254 | V22: =SUM(V18:V21) -> 86.822 | ... X22: =SUM(X18:X21) -> 116.052 | AI22: =SUM(O22:R22) -> 244.352 | AJ22: =SUM(P22:S22) -> 250.177 | AK22: =SUM(S22:V22) -> 307.727
B24: North America Growth Y/y | S24: =S18/O18-1 -> -0.097209061 | T24: =T18/P18-1 -> 0.0096113258 | U24: =U18/Q18-1 -> 0.29994822 | V24: =V18/R18-1 -> 0.25810708 | W24: =W18/S18-1 -> 0.25408865 | X24: =X18/T18-1 -> 0.25478403 | AJ24: =AJ18/AI18-1 -> -0.026644323 | AK24: =AK18/AJ18-1 -> 0.1363519
B25: APAC Growth Y/y | S25: =S19/O19-1 -> 0.37381081 | T25: =T19/P19-1 -> 0.56826568 | U25: =U19/Q19-1 -> 0.38610412 | V25: =V19/R19-1 -> 0.32041028 | W25: =W19/S19-1 -> 0.26131835 | X25: =X19/T19-1 -> 0.18229102 | AJ25: =AJ19/AI19-1 -> 0.098228815 | AK25: =AK19/AJ19-1 -> 0.28447795
B26: Euro, Mid-East & Africa Growth Y/y | S26: =S20/O20-1 -> 0.37644224 | T26: =T20/P20-1 -> 0.36230117 | U26: =U20/Q20-1 -> 0.37989106 | V26: =V20/R20-1 -> 0.761773 | W26: =W20/S20-1 -> 0.85967425 | X26: =X20/T20-1 -> 1.3522393 | AJ26: =AJ20/AI20-1 -> 0.073553542 | AK26: =AK20/AJ20-1 -> 0.37791069
B27: LATAM Growth Y/y | S27: =S21/O21-1 -> -0.10895884 | T27: =T21/P21-1 -> -0.034283652 | U27: =U21/Q21-1 -> 0.073654391 | V27: =V21/R21-1 -> -0.054527095 | W27: =W21/S21-1 -> 0.06871118 | X27: =X21/T21-1 -> 0.025037369 | AJ27: =AJ21/AI21-1 -> -0.025167785 | AK27: =AK21/AJ21-1 -> 0.0023768544
B28: Ttl Revenue Growth Y/y | S28: =S22/O22-1 -> 0.096376572 | T28: =T22/P22-1 -> 0.20123748 | U28: =U22/Q22-1 -> 0.32624947 | V28: =V22/R22-1 -> 0.41050135 | W28: =W22/S22-1 -> 0.42081038 | X28: =X22/T22-1 -> 0.58139155 | AJ28: =AJ22/AI22-1 -> 0.023838561 | AK28: =AK22/AJ22-1 -> 0.23003713
B30: North America % of Ttl Revenues | O30: =O18/O22 -> 0.54124752 | P30: =P18/P22 -> 0.50410856 | Q30: =Q18/Q22 -> 0.44132145 | R30: =R18/R22 -> 0.46791435 | S30: =S18/S22 -> 0.44568022 | T30: =T18/T22 -> 0.42369117 | U30: =U18/U22 -> 0.43256947 | V30: =V18/V22 -> 0.41735966 | ... X30: =X18/X22 -> 0.3361855 | AI30: =AI18/AI22 -> 0.48843472 | AJ30: =AJ18/AJ22 -> 0.46435124 | AK30: =AK18/AK22 -> 0.42898413
B31: APAC % of Ttl Revenues | O31: =O19/O22 -> 0.18434811 | P31: =P19/P22 -> 0.16856544 | Q31: =Q19/Q22 -> 0.16867431 | R31: =R19/R22 -> 0.17264516 | S31: =S19/S22 -> 0.23099676 | T31: =T19/T22 -> 0.22006922 | U31: =U19/U22 -> 0.17628671 | V31: =V19/V22 -> 0.16161802 | ... X31: =X19/X22 -> 0.16452969 | AI31: =AI19/AI22 -> 0.17352426 | AJ31: =AJ19/AJ22 -> 0.18613222 | AK31: =AK19/AK22 -> 0.19437033
B32: Euro, Mid-East & Africa % of Ttl Revenues | O32: =O20/O22 -> 0.22657181 | P32: =P20/P22 -> 0.28196818 | Q32: =Q20/Q22 -> 0.32662488 | R32: =R20/R22 -> 0.31117393 | S32: =S20/S22 -> 0.2844488 | T32: =T20/T22 -> 0.31977489 | U32: =U20/U22 -> 0.33983558 | V32: =V20/V22 -> 0.38866877 | ... X32: =X20/X22 -> 0.47564885 | AI32: =AI20/AI22 -> 0.28681983 | AJ32: =AJ20/AJ22 -> 0.30074707 | AK32: =AK20/AK22 -> 0.33690251
B33: LATAM % of Ttl Revenues | O33: =O21/O22 -> 0.047832561 | P33: =P21/P22 -> 0.045357821 | Q33: =Q21/Q22 -> 0.063379362 | R33: =R21/R22 -> 0.048266563 | S33: =S21/S22 -> 0.038874217 | T33: =T21/T22 -> 0.036464721 | U33: =U21/U22 -> 0.051308243 | V33: =V21/V22 -> 0.032353551 | ... X33: =X21/X22 -> 0.023635956 | AI33: =AI21/AI22 -> 0.051221189 | AJ33: =AJ21/AJ22 -> 0.048769471 | AK33: =AK21/AK22 -> 0.039743019
B35: Sales Backlog | O35: 242.392 | P35: 213.5 | Q35: 232.14 | R35: 503.749 | S35: 527.047 | T35: 736.077 | U35: 734.471 | V35: 900.427 | W35: 906.055 | X35: 814.863 | AI35: =AVERAGE(O35:R35) -> 297.94525 | AJ35: =AVERAGE(P35:S35) -> 369.109 | AK35: =AVERAGE(S35:V35) -> 724.5055
B37: Revenues | C37: 32 | D37: 30.4 | E37: 31.7 | F37: 37.1 | G37: 40.1 | H37: 48.4 | I37: 49.7 | J37: 53 | K37: 52.7 | L37: 53.8 | M37: 55.4 | N37: 58.9 | O37: 60.4 | P37: 61.1 | Q37: 61.3 | R37: 61.6 | S37: 66.3 | T37: 73.4 | U37: 81.3 | V37: 86.8 | W37: 94.2 | X37: 116.052 | AF37: =SUM(C37:F37) -> 131.2 | AG37: =SUM(G37:J37) -> 191.2 | AH37: =SUM(K37:N37) -> 220.8 | AI37: =SUM(O37:R37) -> 244.4 | AJ37: =SUM(P37:S37) -> 250.3 | AK37: =SUM(S37:V37) -> 307.8 | AL37: =AL7 -> 451.5444 | AM37: =AM7 -> 624.55166 | AN37: =AN7 -> 839.11691 | AO37: =AO7 -> 1030.71 | AP37: =AP7 -> 1290.8145 | AQ37: =AQ7 -> 1587.2264 | AR37: =AR7 -> 1913.4088 | AS37: =AS7 -> 2258.8497 | ... AU37: =AU7 -> 2964.47
B38: COGS | C38: 19.126 | D38: 19.82 | E38: 20.811 | F38: =82.987-SUM(C38:E38) -> 23.23 | G38: 23.628 | H38: 24.977 | I38: 24.728 | J38: =97.248-SUM(G38:I38) -> 23.915 | K38: 24.556 | L38: 27.469 | M38: 29.35 | N38: =107.746-SUM(K38:M38) -> 26.371 | O38: 28.757 | P38: 28.782 | Q38: 23.749 | R38: =104.627-SUM(O38:Q38) -> 23.339 | S38: 29.662 | T38: 31.118 | U38: 34.67 | V38: =135.242-SUM(S38:U38) -> 39.792 | W38: 43.749 | X38: 50.42 | AF38: =SUM(C38:F38) -> 82.987 | AG38: =SUM(G38:J38) -> 97.248 | AH38: =SUM(K38:N38) -> 107.746 | AI38: =SUM(O38:R38) -> 104.627 | AJ38: =SUM(P38:S38) -> 105.532 | AK38: =SUM(S38:V38) -> 135.242 | AL38: =AL37*(1-AL54) -> 203.19498 | AM38: =AM37*(1-AM54) -> 271.67997 | AN38: =AN37*(1-AN54) -> 356.62468 | AO38: =AO37*(1-AO54) -> 422.59108 | AP38: =AP37*(1-AP54) -> 516.32578 | AQ38: =AQ37*(1-AQ54) -> 619.01828 | AR38: =AR37*(1-AR54) -> 727.09535 | AS38: =AS37*(1-AS54) -> 835.77437 | ... AU38: =AU37*(1-AU54) -> 1037.5645
B39: GP | C39: =C37-C38 -> 12.874 | D39: =D37-D38 -> 10.58 | E39: =E37-E38 -> 10.889 | F39: =F37-F38 -> 13.87 | G39: =G37-G38 -> 16.472 | H39: =H37-H38 -> 23.423 | I39: =I37-I38 -> 24.972 | J39: =J37-J38 -> 29.085 | ... X39: =X37-X38 -> 65.632 | AF39: =SUM(C39:F39) -> 48.213 | AG39: =SUM(G39:J39) -> 93.952 | AH39: =SUM(K39:N39) -> 113.054 | AI39: =SUM(O39:R39) -> 139.773 | AJ39: =SUM(P39:S39) -> 144.768 | AK39: =SUM(S39:V39) -> 172.558 | AL39: =AL37*AL54 -> 248.34942 | AM39: =AM37*AM54 -> 352.87169 | AN39: =AN37*AN54 -> 482.49222 | AO39: =AO37*AO54 -> 608.11887 | AP39: =AP37*AP54 -> 774.48867 | AQ39: =AQ37*AQ54 -> 968.20808 | AR39: =AR37*AR54 -> 1186.3135 | AS39: =AS37*AS54 -> 1423.0753 | ... AU39: =AU37*AU54 -> 1926.9055
B40: R&D | C40: 12.13 | D40: 12.432 | E40: 14.959 | F40: =66.684-SUM(C40:E40) -> 27.163 | G40: 24.75 | H40: 26.737 | I40: 27.598 | J40: =110.916-SUM(G40:I40) -> 31.831 | K40: 28.186 | L40: 26.741 | M40: 33.002 | N40: =116.339-SUM(K40:M40) -> 28.41 | O40: 25.589 | P40: 27.25 | Q40: 25.216 | R40: =101.006-SUM(O40:Q40) -> 22.951 | S40: 23.074 | T40: 24.155 | U40: 27.327 | V40: =106.749-SUM(S40:U40) -> 32.193 | W40: 33.42 | X40: 35.156 | AF40: =SUM(C40:F40) -> 66.684 | AG40: =SUM(G40:J40) -> 110.916 | AH40: =SUM(K40:N40) -> 116.339 | AI40: =SUM(O40:R40) -> 101.006 | AJ40: =SUM(P40:S40) -> 98.491 | AK40: =SUM(S40:V40) -> 106.749 | AL40: =AL37*AL55 -> 158.04054 | AM40: =AM37*AM55 -> 199.85653 | AN40: =AN37*AN55 -> 243.3439 | AO40: =AO37*AO55 -> 263.86175 | AP40: =AP37*AP55 -> 304.89037 | AQ40: =AQ37*AQ55 -> 353.95148 | AR40: =AR37*AR55 -> 401.81585 | AS40: =AS37*AS55 -> 451.76993 | ... AU40: =AU37*AU55 -> 533.60459
B41: Sales and Marketing | C41: 10.653 | D41: 10.597 | E41: 12.441 | F41: =52.917-SUM(C41:E41) -> 19.226 | G41: 18.855 | H41: 19.483 | I41: 19.383 | J41: =78.02-SUM(G41:I41) -> 20.299 | K41: 23.125 | L41: 22.31 | M41: 20.774 | N41: =86.304-SUM(K41:M41) -> 20.095 | O41: 21.485 | P41: 23.733 | Q41: 16.795 | R41: =77.694-SUM(O41:Q41) -> 15.681 | S41: 16.314 | T41: 17.574 | U41: 18.783 | V41: =72.676-SUM(S41:U41) -> 20.005 | W41: 22.782 | X41: 21.498 | AF41: =SUM(C41:F41) -> 52.917 | AG41: =SUM(G41:J41) -> 78.02 | AH41: =SUM(K41:N41) -> 86.304 | AI41: =SUM(O41:R41) -> 77.694 | AJ41: =SUM(P41:S41) -> 72.523 | AK41: =SUM(S41:V41) -> 72.676 | AL41: =AL37*AL56 -> 108.37066 | AM41: =AM37*AM56 -> 143.64688 | AN41: =AN37*AN56 -> 184.60572 | AO41: =AO37*AO56 -> 216.44909 | AP41: =AP37*AP56 -> 264.61696 | AQ41: =AQ37*AQ56 -> 317.44527 | AR41: =AR37*AR56 -> 373.11472 | AS41: =AS37*AS56 -> 429.18143 | ... AU41: =AU37*AU56 -> 533.60459
B42: General and Admin | C42: 8.315 | D42: 11.824 | E42: 11.8 | F42: =56.672-SUM(C42:E42) -> 24.733 | G42: 20.608 | H42: 19.893 | I42: 20.627 | J42: =80.747-SUM(G42:I42) -> 19.619 | K42: 21.528 | L42: 20.521 | M42: 20.112 | N42: =80.055-SUM(K42:M42) -> 17.894 | O42: 19.18 | P42: 20.904 | Q42: 18.114 | R42: =77.147-SUM(O42:Q42) -> 18.949 | S42: 19.986 | T42: 18.499 | U42: 18.814 | V42: =88.133-SUM(S42:U42) -> 30.834 | W42: 29.087 | X42: 22.487 | AF42: =SUM(C42:F42) -> 56.672 | AG42: =SUM(G42:J42) -> 80.747 | AH42: =SUM(K42:N42) -> 80.055 | AI42: =SUM(O42:R42) -> 77.147 | AJ42: =SUM(P42:S42) -> 77.953 | AK42: =SUM(S42:V42) -> 88.133 | AL42: =AL37*AL57 -> 137.72104 | AM42: =AM37*AM57 -> 177.99722 | AN42: =AN37*AN57 -> 230.75715 | AO42: =AO37*AO57 -> 273.13814 | AP42: =AP37*AP57 -> 329.15769 | AQ42: =AQ37*AQ57 -> 388.87046 | AR42: =AR37*AR57 -> 449.65107 | AS42: =AS37*AS57 -> 646.78102 | ... AU42: =AU37*AU57 -> 848.82271
B43: Operating Income | C43: =C39-SUM(C40:C42) -> -18.224 | D43: =D39-SUM(D40:D42) -> -24.273 | E43: =E39-SUM(E40:E42) -> -28.311 | F43: =F39-SUM(F40:F42) -> -57.252 | G43: =G39-SUM(G40:G42) -> -47.741 | H43: =H39-SUM(H40:H42) -> -42.69 | I43: =I39-SUM(I40:I42) -> -42.636 | J43: =J39-SUM(J40:J42) -> -42.664 | ... X43: =X39-SUM(X40:X42) -> -13.509 | AF43: =SUM(C43:F43) -> -128.06 | AG43: =SUM(G43:J43) -> -175.731 | AH43: =SUM(K43:N43) -> -169.644 | AI43: =SUM(O43:R43) -> -116.074 | AJ43: =SUM(P43:S43) -> -104.199 | AK43: =SUM(S43:V43) -> -95 | AL43: =AL39-SUM(AL40:AL42) -> -155.78282 | AM43: =AM39-SUM(AM40:AM42) -> -168.62895 | AN43: =AN39-SUM(AN40:AN42) -> -176.21455 | AO43: =AO39-SUM(AO40:AO42) -> -145.3301 | AP43: =AP39-SUM(AP40:AP42) -> -124.17635 | AQ43: =AQ39-SUM(AQ40:AQ42) -> -92.059129 | AR43: =AR39-SUM(AR40:AR42) -> -38.268176 | AS43: =AS39-SUM(AS40:AS42) -> -104.6571 | ... AU43: =AU39-SUM(AU40:AU42) -> 10.873576
B44: Interest Income | C44: 0 | D44: 0 | E44: 0.008 | F44: =0.021-SUM(C44:E44) -> 0.013 | G44: 0.112 | H44: 1.311 | I44: 2.853 | J44: =7.67-SUM(G44:I44) -> 3.394 | K44: 4.506 | L44: 3.802 | M44: 3.445 | N44: =15.414-SUM(K44:M44) -> 3.661 | O44: 3.107 | P44: 2.771 | Q44: 2.414 | R44: =10.257-SUM(O44:Q44) -> 1.965 | S44: 1.884 | T44: 2.172 | U44: 4.414 | V44: =14.329-SUM(S44:U44) -> 5.859 | W44: 5.153 | X44: 6.433 | AF44: =SUM(C44:F44) -> 0.021 | AG44: =SUM(G44:J44) -> 7.67 | AH44: =SUM(K44:N44) -> 15.414 | AI44: =SUM(O44:R44) -> 10.257 | AJ44: =SUM(P44:S44) -> 9.034 | AK44: =SUM(S44:V44) -> 14.329 | AL44: =SUM(AK62:AK64)*($BE$62) -> 200.22875 | AM44: =SUM(AL62:AL64)*($BE$62) -> 213.67345 | AN44: =SUM(AM62:AM63)*($BE$62) -> 226.92127 | AO44: =SUM(AN62:AN63)*($BE$62) -> 241.77274 | AP44: =SUM(AO62:AO63)*($BE$62) -> 270.33971 | AQ44: =SUM(AP62:AP63)*($BE$62) -> 313.98162 | AR44: =SUM(AQ62:AQ63)*($BE$62) -> 380.59133 | AS44: =SUM(AR62:AR63)*($BE$62) -> 483.7008 | AT44: =SUM(AS62:AS63)*($BE$62) -> 597.94446 | AU44: =SUM(AT62:AT63)*($BE$62) -> 761.68166
B45: Interest Expense | C45: -2.527 | D45: -2.611 | E45: -2.612 | F45: =-8.772-SUM(C45:E45) -> -1.022 | G45: 0 | H45: 0 | I45: 0 | J45: =0-SUM(G45:I45) -> 0 | K45: 0 | L45: 0 | M45: 0 | N45: =0-SUM(K45:M45) -> 0 | O45: 0 | P45: 0 | Q45: -0.277 | R45: =-0.832-SUM(O45:Q45) -> -0.555 | S45: -0.499 | T45: 0 | U45: -1.02 | V45: =-3.436-SUM(S45:U45) -> -1.917 | W45: -1.446 | X45: -1.439 | AF45: =SUM(C45:F45) -> -8.772 | AG45: =SUM(G45:J45) -> 0 | AH45: =SUM(K45:N45) -> 0 | AI45: =SUM(O45:R45) -> -0.832 | AJ45: =SUM(P45:S45) -> -1.331 | AK45: =SUM(S45:V45) -> -3.436 | AL45: =-AK86*($AZ$79) -> -2.23442 | AM45: =-AL86*($AZ$79) -> -2.2232479 | AN45: =-AM86*($AZ$79) -> -2.2121317 | AO45: =-AN86*($AZ$79) -> -2.201071 | AP45: =-AO86*($AZ$79) -> -2.1900656 | AQ45: =-AP86*($AZ$79) -> -2.1791153 | AR45: =-AQ86*($AZ$79) -> -2.1682197 | AS45: =-AR86*($AZ$79) -> -2.1573786 | ... AU45: =-AT86*($AZ$79) -> -2.1358588
B46: Change in FV of Warrant Liabilities | C46: -8.026 | D46: 6.769 | E46: -10.172 | F46: =5.726-SUM(C46:E46) -> 17.155 | G46: 3.276 | H46: 2.112 | I46: -0.019 | J46: =6.554-SUM(G46:I46) -> 1.185 | K46: 5.945 | L46: 1.226 | M46: 6.833 | N46: =13.709-SUM(K46:M46) -> -0.295 | O46: 1.53 | P46: -0.602 | Q46: 0.198 | R46: =-15.116-SUM(O46:Q46) -> -16.242 | S46: 10.387 | T46: -5.679 | U46: -43.473 | V46: =-161.4-SUM(S46:U46) -> -122.635 | W46: -106.474 | X46: 0 | AF46: =SUM(C46:F46) -> 5.726 | AG46: =SUM(G46:J46) -> 6.554 | AH46: =SUM(K46:N46) -> 13.709 | AI46: =SUM(O46:R46) -> -15.116 | AJ46: =SUM(P46:S46) -> -6.259 | AK46: =SUM(S46:V46) -> -161.4 | AL46: 0 | AM46: 0 | AN46: 0 | AO46: 0 | AP46: 0 | AQ46: 0 | AR46: 0 | AS46: 0 | AT46: 0 | AU46: 0
B47: Other Income | C47: -0.177 | D47: -0.084 | E47: -0.06 | F47: =-2.248-1.69-SUM(C47:E47) -> -3.617 | G47: 0.28 | H47: -0.158 | I47: 0.001 | J47: =0.33-SUM(G47:I47) -> 0.207 | K47: 0.104 | L47: 0.859 | M47: -0.069 | N47: =0.931-SUM(K47:M47) -> 0.037 | O47: 1.083 | P47: -0.363 | Q47: 0.217 | R47: =1.077-SUM(O47:Q47) -> 0.14 | S47: -0.701 | T47: -0.628 | U47: 0.018 | V47: =3.375-SUM(S47:U47) -> 4.686 | W47: -0.206 | X47: -0.105 | AF47: =SUM(C47:F47) -> -3.938 | AG47: =SUM(G47:J47) -> 0.33 | AH47: =SUM(K47:N47) -> 0.931 | AI47: =SUM(O47:R47) -> 1.077 | AJ47: =SUM(P47:S47) -> -0.707 | AK47: =SUM(S47:V47) -> 3.375 | AL47: 0 | AM47: 0 | AN47: 0 | AO47: 0 | AP47: 0 | AQ47: 0 | AR47: 0 | AS47: 0 | AT47: 0 | AU47: 0
...

Sheet Base Case
B1: [Use for Graphing] | C1: Q1 2021 | G1: Q1 2022 | K1: Q1 2023 | O1: Q1 2024 | S1: Q1 2025 | W1: Q1 2026
B2: Quarterly
B3: Revenues | C3: Q1 2021 | D3: Q2 2021 | E3: Q3 2021 | F3: Q4 2021 | G3: Q1 2022 | H3: Q2 2022 | I3: Q3 2022 | J3: Q4 2022 | K3: Q1 2023 | L3: Q2 2023 | M3: Q3 2023 | N3: Q4 2023 | O3: Q1 2024 | P3: Q2 2024 | Q3: Q3 2024 | R3: Q4 2024 | S3: Q1 2025 | T3: Q2 2025 | U3: Q3 2025 | V3: Q4 2025 | W3: Q1 2026 | X3: Q2 2026 | AF3: 2020 | AG3: =AF3+1 -> 2021 | AH3: =AG3+1 -> 2022 | AI3: =AH3+1 -> 2023 | AJ3: =AI3+1 -> 2024 | AK3: =AJ3+1 -> 2025 | AL3: 2026 | AM3: =AL3+1 -> 2027 | AN3: =AM3+1 -> 2028 | AO3: =AN3+1 -> 2029 | AP3: =AO3+1 -> 2030 | AQ3: =AP3+1 -> 2031 | AR3: =AQ3+1 -> 2032 | AS3: =AR3+1 -> 2033 | AT3: =AS3+1 -> 2034 | ... CS3: =CR3+1 -> 2085
B4: Civil Government | O4: 18.049 | P4: 17.179 | Q4: 18.552 | R4: =71.887-SUM(O4:Q4) -> 18.107 | S4: 16.28 | T4: 16.426 | U4: 18.828 | V4: =71.91-SUM(S4:U4) -> 20.376 | W4: 16.169 | X4: 17.498 | AI4: =SUM(O4:R4) -> 71.887 | AJ4: =SUM(P4:S4) -> 70.118 | AK4: =SUM(S4:V4) -> 71.91 | AL4: =AK4*(1+AL9) -> 75.5055 | AM4: =AL4*(1+AM9) -> 80.03583 | AN4: =AM4*(1+AN9) -> 85.638338 | AO4: =AN4*(1+AO9) -> 90.776638 | AP4: =AO4*(1+AP9) -> 95.31547 | AQ4: =AP4*(1+AQ9) -> 99.128089 | AR4: =AQ4*(1+AR9) -> 102.59757 | AS4: =AR4*(1+AS9) -> 105.6755 | ... AU4: =AT4*(1+AU9) -> 110.48373
B5: Commercial | O5: 12.777 | P5: 14.232 | Q5: 14.173 | R5: =56.184-SUM(O5:Q5) -> 15.002 | S5: 13.338 | T5: 15.051 | U5: 13.061 | V5: =55.585-SUM(S5:U5) -> 14.135 | W5: 16.595 | X5: 17.559 | AI5: =SUM(O5:R5) -> 56.184 | AJ5: =SUM(P5:S5) -> 56.745 | AK5: =SUM(S5:V5) -> 55.585 | AL5: =AK5*(1+AL10) -> 67.8137 | AM5: =AL5*(1+AM10) -> 77.307618 | AN5: =AM5*(1+AN10) -> 87.357608 | AO5: =AN5*(1+AO10) -> 97.840521 | AP5: =AO5*(1+AP10) -> 108.60298 | AQ5: =AP5*(1+AQ10) -> 119.46328 | AR5: =AQ5*(1+AR10) -> 130.21497 | AS5: =AR5*(1+AS10) -> 139.33002 | ... AU5: =AT5*(1+AU10) -> 150.68542
B6: Defense & Intelligence | O6: 29.614 | P6: 29.681 | Q6: 28.541 | R6: =116.281-SUM(O6:Q6) -> 28.445 | S6: 36.647 | T6: 41.909 | U6: 49.365 | V6: =180.232-SUM(S6:U6) -> 52.311 | W6: 61.386 | X6: 80.995 | AI6: =SUM(O6:R6) -> 116.281 | AJ6: =SUM(P6:S6) -> 123.314 | AK6: =SUM(S6:V6) -> 180.232 | AL6: =AK6*(1+AL11) -> 279.3596 | AM6: =AL6*(1+AM11) -> 385.51625 | AN6: =AM6*(1+AN11) -> 508.88145 | AO6: =AN6*(1+AO11) -> 646.27944 | AP6: =AO6*(1+AP11) -> 781.99812 | AQ6: =AP6*(1+AQ11) -> 930.57776 | AR6: =AQ6*(1+AR11) -> 1088.776 | AS6: =AR6*(1+AS11) -> 1252.0924 | ... AU6: =AT6*(1+AU11) -> 1570.4995
B7: Ttl Revenues | O7: =SUM(O4:O6) -> 60.44 | P7: =SUM(P4:P6) -> 61.092 | Q7: =SUM(Q4:Q6) -> 61.266 | R7: =SUM(R4:R6) -> 61.554 | S7: =SUM(S4:S6) -> 66.265 | T7: =SUM(T4:T6) -> 73.386 | U7: =SUM(U4:U6) -> 81.254 | V7: =SUM(V4:V6) -> 86.822 | ... X7: =SUM(X4:X6) -> 116.052 | AI7: =SUM(O7:R7) -> 244.352 | AJ7: =SUM(P7:S7) -> 250.177 | AK7: =SUM(S7:V7) -> 307.727 | AL7: =SUM(AL4:AL6) -> 422.6788 | AM7: =SUM(AM4:AM6) -> 542.8597 | AN7: =SUM(AN4:AN6) -> 681.87739 | AO7: =SUM(AO4:AO6) -> 834.8966 | AP7: =SUM(AP4:AP6) -> 985.91657 | AQ7: =SUM(AQ4:AQ6) -> 1149.1691 | AR7: =SUM(AR4:AR6) -> 1321.5885 | AS7: =SUM(AS4:AS6) -> 1497.0979 | ... AU7: =SUM(AU4:AU6) -> 1831.6686
B9: Civil Government Growth Y/y | S9: =S4/O4-1 -> -0.09801097 | T9: =T4/P4-1 -> -0.043832586 | U9: =U4/Q4-1 -> 0.014877102 | V9: =V4/R4-1 -> 0.12531065 | W9: =W4/S4-1 -> -0.0068181818 | X9: =X4/T4-1 -> 0.065262389 | AJ9: =AJ4/AI4-1 -> -0.024608065 | AK9: =AK4/AJ4-1 -> 0.025556918 | AL9: 0.05 | AM9: 0.06 | AN9: 0.07 | AO9: 0.06 | AP9: 0.05 | AQ9: 0.04 | AR9: 0.035 | AS9: 0.03 | AT9: 0.025 | AU9: 0.02
B10: Commercial Growth Y/y | S10: =S5/O5-1 -> 0.04390702 | T10: =T5/P5-1 -> 0.057546374 | U10: =U5/Q5-1 -> -0.078459042 | V10: =V5/R5-1 -> -0.057792294 | W10: =W5/S5-1 -> 0.24418953 | X10: =X5/T5-1 -> 0.16663345 | AJ10: =AJ5/AI5-1 -> 0.0099850491 | AK10: =AK5/AJ5-1 -> -0.02044233 | AL10: 0.22 | AM10: 0.14 | AN10: 0.13 | AO10: 0.12 | AP10: 0.11 | AQ10: 0.1 | AR10: 0.09 | AS10: 0.07 | AT10: 0.05 | AU10: 0.03
B11: Defense & Intelligence Growth Y/y | S11: =S6/O6-1 -> 0.23748903 | T11: =T6/P6-1 -> 0.41198073 | U11: =U6/Q6-1 -> 0.72961704 | V11: =V6/R6-1 -> 0.83902268 | W11: =W6/S6-1 -> 0.67506208 | X11: =X6/T6-1 -> 0.93263977 | AJ11: =AJ6/AI6-1 -> 0.060482796 | AK11: =AK6/AJ6-1 -> 0.46156965 | AL11: 0.55 | AM11: 0.38 | AN11: 0.32 | AO11: 0.27 | AP11: 0.21 | AQ11: 0.19 | AR11: 0.17 | AS11: 0.15 | AT11: 0.13 | AU11: 0.11
B12: Ttl Revenue Growth Y/y | S12: =S7/O7-1 -> 0.096376572 | T12: =T7/P7-1 -> 0.20123748 | U12: =U7/Q7-1 -> 0.32624947 | V12: =V7/R7-1 -> 0.41050135 | W12: =W7/S7-1 -> 0.42081038 | X12: =X7/T7-1 -> 0.58139155 | AJ12: =AJ7/AI7-1 -> 0.023838561 | AK12: =AK7/AJ7-1 -> 0.23003713 | AL12: =AL7/AK7-1 -> 0.37355123 | AM12: =AM7/AL7-1 -> 0.2843315 | AN12: =AN7/AM7-1 -> 0.25608403 | AO12: =AO7/AN7-1 -> 0.22440868 | AP12: =AP7/AO7-1 -> 0.18088464 | AQ12: =AQ7/AP7-1 -> 0.16558456 | ... AU12: =AU7/AT7-1 -> 0.097150305
B14: Civil Government % of Ttl Revenues | O14: =O4/O7 -> 0.29862674 | P14: =P4/P7 -> 0.28119885 | Q14: =Q4/Q7 -> 0.30281069 | R14: =R4/R7 -> 0.29416447 | S14: =S4/S7 -> 0.24568022 | T14: =T4/T7 -> 0.22383016 | U14: =U4/U7 -> 0.23171782 | V14: =V4/V7 -> 0.23468706 | ... X14: =X4/X7 -> 0.15077724 | AI14: =AI4/AI7 -> 0.29419444 | AJ14: =AJ4/AJ7 -> 0.28027357 | AK14: =AK4/AK7 -> 0.23368115
B15: Commercial % of Ttl Revenues | O15: =O5/O7 -> 0.21139974 | P15: =P5/P7 -> 0.23296013 | Q15: =Q5/Q7 -> 0.23133549 | R15: =R5/R7 -> 0.24372096 | S15: =S5/S7 -> 0.20128273 | T15: =T5/T7 -> 0.20509361 | U15: =U5/U7 -> 0.16074286 | V15: =V5/V7 -> 0.16280436 | ... X15: =X5/X7 -> 0.15130286 | AI15: =AI5/AI7 -> 0.22993059 | AJ15: =AJ5/AJ7 -> 0.22681941 | AK15: =AK5/AK7 -> 0.18063088
B16: Defense & Intelligence % of Ttl Revenues | O16: =O6/O7 -> 0.48997353 | P16: =P6/P7 -> 0.48584103 | Q16: =Q6/Q7 -> 0.46585382 | R16: =R6/R7 -> 0.46211457 | S16: =S6/S7 -> 0.55303705 | T16: =T6/T7 -> 0.57107623 | U16: =U6/U7 -> 0.60753932 | V16: =V6/V7 -> 0.60250858 | ... X16: =X6/X7 -> 0.6979199 | AI16: =AI6/AI7 -> 0.47587497 | AJ16: =AJ6/AJ7 -> 0.49290702 | AK16: =AK6/AK7 -> 0.58568796
B18: North America | O18: 32.713 | P18: 30.797 | Q18: 27.038 | R18: =119.35-SUM(O18:Q18) -> 28.802 | S18: 29.533 | T18: 31.093 | U18: 35.148 | V18: =132.01-SUM(S18:U18) -> 36.236 | W18: 37.037 | X18: 39.015 | AI18: =SUM(O18:R18) -> 119.35 | AJ18: =SUM(P18:S18) -> 116.17 | AK18: =SUM(S18:V18) -> 132.01
B19: APAC | O19: 11.142 | P19: 10.298 | Q19: 10.334 | R19: =42.401-SUM(O19:Q19) -> 10.627 | S19: 15.307 | T19: 16.15 | U19: 14.324 | V19: =59.813-SUM(S19:U19) -> 14.032 | W19: 19.307 | X19: 19.094 | AI19: =SUM(O19:R19) -> 42.401 | AJ19: =SUM(P19:S19) -> 46.566 | AK19: =SUM(S19:V19) -> 59.813
B20: Euro, Mid-East & Africa | O20: 13.694 | P20: 17.226 | Q20: 20.011 | R20: =70.085-SUM(O20:Q20) -> 19.154 | S20: 18.849 | T20: 23.467 | U20: 27.613 | V20: =103.674-SUM(S20:U20) -> 33.745 | W20: 35.053 | X20: 55.2 | AI20: =SUM(O20:R20) -> 70.085 | AJ20: =SUM(P20:S20) -> 75.24 | AK20: =SUM(S20:V20) -> 103.674
B21: LATAM | O21: 2.891 | P21: 2.771 | Q21: 3.883 | R21: =12.516-SUM(O21:Q21) -> 2.971 | S21: 2.576 | T21: 2.676 | U21: 4.169 | V21: =12.23-SUM(S21:U21) -> 2.809 | W21: 2.753 | X21: 2.743 | AI21: =SUM(O21:R21) -> 12.516 | AJ21: =SUM(P21:S21) -> 12.201 | AK21: =SUM(S21:V21) -> 12.23
B22: Ttl Revenues | O22: =SUM(O18:O21) -> 60.44 | P22: =SUM(P18:P21) -> 61.092 | Q22: =SUM(Q18:Q21) -> 61.266 | R22: =SUM(R18:R21) -> 61.554 | S22: =SUM(S18:S21) -> 66.265 | T22: =SUM(T18:T21) -> 73.386 | U22: =SUM(U18:U21) -> 81.254 | V22: =SUM(V18:V21) -> 86.822 | ... X22: =SUM(X18:X21) -> 116.052 | AI22: =SUM(O22:R22) -> 244.352 | AJ22: =SUM(P22:S22) -> 250.177 | AK22: =SUM(S22:V22) -> 307.727
B24: North America Growth Y/y | S24: =S18/O18-1 -> -0.097209061 | T24: =T18/P18-1 -> 0.0096113258 | U24: =U18/Q18-1 -> 0.29994822 | V24: =V18/R18-1 -> 0.25810708 | W24: =W18/S18-1 -> 0.25408865 | X24: =X18/T18-1 -> 0.25478403 | AJ24: =AJ18/AI18-1 -> -0.026644323 | AK24: =AK18/AJ18-1 -> 0.1363519
B25: APAC Growth Y/y | S25: =S19/O19-1 -> 0.37381081 | T25: =T19/P19-1 -> 0.56826568 | U25: =U19/Q19-1 -> 0.38610412 | V25: =V19/R19-1 -> 0.32041028 | W25: =W19/S19-1 -> 0.26131835 | X25: =X19/T19-1 -> 0.18229102 | AJ25: =AJ19/AI19-1 -> 0.098228815 | AK25: =AK19/AJ19-1 -> 0.28447795
B26: Euro, Mid-East & Africa Growth Y/y | S26: =S20/O20-1 -> 0.37644224 | T26: =T20/P20-1 -> 0.36230117 | U26: =U20/Q20-1 -> 0.37989106 | V26: =V20/R20-1 -> 0.761773 | W26: =W20/S20-1 -> 0.85967425 | X26: =X20/T20-1 -> 1.3522393 | AJ26: =AJ20/AI20-1 -> 0.073553542 | AK26: =AK20/AJ20-1 -> 0.37791069
B27: LATAM Growth Y/y | S27: =S21/O21-1 -> -0.10895884 | T27: =T21/P21-1 -> -0.034283652 | U27: =U21/Q21-1 -> 0.073654391 | V27: =V21/R21-1 -> -0.054527095 | W27: =W21/S21-1 -> 0.06871118 | X27: =X21/T21-1 -> 0.025037369 | AJ27: =AJ21/AI21-1 -> -0.025167785 | AK27: =AK21/AJ21-1 -> 0.0023768544
B28: Ttl Revenue Growth Y/y | S28: =S22/O22-1 -> 0.096376572 | T28: =T22/P22-1 -> 0.20123748 | U28: =U22/Q22-1 -> 0.32624947 | V28: =V22/R22-1 -> 0.41050135 | W28: =W22/S22-1 -> 0.42081038 | X28: =X22/T22-1 -> 0.58139155 | AJ28: =AJ22/AI22-1 -> 0.023838561 | AK28: =AK22/AJ22-1 -> 0.23003713
B30: North America % of Ttl Revenues | O30: =O18/O22 -> 0.54124752 | P30: =P18/P22 -> 0.50410856 | Q30: =Q18/Q22 -> 0.44132145 | R30: =R18/R22 -> 0.46791435 | S30: =S18/S22 -> 0.44568022 | T30: =T18/T22 -> 0.42369117 | U30: =U18/U22 -> 0.43256947 | V30: =V18/V22 -> 0.41735966 | ... X30: =X18/X22 -> 0.3361855 | AI30: =AI18/AI22 -> 0.48843472 | AJ30: =AJ18/AJ22 -> 0.46435124 | AK30: =AK18/AK22 -> 0.42898413
B31: APAC % of Ttl Revenues | O31: =O19/O22 -> 0.18434811 | P31: =P19/P22 -> 0.16856544 | Q31: =Q19/Q22 -> 0.16867431 | R31: =R19/R22 -> 0.17264516 | S31: =S19/S22 -> 0.23099676 | T31: =T19/T22 -> 0.22006922 | U31: =U19/U22 -> 0.17628671 | V31: =V19/V22 -> 0.16161802 | ... X31: =X19/X22 -> 0.16452969 | AI31: =AI19/AI22 -> 0.17352426 | AJ31: =AJ19/AJ22 -> 0.18613222 | AK31: =AK19/AK22 -> 0.19437033
B32: Euro, Mid-East & Africa % of Ttl Revenues | O32: =O20/O22 -> 0.22657181 | P32: =P20/P22 -> 0.28196818 | Q32: =Q20/Q22 -> 0.32662488 | R32: =R20/R22 -> 0.31117393 | S32: =S20/S22 -> 0.2844488 | T32: =T20/T22 -> 0.31977489 | U32: =U20/U22 -> 0.33983558 | V32: =V20/V22 -> 0.38866877 | ... X32: =X20/X22 -> 0.47564885 | AI32: =AI20/AI22 -> 0.28681983 | AJ32: =AJ20/AJ22 -> 0.30074707 | AK32: =AK20/AK22 -> 0.33690251
B33: LATAM % of Ttl Revenues | O33: =O21/O22 -> 0.047832561 | P33: =P21/P22 -> 0.045357821 | Q33: =Q21/Q22 -> 0.063379362 | R33: =R21/R22 -> 0.048266563 | S33: =S21/S22 -> 0.038874217 | T33: =T21/T22 -> 0.036464721 | U33: =U21/U22 -> 0.051308243 | V33: =V21/V22 -> 0.032353551 | ... X33: =X21/X22 -> 0.023635956 | AI33: =AI21/AI22 -> 0.051221189 | AJ33: =AJ21/AJ22 -> 0.048769471 | AK33: =AK21/AK22 -> 0.039743019
B35: Sales Backlog | O35: 242.392 | P35: 213.5 | Q35: 232.14 | R35: 503.749 | S35: 527.047 | T35: 736.077 | U35: 734.471 | V35: 900.427 | W35: 906.055 | X35: 814.863 | AI35: =AVERAGE(O35:R35) -> 297.94525 | AJ35: =AVERAGE(P35:S35) -> 369.109 | AK35: =AVERAGE(S35:V35) -> 724.5055
B37: Revenues | C37: 32 | D37: 30.4 | E37: 31.7 | F37: 37.1 | G37: 40.1 | H37: 48.4 | I37: 49.7 | J37: 53 | K37: 52.7 | L37: 53.8 | M37: 55.4 | N37: 58.9 | O37: 60.4 | P37: 61.1 | Q37: 61.3 | R37: 61.6 | S37: 66.3 | T37: 73.4 | U37: 81.3 | V37: 86.8 | W37: 94.2 | X37: 116.052 | AF37: =SUM(C37:F37) -> 131.2 | AG37: =SUM(G37:J37) -> 191.2 | AH37: =SUM(K37:N37) -> 220.8 | AI37: =SUM(O37:R37) -> 244.4 | AJ37: =SUM(P37:S37) -> 250.3 | AK37: =SUM(S37:V37) -> 307.8 | AL37: =AL7 -> 422.6788 | AM37: =AM7 -> 542.8597 | AN37: =AN7 -> 681.87739 | AO37: =AO7 -> 834.8966 | AP37: =AP7 -> 985.91657 | AQ37: =AQ7 -> 1149.1691 | AR37: =AR7 -> 1321.5885 | AS37: =AS7 -> 1497.0979 | ... AU37: =AU7 -> 1831.6686
B38: COGS | C38: 19.126 | D38: 19.82 | E38: 20.811 | F38: =82.987-SUM(C38:E38) -> 23.23 | G38: 23.628 | H38: 24.977 | I38: 24.728 | J38: =97.248-SUM(G38:I38) -> 23.915 | K38: 24.556 | L38: 27.469 | M38: 29.35 | N38: =107.746-SUM(K38:M38) -> 26.371 | O38: 28.757 | P38: 28.782 | Q38: 23.749 | R38: =104.627-SUM(O38:Q38) -> 23.339 | S38: 29.662 | T38: 31.118 | U38: 34.67 | V38: =135.242-SUM(S38:U38) -> 39.792 | W38: 43.749 | X38: 50.42 | AF38: =SUM(C38:F38) -> 82.987 | AG38: =SUM(G38:J38) -> 97.248 | AH38: =SUM(K38:N38) -> 107.746 | AI38: =SUM(O38:R38) -> 104.627 | AJ38: =SUM(P38:S38) -> 105.532 | AK38: =SUM(S38:V38) -> 135.242 | AL38: =AL37*(1-AL54) -> 194.43225 | AM38: =AM37*(1-AM54) -> 238.85827 | AN38: =AN37*(1-AN54) -> 293.20728 | AO38: =AO37*(1-AO54) -> 346.48209 | AP38: =AP37*(1-AP54) -> 399.29621 | AQ38: =AQ37*(1-AQ54) -> 453.92181 | AR38: =AR37*(1-AR54) -> 515.41953 | AS38: =AS37*(1-AS54) -> 576.38269 | ... AU38: =AU37*(1-AU54) -> 677.71739
B39: GP | C39: =C37-C38 -> 12.874 | D39: =D37-D38 -> 10.58 | E39: =E37-E38 -> 10.889 | F39: =F37-F38 -> 13.87 | G39: =G37-G38 -> 16.472 | H39: =H37-H38 -> 23.423 | I39: =I37-I38 -> 24.972 | J39: =J37-J38 -> 29.085 | ... X39: =X37-X38 -> 65.632 | AF39: =SUM(C39:F39) -> 48.213 | AG39: =SUM(G39:J39) -> 93.952 | AH39: =SUM(K39:N39) -> 113.054 | AI39: =SUM(O39:R39) -> 139.773 | AJ39: =SUM(P39:S39) -> 144.768 | AK39: =SUM(S39:V39) -> 172.558 | AL39: =AL37*AL54 -> 228.24655 | AM39: =AM37*AM54 -> 304.00143 | AN39: =AN37*AN54 -> 388.67011 | AO39: =AO37*AO54 -> 488.41451 | AP39: =AP37*AP54 -> 586.62036 | AQ39: =AQ37*AQ54 -> 695.24732 | AR39: =AR37*AR54 -> 806.169 | AS39: =AS37*AS54 -> 920.71521 | ... AU39: =AU37*AU54 -> 1153.9512
B40: R&D | C40: 12.13 | D40: 12.432 | E40: 14.959 | F40: =66.684-SUM(C40:E40) -> 27.163 | G40: 24.75 | H40: 26.737 | I40: 27.598 | J40: =110.916-SUM(G40:I40) -> 31.831 | K40: 28.186 | L40: 26.741 | M40: 33.002 | N40: =116.339-SUM(K40:M40) -> 28.41 | O40: 25.589 | P40: 27.25 | Q40: 25.216 | R40: =101.006-SUM(O40:Q40) -> 22.951 | S40: 23.074 | T40: 24.155 | U40: 27.327 | V40: =106.749-SUM(S40:U40) -> 32.193 | W40: 33.42 | X40: 35.156 | AF40: =SUM(C40:F40) -> 66.684 | AG40: =SUM(G40:J40) -> 110.916 | AH40: =SUM(K40:N40) -> 116.339 | AI40: =SUM(O40:R40) -> 101.006 | AJ40: =SUM(P40:S40) -> 98.491 | AK40: =SUM(S40:V40) -> 106.749 | AL40: =AL37*AL55 -> 147.93758 | AM40: =AM37*AM55 -> 179.1437 | AN40: =AN37*AN55 -> 204.56322 | AO40: =AO37*AO55 -> 212.89863 | AP40: =AP37*AP55 -> 241.54956 | AQ40: =AQ37*AQ55 -> 270.05475 | AR40: =AR37*AR55 -> 297.35742 | AS40: =AS37*AS55 -> 321.87605 | ... AU40: =AU37*AU55 -> 338.8587
B41: Sales and Marketing | C41: 10.653 | D41: 10.597 | E41: 12.441 | F41: =52.917-SUM(C41:E41) -> 19.226 | G41: 18.855 | H41: 19.483 | I41: 19.383 | J41: =78.02-SUM(G41:I41) -> 20.299 | K41: 23.125 | L41: 22.31 | M41: 20.774 | N41: =86.304-SUM(K41:M41) -> 20.095 | O41: 21.485 | P41: 23.733 | Q41: 16.795 | R41: =77.694-SUM(O41:Q41) -> 15.681 | S41: 16.314 | T41: 17.574 | U41: 18.783 | V41: =72.676-SUM(S41:U41) -> 20.005 | W41: 22.782 | X41: 21.498 | AF41: =SUM(C41:F41) -> 52.917 | AG41: =SUM(G41:J41) -> 78.02 | AH41: =SUM(K41:N41) -> 86.304 | AI41: =SUM(O41:R41) -> 77.694 | AJ41: =SUM(P41:S41) -> 72.523 | AK41: =SUM(S41:V41) -> 72.676 | AL41: =AL37*AL56 -> 103.55631 | AM41: =AM37*AM56 -> 127.57203 | AN41: =AN37*AN56 -> 150.01303 | AO41: =AO37*AO56 -> 175.32829 | AP41: =AP37*AP56 -> 202.1129 | AQ41: =AQ37*AQ56 -> 229.83383 | AR41: =AR37*AR56 -> 257.70976 | AS41: =AS37*AS56 -> 284.4486 | ... AU41: =AU37*AU56 -> 329.70035
B42: General and Admin | C42: 8.315 | D42: 11.824 | E42: 11.8 | F42: =56.672-SUM(C42:E42) -> 24.733 | G42: 20.608 | H42: 19.893 | I42: 20.627 | J42: =80.747-SUM(G42:I42) -> 19.619 | K42: 21.528 | L42: 20.521 | M42: 20.112 | N42: =80.055-SUM(K42:M42) -> 17.894 | O42: 19.18 | P42: 20.904 | Q42: 18.114 | R42: =77.147-SUM(O42:Q42) -> 18.949 | S42: 19.986 | T42: 18.499 | U42: 18.814 | V42: =88.133-SUM(S42:U42) -> 30.834 | W42: 29.087 | X42: 22.487 | AF42: =SUM(C42:F42) -> 56.672 | AG42: =SUM(G42:J42) -> 80.747 | AH42: =SUM(K42:N42) -> 80.055 | AI42: =SUM(O42:R42) -> 77.147 | AJ42: =SUM(P42:S42) -> 77.953 | AK42: =SUM(S42:V42) -> 88.133 | AL42: =AL37*AL57 -> 131.03043 | AM42: =AM37*AM57 -> 165.57221 | AN42: =AN37*AN57 -> 204.56322 | AO42: =AO37*AO57 -> 246.2945 | AP42: =AP37*AP57 -> 285.91581 | AQ42: =AQ37*AQ57 -> 327.5132 | AR42: =AR37*AR57 -> 370.04479 | AS42: =AS37*AS57 -> 411.70192 | ... AU42: =AU37*AU57 -> 514.69888
B43: Operating Income | C43: =C39-SUM(C40:C42) -> -18.224 | D43: =D39-SUM(D40:D42) -> -24.273 | E43: =E39-SUM(E40:E42) -> -28.311 | F43: =F39-SUM(F40:F42) -> -57.252 | G43: =G39-SUM(G40:G42) -> -47.741 | H43: =H39-SUM(H40:H42) -> -42.69 | I43: =I39-SUM(I40:I42) -> -42.636 | J43: =J39-SUM(J40:J42) -> -42.664 | ... X43: =X39-SUM(X40:X42) -> -13.509 | AF43: =SUM(C43:F43) -> -128.06 | AG43: =SUM(G43:J43) -> -175.731 | AH43: =SUM(K43:N43) -> -169.644 | AI43: =SUM(O43:R43) -> -116.074 | AJ43: =SUM(P43:S43) -> -104.199 | AK43: =SUM(S43:V43) -> -95 | AL43: =AL39-SUM(AL40:AL42) -> -154.27776 | AM43: =AM39-SUM(AM40:AM42) -> -168.28651 | AN43: =AN39-SUM(AN40:AN42) -> -170.46935 | AO43: =AO39-SUM(AO40:AO42) -> -146.1069 | AP43: =AP39-SUM(AP40:AP42) -> -142.9579 | AQ43: =AQ39-SUM(AQ40:AQ42) -> -132.15445 | AR43: =AR39-SUM(AR40:AR42) -> -118.94297 | AS43: =AS39-SUM(AS40:AS42) -> -97.311363 | ... AU43: =AU39-SUM(AU40:AU42) -> -29.306698
B44: Interest Income | C44: 0 | D44: 0 | E44: 0.008 | F44: =0.021-SUM(C44:E44) -> 0.013 | G44: 0.112 | H44: 1.311 | I44: 2.853 | J44: =7.67-SUM(G44:I44) -> 3.394 | K44: 4.506 | L44: 3.802 | M44: 3.445 | N44: =15.414-SUM(K44:M44) -> 3.661 | O44: 3.107 | P44: 2.771 | Q44: 2.414 | R44: =10.257-SUM(O44:Q44) -> 1.965 | S44: 1.884 | T44: 2.172 | U44: 4.414 | V44: =14.329-SUM(S44:U44) -> 5.859 | W44: 5.153 | X44: 6.433 | AF44: =SUM(C44:F44) -> 0.021 | AG44: =SUM(G44:J44) -> 7.67 | AH44: =SUM(K44:N44) -> 15.414 | AI44: =SUM(O44:R44) -> 10.257 | AJ44: =SUM(P44:S44) -> 9.034 | AK44: =SUM(S44:V44) -> 14.329 | AL44: =SUM(AK62:AK64)*($BE$62) -> 190.61777 | AM44: =SUM(AL62:AL64)*($BE$62) -> 200.95925 | AN44: =SUM(AM62:AM63)*($BE$62) -> 210.19213 | AO44: =SUM(AN62:AN63)*($BE$62) -> 221.56608 | AP44: =SUM(AO62:AO63)*($BE$62) -> 243.77937 | AQ44: =SUM(AP62:AP63)*($BE$62) -> 273.68633 | AR44: =SUM(AQ62:AQ63)*($BE$62) -> 315.9408 | AS44: =SUM(AR62:AR63)*($BE$62) -> 375.01692 | AT44: =SUM(AS62:AS63)*($BE$62) -> 458.56849 | AU44: =SUM(AT62:AT63)*($BE$62) -> 575.70332
B45: Interest Expense | C45: -2.527 | D45: -2.611 | E45: -2.612 | F45: =-8.772-SUM(C45:E45) -> -1.022 | G45: 0 | H45: 0 | I45: 0 | J45: =0-SUM(G45:I45) -> 0 | K45: 0 | L45: 0 | M45: 0 | N45: =0-SUM(K45:M45) -> 0 | O45: 0 | P45: 0 | Q45: -0.277 | R45: =-0.832-SUM(O45:Q45) -> -0.555 | S45: -0.499 | T45: 0 | U45: -1.02 | V45: =-3.436-SUM(S45:U45) -> -1.917 | W45: -1.446 | X45: -1.439 | AF45: =SUM(C45:F45) -> -8.772 | AG45: =SUM(G45:J45) -> 0 | AH45: =SUM(K45:N45) -> 0 | AI45: =SUM(O45:R45) -> -0.832 | AJ45: =SUM(P45:S45) -> -1.331 | AK45: =SUM(S45:V45) -> -3.436 | AL45: =-AK86*($AZ$79) -> -2.23442 | AM45: =-AL86*($AZ$79) -> -2.2232479 | AN45: =-AM86*($AZ$79) -> -2.2121317 | AO45: =-AN86*($AZ$79) -> -2.201071 | AP45: =-AO86*($AZ$79) -> -2.1900656 | AQ45: =-AP86*($AZ$79) -> -2.1791153 | AR45: =-AQ86*($AZ$79) -> -2.1682197 | AS45: =-AR86*($AZ$79) -> -2.1573786 | ... AU45: =-AT86*($AZ$79) -> -2.1358588
B46: Change in FV of Warrant Liabilities | C46: -8.026 | D46: 6.769 | E46: -10.172 | F46: =5.726-SUM(C46:E46) -> 17.155 | G46: 3.276 | H46: 2.112 | I46: -0.019 | J46: =6.554-SUM(G46:I46) -> 1.185 | K46: 5.945 | L46: 1.226 | M46: 6.833 | N46: =13.709-SUM(K46:M46) -> -0.295 | O46: 1.53 | P46: -0.602 | Q46: 0.198 | R46: =-15.116-SUM(O46:Q46) -> -16.242 | S46: 10.387 | T46: -5.679 | U46: -43.473 | V46: =-161.4-SUM(S46:U46) -> -122.635 | W46: -106.474 | X46: 0 | AF46: =SUM(C46:F46) -> 5.726 | AG46: =SUM(G46:J46) -> 6.554 | AH46: =SUM(K46:N46) -> 13.709 | AI46: =SUM(O46:R46) -> -15.116 | AJ46: =SUM(P46:S46) -> -6.259 | AK46: =SUM(S46:V46) -> -161.4 | AL46: 0 | AM46: 0 | AN46: 0 | AO46: 0 | AP46: 0 | AQ46: 0 | AR46: 0 | AS46: 0 | AT46: 0 | AU46: 0
B47: Other Income | C47: -0.177 | D47: -0.084 | E47: -0.06 | F47: =-2.248-1.69-SUM(C47:E47) -> -3.617 | G47: 0.28 | H47: -0.158 | I47: 0.001 | J47: =0.33-SUM(G47:I47) -> 0.207 | K47: 0.104 | L47: 0.859 | M47: -0.069 | N47: =0.931-SUM(K47:M47) -> 0.037 | O47: 1.083 | P47: -0.363 | Q47: 0.217 | R47: =1.077-SUM(O47:Q47) -> 0.14 | S47: -0.701 | T47: -0.628 | U47: 0.018 | V47: =3.375-SUM(S47:U47) -> 4.686 | W47: -0.206 | X47: -0.105 | AF47: =SUM(C47:F47) -> -3.938 | AG47: =SUM(G47:J47) -> 0.33 | AH47: =SUM(K47:N47) -> 0.931 | AI47: =SUM(O47:R47) -> 1.077 | AJ47: =SUM(P47:S47) -> -0.707 | AK47: =SUM(S47:V47) -> 3.375 | AL47: 0 | AM47: 0 | AN47: 0 | AO47: 0 | AP47: 0 | AQ47: 0 | AR47: 0 | AS47: 0 | AT47: 0 | AU47: 0
...

Sheet Notes | Quant Analysis
CI1: 0
P2: Employee Scope: | AL2: General Notes/Observations (Updated Q1'26)
Q29: Notes: | R29: [X]
R30: [Y]
R31: [Z]
AL32: Financial Stmts. Notes/Observations (Updated Q1'26)
P33: Institutional Ownership Snapshot Q1'26 | AL33: Revenues:
Q62: Notes: | R62: As of Q1'26 Google is a majority shareholder, owning 11% of The Company's outstanding equity
R63: [Y]
R64: [Z]
P66: Revenue Breakdown by Segment | AL66: Earnings Scope:
Q98: Notes: | R98: [X]
R99: [Y]
R100: [Z]
P102: Revenue Breakdown by Segment | AL102: Balance Sheet Scope:
Q134: Notes: | R134: [X]
R135: [Y] | AL135: [Equity Preformance Compared to Peers]
R136: [Z]
P138: Q/q Total Revenues, Net Income, FCF
Q167: Notes: | R167: [X]
R168: [Y]
R169: [Z]
P171: Y/y Total Revenues, Net Income, FCF
Q200: Notes: | R200: [X]
R201: [Y]
R202: [Z]
A217: VOO Historical Returns | I217: PL Historical Returns
A218: 1003 Trading Days (From: 6/22/22 - 6/22/62) | I218: 1003 Trading Days (From: 6/22/22 - 6/22/62)
A219: Close | B219: High | C219: Low | D219: Open | E219: Volume | F219: UTC Date | G219: Change | I219: Close | J219: High | K219: Low | L219: Open | M219: Volume | N219: UTC Date | O219: Change
A220: 686.1 | B220: 691.5 | C220: 685 | D220: 689.17 | E220: 13326373 | F220: Mon, 22 Jun 2026 00:00:00 GMT | G220: =A220/D220-1 -> -0.0044546338 | I220: 28.77 | J220: 29.135 | K220: 26.71 | L220: 27.96 | M220: 15178414 | N220: Mon, 22 Jun 2026 00:00:00 GMT | O220: =I220/L220-1 -> 0.028969957
A221: 688.11 | B221: 689.7 | C221: 685.7 | D221: 689.3 | E221: 17717272 | F221: Thu, 18 Jun 2026 00:00:00 GMT | G221: =A221/D221-1 -> -0.0017263891 | I221: 28.23 | J221: 29 | K221: 26.33 | L221: 28.65 | M221: 17151428 | N221: Thu, 18 Jun 2026 00:00:00 GMT | O221: =I221/L221-1 -> -0.014659686
A222: 681.41 | B222: 691.53 | C222: 679.64 | D222: 690.76 | E222: 14960955 | F222: Wed, 17 Jun 2026 00:00:00 GMT | G222: =A222/D222-1 -> -0.013535816 | I222: 28.22 | J222: 29.35 | K222: 28.08 | L222: 28.39 | M222: 10639760 | N222: Wed, 17 Jun 2026 00:00:00 GMT | O222: =I222/L222-1 -> -0.005988024
A223: 689.75 | B223: 694.57 | C223: 689.44 | D223: 693.83 | E223: 13283627 | F223: Tue, 16 Jun 2026 00:00:00 GMT | G223: =A223/D223-1 -> -0.005880403 | I223: 28.21 | J223: 31.25 | K223: 27.0442 | L223: 30.02 | M223: 23141671 | N223: Tue, 16 Jun 2026 00:00:00 GMT | O223: =I223/L223-1 -> -0.060293138
A224: 693.83 | B224: 695.75 | C224: 691.26 | D224: 691.3 | E224: 14017150 | F224: Mon, 15 Jun 2026 00:00:00 GMT | G224: =A224/D224-1 -> 0.0036597714 | I224: 30.58 | J224: 32.14 | K224: 30.11 | L224: 32.08 | M224: 14745534 | N224: Mon, 15 Jun 2026 00:00:00 GMT | O224: =I224/L224-1 -> -0.046758105
A225: 681.95 | B225: 684.4387 | C225: 675.81 | D225: 681.075 | E225: 6296298.6 | F225: Fri, 12 Jun 2026 00:00:00 GMT | G225: =A225/D225-1 -> 0.0012847337 | I225: 31.15 | J225: 34.15 | K225: 29.77 | L225: 33.89 | M225: 19504823 | N225: Fri, 12 Jun 2026 00:00:00 GMT | O225: =I225/L225-1 -> -0.080849808
A226: 678.23 | B226: 680.38 | C226: 666 | D226: 670.1 | E226: 19868903 | F226: Thu, 11 Jun 2026 00:00:00 GMT | G226: =A226/D226-1 -> 0.012132518 | I226: 34.17 | J226: 34.32 | K226: 30.42 | L226: 31.5 | M226: 15976294 | N226: Thu, 11 Jun 2026 00:00:00 GMT | O226: =I226/L226-1 -> 0.084761905
A227: 667.05 | B227: 678.875 | C227: 666.88 | D227: 674.315 | E227: 16308606 | F227: Wed, 10 Jun 2026 00:00:00 GMT | G227: =A227/D227-1 -> -0.010773896 | I227: 30.72 | J227: 31.8 | K227: 30.2 | L227: 30.89 | M227: 11044013 | N227: Wed, 10 Jun 2026 00:00:00 GMT | O227: =I227/L227-1 -> -0.0055033992
A228: 677.7 | B228: 686.76 | C228: 664.3201 | D228: 683.71 | E228: 13784137 | F228: Tue, 09 Jun 2026 00:00:00 GMT | G228: =A228/D228-1 -> -0.0087902766 | I228: 31.17 | J228: 34.37 | K228: 29.32 | L228: 33.42 | M228: 22105339 | N228: Tue, 09 Jun 2026 00:00:00 GMT | O228: =I228/L228-1 -> -0.067324955
A229: 679.68 | B229: 685.29 | C229: 678.7 | D229: 683.47 | E229: 8744745.5 | F229: Mon, 08 Jun 2026 00:00:00 GMT | G229: =A229/D229-1 -> -0.0055452324 | I229: 32.74 | J229: 34.04 | K229: 31.33 | L229: 34.01 | M229: 20005204 | N229: Mon, 08 Jun 2026 00:00:00 GMT | O229: =I229/L229-1 -> -0.037341958
A230: 678 | B230: 692.18 | C230: 676.25 | D230: 691.71 | E230: 10689226 | F230: Fri, 05 Jun 2026 00:00:00 GMT | G230: =A230/D230-1 -> -0.019820445 | I230: 32.22 | J230: 39.18 | K230: 31.66 | L230: 38.3 | M230: 40356016 | N230: Fri, 05 Jun 2026 00:00:00 GMT | O230: =I230/L230-1 -> -0.15874674
...

Sheet Product Lines

Sheet Management

Sheet Table Formatting
B2: [Bold Title] | G2: [Bold Title]
B3: Line Titles | G3: <-- General
B4: Line Titles | G4: <-- Info
B5: Line Titles | G5: <-- General
B6: Line Titles | G6: <-- Info
B7: Line Titles | G7: <-- General
B8: Line Titles | G8: <-- Info
