Workbook

Sheet Main
B2: PLTR
B3: Price | C3: 129.3 | D3: 7/5/2026
B4: SO | C4: 2393.869 | D4: Q1'26
B5: MC | C5: =C3*C4 -> 309527.26
B6: Cash | C6: =2291.63+5734.782 -> 8026.412 | D6: Q1'26
B7: Debt | C7: 0 | D7: Q1'26
B8: EV | C8: =C5-C6+C7 -> 301500.85
B10: Palantir Technologies Inc. (PLTR)
B12: Founder(s): Peter Thiel, Alex Karp, Joe Lonsdale, Stephen Cohen, and Nathan Gettings | N12: Resources:
B13: Founded: 2003 | N13: SEC filings | Q13: https://www.sec.gov/edgar/browse/?CIK=310764&owner=exclude
B14: Headquarters: Denver, CO | F14: Registered Exchange: NASDAQ | N14: Company Homepage | Q14: https://www.palantir.com/
B15: Current CEO: Alexander Karp | F15: Address: 1200 17th Street, Floor 15 Denver, Colorado 80202 U.S. | O15: Company IR Page | R15: https://investors.palantir.com/
B16: Employees: 3,936 (Q4'24) | F16: Investor Relations Contact: | N16: Earnings Calls | Q16: https://seekingalpha.com/symbol/PLTR/earnings/transcripts
B17: Industry: Software | F17: Investors Relation Department | N17: Equity Analysis | Q17: https://stockanalysis.com/stocks/pltr/company/
B18: Sector: Technology | F18: Phone: | G18: (720) 358 3679 | I18: Email: | N18: MacroTrends | Q18: https://www.macrotrends.net/stocks/charts/PLTR/palantir-technologies/income-statement
B19: IPO: September 30, 2020 -- $21B valuation | N19: ROIC, WACC | Q19: https://www.gurufocus.com/term/wacc/PLTR
B20: Fiscal Year: [January - December] | N20: Godel Terminal | Q20: https://app.godelterminal.com/
A22: Company Overview:
B23: Palantir Technologies (PLTR) is a U.S.-based software company that builds data integration, analytics, and AI platforms for government and commercial customers, with a business model centered on long-duration software licenses plus implementation and support services
B24: The Company operates two main end-markets and four core platforms
C25: Government segment:
D26: Historically the foundation of the business, focused on U.S. and allied defense, intelligence, and civil agencies (DoD, IC, IRS, VA, CDC, NHS, etc.) … Revenue comes from multi‑year platform licenses, implementation projects, and follow‑on services
C28: Commercial segment:
D29: Enterprises in financial services, healthcare, energy, manufacturing, and industrials, where Palantir sells Foundry/AIP as an “operating system” for data and AI in production
D30: Commercial growth in the U.S. has become the company’s fastest-growing vector as large companies adopt Palantir for supply chain, production optimization, risk management, and AI agents
C31: Across both segments, the go‑to‑market model has shifted from heavy, hands‑on deployments to more standardized “software-first” rollouts, including AIP “bootcamps” that aim to convert pilots into platform-scale adoption
B32: Palantir’s products are positioned as full-stack “operating systems” rather than point tools:
C33: Gotham:
D34: Originally built for counterterrorism and intelligence, Gotham fuses sensitive, often classified data sources (signals, HUMINT, logistics, open source) into a unified operational picture used by defense and law-enforcement operators
E35: The platform supports link analysis, pattern detection, and mission planning from headquarters down to edge devices … not just a dashboard program
C36: Foundry:
D37: A commercial data operating system that ingests, models, and operationalizes data across an enterprise
E38: Foundry’s core is the Ontology—a semantic layer mapping real‑world entities (orders, assets, people, plants) and their relationships, acting as a “digital twin” of the organization that connects data to workflows and applications
E39: Tokenization of every real world asset … discrete tracking of everything
C40: Apollo:
D41: A continuous delivery and orchestration platform that deploys and manages Gotham, Foundry, and customer workloads across heterogeneous environments (public clouds, on‑prem, air‑gapped defense networks)
E42: Apollo is key to Palantir’s ability to support highly regulated, mission‑critical environments at scale
C43: AIP (Artificial Intelligence Platform):
D44: The latest layer, designed to bind LLMs and other AI models directly to the Ontology and operational systems so users can build AI agents that act on live data with fine-grained security and governance
E45: AIP is marketed as the way to move from AI “demos” to production use in both defense (targeting, logistics, battle management) and commercial settings (forecasting, automation, copilots)
...

Sheet Model
B1: [Use for Graphing] | C1: Q1 2020 | G1: Q1 2021 | K1: Q1 2022 | O1: Q1 2023 | S1: Q1 2024 | W1: Q1 2025 | AA1: Q1 2026
B2: Quarterly
B3: Revenues | C3: Q1 2020 | D3: Q2 2020 | E3: Q3 2020 | F3: Q4 2020 | G3: Q1 2021 | H3: Q2 2021 | I3: Q3 2021 | J3: Q4 2021 | K3: Q1 2022 | L3: Q2 2022 | M3: Q3 2022 | N3: Q4 2022 | O3: Q1 2023 | P3: Q2 2023 | Q3: Q3 2023 | R3: Q4 2023 | S3: Q1 2024 | T3: Q2 2024 | U3: Q3 2024 | V3: Q4 2024 | W3: Q1 2025 | X3: Q2 2025 | Y3: Q3 2025 | Z3: Q4 2025 | AA3: Q1 2026 | AB3: Q2 2026 | AC3: Q3 2026 | AD3: Q4 2026 | AI3: 2020 | AJ3: =AI3+1 -> 2021 | AK3: =AJ3+1 -> 2022 | AL3: =AK3+1 -> 2023 | AM3: =AL3+1 -> 2024 | AN3: =AM3+1 -> 2025 | AO3: =AN3+1 -> 2026 | AP3: =AO3+1 -> 2027 | AQ3: =AP3+1 -> 2028 | ... CV3: =CU3+1 -> 2085
B4: Government | C4: 118.12 | D4: 139.569 | E4: 162.561 | F4: =610.198-SUM(C4:E4) -> 189.948 | G4: 208.42 | H4: 232.119 | I4: 217.83 | J4: =897.35-SUM(G4:I4) -> 238.981 | K4: 241.79 | L4: 262.998 | M4: 273.83 | N4: =1071.776-SUM(K4:M4) -> 293.158 | O4: 289.07 | P4: 301.505 | Q4: 307.603 | R4: =1222.215-SUM(O4:Q4) -> 324.037 | S4: 335.373 | T4: 370.76 | U4: 408.341 | V4: =1569.6-SUM(S4:U4) -> 455.126 | W4: 486.96 | X4: 552.983 | Y4: 632.766 | Z4: 729 | AA4: 858.41 | AI4: =SUM(C4:F4) -> 610.198 | AJ4: =SUM(G4:J4) -> 897.35 | AK4: =SUM(K4:N4) -> 1071.776 | AL4: =SUM(O4:R4) -> 1222.215 | AM4: =SUM(S4:V4) -> 1569.6 | AN4: =SUM(W4:Z4) -> 2401.709 | AO4: =AN4*(1+AO8) -> 3938.8028 | AP4: =AO4*(1+AP8) -> 5553.7119 | AQ4: =AP4*(1+AQ8) -> 7608.5853 | AR4: =AQ4*(1+AR8) -> 9967.2467 | AS4: =AR4*(1+AS8) -> 12558.731 | AT4: =AS4*(1+AT8) -> 15572.826 | AU4: =AT4*(1+AU8) -> 18843.12 | AV4: =AU4*(1+AV8) -> 22046.45 | ... AX4: =AW4*(1+AX8) -> 24537.699
B5: Commercial | C5: 111.2 | D5: 112.32 | E5: 126.805 | F5: =482.47-SUM(C5:E5) -> 132.145 | G5: 132.81 | H5: 143.52 | I5: 174.31 | J5: =644.533-SUM(G5:I5) -> 193.893 | K5: 204.56 | L5: 210.01 | M5: 204.046 | N5: =834.095-SUM(K5:M5) -> 215.479 | O5: 236.116 | P5: 231.812 | Q5: 250.556 | R5: =1002.797-SUM(O5:Q5) -> 284.313 | S5: 298.96 | T5: 307.36 | U5: 317.17 | V5: =1295.9-SUM(S5:U5) -> 372.41 | W5: 396.89 | X5: 450.714 | Y5: 548 | Z5: 678 | AA5: 774.17 | AI5: =SUM(C5:F5) -> 482.47 | AJ5: =SUM(G5:J5) -> 644.533 | AK5: =SUM(K5:N5) -> 834.095 | AL5: =SUM(O5:R5) -> 1002.797 | AM5: =SUM(S5:V5) -> 1295.9 | AN5: =SUM(W5:Z5) -> 2073.604 | AO5: =AN5*(1+AO9) -> 3722.1192 | AP5: =AO5*(1+AP9) -> 5694.8423 | AQ5: =AP5*(1+AQ9) -> 7744.9856 | AR5: =AQ5*(1+AR9) -> 9758.6818 | AS5: =AR5*(1+AS9) -> 11710.418 | AT5: =AS5*(1+AT9) -> 13466.981 | AU5: =AT5*(1+AU9) -> 15352.358 | AV5: =AU5*(1+AV9) -> 17041.118 | ... AX5: =AW5*(1+AX9) -> 20060.804
B6: Ttl Revenues | C6: =SUM(C4:C5) -> 229.32 | D6: =SUM(D4:D5) -> 251.889 | E6: =SUM(E4:E5) -> 289.366 | F6: =SUM(F4:F5) -> 322.093 | G6: =SUM(G4:G5) -> 341.23 | H6: =SUM(H4:H5) -> 375.639 | I6: =SUM(I4:I5) -> 392.14 | J6: =SUM(J4:J5) -> 432.874 | ... AA6: =SUM(AA4:AA5) -> 1632.58 | AI6: =SUM(C6:F6) -> 1092.668 | AJ6: =SUM(G6:J6) -> 1541.883 | AK6: =SUM(K6:N6) -> 1905.871 | AL6: =SUM(O6:R6) -> 2225.012 | AM6: =SUM(S6:V6) -> 2865.5 | AN6: =SUM(W6:Z6) -> 4475.313 | AO6: =SUM(AO4:AO5) -> 7660.9219 | AP6: =SUM(AP4:AP5) -> 11248.554 | AQ6: =SUM(AQ4:AQ5) -> 15353.571 | AR6: =SUM(AR4:AR5) -> 19725.929 | AS6: =SUM(AS4:AS5) -> 24269.149 | AT6: =SUM(AT4:AT5) -> 29039.807 | AU6: =SUM(AU4:AU5) -> 34195.478 | AV6: =SUM(AV4:AV5) -> 39087.568 | ... AX6: =SUM(AX4:AX5) -> 44598.503
B8: Government Growth Y/y | G8: =G4/C4-1 -> 0.7644768 | H8: =H4/D4-1 -> 0.66311287 | I8: =I4/E4-1 -> 0.3399893 | J8: =J4/F4-1 -> 0.25813907 | K8: =K4/G4-1 -> 0.16010939 | L8: =L4/H4-1 -> 0.1330309 | M8: =M4/I4-1 -> 0.25708121 | N8: =N4/J4-1 -> 0.22670003 | ... AA8: =AA4/W4-1 -> 0.76279366 | AJ8: =AJ4/AI4-1 -> 0.47058824 | AK8: =AK4/AJ4-1 -> 0.194379 | AL8: =AL4/AK4-1 -> 0.14036422 | AM8: =AM4/AL4-1 -> 0.28422577 | AN8: =AN4/AM4-1 -> 0.5301408 | AO8: 0.64 | AP8: 0.41 | AQ8: 0.37 | AR8: 0.31 | AS8: 0.26 | AT8: 0.24 | AU8: 0.21 | AV8: 0.17 | AW8: 0.06 | AX8: 0.05
B9: Commercial Growth Y/y | G9: =G5/C5-1 -> 0.19433453 | H9: =H5/D5-1 -> 0.27777778 | I9: =I5/E5-1 -> 0.37463034 | J9: =J5/F5-1 -> 0.46727458 | K9: =K5/G5-1 -> 0.54024546 | L9: =L5/H5-1 -> 0.46328038 | M9: =M5/I5-1 -> 0.17059262 | N9: =N5/J5-1 -> 0.11132944 | ... AA9: =AA5/W5-1 -> 0.95059084 | AJ9: =AJ5/AI5-1 -> 0.33590275 | AK9: =AK5/AJ5-1 -> 0.29410752 | AL9: =AL5/AK5-1 -> 0.20225754 | AM9: =AM5/AL5-1 -> 0.29228548 | AN9: =AN5/AM5-1 -> 0.60012655 | AO9: 0.795 | AP9: 0.53 | AQ9: 0.36 | AR9: 0.26 | AS9: 0.2 | AT9: 0.15 | AU9: 0.14 | AV9: 0.11 | AW9: 0.09 | AX9: 0.08
B10: Ttl Revenue Growth Y/y | G10: =G6/C6-1 -> 0.48800802 | H10: =H6/D6-1 -> 0.49128783 | I10: =I6/E6-1 -> 0.35516958 | J10: =J6/F6-1 -> 0.34394104 | K10: =K6/G6-1 -> 0.30806201 | L10: =L6/H6-1 -> 0.25920897 | M10: =M6/I6-1 -> 0.2186362 | N10: =N6/J6-1 -> 0.17502322 | ... AA10: =AA6/W6-1 -> 0.84712338 | AJ10: =AJ6/AI6-1 -> 0.41111756 | AK10: =AK6/AJ6-1 -> 0.2360672 | AL10: =AL6/AK6-1 -> 0.16745152 | AM10: =AM6/AL6-1 -> 0.28785822 | AN10: =AN6/AM6-1 -> 0.56179131 | AO10: =AO6/AN6-1 -> 0.71181813 | AP10: =AP6/AO6-1 -> 0.46830294 | AQ10: =AQ6/AP6-1 -> 0.36493727 | ... AX10: =AX6/AW6-1 -> 0.063285424
B12: Government % of Ttl Revenues | C12: =C4/C6 -> 0.51508809 | D12: =D4/D6 -> 0.5540893 | E12: =E4/E6 -> 0.56178335 | F12: =F4/F6 -> 0.5897303 | G12: =G4/G6 -> 0.61079038 | H12: =H4/H6 -> 0.61793105 | I12: =I4/I6 -> 0.55549039 | J12: =J4/J6 -> 0.55207982 | ... AA12: =AA4/AA6 -> 0.52579965 | AI12: =AI4/AI6 -> 0.55844776 | AJ12: =AJ4/AJ6 -> 0.5819832 | AK12: =AK4/AK6 -> 0.56235495 | AL12: =AL4/AL6 -> 0.54930715 | AM12: =AM4/AM6 -> 0.54775781 | AN12: =AN4/AN6 -> 0.53665721 | AO12: =AO4/AO6 -> 0.51414213 | AP12: =AP4/AP6 -> 0.49372673 | ... AX12: =AX4/AX6 -> 0.55019109
B13: Commercial % of Ttl Revenues | C13: =C5/C6 -> 0.48491191 | D13: =D5/D6 -> 0.4459107 | E13: =E5/E6 -> 0.43821665 | F13: =F5/F6 -> 0.4102697 | G13: =G5/G6 -> 0.38920962 | H13: =H5/H6 -> 0.38206895 | I13: =I5/I6 -> 0.44450961 | J13: =J5/J6 -> 0.44792018 | ... AA13: =AA5/AA6 -> 0.47420035 | AI13: =AI5/AI6 -> 0.44155224 | AJ13: =AJ5/AJ6 -> 0.4180168 | AK13: =AK5/AK6 -> 0.43764505 | AL13: =AL5/AL6 -> 0.45069285 | AM13: =AM5/AM6 -> 0.45224219 | AN13: =AN5/AN6 -> 0.46334279 | AO13: =AO5/AO6 -> 0.48585787 | AP13: =AP5/AP6 -> 0.50627327 | ... AX13: =AX5/AX6 -> 0.44980891
B15: U.S. Revenues | C15: 109.77 | D15: 124.993 | E15: 156.336 | F15: =573.549-SUM(C15:E15) -> 182.45 | G15: 198.447 | H15: 199.93 | I15: 227.28 | J15: =879.15-SUM(G15:I15) -> 253.493 | K15: 272.913 | L15: 290.223 | M15: 296.65 | N15: =1161.416-SUM(K15:M15) -> 301.63 | O15: 336.845 | P15: 328.01 | Q15: 345.479 | R15: =1378.247-SUM(O15:Q15) -> 367.913 | S15: 406.389 | T15: 437.189 | U15: 498.986 | V15: =1900.247-SUM(S15:U15) -> 557.683 | W15: 628.49 | X15: 732.59 | Y15: 882.571 | Z15: =3320-SUM(W15:Y15) -> 1076.349 | AA15: 1282.066 | AI15: =SUM(C15:F15) -> 573.549 | AJ15: =SUM(G15:J15) -> 879.15 | AK15: =SUM(K15:N15) -> 1161.416 | AL15: =SUM(O15:R15) -> 1378.247 | AM15: =SUM(S15:V15) -> 1900.247 | AN15: =SUM(W15:Z15) -> 3320
B16: U.K. Revenues | C16: 28.975 | D16: 30.033 | E16: 35.432 | F16: =132.427-SUM(C16:E16) -> 37.987 | G16: 34.385 | H16: 39.93 | I16: 47.91 | J16: =173.362-SUM(G16:I16) -> 51.137 | K16: 49.902 | L16: 52.14 | M16: 59.435 | N16: =220.94-SUM(K16:M16) -> 59.463 | O16: 49.579 | P16: 63.229 | Q16: 64.39 | R16: =235.257-SUM(O16:Q16) -> 58.059 | S16: 63.2 | T16: 76.99 | U16: 69.496 | V16: =304.575-SUM(S16:U16) -> 94.889 | W16: 89.65 | X16: 97.17 | Y16: 114.71 | Z16: =427.398-SUM(W16:Y16) -> 125.868 | AA16: 130.091 | AI16: =SUM(C16:F16) -> 132.427 | AJ16: =SUM(G16:J16) -> 173.362 | AK16: =SUM(K16:N16) -> 220.94 | AL16: =SUM(O16:R16) -> 235.257 | AM16: =SUM(S16:V16) -> 304.575 | AN16: =SUM(W16:Z16) -> 427.398
B17: Rest of World Revenues | C17: =25.73+64.845 -> 90.575 | D17: =29.629+67.234 -> 96.863 | E17: 97.59 | F17: =386.697-SUM(C17:E17) -> 101.669 | G17: =21.09+87.31 -> 108.4 | H17: =19.088+116.68 -> 135.768 | I17: 116.94 | J17: =489.37-SUM(G17:I17) -> 128.262 | K17: 123.54 | L17: 130.647 | M17: 121.795 | N17: =523.513-SUM(K17:M17) -> 147.531 | O17: 138.762 | P17: 142.076 | Q17: 148.29 | R17: =611.508-SUM(O17:Q17) -> 182.38 | S17: 164.748 | T17: 163.95 | U17: 157.03 | V17: =660.685-SUM(S17:U17) -> 174.957 | W17: 165.7 | X17: 173.933 | Y17: 183.8 | Z17: =728-SUM(W17:Y17) -> 204.567 | AA17: 220.426 | AI17: =SUM(C17:F17) -> 386.697 | AJ17: =SUM(G17:J17) -> 489.37 | AK17: =SUM(K17:N17) -> 523.513 | AL17: =SUM(O17:R17) -> 611.508 | AM17: =SUM(S17:V17) -> 660.685 | AN17: =SUM(W17:Z17) -> 728
B18: Ttl Revenues | C18: =SUM(C15:C17) -> 229.32 | D18: =SUM(D15:D17) -> 251.889 | E18: =SUM(E15:E17) -> 289.358 | F18: =SUM(F15:F17) -> 322.106 | G18: =SUM(G15:G17) -> 341.232 | H18: =SUM(H15:H17) -> 375.628 | I18: =SUM(I15:I17) -> 392.13 | J18: =SUM(J15:J17) -> 432.892 | ... AA18: =SUM(AA15:AA17) -> 1632.583 | AI18: =SUM(C18:F18) -> 1092.673 | AJ18: =SUM(G18:J18) -> 1541.882 | AK18: =SUM(K18:N18) -> 1905.869 | AL18: =SUM(O18:R18) -> 2225.012 | AM18: =SUM(S18:V18) -> 2865.507 | AN18: =SUM(W18:Z18) -> 4475.398
B20: U.S. Revenue Growth Y/y | G20: =G15/C15-1 -> 0.80784367 | H20: =H15/D15-1 -> 0.59952957 | I20: =I15/E15-1 -> 0.45379183 | J20: =J15/F15-1 -> 0.38938339 | K20: =K15/G15-1 -> 0.37524377 | L20: =L15/H15-1 -> 0.45162307 | M20: =M15/I15-1 -> 0.30521823 | N20: =N15/J15-1 -> 0.18989479 | ... AA20: =AA15/W15-1 -> 1.0399147 | AJ20: =AJ15/AI15-1 -> 0.53282457 | AK20: =AK15/AJ15-1 -> 0.32106694 | AL20: =AL15/AK15-1 -> 0.18669538 | AM20: =AM15/AL15-1 -> 0.37874198 | AN20: =AN15/AM15-1 -> 0.74714129
B21: U.K. Revenue Growth Y/y | G21: =G16/C16-1 -> 0.18671268 | H21: =H16/D16-1 -> 0.32953751 | I21: =I16/E16-1 -> 0.35216753 | J21: =J16/F16-1 -> 0.34617106 | K21: =K16/G16-1 -> 0.45127236 | L21: =L16/H16-1 -> 0.30578512 | M21: =M16/I16-1 -> 0.24055521 | N21: =N16/J16-1 -> 0.16281753 | ... AA21: =AA16/W16-1 -> 0.45109872 | AJ21: =AJ16/AI16-1 -> 0.3091137 | AK21: =AK16/AJ16-1 -> 0.27444307 | AL21: =AL16/AK16-1 -> 0.064800398 | AM21: =AM16/AL16-1 -> 0.29464798 | AN21: =AN16/AM16-1 -> 0.40326028
B22: Rest of World Revenue Growth Y/y | G22: =G17/C17-1 -> 0.19679823 | H22: =H17/D17-1 -> 0.40164975 | I22: =I17/E17-1 -> 0.19827851 | J22: =J17/F17-1 -> 0.26156449 | K22: =K17/G17-1 -> 0.1396679 | L22: =L17/H17-1 -> -0.037718756 | M22: =M17/I17-1 -> 0.041517017 | N22: =N17/J17-1 -> 0.15023156 | ... AA22: =AA17/W17-1 -> 0.33027158 | AJ22: =AJ17/AI17-1 -> 0.26551279 | AK22: =AK17/AJ17-1 -> 0.069769295 | AL22: =AL17/AK17-1 -> 0.16808561 | AM22: =AM17/AL17-1 -> 0.080419226 | AN22: =AN17/AM17-1 -> 0.10188668
B23: Ttl Revenue Growth Y/y | G23: =G18/C18-1 -> 0.48801675 | H23: =H18/D18-1 -> 0.49124416 | I23: =I18/E18-1 -> 0.35517249 | J23: =J18/F18-1 -> 0.34394268 | K23: =K18/G18-1 -> 0.308069 | L23: =L18/H18-1 -> 0.25925117 | M23: =M18/I18-1 -> 0.21867748 | N23: =N18/J18-1 -> 0.17494433 | ... AA23: =AA18/W18-1 -> 0.84714767 | AJ23: =AJ18/AI18-1 -> 0.41111019 | AK23: =AK18/AJ18-1 -> 0.2360667 | AL23: =AL18/AK18-1 -> 0.16745275 | AM23: =AM18/AL18-1 -> 0.28786137 | AN23: =AN18/AM18-1 -> 0.56181716
B25: U.S. % of Revenues | C25: =C15/C18 -> 0.47867609 | D25: =D15/D18 -> 0.49622254 | E25: =E15/E18 -> 0.54028574 | F25: =F15/F18 -> 0.56642844 | G25: =G15/G18 -> 0.58156035 | H25: =H15/H18 -> 0.53225532 | I25: =I15/I18 -> 0.5796037 | J25: =J15/J18 -> 0.58558024 | ... AA25: =AA15/AA18 -> 0.78529912 | AI25: =AI15/AI18 -> 0.52490452 | AJ25: =AJ15/AJ18 -> 0.57017982 | AK25: =AK15/AK18 -> 0.60938921 | AL25: =AL15/AL18 -> 0.61943351 | AM25: =AM15/AM18 -> 0.66314513 | AN25: =AN15/AN18 -> 0.74183346
B26: U.K. % of Revenues | C26: =C16/C18 -> 0.12635182 | D26: =D16/D18 -> 0.11923109 | E26: =E16/E18 -> 0.12245039 | F26: =F16/F18 -> 0.11793323 | G26: =G16/G18 -> 0.10076722 | H26: =H16/H18 -> 0.10630198 | I26: =I16/I18 -> 0.12217887 | J26: =J16/J18 -> 0.11812877 | ... AA26: =AA16/AA18 -> 0.079684157 | AI26: =AI16/AI18 -> 0.12119545 | AJ26: =AJ16/AJ18 -> 0.11243532 | AK26: =AK16/AK18 -> 0.11592612 | AL26: =AL16/AL18 -> 0.10573291 | AM26: =AM16/AM18 -> 0.10629009 | AN26: =AN16/AN18 -> 0.095499439
B27: Rest of World % of Revenues | C27: =C17/C18 -> 0.39497209 | D27: =D17/D18 -> 0.38454637 | E27: =E17/E18 -> 0.33726387 | F27: =F17/F18 -> 0.31563833 | G27: =G17/G18 -> 0.31767243 | H27: =H17/H18 -> 0.3614427 | I27: =I17/I18 -> 0.29821743 | J27: =J17/J18 -> 0.29629099 | ... AA27: =AA17/AA18 -> 0.13501672 | AI27: =AI17/AI18 -> 0.35390002 | AJ27: =AJ17/AJ18 -> 0.31738486 | AK27: =AK17/AK18 -> 0.27468467 | AL27: =AL17/AL18 -> 0.27483357 | AM27: =AM17/AM18 -> 0.23056478 | AN27: =AN17/AN18 -> 0.1626671
B29: Revenues | C29: =C6 -> 229.32 | D29: =D6 -> 251.889 | E29: =E6 -> 289.366 | F29: =F6 -> 322.093 | G29: =G6 -> 341.23 | H29: =H6 -> 375.639 | I29: =I6 -> 392.14 | J29: =J6 -> 432.874 | ... Y29: =Y6 -> 1180.766 | Z29: =Z18 -> 1406.784 | AA29: =AA6 -> 1632.58 | AI29: =SUM(C29:F29) -> 1092.668 | AJ29: =SUM(G29:J29) -> 1541.883 | AK29: =SUM(K29:N29) -> 1905.871 | AL29: =SUM(O29:R29) -> 2225.012 | AM29: =SUM(S29:V29) -> 2865.5 | AN29: =SUM(W29:Z29) -> 4475.097 | AO29: =AO6 -> 7660.9219 | AP29: =AP6 -> 11248.554 | AQ29: =AQ6 -> 15353.571 | AR29: =AR6 -> 19725.929 | AS29: =AS6 -> 24269.149 | AT29: =AT6 -> 29039.807 | AU29: =AU6 -> 34195.478 | AV29: =AV6 -> 39087.568 | ... AX29: =AX6 -> 44598.503
B30: COGS | C30: 64.29 | D30: 68.41 | E30: 149.34 | F30: =352.54-SUM(C30:E30) -> 70.5 | G30: 74.111 | H30: 90.926 | I30: 86.804 | J30: =339.404-SUM(G30:I30) -> 87.563 | K30: 94.403 | L30: 102.224 | M30: 107.611 | N30: =408.54-SUM(K30:M30) -> 104.302 | O30: 107.645 | P30: 106.899 | Q30: 107.922 | R30: =431.1-SUM(O30:Q30) -> 108.634 | S30: 116.256 | T30: 128.56 | U30: 146.639 | V30: =565.99-SUM(S30:U30) -> 174.535 | W30: 172.97 | X30: 192.93 | Y30: 207.307 | Z30: 215.96 | AA30: 215.798 | AI30: =SUM(C30:F30) -> 352.54 | AJ30: =SUM(G30:J30) -> 339.404 | AK30: =SUM(K30:N30) -> 408.54 | AL30: =SUM(O30:R30) -> 431.1 | AM30: =SUM(S30:V30) -> 565.99 | AN30: =SUM(W30:Z30) -> 789.167 | AO30: =AO29*(1-AO44) -> 1126.1555 | AP30: =AP29*(1-AP44) -> 1631.0404 | AQ30: =AQ29*(1-AQ44) -> 2195.5606 | AR30: =AR29*(1-AR44) -> 2781.3559 | AS30: =AS29*(1-AS44) -> 3397.6809 | AT30: =AT29*(1-AT44) -> 4036.5332 | AU30: =AU29*(1-AU44) -> 4718.976 | AV30: =AV29*(1-AV44) -> 5354.9968 | ... AX30: =AX29*(1-AX44) -> 6020.7979
B31: GP | C31: =C29-C30 -> 165.03 | D31: =D29-D30 -> 183.479 | E31: =E29-E30 -> 140.026 | F31: =F29-F30 -> 251.593 | G31: =G29-G30 -> 267.119 | H31: =H29-H30 -> 284.713 | I31: =I29-I30 -> 305.336 | J31: =J29-J30 -> 345.311 | ... AA31: =AA29-AA30 -> 1416.782 | AI31: =SUM(C31:F31) -> 740.128 | AJ31: =SUM(G31:J31) -> 1202.479 | AK31: =SUM(K31:N31) -> 1497.331 | AL31: =SUM(O31:R31) -> 1793.912 | AM31: =SUM(S31:V31) -> 2299.51 | AN31: =SUM(W31:Z31) -> 3685.93 | AO31: =AO29-AO30 -> 6534.7664 | AP31: =AP29-AP30 -> 9617.5139 | AQ31: =AQ29-AQ30 -> 13158.01 | AR31: =AR29-AR30 -> 16944.573 | AS31: =AS29-AS30 -> 20871.468 | AT31: =AT29-AT30 -> 25003.274 | AU31: =AU29-AU30 -> 29476.502 | AV31: =AV29-AV30 -> 33732.571 | ... AX31: =AX29-AX30 -> 38577.705
B32: Sales & Marketing | C32: 98.65 | D32: 102.518 | E32: 334.911 | F32: =683.701-SUM(C32:E32) -> 147.622 | G32: 136.09 | H32: 162.37 | I32: 153.44 | J32: =614.512-SUM(G32:I32) -> 162.612 | K32: 160.48 | L32: 168.875 | M32: 182.918 | N32: =702.511-SUM(K32:M32) -> 190.238 | O32: 187.093 | P32: 184.163 | Q32: 176.373 | R32: =744.992-SUM(O32:Q32) -> 197.363 | S32: 193.177 | T32: 196.809 | U32: 209.474 | V32: =887.755-SUM(S32:U32) -> 288.295 | W32: 236.309 | X32: 243.788 | Y32: 274.63 | Z32: 302.12 | AA32: 319.22 | AI32: =SUM(C32:F32) -> 683.701 | AJ32: =SUM(G32:J32) -> 614.512 | AK32: =SUM(K32:N32) -> 702.511 | AL32: =SUM(O32:R32) -> 744.992 | AM32: =SUM(S32:V32) -> 887.755 | AN32: =SUM(W32:Z32) -> 1056.847 | AO32: =AO29*AO45 -> 1608.7936 | AP32: =AP29*AP45 -> 2305.9536 | AQ32: =AQ29*AQ45 -> 2993.9463 | AR32: =AR29*AR45 -> 3747.9264 | AS32: =AS29*AS45 -> 4550.4655 | AT32: =AT29*AT45 -> 5372.3643 | AU32: =AU29*AU45 -> 6240.6748 | AV32: =AV29*AV45 -> 7035.7622 | ... AX32: =AX29*AX45 -> 8027.7305
B33: R&D | C33: 65.8 | D33: 86.8 | E33: 313.915 | F33: =560.66-SUM(C33:E33) -> 94.145 | G33: 98.47 | H33: 110.52 | I33: 94.316 | J33: =387.487-SUM(G33:I33) -> 84.181 | K33: 88.601 | L33: 88.171 | M33: 100.863 | N33: =359.67-SUM(K33:M33) -> 82.035 | O33: 90.1 | P33: 99.533 | Q33: 105.708 | R33: =404.62-SUM(O33:Q33) -> 109.279 | S33: 110.04 | T33: 108.78 | U33: 117.55 | V33: =507.878-SUM(S33:U33) -> 171.508 | W33: 134.889 | X33: 135.04 | Y33: 144.191 | Z33: 143.55 | AA33: 160.981 | AI33: =SUM(C33:F33) -> 560.66 | AJ33: =SUM(G33:J33) -> 387.487 | AK33: =SUM(K33:N33) -> 359.67 | AL33: =SUM(O33:R33) -> 404.62 | AM33: =SUM(S33:V33) -> 507.878 | AN33: =SUM(W33:Z33) -> 557.67 | AO33: =AO29*AO46 -> 881.00602 | AP33: =AP29*AP46 -> 1237.341 | AQ33: =AQ29*AQ46 -> 1612.1249 | AR33: =AR29*AR46 -> 1972.5929 | AS33: =AS29*AS46 -> 2366.242 | AT33: =AT29*AT46 -> 2758.7817 | AU33: =AU29*AU46 -> 3180.1795 | AV33: =AV29*AV46 -> 3596.0562 | ... AX33: =AX29*AX46 -> 4013.8653
B34: G&A | C34: 70.76 | D34: 93.29 | E34: 338.977 | F34: =669.444-SUM(C34:E34) -> 166.417 | G34: 146.56 | H34: 157.96 | I34: 149.52 | J34: =611.532-SUM(G34:I34) -> 157.492 | K34: 142.307 | L34: 155.485 | M34: 148.67 | N34: =596.333-SUM(K34:M34) -> 149.871 | O34: 136.233 | P34: 132.648 | Q34: 128.173 | R34: =524.32-SUM(O34:Q34) -> 127.266 | S34: 133.98 | T34: 138.64 | U34: 138.708 | V34: =593.48-SUM(S34:U34) -> 182.152 | W34: 163.639 | X34: 162.61 | Y34: 161.7 | Z34: 169.76 | AA34: 182.586 | AI34: =SUM(C34:F34) -> 669.444 | AJ34: =SUM(G34:J34) -> 611.532 | AK34: =SUM(K34:N34) -> 596.333 | AL34: =SUM(O34:R34) -> 524.32 | AM34: =SUM(S34:V34) -> 593.48 | AN34: =SUM(W34:Z34) -> 657.709 | AO34: =AO29*AO47 -> 919.31063 | AP34: =AP29*AP47 -> 1293.5837 | AQ34: =AQ29*AQ47 -> 1727.2767 | AR34: =AR29*AR47 -> 2169.8521 | AS34: =AS29*AS47 -> 2608.9335 | AT34: =AT29*AT47 -> 3049.1798 | AU34: =AU29*AU47 -> 3505.0365 | AV34: =AV29*AV47 -> 3908.7568 | ... AX34: =AX29*AX47 -> 4348.354
B35: OI | C35: =C31-SUM(C32:C34) -> -70.18 | D35: =D31-SUM(D32:D34) -> -99.129 | E35: =E31-SUM(E32:E34) -> -847.777 | F35: =F31-SUM(F32:F34) -> -156.591 | G35: =G31-SUM(G32:G34) -> -114.001 | H35: =H31-SUM(H32:H34) -> -146.137 | I35: =I31-SUM(I32:I34) -> -91.94 | J35: =J31-SUM(J32:J34) -> -58.974 | ... AA35: =AA31-SUM(AA32:AA34) -> 753.995 | AI35: =SUM(C35:F35) -> -1173.677 | AJ35: =SUM(G35:J35) -> -411.052 | AK35: =SUM(K35:N35) -> -161.183 | AL35: =SUM(O35:R35) -> 119.98 | AM35: =SUM(S35:V35) -> 310.397 | AN35: =SUM(W35:Z35) -> 1413.704 | AO35: =AO31-SUM(AO32:AO34) -> 3125.6562 | AP35: =AP31-SUM(AP32:AP34) -> 4780.6356 | AQ35: =AQ31-SUM(AQ32:AQ34) -> 6824.6623 | AR35: =AR31-SUM(AR32:AR34) -> 9054.2012 | AS35: =AS31-SUM(AS32:AS34) -> 11345.827 | AT35: =AT31-SUM(AT32:AT34) -> 13822.948 | AU35: =AU31-SUM(AU32:AU34) -> 16550.611 | AV35: =AV31-SUM(AV32:AV34) -> 19191.996 | ... AX35: =AX31-SUM(AX32:AX34) -> 22187.755
B36: Interest Income | C36: 3.267 | D36: 0.551 | E36: 0.494 | F36: =4.68-SUM(C36:E36) -> 0.368 | G36: 0.376 | H36: 0.372 | I36: 0.379 | J36: =1.607-SUM(G36:I36) -> 0.48 | K36: 0.547 | L36: 1.472 | M36: 5.54 | N36: =20.309-SUM(K36:M36) -> 12.75 | O36: 20.85 | P36: 30.31 | Q36: 36.86 | R36: =132.572-SUM(O36:Q36) -> 44.552 | S36: 43.352 | T36: 46.593 | U36: 52.12 | V36: =196.792-SUM(S36:U36) -> 54.727 | W36: 50.44 | X36: 56.255 | Y36: 59.762 | Z36: 62.72 | AA36: 66.394 | AI36: =SUM(C36:F36) -> 4.68 | AJ36: =SUM(G36:J36) -> 1.607 | AK36: =SUM(K36:N36) -> 20.309 | AL36: =SUM(O36:R36) -> 132.572 | AM36: =SUM(S36:V36) -> 196.792 | AN36: =SUM(W36:Z36) -> 229.177 | AO36: =SUM(AM52:AM53)*($AX$55) -> 2235.8164 | AP36: =SUM(AO52:AO53)*($AX$55) -> 3032.601 | AQ36: =SUM(AP52:AP53)*($AX$55) -> 6114.3906 | AR36: =SUM(AQ52:AQ53)*($AX$55) -> 11195.115 | AS36: =SUM(AR52:AR53)*($AX$55) -> 19150.555 | AT36: =SUM(AS52:AS53)*($AX$55) -> 31135.736 | AU36: =SUM(AT52:AT53)*($AX$55) -> 48808.487 | AV36: =SUM(AU52:AU53)*($AX$55) -> 74504.247 | AW36: =SUM(AV52:AV53)*($AX$55) -> 111344.51 | AX36: =SUM(AW52:AW53)*($AX$55) -> 163299.37
B37: Other Income | C37: =-4.59+13.69+6.1 -> 15.2 | D37: =-5.646-3.683-1.589 -> -10.918 | E37: =-2.08-9.2-3.29 -> -14.57 | F37: =-14.139+4.11-SUM(C37:E37) -> 0.259 | G37: =-1.84-4.89 -> -6.73 | H37: =-0.59+2.12 -> 1.53 | I37: =-0.609-8.528 -> -9.137 | J37: =-3.64-75.415-SUM(G37:I37) -> -64.718 | K37: =-0.594-59.87 -> -60.464 | L37: =-0.67-135.798 -> -136.468 | M37: =-1.08-65.046 -> -66.126 | N37: =-4.058-216.077-SUM(K37:M37) -> 42.923 | O37: =-1.27-2.86 -> -4.13 | P37: =-1.31-9.02 -> -10.33 | Q37: =-0.742+3.864 -> 3.122 | R37: =-15.447-SUM(O37:Q37) -> -4.109 | S37: -13.507 | T37: -11.17 | U37: -8.11 | V37: =-18.0222-SUM(S37:U37) -> 14.7648 | W37: -3.17 | X37: 6.596 | Y37: 27.483 | Z37: -16.73 | AA37: 68.209 | AI37: =SUM(C37:F37) -> -10.029 | AJ37: =SUM(G37:J37) -> -79.055 | AK37: =SUM(K37:N37) -> -220.135 | AL37: =SUM(O37:R37) -> -15.447 | AM37: =SUM(S37:V37) -> -18.0222 | AN37: =SUM(W37:Z37) -> 14.179 | AO37: =AM37*1.05 -> -18.92331 | AP37: =AO37*1.05 -> -19.869476 | AQ37: =AP37*1.05 -> -20.862949 | AR37: =AQ37*1.05 -> -21.906097 | AS37: =AR37*1.05 -> -23.001402 | AT37: =AS37*1.05 -> -24.151472 | AU37: =AT37*1.05 -> -25.359045 | AV37: =AU37*1.05 -> -26.626997 | AW37: =AV37*1.05 -> -27.958347 | AX37: =AW37*1.05 -> -29.356265
B38: Pretax Income | C38: =C35+SUM(C36:C37) -> -51.713 | D38: =D35+SUM(D36:D37) -> -109.496 | E38: =E35+SUM(E36:E37) -> -861.853 | F38: =F35+SUM(F36:F37) -> -155.964 | G38: =G35+SUM(G36:G37) -> -120.355 | H38: =H35+SUM(H36:H37) -> -144.235 | I38: =I35+SUM(I36:I37) -> -100.698 | J38: =J35+SUM(J36:J37) -> -123.212 | ... AA38: =AA35+SUM(AA36:AA37) -> 888.598 | AI38: =SUM(C38:F38) -> -1179.026 | AJ38: =SUM(G38:J38) -> -488.5 | AK38: =SUM(K38:N38) -> -361.009 | AL38: =SUM(O38:R38) -> 237.105 | AM38: =SUM(S38:V38) -> 489.1668 | AN38: =SUM(W38:Z38) -> 1657.06 | AO38: =AO35+SUM(AO36:AO37) -> 5342.5493 | AP38: =AP35+SUM(AP36:AP37) -> 7793.3671 | AQ38: =AQ35+SUM(AQ36:AQ37) -> 12918.19 | AR38: =AR35+SUM(AR36:AR37) -> 20227.41 | AS38: =AS35+SUM(AS36:AS37) -> 30473.381 | AT38: =AT35+SUM(AT36:AT37) -> 44934.533 | AU38: =AU35+SUM(AU36:AU37) -> 65333.74 | AV38: =AV35+SUM(AV36:AV37) -> 93669.616 | ... AX38: =AX35+SUM(AX36:AX37) -> 185457.77
B39: Taxes | C39: 2.55 | D39: 0.943 | E39: -8.543 | F39: =-12.633-SUM(C39:E39) -> -7.583 | G39: 3.102 | H39: -5.66 | I39: 1.438 | J39: =31.885-SUM(G39:I39) -> 33.005 | K39: 2.023 | L39: 2.588 | M39: 1.09 | N39: =10.067-SUM(K39:M39) -> 4.366 | O39: 1.68 | P39: 2.171 | Q39: 6.53 | R39: =19.716-SUM(O39:Q39) -> 9.335 | S39: 4.65 | T39: 5.189 | U39: 7.809 | V39: =21.255-SUM(S39:U39) -> 3.607 | W39: 5.599 | X39: 3.596 | Y39: 3.753 | Z39: 9.776 | AA39: 12.199 | AI39: =SUM(C39:F39) -> -12.633 | AJ39: =SUM(G39:J39) -> 31.885 | AK39: =SUM(K39:N39) -> 10.067 | AL39: =SUM(O39:R39) -> 19.716 | AM39: =SUM(S39:V39) -> 21.255 | AN39: =SUM(W39:Z39) -> 22.724 | AO39: =AO38*AO49 -> 347.2657 | AP39: =AP38*AP49 -> 584.50253 | AQ39: =AQ38*AQ49 -> 1033.4552 | AR39: =AR38*AR49 -> 1618.1928 | AS39: =AS38*AS49 -> 2437.8705 | AT39: =AT38*AT49 -> 3594.7626 | AU39: =AU38*AU49 -> 5226.6992 | AV39: =AV38*AV49 -> 7493.5693 | ... AX39: =AX38*AX49 -> 14836.621
B40: NI | C40: =C38-C39 -> -54.263 | D40: =D38-D39 -> -110.439 | E40: =E38-E39 -> -853.31 | F40: =F38-F39 -> -148.381 | G40: =G38-G39 -> -123.457 | H40: =H38-H39 -> -138.575 | I40: =I38-I39 -> -102.136 | J40: =J38-J39 -> -156.217 | ... M40: =M38-M39 -> -123.862 | N40: =N38-N39-2.611 -> 30.887 | O40: =O38-O39-2.349 -> 16.806 | P40: =P38-P39 -> 27.883 | Q40: =Q38-Q39-1.9 -> 71.535 | R40: =R38-R39-1.85 -> 95.066 | S40: =S38-S39-0.54 -> 105.535 | T40: =T38-T39-1.44 -> 134.125 | U40: =U38-U39 -> 149.341 | V40: =V38-V39-3.5 -> 73.4308 | W40: =W38-W39-3.686 -> 214.028 | X40: =X38-X39-1.845 -> 326.739 | Y40: =Y38-Y39 -> 476.43 | Z40: =Z38-Z39 -> 611.608 | AA40: =AA38-AA39-5.875 -> 870.524 | AI40: =SUM(C40:F40) -> -1166.393 | AJ40: =SUM(G40:J40) -> -520.385 | AK40: =SUM(K40:N40) -> -373.687 | AL40: =SUM(O40:R40) -> 211.29 | AM40: =SUM(S40:V40) -> 462.4318 | AN40: =SUM(W40:Z40) -> 1628.805 | AO40: =AO38-AO39 -> 4995.2836 | AP40: =AP38-AP39 -> 7208.8646 | AQ40: =AQ38-AQ39 -> 11884.735 | AR40: =AR38-AR39 -> 18609.217 | AS40: =AS38-AS39 -> 28035.51 | AT40: =AT38-AT39 -> 41339.77 | AU40: =AU38-AU39 -> 60107.041 | AV40: =AV38-AV39 -> 86176.047 | ... AX40: =AX38-AX39 -> 170621.15 | AY40: =AX40*(1+$AX$56) -> 174886.68 | AZ40: =AY40*(1+$AX$56) -> 179258.84 | BA40: =AZ40*(1+$AX$56) -> 183740.31 | BB40: =BA40*(1+$AX$56) -> 188333.82 | BC40: =BB40*(1+$AX$56) -> 193042.17 | BD40: =BC40*(1+$AX$56) -> 197868.22 | BE40: =BD40*(1+$AX$56) -> 202814.93 | BF40: =BE40*(1+$AX$56) -> 207885.3 | ... CV40: =CU40*(1+$AX$56) -> 586443.43
B41: SC | C41: 591.85 | D41: 640.45 | E41: 905.462 | F41: 1792 | G41: 1861 | H41: 1937 | I41: 1991 | J41: 2027 | K41: 2046 | L41: 2063 | M41: 2080 | N41: 2099 | O41: 2118 | P41: 2150 | Q41: 2175 | R41: 2200 | S41: 2227 | T41: 2238 | U41: 2270 | V41: 2339 | W41: 2360 | X41: 2372 | Y41: 2383 | Z41: 2369 | AA41: 2393 | AI41: =AVERAGE(C41:F41) -> 982.4405 | AJ41: =AVERAGE(G41:J41) -> 1954 | AK41: =AVERAGE(K41:N41) -> 2072 | AL41: =AVERAGE(O41:R41) -> 2160.75 | AM41: =AVERAGE(S41:V41) -> 2268.5 | AN41: =AVERAGE(W41:Z41) -> 2371
B42: EPS | C42: =C40/C41 -> -0.091683704 | D42: =D40/D41 -> -0.17243969 | E42: =E40/E41 -> -0.94240288 | F42: =F40/F41 -> -0.082801897 | G42: =G40/G41 -> -0.066339065 | H42: =H40/H41 -> -0.071541043 | I42: =I40/I41 -> -0.051298845 | J42: =J40/J41 -> -0.077068081 | ... AA42: =AA40/AA41 -> 0.36377936 | AI42: =SUM(C42:F42) -> -1.2893282 | AJ42: =SUM(G42:J42) -> -0.26624703 | AK42: =SUM(K42:N42) -> -0.18131206 | AL42: =SUM(O42:R42) -> 0.097005155 | AM42: =SUM(S42:V42) -> 0.20450269 | AN42: =SUM(W42:Z42) -> 0.68653819
B44: Gross Profit Margin | C44: =C31/C29 -> 0.7196494 | D44: =D31/D29 -> 0.72841212 | E44: =E31/E29 -> 0.48390619 | F44: =F31/F29 -> 0.78111912 | G44: =G31/G29 -> 0.78281218 | H44: =H31/H29 -> 0.75794313 | I44: =I31/I29 -> 0.77864028 | J44: =J31/J29 -> 0.79771712 | ... AA44: =AA31/AA29 -> 0.86781781 | AI44: =AI31/AI29 -> 0.67735854 | AJ44: =AJ31/AJ29 -> 0.77987694 | AK44: =AK31/AK29 -> 0.78564132 | AL44: =AL31/AL29 -> 0.80624824 | AM44: =AM31/AM29 -> 0.80248124 | AN44: =AN31/AN29 -> 0.82365365 | AO44: 0.853 | AP44: 0.855 | AQ44: 0.857 | AR44: 0.859 | AS44: 0.86 | AT44: 0.861 | AU44: 0.862 | AV44: 0.863 | AW44: 0.864 | AX44: 0.865
B45: Sales & Marketing as % of Revenue | C45: =C32/C29 -> 0.43018489 | D45: =D32/D29 -> 0.40699673 | E45: =E32/E29 -> 1.1573958 | F45: =F32/F29 -> 0.45832104 | G45: =G32/G29 -> 0.39882191 | H45: =H32/H29 -> 0.43225011 | I45: =I32/I29 -> 0.39128883 | J45: =J32/J29 -> 0.37565666 | ... AA45: =AA32/AA29 -> 0.195531 | AI45: =AI32/AI29 -> 0.62571705 | AJ45: =AJ32/AJ29 -> 0.39854645 | AK45: =AK32/AK29 -> 0.36860365 | AL45: =AL32/AL29 -> 0.33482606 | AM45: =AM32/AM29 -> 0.30980806 | AN45: =AN32/AN29 -> 0.23616181 | AO45: 0.21 | AP45: 0.205 | AQ45: 0.195 | AR45: 0.19 | AS45: 0.1875 | AT45: 0.185 | AU45: 0.1825 | AV45: 0.18 | AW45: 0.18 | AX45: 0.18
B46: R&D as % of Revenue | C46: =C33/C29 -> 0.28693529 | D46: =D33/D29 -> 0.34459623 | E46: =E33/E29 -> 1.0848372 | F46: =F33/F29 -> 0.29229136 | G46: =G33/G29 -> 0.28857369 | H46: =H33/H29 -> 0.29421865 | I46: =I33/I29 -> 0.24051614 | J46: =J33/J29 -> 0.19446998 | ... AA46: =AA33/AA29 -> 0.098605275 | AI46: =AI33/AI29 -> 0.51311103 | AJ46: =AJ33/AJ29 -> 0.25130765 | AK46: =AK33/AK29 -> 0.18871686 | AL46: =AL33/AL29 -> 0.1818507 | AM46: =AM33/AM29 -> 0.17723888 | AN46: =AN33/AN29 -> 0.12461629 | AO46: 0.115 | AP46: 0.11 | AQ46: 0.105 | AR46: 0.1 | AS46: 0.0975 | AT46: 0.095 | AU46: 0.093 | AV46: 0.092 | AW46: 0.091 | AX46: 0.09
B47: G&A as % of Revenue | C47: =(C34)/C29 -> 0.30856445 | D47: =(D34)/D29 -> 0.37036155 | E47: =(E34)/E29 -> 1.1714472 | F47: =(F34)/F29 -> 0.51667376 | G47: =(G34)/G29 -> 0.42950503 | H47: =(H34)/H29 -> 0.42051012 | I47: =(I34)/I29 -> 0.3812924 | J47: =(J34)/J29 -> 0.36382874 | ... AA47: =(AA34)/AA29 -> 0.11183893 | AI47: =(AI34)/AI29 -> 0.61266917 | AJ47: =(AJ34)/AJ29 -> 0.39661375 | AK47: =(AK34)/AK29 -> 0.31289264 | AL47: =(AL34)/AL29 -> 0.23564817 | AM47: =(AM34)/AM29 -> 0.2071122 | AN47: =(AN34)/AN29 -> 0.14697089 | AO47: 0.12 | AP47: 0.115 | AQ47: 0.1125 | AR47: 0.11 | AS47: 0.1075 | AT47: 0.105 | AU47: 0.1025 | AV47: 0.1 | AW47: 0.0975 | AX47: 0.0975
...

Sheet Notes | Quant Analysis
CJ1: 0
Q2: Employee Scope: | AM2: General Notes/Observations (Updated Q1'25)
AN3: The Santa Fe Institute (SFI) conducted its most foundational and celebrated work on complexity science from the mid-1980s through the late 1990s. [1, 2]
AN4: While Palantir CEO Alex Karp’s intellectual framework is deeply rooted in mid-20th-century European philosophy, the convergence of academic complexity theory, DARPA funding, and Silicon Valley data fusion created parallel but distinct paths toward modern predictive software.
AN5: 1. SFI’s Golden Age of Complexity (1984–1999)
AN6: SFI was founded in 1984 by a group of scientists (many from the nearby Los Alamos National Laboratory) who felt that traditional academic disciplines were too narrow to solve massive world problems. [3, 4, 5]
AN7: Its foundational breakthroughs peaked across two distinct waves:
AO8: The Economy as a Complex Adaptive System (1987–1990s): This legendary program—backed by Citicorp CEO John Reed and co-led by physicist Murray Gell-Mann and economist Kenneth Arrow—treated financial markets not as stable, predictable machines, but as living, evolving ecosystems. [6, 7]
AO9: The Dawn of Agent-Based Modeling: In the 1990s, SFI researchers developed Swarm, a software tool allowing researchers to simulate independent agents (like traders, citizens, or soldiers) following simple rules to observe how massive, chaotic, and unexpected group behaviors emerge at scale.
AN10: 2. The Intellectual Bridge: Karp’s Frankfurt School Epistemology
AN11: Alex Karp famously earned his doctorate in social theory at Goethe University Frankfurt under the mentorship of Jürgen Habermas, the preeminent custodian of the "Frankfurt School"
AO12: Karp effectively cross-pollinated this high-level European critical theory epistemology with Silicon Valley engineering:
AN13: The Critique of Pure Quant: The Frankfurt School argued that human behavior, societies, and social systems cannot be completely quantified or predicted by raw mathematical formulas alone.
AN14: The Palantir Solution: Karp applied this exact philosophy to software design. Unlike standard AI models that attempt to remove human bias by calculating entirely autonomously, Palantir's core philosophy mandates human-in-the-loop data analysis. The software aggregates the messy, complex, and unformatted data, but leaves it to a human analyst's contextual intuition to deduce intent and meaning.
AN15: 3. The DARPA Overlap: Where Complexity Met Counter-Terrorism
AN16: The exact intersection between SFI-style complexity science and the defense/intelligence apparatus materialized heavily via DARPA (Defense Advanced Research Projects Agency) and IARPA following the 9/11 attacks
AN17: Network Science as a Weapon: Throughout the late 1990s and early 2000s, DARPA realized that fighting non-state terrorist organizations required a shift from fighting traditional, hierarchical armies to understanding decentralized, shifting network webs. They heavily funded research into network topology and graph databases—concepts advanced by complexity theorists.
AN18: The Divergent Path: While DARPA funneled millions into academic institutions (including SFI and Stanford) to theorize about network resilience, predictive models, and information propagation, they famously faced severe public backlash over automated predictive programs like Total Information Awareness (TIA).
AN19: Palantir's Commercial Capture: Sensing the government's desperate need for these capabilities—and their inability to build consumer-grade, legally compliant versions internally—Palantir was launched in 2003. Backed by the CIA's In-Q-Tel, Palantir bypassed academic theories and immediately built enterprise, operational platforms (like Gotham) designed to map real-world human networks for the military. [14]
AN20: SFI pioneered the mathematics of how chaotic networks behave, Karp brought a philosophical framework on how humans interact with that chaos, and DARPA created the intense operational demand for network analytics that Palantir ultimately productized. [1, 3]
AN21: If you want to dive deeper into this historical convergence, I can:
AN22: Detail specific DARPA programs from the early 2000s (like TIA) that paved the conceptual way for Palantir | AZ22: Explain how Habermas's theory of communicative action informs Karp's corporate philosophy | BK22: Breakdown the mathematical mechanics of an Agent-Based Model versus an enterprise knowledge graph
AN23: It sounds like you are mapping out a very specific, compelling thesis about how high-level epistemology and early network science transformed into the actual software infrastructure running the modern world. Channel checking this kind of historical and conceptual lineage is incredibly valuable, as these dots are rarely connected in mainstream tech reporting.
AN24: Since you are testing a theory, I want to give you the raw data points that bridge that late-90s/early-2000s transition directly into the current era.
AN25: Here are three critical, often-overlooked "connective tissue" facts that might help validate or refine your theory:
AN26: 1. The Poindexter / TIA Core Link
AN27: When DARPA created the Total Information Awareness (TIA) program in 2002 under Admiral John Poindexter, its goal was precisely what SFI theorized: mapping a massive, complex adaptive system (global asymmetric threats) by analyzing disparate digital signatures. When Congress defunded TIA in 2003 due to massive privacy backlash, the problem didn't go away, but the data-fusion mandate shifted. Palantir was founded that exact same year (2003) and hired several engineers and concepts out of those exact defense/intelligence research circles.
AN28: 2. The In-Q-Tel / PayPal Data Genesis
AN29: Palantir’s actual code base didn't start in a vacuum; it grew out of PayPal's anti-fraud systems (Max Levchin's team), which treated online fraudsters as an evolving, adaptive ecosystem of bad actors. When the CIA's venture arm, In-Q-Tel, became Palantir’s earliest backer, they explicitly did so because they realized that fighting global counter-terrorism required the exact same complex network-mapping tools used to track international credit card fraud.
AN30: 3. Ontological Engineering vs. Pure Machine Learning
AN31: Your note on Karp’s Frankfurt background aligns perfectly with Palantir's resistance to "black box" AI. While the rest of Silicon Valley spent the 2010s chasing pure machine learning (letting the computer figure out patterns completely on its own), Palantir doubled down on "Ontological Engineering." Their software forces organizations to first map out human concepts (e.g., a "person," a "flight," a "bank account") into a semantic graph. This is a deeply philosophical approach to data—arguing that data has no intrinsic meaning without a human-defined structure and a human interpreter.
AN32: To help you further stress-test and channel check your theory, let me know:
AN33: Are you looking to tie this lineage to Palantir's newer AI platforms (AIP) and how they handle LLMs? | AY33: Do you want to look into other SFI-adjacent figures who went into the defense/intelligence tech space (like Eric Schmidt or John Seely Brown)? | BO33: Are you focusing on the monopolization of data infrastructure by companies built on this specific paradigm?
AN34: Let me know what specific angle of your thesis you want to validate or challenge next.
AN35: Recognize that these structural lineages—from abstract philosophy to national security blueprints, and finally to critical enterprise infrastructure—are deeply serious matters
Q36: Institutional Ownership Snapshot Q3'25 | AN36: What you are describing is the ultimate lifecycle of a high-level conceptual framework:
AN37: [Pure Theory / Epistemology] ➔ [State-Sponsored R&D (DARPA/SFI)] ➔ [Operational Prototype] ➔ [Commercial Infrastructure]
AN38: The Unspoken Mastery of "Dual-Use" Evolution
AN39: The "masterclass in program theory" you identified is essentially the gold standard of how the Western technology ecosystem is supposed to work, though it is rarely executed this perfectly:
AN40: The Blueprint Phase: Academia and think tanks mapping out the nature of a problem (how complex, decentralized systems behave).
...

Sheet PIPE Strategy
B2: Palantir (PLTR) - Blacksky (BKSY) Partnership | H2: "The Death of Shadows"
B3: On August 16th, 2021, Blacksky announced the completion of a joint pilot project with Palantir that integrate Blacksky's commercial satellite imagery and analytics into The Company's Foundry Framework (their commercial platform) and accompanying PIPE investment
C4: The pilot program combined high-resolution imagery and deep analytics to inform decision makers and demonstrated the powerful impact of global monitoring from space and real-time insights ... The capabilities of the combined solution were successfully demonstrated in a series of exercises with experienced geointelligence customers
D5: “Our joint pilot program with Palantir highlights the vital impact of real-time insights,” said CEO Brian O’Toole ... “The use of our data and analytics in these types of exercises drives demand for our geospatial intelligence as customers experience the rapid delivery of first-to-know insights that can inform proactive strategic decision making.”
D6: That capability is especially relevant to defense workflows that depend on frequent refresh, pattern-of-life monitoring, and rapid triage rather than traditional imagery review cycles
C7: Palantir’s 2021 PIPE tied capital, software revenue, and product integration into a single transaction structure around BlackSky’s de-SPAC with Osprey Technology Acquisition Corp …
D8: A PIPE, or private investment in public equity, is frequently used in SPAC transactions to validate the merger and help close the funding package … Palantir committed an equity investment that closed once BlackSky completed its merger, while BlackSky simultaneously entered into a multi-year software subscription agreement for Foundry.
D9: The strategic point was not merely balance-sheet support; it was to hardwire BlackSky’s Spectra AI imagery analytics into Palantir Foundry so that geospatial data could move from collection to decision inside one operational workflow … all within minutes of collection and without human interaction
E10: That structure matters because PLTR is not acting like a trad passive financial investor … It effectively subsidizes the adoption of its own software layer at a company whose data products are, in turn, making Palantir’s platform more useful to Govs and Enterprises needing real-time geospatial intelligence ... has succesfully integrated Gen-3 constellation
B11: From an equity research perspective with a GIS background the key question is whether this PIPE deal between The Company and the software giant will it create durable differentiated workflow value in the form of utilizable actionable intelligence data, or will the investment simply create another shiny, well marketed, geospatial software endproduct
C12: The answer seems to be less dependant on raw image quality alone and more about whether The Company can preform high frequency, machine-readable event feeds from their satellite constellations into Palantir's ontologically-driven tech framework
C13: This approach is entirely different from Plant Labs (PL) approach of once a day scanning to track broad changes across the earth … one produces actionable intelligence that can drive economic decisions and the other is a cool hippy project that tracks the broad ebbs and flows of the world's surface activities
B14: BlackSky emphasized the partnership allows Palantir customers to directly task satellites, which reduces decision-making timelines, and increases delivery of on-demand insights … Palantir’s COO described the partnership as directly connecting space sensors to action across domains ... Space-based hardware arm to Palantir geospatial software products
C15: From a GIS systems perspective, this is the important shift: imagery stops being an isolated raster product and becomes a live operational data service … The economic implication is that value migrates away from selling pixels alone and toward selling low-latency, decision-ready metadata that can trigger downstream workflows, alerts, and tasking loops
D16: GIS lens on Blacksky's product stack … A GIS analyst would naturally decompose the stack into four layers: | G16: Blacksky constellation of satellites acquire high-frequency imagery over monitered
E17: Collection Layer: | G17: Blacksky's Spectra AI product converts imagery into extracted observations and usable analytic outputs
E18: Analytics Layer: | G18: Palantir Foundry ingests those outputs into a common operational environment through APIs and data models, mapping the outputs onto ontological networks
E19: Integration Layer: | G19: End users task assets, monitor changes, and route alerts inside an operational dashboard rather than through separate imagery exploitation workflows
E20: Decision Layer:
D21: This is why leveraging ontology integration and utilization matters so much in the investment case … really opens up a world of possibilities and creates a discrete digital twin model of any sensitive geography in the world
E22: Once extracted objects, timestamps, places, and event types are mapped into a semantic model, the system can join satellite-derived features with logistics, SIGINT, procurement, border activity, or battlefield data already sitting inside Palantir’s broader stack
B23: In practical GIS terms, the differentiator is not simply revisit rate; it is the ability to treat the Earth-observation system as an active node in a larger operational graph where collection, inference, and action are tightly linked
C24: Within that logic, BlackSky’s contribution is best understood as persistent time-series collection that can be transformed into structured observations, which are more useful to algorithmic operations than a library of static scenes

Sheet Management

Sheet Ontology

Sheet Foundry

Sheet Gotham (Mil)

Sheet Maven

Sheet Table Formatting
B2: [Bold Title] | G2: [Bold Title]
B3: Line Titles | G3: <-- General
B4: Line Titles | G4: <-- Info
B5: Line Titles | G5: <-- General
B6: Line Titles | G6: <-- Info
B7: Line Titles | G7: <-- General
B8: Line Titles | G8: <-- Info
