Workbook

Sheet Main
A1: Master
B2: PODD
B3: Price | C3: 133.93 | D3: 10/14/2026
B4: SO | C4: 96.298 | D4: Q2'26
B5: MC | C5: =C3*C4 -> 12897.191
B6: Cash | C6: 534.9 | D6: Q2'26
B7: Debt | C7: =18.9+929.5 -> 948.4 | D7: Q2'26
B8: EV | C8: =C5-C6+C7 -> 13310.691
B10: Insulet Corporation (PODD)
B12: Founder(s): John Brooks, Amparo Diaz, and Duane DeSisto | G12: Registered Exchange: NASDAQ | M12: Resources:
B13: Founded: 2000 | G13: Address: 100 Nagog Park, Acton, MA 01720 U.S. | M13: SEC filings | P13: https://www.sec.gov/edgar/browse/?CIK=1145197&owner=exclude
B14: Headquarters: Acton, MA | G14: Investor Relations Contact: | M14: Company Homepage | P14: https://www.insulet.com/
B15: Current CEO: Ashley McEvoy | G15: Investors Relation Department | N15: Company IR Page | Q15: https://investor.insulet.com/overview/default.aspx
B16: Employees: 5,700 | G16: Phone: | H16: (978) 600 - 7000 | J16: Email: | M16: Earnings Calls | P16: https://seekingalpha.com/symbol/PODD/earnings/transcripts
B17: Industry: Medical Devices | M17: Equity Analysis | P17: https://stockanalysis.com/stocks/podd/company/
B18: Sector: Healthcare | M18: MacroTrends | P18: https://www.macrotrends.net/stocks/charts/PODD/insulet/income-statement?freq=A
B19: IPO: May 15, 2007 | M19: ROIC, WACC | P19: https://www.gurufocus.com/term/wacc/PODD
B20: Fiscal Year: [January - December] | M20: Godel Terminal | P20: https://app.godelterminal.com/
A22: Company Overview:
B23: Insulet Corporation develops, manufactures, and sells insulin delivery systems for people with insulin-dependent diabetes in the United States and internationally
B24: The Company offers Omnipod platform products comprising Omnipod 5 automated insulin delivery system, which includes a proprietary AID algorithm embedded in the pod that integrates with a third-party continuous glucose monitor to obtain glucose values through wireless Bluetooth communication
C25: The Company also offers Omnipod DASH insulin management system that features a Bluetooth enabled pod that is controlled by a smartphone-like personal diabetes manager with a color touch screen user interface
C26: It also provides pods for Amgen for use in the Neulasta Onpro kit, which is a delivery system to help reduce the risk of infection after intense chemotherapy
B27: The Company sells its products to end-users through the pharmacy channel; and independent distributors
B28: Insulet Corporation was incorporated in 2000 and is headquartered in Acton, Massachusetts
A30: Business Segments and Geographical Info:

Sheet Model
B1: [Use for Graphing] | AM1: Q1 2020 | AQ1: Q1 2021 | AU1: Q1 2022 | AY1: Q1 2023 | BC1: Q1 2024 | BG1: Q1 2025 | BK1: Q1 2026
B2: Quarterly
B3: Revenues | C3: {="Q"&MOD(_xlfn.SEQUENCE(1,64)-1,4)+1&" "&(2011+INT((_xlfn.SEQUENCE(1,64)-1)/4))} -> Q1 2011 | D3: Q2 2011 | E3: Q3 2011 | F3: Q4 2011 | G3: Q1 2012 | H3: Q2 2012 | I3: Q3 2012 | J3: Q4 2012 | K3: Q1 2013 | L3: Q2 2013 | M3: Q3 2013 | N3: Q4 2013 | O3: Q1 2014 | P3: Q2 2014 | Q3: Q3 2014 | R3: Q4 2014 | S3: Q1 2015 | T3: Q2 2015 | U3: Q3 2015 | V3: Q4 2015 | W3: Q1 2016 | X3: Q2 2016 | Y3: Q3 2016 | Z3: Q4 2016 | AA3: Q1 2017 | AB3: Q2 2017 | AC3: Q3 2017 | AD3: Q4 2017 | AE3: Q1 2018 | AF3: Q2 2018 | AG3: Q3 2018 | AH3: Q4 2018 | AI3: Q1 2019 | AJ3: Q2 2019 | AK3: Q3 2019 | AL3: Q4 2019 | AM3: Q1 2020 | AN3: Q2 2020 | AO3: Q3 2020 | AP3: Q4 2020 | AQ3: Q1 2021 | AR3: Q2 2021 | AS3: Q3 2021 | AT3: Q4 2021 | AU3: Q1 2022 | AV3: Q2 2022 | AW3: Q3 2022 | AX3: Q4 2022 | AY3: Q1 2023 | AZ3: Q2 2023 | BA3: Q3 2023 | BB3: Q4 2023 | BC3: Q1 2024 | BD3: Q2 2024 | BE3: Q3 2024 | BF3: Q4 2024 | BG3: Q1 2025 | BH3: Q2 2025 | BI3: Q3 2025 | BJ3: Q4 2025 | BK3: Q1 2026 | BL3: Q2 2026 | BM3: Q3 2026 | BN3: Q4 2026 | BS3: 2011 | BT3: =BS3+1 -> 2012 | BU3: =BT3+1 -> 2013 | BV3: =BU3+1 -> 2014 | BW3: =BV3+1 -> 2015 | BX3: =BW3+1 -> 2016 | BY3: =BX3+1 -> 2017 | BZ3: =BY3+1 -> 2018 | CA3: =BZ3+1 -> 2019 | ... EO3: =EN3+1 -> 2085
B4: Omnipod Products | AQ4: 233.2 | AR4: 242.1 | AS4: 260.3 | AT4: =1011.4-SUM(AQ4:AS4) -> 275.8 | AU4: 269.5 | AV4: 285.8 | AW4: 326.1 | AX4: =1247.8-SUM(AU4:AW4) -> 366.4 | AY4: 357.6 | AZ4: 380.5 | BA4: 422 | BB4: =1661.1-SUM(AY4:BA4) -> 501 | BC4: 433 | BD4: 480.4 | BE4: 533.5 | BF4: =2032.7-SUM(BC4:BE4) -> 585.8 | BG4: 554 | BH4: 639 | BI4: 699.2 | BJ4: =2674-SUM(BG4:BI4) -> 781.8 | BK4: 758.4 | BL4: 795.9 | CC4: =SUM(AQ4:AT4) -> 1011.4 | CD4: =SUM(AU4:AX4) -> 1247.8 | CE4: =SUM(AY4:BB4) -> 1661.1 | CF4: =SUM(BC4:BF4) -> 2032.7 | CG4: =SUM(BG4:BJ4) -> 2674 | CH4: =CG4*(1+CH8) -> 3262.28 | CI4: =CH4*(1+CI8) -> 3718.9992 | CJ4: =CI4*(1+CJ8) -> 4128.0891 | CK4: =CJ4*(1+CK8) -> 4499.6171 | CL4: =CK4*(1+CL8) -> 4859.5865 | CM4: =CL4*(1+CM8) -> 5199.7576 | CN4: =CM4*(1+CN8) -> 5511.743 | CO4: =CN4*(1+CO8) -> 5787.3302 | ... CQ4: =CP4*(1+CQ8) -> 6199.3881
B5: Drug Delivery | AQ5: 19.1 | AR5: 21.1 | AS5: 15.3 | AT5: =87.4-SUM(AQ5:AS5) -> 31.9 | AU5: 25.9 | AV5: 13.6 | AW5: 14.7 | AX5: =57.5-SUM(AU5:AW5) -> 3.3 | AY5: 0.5 | AZ5: 16 | BA5: 10.7 | BB5: =36-SUM(AY5:BA5) -> 8.8 | BC5: 8.7 | BD5: 8.1 | BE5: 10.3 | BF5: =38.9-SUM(BC5:BE5) -> 11.8 | BG5: 14.9 | BH5: 10.2 | BI5: 7.1 | BJ5: =34.1-SUM(BG5:BI5) -> 1.9 | BK5: 3.3 | BL5: 5.8 | CC5: =SUM(AQ5:AT5) -> 87.4 | CD5: =SUM(AU5:AX5) -> 57.5 | CE5: =SUM(AY5:BB5) -> 36 | CF5: =SUM(BC5:BF5) -> 38.9 | CG5: =SUM(BG5:BJ5) -> 34.1 | CH5: =CG5*(1+CH9) -> 13.64 | CI5: =CH5*(1+CI9) -> 10.912 | CJ5: =CI5*(1+CJ9) -> 8.7296 | CK5: =CJ5*(1+CK9) -> 9.60256 | CL5: =CK5*(1+CL9) -> 10.178714 | CM5: =CL5*(1+CM9) -> 10.585862 | CN5: =CM5*(1+CN9) -> 10.956367 | CO5: =CN5*(1+CO9) -> 11.285058 | ... CQ5: =CP5*(1+CQ9) -> 11.798528
B6: Ttl Revenues | AQ6: =SUM(AQ4:AQ5) -> 252.3 | AR6: =SUM(AR4:AR5) -> 263.2 | AS6: =SUM(AS4:AS5) -> 275.6 | AT6: =SUM(AT4:AT5) -> 307.7 | AU6: =SUM(AU4:AU5) -> 295.4 | AV6: =SUM(AV4:AV5) -> 299.4 | AW6: =SUM(AW4:AW5) -> 340.8 | AX6: =SUM(AX4:AX5) -> 369.7 | ... BL6: =SUM(BL4:BL5) -> 801.7 | CC6: =SUM(AQ6:AT6) -> 1098.8 | CD6: =SUM(AU6:AX6) -> 1305.3 | CE6: =SUM(AY6:BB6) -> 1697.1 | CF6: =SUM(BC6:BF6) -> 2071.6 | CG6: =SUM(BG6:BJ6) -> 2708.1 | CH6: =SUM(CH4:CH5) -> 3275.92 | CI6: =SUM(CI4:CI5) -> 3729.9112 | CJ6: =SUM(CJ4:CJ5) -> 4136.8187 | CK6: =SUM(CK4:CK5) -> 4509.2197 | CL6: =SUM(CL4:CL5) -> 4869.7652 | CM6: =SUM(CM4:CM5) -> 5210.3434 | CN6: =SUM(CN4:CN5) -> 5522.6994 | CO6: =SUM(CO4:CO5) -> 5798.6152 | ... CQ6: =SUM(CQ4:CQ5) -> 6211.1866
B8: Omnipod Products Growth Y/y | AU8: =AU4/AQ4-1 -> 0.15566038 | AV8: =AV4/AR4-1 -> 0.18050392 | AW8: =AW4/AS4-1 -> 0.25278525 | AX8: =AX4/AT4-1 -> 0.32849891 | AY8: =AY4/AU4-1 -> 0.32690167 | AZ8: =AZ4/AV4-1 -> 0.33135059 | BA8: =BA4/AW4-1 -> 0.29408157 | BB8: =BB4/AX4-1 -> 0.36735808 | ... BL8: =BL4/BH4-1 -> 0.24553991 | CD8: =CD4/CC4-1 -> 0.23373542 | CE8: =CE4/CD4-1 -> 0.33122295 | CF8: =CF4/CE4-1 -> 0.22370718 | CG8: =CG4/CF4-1 -> 0.31549171 | CH8: 0.22 | CI8: 0.14 | CJ8: 0.11 | CK8: 0.09 | CL8: 0.08 | CM8: 0.07 | CN8: 0.06 | CO8: 0.05 | CP8: 0.04 | CQ8: 0.03
B9: Drug Delivery Growth Y/y | AU9: =AU5/AQ5-1 -> 0.35602094 | AV9: =AV5/AR5-1 -> -0.35545024 | AW9: =AW5/AS5-1 -> -0.039215686 | AX9: =AX5/AT5-1 -> -0.89655172 | AY9: =AY5/AU5-1 -> -0.98069498 | AZ9: =AZ5/AV5-1 -> 0.17647059 | BA9: =BA5/AW5-1 -> -0.27210884 | BB9: =BB5/AX5-1 -> 1.6666667 | ... BL9: =BL5/BH5-1 -> -0.43137255 | CD9: =CD5/CC5-1 -> -0.34210526 | CE9: =CE5/CD5-1 -> -0.37391304 | CF9: =CF5/CE5-1 -> 0.080555556 | CG9: =CG5/CF5-1 -> -0.12339332 | CH9: -0.6 | CI9: -0.2 | CJ9: -0.2 | CK9: 0.1 | CL9: 0.06 | CM9: 0.04 | CN9: 0.035 | CO9: 0.03 | CP9: 0.025 | CQ9: 0.02
B10: Ttl Revenue Growth Y/y | AU10: =AU6/AQ6-1 -> 0.17082838 | AV10: =AV6/AR6-1 -> 0.13753799 | AW10: =AW6/AS6-1 -> 0.23657475 | AX10: =AX6/AT6-1 -> 0.20149496 | AY10: =AY6/AU6-1 -> 0.21225457 | AZ10: =AZ6/AV6-1 -> 0.3243153 | BA10: =BA6/AW6-1 -> 0.26965962 | BB10: =BB6/AX6-1 -> 0.37895591 | ... BL10: =BL6/BH6-1 -> 0.2349045 | CD10: =CD6/CC6-1 -> 0.18793229 | CE10: =CE6/CD6-1 -> 0.30016088 | CF10: =CF6/CE6-1 -> 0.22067056 | CG10: =CG6/CF6-1 -> 0.30725043 | CH10: =CH6/CG6-1 -> 0.20967468 | CI10: =CI6/CH6-1 -> 0.13858434 | CJ10: =CJ6/CI6-1 -> 0.10909308 | CK10: =CK6/CJ6-1 -> 0.090021102 | ... CQ10: =CQ6/CP6-1 -> 0.029980819
B12: Omnipod Products % of Revenues | AQ12: =AQ4/AQ6 -> 0.92429647 | AR12: =AR4/AR6 -> 0.91983283 | AS12: =AS4/AS6 -> 0.94448476 | AT12: =AT4/AT6 -> 0.89632759 | AU12: =AU4/AU6 -> 0.91232227 | AV12: =AV4/AV6 -> 0.95457582 | AW12: =AW4/AW6 -> 0.9568662 | AX12: =AX4/AX6 -> 0.99107384 | ... BL12: =BL4/BL6 -> 0.99276537 | CC12: =CC4/CC6 -> 0.92045868 | CD12: =CD4/CD6 -> 0.95594882 | CE12: =CE4/CE6 -> 0.97878734 | CF12: =CF4/CF6 -> 0.98122224 | CG12: =CG4/CG6 -> 0.98740815
B13: Drug Delivery % of Revenues | AQ13: =AQ5/AQ6 -> 0.075703528 | AR13: =AR5/AR6 -> 0.080167173 | AS13: =AS5/AS6 -> 0.055515239 | AT13: =AT5/AT6 -> 0.10367241 | AU13: =AU5/AU6 -> 0.087677725 | AV13: =AV5/AV6 -> 0.045424182 | AW13: =AW5/AW6 -> 0.043133803 | AX13: =AX5/AX6 -> 0.0089261563 | ... BL13: =BL5/BL6 -> 0.0072346264 | CC13: =CC5/CC6 -> 0.079541318 | CD13: =CD5/CD6 -> 0.044051176 | CE13: =CE5/CE6 -> 0.021212657 | CF13: =CF5/CF6 -> 0.018777756 | CG13: =CG5/CG6 -> 0.012591854
B15: U.S. | BK15: 469.3 | BL15: 470.3
B16: Malaysia | BK16: 224.7 | BL16: 234.1
B17: Other | BK17: 136.4 | BL17: 154.2
B18: Ttl Revenues | BK18: =SUM(BK15:BK17) -> 830.4 | BL18: =SUM(BL15:BL17) -> 858.6
B20: U.S. Growth Y/y
B21: Malaysia Growth Y/y
B22: Other Growth Y/y
B23: Ttl Revenues Growth Y/y
B25: U.S. % of Revenues | BK25: =BK15/BK18 -> 0.56514933 | BL25: =BL15/BL18 -> 0.54775215
B26: Malaysia % of Revenues | BK26: =BK16/BK18 -> 0.27059249 | BL26: =BL16/BL18 -> 0.27265316
B27: Other % of Revenues | BK27: =BK17/BK18 -> 0.16425819 | BL27: =BL17/BL18 -> 0.17959469
B29: Revenues | C29: 28.258 | D29: 32.211 | E29: 44.594 | F29: 47.192 | G29: 47.754 | H29: 51.035 | I29: 54.752 | J29: 57.828 | K29: 57.356 | L29: 60.092 | M29: 61.103 | N29: 68.533 | O29: 69.161 | P29: 72.013 | Q29: 74.985 | R29: 15.162 | S29: 48.148 | T29: 60.551 | U29: 71.393 | V29: 83.801 | W29: 81.213 | X29: 87.33 | Y29: 94.871 | Z29: 103.575 | AA29: 101.713 | AB29: 109.756 | AC29: 121.775 | AD29: 130.556 | AE29: 123.578 | AF29: 124.262 | AG29: 151.076 | AH29: 164.884 | AI29: 159.6 | AJ29: 177.1 | AK29: 192.1 | AL29: 209.4 | AM29: 198 | AN29: 226.3 | AO29: 234 | AP29: 246.1 | AQ29: 252.3 | AR29: 263.2 | AS29: 275.6 | AT29: 307.7 | AU29: =AU6 -> 295.4 | AV29: =AV6 -> 299.4 | AW29: =AW6 -> 340.8 | AX29: =AX6 -> 369.7 | AY29: =AY6 -> 358.1 | AZ29: =AZ6 -> 396.5 | BA29: =BA6 -> 432.7 | BB29: =BB6 -> 509.8 | ... BL29: =BL6 -> 801.7 | BS29: =SUM(C29:F29) -> 152.255 | BT29: =SUM(G29:J29) -> 211.369 | BU29: =SUM(K29:N29) -> 247.084 | BV29: =SUM(O29:R29) -> 231.321 | BW29: =SUM(S29:V29) -> 263.893 | BX29: =SUM(W29:Z29) -> 366.989 | BY29: =SUM(AA29:AD29) -> 463.8 | BZ29: =SUM(AE29:AH29) -> 563.8 | CA29: =SUM(AI29:AL29) -> 738.2 | CB29: =SUM(AM29:AP29) -> 904.4 | CC29: =SUM(AQ29:AT29) -> 1098.8 | CD29: =SUM(AU29:AX29) -> 1305.3 | CE29: =SUM(AY29:BB29) -> 1697.1 | CF29: =SUM(BC29:BF29) -> 2071.6 | CG29: =SUM(BG29:BJ29) -> 2708.1 | CH29: =CH6 -> 3275.92 | CI29: =CI6 -> 3729.9112 | CJ29: =CJ6 -> 4136.8187 | CK29: =CK6 -> 4509.2197 | CL29: =CL6 -> 4869.7652 | CM29: =CM6 -> 5210.3434 | CN29: =CN6 -> 5522.6994 | CO29: =CO6 -> 5798.6152 | ... CQ29: =CQ6 -> 6211.1866
B30: COGS | C30: 14.725 | D30: 17.673 | E30: 26.033 | F30: 27.112 | G30: 27.458 | H30: 28.704 | I30: 30.362 | J30: 32.509 | K30: 32.201 | L30: 33.259 | M30: 33.708 | N30: 35.515 | O30: 36.353 | P30: 36.248 | Q30: 36.943 | R30: -5.349 | S30: 18.955 | T30: 30.036 | U30: 39.823 | V30: 41.808 | W30: 37.162 | X30: 36.873 | Y30: 39.23 | Z30: 42.638 | AA30: 42.315 | AB30: 45.117 | AC30: 48.151 | AD30: 51.017 | AE30: 47.763 | AF30: 42.19 | AG30: 49.107 | AH30: 54.54 | AI30: 52.9 | AJ30: 60.7 | AK30: 69 | AL30: 75.3 | AM30: 71.1 | AN30: 83.8 | AO30: 82.2 | AP30: 85 | AQ30: 84.8 | AR30: 80.5 | AS30: 86.9 | AT30: 94.5 | AU30: 85.7 | AV30: 109.1 | AW30: 152.5 | AX30: =499.7-SUM(AU30:AW30) -> 152.4 | AY30: 117.6 | AZ30: 131.6 | BA30: 139.4 | BB30: =537.2-SUM(AY30:BA30) -> 148.6 | BC30: 134.9 | BD30: 157.6 | BE30: 166.8 | BF30: =625.9-SUM(BC30:BE30) -> 166.6 | BG30: 159.9 | BH30: 196.9 | BI30: 196.2 | BJ30: =768.2-SUM(BG30:BI30) -> 215.2 | BK30: 232.7 | BL30: 239.1 | BS30: =SUM(C30:F30) -> 85.543 | BT30: =SUM(G30:J30) -> 119.033 | BU30: =SUM(K30:N30) -> 134.683 | BV30: =SUM(O30:R30) -> 104.195 | BW30: =SUM(S30:V30) -> 130.622 | BX30: =SUM(W30:Z30) -> 155.903 | BY30: =SUM(AA30:AD30) -> 186.6 | BZ30: =SUM(AE30:AH30) -> 193.6 | CA30: =SUM(AI30:AL30) -> 257.9 | CB30: =SUM(AM30:AP30) -> 322.1 | CC30: =SUM(AQ30:AT30) -> 346.7 | CD30: =SUM(AU30:AX30) -> 499.7 | CE30: =SUM(AY30:BB30) -> 537.2 | CF30: =SUM(BC30:BF30) -> 625.9 | CG30: =SUM(BG30:BJ30) -> 768.2 | CH30: =CH29*(1-CH45) -> 929.27209 | CI30: =CI29*(1-CI45) -> 1100.3238 | CJ30: =CJ29*(1-CJ45) -> 1261.7297 | CK30: =CK29*(1-CK45) -> 1352.7659 | CL30: =CL29*(1-CL45) -> 1448.7552 | CM30: =CM29*(1-CM45) -> 1537.0513 | CN30: =CN29*(1-CN45) -> 1615.3896 | CO30: =CO29*(1-CO45) -> 1681.5984 | ... CQ30: =CQ29*(1-CQ45) -> 1801.2441
B31: GP | C31: =C29-C30 -> 13.533 | D31: =D29-D30 -> 14.538 | E31: =E29-E30 -> 18.561 | F31: =F29-F30 -> 20.08 | G31: =G29-G30 -> 20.296 | H31: =H29-H30 -> 22.331 | I31: =I29-I30 -> 24.39 | J31: =J29-J30 -> 25.319 | ... BL31: =BL29-BL30 -> 562.6 | BS31: =SUM(C31:F31) -> 66.712 | BT31: =SUM(G31:J31) -> 92.336 | BU31: =SUM(K31:N31) -> 112.401 | BV31: =SUM(O31:R31) -> 127.126 | BW31: =SUM(S31:V31) -> 133.271 | BX31: =SUM(W31:Z31) -> 211.086 | BY31: =SUM(AA31:AD31) -> 277.2 | BZ31: =SUM(AE31:AH31) -> 370.2 | CA31: =SUM(AI31:AL31) -> 480.3 | CB31: =SUM(AM31:AP31) -> 582.3 | CC31: =SUM(AQ31:AT31) -> 752.1 | CD31: =SUM(AU31:AX31) -> 805.6 | CE31: =SUM(AY31:BB31) -> 1159.9 | CF31: =SUM(BC31:BF31) -> 1445.7 | CG31: =SUM(BG31:BJ31) -> 1939.9 | CH31: =CH29*CH45 -> 2346.6479 | CI31: =CI29*CI45 -> 2629.5874 | CJ31: =CJ29*CJ45 -> 2875.089 | CK31: =CK29*CK45 -> 3156.4538 | CL31: =CL29*CL45 -> 3421.0101 | CM31: =CM29*CM45 -> 3673.2921 | CN31: =CN29*CN45 -> 3907.3098 | CO31: =CO29*CO45 -> 4117.0168 | ... CQ31: =CQ29*CQ45 -> 4409.9425
B32: R&D | C32: 4.589 | D32: 6.832 | E32: 4.638 | F32: 5.804 | G32: 5.432 | H32: 6.521 | I32: 6.559 | J32: 5.847 | K32: 4.396 | L32: 5.174 | M32: 5.771 | N32: 6.424 | O32: 6.779 | P32: 6.677 | Q32: 7.158 | R32: 7.286 | S32: 8.207 | T32: 12.069 | U32: 10.035 | V32: 12.897 | W32: 12.989 | X32: 12.953 | Y32: 13.734 | Z32: 16.034 | AA32: 17.5 | AB32: 18.029 | AC32: 20.141 | AD32: 20.03 | AE32: 20.267 | AF32: 18.801 | AG32: 22.336 | AH32: 33.396 | AI32: 32.5 | AJ32: 33 | AK32: 31.3 | AL32: 35.5 | AM32: 35.5 | AN32: 34.2 | AO32: 38.8 | AP32: 38.3 | AQ32: 40.7 | AR32: 40.1 | AS32: 37.5 | AT32: 41.8 | AU32: 43.1 | AV32: 42.6 | AW32: 45 | AX32: =180.2-SUM(AU32:AW32) -> 49.5 | AY32: 50.1 | AZ32: 55.1 | BA32: 57.8 | BB32: =205-SUM(AY32:BA32) -> 42 | BC32: 50.2 | BD32: 53.9 | BE32: 54.9 | BF32: =219.6-SUM(BC32:BE32) -> 60.6 | BG32: 59.6 | BH32: 73.4 | BI32: 77.2 | BJ32: =301.1-SUM(BG32:BI32) -> 90.9 | BK32: 89.7 | BL32: 88.1 | BS32: =SUM(C32:F32) -> 21.863 | BT32: =SUM(G32:J32) -> 24.359 | BU32: =SUM(K32:N32) -> 21.765 | BV32: =SUM(O32:R32) -> 27.9 | BW32: =SUM(S32:V32) -> 43.208 | BX32: =SUM(W32:Z32) -> 55.71 | BY32: =SUM(AA32:AD32) -> 75.7 | BZ32: =SUM(AE32:AH32) -> 94.8 | CA32: =SUM(AI32:AL32) -> 132.3 | CB32: =SUM(AM32:AP32) -> 146.8 | CC32: =SUM(AQ32:AT32) -> 160.1 | CD32: =SUM(AU32:AX32) -> 180.2 | CE32: =SUM(AY32:BB32) -> 205 | CF32: =SUM(BC32:BF32) -> 219.6 | CG32: =SUM(BG32:BJ32) -> 301.1 | CH32: =CH29*CH46 -> 364.23305 | CI32: =CI29*CI46 -> 428.93979 | CJ32: =CJ29*CJ46 -> 486.0762 | CK32: =CK29*CK46 -> 518.56026 | CL32: =CL29*CL46 -> 547.84859 | CM32: =CM29*CM46 -> 573.13778 | CN32: =CN29*CN46 -> 601.97423 | CO32: =CO29*CO46 -> 626.25044 | ... CQ32: =CQ29*CQ46 -> 658.38578
B33: SG&A | C33: 16.217 | D33: 22.621 | E33: 23.691 | F33: 24.787 | G33: 25.759 | H33: 26.329 | I33: 26.302 | J33: 25.558 | K33: 26.965 | L33: 27.481 | M33: 38.937 | N33: 26.388 | O33: 27.915 | P33: 34.368 | Q33: 33.76 | R33: 12.057 | S33: 28.252 | T33: 32.505 | U33: 36.33 | V33: 41.712 | W33: 38.761 | X33: 38.792 | Y33: 39.489 | Z33: 49.038 | AA33: 47.206 | AB33: 49.968 | AC33: 51.436 | AD33: 60.29 | AE33: 55.548 | AF33: 58.946 | AG33: 72.768 | AH33: 60.738 | AI33: 66.9 | AJ33: 75.8 | AK33: 74.8 | AL33: 80.5 | AM33: 83.9 | AN33: 80.8 | AO33: 89.2 | AP33: 130.1 | AQ33: 110.5 | AR33: 116.3 | AS33: 117.5 | AT33: 121.7 | AU33: 128.7 | AV33: 174.4 | AW33: 140.4 | AX33: =587.8-SUM(AU33:AW33) -> 144.3 | AY33: 162.7 | AZ33: 178.7 | BA33: 180.7 | BB33: =734.8-SUM(AY33:BA33) -> 212.7 | BC33: 199.7 | BD33: 222.4 | BE33: 234.1 | BF33: =917.2-SUM(BC33:BE33) -> 261 | BG33: 260.7 | BH33: 257.7 | BI33: 315.2 | BJ33: =1165-SUM(BG33:BI33) -> 331.4 | BK33: 317.2 | BL33: 344.8 | BS33: =SUM(C33:F33) -> 87.316 | BT33: =SUM(G33:J33) -> 103.948 | BU33: =SUM(K33:N33) -> 119.771 | BV33: =SUM(O33:R33) -> 108.1 | BW33: =SUM(S33:V33) -> 138.799 | BX33: =SUM(W33:Z33) -> 166.08 | BY33: =SUM(AA33:AD33) -> 208.9 | BZ33: =SUM(AE33:AH33) -> 248 | CA33: =SUM(AI33:AL33) -> 298 | CB33: =SUM(AM33:AP33) -> 384 | CC33: =SUM(AQ33:AT33) -> 466 | CD33: =SUM(AU33:AX33) -> 587.8 | CE33: =SUM(AY33:BB33) -> 734.8 | CF33: =SUM(BC33:BF33) -> 917.2 | CG33: =SUM(BG33:BJ33) -> 1165 | CH33: =CH29*CH47 -> 1409.271 | CI33: =CI29*CI47 -> 1566.5627 | CJ33: =CJ29*CJ47 -> 1716.7798 | CK33: =CK29*CK47 -> 1860.0531 | CL33: =CL29*CL47 -> 1996.6037 | CM33: =CM29*CM47 -> 2123.2149 | CN33: =CN29*CN47 -> 2236.6932 | CO33: =CO29*CO47 -> 2333.9426 | ... CQ33: =CQ29*CQ47 -> 2484.4746
B34: OI | C34: =C31-SUM(C32:C33) -> -7.273 | D34: =D31-SUM(D32:D33) -> -14.915 | E34: =E31-SUM(E32:E33) -> -9.768 | F34: =F31-SUM(F32:F33) -> -10.511 | G34: =G31-SUM(G32:G33) -> -10.895 | H34: =H31-SUM(H32:H33) -> -10.519 | I34: =I31-SUM(I32:I33) -> -8.471 | J34: =J31-SUM(J32:J33) -> -6.086 | ... BL34: =BL31-SUM(BL32:BL33) -> 129.7 | BS34: =SUM(C34:F34) -> -42.467 | BT34: =SUM(G34:J34) -> -35.971 | BU34: =SUM(K34:N34) -> -29.135 | BV34: =SUM(O34:R34) -> -8.874 | BW34: =SUM(S34:V34) -> -48.736 | BX34: =SUM(W34:Z34) -> -10.704 | BY34: =SUM(AA34:AD34) -> -7.4 | BZ34: =SUM(AE34:AH34) -> 27.4 | CA34: =SUM(AI34:AL34) -> 50 | CB34: =SUM(AM34:AP34) -> 51.5 | CC34: =SUM(AQ34:AT34) -> 126 | CD34: =SUM(AU34:AX34) -> 37.6 | CE34: =SUM(AY34:BB34) -> 220.1 | CF34: =SUM(BC34:BF34) -> 308.9 | CG34: =SUM(BG34:BJ34) -> 473.8 | CH34: =CH31-SUM(CH32:CH33) -> 573.14386 | CI34: =CI31-SUM(CI32:CI33) -> 634.0849 | CJ34: =CJ31-SUM(CJ32:CJ33) -> 672.23304 | CK34: =CK31-SUM(CK32:CK33) -> 777.8404 | CL34: =CL31-SUM(CL32:CL33) -> 876.55774 | CM34: =CM31-SUM(CM32:CM33) -> 976.93939 | CN34: =CN31-SUM(CN32:CN33) -> 1068.6423 | CO34: =CO31-SUM(CO32:CO33) -> 1156.8237 | ... CQ34: =CQ31-SUM(CQ32:CQ33) -> 1267.0821
B35: Interest Expenses | C35: 0 | D35: 0 | E35: 0 | F35: 0 | G35: 0 | H35: 0 | I35: 0 | J35: 0 | K35: 0 | L35: 0 | M35: 0 | N35: 0 | O35: 0 | P35: 0 | Q35: 0 | R35: 0 | S35: 0 | T35: 0 | U35: 0 | V35: 0 | W35: 0 | X35: 0 | Y35: 0 | Z35: 0 | AA35: 0 | AB35: 0 | AC35: 0 | AD35: 0 | AE35: 0 | AF35: 0 | AG35: 0 | AH35: 0 | AI35: 0 | AJ35: 0 | AK35: 0 | AL35: 0 | AM35: 0 | AN35: 0 | AO35: 0 | AP35: 0 | AQ35: 0 | AR35: 0 | AS35: 0 | AT35: 0 | AU35: -8.9 | AV35: -8.3 | AW35: -6.8 | AX35: =-26.7-SUM(AU35:AW35) -> -2.7 | AY35: -9.4 | AZ35: -9.7 | BA35: -10.4 | BB35: =-36.2-SUM(AY35:BA35) -> -6.7 | BC35: -10.7 | BD35: -11 | BE35: -12.4 | BF35: =-42.7-SUM(BC35:BE35) -> -8.6 | BG35: -9.2 | BH35: -19.6 | BI35: -15.6 | BJ35: =-59.4-SUM(BG35:BI35) -> -15 | BK35: -14.7 | BL35: -13.5 | BS35: =SUM(C35:F35) -> 0 | BT35: =SUM(G35:J35) -> 0 | BU35: =SUM(K35:N35) -> 0 | BV35: =SUM(O35:R35) -> 0 | BW35: =SUM(S35:V35) -> 0 | BX35: =SUM(W35:Z35) -> 0 | BY35: =SUM(AA35:AD35) -> 0 | BZ35: =SUM(AE35:AH35) -> 0 | CA35: =SUM(AI35:AL35) -> 0 | CB35: =SUM(AM35:AP35) -> 0 | CC35: =SUM(AQ35:AT35) -> 0 | CD35: =SUM(AU35:AX35) -> -26.7 | CE35: =SUM(AY35:BB35) -> -36.2 | CF35: =SUM(BC35:BF35) -> -42.7 | CG35: =SUM(BG35:BJ35) -> -59.4 | CH35: =CG65*(-$CV$69) -> -104.7995 | CI35: =CH65*(-$CV$69) -> -97.987533 | CJ35: =CI65*(-$CV$69) -> -91.618343 | CK35: =CJ65*(-$CV$69) -> -85.663151 | CL35: =CK65*(-$CV$69) -> -80.095046 | CM35: =CL65*(-$CV$69) -> -74.888868 | CN35: =CM65*(-$CV$69) -> -70.021091 | CO35: =CN65*(-$CV$69) -> -65.46972 | ... CQ35: =CP65*(-$CV$69) -> -57.235266
B36: Interest Income | C36: 0 | D36: 0 | E36: 0 | F36: 0 | G36: 0 | H36: 0 | I36: 0 | J36: 0 | K36: 0 | L36: 0 | M36: 0 | N36: 0 | O36: 0 | P36: 0 | Q36: 0 | R36: 0 | S36: 0 | T36: 0 | U36: 0 | V36: 0 | W36: 0 | X36: 0 | Y36: 0 | Z36: 0 | AA36: 0 | AB36: 0 | AC36: 0 | AD36: 0 | AE36: 0 | AF36: 0 | AG36: 0 | AH36: 0 | AI36: 0 | AJ36: 0 | AK36: 0 | AL36: 0 | AM36: 0 | AN36: 0 | AO36: 0 | AP36: 0 | AQ36: 0 | AR36: 0 | AS36: 0 | AT36: 0 | AU36: 0 | AV36: 0 | AW36: 0 | AX36: =0-SUM(AU36:AW36) -> 0 | AY36: 6.5 | AZ36: 7.3 | BA36: 8.6 | BB36: =28.6-SUM(AY36:BA36) -> 6.2 | BC36: 9.4 | BD36: 9.3 | BE36: 10.5 | BF36: =39.5-SUM(BC36:BE36) -> 10.3 | BG36: 10.3 | BH36: 10.1 | BI36: 8.6 | BJ36: =34.7-SUM(BG36:BI36) -> 5.7 | BK36: 4.9 | BL36: 3.6 | BS36: =SUM(C36:F36) -> 0 | BT36: =SUM(G36:J36) -> 0 | BU36: =SUM(K36:N36) -> 0 | BV36: =SUM(O36:R36) -> 0 | BW36: =SUM(S36:V36) -> 0 | BX36: =SUM(W36:Z36) -> 0 | BY36: =SUM(AA36:AD36) -> 0 | BZ36: =SUM(AE36:AH36) -> 0 | CA36: =SUM(AI36:AL36) -> 0 | CB36: =SUM(AM36:AP36) -> 0 | CC36: =SUM(AQ36:AT36) -> 0 | CD36: =SUM(AU36:AX36) -> 0 | CE36: =SUM(AY36:BB36) -> 28.6 | CF36: =SUM(BC36:BF36) -> 39.5 | CG36: =SUM(BG36:BJ36) -> 34.7 | CH36: =CG52*$DA$52 -> 141.141 | CI36: =CH52*$DA$52 -> 194.10528 | CJ36: =CI52*$DA$52 -> 257.55989 | CK36: =CJ52*$DA$52 -> 330.39726 | CL36: =CK52*$DA$52 -> 419.25898 | CM36: =CL52*$DA$52 -> 524.9052 | CN36: =CM52*$DA$52 -> 648.90765 | CO36: =CN52*$DA$52 -> 792.07791 | ... CQ36: =CP52*$DA$52 -> 1139.0774
B37: Loss on Extinguishment of Debt | C37: 0 | D37: 0 | E37: 0 | F37: 0 | G37: 0 | H37: 0 | I37: 0 | J37: 0 | K37: 0 | L37: 0 | M37: 0 | N37: 0 | O37: 0 | P37: 0 | Q37: 0 | R37: 0 | S37: 0 | T37: 0 | U37: 0 | V37: 0 | W37: 0 | X37: 0 | Y37: 0 | Z37: 0 | AA37: 0 | AB37: 0 | AC37: 0 | AD37: 0 | AE37: 0 | AF37: 0 | AG37: 0 | AH37: 0 | AI37: 0 | AJ37: 0 | AK37: 0 | AL37: 0 | AM37: 0 | AN37: 0 | AO37: 0 | AP37: 0 | AQ37: 0 | AR37: 0 | AS37: 0 | AT37: 0 | AU37: 0 | AV37: 0 | AW37: 0 | AX37: =0-SUM(AU37:AW37) -> 0 | AY37: 0 | AZ37: 0 | BA37: 0 | BB37: =0-SUM(AY37:BA37) -> 0 | BC37: 0 | BD37: 0 | BE37: 0 | BF37: =0-SUM(BC37:BE37) -> 0 | BG37: -39.5 | BH37: -84.4 | BI37: 0 | BJ37: =-123.9-SUM(BG37:BI37) -> 0 | BK37: 0 | BL37: 0 | BS37: =SUM(C37:F37) -> 0 | BT37: =SUM(G37:J37) -> 0 | BU37: =SUM(K37:N37) -> 0 | BV37: =SUM(O37:R37) -> 0 | BW37: =SUM(S37:V37) -> 0 | BX37: =SUM(W37:Z37) -> 0 | BY37: =SUM(AA37:AD37) -> 0 | BZ37: =SUM(AE37:AH37) -> 0 | CA37: =SUM(AI37:AL37) -> 0 | CB37: =SUM(AM37:AP37) -> 0 | CC37: =SUM(AQ37:AT37) -> 0 | CD37: =SUM(AU37:AX37) -> 0 | CE37: =SUM(AY37:BB37) -> 0 | CF37: =SUM(BC37:BF37) -> 0 | CG37: =SUM(BG37:BJ37) -> -123.9 | CH37: 0 | CI37: 0 | CJ37: 0 | CK37: 0 | CL37: 0 | CM37: 0 | CN37: 0 | CO37: 0 | CP37: 0 | CQ37: 0
B38: Other Income | C38: -2.575 | D38: -4.508 | E38: -3.794 | F38: -3.699 | G38: -3.839 | H38: -3.888 | I38: -3.918 | J38: -4.039 | K38: -4.328 | L38: -4.579 | M38: -3.972 | N38: -2.86 | O38: -4.193 | P38: -23.779 | Q38: -7.948 | R38: -3.083 | S38: -3.152 | T38: -3.193 | U38: -3.146 | V38: -3.163 | W38: -2.926 | X38: -2.998 | Y38: -5.369 | Z38: -4.821 | AA38: -4.573 | AB38: -4.308 | AC38: -4.153 | AD38: -6.166 | AE38: -6.236 | AF38: -5.604 | AG38: -5.012 | AH38: -5.348 | AI38: -2.6 | AJ38: -5.7 | AK38: -15.9 | AL38: -11.3 | AM38: -10.1 | AN38: -10.1 | AO38: -10.4 | AP38: -11.2 | AQ38: -16 | AR38: -54.7 | AS38: -18.5 | AT38: -16.3 | AU38: 0.3 | AV38: -1.1 | AW38: -1.8 | AX38: =-1.1-SUM(AU38:AW38) -> 1.5 | AY38: -0.2 | AZ38: -0.2 | BA38: 0.7 | BB38: =2.2-SUM(AY38:BA38) -> 1.9 | BC38: -0.7 | BD38: -1.8 | BE38: -3.4 | BF38: =-5.5-SUM(BC38:BE38) -> 0.4 | BG38: -2.2 | BH38: 1.1 | BI38: 12.1 | BJ38: =14.3-SUM(BG38:BI38) -> 3.3 | BK38: 0.7 | BL38: -1.1 | BS38: =SUM(C38:F38) -> -14.576 | BT38: =SUM(G38:J38) -> -15.684 | BU38: =SUM(K38:N38) -> -15.739 | BV38: =SUM(O38:R38) -> -39.003 | BW38: =SUM(S38:V38) -> -12.654 | BX38: =SUM(W38:Z38) -> -16.114 | BY38: =SUM(AA38:AD38) -> -19.2 | BZ38: =SUM(AE38:AH38) -> -22.2 | CA38: =SUM(AI38:AL38) -> -35.5 | CB38: =SUM(AM38:AP38) -> -41.8 | CC38: =SUM(AQ38:AT38) -> -105.5 | CD38: =SUM(AU38:AX38) -> -1.1 | CE38: =SUM(AY38:BB38) -> 2.2 | CF38: =SUM(BC38:BF38) -> -5.5 | CG38: =SUM(BG38:BJ38) -> 14.3 | CH38: 0 | CI38: 0 | CJ38: 0 | CK38: 0 | CL38: 0 | CM38: 0 | CN38: 0 | CO38: 0 | CP38: 0 | CQ38: 0
B39: Pretax Income | C39: =C34+SUM(C35:C38) -> -9.848 | D39: =D34+SUM(D35:D38) -> -19.423 | E39: =E34+SUM(E35:E38) -> -13.562 | F39: =F34+SUM(F35:F38) -> -14.21 | G39: =G34+SUM(G35:G38) -> -14.734 | H39: =H34+SUM(H35:H38) -> -14.407 | I39: =I34+SUM(I35:I38) -> -12.389 | J39: =J34+SUM(J35:J38) -> -10.125 | ... BL39: =BL34+SUM(BL35:BL38) -> 118.7 | BS39: =SUM(C39:F39) -> -57.043 | BT39: =SUM(G39:J39) -> -51.655 | BU39: =SUM(K39:N39) -> -44.874 | BV39: =SUM(O39:R39) -> -47.877 | BW39: =SUM(S39:V39) -> -61.39 | BX39: =SUM(W39:Z39) -> -26.818 | BY39: =SUM(AA39:AD39) -> -26.6 | BZ39: =SUM(AE39:AH39) -> 5.2 | CA39: =SUM(AI39:AL39) -> 14.5 | CB39: =SUM(AM39:AP39) -> 9.7 | CC39: =SUM(AQ39:AT39) -> 20.5 | CD39: =SUM(AU39:AX39) -> 9.8 | CE39: =SUM(AY39:BB39) -> 214.7 | CF39: =SUM(BC39:BF39) -> 300.2 | CG39: =SUM(BG39:BJ39) -> 339.5 | CH39: =CH34+SUM(CH35:CH38) -> 609.48536 | CI39: =CI34+SUM(CI35:CI38) -> 730.20265 | CJ39: =CJ34+SUM(CJ35:CJ38) -> 838.17459 | CK39: =CK34+SUM(CK35:CK38) -> 1022.5745 | CL39: =CL34+SUM(CL35:CL38) -> 1215.7217 | CM39: =CM34+SUM(CM35:CM38) -> 1426.9557 | CN39: =CN34+SUM(CN35:CN38) -> 1647.5289 | CO39: =CO34+SUM(CO35:CO38) -> 1883.4319 | ... CQ39: =CQ34+SUM(CQ35:CQ38) -> 2348.9242
B40: Taxes | C40: 0 | D40: -11.339 | E40: 0 | F40: 0 | G40: 0.046 | H40: 0.069 | I40: 0.028 | J40: 0.069 | K40: 0.131 | L40: 0.118 | M40: 0.005 | N40: -0.154 | O40: 0.065 | P40: 0.052 | Q40: 0.021 | R40: -0.078 | S40: 0.024 | T40: 0.015 | U40: 0.044 | V40: 0.129 | W40: 0.1 | X40: 0.1 | Y40: 0.1 | Z40: 0.092 | AA40: 0.096 | AB40: 0.101 | AC40: 0.1 | AD40: -0.097 | AE40: 0.333 | AF40: 0.412 | AG40: 0.194 | AH40: 0.961 | AI40: 0.3 | AJ40: 0.5 | AK40: 0.3 | AL40: 1.8 | AM40: -0.5 | AN40: 3 | AO40: 1.8 | AP40: -1.4 | AQ40: 0.3 | AR40: -3.4 | AS40: 2.6 | AT40: 4.2 | AU40: 1.5 | AV40: -1.1 | AW40: -0.5 | AX40: =5.2-SUM(AU40:AW40) -> 5.3 | AY40: -0.8 | AZ40: -1.2 | BA40: -1.7 | BB40: =8.4-SUM(AY40:BA40) -> 12.1 | BC40: -3.4 | BD40: 137.5 | BE40: -5.4 | BF40: =-118.1-SUM(BC40:BE40) -> -246.8 | BG40: 12.7 | BH40: 5.9 | BI40: 35.2 | BJ40: =92.4-SUM(BG40:BI40) -> 38.6 | BK40: 21.9 | BL40: 23.7 | BS40: =SUM(C40:F40) -> -11.339 | BT40: =SUM(G40:J40) -> 0.212 | BU40: =SUM(K40:N40) -> 0.1 | BV40: =SUM(O40:R40) -> 0.06 | BW40: =SUM(S40:V40) -> 0.212 | BX40: =SUM(W40:Z40) -> 0.392 | BY40: =SUM(AA40:AD40) -> 0.2 | BZ40: =SUM(AE40:AH40) -> 1.9 | CA40: =SUM(AI40:AL40) -> 2.9 | CB40: =SUM(AM40:AP40) -> 2.9 | CC40: =SUM(AQ40:AT40) -> 3.7 | CD40: =SUM(AU40:AX40) -> 5.2 | CE40: =SUM(AY40:BB40) -> 8.4 | CF40: =SUM(BC40:BF40) -> -118.1 | CG40: =SUM(BG40:BJ40) -> 92.4 | CH40: =CH39*CH49 -> 127.99193 | CI40: =CI39*CI49 -> 153.34256 | CJ40: =CJ39*CJ49 -> 176.01666 | CK40: =CK39*CK49 -> 214.74065 | CL40: =CL39*CL49 -> 255.30155 | CM40: =CM39*CM49 -> 299.6607 | CN40: =CN39*CN49 -> 345.98107 | CO40: =CO39*CO49 -> 395.5207 | ... CQ40: =CQ39*CQ49 -> 493.27408
B41: Net Income | C41: =C39-C40 -> -9.848 | D41: =D39-D40 -> -8.084 | E41: =E39-E40 -> -13.562 | F41: =F39-F40 -> -14.21 | G41: =G39-G40 -> -14.78 | H41: =H39-H40 -> -14.476 | I41: =I39-I40 -> -12.417 | J41: =J39-J40 -> -10.194 | ... BL41: =BL39-BL40 -> 95 | BS41: =SUM(C41:F41) -> -45.704 | BT41: =SUM(G41:J41) -> -51.867 | BU41: =SUM(K41:N41) -> -44.974 | BV41: =SUM(O41:R41) -> -47.937 | BW41: =SUM(S41:V41) -> -61.602 | BX41: =SUM(W41:Z41) -> -27.21 | BY41: =SUM(AA41:AD41) -> -26.8 | BZ41: =SUM(AE41:AH41) -> 3.3 | CA41: =SUM(AI41:AL41) -> 11.6 | CB41: =SUM(AM41:AP41) -> 6.8 | CC41: =SUM(AQ41:AT41) -> 16.8 | CD41: =SUM(AU41:AX41) -> 4.6 | CE41: =SUM(AY41:BB41) -> 206.3 | CF41: =SUM(BC41:BF41) -> 418.3 | CG41: =SUM(BG41:BJ41) -> 247.1 | CH41: =CH39-CH40 -> 481.49344 | CI41: =CI39-CI40 -> 576.86009 | CJ41: =CJ39-CJ40 -> 662.15792 | CK41: =CK39-CK40 -> 807.83386 | CL41: =CL39-CL40 -> 960.42013 | CM41: =CM39-CM40 -> 1127.295 | CN41: =CN39-CN40 -> 1301.5478 | CO41: =CO39-CO40 -> 1487.9112 | ... CQ41: =CQ39-CQ40 -> 1855.6501 | CR41: =CQ41*(1+$DA$53) -> 1874.2066 | CS41: =CR41*(1+$DA$53) -> 1892.9487 | CT41: =CS41*(1+$DA$53) -> 1911.8782 | CU41: =CT41*(1+$DA$53) -> 1930.9969 | CV41: =CU41*(1+$DA$53) -> 1950.3069 | CW41: =CV41*(1+$DA$53) -> 1969.81 | CX41: =CW41*(1+$DA$53) -> 1989.5081 | CY41: =CX41*(1+$DA$53) -> 2009.4032 | ... EO41: =EN41*(1+$DA$53) -> 3051.8612
B42: SC | C42: 45.58 | D42: 46.38 | E42: 47.32 | F42: 47.42 | G42: 47.61 | H42: 47.82 | I42: 48.04 | J42: 48.22 | K42: 53.05 | L42: 53.83 | M42: 54.46 | N42: 54.68 | O42: 55.09 | P42: 55.43 | Q42: 55.82 | R42: 56.17 | S42: 56.5 | T42: 56.81 | U42: 56.9 | V42: 56.93 | W42: 57.03 | X42: 57.2 | Y42: 57.34 | Z42: 57.44 | AA42: 57.69 | AB42: 57.98 | AC42: 58.1 | AD42: 58.24 | AE42: 58.48 | AF42: 58.83 | AG42: 59.02 | AH42: 59.1 | AI42: 59.36 | AJ42: 59.85 | AK42: 60.74 | AL42: 62.4 | AM42: 62.88 | AN42: 64.37 | AO42: 65.72 | AP42: 65.95 | AQ42: 66.11 | AR42: 66.7 | AS42: 68.87 | AT42: 69.07 | AU42: 69.25 | AV42: 69.36 | AW42: 69.42 | AX42: 69.47 | AY42: 69.58 | AZ42: 69.74 | BA42: 69.82 | BB42: 69.86 | BC42: 69.96 | BD42: 70.06 | BE42: 70.12 | BF42: 70.27 | BG42: 70.272 | BH42: 70.37 | BI42: 70.367 | BJ42: 70.25 | BK42: 69.98 | BL42: 69.3 | BS42: =AVERAGE(C42:F42) -> 46.675 | BT42: =AVERAGE(G42:J42) -> 47.9225 | BU42: =AVERAGE(K42:N42) -> 54.005 | BV42: =AVERAGE(O42:R42) -> 55.6275 | BW42: =AVERAGE(S42:V42) -> 56.785 | BX42: =AVERAGE(W42:Z42) -> 57.2525 | BY42: =AVERAGE(AA42:AD42) -> 58.0025 | BZ42: =AVERAGE(AE42:AH42) -> 58.8575 | CA42: =AVERAGE(AI42:AL42) -> 60.5875 | CB42: =AVERAGE(AM42:AP42) -> 64.73 | CC42: =AVERAGE(AQ42:AT42) -> 67.6875 | CD42: =AVERAGE(AU42:AX42) -> 69.375 | CE42: =AVERAGE(AY42:BB42) -> 69.75 | CF42: =AVERAGE(BC42:BF42) -> 70.1025 | CG42: =AVERAGE(BG42:BJ42) -> 70.31475
B43: EPS | C43: =C41/C42 -> -0.21605968 | D43: =D41/D42 -> -0.17429927 | E43: =E41/E42 -> -0.28660186 | F43: =F41/F42 -> -0.29966259 | G43: =G41/G42 -> -0.31043898 | H43: =H41/H42 -> -0.30271853 | I43: =I41/I42 -> -0.25847211 | J43: =J41/J42 -> -0.21140606 | ... BL43: =BL41/BL42 -> 1.3708514 | BS43: =SUM(C43:F43) -> -0.97662339 | BT43: =SUM(G43:J43) -> -1.0830357 | BU43: =SUM(K43:N43) -> -0.83309792 | BV43: =SUM(O43:R43) -> -0.863701 | BW43: =SUM(S43:V43) -> -1.0842689 | BX43: =SUM(W43:Z43) -> -0.47546706 | BY43: =SUM(AA43:AD43) -> -0.46248735 | BZ43: =SUM(AE43:AH43) -> 0.054565887 | CA43: =SUM(AI43:AL43) -> 0.1908149 | CB43: =SUM(AM43:AP43) -> 0.1075288 | CC43: =SUM(AQ43:AT43) -> 0.23090032 | CD43: =SUM(AU43:AX43) -> 0.066634013 | CE43: =SUM(AY43:BB43) -> 2.9556979 | CF43: =SUM(BC43:BF43) -> 5.9554265 | CG43: =SUM(BG43:BJ43) -> 3.5146604
B45: Gross Profit Margin | C45: =C31/C29 -> 0.47890863 | D45: =D31/D29 -> 0.4513365 | E45: =E31/E29 -> 0.41622191 | F45: =F31/F29 -> 0.42549585 | G45: =G31/G29 -> 0.42501152 | H45: =H31/H29 -> 0.43756246 | I45: =I31/I29 -> 0.44546318 | J45: =J31/J29 -> 0.43783288 | ... BL45: =BL31/BL29 -> 0.70175876 | BS45: =BS31/BS29 -> 0.43815967 | BT45: =BT31/BT29 -> 0.43684741 | BU45: =BU31/BU29 -> 0.45491007 | BV45: =BV31/BV29 -> 0.54956532 | BW45: =BW31/BW29 -> 0.50501908 | BX45: =BX31/BX29 -> 0.57518345 | BY45: =BY31/BY29 -> 0.59767141 | BZ45: =BZ31/BZ29 -> 0.65661582 | ... CG45: =CG31/CG29 -> 0.71633248 | CH45: 0.71633248 | CI45: 0.705 | CJ45: 0.695 | CK45: 0.7 | CL45: 0.7025 | CM45: 0.705 | CN45: 0.7075 | CO45: 0.71 | CP45: 0.71 | CQ45: 0.71
B46: R&D as % of Revenue | C46: =C32/C29 -> 0.16239649 | D46: =D32/D29 -> 0.21210146 | E46: =E32/E29 -> 0.10400502 | F46: =F32/F29 -> 0.12298695 | G46: =G32/G29 -> 0.11374963 | H46: =H32/H29 -> 0.12777506 | I46: =I32/I29 -> 0.11979471 | J46: =J32/J29 -> 0.10111019 | ... BL46: =BL32/BL29 -> 0.10989148 | BS46: =BS32/BS29 -> 0.14359463 | BT46: =BT32/BT29 -> 0.11524396 | BU46: =BU32/BU29 -> 0.088087452 | BV46: =BV32/BV29 -> 0.12061162 | BW46: =BW32/BW29 -> 0.16373303 | BX46: =BX32/BX29 -> 0.15180292 | BY46: =BY32/BY29 -> 0.1632169 | BZ46: =BZ32/BZ29 -> 0.16814473 | ... CG46: =CG32/CG29 -> 0.11118496 | CH46: 0.11118496 | CI46: 0.115 | CJ46: 0.1175 | CK46: 0.115 | CL46: 0.1125 | CM46: 0.11 | CN46: 0.109 | CO46: 0.108 | CP46: 0.107 | CQ46: 0.106
B47: SG&A as % of Revenue | C47: =C33/C29 -> 0.57389058 | D47: =D33/D29 -> 0.70227562 | E47: =E33/E29 -> 0.53125981 | F47: =F33/F29 -> 0.52523733 | G47: =G33/G29 -> 0.53941031 | H47: =H33/H29 -> 0.51590085 | I47: =I33/I29 -> 0.48038428 | J47: =J33/J29 -> 0.44196583 | ... BL47: =BL33/BL29 -> 0.43008607 | BS47: =BS33/BS29 -> 0.57348527 | BT47: =BT33/BT29 -> 0.49178451 | BU47: =BU33/BU29 -> 0.48473798 | BV47: =BV33/BV29 -> 0.46731598 | BW47: =BW33/BW29 -> 0.52596696 | BX47: =BX33/BX29 -> 0.45254762 | BY47: =BY33/BY29 -> 0.45040966 | BZ47: =BZ33/BZ29 -> 0.4398723 | ... CG47: =CG33/CG29 -> 0.43019091 | CH47: 0.43019091 | CI47: 0.42 | CJ47: 0.415 | CK47: 0.4125 | CL47: 0.41 | CM47: 0.4075 | CN47: 0.405 | CO47: 0.4025 | CP47: 0.4015 | CQ47: 0.4
...

Sheet Notes | Quant Analysis
CL1: 0
P2: Employee Scope: | AO2: General Notes/Observations
Q32: Notes: | R32: [X]
R33: [Y]
R34: [Z]
AO35: Financial Stmts. Notes/Observations
P36: Institutional Ownership Snapshot | AO36: Revenues:
Q65: Notes: | R65: [X]
R66: [Y]
R67: [Z]
P69: Revenue Breakdown by Segment | AO69: Earnings Scope:
Q101: Notes: | R101: [X]
R102: [Y]
R103: [Z]
P105: Q/q Total Revenues, Net Income, FCF | AO105: Balance Sheet Scope:
Q134: Notes: | R134: [X]
R135: [Y]
R136: [Z]
P138: Y/y Total Revenues, Net Income, FCF | AO138: [Equity Preformance Compared to Peers]
Q167: Notes: | R167: [X]
R168: [Y]
R169: [Z]
A184: VOO Historical Returns | I184: PODD Historical Returns
A185: 1003 Trading Days? (From: 10/11/2022 - 10/11/2026) | I185: 1003 Trading Days? (From: 10/11/2022 - 10/11/2026)
A186: Close | B186: High | C186: Low | D186: Open | E186: Volume | F186: UTC Date | G186: Change | I186: Close | J186: High | K186: Low | L186: Open | M186: Volume | N186: UTC Date | O186: Change
A187: 715.59 | B187: 716.435 | C187: 712.54 | D187: 713.54 | E187: 4345835.7 | F187: Fri, 09 Oct 2026 00:00:00 GMT | G187: =A187/D187-1 -> 0.0028729994 | I187: 135.28 | J187: 137.17 | K187: 133.72 | L187: 134.19 | M187: 865360.2 | N187: Fri, 09 Oct 2026 00:00:00 GMT | O187: =I187/L187-1 -> 0.0081228109
A188: 711.28 | B188: 714.27 | C188: 708.16 | D188: 712.25 | E188: 4763330.7 | F188: Thu, 08 Oct 2026 00:00:00 GMT | G188: =A188/D188-1 -> -0.0013618814 | I188: 134.47 | J188: 134.6 | K188: 132.855 | L188: 133.96 | M188: 1557440.6 | N188: Thu, 08 Oct 2026 00:00:00 GMT | O188: =I188/L188-1 -> 0.0038071066
A189: 714.34 | B189: 715.055 | C189: 711.06 | D189: 713.06 | E189: 4675948.1 | F189: Wed, 07 Oct 2026 00:00:00 GMT | G189: =A189/D189-1 -> 0.0017950804 | I189: 134.36 | J189: 137.1 | K189: 133.33 | L189: 134.94 | M189: 1032906.1 | N189: Wed, 07 Oct 2026 00:00:00 GMT | O189: =I189/L189-1 -> -0.0042982066
A190: 716.2 | B190: 718.47 | C190: 715.09 | D190: 715.21 | E190: 4568431.3 | F190: Tue, 06 Oct 2026 00:00:00 GMT | G190: =A190/D190-1 -> 0.0013842088 | I190: 134.73 | J190: 136.16 | K190: 133.725 | L190: 135.77 | M190: 1712375.2 | N190: Tue, 06 Oct 2026 00:00:00 GMT | O190: =I190/L190-1 -> -0.0076600133
A191: 712.32 | B191: 713.8583 | C191: 707.42 | D191: 707.44 | E191: 6172916.9 | F191: Mon, 05 Oct 2026 00:00:00 GMT | G191: =A191/D191-1 -> 0.0068981115 | I191: 135.62 | J191: 135.81 | K191: 131.225 | L191: 131.69 | M191: 1940340.7 | N191: Mon, 05 Oct 2026 00:00:00 GMT | O191: =I191/L191-1 -> 0.029842813
A192: 707.54 | B192: 710.2 | C192: 705.12 | D192: 708.31 | E192: 6612533.1 | F192: Fri, 02 Oct 2026 00:00:00 GMT | G192: =A192/D192-1 -> -0.0010870946 | I192: 131.69 | J192: 132.53 | K192: 128.01 | L192: 131.825 | M192: 3060814.4 | N192: Fri, 02 Oct 2026 00:00:00 GMT | O192: =I192/L192-1 -> -0.001024085
A193: 702.35 | B193: 703.725 | C193: 697.47 | D193: 702.555 | E193: 8433749.3 | F193: Thu, 01 Oct 2026 00:00:00 GMT | G193: =A193/D193-1 -> -0.0002917921 | I193: 130.79 | J193: 132.015 | K193: 128.745 | L193: 131.78 | M193: 3257419.9 | N193: Thu, 01 Oct 2026 00:00:00 GMT | O193: =I193/L193-1 -> -0.0075125209
A194: 700.86 | B194: 707.2 | C194: 700.56 | D194: 704.58 | E194: 9876125.1 | F194: Wed, 30 Sep 2026 00:00:00 GMT | G194: =A194/D194-1 -> -0.0052797411 | I194: 130.47 | J194: 133.145 | K194: 130.1 | L194: 132.93 | M194: 1416042.3 | N194: Wed, 30 Sep 2026 00:00:00 GMT | O194: =I194/L194-1 -> -0.018505981
A195: 702.46 | B195: 705 | C195: 700.74 | D195: 704.82 | E195: 7643258.6 | F195: Tue, 29 Sep 2026 00:00:00 GMT | G195: =A195/D195-1 -> -0.0033483726 | I195: 132.84 | J195: 133.49 | K195: 130.8 | L195: 132.58 | M195: 1366136.6 | N195: Tue, 29 Sep 2026 00:00:00 GMT | O195: =I195/L195-1 -> 0.0019610801
A196: 703.61 | B196: 707.33 | C196: 701.97 | D196: 706.29 | E196: 8539385.2 | F196: Mon, 28 Sep 2026 00:00:00 GMT | G196: =A196/D196-1 -> -0.0037944754 | I196: 133.11 | J196: 135.4 | K196: 130.385 | L196: 134.44 | M196: 1724759.4 | N196: Mon, 28 Sep 2026 00:00:00 GMT | O196: =I196/L196-1 -> -0.009892889
A197: 708.9674 | B197: 709.82021 | C197: 704.36423 | D197: 706.62343 | E197: 5482247.9 | F197: Fri, 25 Sep 2026 00:00:00 GMT | G197: =A197/D197-1 -> 0.0033171475 | I197: 136.13 | J197: 138.06 | K197: 134.48 | L197: 135.78 | M197: 1055965.7 | N197: Fri, 25 Sep 2026 00:00:00 GMT | O197: =I197/L197-1 -> 0.0025776992
A198: 705.17714 | B198: 706.76805 | C198: 701.54548 | D198: 702.26463 | E198: 9443878 | F198: Thu, 24 Sep 2026 00:00:00 GMT | G198: =A198/D198-1 -> 0.0041473149 | I198: 135.78 | J198: 139.3511 | K198: 134.5501 | L198: 136.8 | M198: 1085511.9 | N198: Thu, 24 Sep 2026 00:00:00 GMT | O198: =I198/L198-1 -> -0.0074561404
A199: 705.78558 | B199: 710.55332 | C199: 704.55215 | D199: 710.30895 | E199: 13844442 | F199: Wed, 23 Sep 2026 00:00:00 GMT | G199: =A199/D199-1 -> -0.0063681746 | I199: 136.49 | J199: 139.82 | K199: 134.73 | L199: 139.07 | M199: 1021320.7 | N199: Wed, 23 Sep 2026 00:00:00 GMT | O199: =I199/L199-1 -> -0.018551808
A200: 710.9523 | B200: 712.4684 | C200: 710.15435 | D200: 711.45102 | E200: 20783008 | F200: Tue, 22 Sep 2026 00:00:00 GMT | G200: =A200/D200-1 -> -0.00070098699 | I200: 139.38 | J200: 142.0425 | K200: 137.6 | L200: 141.93 | M200: 1246949.4 | N200: Tue, 22 Sep 2026 00:00:00 GMT | O200: =I200/L200-1 -> -0.017966603 | R200: Min | S200: =MIN(O187:O1189) -> -0.11815276
A201: 710.9523 | B201: 712.24398 | C201: 704.14979 | D201: 704.3792 | E201: 8882600.7 | F201: Mon, 21 Sep 2026 00:00:00 GMT | G201: =A201/D201-1 -> 0.0093317662 | I201: 140.53 | J201: 141.49 | K201: 138.59 | L201: 140.6 | M201: 1335831.6 | N201: Mon, 21 Sep 2026 00:00:00 GMT | O201: =I201/L201-1 -> -0.00049786629 | R201: Max | S201: =MAX(O187:O1189) -> 0.085451862
...

Sheet Product Lines

Sheet Economics

Sheet Management

Sheet Table Formatting
B2: [Bold Title] | G2: [Bold Title]
B3: Line Titles | G3: <-- General
B4: Line Titles | G4: <-- Info
B5: Line Titles | G5: <-- General
B6: Line Titles | G6: <-- Info
B7: Line Titles | G7: <-- General
B8: Line Titles | G8: <-- Info
