Workbook

Sheet Main
A1: Master
A2: Capital Structure Snapshot:
B4: PYPL
B5: Price | C5: 57.8 | D5: 1/10/2025
B6: SO | C6: 935.65 | D6: Q3'25
B7: MC | C7: =C5*C6 -> 54080.57
B8: Cash | C8: =8995+1760 -> 10755 | D8: Q3'25
B9: Debt | C9: 11276 | D9: Q3'25
B10: EV | C10: =C7-C8+C9 -> 54601.57
B12: Paypal (PYPL)
B14: Founder(s): Peter Thiel, Max Levchin, Luke Nosek, Ken Howery, Yu Pan, Elon Musk | J14: Registered Exchange: | Q14: Resources:
B15: Founded: 1998 | J15: Address: | K15: 2211 North First Street San Jose, CA 95131 U.S. | Q15: SEC filings | T15: https://www.sec.gov/edgar/browse/?CIK=1633917&owner=exclude
B16: Headquarters: San Jose, CA | J16: Investor Relations Contact: | Q16: Paypal Homepage | T16: https://www.paypal.com/us/home
B17: Current CEO: James Alexander Chriss (Joined Sep 27, 2023) | J17: Investors Relation Department | R17: Paypal IR Page | U17: https://investor.pypl.com/home/
B18: Employees: 24,400 | J18: Phone: | K18: (408) 967 - 7000 | M18: Email: | Q18: Earnings Calls | T18: https://seekingalpha.com/symbol/PYPL/earnings/transcripts
B19: Industry: FinTech / Credit Services | Q19: Equity Analysis | T19: https://stockanalysis.com/stocks/pypl/
B20: Sector: Financials | Q20: Godel Terminal | T20: https://app.godelterminal.com/
B21: IPO: Feb 15, 2002 -- ~$800M valuation (bought by eBay for $1.5B in stock: Oct, 3,2002)
B22: Active Users: 432M
A24: Company Overview:
B25: PayPal Holdings, Inc. operates a scaled financial technology platform that enables digital payments on behalf of both merchants and consumers worldwide
C26: It generates most revenue from transaction fees on total payment volume (TPV), with additional contribution from value‑added services such as merchant solutions, credit products, and partnerships
B27: The Company's payments platform allows consumers to send and receive payments in approximately 200 markets and in approximately 100 currencies, withdraw funds to their bank accounts in 56 currencies, and hold balances in their PayPal accounts in 25 currencies
A35: Product Lines:
B36: The Business provides payment solutions under the PayPal, PayPal Credit, Braintree, Venmo, Xoom, Zettle, Hyperwallet, Honey, and Paidy names.
B37: PayPal: | C37: PayPal is The Company's core digital payment platform that connects consumers and merchants with a secure and convenient way to transact online, in-store, and across borders.
D38: PayPal supports a "digital wallet" and allows for multiple payment methods including Visa, Mastercard, Discover, American Express, traditional bank accounts or direct PayPal account debits
D39: The Company facilitates withdraws to bank accounts in 56 currencies and balance holding in 25 currencies. Cross-boarder transactions are approximately 25% of PayPal's TPV
D40: PayPal account presents users with a gateway to Buy-Now Pay-Later products
B41: PayPal Credit: | C41: PayPal Credit is a digital, reusable line of credit that functions similarly to a credit card but without a physical card.
D42: Revolving credit line that is automatically integrated into the user's PayPal account upon approval
D43: Minimum beginning credit line of $250, which increases or decreases based on periodic account reviews
D44: PayPal Credit allows users to send money online, but a 2.9% + $0.30 fee applies for this feature
B45: Braintree: | C45: Braintree is a robust payment gateway and processor that offers comprehensive payment solutions for enterprises
D46: Allows for businesses to digitally process transactions through various payment methods including major credit/debit cards, digital wallets (PayPal, Apple Pay, Google Pay), and local payment options
D47: Offers additional transaction security for consumers and merchants.
D48: Supports subscription-based businesses with easy-to-manage recurring payment schedules
D49: Offers solutions for seamless mobile payment integration
D50: Transparent pricing model with a standard rate of 2.59% + $0.49 per transaction for most payment types
B51: Venmo: | C51: Venmo is a mobile payments app/platform (owned and operated by PayPal) that specializes in peer-to-peer money transfers and payments
...

Sheet Model
B1: [Use for Graphing] | W1: Q1 2020 | AA1: Q1 2021 | AE1: Q1 2022 | AI1: Q1 2023 | AM1: Q1 2024 | AQ1: Q1 2025 | AU1: Q1 2026
B2: Quarterly
B3: Revenues | C3: Q1 2015 | D3: Q2 2015 | E3: Q3 2015 | F3: Q4 2015 | G3: Q1 2016 | H3: Q2 2016 | I3: Q3 2016 | J3: Q4 2016 | K3: Q1 2017 | L3: Q2 2017 | M3: Q3 2017 | N3: Q4 2017 | O3: Q1 2018 | P3: Q2 2018 | Q3: Q3 2018 | R3: Q4 2018 | S3: Q1 2019 | T3: Q2 2019 | U3: Q3 2019 | V3: Q4 2019 | W3: Q1 2020 | X3: Q2 2020 | Y3: Q3 2020 | Z3: Q4 2020 | AA3: Q1 2021 | AB3: Q2 2021 | AC3: Q3 2021 | AD3: Q4 2021 | AE3: Q1 2022 | AF3: Q2 2022 | AG3: Q3 2022 | AH3: Q4 2022 | AI3: Q1 2023 | AJ3: Q2 2023 | AK3: Q3 2023 | AL3: Q4 2023 | AM3: Q1 2024 | AN3: Q2 2024 | AO3: Q3 2024 | AP3: Q4 2024 | AQ3: Q1 2025 | AR3: Q2 2025 | AS3: Q3 2025 | AT3: Q4 2025 | AU3: Q1 2026 | AV3: Q2 2026 | AW3: Q3 2026 | AX3: Q4 2026 | AY3: Q1 2027 | AZ3: Q2 2027 | BA3: Q3 2027 | BB3: Q4 2027 | BG3: 2015 | BH3: =BG3+1 -> 2016 | BI3: =BH3+1 -> 2017 | BJ3: =BI3+1 -> 2018 | BK3: =BJ3+1 -> 2019 | BL3: =BK3+1 -> 2020 | BM3: =BL3+1 -> 2021 | BN3: =BM3+1 -> 2022 | BO3: =BN3+1 -> 2023 | ... DX3: =DW3+1 -> 2084
B4: Transaction Revenues | W4: 4215 | X4: 4945 | Y4: 5076 | Z4: =19918-SUM(W4:Y4) -> 5682 | AA4: 5621 | AB4: 5797 | AC4: 5607 | AD4: =23402-SUM(AA4:AC4) -> 6377 | AE4: 5998 | AF4: 6272 | AG4: 6234 | AH4: =25206-SUM(AE4:AG4) -> 6702 | AI4: 6364 | AJ4: 6556 | AK4: 6654 | AL4: =26857-SUM(AI4:AK4) -> 7283 | AM4: 7034 | AN4: 7153 | AO4: 7067 | AP4: =28842-SUM(AM4:AO4) -> 7588 | AQ4: 7016 | AR4: 7441 | AS4: 7522 | BL4: =SUM(W4:Z4) -> 19918 | BM4: =SUM(AA4:AD4) -> 23402 | BN4: =SUM(AE4:AH4) -> 25206 | BO4: =SUM(Model!AI4:AL4) -> 26857 | BP4: =SUM(Model!AM4:AP4) -> 28842 | BQ4: =BP4*(1+BQ8) -> 30067.785 | BR4: =BQ4*(1+BR8) -> 31390.768 | BS4: =BR4*(1+BS8) -> 32803.352 | BT4: =BS4*(1+BT8) -> 34312.306 | BU4: =BT4*(1+BU8) -> 35924.985 | BV4: =BU4*(1+BV8) -> 37649.384 | BW4: =BV4*(1+BW8) -> 39494.204 | BX4: =BW4*(1+BX8) -> 41468.914 | ... BZ4: =BY4*(1+BZ8) -> 45719.478
B5: Revenues from other VASs | W5: 403 | X5: 316 | Y5: 383 | Z5: =1536-SUM(W5:Y5) -> 434 | AA5: 412 | AB5: 441 | AC5: 575 | AD5: =1969-SUM(AA5:AC5) -> 541 | AE5: 485 | AF5: 534 | AG5: 612 | AH5: =2312-SUM(AE5:AG5) -> 681 | AI5: 676 | AJ5: 731 | AK5: 764 | AL5: =2914-SUM(AI5:AK5) -> 743 | AM5: 665 | AN5: 732 | AO5: 780 | AP5: =2955-SUM(AM5:AO5) -> 778 | AQ5: 775 | AR5: 847 | AS5: 895 | BL5: =SUM(W5:Z5) -> 1536 | BM5: =SUM(AA5:AD5) -> 1969 | BN5: =SUM(AE5:AH5) -> 2312 | BO5: =SUM(Model!AI5:AL5) -> 2914 | BP5: =SUM(Model!AM5:AP5) -> 2955 | BQ5: =BP5*(1+BQ9) -> 3353.925 | BR5: =BQ5*(1+BR9) -> 3957.6315 | BS5: =BR5*(1+BS9) -> 4749.1578 | BT5: =BS5*(1+BT9) -> 5556.5146 | BU5: =BT5*(1+BU9) -> 6334.4267 | BV5: =BU5*(1+BV9) -> 7094.5579 | BW5: =BV5*(1+BW9) -> 7804.0137 | BX5: =BW5*(1+BX9) -> 8506.3749 | ... BZ5: =BY5*(1+BZ9) -> 9829.9668
B6: Ttl Revenues | W6: =SUM(W4:W5) -> 4618 | X6: =SUM(X4:X5) -> 5261 | Y6: =SUM(Y4:Y5) -> 5459 | Z6: =SUM(Z4:Z5) -> 6116 | AA6: =SUM(AA4:AA5) -> 6033 | AB6: =SUM(AB4:AB5) -> 6238 | AC6: =SUM(AC4:AC5) -> 6182 | AD6: =SUM(AD4:AD5) -> 6918 | ... AS6: =SUM(AS4:AS5) -> 8417 | BL6: =SUM(W6:Z6) -> 21454 | BM6: =SUM(AA6:AD6) -> 25371 | BN6: =SUM(AE6:AH6) -> 27518 | BO6: =SUM(Model!AI6:AL6) -> 29771 | BP6: =SUM(Model!AM6:AP6) -> 31797 | BQ6: =SUM(BQ4:BQ5) -> 33421.71 | BR6: =SUM(BR4:BR5) -> 35348.399 | BS6: =SUM(BS4:BS5) -> 37552.51 | BT6: =SUM(BT4:BT5) -> 39868.821 | BU6: =SUM(BU4:BU5) -> 42259.411 | BV6: =SUM(BV4:BV5) -> 44743.942 | BW6: =SUM(BW4:BW5) -> 47298.217 | BX6: =SUM(BX4:BX5) -> 49975.289 | ... BZ6: =SUM(BZ4:BZ5) -> 55549.444
B8: Transaction Revenue Growth Y/y | AA8: =AA4/W4-1 -> 0.33357058 | AB8: =AB4/X4-1 -> 0.17229525 | AC8: =AC4/Y4-1 -> 0.10460993 | AD8: =AD4/Z4-1 -> 0.12231609 | AE8: =AE4/AA4-1 -> 0.067069916 | AF8: =AF4/AB4-1 -> 0.081938934 | AG8: =AG4/AC4-1 -> 0.11182451 | AH8: =AH4/AD4-1 -> 0.050964403 | ... AS8: =AS4/AO4-1 -> 0.064383755 | BM8: =BM4/BL4-1 -> 0.17491716 | BN8: =BN4/BM4-1 -> 0.077087428 | BO8: =BO4/BN4-1 -> 0.065500278 | BP8: =BP4/BO4-1 -> 0.073909968 | BQ8: 0.0425 | BR8: 0.044 | BS8: 0.045 | BT8: 0.046 | BU8: 0.047 | BV8: 0.048 | BW8: 0.049 | BX8: 0.05 | BY8: 0.05 | BZ8: 0.05
B9: VAS Revenue Growth Y/y | AA9: =AA5/W5-1 -> 0.022332506 | AB9: =AB5/X5-1 -> 0.39556962 | AC9: =AC5/Y5-1 -> 0.50130548 | AD9: =AD5/Z5-1 -> 0.24654378 | AE9: =AE5/AA5-1 -> 0.17718447 | AF9: =AF5/AB5-1 -> 0.21088435 | AG9: =AG5/AC5-1 -> 0.064347826 | AH9: =AH5/AD5-1 -> 0.25878004 | ... AS9: =AS5/AO5-1 -> 0.1474359 | BM9: =BM5/BL5-1 -> 0.28190104 | BN9: =BN5/BM5-1 -> 0.1742001 | BO9: =BO5/BN5-1 -> 0.26038062 | BP9: =BP5/BO5-1 -> 0.014070007 | BQ9: 0.135 | BR9: 0.18 | BS9: 0.2 | BT9: 0.17 | BU9: 0.14 | BV9: 0.12 | BW9: 0.1 | BX9: 0.09 | BY9: 0.08 | BZ9: 0.07
B10: Total Revenue Growth Y/y | AA10: =AA6/W6-1 -> 0.3064097 | AB10: =AB6/X6-1 -> 0.18570614 | AC10: =AC6/Y6-1 -> 0.13244184 | AD10: =AD6/Z6-1 -> 0.13113146 | AE10: =AE6/AA6-1 -> 0.074589756 | AF10: =AF6/AB6-1 -> 0.091054825 | AG10: =AG6/AC6-1 -> 0.10740861 | AH10: =AH6/AD6-1 -> 0.067215958 | ... AS10: =AS6/AO6-1 -> 0.072639225 | BM10: =BM6/BL6-1 -> 0.18257668 | BN10: =BN6/BM6-1 -> 0.084624177 | BO10: =BO6/BN6-1 -> 0.081873683 | BP10: =BP6/BO6-1 -> 0.068052803 | BQ10: =BQ6/BP6-1 -> 0.05109633 | BR10: =BR6/BQ6-1 -> 0.05764783 | BS10: =BS6/BR6-1 -> 0.062353908 | BT10: =BT6/BS6-1 -> 0.061681923 | ... BZ10: =BZ6/BY6-1 -> 0.05348455
B12: Transcation % of Ttl Revenues | W12: =W4/W6 -> 0.91273278 | X12: =X4/X6 -> 0.93993537 | Y12: =Y4/Y6 -> 0.92984063 | Z12: =Z4/Z6 -> 0.92903859 | AA12: =AA4/AA6 -> 0.93170893 | AB12: =AB4/AB6 -> 0.92930426 | AC12: =AC4/AC6 -> 0.90698803 | AD12: =AD4/AD6 -> 0.92179821 | ... AS12: =AS4/AS6 -> 0.89366758 | BL12: =BL4/BL6 -> 0.92840496 | BM12: =BM4/BM6 -> 0.92239171 | BN12: =BN4/BN6 -> 0.91598227 | BO12: =BO4/BO6 -> 0.90211951 | BP12: =BP4/BP6 -> 0.9070667 | BQ12: =BQ4/BQ6 -> 0.89964831 | BR12: =BR4/BR6 -> 0.8880393 | BS12: =BS4/BS6 -> 0.87353288 | ... BZ12: =BZ4/BZ6 -> 0.82304113
B13: VASs % of Ttl Revenues | W13: =W5/W6 -> 0.087267215 | X13: =X5/X6 -> 0.060064626 | Y13: =Y5/Y6 -> 0.07015937 | Z13: =Z5/Z6 -> 0.070961413 | AA13: =AA5/AA6 -> 0.068291066 | AB13: =AB5/AB6 -> 0.070695736 | AC13: =AC5/AC6 -> 0.09301197 | AD13: =AD5/AD6 -> 0.078201792 | ... AS13: =AS5/AS6 -> 0.10633242 | BL13: =BL5/BL6 -> 0.071595041 | BM13: =BM5/BM6 -> 0.077608293 | BN13: =BN5/BN6 -> 0.084017734 | BO13: =BO5/BO6 -> 0.097880488 | BP13: =BP5/BP6 -> 0.092933296 | BQ13: =BQ5/BQ6 -> 0.10035169 | BR13: =BR5/BR6 -> 0.1119607 | BS13: =BS5/BS6 -> 0.12646712 | ... BZ13: =BZ5/BZ6 -> 0.17695887
B15: U.S. | W15: 2469 | X15: 2651 | Y15: 2820 | Z15: =11013-SUM(W15:Y15) -> 3073 | AA15: 3063 | AB15: 3272 | AC15: 3476 | AD15: =13712-SUM(AA15:AC15) -> 3901 | AE15: 3671 | AF15: 3863 | AG15: 3978 | AH15: =15807-SUM(AE15:AG15) -> 4295 | AI15: 4147 | AJ15: 4210 | AK15: 4257 | AL15: =17253-SUM(AI15:AK15) -> 4639 | AM15: 4467 | AN15: 4550 | AO15: 4518 | AP15: =18267-SUM(AM15:AO15) -> 4732 | AQ15: 4463 | AR15: 4709 | AS15: 4753 | BL15: =SUM(W15:Z15) -> 11013 | BM15: =SUM(AA15:AD15) -> 13712 | BN15: =SUM(AE15:AH15) -> 15807 | BO15: =SUM(Model!AI15:AL15) -> 17253 | BP15: =SUM(Model!AM15:AP15) -> 18267
B16: International | W16: =478+1671 -> 2149 | X16: =586+2024 -> 2610 | Y16: =606+2033 -> 2639 | Z16: =2340+8101-SUM(W16:Y16) -> 3043 | AA16: =625+2345 -> 2970 | AB16: =587+2379 -> 2966 | AC16: =529+2177 -> 2706 | AD16: =2340+9319-SUM(AA16:AC16) -> 3017 | AE16: 2812 | AF16: 2943 | AG16: 2868 | AH16: =2071+9640-SUM(AE16:AG16) -> 3088 | AI16: 2893 | AJ16: 3077 | AK16: 3161 | AL16: =12518-SUM(AI16:AK16) -> 3387 | AM16: 3232 | AN16: 3335 | AO16: 3329 | AP16: =13530-SUM(AM16:AO16) -> 3634 | AQ16: 3328 | AR16: 3579 | AS16: 3664 | BL16: =SUM(W16:Z16) -> 10441 | BM16: =SUM(AA16:AD16) -> 11659 | BN16: =SUM(AE16:AH16) -> 11711 | BO16: =SUM(Model!AI16:AL16) -> 12518 | BP16: =SUM(Model!AM16:AP16) -> 13530
B17: Ttl Revenues | W17: =W16+W15 -> 4618 | X17: =X16+X15 -> 5261 | Y17: =Y16+Y15 -> 5459 | Z17: =Z16+Z15 -> 6116 | AA17: =AA16+AA15 -> 6033 | AB17: =AB16+AB15 -> 6238 | AC17: =AC16+AC15 -> 6182 | AD17: =AD16+AD15 -> 6918 | ... AS17: =AS16+AS15 -> 8417 | BL17: =SUM(W17:Z17) -> 21454 | BM17: =SUM(AA17:AD17) -> 25371 | BN17: =SUM(AE17:AH17) -> 27518 | BO17: =SUM(Model!AI17:AL17) -> 29771 | BP17: =SUM(Model!AM17:AP17) -> 31797
B19: U.S. Revenue Growth Y/y | AA19: =AA15/W15-1 -> 0.24058323 | AB19: =AB15/X15-1 -> 0.23425123 | AC19: =AC15/Y15-1 -> 0.23262411 | AD19: =AD15/Z15-1 -> 0.26944354 | AE19: =AE15/AA15-1 -> 0.1984982 | AF19: =AF15/AB15-1 -> 0.18062347 | AG19: =AG15/AC15-1 -> 0.14441887 | AH19: =AH15/AD15-1 -> 0.10099974 | ... AS19: =AS15/AO15-1 -> 0.052014166 | BM19: =BM15/BL15-1 -> 0.245074 | BN19: =BN15/BM15-1 -> 0.15278588 | BO19: =BO15/BN15-1 -> 0.091478459 | BP19: =BP15/BO15-1 -> 0.058772387
B20: International Revenue Growth Y/y | AA20: =AA16/W16-1 -> 0.38203816 | AB20: =AB16/X16-1 -> 0.13639847 | AC20: =AC16/Y16-1 -> 0.025388405 | AD20: =AD16/Z16-1 -> -0.0085441998 | AE20: =AE16/AA16-1 -> -0.053198653 | AF20: =AF16/AB16-1 -> -0.0077545516 | AG20: =AG16/AC16-1 -> 0.059866962 | AH20: =AH16/AD16-1 -> 0.023533311 | ... AS20: =AS16/AO16-1 -> 0.10063082 | BM20: =BM16/BL16-1 -> 0.11665549 | BN20: =BN16/BM16-1 -> 0.0044600738 | BO20: =BO16/BN16-1 -> 0.068909572 | BP20: =BP16/BO16-1 -> 0.080843585
B21: Ttl Revenue Growth Y/y | AA21: =AA17/W17-1 -> 0.3064097 | AB21: =AB17/X17-1 -> 0.18570614 | AC21: =AC17/Y17-1 -> 0.13244184 | AD21: =AD17/Z17-1 -> 0.13113146 | AE21: =AE17/AA17-1 -> 0.074589756 | AF21: =AF17/AB17-1 -> 0.091054825 | AG21: =AG17/AC17-1 -> 0.10740861 | AH21: =AH17/AD17-1 -> 0.067215958 | ... AS21: =AS17/AO17-1 -> 0.072639225 | BM21: =BM17/BL17-1 -> 0.18257668 | BN21: =BN17/BM17-1 -> 0.084624177 | BO21: =BO17/BN17-1 -> 0.081873683 | BP21: =BP17/BO17-1 -> 0.068052803
B23: U.S. % of Ttl Revenues | W23: =W15/W17 -> 0.53464703 | X23: =X15/X17 -> 0.5038966 | Y23: =Y15/Y17 -> 0.51657813 | Z23: =Z15/Z17 -> 0.50245258 | AA23: =AA15/AA17 -> 0.50770761 | AB23: =AB15/AB17 -> 0.52452709 | AC23: =AC15/AC17 -> 0.56227758 | AD23: =AD15/AD17 -> 0.5638913 | ... AS23: =AS15/AS17 -> 0.56469051 | BL23: =BL15/BL17 -> 0.51333085 | BM23: =BM15/BM17 -> 0.54045958 | BN23: =BN15/BN17 -> 0.57442401 | BO23: =BO15/BO17 -> 0.5795237 | BP23: =BP15/BP17 -> 0.57448816
B24: International % of Ttl Revenues | W24: =W16/W17 -> 0.46535297 | X24: =X16/X17 -> 0.4961034 | Y24: =Y16/Y17 -> 0.48342187 | Z24: =Z16/Z17 -> 0.49754742 | AA24: =AA16/AA17 -> 0.49229239 | AB24: =AB16/AB17 -> 0.47547291 | AC24: =AC16/AC17 -> 0.43772242 | AD24: =AD16/AD17 -> 0.4361087 | ... AS24: =AS16/AS17 -> 0.43530949 | BL24: =BL16/BL17 -> 0.48666915 | BM24: =BM16/BM17 -> 0.45954042 | BN24: =BN16/BN17 -> 0.42557599 | BO24: =BO16/BO17 -> 0.4204763 | BP24: =BP16/BP17 -> 0.42551184
B26: Ttl Active Users | AD26: 428 | AE26: 429 | AF26: 429 | AG26: 432 | AH26: 435 | AI26: 433 | AJ26: 431 | AK26: 428 | AL26: 426 | AM26: 427 | AN26: 429 | AO26: 432 | AP26: 434 | AQ26: 432 | AR26: 438 | AS26: 432 | BN26: =AVERAGE(AE26:AH26) -> 431.25 | BO26: =AVERAGE(Model!AI26:AL26) -> 429.5 | BP26: =AVERAGE(Model!AM26:AP26) -> 430.5
B27: TPV | BL27: $936 B | BM27: $1.25 T | BN27: $1.36 T | BO27: $1.53 T | BP27: $1.68 T
B29: Revenues | C29: 2137 | D29: 2297 | E29: 2258 | F29: 2556 | G29: 2544 | H29: 2650 | I29: 2667 | J29: 2981 | K29: 2975 | L29: 3136 | M29: 3239 | N29: 3744 | O29: 3685 | P29: 3857 | Q29: 3683 | R29: 4226 | S29: 4128 | T29: 4305 | U29: 4378 | V29: 4961 | W29: =W6 -> 4618 | X29: =X6 -> 5261 | Y29: =Y6 -> 5459 | Z29: =Z6 -> 6116 | AA29: =AA6 -> 6033 | AB29: =AB6 -> 6238 | AC29: =AC6 -> 6182 | AD29: =AD6 -> 6918 | ... AS29: =AS6 -> 8417 | AT29: 8850 | AU29: 8280 | AV29: 8530 | AW29: 8630 | AX29: 9210 | AY29: 8940 | AZ29: 8970 | BA29: 9020 | BG29: =SUM(C29:F29) -> 9248 | BH29: =SUM(G29:J29) -> 10842 | BI29: =SUM(K29:N29) -> 13094 | BJ29: =SUM(O29:R29) -> 15451 | BK29: =SUM(S29:V29) -> 17772 | BL29: =SUM(W29:Z29) -> 21454 | BM29: =SUM(AA29:AD29) -> 25371 | BN29: =SUM(AE29:AH29) -> 27518 | BO29: =SUM(AI29:AL29) -> 29771 | BP29: =SUM(AM29:AP29) -> 31797 | BQ29: =BQ6 -> 33421.71 | BR29: =BR6 -> 35348.399 | BS29: =BS6 -> 37552.51 | BT29: =BT6 -> 39868.821 | BU29: =BU6 -> 42259.411 | BV29: =BV6 -> 44743.942 | BW29: =BW6 -> 47298.217 | BX29: =BX6 -> 49975.289 | ... BZ29: =BZ6 -> 55549.444
B30: Transaction Expenses | W30: 1739 | X30: 1843 | Y30: 2022 | Z30: =7934-SUM(W30:Y30) -> 2330 | AA30: 2275 | AB30: 2524 | AC30: 2564 | AD30: =10315-SUM(AA30:AC30) -> 2952 | AE30: 2817 | AF30: 3044 | AG30: 2988 | AH30: =12173-SUM(AE30:AG30) -> 3324 | AI30: 3283 | AJ30: 3541 | AK30: 3603 | AL30: =14385-SUM(AI30:AK30) -> 3958 | AM30: 3917 | AN30: 3942 | AO30: 3841 | AP30: =15697-SUM(AM30:AO30) -> 3997 | AQ30: 3704 | AR30: 3968 | AS30: 4063 | BG30: =SUM(C30:F30) -> 0 | BH30: =SUM(G30:J30) -> 0 | BI30: =SUM(K30:N30) -> 0 | BJ30: =SUM(O30:R30) -> 0 | BK30: =SUM(S30:V30) -> 0 | BL30: =SUM(W30:Z30) -> 7934 | BM30: =SUM(AA30:AD30) -> 10315 | BN30: =SUM(AE30:AH30) -> 12173 | BO30: =SUM(AI30:AL30) -> 14385 | BP30: =SUM(AM30:AP30) -> 15697 | BQ30: =BQ29*BQ45 -> 16042.421 | BR30: =BR29*BR45 -> 17143.974 | BS30: =BS29*BS45 -> 18400.73 | BT30: =BT29*BT45 -> 19735.066 | BU30: =BU29*BU45 -> 21129.706 | BV30: =BV29*BV45 -> 22819.41 | BW30: =BW29*BW45 -> 24595.073 | BX30: =BX29*BX45 -> 26486.903 | ... BZ30: =BZ29*BZ45 -> 30552.194
B31: Transaction & Credit Losses | W31: 591 | X31: 440 | Y31: 344 | Z31: =1741-SUM(W31:Y31) -> 366 | AA31: 273 | AB31: 169 | AC31: 268 | AD31: =1060-SUM(AA31:AC31) -> 350 | AE31: 369 | AF31: 448 | AG31: 367 | AH31: =1572-SUM(AE31:AG31) -> 388 | AI31: 442 | AJ31: 398 | AK31: 446 | AL31: =1682-SUM(AI31:AK31) -> 396 | AM31: 321 | AN31: 335 | AO31: 352 | AP31: =1442-SUM(AM31:AO31) -> 434 | AQ31: 371 | AR31: 476 | AS31: 483 | BG31: =SUM(C31:F31) -> 0 | BH31: =SUM(G31:J31) -> 0 | BI31: =SUM(K31:N31) -> 0 | BJ31: =SUM(O31:R31) -> 0 | BK31: =SUM(S31:V31) -> 0 | BL31: =SUM(W31:Z31) -> 1741 | BM31: =SUM(AA31:AD31) -> 1060 | BN31: =SUM(AE31:AH31) -> 1572 | BO31: =SUM(AI31:AL31) -> 1682 | BP31: =SUM(AM31:AP31) -> 1442 | BQ31: =BQ29*BQ46 -> 1771.3506 | BR31: =BR29*BR46 -> 1944.1619 | BS31: =BS29*BS46 -> 2253.1506 | BT31: =BT29*BT46 -> 1993.441 | BU31: =BU29*BU46 -> 1916.4723 | BV31: =BV29*BV46 -> 1901.6175 | BW31: =BW29*BW46 -> 1986.5251 | BX31: =BX29*BX46 -> 2048.9868 | ... BZ31: =BZ29*BZ46 -> 2221.9778
B32: Customer Support & Op. Expenses | W32: 399 | X32: 423 | Y32: 449 | Z32: =1778-SUM(W32:Y32) -> 507 | AA32: 518 | AB32: 521 | AC32: 504 | AD32: =2075-SUM(AA32:AC32) -> 532 | AE32: 534 | AF32: 536 | AG32: 509 | AH32: =2120-SUM(AE32:AG32) -> 541 | AI32: 488 | AJ32: 492 | AK32: 474 | AL32: =1919-SUM(AI32:AK32) -> 465 | AM32: 454 | AN32: 436 | AO32: 427 | AP32: =1768-SUM(AM32:AO32) -> 451 | AQ32: 398 | AR32: 413 | AS32: 447 | BG32: =SUM(C32:F32) -> 0 | BH32: =SUM(G32:J32) -> 0 | BI32: =SUM(K32:N32) -> 0 | BJ32: =SUM(O32:R32) -> 0 | BK32: =SUM(S32:V32) -> 0 | BL32: =SUM(W32:Z32) -> 1778 | BM32: =SUM(AA32:AD32) -> 2075 | BN32: =SUM(AE32:AH32) -> 2120 | BO32: =SUM(AI32:AL32) -> 1919 | BP32: =SUM(AM32:AP32) -> 1768 | BQ32: =BQ29*BQ48 -> 3141.6407 | BR32: =BR29*BR48 -> 3358.0979 | BS32: =BS29*BS48 -> 3680.146 | BT32: =BT29*BT48 -> 4066.6197 | BU32: =BU29*BU48 -> 4437.2382 | BV32: =BV29*BV48 -> 4698.1139 | BW32: =BW29*BW48 -> 4966.3128 | BX32: =BX29*BX48 -> 5247.4053 | ... BZ32: =BZ29*BZ48 -> 5832.6917
B33: Sales & Marketing Expenses | C33: 217 | D33: 215 | E33: 216 | F33: 273 | G33: 231 | H33: 261 | I33: 261 | J33: 275 | K33: 305 | L33: 282 | M33: 293 | N33: 510 | O33: 500 | P33: 503 | Q33: 405 | R33: 442 | S33: 492 | T33: 417 | U33: 401 | V33: 401 | W33: 371 | X33: 414 | Y33: 471 | Z33: =1861-SUM(W33:Y33) -> 605 | AA33: 602 | AB33: 628 | AC33: 549 | AD33: =2445-SUM(AA33:AC33) -> 666 | AE33: 594 | AF33: 595 | AG33: 544 | AH33: =2257-SUM(AE33:AG33) -> 524 | AI33: 436 | AJ33: 465 | AK33: 442 | AL33: =1809-SUM(AI33:AK33) -> 466 | AM33: 421 | AN33: 446 | AO33: 508 | AP33: =2001-SUM(AM33:AO33) -> 626 | AQ33: 488 | AR33: 583 | AS33: 521 | BG33: =SUM(C33:F33) -> 921 | BH33: =SUM(G33:J33) -> 1028 | BI33: =SUM(K33:N33) -> 1390 | BJ33: =SUM(O33:R33) -> 1850 | BK33: =SUM(S33:V33) -> 1711 | BL33: =SUM(W33:Z33) -> 1861 | BM33: =SUM(AA33:AD33) -> 2445 | BN33: =SUM(AE33:AH33) -> 2257 | BO33: =SUM(AI33:AL33) -> 1809 | BP33: =SUM(AM33:AP33) -> 2001 | BQ33: 0 | BR33: 0 | BS33: 0 | BT33: 0 | BU33: 0 | BV33: 0 | BW33: 0 | BX33: 0 | BY33: 0 | BZ33: 0
B34: R&D Expenses | C34: 185 | D34: 202 | E34: 197 | F34: 208 | G34: 195 | H34: 209 | I34: 215 | J34: 215 | K34: 214 | L34: 232 | M34: 240 | N34: 1054 | O34: 448 | P34: 441 | Q34: 452 | R34: 490 | S34: 511 | T34: 483 | U34: 533 | V34: 558 | W34: 605 | X34: 631 | Y34: 674 | Z34: =2642-SUM(W34:Y34) -> 732 | AA34: 741 | AB34: 746 | AC34: 755 | AD34: =3038-SUM(AA34:AC34) -> 796 | AE34: 815 | AF34: 815 | AG34: 801 | AH34: =3253-SUM(AE34:AG34) -> 822 | AI34: 721 | AJ34: 743 | AK34: 739 | AL34: =2973-SUM(AI34:AK34) -> 770 | AM34: 742 | AN34: 718 | AO34: 746 | AP34: =2979-SUM(AM34:AO34) -> 773 | AQ34: 731 | AR34: 767 | AS34: 801 | BG34: =SUM(C34:F34) -> 792 | BH34: =SUM(G34:J34) -> 834 | BI34: =SUM(K34:N34) -> 1740 | BJ34: =SUM(O34:R34) -> 1831 | BK34: =SUM(S34:V34) -> 2085 | BL34: =SUM(W34:Z34) -> 2642 | BM34: =SUM(AA34:AD34) -> 3038 | BN34: =SUM(AE34:AH34) -> 3253 | BO34: =SUM(AI34:AL34) -> 2973 | BP34: =SUM(AM34:AP34) -> 2979 | BQ34: =BQ29*BQ48 -> 3141.6407 | BR34: =BR29*BR48 -> 3358.0979 | BS34: =BS29*BS48 -> 3680.146 | BT34: =BT29*BT48 -> 4066.6197 | BU34: =BU29*BU48 -> 4437.2382 | BV34: =BV29*BV48 -> 4698.1139 | BW34: =BW29*BW48 -> 4966.3128 | BX34: =BX29*BX48 -> 5247.4053 | ... BZ34: =BZ29*BZ48 -> 5832.6917
B35: G&A Expenses | C35: =1815-SUM(C33:C34) -> 1413 | D35: =1899-SUM(D33:D34) -> 1482 | E35: =1928-SUM(E33:E34) -> 1515 | F35: =2145-SUM(F33:F34) -> 1664 | G35: =2137-SUM(G33:G34) -> 1711 | H35: =2279-SUM(H33:H34) -> 1809 | I35: =2319-SUM(I33:I34) -> 1843 | J35: =2521-SUM(J33:J34) -> 2031 | K35: =2544-SUM(K33:K34) -> 2025 | L35: =2706-SUM(L33:L34) -> 2192 | M35: =2816-SUM(M33:M34) -> 2283 | N35: =2901-SUM(N33:N34) -> 1337 | O35: =3151-SUM(O33:O34) -> 2203 | P35: =3285-SUM(P33:P34) -> 2341 | Q35: =3193-SUM(Q33:Q34) -> 2336 | R35: =3628-SUM(R33:R34) -> 2696 | S35: =3610-SUM(S33:S34) -> 2607 | T35: =3600-SUM(T33:T34) -> 2700 | U35: =3681-SUM(U33:U34) -> 2747 | V35: =4162-SUM(V33:V34) -> 3203 | W35: 486 | X35: 512 | Y35: 503 | Z35: =2070-SUM(W35:Y35) -> 569 | AA35: 524 | AB35: 522 | AC35: 498 | AD35: =2114-SUM(AA35:AC35) -> 570 | AE35: 607 | AF35: 514 | AG35: 463 | AH35: =2099-SUM(AE35:AG35) -> 515 | AI35: 507 | AJ35: 491 | AK35: 507 | AL35: =2059-SUM(AI35:AK35) -> 554 | AM35: 464 | AN35: 570 | AO35: 519 | AP35: =2147-SUM(AM35:AO35) -> 594 | AQ35: 503 | AR35: 461 | AS35: 513 | BG35: =SUM(C35:F35) -> 6074 | BH35: =SUM(G35:J35) -> 7394 | BI35: =SUM(K35:N35) -> 7837 | BJ35: =SUM(O35:R35) -> 9576 | BK35: =SUM(S35:V35) -> 11257 | BL35: =SUM(W35:Z35) -> 2070 | BM35: =SUM(AA35:AD35) -> 2114 | BN35: =SUM(AE35:AH35) -> 2099 | BO35: =SUM(AI35:AL35) -> 2059 | BP35: =SUM(AM35:AP35) -> 2147 | BQ35: =BQ29*BQ49 -> 4144.292 | BR35: =BR29*BR49 -> 4418.5499 | BS35: =BS29*BS49 -> 4506.3012 | BT35: =BT29*BT49 -> 4704.5209 | BU35: =BU29*BU49 -> 4859.8323 | BV35: =BV29*BV49 -> 5145.5533 | BW35: =BW29*BW49 -> 5321.0495 | BX35: =BX29*BX49 -> 5497.2818 | ... BZ35: =BZ29*BZ49 -> 5554.9444
B36: Restructuring & Other Expenses | W36: 29 | X36: 47 | Y36: 19 | Z36: =139-SUM(W36:Y36) -> 44 | AA36: 58 | AB36: 1 | AC36: 1 | AD36: =62-SUM(AA36:AC36) -> 2 | AE36: 36 | AF36: 90 | AG36: 56 | AH36: =207-SUM(AE36:AG36) -> 25 | AI36: 164 | AJ36: 24 | AK36: 39 | AL36: =-84-SUM(AI36:AK36) -> -311 | AM36: 212 | AN36: 113 | AO36: 63 | AP36: =438-SUM(AM36:AO36) -> 50 | AQ36: 66 | AR36: 116 | AS36: 69 | BG36: =SUM(C36:F36) -> 0 | BH36: =SUM(G36:J36) -> 0 | BI36: =SUM(K36:N36) -> 0 | BJ36: =SUM(O36:R36) -> 0 | BK36: =SUM(S36:V36) -> 0 | BL36: =SUM(W36:Z36) -> 139 | BM36: =SUM(AA36:AD36) -> 62 | BN36: =SUM(AE36:AH36) -> 207 | BO36: =SUM(AI36:AL36) -> -84 | BP36: =SUM(AM36:AP36) -> 438 | BQ36: 0 | BR36: 0 | BS36: 0 | BT36: 0 | BU36: 0 | BV36: 0 | BW36: 0 | BX36: 0 | BY36: 0 | BZ36: 0
B37: Operating Income | C37: =C29-SUM(C30:C36) -> 322 | D37: =D29-SUM(D30:D36) -> 398 | E37: =E29-SUM(E30:E36) -> 330 | F37: =F29-SUM(F30:F36) -> 411 | G37: =G29-SUM(G30:G36) -> 407 | H37: =H29-SUM(H30:H36) -> 371 | I37: =I29-SUM(I30:I36) -> 348 | J37: =J29-SUM(J30:J36) -> 460 | ... AS37: =AS29-SUM(AS30:AS36) -> 1520 | BG37: =SUM(C37:F37) -> 1461 | BH37: =SUM(G37:J37) -> 1586 | BI37: =SUM(K37:N37) -> 2127 | BJ37: =SUM(O37:R37) -> 2194 | BK37: =SUM(S37:V37) -> 2719 | BL37: =SUM(W37:Z37) -> 3289 | BM37: =SUM(AA37:AD37) -> 4262 | BN37: =SUM(AE37:AH37) -> 3837 | BO37: =SUM(AI37:AL37) -> 5028 | BP37: =SUM(AM37:AP37) -> 5325 | BQ37: =BQ29-SUM(BQ30:BQ36) -> 5180.3651 | BR37: =BR29-SUM(BR30:BR36) -> 5125.5179 | BS37: =BS29-SUM(BS30:BS36) -> 5032.0363 | BT37: =BT29-SUM(BT30:BT36) -> 5302.5532 | BU37: =BU29-SUM(BU30:BU36) -> 5478.9246 | BV37: =BV29-SUM(BV30:BV36) -> 5481.1329 | BW37: =BW29-SUM(BW30:BW36) -> 5462.9441 | BX37: =BX29-SUM(BX30:BX36) -> 5447.3065 | ... BZ37: =BZ29-SUM(BZ30:BZ36) -> 5554.9444
B38: Other Income/(Expenses), net | C38: -1 | D38: 1 | E38: 20 | F38: 7 | G38: 15 | H38: 9 | I38: 12 | J38: 9 | K38: 7 | L38: 17 | M38: 28 | N38: 21 | O38: 14 | P38: 37 | Q38: 43 | R38: 88 | S38: 199 | T38: 238 | U38: -213 | V38: 55 | W38: -135 | X38: 848 | Y38: 167 | Z38: =1776-SUM(W38:Y38) -> 896 | AA38: -170 | AB38: 229 | AC38: 122 | AD38: =-163-SUM(AA38:AC38) -> -344 | AE38: -82 | AF38: -715 | AG38: 460 | AH38: =-471-SUM(AE38:AG38) -> -134 | AI38: 75 | AJ38: 170 | AK38: 73 | AL38: =383-SUM(AI38:AK38) -> 65 | AM38: 41 | AN38: 74 | AO38: -80 | AP38: =4-SUM(AM38:AO38) -> -31 | AQ38: 73 | AR38: 25 | AS38: 13 | BG38: =SUM(C38:F38) -> 27 | BH38: =SUM(G38:J38) -> 45 | BI38: =SUM(K38:N38) -> 73 | BJ38: =SUM(O38:R38) -> 182 | BK38: =SUM(S38:V38) -> 279 | BL38: =SUM(W38:Z38) -> 1776 | BM38: =SUM(AA38:AD38) -> -163 | BN38: =SUM(AE38:AH38) -> -471 | BO38: =SUM(AI38:AL38) -> 383 | BP38: =SUM(AM38:AP38) -> 4 | BQ38: =BP54*$BZ$56 -> 387.099 | BR38: =BQ54*$BZ$56 -> 654.15355 | BS38: =BR54*$BZ$56 -> 932.06905 | BT38: =BS54*$BZ$56 -> 1220.6125 | BU38: =BT54*$BZ$56 -> 1536.2032 | BV38: =BU54*$BZ$56 -> 1875.5951 | BW38: =BV54*$BZ$56 -> 2231.5136 | BX38: =BW54*$BZ$56 -> 2603.7715 | ... BZ38: =BY54*$BZ$56 -> 3418.7121
B39: Pretax Income | C39: =C37+C38 -> 321 | D39: =D37+D38 -> 399 | E39: =E37+E38 -> 350 | F39: =F37+F38 -> 418 | G39: =G37+G38 -> 422 | H39: =H37+H38 -> 380 | I39: =I37+I38 -> 360 | J39: =J37+J38 -> 469 | ... AS39: =AS37+AS38 -> 1533 | BG39: =SUM(C39:F39) -> 1488 | BH39: =SUM(G39:J39) -> 1631 | BI39: =SUM(K39:N39) -> 2200 | BJ39: =SUM(O39:R39) -> 2376 | BK39: =SUM(S39:V39) -> 2998 | BL39: =SUM(W39:Z39) -> 5065 | BM39: =SUM(AA39:AD39) -> 4099 | BN39: =SUM(AE39:AH39) -> 3366 | BO39: =SUM(AI39:AL39) -> 5411 | BP39: =SUM(AM39:AP39) -> 5329 | BQ39: =BQ37+BQ38 -> 5567.4641 | BR39: =BR37+BR38 -> 5779.6714 | BS39: =BS37+BS38 -> 5964.1054 | BT39: =BT37+BT38 -> 6523.1656 | BU39: =BU37+BU38 -> 7015.1279 | BV39: =BV37+BV38 -> 7356.728 | BW39: =BW37+BW38 -> 7694.4577 | BX39: =BX37+BX38 -> 8051.078 | ... BZ39: =BZ37+BZ38 -> 8973.6566
B40: Taxes | C40: 66 | D40: 94 | E40: 49 | F40: 51 | G40: 57 | H40: 57 | I40: 37 | J40: 79 | K40: 54 | L40: 36 | M40: 71 | N40: 244 | O40: 37 | P40: 83 | Q40: 97 | R40: 102 | S40: 50 | T40: 120 | U40: 22 | V40: 347 | W40: 179 | X40: 269 | Y40: 123 | Z40: =863-SUM(W40:Y40) -> 292 | AA40: -225 | AB40: 172 | AC40: 78 | AD40: =-70-SUM(AA40:AC40) -> -95 | AE40: 120 | AF40: 390 | AG40: 248 | AH40: =947-SUM(AE40:AG40) -> 189 | AI40: 279 | AJ40: 274 | AK40: 221 | AL40: =1165-SUM(AI40:AK40) -> 391 | AM40: 321 | AN40: 271 | AO40: 301 | AP40: =1182-SUM(AM40:AO40) -> 289 | AQ40: 316 | AR40: 268 | AS40: 285 | BG40: =SUM(C40:F40) -> 260 | BH40: =SUM(G40:J40) -> 230 | BI40: =SUM(K40:N40) -> 405 | BJ40: =SUM(O40:R40) -> 319 | BK40: =SUM(S40:V40) -> 539 | BL40: =SUM(W40:Z40) -> 863 | BM40: =SUM(AA40:AD40) -> -70 | BN40: =SUM(AE40:AH40) -> 947 | BO40: =SUM(AI40:AL40) -> 1165 | BP40: =SUM(AM40:AP40) -> 1182 | BQ40: =BQ39*BQ51 -> 1041.1158 | BR40: =BR39*BR51 -> 1069.2392 | BS40: =BS39*BS51 -> 1073.539 | BT40: =BT39*BT51 -> 1174.1698 | BU40: =BU39*BU51 -> 1262.723 | BV40: =BV39*BV51 -> 1324.211 | BW40: =BW39*BW51 -> 1385.0024 | BX40: =BX39*BX51 -> 1449.194 | ... BZ40: =BZ39*BZ51 -> 1615.2582
B41: Net Income | C41: =C39-C40 -> 255 | D41: =D39-D40 -> 305 | E41: =E39-E40 -> 301 | F41: =F39-F40 -> 367 | G41: =G39-G40 -> 365 | H41: =H39-H40 -> 323 | I41: =I39-I40 -> 323 | J41: =J39-J40 -> 390 | ... AS41: =AS39-AS40 -> 1248 | AT41: 1290 | AU41: 1150 | AV41: 1200 | AW41: 1250 | AX41: 1380 | AY41: 1280 | AZ41: 1340 | BA41: 1360 | BG41: =SUM(C41:F41) -> 1228 | BH41: =SUM(G41:J41) -> 1401 | BI41: =SUM(K41:N41) -> 1795 | BJ41: =SUM(O41:R41) -> 2057 | BK41: =SUM(S41:V41) -> 2459 | BL41: =SUM(W41:Z41) -> 4202 | BM41: =SUM(AA41:AD41) -> 4169 | BN41: =SUM(AE41:AH41) -> 2419 | BO41: =SUM(AI41:AL41) -> 4246 | BP41: =SUM(AM41:AP41) -> 4147 | BQ41: =BQ39-BQ40 -> 4526.3483 | BR41: =BR39-BR40 -> 4710.4322 | BS41: =BS39-BS40 -> 4890.5664 | BT41: =BT39-BT40 -> 5348.9958 | BU41: =BU39-BU40 -> 5752.4048 | BV41: =BV39-BV40 -> 6032.5169 | BW41: =BW39-BW40 -> 6309.4553 | BX41: =BX39-BX40 -> 6601.8839 | ... BZ41: =BZ39-BZ40 -> 7358.3984 | CA41: =BZ41*(1+$BZ$57) -> 7450.3784 | CB41: =CA41*(1+$BZ$57) -> 7543.5081 | CC41: =CB41*(1+$BZ$57) -> 7637.8019 | CD41: =CC41*(1+$BZ$57) -> 7733.2745 | CE41: =CD41*(1+$BZ$57) -> 7829.9404 | CF41: =CE41*(1+$BZ$57) -> 7927.8147 | CG41: =CF41*(1+$BZ$57) -> 8026.9123 | CH41: =CG41*(1+$BZ$57) -> 8127.2487 | ... DX41: =DW41*(1+$BZ$57) -> 13694.144
B42: SC | C42: 1218 | D42: 1218 | E42: 1221 | F42: 1222 | G42: 1216 | H42: 1210 | I42: 1207 | J42: 1210 | K42: 1203 | L42: 1202 | M42: 1202 | N42: 1203 | O42: 1192 | P42: 1187 | Q42: 1181 | R42: 1184 | S42: 1171 | T42: 1175 | U42: 1175 | V42: 1174 | W42: 1185 | X42: 1184 | Y42: 1190 | Z42: 1174 | AA42: 1190 | AB42: 1186 | AC42: 1187 | AD42: 1174 | AE42: 1163 | AF42: 1158 | AG42: 1157 | AH42: 1131 | AI42: 1134 | AJ42: 1114 | AK42: 1098 | AL42: 1071 | AM42: 1072 | AN42: 1047 | AO42: 1024 | AP42: 989 | AQ42: 986 | AR42: 969 | AS42: 950 | AT42: =AT41/AT43 -> 962.68657 | AU42: =AU41/AU43 -> 884.61538 | AV42: =AV41/AV43 -> 857.14286 | AW42: =AW41/AW43 -> 850.34014 | AX42: =AX41/AX43 -> 971.83099 | AY42: =AY41/AY43 -> 831.16883 | AZ42: =AZ41/AZ43 -> 858.97436 | BA42: =BA41/BA43 -> 814.37126 | BG42: =AVERAGE(C42:F42) -> 1219.75 | BH42: =AVERAGE(G42:J42) -> 1210.75 | BI42: =AVERAGE(K42:N42) -> 1202.5 | BJ42: =AVERAGE(O42:R42) -> 1186 | BK42: =AVERAGE(S42:V42) -> 1173.75 | BL42: =AVERAGE(W42:Z42) -> 1183.25 | BM42: =AVERAGE(AA42:AD42) -> 1184.25 | BN42: =AVERAGE(AE42:AH42) -> 1152.25 | BO42: =AVERAGE(AI42:AL42) -> 1104.25 | BP42: =AVERAGE(AM42:AP42) -> 1033
B43: EPS | C43: =C41/C42 -> 0.20935961 | D43: =D41/D42 -> 0.25041051 | E43: =E41/E42 -> 0.24651925 | F43: =F41/F42 -> 0.30032733 | G43: =G41/G42 -> 0.30016447 | H43: =H41/H42 -> 0.26694215 | I43: =I41/I42 -> 0.26760563 | J43: =J41/J42 -> 0.32231405 | ... AS43: =AS41/AS42 -> 1.3136842 | AT43: 1.34 | AU43: 1.3 | AV43: 1.4 | AW43: 1.47 | AX43: 1.42 | AY43: 1.54 | AZ43: 1.56 | BA43: 1.67 | BG43: =SUM(C43:F43) -> 1.0066167 | BH43: =SUM(G43:J43) -> 1.1570263 | BI43: =SUM(K43:N43) -> 1.4926501 | BJ43: =SUM(O43:R43) -> 1.7342471 | BK43: =SUM(S43:V43) -> 2.0950726 | BL43: =SUM(W43:Z43) -> 3.555852 | BM43: =SUM(AA43:AD43) -> 3.5181992 | BN43: =SUM(AE43:AH43) -> 2.1070362 | BO43: =SUM(AI43:AL43) -> 3.8627753 | BP43: =SUM(AM43:AP43) -> 4.0255184
B45: Transaction Expenses % of Revenue | W45: =W30/W29 -> 0.37656994 | X45: =X30/X29 -> 0.35031363 | Y45: =Y30/Y29 -> 0.37039751 | Z45: =Z30/Z29 -> 0.38096795 | AA45: =AA30/AA29 -> 0.37709266 | AB45: =AB30/AB29 -> 0.40461686 | AC45: =AC30/AC29 -> 0.41475251 | AD45: =AD30/AD29 -> 0.42671292 | ... AS45: =AS30/AS29 -> 0.48271356 | BL45: =BL30/BL29 -> 0.36981449 | BM45: =BM30/BM29 -> 0.40656655 | BN45: =BN30/BN29 -> 0.442365 | BO45: =BO30/BO29 -> 0.48318834 | BP45: =BP30/BP29 -> 0.49366292 | BQ45: 0.48 | BR45: 0.485 | BS45: 0.49 | BT45: 0.495 | BU45: 0.5 | BV45: 0.51 | BW45: 0.52 | BX45: 0.53 | BY45: 0.54 | BZ45: 0.55
B46: Transaction & Credit Losses % of Revenue | W46: =W31/W29 -> 0.12797748 | X46: =X31/X29 -> 0.08363429 | Y46: =Y31/Y29 -> 0.063015204 | Z46: =Z31/Z29 -> 0.059843035 | AA46: =AA31/AA29 -> 0.045251119 | AB46: =AB31/AB29 -> 0.027092017 | AC46: =AC31/AC29 -> 0.043351666 | AD46: =AD31/AD29 -> 0.050592657 | ... AS46: =AS31/AS29 -> 0.057383866 | BL46: =BL31/BL29 -> 0.081150368 | BM46: =BM31/BM29 -> 0.041779985 | BN46: =BN31/BN29 -> 0.057126245 | BO46: =BO31/BO29 -> 0.056497934 | BP46: =BP31/BP29 -> 0.04535019 | BQ46: 0.053 | BR46: 0.055 | BS46: 0.06 | BT46: 0.05 | BU46: 0.04535019 | BV46: 0.0425 | BW46: 0.042 | BX46: 0.041 | BY46: 0.04 | BZ46: 0.04
B47: Customer Support & Op. Expenses % of Revenue | W47: =W32/W29 -> 0.086401039 | X47: =X32/X29 -> 0.080402965 | Y47: =Y32/Y29 -> 0.082249496 | Z47: =Z32/Z29 -> 0.082897319 | AA47: =AA32/AA29 -> 0.085861097 | AB47: =AB32/AB29 -> 0.083520359 | AC47: =AC32/AC29 -> 0.081527014 | AD47: =AD32/AD29 -> 0.076900838 | ... AS47: =AS32/AS29 -> 0.053106808 | BL47: =BL32/BL29 -> 0.082874988 | BM47: =BM32/BM29 -> 0.081786291 | BN47: =BN32/BN29 -> 0.077040483 | BO47: =BO32/BO29 -> 0.064458701 | BP47: =BP32/BP29 -> 0.05560273 | BQ47: 0.052 | BR47: 0.05 | BS47: 0.049 | BT47: 0.048 | BU47: 0.047 | BV47: 0.046 | BW47: 0.045 | BX47: 0.045 | BY47: 0.045 | BZ47: 0.045
B48: R&D as % of Revenue | C48: =C34/C29 -> 0.086569958 | D48: =D34/D29 -> 0.087940792 | E48: =E34/E29 -> 0.08724535 | F48: =F34/F29 -> 0.081377152 | G48: =G34/G29 -> 0.076650943 | H48: =H34/H29 -> 0.078867925 | I48: =I34/I29 -> 0.080614923 | J48: =J34/J29 -> 0.072123449 | ... AS48: =AS34/AS29 -> 0.095164548 | BL48: =BL34/BL29 -> 0.1231472 | BM48: =BM34/BM29 -> 0.11974301 | BN48: =BN34/BN29 -> 0.11821353 | BO48: =BO34/BO29 -> 0.099862282 | BP48: =BP34/BP29 -> 0.093688084 | BQ48: 0.094 | BR48: 0.095 | BS48: 0.098 | BT48: 0.102 | BU48: 0.105 | BV48: 0.105 | BW48: 0.105 | BX48: 0.105 | BY48: 0.105 | BZ48: 0.105
...

Sheet Notes | Quant Analysis
CA1: 0
H2: Employee Scope: | AD2: General Notes/Observations (Updated Q1'25)
AD4: TPV is the sole most important "macro" figure for PayPal. PayPal's revenues are directly correlated with TPV --> a focus of management should be on network access/boosting conversion rates
AE5: BNPL services allow for a greater sum of users to access "credit" and make transactions they otherwise may have held off on --> increases TPV --> must analyze consumer credit risks to ensure recollection of loaned funds
AE6: User growth has stagnated for the last couple of years; TPV is still growing faster than GDP… check against inflation/money supply growth
AF7: 60% of 2025 Coachella tickets were purchased using BNPL services… LMAOO
AD9: Operating income margin will be important to track very closely for short term modeling
AE10: Operating margin better tracks the true operating performance on a Q/q basis ex 1 time cash inflows from other incomes and divestments
AD12: A brief observation I had while scoping out the balance sheet was in regards to the refinancing of $1.5 billion in bonds terming out in 2025
AE13: The notes terming out were issued before the FED hiking cycle beginning Mar. '22, having effective interest rates below 2%
AE14: The newly issued notes have effective interest rates between 4.5-5%, a 2-3x increase in borrowing costs
AD15: 2025 is expected to see a disproportionately large wave of corporate debt refinancing from the 2020-2021 low rate era. Refinancing will happen at a much higher rate across the board.
AE16: From a macro perspective -> watching credit spreads, default rates and credit revaluations will be important to monitor throughout the year
AE17: Looking at the CME tool, 3 FED cuts are currently priced in for year end overnight lending rates between 3.5-3.75%
AD19: My model is relatively conservative with most future projected figures, except for operating margin (which I believe will see some decent expansion over FY '25 due to Braintree contract renegotiations). I believe PayPal is a decent long around the ($55-65) range and have an initial price target of ~$85… could be an incredible value trap though as there are a few challenges I feel will be difficult for the firm to overcome.
AD20: The Company's valuation multiples is discounted in comparison to peers... the firm has anemic user growth, and is continuing to spend on expensive marketing campaigns, all while competing firms continue to seize market share in virtually every category PayPal operates in
AD21: PayPal operates in many high value markets including:
AE22: Operating a traditional payment network/CC offerings (competing with V, MA, and AXP)
AE23: Digital wallets (competing with AAPL, GOOG, XYZ, Zelle)
AE24: BNPL (competing with AFRM, XYZ and Klarna)
AE25: E-Commerce payment processing (competing with XYY, ADYEY, SHOP)
I32: Notes: | J32: [X]
J33: [Y]
J34: [Z]
AD35: Financial Stmts. Notes/Observations (Updated Q1'25)
H36: Institutional Ownership Snapshot (4/14/2025) | AD36: Revenues:
I64: Notes: | J64: [X]
J65: [Y]
J66: [Z]
H68: Revenue Breakdown by Segment | AD68: Earnings Scope:
I100: Notes: | J100: [X]
J101: [Y]
J102: [Z]
H104: Q/q Total Revenues, Net Income, FCF | AD104: Balance Sheet Scope:
I133: Notes: | J133: [X]
J134: [Y]
J135: [Z]
H137: Y/y Total Revenues, Net Income, FCF | AD137: [Equity Preformance Compared to Peers]
I166: Notes: | J166: [X]
J167: [Y]
...

Sheet Product Lines

Sheet Management

Sheet Table Formatting
B2: [Bold Title] | G2: [Bold Title]
B3: Line Titles | G3: <-- General
B4: Line Titles | G4: <-- Info
B5: Line Titles | G5: <-- General
B6: Line Titles | G6: <-- Info
B7: Line Titles | G7: <-- General
B8: Line Titles | G8: <-- Info
