Workbook

Sheet Main
B2: RTX
B3: Price | C3: 192.23 | D3: 10/21/2026
B4: SO | C4: 1347.758 | D4: Q3'26
B5: MC | C5: =C3*C4 -> 259079.52
B6: Cash | C6: 9173 | D6: Q3'26
B7: Debt | C7: =210+5679+31490 -> 37379 | D7: Q3'26
B8: EV | C8: =C5-C6+C7 -> 287285.52
B10: RTX Corporation (RTX)
B12: Founder(s): Vannevar Bush, Laurence K. Marshall, Charles G. Smith | F12: Registered Exchange: NYSE | N12: Resources:
B13: Founded: 1922 | F13: Address: 1000 Wilson Boulevard, Arlington, VA 22209 U.S. | N13: SEC filings | Q13: https://www.sec.gov/edgar/browse/?CIK=101829&owner=exclude
B14: Headquarters: Arlington, VA | F14: Investor Relations Contact: | N14: Company Homepage | Q14: https://www.rtx.com/
B15: Current CEO: Christopher Calio | F15: Investors Relation Department | O15: Company IR Page | R15: https://investors.rtx.com/#Investors
B16: Employees: 180,000 | F16: Phone: | G16: (781) 522 - 3000 | I16: Email: | N16: Earnings Calls | Q16: https://seekingalpha.com/symbol/RTX/earnings/transcripts
B17: Industry: Aerospace & Defense | N17: Equity Analysis | Q17: https://stockanalysis.com/stocks/rtx/company/
B18: Sector: Industrials | N18: MacroTrends | Q18: https://www.macrotrends.net/stocks/charts/RTX/rtx/income-statement
B19: IPO: September 15, 1952 | N19: ROIC, WACC | Q19: https://www.gurufocus.com/term/wacc/RTX
B20: Fiscal Year: [January - December] | N20: Godel Terminal | Q20: https://app.godelterminal.com/
A22: Company Overview:
B23: RTX Corporation, an aerospace and defense company, provides systems and services for commercial, military, and government customers worldwide
B24: The Company operates through three segments: Collins Aerospace (Collins), Pratt & Whitney, and Raytheon
C25: The Collins segment offers aerospace and defense products, and aftermarket services for civil and military aircraft manufacturers and commercial airlines, as well as regional, business, and general aviation, defense, and commercial space operations
D26: This segment designs, manufactures, and supplies electric power generation and management and distribution, environmental control, flight control, air data and aircraft sensing, engine control, and engine nacelle systems, as well as engine components
D27: cabin interiors, including seating, oxygen, food and beverage preparation, storage and galley, lavatory, and wastewater management systems; connected aviation solutions and services; and systems solutions for connected battlespace, test and training range systems, crew escape systems, and simulation and training
D28: It also provides spare parts, overhaul and repair, engineering and technical support, training and fleet management solutions, and asset and information management services
C29: The Pratt & Whitney segment supplies aircraft engines for commercial, military, business jet, and general aviation customers; and produces, sells, and services military and commercial auxiliary power units, as well as offers fleet management and aftermarket maintenance, repair, and overhaul services
C30: The Raytheon segment provides defensive and offensive threat detection, tracking, and mitigation capabilities for government and commercial customers
D31: This segment offers sensors, mission orchestration and satellite control products, and software. The company was formerly known as Raytheon Technologies Corporation and changed its name to RTX Corporation in July 2023
B32: RTX Corporation was incorporated in 1934 and is headquartered in Arlington, Virginia
A34: Business Segments and Geographical Info:
B35: [Begin researching fundamentals / core business … begin with SEC filings, but expand and use all public resources available]

Sheet Model
B1: [Use for Graphing] | AI1: Q1 2020 | AM1: Q1 2021 | AQ1: Q1 2022 | AU1: Q1 2023 | AY1: Q1 2024 | BC1: Q1 2025 | BG1: Q1 2026
B2: Quarterly
B3: Revenues | C3: {="Q"&MOD(_xlfn.SEQUENCE(1,60)-1,4)+1&" "&(2012+INT((_xlfn.SEQUENCE(1,60)-1)/4))} -> Q1 2012 | D3: Q2 2012 | E3: Q3 2012 | F3: Q4 2012 | G3: Q1 2013 | H3: Q2 2013 | I3: Q3 2013 | J3: Q4 2013 | K3: Q1 2014 | L3: Q2 2014 | M3: Q3 2014 | N3: Q4 2014 | O3: Q1 2015 | P3: Q2 2015 | Q3: Q3 2015 | R3: Q4 2015 | S3: Q1 2016 | T3: Q2 2016 | U3: Q3 2016 | V3: Q4 2016 | W3: Q1 2017 | X3: Q2 2017 | Y3: Q3 2017 | Z3: Q4 2017 | AA3: Q1 2018 | AB3: Q2 2018 | AC3: Q3 2018 | AD3: Q4 2018 | AE3: Q1 2019 | AF3: Q2 2019 | AG3: Q3 2019 | AH3: Q4 2019 | AI3: Q1 2020 | AJ3: Q2 2020 | AK3: Q3 2020 | AL3: Q4 2020 | AM3: Q1 2021 | AN3: Q2 2021 | AO3: Q3 2021 | AP3: Q4 2021 | AQ3: Q1 2022 | AR3: Q2 2022 | AS3: Q3 2022 | AT3: Q4 2022 | AU3: Q1 2023 | AV3: Q2 2023 | AW3: Q3 2023 | AX3: Q4 2023 | AY3: Q1 2024 | AZ3: Q2 2024 | BA3: Q3 2024 | BB3: Q4 2024 | BC3: Q1 2025 | BD3: Q2 2025 | BE3: Q3 2025 | BF3: Q4 2025 | BG3: Q1 2026 | BH3: Q2 2026 | BI3: Q3 2026 | BJ3: Q4 2026 | BS3: 2012 | BT3: =BS3+1 -> 2013 | BU3: =BT3+1 -> 2014 | BV3: =BU3+1 -> 2015 | BW3: =BV3+1 -> 2016 | BX3: =BW3+1 -> 2017 | BY3: =BX3+1 -> 2018 | BZ3: =BY3+1 -> 2019 | CA3: =BZ3+1 -> 2020 | ... EN3: =EM3+1 -> 2085
B4: Collins Aerospace | AM4: 4370 | AN4: 4545 | AO4: 4592 | AP4: =18449-SUM(AM4:AO4) -> 4942 | AQ4: 4824 | AR4: 5011 | AS4: 5718 | AT4: =20597-SUM(AQ4:AS4) -> 5044 | AU4: 6120 | AV4: 6384 | AW4: 6629 | AX4: =26253-SUM(AU4:AW4) -> 7120 | AY4: 6673 | AZ4: 6999 | BA4: 7075 | BB4: =28284-SUM(AY4:BA4) -> 7537 | BC4: 7217 | BD4: 7622 | BE4: 7621 | BF4: =30196-SUM(BC4:BE4) -> 7736 | BG4: 7602 | BH4: 8210 | BI4: 8382 | CB4: =SUM(AM4:AP4) -> 18449 | CC4: =SUM(AQ4:AT4) -> 20597 | CD4: =SUM(AU4:AX4) -> 26253 | CE4: =SUM(AY4:BB4) -> 28284 | CF4: =SUM(BC4:BF4) -> 30196 | CG4: =CF4*(1+CG10) -> 32460.7 | CH4: =CG4*(1+CH10) -> 35382.163 | CI4: =CH4*(1+CI10) -> 39097.29 | CJ4: =CI4*(1+CJ10) -> 42811.533 | CK4: =CJ4*(1+CK10) -> 46236.455 | CL4: =CK4*(1+CL10) -> 49010.643 | CM4: =CL4*(1+CM10) -> 51706.228 | CN4: =CM4*(1+CN10) -> 54291.539 | ... CP4: =CO4*(1+CP10) -> 59004.045
B5: Pratt & Whitney | AM5: 4030 | AN5: 4280 | AO5: 4725 | AP5: =18150-SUM(AM5:AO5) -> 5115 | AQ5: 4529 | AR5: 4969 | AS5: 5380 | AT5: =20530-SUM(AQ5:AS5) -> 5652 | AU5: 5230 | AV5: 5701 | AW5: 926 | AX5: =18296-SUM(AU5:AW5) -> 6439 | AY5: 6456 | AZ5: 6802 | BA5: 7239 | BB5: =28066-SUM(AY5:BA5) -> 7569 | BC5: 7366 | BD5: 7631 | BE5: 8423 | BF5: =32916-SUM(BC5:BE5) -> 9496 | BG5: 8173 | BH5: 8889 | BI5: 9231 | CB5: =SUM(AM5:AP5) -> 18150 | CC5: =SUM(AQ5:AT5) -> 20530 | CD5: =SUM(AU5:AX5) -> 18296 | CE5: =SUM(AY5:BB5) -> 28066 | CF5: =SUM(BC5:BF5) -> 32916 | CG5: =CF5*(1+CG11) -> 37030.5 | CH5: =CG5*(1+CH11) -> 42214.77 | CI5: =CH5*(1+CI11) -> 48546.986 | CJ5: =CI5*(1+CJ11) -> 54858.094 | CK5: =CJ5*(1+CK11) -> 60892.484 | CL5: =CK5*(1+CL11) -> 66372.807 | CM5: =CL5*(1+CM11) -> 71018.904 | CN5: =CM5*(1+CN11) -> 75280.038 | ... CP5: =CO5*(1+CP11) -> 82205.802
B6: Raytheon Intelligence & Space + Missiles & Defense | AM6: =3765+3793 -> 7558 | AN6: =3805+3985 -> 7790 | AO6: =3740+3902 -> 7642 | AP6: =15180+15539-SUM(AM6:AO6) -> 7729 | AQ6: =3572+3527 -> 7099 | AR6: =3570+3558 -> 7128 | AS6: 6308 | AT6: =14312+14863-SUM(AQ6:AS6) -> 8640 | AU6: 6292 | AV6: 6700 | AW6: 6472 | AX6: =26350-SUM(AU6:AW6) -> 6886 | AY6: 6659 | AZ6: 6511 | BA6: 6386 | BB6: =26713-SUM(AY6:BA6) -> 7157 | BC6: 6340 | BD6: 7001 | BE6: 7045 | BF6: =28043-SUM(BC6:BE6) -> 7657 | BG6: 6945 | BH6: 8269 | BI6: 8031 | CB6: =SUM(AM6:AP6) -> 30719 | CC6: =SUM(AQ6:AT6) -> 29175 | CD6: =SUM(AU6:AX6) -> 26350 | CE6: =SUM(AY6:BB6) -> 26713 | CF6: =SUM(BC6:BF6) -> 28043 | CG6: =CF6*(1+CG12) -> 31688.59 | CH6: =CG6*(1+CH12) -> 36441.878 | CI6: =CH6*(1+CI12) -> 40450.485 | CJ6: =CI6*(1+CJ12) -> 44091.029 | CK6: =CJ6*(1+CK12) -> 47618.311 | CL6: =CK6*(1+CL12) -> 49999.227 | CM6: =CL6*(1+CM12) -> 51499.203 | CN6: =CM6*(1+CN12) -> 52529.188 | ... CP6: =CO6*(1+CP12) -> 54250.175
B7: Intersegment Eliminations | AM7: -707 | AN7: -735 | AO7: -746 | AP7: =-2930-SUM(AM7:AO7) -> -742 | AQ7: -736 | AR7: -794 | AS7: -455 | AT7: =-3228-SUM(AQ7:AS7) -> -1243 | AU7: -428 | AV7: -470 | AW7: -563 | AX7: =-1979-SUM(AU7:AW7) -> -518 | AY7: -483 | AZ7: -591 | BA7: -611 | BB7: =-2325-SUM(AY7:BA7) -> -640 | BC7: -617 | BD7: -673 | BE7: -611 | BF7: =-2552-SUM(BC7:BE7) -> -651 | BG7: -644 | BH7: -660 | BI7: -679 | CB7: =SUM(AM7:AP7) -> -2930 | CC7: =SUM(AQ7:AT7) -> -3228 | CD7: =SUM(AU7:AX7) -> -1979 | CE7: =SUM(AY7:BB7) -> -2325 | CF7: =SUM(BC7:BF7) -> -2552 | CG7: =CF7*(1+CG13) -> -2603.04 | CH7: =CG7*(1+CH13) -> -2707.1616 | CI7: =CH7*(1+CI13) -> -2815.4481 | CJ7: =CI7*(1+CJ13) -> -2871.757 | CK7: =CJ7*(1+CK13) -> -2929.1922 | CL7: =CK7*(1+CL13) -> -2987.776 | CM7: =CL7*(1+CM13) -> -3047.5315 | CN7: =CM7*(1+CN13) -> -3108.4822 | ... CP7: =CO7*(1+CP13) -> -3234.0648
B8: Ttl Revenues | AM8: =SUM(AM4:AM7) -> 15251 | AN8: =SUM(AN4:AN7) -> 15880 | AO8: =SUM(AO4:AO7) -> 16213 | AP8: =SUM(AP4:AP7) -> 17044 | AQ8: =SUM(AQ4:AQ7) -> 15716 | AR8: =SUM(AR4:AR7) -> 16314 | AS8: =SUM(AS4:AS7) -> 16951 | AT8: =SUM(AT4:AT7) -> 18093 | ... BI8: =SUM(BI4:BI7) -> 24965 | CB8: =SUM(AM8:AP8) -> 64388 | CC8: =SUM(AQ8:AT8) -> 67074 | CD8: =SUM(AU8:AX8) -> 68920 | CE8: =SUM(AY8:BB8) -> 80738 | CF8: =SUM(BC8:BF8) -> 88603 | CG8: =SUM(CG4:CG7) -> 98576.75 | CH8: =SUM(CH4:CH7) -> 111331.65 | CI8: =SUM(CI4:CI7) -> 125279.31 | CJ8: =SUM(CJ4:CJ7) -> 138888.9 | CK8: =SUM(CK4:CK7) -> 151818.06 | CL8: =SUM(CL4:CL7) -> 162394.9 | CM8: =SUM(CM4:CM7) -> 171176.8 | CN8: =SUM(CN4:CN7) -> 178992.28 | ... CP8: =SUM(CP4:CP7) -> 192225.96
B10: Collins Aerospace Growth Y/y | AQ10: =AQ4/AM4-1 -> 0.10389016 | AR10: =AR4/AN4-1 -> 0.10253025 | AS10: =AS4/AO4-1 -> 0.24520906 | AT10: =AT4/AP4-1 -> 0.020639417 | AU10: =AU4/AQ4-1 -> 0.26865672 | AV10: =AV4/AR4-1 -> 0.27399721 | AW10: =AW4/AS4-1 -> 0.15932144 | AX10: =AX4/AT4-1 -> 0.41157811 | ... BI10: =BI4/BE4-1 -> 0.099855662 | CC10: =CC4/CB4-1 -> 0.11642907 | CD10: =CD4/CC4-1 -> 0.2746031 | CE10: =CE4/CD4-1 -> 0.077362587 | CF10: =CF4/CE4-1 -> 0.067600057 | CG10: 0.075 | CH10: 0.09 | CI10: 0.105 | CJ10: 0.095 | CK10: 0.08 | CL10: 0.06 | CM10: 0.055 | CN10: 0.05 | CO10: 0.045 | CP10: 0.04
B11: Pratt & Whitney Growth Y/y | AQ11: =AQ5/AM5-1 -> 0.12382134 | AR11: =AR5/AN5-1 -> 0.16098131 | AS11: =AS5/AO5-1 -> 0.13862434 | AT11: =AT5/AP5-1 -> 0.10498534 | AU11: =AU5/AQ5-1 -> 0.1547803 | AV11: =AV5/AR5-1 -> 0.14731334 | AW11: =AW5/AS5-1 -> -0.82788104 | AX11: =AX5/AT5-1 -> 0.13924275 | ... BI11: =BI5/BE5-1 -> 0.095927817 | CC11: =CC5/CB5-1 -> 0.13112948 | CD11: =CD5/CC5-1 -> -0.10881637 | CE11: =CE5/CD5-1 -> 0.5339965 | CF11: =CF5/CE5-1 -> 0.17280696 | CG11: 0.125 | CH11: 0.14 | CI11: 0.15 | CJ11: 0.13 | CK11: 0.11 | CL11: 0.09 | CM11: 0.07 | CN11: 0.06 | CO11: 0.05 | CP11: 0.04
B12: Raytheon Growth Y/y | AQ12: =AQ6/AM6-1 -> -0.060730352 | AR12: =AR6/AN6-1 -> -0.084980745 | AS12: =AS6/AO6-1 -> -0.17456163 | AT12: =AT6/AP6-1 -> 0.11786777 | AU12: =AU6/AQ6-1 -> -0.11367798 | AV12: =AV6/AR6-1 -> -0.060044893 | AW12: =AW6/AS6-1 -> 0.025998732 | AX12: =AX6/AT6-1 -> -0.20300926 | ... BI12: =BI6/BE6-1 -> 0.13995742 | CC12: =CC6/CB6-1 -> -0.050262053 | CD12: =CD6/CC6-1 -> -0.096829477 | CE12: =CE6/CD6-1 -> 0.013776091 | CF12: =CF6/CE6-1 -> 0.049788492 | CG12: 0.13 | CH12: 0.15 | CI12: 0.11 | CJ12: 0.09 | CK12: 0.08 | CL12: 0.05 | CM12: 0.03 | CN12: 0.02 | CO12: 0.0175 | CP12: 0.015
B13: Intersegment Eliminations | AQ13: =AQ7/AM7-1 -> 0.041018388 | AR13: =AR7/AN7-1 -> 0.080272109 | AS13: =AS7/AO7-1 -> -0.39008043 | AT13: =AT7/AP7-1 -> 0.67520216 | AU13: =AU7/AQ7-1 -> -0.41847826 | AV13: =AV7/AR7-1 -> -0.40806045 | AW13: =AW7/AS7-1 -> 0.23736264 | AX13: =AX7/AT7-1 -> -0.58326629 | ... BI13: =BI7/BE7-1 -> 0.11129296 | CC13: =CC7/CB7-1 -> 0.10170648 | CD13: =CD7/CC7-1 -> -0.38692689 | CE13: =CE7/CD7-1 -> 0.17483578 | CF13: =CF7/CE7-1 -> 0.097634409 | CG13: 0.02 | CH13: 0.04 | CI13: 0.04 | CJ13: 0.02 | CK13: 0.02 | CL13: 0.02 | CM13: 0.02 | CN13: 0.02 | CO13: 0.02 | CP13: 0.02
B14: Ttl Revenue Growth Y/y | AQ14: =AQ8/AM8-1 -> 0.030489804 | AR14: =AR8/AN8-1 -> 0.027329975 | AS14: =AS8/AO8-1 -> 0.045519028 | AT14: =AT8/AP8-1 -> 0.061546585 | AU14: =AU8/AQ8-1 -> 0.095316875 | AV14: =AV8/AR8-1 -> 0.12265539 | AW14: =AW8/AS8-1 -> -0.20571058 | AX14: =AX8/AT8-1 -> 0.10136517 | ... BI14: =BI8/BE8-1 -> 0.11064152 | CC14: =CC8/CB8-1 -> 0.041715848 | CD14: =CD8/CC8-1 -> 0.027521842 | CE14: =CE8/CD8-1 -> 0.17147417 | CF14: =CF8/CE8-1 -> 0.097413857 | CG14: =CG8/CF8-1 -> 0.11256673 | CH14: =CH8/CG8-1 -> 0.12939055 | CI14: =CI8/CH8-1 -> 0.1252803 | CJ14: =CJ8/CI8-1 -> 0.10863394 | ... CP14: =CP8/CO8-1 -> 0.033159077
B16: Collins Aerospace % of Ttl Revenues | AM16: =AM4/AM8 -> 0.28653859 | AN16: =AN4/AN8 -> 0.28620907 | AO16: =AO4/AO8 -> 0.28322951 | AP16: =AP4/AP8 -> 0.28995541 | AQ16: =AQ4/AQ8 -> 0.30694833 | AR16: =AR4/AR8 -> 0.30715949 | AS16: =AS4/AS8 -> 0.33732523 | AT16: =AT4/AT8 -> 0.27878185 | ... BI16: =BI4/BI8 -> 0.33575005 | CB16: =CB4/CB8 -> 0.28652855 | CC16: =CC4/CC8 -> 0.30707875 | CD16: =CD4/CD8 -> 0.38091991 | CE16: =CE4/CE8 -> 0.35031831 | CF16: =CF4/CF8 -> 0.3408011
B17: Pratt & Whitney % of Ttl Revenues | AM17: =AM5/AM8 -> 0.26424497 | AN17: =AN5/AN8 -> 0.26952141 | AO17: =AO5/AO8 -> 0.2914328 | AP17: =AP5/AP8 -> 0.30010561 | AQ17: =AQ5/AQ8 -> 0.28817765 | AR17: =AR5/AR8 -> 0.30458502 | AS17: =AS5/AS8 -> 0.3173854 | AT17: =AT5/AT8 -> 0.31238601 | ... BI17: =BI5/BI8 -> 0.36975766 | CB17: =CB5/CB8 -> 0.28188482 | CC17: =CC5/CC8 -> 0.30607985 | CD17: =CD5/CD8 -> 0.26546721 | CE17: =CE5/CE8 -> 0.34761822 | CF17: =CF5/CF8 -> 0.37149984
B18: Raytheon % of Ttl Revenues | AM18: =AM6/AM8 -> 0.49557406 | AN18: =AN6/AN8 -> 0.49055416 | AO18: =AO6/AO8 -> 0.47135015 | AP18: =AP6/AP8 -> 0.45347336 | AQ18: =AQ6/AQ8 -> 0.45170527 | AR18: =AR6/AR8 -> 0.43692534 | AS18: =AS6/AS8 -> 0.37213144 | AT18: =AT6/AT8 -> 0.47753275 | ... BI18: =BI6/BI8 -> 0.32169037 | CB18: =CB6/CB8 -> 0.477092 | CC18: =CC6/CC8 -> 0.43496735 | CD18: =CD6/CD8 -> 0.38232734 | CE18: =CE6/CE8 -> 0.33086031 | CF18: =CF6/CF8 -> 0.3165017
B20: U.S. | AM20: 9730 | AN20: 9871 | AO20: 10096 | AP20: =40011-SUM(AM20:AO20) -> 10314 | AQ20: 9730 | AR20: 10185 | AS20: 10422 | AT20: =41190-SUM(AQ20:AS20) -> 10853 | AU20: 10548 | AV20: 11227 | AW20: 11155 | AX20: =44881-SUM(AU20:AW20) -> 11951 | AY20: 11361 | AZ20: 11625 | BA20: 11411 | BB20: =46087-SUM(AY20:BA20) -> 11690 | BC20: 11266 | BD20: 11737 | BE20: 11734 | BF20: =47291-SUM(BC20:BE20) -> 12554 | BG20: 11913 | BH20: 13093 | BI20: 13241 | CB20: =SUM(AM20:AP20) -> 40011 | CC20: =SUM(AQ20:AT20) -> 41190 | CD20: =SUM(AU20:AX20) -> 44881 | CE20: =SUM(AY20:BB20) -> 46087 | CF20: =SUM(BC20:BF20) -> 47291
B21: Europe | AM21: 2147 | AN21: 2316 | AO21: 2408 | AP21: =9598-SUM(AM21:AO21) -> 2727 | AQ21: 2572 | AR21: 2678 | AS21: 2663 | AT21: =11111-SUM(AQ21:AS21) -> 3198 | AU21: 2990 | AV21: 3286 | AW21: 3514 | AX21: =13501-SUM(AU21:AW21) -> 3711 | AY21: 3833 | AZ21: 3589 | BA21: 4120 | BB21: =15975-SUM(AY21:BA21) -> 4433 | BC21: 4413 | BD21: 4205 | BE21: 5225 | BF21: =18799-SUM(BC21:BE21) -> 4956 | BG21: 4882 | BH21: 5350 | BI21: 5670 | CB21: =SUM(AM21:AP21) -> 9598 | CC21: =SUM(AQ21:AT21) -> 11111 | CD21: =SUM(AU21:AX21) -> 13501 | CE21: =SUM(AY21:BB21) -> 15975 | CF21: =SUM(BC21:BF21) -> 18799
B22: APAC | AM22: 1772 | AN22: 2002 | AO22: 2006 | AP22: =7969-SUM(AM22:AO22) -> 2189 | AQ22: 1857 | AR22: 1808 | AS22: 2160 | AT22: =8057-SUM(AQ22:AS22) -> 2232 | AU22: 2050 | AV22: 2109 | AW22: 2414 | AX22: =9049-SUM(AU22:AW22) -> 2476 | AY22: 2427 | AZ22: 2661 | BA22: 2789 | BB22: =10893-SUM(AY22:BA22) -> 3016 | BC22: 2592 | BD22: 3410 | BE22: 3567 | BF22: =13782-SUM(BC22:BE22) -> 4213 | BG22: 2804 | BH22: 3656 | BI22: 3521 | CB22: =SUM(AM22:AP22) -> 7969 | CC22: =SUM(AQ22:AT22) -> 8057 | CD22: =SUM(AU22:AX22) -> 9049 | CE22: =SUM(AY22:BB22) -> 10893 | CF22: =SUM(BC22:BF22) -> 13782
B23: Mid-East | AM23: 992 | AN23: 1167 | AO23: 1140 | AP23: =4379-SUM(AM23:AO23) -> 1080 | AQ23: 829 | AR23: 869 | AS23: 978 | AT23: =3599-SUM(AQ23:AS23) -> 923 | AU23: 763 | AV23: 851 | AW23: 824 | AX23: =3237-SUM(AU23:AW23) -> 799 | AY23: 849 | AZ23: 791 | BA23: 628 | BB23: =3458-SUM(AY23:BA23) -> 1190 | BC23: 848 | BD23: 904 | BE23: 732 | BF23: =3621-SUM(BC23:BE23) -> 1137 | BG23: 930 | BH23: 1042 | BI23: 975 | CB23: =SUM(AM23:AP23) -> 4379 | CC23: =SUM(AQ23:AT23) -> 3599 | CD23: =SUM(AU23:AX23) -> 3237 | CE23: =SUM(AY23:BB23) -> 3458 | CF23: =SUM(BC23:BF23) -> 3621
B24: Other regions | AM24: 610 | AN24: 524 | AO24: 563 | AP24: =2431-SUM(AM24:AO24) -> 734 | AQ24: 728 | AR24: 774 | AS24: 728 | AT24: =3117-SUM(AQ24:AS24) -> 887 | AU24: 863 | AV24: 842 | AW24: 958 | AX24: =3653-SUM(AU24:AW24) -> 990 | AY24: 835 | AZ24: 1055 | BA24: 1141 | BB24: =4325-SUM(AY24:BA24) -> 1294 | BC24: 1187 | BD24: 1325 | BE24: 1220 | BF24: =5110-SUM(BC24:BE24) -> 1378 | BG24: 1547 | BH24: 1567 | BI24: 1558 | CB24: =SUM(AM24:AP24) -> 2431 | CC24: =SUM(AQ24:AT24) -> 3117 | CD24: =SUM(AU24:AX24) -> 3653 | CE24: =SUM(AY24:BB24) -> 4325 | CF24: =SUM(BC24:BF24) -> 5110
B25: Ttl Revenues | AM25: =SUM(AM20:AM24) -> 15251 | AN25: =SUM(AN20:AN24) -> 15880 | AO25: =SUM(AO20:AO24) -> 16213 | AP25: =SUM(AP20:AP24) -> 17044 | AQ25: =SUM(AQ20:AQ24) -> 15716 | AR25: =SUM(AR20:AR24) -> 16314 | AS25: =SUM(AS20:AS24) -> 16951 | AT25: =SUM(AT20:AT24) -> 18093 | ... AV25: =SUM(AV20:AV24) -> 18315 | AW25: =SUM(AW19:AW24)-5401 -> 13464 | AX25: =SUM(AX20:AX24) -> 19927 | AY25: =SUM(AY20:AY24) -> 19305 | AZ25: =SUM(AZ20:AZ24) -> 19721 | BA25: =SUM(BA20:BA24) -> 20089 | BB25: =SUM(BB20:BB24) -> 21623 | BC25: =SUM(BC20:BC24) -> 20306 | BD25: =SUM(BD20:BD24) -> 21581 | BE25: =SUM(BE20:BE24) -> 22478 | ... BI25: =SUM(BI20:BI24) -> 24965 | CB25: =SUM(AM25:AP25) -> 64388 | CC25: =SUM(AQ25:AT25) -> 67074 | CD25: =SUM(AU25:AX25) -> 68920 | CE25: =SUM(AY25:BB25) -> 80738 | CF25: =SUM(BC25:BF25) -> 88603
B27: U.S. Growth Y/y | AQ27: =AQ20/AM20-1 -> 0 | AR27: =AR20/AN20-1 -> 0.031810354 | AS27: =AS20/AO20-1 -> 0.032290016 | AT27: =AT20/AP20-1 -> 0.052259065 | AU27: =AU20/AQ20-1 -> 0.084069887 | AV27: =AV20/AR20-1 -> 0.10230731 | AW27: =AW20/AS20-1 -> 0.07033199 | AX27: =AX20/AT20-1 -> 0.10117018 | ... BI27: =BI20/BE20-1 -> 0.1284302 | CC27: =CC20/CB20-1 -> 0.029466897 | CD27: =CD20/CC20-1 -> 0.089609128 | CE27: =CE20/CD20-1 -> 0.026871059 | CF27: =CF20/CE20-1 -> 0.026124504
B28: Europe Growth Y/y | AQ28: =AQ21/AM21-1 -> 0.19795063 | AR28: =AR21/AN21-1 -> 0.15630397 | AS28: =AS21/AO21-1 -> 0.10589701 | AT28: =AT21/AP21-1 -> 0.17271727 | AU28: =AU21/AQ21-1 -> 0.16251944 | AV28: =AV21/AR21-1 -> 0.2270351 | AW28: =AW21/AS21-1 -> 0.3195644 | AX28: =AX21/AT21-1 -> 0.16041276 | ... BI28: =BI21/BE21-1 -> 0.085167464 | CC28: =CC21/CB21-1 -> 0.15763701 | CD28: =CD21/CC21-1 -> 0.21510215 | CE28: =CE21/CD21-1 -> 0.18324569 | CF28: =CF21/CE21-1 -> 0.17677621
B29: APAC Growth Y/y | AQ29: =AQ22/AM22-1 -> 0.047968397 | AR29: =AR22/AN22-1 -> -0.096903097 | AS29: =AS22/AO22-1 -> 0.076769691 | AT29: =AT22/AP22-1 -> 0.019643673 | AU29: =AU22/AQ22-1 -> 0.10393107 | AV29: =AV22/AR22-1 -> 0.1664823 | AW29: =AW22/AS22-1 -> 0.11759259 | AX29: =AX22/AT22-1 -> 0.109319 | ... BI29: =BI22/BE22-1 -> -0.012895991 | CC29: =CC22/CB22-1 -> 0.011042791 | CD29: =CD22/CC22-1 -> 0.12312275 | CE29: =CE22/CD22-1 -> 0.20377942 | CF29: =CF22/CE22-1 -> 0.26521619
B30: Mid-East Growth Y/y | AQ30: =AQ23/AM23-1 -> -0.16431452 | AR30: =AR23/AN23-1 -> -0.25535561 | AS30: =AS23/AO23-1 -> -0.14210526 | AT30: =AT23/AP23-1 -> -0.14537037 | AU30: =AU23/AQ23-1 -> -0.079613993 | AV30: =AV23/AR23-1 -> -0.020713464 | AW30: =AW23/AS23-1 -> -0.15746421 | AX30: =AX23/AT23-1 -> -0.13434453 | ... BI30: =BI23/BE23-1 -> 0.33196721 | CC30: =CC23/CB23-1 -> -0.17812286 | CD30: =CD23/CC23-1 -> -0.1005835 | CE30: =CE23/CD23-1 -> 0.068273092 | CF30: =CF23/CE23-1 -> 0.047137073
B31: Other regions Growth Y/y | AQ31: =AQ24/AM24-1 -> 0.19344262 | AR31: =AR24/AN24-1 -> 0.47709924 | AS31: =AS24/AO24-1 -> 0.29307282 | AT31: =AT24/AP24-1 -> 0.20844687 | AU31: =AU24/AQ24-1 -> 0.18543956 | AV31: =AV24/AR24-1 -> 0.087855297 | AW31: =AW24/AS24-1 -> 0.31593407 | AX31: =AX24/AT24-1 -> 0.11612176 | ... BI31: =BI24/BE24-1 -> 0.27704918 | CC31: =CC24/CB24-1 -> 0.2821884 | CD31: =CD24/CC24-1 -> 0.17196022 | CE31: =CE24/CD24-1 -> 0.18395839 | CF31: =CF24/CE24-1 -> 0.18150289
B32: Ttl Revenue Growth | AQ32: =AQ25/AM25-1 -> 0.030489804 | AR32: =AR25/AN25-1 -> 0.027329975 | AS32: =AS25/AO25-1 -> 0.045519028 | AT32: =AT25/AP25-1 -> 0.061546585 | AU32: =AU25/AQ25-1 -> 0.095316875 | AV32: =AV25/AR25-1 -> 0.12265539 | AW32: =AW25/AS25-1 -> -0.20571058 | AX32: =AX25/AT25-1 -> 0.10136517 | ... BI32: =BI25/BE25-1 -> 0.11064152 | CC32: =CC25/CB25-1 -> 0.041715848 | CD32: =CD25/CC25-1 -> 0.027521842 | CE32: =CE25/CD25-1 -> 0.17147417 | CF32: =CF25/CE25-1 -> 0.097413857
B34: U.S. % of Revenues | AM34: =AM20/AM25 -> 0.63799095 | AN34: =AN20/AN25 -> 0.6215995 | AO34: =AO20/AO25 -> 0.62271017 | AP34: =AP20/AP25 -> 0.60513964 | AQ34: =AQ20/AQ25 -> 0.61911428 | AR34: =AR20/AR25 -> 0.62431041 | AS34: =AS20/AS25 -> 0.61483098 | AT34: =AT20/AT25 -> 0.59984524 | ... BI34: =BI20/BI25 -> 0.53038254 | CB34: =CB20/CB25 -> 0.62140461 | CC34: =CC20/CC25 -> 0.61409786 | CD34: =CD20/CD25 -> 0.65120429 | CE34: =CE20/CE25 -> 0.57082167 | CF34: =CF20/CF25 -> 0.53374039
B35: Europe % of Revenues | AM35: =AM21/AM25 -> 0.14077765 | AN35: =AN21/AN25 -> 0.14584383 | AO35: =AO21/AO25 -> 0.14852279 | AP35: =AP21/AP25 -> 0.15999765 | AQ35: =AQ21/AQ25 -> 0.16365487 | AR35: =AR21/AR25 -> 0.16415349 | AS35: =AS21/AS25 -> 0.15709988 | AT35: =AT21/AT25 -> 0.17675344 | ... BI35: =BI21/BI25 -> 0.22711797 | CB35: =CB21/CB25 -> 0.14906504 | CC35: =CC21/CC25 -> 0.16565286 | CD35: =CD21/CD25 -> 0.19589379 | CE35: =CE21/CE25 -> 0.19786222 | CF35: =CF21/CF25 -> 0.21217115
B36: APAC % of Revenues | AM36: =AM22/AM25 -> 0.1161891 | AN36: =AN22/AN25 -> 0.12607053 | AO36: =AO22/AO25 -> 0.12372787 | AP36: =AP22/AP25 -> 0.12843229 | AQ36: =AQ22/AQ25 -> 0.11815984 | AR36: =AR22/AR25 -> 0.11082506 | AS36: =AS22/AS25 -> 0.12742611 | AT36: =AT22/AT25 -> 0.12336263 | ... BI36: =BI22/BI25 -> 0.14103745 | CB36: =CB22/CB25 -> 0.1237653 | CC36: =CC22/CC25 -> 0.12012106 | CD36: =CD22/CD25 -> 0.13129716 | CE36: =CE22/CE25 -> 0.13491788 | CF36: =CF22/CF25 -> 0.15554778
B37: Mid-East % of Revenues | AM37: =AM23/AM25 -> 0.065044915 | AN37: =AN23/AN25 -> 0.073488665 | AO37: =AO23/AO25 -> 0.070313946 | AP37: =AP23/AP25 -> 0.063365407 | AQ37: =AQ23/AQ25 -> 0.052748791 | AR37: =AR23/AR25 -> 0.053267133 | AS37: =AS23/AS25 -> 0.057695711 | AT37: =AT23/AT25 -> 0.051014204 | ... BI37: =BI23/BI25 -> 0.039054677 | CB37: =CB23/CB25 -> 0.068009567 | CC37: =CC23/CC25 -> 0.053657155 | CD37: =CD23/CD25 -> 0.046967499 | CE37: =CE23/CE25 -> 0.042829894 | CF37: =CF23/CF25 -> 0.040867691
B38: Other regions % of Revenues | AM38: =AM24/AM25 -> 0.039997377 | AN38: =AN24/AN25 -> 0.032997481 | AO38: =AO24/AO25 -> 0.034725221 | AP38: =AP24/AP25 -> 0.043065008 | AQ38: =AQ24/AQ25 -> 0.046322219 | AR38: =AR24/AR25 -> 0.047443913 | AS38: =AS24/AS25 -> 0.042947319 | AT38: =AT24/AT25 -> 0.049024485 | ... BI38: =BI24/BI25 -> 0.06240737 | CB38: =CB24/CB25 -> 0.037755482 | CC38: =CC24/CC25 -> 0.046471062 | CD38: =CD24/CD25 -> 0.053003482 | CE38: =CE24/CE25 -> 0.053568332 | CF38: =CF24/CF25 -> 0.057672991
B40: Revenues | C40: 12416 | D40: 13807 | E40: 15042 | F40: 16443 | G40: 14399 | H40: 16006 | I40: 15462 | J40: 10733 | K40: 14745 | L40: 17191 | M40: 14613 | N40: 11351 | O40: 13320 | P40: 14690 | Q40: 13788 | R40: 14300 | S40: 13357 | T40: 14874 | U40: 14354 | V40: 14659 | W40: 13815 | X40: 15280 | Y40: 15062 | Z40: 15680 | AA40: 15242 | AB40: 16705 | AC40: 16510 | AD40: -13756 | AE40: 18365 | AF40: 11329 | AG40: 11373 | AH40: 4282 | AI40: 18210 | AJ40: 14277 | AK40: 14747 | AL40: 16583 | AM40: =AM8 -> 15251 | AN40: =AN8 -> 15880 | AO40: =AO8 -> 16213 | AP40: =AP8 -> 17044 | AQ40: =AQ8 -> 15716 | AR40: =AR8 -> 16314 | AS40: =AS8 -> 16951 | AT40: =AT8 -> 18093 | ... BI40: =BI8 -> 24965 | BS40: =SUM(C40:F40) -> 57708 | BT40: =SUM(G40:J40) -> 56600 | BU40: =SUM(K40:N40) -> 57900 | BV40: =SUM(O40:R40) -> 56098 | BW40: =SUM(S40:V40) -> 57244 | BX40: =SUM(W40:Z40) -> 59837 | BY40: =SUM(AA40:AD40) -> 34701 | BZ40: =SUM(AE40:AH40) -> 45349 | CA40: =SUM(AI40:AL40) -> 63817 | CB40: =SUM(AM40:AP40) -> 64388 | CC40: =SUM(AQ40:AT40) -> 67074 | CD40: =SUM(AU40:AX40) -> 68920 | CE40: =SUM(AY40:BB40) -> 80738 | CF40: =SUM(BC40:BF40) -> 88603 | CG40: =CG8 -> 98576.75 | CH40: =CH8 -> 111331.65 | CI40: =CI8 -> 125279.31 | CJ40: =CJ8 -> 138888.9 | CK40: =CK8 -> 151818.06 | CL40: =CL8 -> 162394.9 | CM40: =CM8 -> 171176.8 | CN40: =CN8 -> 178992.28 | ... CP40: =CP8 -> 192225.96
B41: COGS | C41: 8930 | D41: 9934 | E41: 11003 | F41: 12286 | G41: 10465 | H41: 11552 | I41: 11020 | J41: 7431 | K41: 10690 | L41: 12931 | M41: 10165 | N41: 7112 | O41: 9506 | P41: 10472 | Q41: 9800 | R41: 10653 | S41: 9654 | T41: 10741 | U41: 10342 | V41: 10734 | W41: 10136 | X41: 11164 | Y41: 11106 | Z41: 11795 | AA41: 11280 | AB41: 12422 | AC41: 12536 | AD41: -8773 | AE41: 13707 | AF41: 8554 | AG41: 8509 | AH41: 3828 | AI41: 8572 | AJ41: 12214 | AK41: 13004 | AL41: 14266 | AM41: =9974+2563 -> 12537 | AN41: =9997+2658 -> 12655 | AO41: =10296+2793 -> 13089 | AP41: =41095+10802-SUM(AM41:AO41) -> 13616 | AQ41: =9820+2740 -> 12560 | AR41: =10040+2816 -> 12856 | AS41: =10493+2971 -> 13464 | AT41: =41927+11479-SUM(AQ41:AS41) -> 14526 | AU41: =10700+2945 -> 13645 | AV41: =11089+3429 -> 14518 | AW41: =9289+3461 -> 12750 | AX41: =43425+13406-SUM(AU41:AW41) -> 15918 | AY41: =12216+3528 -> 15744 | AZ41: =12625+3516 -> 16141 | BA41: =12336+3719 -> 16055 | BB41: =50768+14560-SUM(AY41:BA41) -> 17388 | BC41: =12283+3907 -> 16190 | BD41: =12989+4216 -> 17205 | BE41: =13593+4305 -> 17898 | BF41: =53780+17034-SUM(BC41:BE41) -> 19521 | BG41: =13000+4482 -> 17482 | BH41: =14802+4773 -> 19575 | BI41: 19160 | BS41: =SUM(C41:F41) -> 42153 | BT41: =SUM(G41:J41) -> 40468 | BU41: =SUM(K41:N41) -> 40898 | BV41: =SUM(O41:R41) -> 40431 | BW41: =SUM(S41:V41) -> 41471 | BX41: =SUM(W41:Z41) -> 44201 | BY41: =SUM(AA41:AD41) -> 27465 | BZ41: =SUM(AE41:AH41) -> 34598 | CA41: =SUM(AI41:AL41) -> 48056 | CB41: =SUM(AM41:AP41) -> 51897 | CC41: =SUM(AQ41:AT41) -> 53406 | CD41: =SUM(AU41:AX41) -> 56831 | CE41: =SUM(AY41:BB41) -> 65328 | CF41: =SUM(BC41:BF41) -> 70814 | CG41: =CG40*(1-CG57) -> 77875.633 | CH41: =CH40*(1-CH57) -> 87673.674 | CI41: =CI40*(1-CI57) -> 98344.26 | CJ41: =CJ40*(1-CJ57) -> 108333.34 | CK41: =CK40*(1-CK57) -> 118266.27 | CL41: =CL40*(1-CL57) -> 126343.23 | CM41: =CM40*(1-CM57) -> 133004.38 | CN41: =CN40*(1-CN57) -> 138898.01 | ... CP41: =CP40*(1-CP57) -> 148975.12
B42: GP | C42: =C40-C41 -> 3486 | D42: =D40-D41 -> 3873 | E42: =E40-E41 -> 4039 | F42: =F40-F41 -> 4157 | G42: =G40-G41 -> 3934 | H42: =H40-H41 -> 4454 | I42: =I40-I41 -> 4442 | J42: =J40-J41 -> 3302 | ... BI42: =BI40-BI41 -> 5805 | BS42: =SUM(C42:F42) -> 15555 | BT42: =SUM(G42:J42) -> 16132 | BU42: =SUM(K42:N42) -> 17002 | BV42: =SUM(O42:R42) -> 15667 | BW42: =SUM(S42:V42) -> 15773 | BX42: =SUM(W42:Z42) -> 15636 | BY42: =SUM(AA42:AD42) -> 7236 | BZ42: =SUM(AE42:AH42) -> 10751 | CA42: =SUM(AI42:AL42) -> 15761 | CB42: =SUM(AM42:AP42) -> 12491 | CC42: =SUM(AQ42:AT42) -> 13668 | CD42: =SUM(AU42:AX42) -> 12089 | CE42: =SUM(AY42:BB42) -> 15410 | CF42: =SUM(BC42:BF42) -> 17789 | CG42: =CG40-CG41 -> 20701.117 | CH42: =CH40-CH41 -> 23657.976 | CI42: =CI40-CI41 -> 26935.052 | CJ42: =CJ40-CJ41 -> 30555.558 | CK42: =CK40-CK41 -> 33551.791 | CL42: =CL40-CL41 -> 36051.668 | CM42: =CM40-CM41 -> 38172.427 | CN42: =CN40-CN41 -> 40094.271 | ... CP42: =CP40-CP41 -> 43250.84
B43: R&D | C43: 544 | D43: 525 | E43: 590 | F43: 712 | G43: 610 | H43: 631 | I43: 630 | J43: 471 | K43: 624 | L43: 666 | M43: 640 | N43: 545 | O43: 564 | P43: 558 | Q43: 546 | R43: 611 | S43: 541 | T43: 588 | U43: 582 | V43: 665 | W43: 586 | X43: 619 | Y43: 592 | Z43: 630 | AA43: 554 | AB43: 589 | AC43: 586 | AD43: 149 | AE43: 728 | AF43: 605 | AG43: 592 | AH43: 527 | AI43: 535 | AJ43: 695 | AK43: 642 | AL43: 710 | AM43: 589 | AN43: 657 | AO43: 676 | AP43: =2711-SUM(AM43:AO43) -> 789 | AQ43: 635 | AR43: 698 | AS43: 662 | AT43: =2711-SUM(AQ43:AS43) -> 716 | AU43: 607 | AV43: 729 | AW43: 712 | AX43: =2805-SUM(AU43:AW43) -> 757 | AY43: 669 | AZ43: 706 | BA43: 751 | BB43: =2934-SUM(AY43:BA43) -> 808 | BC43: 637 | BD43: 697 | BE43: 684 | BF43: =2807-SUM(BC43:BE43) -> 789 | BG43: 627 | BH43: 726 | BI43: 711 | BS43: =SUM(C43:F43) -> 2371 | BT43: =SUM(G43:J43) -> 2342 | BU43: =SUM(K43:N43) -> 2475 | BV43: =SUM(O43:R43) -> 2279 | BW43: =SUM(S43:V43) -> 2376 | BX43: =SUM(W43:Z43) -> 2427 | BY43: =SUM(AA43:AD43) -> 1878 | BZ43: =SUM(AE43:AH43) -> 2452 | CA43: =SUM(AI43:AL43) -> 2582 | CB43: =SUM(AM43:AP43) -> 2711 | CC43: =SUM(AQ43:AT43) -> 2711 | CD43: =SUM(AU43:AX43) -> 2805 | CE43: =SUM(AY43:BB43) -> 2934 | CF43: =SUM(BC43:BF43) -> 2807 | CG43: =CG40*CG58 -> 2760.149 | CH43: =CH40*CH58 -> 3228.6178 | CI43: =CI40*CI58 -> 3758.3794 | CJ43: =CJ40*CJ58 -> 4305.5558 | CK43: =CK40*CK58 -> 4858.1779 | CL43: =CL40*CL58 -> 5196.6368 | CM43: =CM40*CM58 -> 5306.4809 | CN43: =CN40*CN58 -> 5369.7685 | ... CP43: =CP40*CP58 -> 5382.3268
B44: SG&A | C44: 1529 | D44: 1509 | E44: 1619 | F44: 1795 | G44: 1627 | H44: 1737 | I44: 1633 | J44: 1367 | K44: 1596 | L44: 1623 | M44: 1501 | N44: 1452 | O44: 1476 | P44: 1426 | Q44: 1359 | R44: 1836 | S44: 1363 | T44: 1451 | U44: 1390 | V44: 1754 | W44: 1537 | X44: 1590 | Y44: 1582 | Z44: 1720 | AA44: 1711 | AB44: 1759 | AC44: 1681 | AD44: -2287 | AE44: 1997 | AF44: 902 | AG44: 902 | AH44: -90 | AI44: 977 | AJ44: 1811 | AK44: 1401 | AL44: 1351 | AM44: 1220 | AN44: 1368 | AO44: 1229 | AP44: =5663-SUM(AM44:AO44) -> 1846 | AQ44: 1469 | AR44: 1424 | AS44: 1351 | AT44: =5663-SUM(AQ44:AS44) -> 1419 | AU44: 1363 | AV44: 1600 | AW44: 1401 | AX44: =5809-SUM(AU44:AW44) -> 1445 | AY44: 1394 | AZ44: 1449 | BA44: 1389 | BB44: =5806-SUM(AY44:BA44) -> 1574 | BC44: 1448 | BD44: 1573 | BE44: 1436 | BF44: =6095-SUM(BC44:BE44) -> 1638 | BG44: 1476 | BH44: 1658 | BI44: 1918 | BS44: =SUM(C44:F44) -> 6452 | BT44: =SUM(G44:J44) -> 6364 | BU44: =SUM(K44:N44) -> 6172 | BV44: =SUM(O44:R44) -> 6097 | BW44: =SUM(S44:V44) -> 5958 | BX44: =SUM(W44:Z44) -> 6429 | BY44: =SUM(AA44:AD44) -> 2864 | BZ44: =SUM(AE44:AH44) -> 3711 | CA44: =SUM(AI44:AL44) -> 5540 | CB44: =SUM(AM44:AP44) -> 5663 | CC44: =SUM(AQ44:AT44) -> 5663 | CD44: =SUM(AU44:AX44) -> 5809 | CE44: =SUM(AY44:BB44) -> 5806 | CF44: =SUM(BC44:BF44) -> 6095 | CG44: =CG40*CG59 -> 6604.6423 | CH44: =CH40*CH59 -> 7793.2155 | CI44: =CI40*CI59 -> 9020.1105 | CJ44: =CJ40*CJ59 -> 9722.2229 | CK44: =CK40*CK59 -> 10247.719 | CL44: =CL40*CL59 -> 10555.669 | CM44: =CM40*CM59 -> 10698.55 | CN44: =CN40*CN59 -> 11097.522 | ... CP44: =CP40*CP59 -> 11533.557
B45: Other (Income), net | C45: -300 | D45: -340 | E45: -211 | F45: -101 | G45: -309 | H45: -421 | I45: -187 | J45: -206 | K45: -263 | L45: -384 | M45: -305 | N45: -286 | O45: -408 | P45: -181 | Q45: -219 | R45: 808 | S45: -146 | T45: -243 | U45: -211 | V45: -182 | W45: -588 | X45: -257 | Y45: -250 | Z45: -263 | AA45: -231 | AB45: -941 | AC45: -131 | AD45: 920 | AE45: -112 | AF45: -118 | AG45: -60 | AH45: -36 | AI45: -19 | AJ45: 3101 | AK45: -734 | AL45: -50 | AM45: -108 | AN45: -82 | AO45: -124 | AP45: =1000-SUM(AM45:AO45) -> 1314 | AQ45: -28 | AR45: -17 | AS45: -46 | AT45: =-120-SUM(AQ45:AS45) -> -29 | AU45: -88 | AV45: -25 | AW45: -3 | AX45: =-86-SUM(AU45:AW45) -> 30 | AY45: -372 | AZ45: 896 | BA45: -134 | BB45: =132-SUM(AY45:BA45) -> -258 | BC45: -4 | BD45: -40 | BE45: -63 | BF45: =-413-SUM(BC45:BE45) -> -306 | BG45: -64 | BH45: -62 | BI45: -161 | BS45: =SUM(C45:F45) -> -952 | BT45: =SUM(G45:J45) -> -1123 | BU45: =SUM(K45:N45) -> -1238 | BV45: =SUM(O45:R45) -> 0 | BW45: =SUM(S45:V45) -> -782 | BX45: =SUM(W45:Z45) -> -1358 | BY45: =SUM(AA45:AD45) -> -383 | BZ45: =SUM(AE45:AH45) -> -326 | CA45: =SUM(AI45:AL45) -> 2298 | CB45: =SUM(AM45:AP45) -> 1000 | CC45: =SUM(AQ45:AT45) -> -120 | CD45: =SUM(AU45:AX45) -> -86 | CE45: =SUM(AY45:BB45) -> 132 | CF45: =SUM(BC45:BF45) -> -413 | CG45: =CG40*CG60 -> -295.73025 | CH45: =CH40*CH60 -> -333.99495 | CI45: =CI40*CI60 -> -375.83794 | CJ45: =CJ40*CJ60 -> -416.66669 | CK45: =CK40*CK60 -> -455.45417 | CL45: =CL40*CL60 -> -487.1847 | CM45: =CM40*CM60 -> -513.53041 | CN45: =CN40*CN60 -> -536.97685 | ... CP45: =CP40*CP60 -> -576.67787
B46: OI | C46: =C42-SUM(C43:C45) -> 1713 | D46: =D42-SUM(D43:D45) -> 2179 | E46: =E42-SUM(E43:E45) -> 2041 | F46: =F42-SUM(F43:F45) -> 1751 | G46: =G42-SUM(G43:G45) -> 2006 | H46: =H42-SUM(H43:H45) -> 2507 | I46: =I42-SUM(I43:I45) -> 2366 | J46: =J42-SUM(J43:J45) -> 1670 | ... BI46: =BI42-SUM(BI43:BI45) -> 3337 | BS46: =SUM(C46:F46) -> 7684 | BT46: =SUM(G46:J46) -> 8549 | BU46: =SUM(K46:N46) -> 9593 | BV46: =SUM(O46:R46) -> 7291 | BW46: =SUM(S46:V46) -> 8221 | BX46: =SUM(W46:Z46) -> 8138 | BY46: =SUM(AA46:AD46) -> 2877 | BZ46: =SUM(AE46:AH46) -> 4914 | CA46: =SUM(AI46:AL46) -> 5341 | CB46: =SUM(AM46:AP46) -> 3117 | CC46: =SUM(AQ46:AT46) -> 5414 | CD46: =SUM(AU46:AX46) -> 3561 | CE46: =SUM(AY46:BB46) -> 6538 | CF46: =SUM(BC46:BF46) -> 9300 | CG46: =CG42-SUM(CG43:CG45) -> 11632.056 | CH46: =CH42-SUM(CH43:CH45) -> 12970.137 | CI46: =CI42-SUM(CI43:CI45) -> 14532.4 | CJ46: =CJ42-SUM(CJ43:CJ45) -> 16944.446 | CK46: =CK42-SUM(CK43:CK45) -> 18901.348 | CL46: =CL42-SUM(CL43:CL45) -> 20786.547 | CM46: =CM42-SUM(CM43:CM45) -> 22680.927 | CN46: =CN42-SUM(CN43:CN45) -> 24163.958 | ... CP46: =CP42-SUM(CP43:CP45) -> 26911.634
...

Sheet Notes | Quant Analysis
CK1: 0
P2: Employee Scope: | AN2: General Notes/Observations
Q33: Notes: | R33: [X]
R34: [Y]
R35: [Z]
AN36: Financial Stmts. Notes/Observations
P37: Institutional Ownership | AN37: Revenues:
Q67: Notes: | R67: [X]
R68: [Y]
R69: [Z]
P71: Revenue Breakdown by Segment | AN71: Earnings Scope:
Q103: Notes: | R103: [X]
R104: [Y]
R105: [Z]
P107: Revenue Breakdown by Geography | AN107: Balance Sheet Scope:
Q139: Notes: | R139: [X]
R140: [Y] | AN140: [Equity Preformance Compared to Peers]
R141: [Z]
P143: Q/q Total Revenues, Net Income, FCF
Q172: Notes: | R172: [X]
R173: [Y]
R174: [Z]
P176: Y/y Total Revenues, Net Income, FCF
Q205: Notes: | R205: [X]
R206: [Y]
R207: [Z]
A222: VOO Historical Returns | I222: RTX Historical Returns
A223: 1506 Trading Days? (From: 9/19/2020 - 9/19/2026) | I223: 1506 Trading Days? (From: 9/19/2020 - 9/19/2026)
A224: Close | B224: High | C224: Low | D224: Open | E224: Volume | F224: UTC Date | G224: Change | I224: Close | J224: High | K224: Low | L224: Open | M224: Volume | N224: UTC Date | O224: Change
A225: 701.78 | B225: 702.19 | C225: 698.5 | D225: 701.58 | E225: 9594039.2 | F225: Fri, 18 Sep 2026 00:00:00 GMT | G225: =A225/D225-1 -> 0.00028507084 | I225: 194 | J225: 194 | K225: 191.175 | L225: 193 | M225: 9843426.5 | N225: Fri, 18 Sep 2026 00:00:00 GMT | O225: =I225/L225-1 -> 0.0051813472
A226: 701.03 | B226: 701.88 | C226: 698.61 | D226: 701.6 | E226: 9903368.8 | F226: Thu, 17 Sep 2026 00:00:00 GMT | G226: =A226/D226-1 -> -0.00081242873 | I226: 193.54 | J226: 197.5 | K226: 191.84 | L226: 197.5 | M226: 3549581.7 | N226: Thu, 17 Sep 2026 00:00:00 GMT | O226: =I226/L226-1 -> -0.020050633
A227: 693.24 | B227: 700.1 | C227: 689.04 | D227: 698.17 | E227: 14168409 | F227: Wed, 16 Sep 2026 00:00:00 GMT | G227: =A227/D227-1 -> -0.0070613174 | I227: 196.83 | J227: 197.67 | K227: 194.78 | L227: 195.39 | M227: 3485674.5 | N227: Wed, 16 Sep 2026 00:00:00 GMT | O227: =I227/L227-1 -> 0.0073698756
A228: 696.2 | B228: 698.94 | C228: 695.09 | D228: 698.77 | E228: 9657887.8 | F228: Tue, 15 Sep 2026 00:00:00 GMT | G228: =A228/D228-1 -> -0.0036778912 | I228: 195.5 | J228: 197.205 | K228: 193.05 | L228: 196.73 | M228: 4729145.5 | N228: Tue, 15 Sep 2026 00:00:00 GMT | O228: =I228/L228-1 -> -0.0062522239
A229: 699.3 | B229: 701.85 | C229: 696.72 | D229: 697.78 | E229: 6776056.6 | F229: Mon, 14 Sep 2026 00:00:00 GMT | G229: =A229/D229-1 -> 0.002178337 | I229: 195.34 | J229: 196.5 | K229: 194.01 | L229: 196.4 | M229: 3568413 | N229: Mon, 14 Sep 2026 00:00:00 GMT | O229: =I229/L229-1 -> -0.0053971487
A230: 702.56 | B230: 704.4954 | C230: 701.93 | D230: 703 | E230: 5797972.9 | F230: Fri, 11 Sep 2026 00:00:00 GMT | G230: =A230/D230-1 -> -0.00062588905 | I230: 197.68 | J230: 200.38 | K230: 196.31 | L230: 199.57 | M230: 3680583.8 | N230: Fri, 11 Sep 2026 00:00:00 GMT | O230: =I230/L230-1 -> -0.0094703613
A231: 696.65 | B231: 698.64 | C231: 695.5421 | D231: 696.78 | E231: 18313415 | F231: Thu, 10 Sep 2026 00:00:00 GMT | G231: =A231/D231-1 -> -0.00018657252 | I231: 198.12 | J231: 198.86 | K231: 196.6801 | L231: 198.03 | M231: 2651871 | N231: Thu, 10 Sep 2026 00:00:00 GMT | O231: =I231/L231-1 -> 0.00045447659
A232: 700.87 | B232: 702.71 | C232: 699.485 | D232: 702.35 | E232: 4300871.2 | F232: Wed, 09 Sep 2026 00:00:00 GMT | G232: =A232/D232-1 -> -0.0021072115 | I232: 197.55 | J232: 199.56 | K232: 196.8 | L232: 198.92 | M232: 3319425.7 | N232: Wed, 09 Sep 2026 00:00:00 GMT | O232: =I232/L232-1 -> -0.0068871908
A233: 704.07 | B233: 707.51 | C233: 703.37 | D233: 706.98 | E233: 7827554 | F233: Tue, 08 Sep 2026 00:00:00 GMT | G233: =A233/D233-1 -> -0.0041160995 | I233: 198.81 | J233: 201.75 | K233: 198.13 | L233: 199.73 | M233: 3627291.7 | N233: Tue, 08 Sep 2026 00:00:00 GMT | O233: =I233/L233-1 -> -0.0046062184
A234: 708.01 | B234: 710.45 | C234: 706.9 | D234: 709.72 | E234: 6816157.9 | F234: Fri, 04 Sep 2026 00:00:00 GMT | G234: =A234/D234-1 -> -0.0024094009 | I234: 200.79 | J234: 201.6357 | K234: 199.04 | L234: 200.77 | M234: 2803336.8 | N234: Fri, 04 Sep 2026 00:00:00 GMT | O234: =I234/L234-1 -> 9.9616477e-05
A235: 710.72 | B235: 711.515 | C235: 705.51 | D235: 705.82 | E235: 8594521.7 | F235: Thu, 03 Sep 2026 00:00:00 GMT | G235: =A235/D235-1 -> 0.0069422799 | I235: 202.13 | J235: 202.665 | K235: 200.1 | L235: 202 | M235: 3706634 | N235: Thu, 03 Sep 2026 00:00:00 GMT | O235: =I235/L235-1 -> 0.00064356436
...

Sheet Product Lines

Sheet Management

Sheet Table Formatting
B2: [Bold Title] | G2: [Bold Title]
B3: Line Titles | G3: <-- General
B4: Line Titles | G4: <-- Info
B5: Line Titles | G5: <-- General
B6: Line Titles | G6: <-- Info
B7: Line Titles | G7: <-- General
B8: Line Titles | G8: <-- Info
