Workbook

Sheet Main
B2: SHOP
B3: Price | C3: 168.81 | D3: 10/22/2026
B4: SO | C4: 1295.22 | D4: Q2'26
B5: MC | C5: =C3*C4 -> 218646.09
B6: Cash | C6: =1656+3291 -> 4947 | D6: Q2'26
B7: Debt | C7: 0 | D7: Q2'26
B8: EV | C8: =C5-C6+C7 -> 213699.09
B10: Shopify Inc. (SHOP)
B12: Founder(s): Tobias Lutke, Daniel Weinand and Scott Lake | F12: Registered Exchange: NASDAQ | N12: Resources:
B13: Founded: 2004 | F13: Address: 151 O'Connor Street, Ottawa, ON Canada | N13: SEC filings | Q13: https://www.sec.gov/edgar/browse/?CIK=1594805&owner=exclude
B14: Headquarters: Ottawa, ON | F14: Investor Relations Contact: | N14: Company Homepage | Q14: https://www.shopify.com/
B15: Current CEO: Tobias Lutke | F15: Investors Relation Department | O15: Company IR Page | R15: https://www.shopify.com/investors
B16: Employees: 7,600 | F16: Phone: | G16: (613) 241 - 2828 | I16: Email: | N16: Earnings Calls | Q16: https://app.godelterminal.com/
B17: Industry: Software Services | N17: Equity Analysis | Q17: https://stockanalysis.com/stocks/shop/company/
B18: Sector: Technology | N18: MacroTrends | Q18: https://www.macrotrends.net/stocks/charts/SHOP/shopify/income-statement
B19: IPO: May, 21 2015 -- $1.27B valuation | N19: ROIC, WACC | Q19: https://www.gurufocus.com/term/wacc/SHOP
B20: Fiscal Year: [January - December] | N20: Godel Terminal | Q20: https://app.godelterminal.com/
A22: Company Overview:
B23: Shopify Inc., a commerce technology company, provides tools to start, scale, market, and run a business of various sizes in Canada, the United States, Europe, the Middle East, Africa, the Asia Pacific, and Latin America
B24: The Company offers Shopify platform that enables merchants to manage products and inventory, process orders and payments, fulfill and ship orders, build customer relationships, source products, leverage analytics, and reporting and access financing for running their business
C25: Supports partner businesses across all of their sales channels, including web and mobile storefronts, physical retail locations, social media storefronts, and marketplaces
B26: It also provides Shopify Payments, a fully integrated payment processing service that allows merchants to accept and process payment cards online and offline
C27: In addition, the company engages in the sale of themes and apps; shipping labels through Shopify Shipping; point-of-sale hardware, advertising on the Shopify App Store … and Shop Campaigns for buyer acquisitions, as well as registration of domain names
B28: Shopify Inc. was incorporated in 2004 and is based in Ottawa, Canada
C29: The Company was formerly known as Jaded Pixel Technologies Inc. and changed its name to Shopify Inc. in November 2011
A33: Business Segments and Geographical Info:
B34: [Begin researching fundamentals / core business … begin with SEC filings, but expand and use all public resources available]

Sheet Model
B1: [Use for Graphing] | C1: Q1 2024 | G1: Q1 2025 | K1: Q1 2026
B2: Quarterly
B3: Revenues | C3: Q1 2024 | D3: Q2 2024 | E3: Q3 2024 | F3: Q4 2024 | G3: Q1 2025 | H3: Q2 2025 | I3: Q3 2025 | J3: Q4 2025 | K3: Q1 2026 | L3: Q2 2026 | M3: Q3 2026 | N3: Q4 2026 | W3: 2024 | X3: 2025 | Y3: =X3+1 -> 2026 | Z3: =Y3+1 -> 2027 | AA3: =Z3+1 -> 2028 | AB3: =AA3+1 -> 2029 | AC3: =AB3+1 -> 2030 | AD3: =AC3+1 -> 2031 | AE3: =AD3+1 -> 2032 | AF3: =AE3+1 -> 2033 | ... CF3: =CE3+1 -> 2085
B4: U.S. | C4: 1198 | D4: 1323 | E4: 1377 | F4: =5708-SUM(C4:E4) -> 1810 | G4: 1499 | H4: 1703 | I4: 1783 | J4: =7331-SUM(G4:I4) -> 2346 | K4: 2001 | L4: 2283 | M4: 2283 | W4: =SUM(C4:F4) -> 5708 | X4: =SUM(G4:J4) -> 7331 | Y4: =X4*(1+Y11) -> 9823.54 | Z4: =Y4*(1+Z11) -> 12967.073 | AA4: =Z4*(1+AA11) -> 16857.195 | AB4: =AA4*(1+AB11) -> 21408.637 | AC4: =AB4*(1+AC11) -> 26760.796 | AD4: =AC4*(1+AD11) -> 32915.78 | AE4: =AD4*(1+AE11) -> 39828.093 | AF4: =AE4*(1+AF11) -> 47395.431 | ... AH4: =AG4*(1+AH11) -> 64325.079
B5: Canada | C5: 99 | D5: 114 | E5: 119 | F5: =483-SUM(C5:E5) -> 151 | G5: 119 | H5: 133 | I5: 138 | J5: =567-SUM(G5:I5) -> 177 | K5: 147 | L5: 171 | M5: 171 | W5: =SUM(C5:F5) -> 483 | X5: =SUM(G5:J5) -> 567 | Y5: =X5*(1+Y12) -> 714.42 | Z5: =Y5*(1+Z12) -> 878.7366 | AA5: =Z5*(1+AA12) -> 1072.0587 | AB5: =AA5*(1+AB12) -> 1286.4704 | AC5: =AB5*(1+AC12) -> 1518.0351 | AD5: =AC5*(1+AD12) -> 1760.9207 | AE5: =AD5*(1+AE12) -> 1989.8403 | AF5: =AE5*(1+AF12) -> 2188.8244 | ... AH5: =AG5*(1+AH12) -> 2505.7661
B6: Europe | C6: 354 | D6: 381 | E6: 418 | F6: =1707-SUM(C6:E6) -> 554 | G6: 461 | H6: 554 | I6: 615 | J6: =2426-SUM(G6:I6) -> 796 | K6: 653 | L6: 721 | M6: 721 | W6: =SUM(C6:F6) -> 1707 | X6: =SUM(G6:J6) -> 2426 | Y6: =X6*(1+Y13) -> 3347.88 | Z6: =Y6*(1+Z13) -> 4653.5532 | AA6: =Z6*(1+AA13) -> 6096.1547 | AB6: =AA6*(1+AB13) -> 7681.1549 | AC6: =AB6*(1+AC13) -> 9294.1974 | AD6: =AC6*(1+AD13) -> 10967.153 | AE6: =AD6*(1+AE13) -> 12612.226 | AF6: =AE6*(1+AF13) -> 14251.815 | ... AH6: =AG6*(1+AH13) -> 17243.271
B7: APAC | C7: 189 | D7: 203 | E7: 223 | F7: =885-SUM(C7:E7) -> 270 | G7: 240 | H7: 265 | I7: 282 | J7: =1128-SUM(G7:I7) -> 341 | K7: 312 | L7: 346 | M7: 346 | W7: =SUM(C7:F7) -> 885 | X7: =SUM(G7:J7) -> 1128 | Y7: =X7*(1+Y14) -> 1477.68 | Z7: =Y7*(1+Z14) -> 1965.3144 | AA7: =Z7*(1+AA14) -> 2495.9493 | AB7: =AA7*(1+AB14) -> 3094.9771 | AC7: =AB7*(1+AC14) -> 3744.9223 | AD7: =AC7*(1+AD14) -> 4419.0083 | AE7: =AD7*(1+AE14) -> 5081.8596 | AF7: =AE7*(1+AF14) -> 5691.6827 | ... AH7: =AG7*(1+AH14) -> 6761.7191
B8: Rest of World | C8: 21 | D8: 24 | E8: 25 | F8: =97-SUM(C8:E8) -> 27 | G8: 41 | H8: 25 | I8: 26 | J8: =104-SUM(G8:I8) -> 12 | K8: 57 | L8: 62 | M8: 62 | W8: =SUM(C8:F8) -> 97 | X8: =SUM(G8:J8) -> 104 | Y8: =X8*(1+Y15) -> 202.8 | Z8: =Y8*(1+Z15) -> 275.808 | AA8: =Z8*(1+AA15) -> 353.03424 | AB8: =AA8*(1+AB15) -> 425.40626 | AC8: =AB8*(1+AC15) -> 495.59829 | AD8: =AC8*(1+AD15) -> 562.50406 | AE8: =AD8*(1+AE15) -> 618.75447 | AF8: =AE8*(1+AF15) -> 668.25482 | ... AH8: =AG8*(1+AH15) -> 736.68412
B9: Ttl Revenues | C9: =SUM(C4:C8) -> 1861 | D9: =SUM(D4:D8) -> 2045 | E9: =SUM(E4:E8) -> 2162 | F9: =SUM(F4:F8) -> 2812 | G9: =SUM(G4:G8) -> 2360 | H9: =SUM(H4:H8) -> 2680 | I9: =SUM(I4:I8) -> 2844 | J9: =SUM(J4:J8) -> 3672 | ... M9: =SUM(M4:M8) -> 3583 | W9: =SUM(C9:F9) -> 8880 | X9: =SUM(G9:J9) -> 11556 | Y9: =SUM(Y4:Y8) -> 15566.32 | Z9: =SUM(Z4:Z8) -> 20740.485 | AA9: =SUM(AA4:AA8) -> 26874.392 | AB9: =SUM(AB4:AB8) -> 33896.646 | AC9: =SUM(AC4:AC8) -> 41813.55 | AD9: =SUM(AD4:AD8) -> 50625.366 | AE9: =SUM(AE4:AE8) -> 60130.774 | AF9: =SUM(AF4:AF8) -> 70196.008 | ... AH9: =SUM(AH4:AH8) -> 91572.52
B11: U.S. Growth Y/y | G11: =G4/C4-1 -> 0.25125209 | H11: =H4/D4-1 -> 0.287226 | I11: =I4/E4-1 -> 0.29484386 | J11: =J4/F4-1 -> 0.2961326 | K11: =K4/G4-1 -> 0.33488993 | L11: =L4/H4-1 -> 0.34057546 | M11: =M4/I4-1 -> 0.28042625 | X11: =X4/W4-1 -> 0.28433777 | Y11: 0.34 | Z11: 0.32 | AA11: 0.3 | AB11: 0.27 | AC11: 0.25 | AD11: 0.23 | AE11: 0.21 | AF11: 0.19 | AG11: 0.17 | AH11: 0.16
B12: Canada Growth Y/y | G12: =G5/C5-1 -> 0.2020202 | H12: =H5/D5-1 -> 0.16666667 | I12: =I5/E5-1 -> 0.15966387 | J12: =J5/F5-1 -> 0.17218543 | K12: =K5/G5-1 -> 0.23529412 | L12: =L5/H5-1 -> 0.28571429 | M12: =M5/I5-1 -> 0.23913043 | X12: =X5/W5-1 -> 0.17391304 | Y12: 0.26 | Z12: 0.23 | AA12: 0.22 | AB12: 0.2 | AC12: 0.18 | AD12: 0.16 | AE12: 0.13 | AF12: 0.1 | AG12: 0.08 | AH12: 0.06
B13: Europe Growth Y/y | G13: =G6/C6-1 -> 0.30225989 | H13: =H6/D6-1 -> 0.45406824 | I13: =I6/E6-1 -> 0.47129187 | J13: =J6/F6-1 -> 0.4368231 | K13: =K6/G6-1 -> 0.4164859 | L13: =L6/H6-1 -> 0.30144404 | M13: =M6/I6-1 -> 0.17235772 | X13: =X6/W6-1 -> 0.4212068 | Y13: 0.38 | Z13: 0.39 | AA13: 0.31 | AB13: 0.26 | AC13: 0.21 | AD13: 0.18 | AE13: 0.15 | AF13: 0.13 | AG13: 0.11 | AH13: 0.09
B14: APAC Growth Y/y | G14: =G7/C7-1 -> 0.26984127 | H14: =H7/D7-1 -> 0.30541872 | I14: =I7/E7-1 -> 0.26457399 | J14: =J7/F7-1 -> 0.26296296 | K14: =K7/G7-1 -> 0.3 | L14: =L7/H7-1 -> 0.30566038 | M14: =M7/I7-1 -> 0.22695035 | X14: =X7/W7-1 -> 0.27457627 | Y14: 0.31 | Z14: 0.33 | AA14: 0.27 | AB14: 0.24 | AC14: 0.21 | AD14: 0.18 | AE14: 0.15 | AF14: 0.12 | AG14: 0.1 | AH14: 0.08
B15: Rest of World Growth Y/y | G15: =G8/C8-1 -> 0.95238095 | H15: =H8/D8-1 -> 0.041666667 | I15: =I8/E8-1 -> 0.04 | J15: =J8/F8-1 -> -0.55555556 | K15: =K8/G8-1 -> 0.3902439 | L15: =L8/H8-1 -> 1.48 | M15: =M8/I8-1 -> 1.3846154 | X15: =X8/W8-1 -> 0.072164948 | Y15: 0.95 | Z15: 0.36 | AA15: 0.28 | AB15: 0.205 | AC15: 0.165 | AD15: 0.135 | AE15: 0.1 | AF15: 0.08 | AG15: 0.06 | AH15: 0.04
B16: Ttl Revenue Growth Y/y | G16: =G9/C9-1 -> 0.26813541 | H16: =H9/D9-1 -> 0.31051345 | I16: =I9/E9-1 -> 0.31544866 | J16: =J9/F9-1 -> 0.30583215 | K16: =K9/G9-1 -> 0.34322034 | L16: =L9/H9-1 -> 0.3369403 | M16: =M9/I9-1 -> 0.25984529 | X16: =X9/W9-1 -> 0.30135135 | Y16: =Y9/X9-1 -> 0.34703358 | Z16: =Z9/Y9-1 -> 0.33239488 | AA16: =AA9/Z9-1 -> 0.29574557 | AB16: =AB9/AA9-1 -> 0.2612991 | AC16: =AC9/AB9-1 -> 0.23356009 | AD16: =AD9/AC9-1 -> 0.21074069 | AE16: =AE9/AD9-1 -> 0.18775979 | ... AH16: =AH9/AG9-1 -> 0.13606077
B18: U.S. % of Ttl Revenues | C18: =C4/C9 -> 0.64373992 | D18: =D4/D9 -> 0.64694377 | E18: =E4/E9 -> 0.63691027 | F18: =F4/F9 -> 0.64366999 | G18: =G4/G9 -> 0.63516949 | H18: =H4/H9 -> 0.63544776 | I18: =I4/I9 -> 0.6269339 | J18: =J4/J9 -> 0.63888889 | ... M18: =M4/M9 -> 0.63717555 | W18: =W4/W9 -> 0.64279279 | X18: =X4/X9 -> 0.63438906
B19: Canada % of Ttl Revenues | C19: =C5/C9 -> 0.053197206 | D19: =D5/D9 -> 0.055745721 | E19: =E5/E9 -> 0.055041628 | F19: =F5/F9 -> 0.053698435 | G19: =G5/G9 -> 0.050423729 | H19: =H5/H9 -> 0.049626866 | I19: =I5/I9 -> 0.048523207 | J19: =J5/J9 -> 0.048202614 | ... M19: =M5/M9 -> 0.04772537 | W19: =W5/W9 -> 0.054391892 | X19: =X5/X9 -> 0.049065421
B20: Europe % of Ttl Revenues | C20: =C6/C9 -> 0.19022031 | D20: =D6/D9 -> 0.18630807 | E20: =E6/E9 -> 0.1933395 | F20: =F6/F9 -> 0.1970128 | G20: =G6/G9 -> 0.19533898 | H20: =H6/H9 -> 0.20671642 | I20: =I6/I9 -> 0.21624473 | J20: =J6/J9 -> 0.2167756 | ... M20: =M6/M9 -> 0.20122802 | W20: =W6/W9 -> 0.19222973 | X20: =X6/X9 -> 0.20993423
B21: APAC % of Ttl Revenues | C21: =C7/C9 -> 0.1015583 | D21: =D7/D9 -> 0.099266504 | E21: =E7/E9 -> 0.10314524 | F21: =F7/F9 -> 0.09601707 | G21: =G7/G9 -> 0.10169492 | H21: =H7/H9 -> 0.098880597 | I21: =I7/I9 -> 0.099156118 | J21: =J7/J9 -> 0.092864924 | ... M21: =M7/M9 -> 0.096567123 | W21: =W7/W9 -> 0.099662162 | X21: =X7/X9 -> 0.09761163
B22: Rest of World % of Ttl Revenues | C22: =C8/C9 -> 0.011284256 | D22: =D8/D9 -> 0.011735941 | E22: =E8/E9 -> 0.011563367 | F22: =F8/F9 -> 0.009601707 | G22: =G8/G9 -> 0.017372881 | H22: =H8/H9 -> 0.0093283582 | I22: =I8/I9 -> 0.0091420534 | J22: =J8/J9 -> 0.0032679739 | ... M22: =M8/M9 -> 0.017303935 | W22: =W8/W9 -> 0.010923423 | X22: =X8/X9 -> 0.0089996539
B24: Subscription Revenue | C24: 511 | D24: 563 | E24: 610 | F24: =2350-SUM(C24:E24) -> 666 | G24: 620 | H24: 656 | I24: 699 | J24: =2752-SUM(G24:I24) -> 777 | K24: 750 | L24: 802 | M24: 802 | W24: =SUM(C24:F24) -> 2350 | X24: =SUM(G24:J24) -> 2752
B25: Merchant Revenue | C25: 1350 | D25: 1482 | E25: 1552 | F25: =6530-SUM(C25:E25) -> 2146 | G25: 1740 | H25: 2024 | I25: 2145 | J25: =8804-SUM(G25:I25) -> 2895 | K25: 2420 | L25: 2781 | M25: 2781 | W25: =SUM(C25:F25) -> 6530 | X25: =SUM(G25:J25) -> 8804
B26: Ttl Revenues | C26: =SUM(C24:C25) -> 1861 | D26: =SUM(D24:D25) -> 2045 | E26: =SUM(E24:E25) -> 2162 | F26: =SUM(F24:F25) -> 2812 | G26: =SUM(G24:G25) -> 2360 | H26: =SUM(H24:H25) -> 2680 | I26: =SUM(I24:I25) -> 2844 | J26: =SUM(J24:J25) -> 3672 | ... M26: =SUM(M24:M25) -> 3583 | W26: =SUM(C26:F26) -> 8880 | X26: =SUM(G26:J26) -> 11556
B28: Subscription Costs | C28: 95 | D28: 97 | E28: 108 | F28: =434-SUM(C28:E28) -> 134 | G28: 123 | H28: 121 | I28: 128 | J28: =520-SUM(G28:I28) -> 148 | K28: 148 | L28: 163 | M28: 163 | W28: =SUM(C28:F28) -> 434 | X28: =SUM(G28:J28) -> 520
B29: Merchant Costs | C29: 809 | D29: 903 | E29: 936 | F29: =3974-SUM(C29:E29) -> 1326 | G29: 1068 | H29: 1257 | I29: 1325 | J29: =5481-SUM(G29:I29) -> 1831 | K29: 1476 | L29: 1712 | M29: 1712 | W29: =SUM(C29:F29) -> 3974 | X29: =SUM(G29:J29) -> 5481
B30: Ttl Costs | C30: =SUM(C28:C29) -> 904 | D30: =SUM(D28:D29) -> 1000 | E30: =SUM(E28:E29) -> 1044 | F30: =SUM(F28:F29) -> 1460 | G30: =SUM(G28:G29) -> 1191 | H30: =SUM(H28:H29) -> 1378 | I30: =SUM(I28:I29) -> 1453 | J30: =SUM(J28:J29) -> 1979 | ... M30: =SUM(M28:M29) -> 1875 | W30: =SUM(C30:F30) -> 4408 | X30: =SUM(G30:J30) -> 6001
B32: Revenues | C32: =C9 -> 1861 | D32: =D9 -> 2045 | E32: =E9 -> 2162 | F32: =F9 -> 2812 | G32: =G9 -> 2360 | H32: =H9 -> 2680 | I32: =I9 -> 2844 | J32: =J9 -> 3672 | ... M32: =M9 -> 3583 | W32: =SUM(C32:F32) -> 8880 | X32: =SUM(G32:J32) -> 11556 | Y32: =Y9 -> 15566.32 | Z32: =Z9 -> 20740.485 | AA32: =AA9 -> 26874.392 | AB32: =AB9 -> 33896.646 | AC32: =AC9 -> 41813.55 | AD32: =AD9 -> 50625.366 | AE32: =AE9 -> 60130.774 | AF32: =AF9 -> 70196.008 | ... AH32: =AH9 -> 91572.52
B33: COGS | C33: =C30 -> 904 | D33: =D30 -> 1000 | E33: =E30 -> 1044 | F33: =F30 -> 1460 | G33: =G30 -> 1191 | H33: =H30 -> 1378 | I33: =I30 -> 1453 | J33: =J30 -> 1979 | ... M33: =M30 -> 1875 | W33: =SUM(C33:F33) -> 4408 | X33: =SUM(G33:J33) -> 6001 | Y33: =Y32*(1-Y51) -> 8083.5485 | Z33: =Z32*(1-Z51) -> 10577.647 | AA33: =AA32*(1-AA51) -> 13437.196 | AB33: =AB32*(1-AB51) -> 16778.84 | AC33: =AC32*(1-AC51) -> 20488.639 | AD33: =AD32*(1-AD51) -> 24679.866 | AE33: =AE32*(1-AE51) -> 29163.425 | AF33: =AF32*(1-AF51) -> 33869.574 | ... AH33: =AH32*(1-AH51) -> 43954.81
B34: GP | C34: =C32-C33 -> 957 | D34: =D32-D33 -> 1045 | E34: =E32-E33 -> 1118 | F34: =F32-F33 -> 1352 | G34: =G32-G33 -> 1169 | H34: =H32-H33 -> 1302 | I34: =I32-I33 -> 1391 | J34: =J32-J33 -> 1693 | ... M34: =M32-M33 -> 1708 | W34: =SUM(C34:F34) -> 4472 | X34: =SUM(G34:J34) -> 5555 | Y34: =Y32*Y51 -> 7482.7715 | Z34: =Z32*Z51 -> 10162.838 | AA34: =AA32*AA51 -> 13437.196 | AB34: =AB32*AB51 -> 17117.806 | AC34: =AC32*AC51 -> 21324.91 | AD34: =AD32*AD51 -> 25945.5 | AE34: =AE32*AE51 -> 30967.348 | AF34: =AF32*AF51 -> 36326.434 | ... AH34: =AH32*AH51 -> 47617.71
B35: Sales & Marketing | C35: 361 | D35: 353 | E35: 331 | F35: =1393-SUM(C35:E35) -> 348 | G35: 405 | H35: 415 | I35: 410 | J35: =1663-SUM(G35:I35) -> 433 | K35: 496 | L35: 498 | M35: 498 | W35: =SUM(C35:F35) -> 1393 | X35: =SUM(G35:J35) -> 1663 | Y35: =Y32*Y52 -> 2240.1168 | Z35: =Z32*Z52 -> 2841.4464 | AA35: =AA32*AA52 -> 3547.4197 | AB35: =AB32*AB52 -> 4304.874 | AC35: =AC32*AC52 -> 5226.6937 | AD35: =AD32*AD52 -> 6277.5453 | AE35: =AE32*AE52 -> 7396.0852 | AF35: =AF32*AF52 -> 8563.913 | ... AH35: =AH32*AH52 -> 10988.702
B36: R&D | C36: 335 | D36: 349 | E36: 332 | F36: =1367-SUM(C36:E36) -> 351 | G36: 377 | H36: 394 | I36: 375 | J36: =1536-SUM(G36:I36) -> 390 | K36: 437 | L36: 445 | M36: 445 | W36: =SUM(C36:F36) -> 1367 | X36: =SUM(G36:J36) -> 1536 | Y36: =Y32*Y53 -> 2117.0195 | Z36: =Z32*Z53 -> 2799.9655 | AA36: =AA32*AA53 -> 3547.4197 | AB36: =AB32*AB53 -> 4372.6673 | AC36: =AC32*AC53 -> 5310.3208 | AD36: =AD32*AD53 -> 6328.1707 | AE36: =AE32*AE53 -> 7215.6928 | AF36: =AF32*AF53 -> 8072.541 | ... AH36: =AH32*AH53 -> 9615.1146
B37: General & Administrative | C37: 124 | D37: 60 | E37: 114 | F37: =410-SUM(C37:E37) -> 112 | G37: 109 | H37: 122 | I37: 115 | J37: =471-SUM(G37:I37) -> 125 | K37: 115 | L37: 136 | M37: 136 | W37: =SUM(C37:F37) -> 410 | X37: =SUM(G37:J37) -> 471 | Y37: =Y32*Y54 -> 634.45281 | Z37: =Z32*Z54 -> 788.13843 | AA37: =AA32*AA54 -> 967.47809 | AB37: =AB32*AB54 -> 1186.3826 | AC37: =AC32*AC54 -> 1463.4742 | AD37: =AD32*AD54 -> 1771.8878 | AE37: =AE32*AE54 -> 2104.5771 | AF37: =AF32*AF54 -> 2456.8603 | ... AH37: =AH32*AH54 -> 3205.0382
B38: Transaction & Loan Losses | C38: 51 | D38: 42 | E38: 58 | F38: =227-SUM(C38:E38) -> 76 | G38: 75 | H38: 80 | I38: 148 | J38: =417-SUM(G38:I38) -> 114 | K38: 116 | L38: 141 | M38: 141 | W38: =SUM(C38:F38) -> 227 | X38: =SUM(G38:J38) -> 417 | Y38: =Y32*Y55 -> 561.713 | Z38: =Z32*Z55 -> 705.17649 | AA38: =AA32*AA55 -> 886.85492 | AB38: =AB32*AB55 -> 1084.6927 | AC38: =AC32*AC55 -> 1296.22 | AD38: =AD32*AD55 -> 1518.761 | AE38: =AE32*AE55 -> 1803.9232 | AF38: =AF32*AF55 -> 2105.8803 | ... AH38: =AH32*AH55 -> 2747.1756
B39: Operating Income | C39: =C34-SUM(C35:C38) -> 86 | D39: =D34-SUM(D35:D38) -> 241 | E39: =E34-SUM(E35:E38) -> 283 | F39: =F34-SUM(F35:F38) -> 465 | G39: =G34-SUM(G35:G38) -> 203 | H39: =H34-SUM(H35:H38) -> 291 | I39: =I34-SUM(I35:I38) -> 343 | J39: =J34-SUM(J35:J38) -> 631 | ... M39: =M34-SUM(M35:M38) -> 488 | W39: =SUM(C39:F39) -> 1075 | X39: =SUM(G39:J39) -> 1468 | Y39: =Y34-SUM(Y35:Y38) -> 1929.4693 | Z39: =Z34-SUM(Z35:Z38) -> 3028.1108 | AA39: =AA34-SUM(AA35:AA38) -> 4488.0234 | AB39: =AB34-SUM(AB35:AB38) -> 6169.1895 | AC39: =AC34-SUM(AC35:AC38) -> 8028.2015 | AD39: =AD34-SUM(AD35:AD38) -> 10049.135 | AE39: =AE34-SUM(AE35:AE38) -> 12447.07 | AF39: =AF34-SUM(AF35:AF38) -> 15127.24 | ... AH39: =AH34-SUM(AH35:AH38) -> 21061.68
B40: Interest Income | C40: 79 | D40: 80 | E40: 77 | F40: =308-SUM(C40:E40) -> 72 | G40: 65 | H40: 106 | I40: 81 | J40: =331-SUM(G40:I40) -> 79 | K40: 75 | L40: 1228 | M40: 1228 | W40: =SUM(C40:F40) -> 308 | X40: =SUM(G40:J40) -> 331 | Y40: =X60*($AR$60) -> 374.6625 | Z40: =Y60*($AR$60) -> 978.11463 | AA40: =Z60*($AR$60) -> 2075.9206 | AB40: =AA60*($AR$60) -> 3906.4404 | AC40: =AB60*($AR$60) -> 6740.7151 | AD40: =AC60*($AR$60) -> 10913.119 | AE40: =AD60*($AR$60) -> 16860.634 | AF40: =AE60*($AR$60) -> 25211.498 | ... AH40: =AG60*($AR$60) -> 52438.314
B41: Net Realized G/L on Equity Inv | C41: -373 | D41: 3 | E41: 0 | F41: =3-SUM(C41:E41) -> 373 | G41: 0 | H41: 1 | I41: 0 | J41: =33-SUM(G41:I41) -> 32 | K41: 3 | L41: 59 | M41: 59 | W41: =SUM(C41:F41) -> 3 | X41: =SUM(G41:J41) -> 33 | Y41: 0 | Z41: 0 | AA41: 0 | AB41: 0 | AC41: 0 | AD41: 0 | AE41: 0 | AF41: 0 | AG41: 0 | AH41: 0
B42: Net Unealized G/L on Equity Inv | C42: 0 | D42: -79 | E42: 512 | F42: =988-SUM(C42:E42) -> 555 | G42: -1021 | H42: 681 | I42: -62 | J42: =-186-SUM(G42:I42) -> 216 | K42: -1064 | L42: 0 | M42: 0 | W42: =SUM(C42:F42) -> 988 | X42: =SUM(G42:J42) -> -186 | Y42: 0 | Z42: 0 | AA42: 0 | AB42: 0 | AC42: 0 | AD42: 0 | AE42: 0 | AF42: 0 | AG42: 0 | AH42: 0
B43: Net G/L on Equity Method Inv | C43: -44 | D43: -44 | E43: -28 | F43: =-138-SUM(C43:E43) -> -22 | G43: -23 | H43: -24 | I43: -21 | J43: =-40-SUM(G43:I43) -> 28 | K43: -21 | L43: 0 | M43: 0 | W43: =SUM(C43:F43) -> -138 | X43: =SUM(G43:J43) -> -40 | Y43: 0 | Z43: 0 | AA43: 0 | AB43: 0 | AC43: 0 | AD43: 0 | AE43: 0 | AF43: 0 | AG43: 0 | AH43: 0
B44: ForEx G/L | C44: -4 | D44: 2 | E44: 16 | F44: =-8-SUM(C44:E44) -> -22 | G44: 6 | H44: 24 | I44: -33 | J44: =-123+26-SUM(G44:I44) -> -94 | K44: -9 | L44: 0 | M44: 0 | W44: =SUM(C44:F44) -> -8 | X44: =SUM(G44:J44) -> -97 | Y44: 0 | Z44: 0 | AA44: 0 | AB44: 0 | AC44: 0 | AD44: 0 | AE44: 0 | AF44: 0 | AG44: 0 | AH44: 0
B45: Pretax Income | C45: =C39+SUM(C40:C44) -> -256 | D45: =D39+SUM(D40:D44) -> 203 | E45: =E39+SUM(E40:E44) -> 860 | F45: =F39+SUM(F40:F44) -> 1421 | G45: =G39+SUM(G40:G44) -> -770 | H45: =H39+SUM(H40:H44) -> 1079 | I45: =I39+SUM(I40:I44) -> 308 | J45: =J39+SUM(J40:J44) -> 892 | ... M45: =M39+SUM(M40:M44) -> 1775 | W45: =SUM(C45:F45) -> 2228 | X45: =SUM(G45:J45) -> 1509 | Y45: =Y39+Y40 -> 2304.1318 | Z45: =Z39+Z40 -> 4006.2254 | AA45: =AA39+AA40 -> 6563.9439 | AB45: =AB39+AB40 -> 10075.63 | AC45: =AC39+AC40 -> 14768.917 | AD45: =AD39+AD40 -> 20962.254 | AE45: =AE39+AE40 -> 29307.704 | AF45: =AF39+AF40 -> 40338.738 | ... AH45: =AH39+AH40 -> 73499.994
...

Sheet Notes | Quant Analysis
CI1: 0
P2: Employee Scope: | AL2: General Notes/Observations
Q32: Notes: | R32: [X]
R33: [Y]
R34: [Z]
AL35: Financial Stmts. Notes/Observations
P36: Institutional Ownership Snapshot Q2'25 | AL36: Revenues:
Q66: Notes: | R66: [X]
R67: [Y]
R68: [Z]
P70: Revenue Breakdown by Segment (Build graph for this section if applicable…. See example below) | AL70: Earnings Scope:
Q102: Notes: | R102: [X]
R103: [Y]
R104: [Z]
P106: Q/q Total Revenues, Net Income, FCF | AL106: Balance Sheet Scope:
Q135: Notes: | R135: [X]
R136: [Y]
R137: [Z]
P139: Y/y Total Revenues, Net Income, FCF | AL139: [Equity Preformance Compared to Peers]
Q168: Notes: | R168: [X]
R169: [Y]
R170: [Z]
A185: VOO Historical Returns
A186: 251 Trading Days? (From: 8/1/2025 - 8/1/2026) | I186: 251 Trading Days? (From: 8/1/2025 - 8/1/2026)
A187: Close | B187: High | C187: Low | D187: Open | E187: Volume | F187: UTC Date | G187: Change | I187: Close | J187: High | K187: Low | L187: Open | M187: Volume | N187: UTC Date | O187: Change
A188: 686.65 | B188: 688.35 | C188: 678.06 | D188: 684.5 | E188: 7661568.2 | F188: Fri, 31 Jul 2026 00:00:00 GMT | G188: =A188/D188-1 -> 0.0031409788 | I188: 117.15 | J188: 122.25 | K188: 115.27 | L188: 120.93 | M188: 12043764 | N188: Fri, 31 Jul 2026 00:00:00 GMT | O188: =I188/L188-1 -> -0.031257752
A189: 681.79 | B189: 682.4363 | C189: 675.21 | D189: 676.54 | E189: 6009104.5 | F189: Thu, 30 Jul 2026 00:00:00 GMT | G189: =A189/D189-1 -> 0.0077600733 | I189: 122.4 | J189: 126.61 | K189: 122.29 | L189: 126.315 | M189: 10314840 | N189: Thu, 30 Jul 2026 00:00:00 GMT | O189: =I189/L189-1 -> -0.030993944
A190: 670.63 | B190: 682.63 | C190: 670.155 | D190: 680.12 | E190: 7845443.5 | F190: Wed, 29 Jul 2026 00:00:00 GMT | G190: =A190/D190-1 -> -0.01395342 | I190: 129.17 | J190: 133.73 | K190: 128.22 | L190: 129.045 | M190: 7304206.9 | N190: Wed, 29 Jul 2026 00:00:00 GMT | O190: =I190/L190-1 -> 0.00096865435
A191: 680.96 | B191: 682.755 | C191: 676.4801 | D191: 679.45 | E191: 5021080 | F191: Tue, 28 Jul 2026 00:00:00 GMT | G191: =A191/D191-1 -> 0.0022223858 | I191: 130.28 | J191: 133.99 | K191: 127.87 | L191: 128.29 | M191: 9553143.2 | N191: Tue, 28 Jul 2026 00:00:00 GMT | O191: =I191/L191-1 -> 0.015511731
A192: 679.31 | B192: 685.2391 | C192: 676.395 | D192: 684.69 | E192: 5207757.8 | F192: Mon, 27 Jul 2026 00:00:00 GMT | G192: =A192/D192-1 -> -0.0078575706 | I192: 126.88 | J192: 126.91 | K192: 117.81 | L192: 118.195 | M192: 10161838 | N192: Mon, 27 Jul 2026 00:00:00 GMT | O192: =I192/L192-1 -> 0.073480266
A193: 679.14 | B193: 683.55 | C193: 677.7 | D193: 678.8 | E193: 6286807 | F193: Fri, 24 Jul 2026 00:00:00 GMT | G193: =A193/D193-1 -> 0.00050088391 | I193: 113.75 | J193: 114.6 | K193: 111.26 | L193: 112.99 | M193: 6998804.4 | N193: Fri, 24 Jul 2026 00:00:00 GMT | O193: =I193/L193-1 -> 0.006726259
A194: 678.61 | B194: 682.5495 | C194: 675.755 | D194: 679.55 | E194: 4942804.8 | F194: Thu, 23 Jul 2026 00:00:00 GMT | G194: =A194/D194-1 -> -0.0013832683 | I194: 112 | J194: 117.91 | K194: 111.055 | L194: 117.44 | M194: 10236843 | N194: Thu, 23 Jul 2026 00:00:00 GMT | O194: =I194/L194-1 -> -0.046321526
A195: 687.03 | B195: 689.4 | C195: 686.02 | D195: 686.29 | E195: 3349102.7 | F195: Wed, 22 Jul 2026 00:00:00 GMT | G195: =A195/D195-1 -> 0.0010782614 | I195: 118.42 | J195: 123.425 | K195: 116.621 | L195: 122.95 | M195: 7679815.6 | N195: Wed, 22 Jul 2026 00:00:00 GMT | O195: =I195/L195-1 -> -0.036844246
A196: 687.87 | B196: 688.485 | C196: 684.03 | D196: 685.95 | E196: 4054717.9 | F196: Tue, 21 Jul 2026 00:00:00 GMT | G196: =A196/D196-1 -> 0.0027990378 | I196: 123.03 | J196: 124.29 | K196: 119.25 | L196: 121.21 | M196: 6551861.5 | N196: Tue, 21 Jul 2026 00:00:00 GMT | O196: =I196/L196-1 -> 0.015015263
A197: 682.21 | B197: 688.2 | C197: 681.57 | D197: 686.67 | E197: 5321985.3 | F197: Mon, 20 Jul 2026 00:00:00 GMT | G197: =A197/D197-1 -> -0.0064951141 | I197: 124.48 | J197: 128.26 | K197: 123.45 | L197: 124.23 | M197: 7312521.2 | N197: Mon, 20 Jul 2026 00:00:00 GMT | O197: =I197/L197-1 -> 0.0020123964
A198: 683.17 | B198: 686.8653 | C198: 680.92 | D198: 682.12 | E198: 5627641.4 | F198: Fri, 17 Jul 2026 00:00:00 GMT | G198: =A198/D198-1 -> 0.0015393186 | I198: 123.56 | J198: 124.6 | K198: 121.11 | L198: 124.6 | M198: 6312592.5 | N198: Fri, 17 Jul 2026 00:00:00 GMT | O198: =I198/L198-1 -> -0.0083467095
A199: 690.14 | B199: 693.55 | C199: 687.43 | D199: 691.98 | E199: 4722611.2 | F199: Thu, 16 Jul 2026 00:00:00 GMT | G199: =A199/D199-1 -> -0.0026590364 | I199: 125.06 | J199: 127.89 | K199: 121.78 | L199: 124.6 | M199: 7302620.4 | N199: Thu, 16 Jul 2026 00:00:00 GMT | O199: =I199/L199-1 -> 0.0036918138
A200: 693.8 | B200: 694.5 | C200: 689.58 | D200: 693.27 | E200: 4110059.9 | F200: Wed, 15 Jul 2026 00:00:00 GMT | G200: =A200/D200-1 -> 0.00076449291 | I200: 123.55 | J200: 127.59 | K200: 120.87 | L200: 126.45 | M200: 8182482 | N200: Wed, 15 Jul 2026 00:00:00 GMT | O200: =I200/L200-1 -> -0.022933966
A201: 691.1 | B201: 692.4 | C201: 688.2 | D201: 690.21 | E201: 4570040.4 | F201: Tue, 14 Jul 2026 00:00:00 GMT | G201: =A201/D201-1 -> 0.0012894626 | I201: 125.68 | J201: 126.11 | K201: 120 | L201: 121.63 | M201: 4727877.2 | N201: Tue, 14 Jul 2026 00:00:00 GMT | O201: =I201/L201-1 -> 0.033297706 | R201: Min | S201: =MIN(O188:O438) -> -0.14535637
A202: 688.5 | B202: 692.96 | C202: 687.54 | D202: 691.6 | E202: 6587891.4 | F202: Mon, 13 Jul 2026 00:00:00 GMT | G202: =A202/D202-1 -> -0.0044823597 | I202: 124.74 | J202: 126.7 | K202: 121.7 | L202: 124.63 | M202: 6576280.4 | N202: Mon, 13 Jul 2026 00:00:00 GMT | O202: =I202/L202-1 -> 0.00088261253 | R202: Max | S202: =MAX(O188:O438) -> 0.076364923
...

Sheet Product Lines

Sheet Management

Sheet Table Formatting
B2: [Bold Title] | G2: [Bold Title]
B3: Line Titles | G3: <-- General
B4: Line Titles | G4: <-- Info
B5: Line Titles | G5: <-- General
B6: Line Titles | G6: <-- Info
B7: Line Titles | G7: <-- General
B8: Line Titles | G8: <-- Info
