Workbook

Sheet Main
A2: Capital Structure Snapshot:
B4: SRPT
B5: Price | C5: 23.73 | D5: 1/10/2026
B6: SO | C6: 104.787 | D6: Q3'25
B7: MC | C7: =C5*C6 -> 2486.5955
B8: Cash | C8: =510.59+289.54+195.52 -> 995.65 | D8: Q3'25 | O8: Resources:
B9: Debt | C9: ='Bull Case (20%)'!X65 -> 1139.458 | D9: Q3'25 | O9: SEC Filings | R9: https://www.sec.gov/edgar/browse/?CIK=873303&owner=exclude
B10: EV | C10: =C7-C8+C9 -> 2630.4035 | O10: Sarepta Homepage | R10: https://www.sarepta.com/
P11: Sarepta IR Page | S11: https://investorrelations.sarepta.com/
B12: Sarepta, Therapeutics Inc. (SRPT) | O12: Earnings Calls | R12: https://seekingalpha.com/symbol/SRPT/sec-filings
O13: Equity Analysis | R13: https://stockanalysis.com/stocks/srpt/company/
B14: Founder(s): James Summerton & Dwight Weller | H14: Registered Exchange: NASDAQ | O14: MacroTrends | R14: https://www.macrotrends.net/stocks/charts/SRPT/sarepta-therapeutics/income-statement?freq=A
B15: Founded: 1980 | H15: Address: | I15: 215 First Street, Suite 415, Cambridge, MA 02142 | O15: ROIC/WACC | R15: https://www.gurufocus.com/term/wacc/SRPT
B16: Headquarters: Cambridge, MA | H16: Investor Relations Contact: | O16: Godel Terminal | R16: https://app.godelterminal.com/
B17: Current CEO: Douglas Ingram | H17: Investors Relation Department | O17: Pharsight Patent Search | R17: https://pharsight.greyb.com/drug/exondys-51-patent-expiration
B18: Employees: 1,372 (Q4'24) | H18: Phone: | I18: (617) 274-4000 | K18: Email: | L18: investors@sarepta.com | P18: Vyondys 53 | S18: https://pharsight.greyb.com/drug/vyondys-53-patent-expiration
B19: Industry: BioTech | P19: Amondys 45 Scope | S19: https://pharsight.greyb.com/drug/amondys-45-patent-expiration
B20: Sector: Healthcare | P20: Exondys 51 | S20: https://pharsight.greyb.com/drug/exondys-51-patent-expiration
B21: IPO: June 3rd, 1997 -- ~$600M valuation | O21: Duchenne Info | R21: https://cureduchenne.org/about/what-is-duchenne/
A23: Company Overview:
B24: Sarepta Therapeutics, Inc., a commercial-stage biopharmaceutical company, focuses on the discovery and development of RNA-targeted therapeutics, gene therapies, and other genetic therapeutic modalities for the treatment of rare diseases
C25: It offers EXONDYS 51 injection to treat Duchenne muscular dystrophy (Duchenne) in patients with confirmed mutation of the dystrophin gene that is amenable to exon 51 skipping
C26: VYONDYS 53 for the treatment of Duchenne in patients with confirmed mutation of the dystrophin gene that is amenable to exon 53 skipping
C27: AMONDYS 45, for the treatment of Duchenne in patients with confirmed mutation of the dystrophin gene that is amenable to exon 45 skipping
C28: ELEVIDYS, an adeno-associated virus based gene therapy for the treatment of ambulatory pediatric patients with Duchenne with a confirmed mutation in the Duchenne gene
C29: The company is also developing SRP-9003, a limb-girdle muscular dystrophies gene therapy program
B30: It has collaboration and license agreements with:
C31: F. Hoffman-La Roche Ltd
C32: Arrowhead Pharmaceuticals, Inc.
C33: University of Western Australia
C34: Catalent Maryland, Inc.
C35: Nationwide Children’s Hospital
C36: Dyno Therapeutics
C37: Hansa Biopharma
C38: Duke University
C39: Genethon
B40: The Company was incorporated in 1980 and is headquartered in Cambridge, Massachusetts
B41: The Company's current portfolio seeks to address Duchenne muscular dystrophy (DMD), a rare, progressive genetic disorder that primarily affects boys
C42: By the age of 12, many are reliant on wheelchairs due to muscle degeneration and also encounter social isolation
C43: The condition complicates even the simplest daily activities and, as it progresses, critically affects the heart and respiratory muscles
...

Sheet Bull Case (20%)
C1: Q1 2020 | G1: Q1 2021 | K1: Q1 2022 | O1: Q1 2023 | S1: Q1 2024 | W1: Q1 2025 | AA1: Q1 2026
B2: Quarterly
B3: Revenues | C3: Q1 2020 | D3: Q2 2020 | E3: Q3 2020 | F3: Q4 2020 | G3: Q1 2021 | H3: Q2 2021 | I3: Q3 2021 | J3: Q4 2021 | K3: Q1 2022 | L3: Q2 2022 | M3: Q3 2022 | N3: Q4 2022 | O3: Q1 2023 | P3: Q2 2023 | Q3: Q3 2023 | R3: Q4 2023 | S3: Q1 2024 | T3: Q2 2024 | U3: Q3 2024 | V3: Q4 2024 | W3: Q1 2025 | X3: Q2 2025 | Y3: Q3 2025 | Z3: Q4 2025 | AA3: Q1 2026 | AB3: Q2 2026 | AC3: Q3 2026 | AD3: Q4 2026 | AM3: 2020 | AN3: =AM3+1 -> 2021 | AO3: =AN3+1 -> 2022 | AP3: =AO3+1 -> 2023 | AQ3: =AP3+1 -> 2024 | AR3: =AQ3+1 -> 2025 | AS3: =AR3+1 -> 2026 | AT3: =AS3+1 -> 2027 | AU3: =AT3+1 -> 2028 | ... CY3: =CX3+1 -> 2084
B4: PMO Products | C4: 100.448 | D4: 111.34 | E4: 121.429 | F4: =455.865-SUM(C4:E4) -> 122.648 | G4: 124.926 | H4: 141.839 | I4: 166.911 | J4: =612.401-SUM(G4:I4) -> 178.725 | K4: 188.825 | L4: 211.237 | M4: 207.774 | N4: =843.769-SUM(K4:M4) -> 235.933 | O4: 231.495 | P4: 238.988 | Q4: 240.21 | R4: =944.52-SUM(O4:Q4) -> 233.827 | S4: 225.548 | T4: 238.827 | U4: 248.788 | V4: =967.169-SUM(S4:U4) -> 254.006 | W4: 236.538 | X4: 231.272 | Y4: 238.545 | Z4: =V4*(1+Z14) -> 266.7063 | AA4: =W4*(1+AA14) -> 275.09369 | AB4: =X4*(1+AB14) -> 280.07039 | AC4: =Y4*(1+AC14) -> 218.50722 | AD4: =Z4*(1+AD14) -> 283.5088 | AM4: =SUM(C4:F4) -> 455.865 | AN4: =SUM(G4:J4) -> 612.401 | AO4: =SUM(K4:N4) -> 843.769 | AP4: =SUM(O4:R4) -> 944.52 | AQ4: =SUM(S4:V4) -> 967.169 | AR4: =AQ4*(1+AR14) -> 1010.6916 | AS4: =AR4*(1+AS14) -> 1041.0124 | AT4: =AS4*(1+AT14) -> 1061.8326 | AU4: =AT4*(1+AU14) -> 1008.741 | AV4: =AU4*(1+AV14) -> 933.0854 | AW4: =AV4*(1+AW14) -> 839.77686 | AX4: =AW4*(1+AX14) -> 671.82149 | AY4: =AX4*(1+AY14) -> 537.45719 | ... BA4: =AZ4*(1+BA14) -> 343.9726
B5: ELEVIDYS | C5: 0 | D5: 0 | E5: 0 | F5: 0 | G5: 0 | H5: 0 | I5: 0 | J5: 0 | K5: 0 | L5: 0 | M5: 0 | N5: 0 | O5: 0 | P5: 0 | Q5: 69.108 | R5: =200.356-SUM(O5:Q5) -> 131.248 | S5: 133.936 | T5: 121.72 | U5: 180.983 | V5: =820.791-SUM(S5:U5) -> 384.152 | W5: 374.895 | X5: 281.851 | Y5: 131.49 | Z5: =V5*(1+Z15) -> 111.40408 | AA5: =W5*(1+AA15) -> 104.9706 | AB5: =X5*(1+AB15) -> 98.64785 | AC5: =Y5*(1+AC15) -> 89.4132 | AD5: =Z5*(1+AD15) -> 77.982856 | AM5: =SUM(C5:F5) -> 0 | AN5: =SUM(G5:J5) -> 0 | AO5: =SUM(K5:N5) -> 0 | AP5: =SUM(O5:R5) -> 200.356 | AQ5: =SUM(S5:V5) -> 820.791 | AR5: =AQ5*(1+AR15) -> 906.97406 | AS5: =AR5*(1+AS15) -> 634.88184 | AT5: =AS5*(1+AT15) -> 571.39365 | AU5: =AT5*(1+AU15) -> 514.25429 | AV5: =AU5*(1+AV15) -> 462.82886 | AW5: =AV5*(1+AW15) -> 416.54597 | AX5: =AW5*(1+AX15) -> 374.89138 | AY5: =AX5*(1+AY15) -> 356.14681 | ... BA5: =AZ5*(1+BA15) -> 321.42249
B6: Product Revenues | C6: =SUM(C4:C5) -> 100.448 | D6: =SUM(D4:D5) -> 111.34 | E6: =SUM(E4:E5) -> 121.429 | F6: =SUM(F4:F5) -> 122.648 | G6: =SUM(G4:G5) -> 124.926 | H6: =SUM(H4:H5) -> 141.839 | I6: =SUM(I4:I5) -> 166.911 | J6: =SUM(J4:J5) -> 178.725 | ... AD6: =SUM(AD4:AD5) -> 361.49165 | AM6: =SUM(C6:F6) -> 455.865 | AN6: =SUM(G6:J6) -> 612.401 | AO6: =SUM(K6:N6) -> 843.769 | AP6: =SUM(O6:R6) -> 1144.876 | AQ6: =SUM(S6:V6) -> 1787.96 | AR6: =SUM(AR4:AR5) -> 1917.6657 | AS6: =SUM(AS4:AS5) -> 1675.8942 | AT6: =SUM(AT4:AT5) -> 1633.2263 | AU6: =SUM(AU4:AU5) -> 1522.9953 | AV6: =SUM(AV4:AV5) -> 1395.9143 | AW6: =SUM(AW4:AW5) -> 1256.3228 | AX6: =SUM(AX4:AX5) -> 1046.7129 | AY6: =SUM(AY4:AY5) -> 893.604 | ... BA6: =SUM(BA4:BA5) -> 665.3951
B7: Collaboration Revenues | C7: 0 | D7: 0 | E7: 0 | F7: 0 | G7: 0 | H7: 0 | I7: 0 | J7: 0 | K7: 0 | L7: 0 | M7: 0 | N7: 0 | O7: 0 | P7: 0 | Q7: 0 | R7: 0 | S7: 48 | T7: 0 | U7: 0 | V7: =48-SUM(S7:U7) -> 0 | W7: 112 | X7: 63.5 | Y7: 0 | AM7: =SUM(C7:F7) -> 0 | AN7: =SUM(G7:J7) -> 0 | AO7: =SUM(K7:N7) -> 0 | AP7: =SUM(O7:R7) -> 0 | AQ7: =SUM(S7:V7) -> 48
B8: Contract Manufacturing | C8: 0 | D8: 0 | E8: 0 | F8: 0 | G8: 0 | H8: 0 | I8: 0 | J8: 0 | K8: 0 | L8: 0 | M8: 0 | N8: 0 | O8: 0 | P8: 0 | Q8: 0 | R8: =9.216-SUM(O8:Q8) -> 9.216 | S8: 5.8 | T8: 2.38 | U8: 27.89 | V8: =49.038-SUM(S8:U8) -> 12.968 | W8: 17.379 | X8: 27.02 | Y8: 18.7 | AM8: =SUM(C8:F8) -> 0 | AN8: =SUM(G8:J8) -> 0 | AO8: =SUM(K8:N8) -> 0 | AP8: =SUM(O8:R8) -> 9.216 | AQ8: =SUM(S8:V8) -> 49.038
B9: Royalty Revenues | C9: 0 | D9: 0 | E9: 0 | F9: 0 | G9: 0 | H9: 0 | I9: 0 | J9: 0 | K9: 0 | L9: 0 | M9: 0 | N9: 0 | O9: 0 | P9: 0 | Q9: 0 | R9: 0 | S9: 0.173 | T9: 0 | U9: 9.51 | V9: =16.981-SUM(S9:U9) -> 7.298 | W9: 4.05 | X9: 7.445 | Y9: 10.608 | AM9: =SUM(C9:F9) -> 0 | AN9: =SUM(G9:J9) -> 0 | AO9: =SUM(K9:N9) -> 0 | AP9: =SUM(O9:R9) -> 0 | AQ9: =SUM(S9:V9) -> 16.981
B10: Amortization of PO | C10: 13.226 | D10: 26.019 | E10: 22.495 | F10: =84.234-SUM(C10:E10) -> 22.494 | G10: 22.005 | H10: 22.25 | I10: 22.459 | J10: =89.444-SUM(G10:I10) -> 22.73 | K10: 22.005 | L10: 22.3 | M10: 22.5 | N10: =89.244-SUM(K10:M10) -> 22.439 | O10: 22 | P10: 22.25 | Q10: 22.49 | R10: =89.244-SUM(O10:Q10) -> 22.504 | S10: 0 | T10: 0 | U10: 0 | V10: =0-SUM(S10:U10) -> 0 | W10: 0 | X10: 0 | Y10: 0 | AM10: =SUM(C10:F10) -> 84.234 | AN10: =SUM(G10:J10) -> 89.444 | AO10: =SUM(K10:N10) -> 89.244 | AP10: =SUM(O10:R10) -> 89.244 | AQ10: =SUM(S10:V10) -> 0
B11: Collaboration and Other Revenues | C11: =SUM(C7:C10) -> 13.226 | D11: =SUM(D7:D10) -> 26.019 | E11: =SUM(E7:E10) -> 22.495 | F11: =SUM(F7:F10) -> 22.494 | G11: =SUM(G7:G10) -> 22.005 | H11: =SUM(H7:H10) -> 22.25 | I11: =SUM(I7:I10) -> 22.459 | J11: =SUM(J7:J10) -> 22.73 | ... Y11: =SUM(Y7:Y10) -> 29.308 | Z11: =V11*(1+Z16) -> 35.4655 | AA11: =W11*(1+AA16) -> 30.68867 | AB11: =X11*(1+AB16) -> 24.49125 | AC11: =Y11*(1+AC16) -> 8.20624 | AD11: =Z11*(1+AD16) -> 21.2793 | AM11: =AM10 -> 84.234 | AN11: =AN10 -> 89.444 | AO11: =SUM(K11:N11) -> 89.244 | AP11: =SUM(O11:R11) -> 98.46 | AQ11: =SUM(S11:V11) -> 114.019 | AR11: =AQ11*(1+AR16) -> 293.02883 | AS11: =AR11*(1+AS16) -> 84.978361 | AT11: =AS11*(1+AT16) -> 89.227279 | AU11: =AT11*(1+AU16) -> 93.688643 | AV11: =AU11*(1+AV16) -> 97.436188 | AW11: =AV11*(1+AW16) -> 101.33364 | AX11: =AW11*(1+AX16) -> 104.37364 | AY11: =AX11*(1+AY16) -> 107.50485 | ... BA11: =AZ11*(1+BA16) -> 111.84805
B12: Ttl Revenues | C12: =C6+C11 -> 113.674 | D12: =D11+D6 -> 137.359 | E12: =E6+E11 -> 143.924 | F12: =F6+F11 -> 145.142 | G12: =G6+G11 -> 146.931 | H12: =H6+H11 -> 164.089 | I12: =I6+I11 -> 189.37 | J12: =J6+J11 -> 201.455 | K12: =K6+K11 -> 210.83 | L12: =L6+L11 -> 233.537 | ... AD12: =AD6+AD11 -> 382.77095 | AM12: =AM6+AM11 -> 540.099 | AN12: =AN6+AN11 -> 701.845 | AO12: =SUM(K12:N12) -> 933.013 | AP12: =SUM(O12:R12) -> 1243.336 | AQ12: =SUM(S12:V12) -> 1901.979 | AR12: =AR6+AR11 -> 2210.6945 | AS12: =AS6+AS11 -> 1760.8726 | AT12: =AT6+AT11 -> 1722.4535 | AU12: =AU6+AU11 -> 1616.6839 | AV12: =AV6+AV11 -> 1493.3504 | AW12: =AW6+AW11 -> 1357.6565 | AX12: =AX6+AX11 -> 1151.0865 | AY12: =AY6+AY11 -> 1001.1089 | ... BA12: =BA6+BA11 -> 777.24315
B14: PMO Products Growth Y/y | G14: =G4/C4-1 -> 0.24368828 | H14: =H4/D4-1 -> 0.27392671 | I14: =I4/E4-1 -> 0.37455633 | J14: =J4/F4-1 -> 0.45721903 | K14: =K4/G4-1 -> 0.5114948 | L14: =L4/H4-1 -> 0.48927305 | M14: =M4/I4-1 -> 0.2448191 | N14: =N4/J4-1 -> 0.32008952 | ... X14: =X4/T4-1 -> -0.031633777 | Y14: 0.04 | Z14: 0.05 | AA14: 0.163 | AB14: 0.211 | AC14: -0.084 | AD14: 0.063 | AN14: =AN4/AM4-1 -> 0.34338236 | AO14: =AO4/AN4-1 -> 0.37780474 | AP14: =AP4/AO4-1 -> 0.1194059 | AQ14: =AQ4/AP4-1 -> 0.023979376 | AR14: 0.045 | AS14: 0.03 | AT14: 0.02 | AU14: -0.05 | AV14: -0.075 | AW14: -0.1 | AX14: -0.2 | AY14: -0.2 | AZ14: -0.2 | BA14: -0.2
B15: ELEVIDYS Growth Y/y | U15: =U5/Q5-1 -> 1.618843 | V15: =V5/R5-1 -> 1.926917 | W15: =W5/S5-1 -> 1.7990607 | X15: =X5/T5-1 -> 1.3155685 | Y15: 0.48 | Z15: -0.71 | AA15: -0.72 | AB15: -0.65 | AC15: -0.32 | AD15: -0.3 | AQ15: =AQ5/AP5-1 -> 3.0966629 | AR15: 0.105 | AS15: -0.3 | AT15: -0.1 | AU15: -0.1 | AV15: -0.1 | AW15: -0.1 | AX15: -0.1 | AY15: -0.05 | AZ15: -0.05 | BA15: -0.05
B16: Other Growth Y/y | G16: =G11/C11-1 -> 0.66376834 | H16: =H11/D11-1 -> -0.14485568 | I16: =I11/E11-1 -> -0.0016003556 | J16: =J11/F11-1 -> 0.010491687 | K16: =K11/G11-1 -> 0 | L16: =L11/H11-1 -> 0.002247191 | M16: =M11/I11-1 -> 0.0018255488 | N16: =N11/J11-1 -> -0.012802464 | ... X16: =X11/T11-1 -> 40.161765 | Y16: 1.15 | Z16: 0.75 | AA16: -0.77 | AB16: -0.75 | AC16: -0.72 | AD16: -0.4 | AN16: =AN11/AM11-1 -> 0.061851509 | AO16: =AO11/AN11-1 -> -0.002236036 | AP16: =AP11/AO11-1 -> 0.10326745 | AQ16: =AQ11/AP11-1 -> 0.15802356 | AR16: 1.57 | AS16: -0.71 | AT16: 0.05 | AU16: 0.05 | AV16: 0.04 | AW16: 0.04 | AX16: 0.03 | AY16: 0.03 | AZ16: 0.02 | BA16: 0.02
B17: Ttl Revenue Growth Y/y | G17: =G6/C6-1 -> 0.24368828 | H17: =H6/D6-1 -> 0.27392671 | I17: =I6/E6-1 -> 0.37455633 | J17: =J6/F6-1 -> 0.45721903 | K17: =K6/G6-1 -> 0.5114948 | L17: =L6/H6-1 -> 0.48927305 | M17: =M6/I6-1 -> 0.2448191 | N17: =N6/J6-1 -> 0.32008952 | ... AD17: =AD6/Z6-1 -> -0.043952052 | AN17: =AN12/AM12-1 -> 0.29947473 | AO17: =AO12/AN12-1 -> 0.32937187 | AP17: =AP12/AO12-1 -> 0.33260308 | AQ17: =AQ12/AP12-1 -> 0.52973854 | AR17: =AR12/AQ12-1 -> 0.16231278 | AS17: =AS12/AR12-1 -> -0.2034754 | AT17: =AT12/AS12-1 -> -0.021818171 | AU17: =AU12/AT12-1 -> -0.061406377 | ... BA17: =BA12/AZ12-1 -> -0.11471708
B19: PMO % of Ttl Revenues | C19: =C4/C12 -> 0.88364974 | D19: =D4/D12 -> 0.81057666 | E19: =E4/E12 -> 0.84370223 | F19: =F4/F12 -> 0.84502074 | G19: =G4/G12 -> 0.85023582 | H19: =H4/H12 -> 0.86440285 | I19: =I4/I12 -> 0.88140149 | J19: =J4/J12 -> 0.88717083 | ... AD19: =AD4/AD12 -> 0.74067479 | AM19: =AM4/AM6 -> 1 | AN19: =AN4/AN6 -> 1 | AO19: =AO4/AO6 -> 1 | AP19: =AP4/AP6 -> 0.82499764 | AQ19: =AQ4/AQ6 -> 0.54093436 | AR19: =AR4/AR6 -> 0.52704266 | AS19: =AS4/AS6 -> 0.6211683 | AT19: =AT4/AT6 -> 0.65014421 | ... BA19: =BA4/BA6 -> 0.5169449
B20: ELEVIDYS % of Ttl Revenues | Q20: =Q5/Q12 -> 0.20827708 | R20: =R5/R12 -> 0.3307703 | S20: =S5/S12 -> 0.32394179 | T20: =T5/T12 -> 0.33538425 | U20: =U5/U12 -> 0.38740204 | V20: =V5/V12 -> 0.58344167 | W20: =W5/W12 -> 0.503308 | X20: =X5/X12 -> 0.46122817 | ... AD20: =AD5/AD12 -> 0.20373243 | AM20: =AM5/AM6 -> 0 | AN20: =AN5/AN6 -> 0 | AO20: =AO5/AO6 -> 0 | AP20: =AP5/AP6 -> 0.17500236 | AQ20: =AQ5/AQ6 -> 0.45906564 | AR20: =AR5/AR6 -> 0.47295734 | AS20: =AS5/AS6 -> 0.3788317 | AT20: =AT5/AT6 -> 0.34985579 | ... BA20: =BA5/BA6 -> 0.4830551
B21: Other % of Ttl Revenues | C21: =C11/C12 -> 0.11635026 | D21: =D11/D12 -> 0.18942334 | E21: =E11/E12 -> 0.15629777 | F21: =F11/F12 -> 0.15497926 | G21: =G11/G12 -> 0.14976418 | H21: =H11/H12 -> 0.13559715 | I21: =I11/I12 -> 0.11859851 | J21: =J11/J12 -> 0.11282917 | ... AD21: =AD11/AD12 -> 0.055592776
B23: Revenues | C23: =C12 -> 113.674 | D23: =D12 -> 137.359 | E23: =E12 -> 143.924 | F23: =F12 -> 145.142 | G23: =G12 -> 146.931 | H23: =H12 -> 164.089 | I23: =I12 -> 189.37 | J23: =J12 -> 201.455 | ... AD23: =AD12 -> 382.77095 | AM23: =SUM(C23:F23) -> 540.099 | AN23: =SUM(G23:J23) -> 701.845 | AO23: =SUM(K23:N23) -> 933.013 | AP23: =SUM(O23:R23) -> 1243.336 | AQ23: =SUM(S23:V23) -> 1901.979 | AR23: =AR12 -> 2210.6945 | AS23: =AS12 -> 1760.8726 | AT23: =AT12 -> 1722.4535 | AU23: =AU12 -> 1616.6839 | AV23: =AV12 -> 1493.3504 | AW23: =AW12 -> 1357.6565 | AX23: =AX12 -> 1151.0865 | AY23: =AY12 -> 1001.1089 | ... BA23: =BA12 -> 777.24315
B24: COGS | C24: 12.622 | D24: 13.341 | E24: 15.015 | F24: =63.382-SUM(C24:E24) -> 22.404 | G24: 22.346 | H24: 19.515 | I24: 23.44 | J24: =97.049-SUM(G24:I24) -> 31.748 | K24: 31.443 | L24: 37.795 | M24: 39.952 | N24: =139.989-SUM(K24:M24) -> 30.799 | O24: 35.017 | P24: 34.124 | Q24: 37.026 | R24: =150.343-SUM(O24:Q24) -> 44.176 | S24: 50.559 | T24: 44.54 | U24: 91.691 | V24: =319.099-SUM(S24:U24) -> 132.309 | W24: 137.56 | X24: 152.558 | Y24: 150.775 | Z24: =Z23*(1-Z39) -> 82.715176 | AA24: =AA23*(1-AA39) -> 78.043063 | AB24: =AB23*(1-AB39) -> 72.577709 | AC24: =AC23*(1-AC39) -> 53.741532 | AD24: =AD23*(1-AD39) -> 65.071062 | AM24: =SUM(C24:F24) -> 63.382 | AN24: =SUM(G24:J24) -> 97.049 | AO24: =SUM(K24:N24) -> 139.989 | AP24: =SUM(O24:R24) -> 150.343 | AQ24: =SUM(S24:V24) -> 319.099 | AR24: =AR23*(1-AR39) -> 530.56668 | AS24: =AS23*(1-AS39) -> 334.56578 | AT24: =AT23*(1-AT39) -> 249.75576 | AU24: =AU23*(1-AU39) -> 226.33575 | AV24: =AV23*(1-AV39) -> 209.06906 | AW24: =AW23*(1-AW39) -> 190.07191 | AX24: =AX23*(1-AX39) -> 161.15211 | AY24: =AY23*(1-AY39) -> 140.15524 | ... BA24: =BA23*(1-BA39) -> 108.81404
B25: GP | C25: =C23-C24 -> 101.052 | D25: =D23-D24 -> 124.018 | E25: =E23-E24 -> 128.909 | F25: =F23-F24 -> 122.738 | G25: =G23-G24 -> 124.585 | H25: =H23-H24 -> 144.574 | I25: =I23-I24 -> 165.93 | J25: =J23-J24 -> 169.707 | ... Y25: =Y23-Y24 -> 248.568 | Z25: =Z23*Z39 -> 330.8607 | AA25: =AA23*AA39 -> 332.7099 | AB25: =AB23*AB39 -> 330.63178 | AC25: =AC23*AC39 -> 262.38513 | AD25: =AD23*AD39 -> 317.69989 | AM25: =SUM(C25:F25) -> 476.717 | AN25: =SUM(G25:J25) -> 604.796 | AO25: =SUM(K25:N25) -> 793.024 | AP25: =SUM(O25:R25) -> 1092.993 | AQ25: =SUM(S25:V25) -> 1582.88 | AR25: =AR23-AR24 -> 1680.1278 | AS25: =AS23-AS24 -> 1426.3068 | AT25: =AT23-AT24 -> 1472.6978 | AU25: =AU23-AU24 -> 1390.3482 | AV25: =AV23-AV24 -> 1284.2814 | AW25: =AW23-AW24 -> 1167.5846 | AX25: =AX23-AX24 -> 989.9344 | AY25: =AY23-AY24 -> 860.95361 | ... BA25: =BA23-BA24 -> 668.42911
B26: R&D | C26: 136.144 | D26: 188.522 | E26: 190.438 | F26: =722.343-SUM(C26:E26) -> 207.239 | G26: 195.149 | H26: 239.622 | I26: 139.115 | J26: =771.182-SUM(G26:I26) -> 197.296 | K26: 194.25 | L26: 252.329 | M26: 216.7 | N26: =877.09-SUM(K26:M26) -> 213.811 | O26: 245.679 | P26: 241.89 | Q26: 194.301 | R26: =877.387-SUM(O26:Q26) -> 195.517 | S26: 200.396 | T26: 179.69 | U26: 224.483 | V26: =804.522-SUM(S26:U26) -> 199.953 | W26: 773.448 | X26: 204.392 | Y26: 218.89 | Z26: =Z23*Z40 -> 138.32967 | AA26: =AA23*AA40 -> 137.38548 | AB26: =AB23*AB40 -> 134.8624 | AC26: =AC23*AC40 -> 105.73561 | AD26: =AD23*AD40 -> 128.02628 | AM26: =SUM(C26:F26) -> 722.343 | AN26: =SUM(G26:J26) -> 771.182 | AO26: =SUM(K26:N26) -> 877.09 | AP26: =SUM(O26:R26) -> 877.387 | AQ26: =SUM(S26:V26) -> 804.522 | AR26: =AR23*AR40 -> 1348.5236 | AS26: =AS23*AS40 -> 968.4799 | AT26: =AT23*AT40 -> 723.43048 | AU26: =AU23*AU40 -> 517.33885 | AV26: =AV23*AV40 -> 418.13812 | AW26: =AW23*AW40 -> 339.41412 | AX26: =AX23*AX40 -> 276.26076 | AY26: =AY23*AY40 -> 240.26612 | ... BA26: =BA23*BA40 -> 186.53835
B27: SG&A | C27: 82.768 | D27: 73.688 | E27: 75.373 | F27: =317.875-SUM(C27:E27) -> 86.046 | G27: 71.131 | H27: 72.347 | I27: 61.127 | J27: =282.66-SUM(G27:I27) -> 78.055 | K27: 71.84 | L27: 154.316 | M27: 104.787 | N27: =451.421-SUM(K27:M27) -> 120.478 | O27: 110.714 | P27: 118.56 | Q27: 120.893 | R27: =481.871-SUM(O27:Q27) -> 131.704 | S27: 127.003 | T27: 138.796 | U27: 128.2 | V27: =557.87-SUM(S27:U27) -> 163.871 | W27: 133.629 | X27: 137.897 | Y27: 91.89 | Z27: =Z23*Z41 -> 93.326776 | AA27: =AA23*AA41 -> 92.689762 | AB27: =AB23*AB41 -> 90.987516 | AC27: =AC23*AC41 -> 71.336564 | AD27: =AD23*AD41 -> 86.375393 | AM27: =SUM(C27:F27) -> 317.875 | AN27: =SUM(G27:J27) -> 282.66 | AO27: =SUM(K27:N27) -> 451.421 | AP27: =SUM(O27:R27) -> 481.871 | AQ27: =SUM(S27:V27) -> 557.87 | AR27: =AR23*AR41 -> 541.62015 | AS27: =AS23*AS41 -> 343.37015 | AT27: =AT23*AT41 -> 331.57231 | AU27: =AU23*AU41 -> 307.16994 | AV27: =AV23*AV41 -> 276.26983 | AW27: =AW23*AW41 -> 247.77231 | AX27: =AX23*AX41 -> 207.19557 | AY27: =AY23*AY41 -> 180.19959 | ... BA27: =BA23*BA41 -> 139.90377
B28: Settlement and Liscence | C28: 0 | D28: 0 | E28: 0 | F28: =0-SUM(C28:E28) -> 0 | G28: 10 | H28: 0 | I28: 0 | J28: =10-SUM(G28:I28) -> 0 | K28: 0 | L28: 0 | M28: 0 | N28: =0-SUM(K28:M28) -> 0 | O28: 0 | P28: 0 | Q28: =0-SUM(N28:P28) -> 0 | R28: =0-SUM(O28:Q28) -> 0 | S28: =0-SUM(P28:R28) -> 0 | T28: =0-SUM(Q28:S28) -> 0 | U28: 0 | V28: 0 | W28: 0 | X28: 0 | Y28: 40.51 | Z28: 0 | AA28: 0 | AB28: 0 | AC28: 0 | AD28: 0 | AM28: =SUM(C28:F28) -> 0 | AN28: =SUM(G28:J28) -> 10 | AO28: =SUM(K28:N28) -> 0 | AP28: =SUM(O28:R28) -> 0 | AQ28: =SUM(S28:V28) -> 0 | AR28: 0 | AS28: 0 | AT28: 0 | AU28: 0 | AV28: 0 | AW28: 0 | AX28: 0 | AY28: 0 | AZ28: 0 | BA28: 0
B29: Amortization of In-Liscensed Rights | C29: 0.166 | D29: 0.165 | E29: 0.166 | F29: =0.662-SUM(C29:E29) -> 0.165 | G29: 0.17 | H29: 0.179 | I29: 0.178 | J29: =0.706-SUM(G29:I29) -> 0.179 | K29: 0.178 | L29: 0.179 | M29: 0.178 | N29: =0.71-SUM(K29:M29) -> 0.175 | O29: 0.178 | P29: 0.179 | Q29: 0.439 | R29: =1.559-SUM(O29:Q29) -> 0.763 | S29: 0.601 | T29: 0.601 | U29: 0.6 | V29: =2.405-SUM(S29:U29) -> 0.603 | W29: 0.6 | X29: 0.667 | Y29: 0.677 | Z29: 0 | AA29: 0 | AB29: 0 | AC29: 0 | AD29: 0 | AM29: =SUM(C29:F29) -> 0.662 | AN29: =SUM(G29:J29) -> 0.706 | AO29: =SUM(K29:N29) -> 0.71 | AP29: =SUM(O29:R29) -> 1.559 | AQ29: =SUM(S29:V29) -> 2.405 | AR29: =AQ29*1 -> 2.405 | AS29: =AR29*1.05 -> 2.52525 | AT29: =AS29*1.05 -> 2.6515125 | AU29: =AT29*1.05 -> 2.7840881 | AV29: =AU29*1.05 -> 2.9232925 | AW29: =AV29*1.05 -> 3.0694572 | AX29: =AW29*1.05 -> 3.22293 | AY29: =AX29*1.05 -> 3.3840765 | AZ29: =AY29*1.05 -> 3.5532803 | BA29: =AZ29*1.05 -> 3.7309444
B30: Operating Income | C30: =C25-SUM(C26:C29) -> -118.026 | D30: =D25-SUM(D26:D29) -> -138.357 | E30: =E25-SUM(E26:E29) -> -137.068 | F30: =F25-SUM(F26:F29) -> -170.712 | G30: =G25-SUM(G26:G29) -> -151.865 | H30: =H25-SUM(H26:H29) -> -167.574 | I30: =I25-SUM(I26:I29) -> -34.49 | J30: =J25-SUM(J26:J29) -> -105.823 | ... AD30: =AD25-SUM(AD26:AD29) -> 103.29822 | AM30: =SUM(C30:F30) -> -564.163 | AN30: =SUM(G30:J30) -> -459.752 | AO30: =SUM(K30:N30) -> -536.197 | AP30: =SUM(O30:R30) -> -267.824 | AQ30: =SUM(S30:V30) -> 218.083 | AR30: =AR25-SUM(AR26:AR29) -> -212.42098 | AS30: =AS25-SUM(AS26:AS29) -> 111.93147 | AT30: =AT25-SUM(AT26:AT29) -> 415.04347 | AU30: =AU25-SUM(AU26:AU29) -> 563.05528 | AV30: =AV25-SUM(AV26:AV29) -> 586.95013 | AW30: =AW25-SUM(AW26:AW29) -> 577.32868 | AX30: =AX25-SUM(AX26:AX29) -> 503.25513 | AY30: =AY25-SUM(AY26:AY29) -> 437.10382 | ... BA30: =BA25-SUM(BA26:BA29) -> 338.25604
B31: Other Income (Expenses) | C31: -7.42 | D31: 0 | E31: -45 | F31: =-51.971-SUM(C31:E31) -> 0.449 | G31: -15.528 | H31: 102 | I31: -20.649 | J31: =-68.43-SUM(G31:I31) -> -134.253 | K31: -17.26 | L31: 0 | M31: =6.7-125.44 -> -118.74 | N31: =-125.441+6.7-SUM(K31:M31) -> 17.259 | O31: 12.7 | P31: 16.934 | Q31: -12.33 | R31: =33.055-SUM(O31:Q31) -> 15.751 | S31: 6.54 | T31: 14.278 | U31: 11.81 | V31: =42.693-SUM(S31:U31) -> 10.065 | W31: -83.132 | X31: 38.06 | Y31: -138.61 | Z31: =Y46*(0.06) -> 36.7842 | AA31: =Z46*(0.06) -> 43.474832 | AB31: =AA46*(0.06) -> 50.663419 | AC31: =AB46*(0.06) -> 58.311327 | AD31: =AC46*(0.06) -> 65.377642 | AM31: =SUM(C31:F31) -> -51.971 | AN31: =SUM(G31:J31) -> -68.43 | AO31: =SUM(K31:N31) -> -118.741 | AP31: =SUM(O31:R31) -> 33.055 | AQ31: =SUM(S31:V31) -> 42.693 | AR31: -35 | AS31: =AR46*($BA$48) -> 87.986157 | AT31: =AS46*($BA$48) -> 106.89836 | AU31: =AT46*($BA$48) -> 155.15189 | AV31: =AU46*($BA$48) -> 220.77807 | AW31: =AV46*($BA$48) -> 294.58423 | AX31: =AW46*($BA$48) -> 374.25527 | AY31: =AX46*($BA$48) -> 454.43779 | AZ31: =AY46*($BA$48) -> 535.9024 | BA31: =AZ46*($BA$48) -> 619.84419
B32: Gain on, Income | C32: 108.069 | D32: -12.447 | E32: -14.335 | F32: =108.1-45-SUM(C32:E32) -> -18.187 | G32: 0 | H32: -16.185 | I32: 7.2 | J32: =102+7.2-SUM(G32:I32) -> 118.185 | K32: 0 | L32: -16.961 | M32: -6.33 | N32: =-35.021-SUM(K32:M32) -> -11.73 | O32: -387.32 | P32: 102 | Q32: 0 | R32: =-387.329+102-SUM(O32:Q32) -> -0.009 | S32: 0 | T32: 0 | U32: 0 | V32: =0-SUM(S32:U32) -> 0 | W32: 0 | X32: 0 | Y32: 47.95 | Z32: 0 | AA32: 0 | AB32: 0 | AC32: 0 | AD32: 0 | AM32: =SUM(C32:F32) -> 63.1 | AN32: =SUM(G32:J32) -> 109.2 | AO32: =SUM(K32:N32) -> -35.021 | AP32: =SUM(O32:R32) -> -285.329 | AQ32: =SUM(S32:V32) -> 0 | AR32: 0 | AS32: 0 | AT32: 0 | AU32: 0 | AV32: 0 | AW32: 0 | AX32: 0 | AY32: 0 | AZ32: 0 | BA32: 0
B33: Pretax Income | C33: =C30+SUM(C31:C32) -> -17.377 | D33: =D30+SUM(D31:D32) -> -150.804 | E33: =E30+SUM(E31:E32) -> -196.403 | F33: =F30+SUM(F31:F32) -> -188.45 | G33: =G30+SUM(G31:G32) -> -167.393 | H33: =H30+SUM(H31:H32) -> -81.759 | I33: =I30+SUM(I31:I32) -> -47.939 | J33: =J30+SUM(J31:J32) -> -121.891 | ... AD33: =AD30+SUM(AD31:AD32) -> 168.67586 | AM33: =SUM(C33:F33) -> -553.034 | AN33: =SUM(G33:J33) -> -418.982 | AO33: =SUM(K33:N33) -> -689.959 | AP33: =SUM(O33:R33) -> -520.098 | AQ33: =SUM(S33:V33) -> 260.776 | AR33: =AR30+SUM(AR31:AR32) -> -247.42098 | AS33: =AS30+SUM(AS31:AS32) -> 199.91762 | AT33: =AT30+SUM(AT31:AT32) -> 521.94183 | AU33: =AU30+SUM(AU31:AU32) -> 718.20716 | AV33: =AV30+SUM(AV31:AV32) -> 807.7282 | AW33: =AW30+SUM(AW31:AW32) -> 871.91291 | AX33: =AX30+SUM(AX31:AX32) -> 877.51041 | AY33: =AY30+SUM(AY31:AY32) -> 891.5416 | ... BA33: =BA30+SUM(BA31:BA32) -> 958.10023
B34: Taxes | C34: 0.115 | D34: 0.2 | E34: 0.096 | F34: =1.063-SUM(C34:E34) -> 0.652 | G34: -0.143 | H34: -0.35 | I34: 0.237 | J34: =-0.168-SUM(G34:I34) -> 0.088 | K34: 0.879 | L34: 3.388 | M34: 1.32 | N34: =13.525-SUM(K34:M34) -> 7.938 | O34: 4.045 | P34: 9.355 | Q34: 7.763 | R34: =15.879-SUM(O34:Q34) -> -5.284 | S34: 5.329 | T34: 7.117 | U34: 0.395 | V34: =25.535-SUM(S34:U34) -> 12.694 | W34: 63.99 | X34: -43.25 | Y34: -14.1 | Z34: =Z33*Z43 -> 24.477922 | AA34: =AA33*AA43 -> 26.299708 | AB34: =AB33*AB43 -> 27.980151 | AC34: =AC33*AC43 -> 25.852371 | AD34: =AD33*AD43 -> 30.361656 | AM34: =SUM(C34:F34) -> 1.063 | AN34: =SUM(G34:J34) -> -0.168 | AO34: =SUM(K34:N34) -> 13.525 | AP34: =SUM(O34:R34) -> 15.879 | AQ34: =SUM(S34:V34) -> 25.535 | AR34: =AR33*AR43 -> 37.113146 | AS34: =AS33*AS43 -> 23.990115 | AT34: =AT33*AT43 -> 73.071857 | AU34: =AU33*AU43 -> 107.73107 | AV34: =AV33*AV43 -> 121.15923 | AW34: =AW33*AW43 -> 130.78694 | AX34: =AX33*AX43 -> 131.62656 | AY34: =AY33*AY43 -> 133.73124 | ... BA34: =BA33*BA43 -> 143.71503
B35: Net Income | C35: =C33-C34 -> -17.492 | D35: =D33-D34 -> -151.004 | E35: =E33-E34 -> -196.499 | F35: =F33-F34 -> -189.102 | G35: =G33-G34 -> -167.25 | H35: =H33-H34 -> -81.409 | I35: =I33-I34 -> -48.176 | J35: =J33-J34 -> -121.979 | K35: =K33-K34 -> -105.02 | L35: =L33-L34+-2.2 -> -233.631 | M35: =M33-M34-0.72 -> -258.453 | N35: =N33-N34 -> -109.3 | O35: =O33-O34 -> -516.758 | P35: =P33-P34 -> -23.936 | Q35: =Q33-Q34 -> -40.944 | R35: =R33-R34 -> 45.661 | S35: =S33-S34-1.6 -> 34.509 | T35: =T33-T34 -> 6.461 | U35: =U33-U34 -> 33.612 | V35: =V33-V34 -> 159.059 | W35: =W33-W34 -> -447.497 | X35: =X33-X34 -> 196.884 | Y35: =Y33-Y34 -> -179.959 | Z35: =Z33-Z34 -> 111.51054 | AA35: =AA33-AA34 -> 119.80978 | ... AD35: =AD33-AD34 -> 138.31421 | AM35: =SUM(C35:F35) -> -554.097 | AN35: =SUM(G35:J35) -> -418.814 | AO35: =SUM(K35:N35) -> -706.404 | AP35: =SUM(O35:R35) -> -535.977 | AQ35: =SUM(S35:V35) -> 233.641 | AR35: =AR33-AR34 -> -284.53412 | AS35: =AS33-AS34 -> 175.92751 | AT35: =AT33-AT34 -> 448.86998 | AU35: =AU33-AU34 -> 610.47609 | AV35: =AV33-AV34 -> 686.56897 | AW35: =AW33-AW34 -> 741.12598 | AX35: =AX33-AX34 -> 745.88385 | AY35: =AY33-AY34 -> 757.81036 | ... BA35: =BA33-BA34 -> 814.38519 | BB35: =BA35*(1+$BA$49) -> 749.23438 | BC35: =BB35*(1+$BA$49) -> 689.29563 | BD35: =BC35*(1+$BA$49) -> 634.15198 | BE35: =BD35*(1+$BA$49) -> 583.41982 | BF35: =BE35*(1+$BA$49) -> 536.74623 | BG35: =BF35*(1+$BA$49) -> 493.80654 | BH35: =BG35*(1+$BA$49) -> 454.30201 | BI35: =BH35*(1+$BA$49) -> 417.95785 | ... BK35: =BJ35*(1+$BA$49) -> 353.75953
B36: SC | C36: 76.432 | D36: 77.968 | E36: 78.501 | F36: 77.77 | G36: 79.454 | H36: 79.746 | I36: 79.88 | J36: 87.12 | K36: 87.253 | L36: 87.511 | M36: 87.62 | N36: 87.981 | O36: 88.186 | P36: 88.743 | Q36: 88.889 | R36: 92.398 | S36: 93.99 | T36: 94.618 | U36: 95.39 | V36: 97.032 | W36: 97.362 | X36: 98.005 | Y36: 100.23 | AM36: =AVERAGE(C36:F36) -> 77.66775 | AN36: =AVERAGE(G36:J36) -> 81.55 | AO36: =AVERAGE(K36:N36) -> 87.59125 | AP36: =AVERAGE(O36:R36) -> 89.554 | AQ36: =AVERAGE(S36:V36) -> 95.2575
B37: EPS | C37: =C35/C36 -> -0.22885702 | D37: =D35/D36 -> -1.9367433 | E37: =E35/E36 -> -2.5031401 | F37: =F35/F36 -> -2.4315546 | G37: =G35/G36 -> -2.1049916 | H37: =H35/H36 -> -1.0208537 | I37: =I35/I36 -> -0.60310466 | J37: =(J35/J36) -> -1.4001263 | K37: =K35/K36 -> -1.2036262 | L37: =L35/L36 -> -2.6697329 | M37: =M35/M36 -> -2.9497033 | N37: =N35/N36 -> -1.2423137 | O37: =O35/O36 -> -5.8598644 | P37: =P35/P36 -> -0.26972268 | Q37: =Q35/Q36 -> -0.46061942 | R37: =R35/R36 -> 0.49417736 | ... Y37: =Y35/Y36 -> -1.7954604 | AM37: =SUM(C37:F37) -> -7.100295 | AN37: =SUM(G37:J37) -> -5.1290762 | AO37: =SUM(K37:N37) -> -8.0653761 | AP37: =SUM(O37:R37) -> -6.0960291 | AQ37: =SUM(S37:V37) -> 2.4270479
B39: Gross Profit Margin | C39: =C25/C23 -> 0.88896318 | D39: =D25/D23 -> 0.90287495 | E39: =E25/E23 -> 0.89567411 | F39: =F25/F23 -> 0.84564082 | G39: =G25/G23 -> 0.84791501 | H39: =H25/H23 -> 0.88107064 | I39: =I25/I23 -> 0.87622115 | J39: =J25/J23 -> 0.84240649 | ... Y39: =Y25/Y23 -> 0.62244236 | Z39: 0.8 | AA39: 0.81 | AB39: 0.82 | AC39: 0.83 | AD39: 0.83 | AM39: =AM25/AM23 -> 0.88264744 | AN39: =AN25/AN23 -> 0.86172303 | AO39: =AO25/AO23 -> 0.84996029 | AP39: =AP25/AP23 -> 0.87908096 | AQ39: =AQ25/AQ23 -> 0.83222791 | AR39: 0.76 | AS39: 0.81 | AT39: 0.855 | AU39: 0.86 | AV39: 0.86 | AW39: 0.86 | AX39: 0.86 | AY39: 0.86 | AZ39: 0.86 | BA39: 0.86
B40: R&D as % of Revenue | C40: =C26/C23 -> 1.1976705 | D40: =D26/D23 -> 1.3724765 | E40: =E26/E23 -> 1.3231845 | F40: =F26/F23 -> 1.4278362 | G40: =G26/G23 -> 1.3281676 | H40: =H26/H23 -> 1.4603173 | I40: =I26/I23 -> 0.73462006 | J40: =J26/J23 -> 0.97935519 | ... Y40: =Y26/Y23 -> 0.5481253 | Z40: 0.33447229 | AA40: 0.33447229 | AB40: 0.33447229 | AC40: 0.33447229 | AD40: 0.33447229 | AM40: =AM26/AM23 -> 1.337427 | AN40: =AN26/AN23 -> 1.0987925 | AO40: =AO26/AO23 -> 0.94006193 | AP40: =AP26/AP23 -> 0.70567168 | AQ40: =AQ26/AQ23 -> 0.42299205 | AR40: 0.61 | AS40: 0.55 | AT40: 0.42 | AU40: 0.32 | AV40: 0.28 | AW40: 0.25 | AX40: 0.24 | AY40: 0.24 | AZ40: 0.24 | BA40: 0.24
B41: SG&A as % of Revenue | C41: =C27/C23 -> 0.72811725 | D41: =D27/D23 -> 0.53646285 | E41: =E27/E23 -> 0.52370001 | F41: =F27/F23 -> 0.59284012 | G41: =G27/G23 -> 0.48411159 | H41: =H27/H23 -> 0.44090097 | I41: =I27/I23 -> 0.32279136 | J41: =J27/J23 -> 0.38745626 | ... Y41: =Y27/Y23 -> 0.23010294 | Z41: 0.22565817 | AA41: 0.22565817 | AB41: 0.22565817 | AC41: 0.22565817 | AD41: 0.22565817 | AM41: =AM27/AM23 -> 0.58854951 | AN41: =AN27/AN23 -> 0.4027385 | AO41: =AO27/AO23 -> 0.48383141 | AP41: =AP27/AP23 -> 0.38756298 | AQ41: =AQ27/AQ23 -> 0.29331028 | AR41: 0.245 | AS41: 0.195 | AT41: 0.1925 | AU41: 0.19 | AV41: 0.185 | AW41: 0.1825 | AX41: 0.18 | AY41: 0.18 | AZ41: 0.18 | BA41: 0.18
B42: Operating Profit Margin | C42: =C30/C23 -> -1.0382849 | D42: =D30/D23 -> -1.0072656 | E42: =E30/E23 -> -0.95236375 | F42: =F30/F23 -> -1.1761723 | G42: =G30/G23 -> -1.0335804 | H42: =H30/H23 -> -1.0212385 | I42: =I30/I23 -> -0.18213022 | J42: =J30/J23 -> -0.52529349 | ... AD42: =AD30/AD23 -> 0.26986954 | AM42: =AM30/AM23 -> -1.0445548 | AN42: =AN30/AN23 -> -0.65506202 | AO42: =AO30/AO23 -> -0.57469403 | AP42: =AP30/AP23 -> -0.21540758 | AQ42: =AQ30/AQ23 -> 0.1146611 | AR42: =AR30/AR23 -> -0.096087893 | AS42: =AS30/AS23 -> 0.06356591 | AT42: =AT30/AT23 -> 0.24096062 | ... BA42: =BA30/BA23 -> 0.43519977
B43: Effective Tax Rate | C43: =-C34/C33 -> 0.0066179433 | D43: =-D34/D33 -> 0.0013262248 | E43: =-E34/E33 -> 0.0004887909 | F43: =-F34/F33 -> 0.0034598037 | G43: =-G34/G33 -> -0.00085427706 | H43: =-H34/H33 -> -0.0042808743 | I43: =-I34/I33 -> 0.0049437827 | J43: =-J34/J33 -> 0.0007219565 | ... Q43: =-Q34/Q33 -> 0.23395919 | R43: =R34/R33 -> -0.13086658 | S43: =S34/S33 -> 0.12860177 | T43: =T34/T33 -> 0.52415672 | U43: =U34/U33 -> 0.011615256 | V43: =V34/V33 -> 0.073908462 | W43: =-W34/W33 -> 0.16685484 | X43: =X34/X33 -> -0.28151321 | Y43: =Y34/Y33 -> 0.072658315 | Z43: 0.18 | AA43: 0.18 | AB43: 0.18 | AC43: 0.18 | AD43: 0.18 | AM43: =-AM34/AM33 -> 0.0019221241 | AN43: =-AN34/AN33 -> -0.00040097188 | AO43: =-AO34/AO33 -> 0.019602614 | AP43: =-AP34/AP33 -> 0.030530785 | AQ43: =-AQ34/AQ33 -> -0.097919287 | AR43: -0.15 | AS43: 0.12 | AT43: 0.14 | AU43: 0.15 | AV43: 0.15 | AW43: 0.15 | AX43: 0.15 | AY43: 0.15 | AZ43: 0.15 | BA43: 0.15
B44: Net Profit Margin | C44: =C35/C23 -> -0.15387864 | D44: =D35/D23 -> -1.0993382 | E44: =E35/E23 -> -1.365297 | F44: =F35/F23 -> -1.3028758 | G44: =G35/G23 -> -1.1382894 | H44: =H35/H23 -> -0.4961271 | I44: =I35/I23 -> -0.25440144 | J44: =J35/J23 -> -0.60549006 | ... Y44: =Y35/Y23 -> -0.45063767 | Z44: 0.322186 | AA44: 0.322186 | AB44: 0.322186 | AC44: 0.322186 | AD44: 0.322186 | AM44: =AM35/AM23 -> -1.0259175 | AN44: =AN35/AN23 -> -0.5967329 | AO44: =AO35/AO23 -> -0.75712128 | AP44: =AP35/AP23 -> -0.43107977 | AQ44: =AQ35/AQ23 -> 0.122841 | AR44: =AR35/AR23 -> -0.12870803 | AS44: =AS35/AS23 -> 0.099909279 | AT44: =AT35/AT23 -> 0.26059918 | ... BA44: =BA35/BA23 -> 1.0477869
...

Sheet Base Case (50%)
C1: Q1 2020 | G1: Q1 2021 | K1: Q1 2022 | O1: Q1 2023 | S1: Q1 2024 | W1: Q1 2025
B2: Quarterly
B3: Revenues | C3: Q1 2020 | D3: Q2 2020 | E3: Q3 2020 | F3: Q4 2020 | G3: Q1 2021 | H3: Q2 2021 | I3: Q3 2021 | J3: Q4 2021 | K3: Q1 2022 | L3: Q2 2022 | M3: Q3 2022 | N3: Q4 2022 | O3: Q1 2023 | P3: Q2 2023 | Q3: Q3 2023 | R3: Q4 2023 | S3: Q1 2024 | T3: Q2 2024 | U3: Q3 2024 | V3: Q4 2024 | W3: Q1 2025 | X3: Q2 2025 | Y3: Q3 2025 | Z3: Q4 2025 | AA3: Q1 2026 | AB3: Q2 2026 | AC3: Q3 2026 | AD3: Q4 2026 | AM3: 2020 | AN3: =AM3+1 -> 2021 | AO3: =AN3+1 -> 2022 | AP3: =AO3+1 -> 2023 | AQ3: =AP3+1 -> 2024 | AR3: =AQ3+1 -> 2025 | AS3: =AR3+1 -> 2026 | AT3: =AS3+1 -> 2027 | AU3: =AT3+1 -> 2028 | ... CY3: =CX3+1 -> 2084
B4: PMO Products | C4: 100.448 | D4: 111.34 | E4: 121.429 | F4: =455.865-SUM(C4:E4) -> 122.648 | G4: 124.926 | H4: 141.839 | I4: 166.911 | J4: =612.401-SUM(G4:I4) -> 178.725 | K4: 188.825 | L4: 211.237 | M4: 207.774 | N4: =843.769-SUM(K4:M4) -> 235.933 | O4: 231.495 | P4: 238.988 | Q4: 240.21 | R4: =944.52-SUM(O4:Q4) -> 233.827 | S4: 225.548 | T4: 238.827 | U4: 248.788 | V4: =967.169-SUM(S4:U4) -> 254.006 | W4: 236.538 | X4: 231.272 | Y4: 238.545 | Z4: 240 | AA4: 255 | AB4: 260 | AC4: 270 | AD4: 275 | AM4: =SUM(C4:F4) -> 455.865 | AN4: =SUM(G4:J4) -> 612.401 | AO4: =SUM(K4:N4) -> 843.769 | AP4: =SUM(O4:R4) -> 944.52 | AQ4: =SUM(S4:V4) -> 967.169 | AR4: =AQ4*(1+AR14) -> 1010.6916 | AS4: =AR4*(1+AS14) -> 909.62244 | AT4: =AS4*(1+AT14) -> 955.10357 | AU4: =AT4*(1+AU14) -> 993.30771 | AV4: =AU4*(1+AV14) -> 1028.0735 | AW4: =AV4*(1+AW14) -> 1058.9157 | AX4: =AW4*(1+AX14) -> 1085.3886 | AY4: =AX4*(1+AY14) -> 1107.0963 | ... BA4: =AZ4*(1+BA14) -> 1134.9398
B5: ELEVIDYS | C5: 0 | D5: 0 | E5: 0 | F5: 0 | G5: 0 | H5: 0 | I5: 0 | J5: 0 | K5: 0 | L5: 0 | M5: 0 | N5: 0 | O5: 0 | P5: 0 | Q5: 69.108 | R5: =200.356-SUM(O5:Q5) -> 131.248 | S5: 133.936 | T5: 121.72 | U5: 180.983 | V5: =820.791-SUM(S5:U5) -> 384.152 | W5: 374.895 | X5: 281.851 | Y5: 131.49 | Z5: 160 | AA5: 175 | AB5: 170 | AC5: 160 | AD5: 150 | AM5: =SUM(C5:F5) -> 0 | AN5: =SUM(G5:J5) -> 0 | AO5: =SUM(K5:N5) -> 0 | AP5: =SUM(O5:R5) -> 200.356 | AQ5: =SUM(S5:V5) -> 820.791 | AR5: =AQ5*(1+AR15) -> 878.24637 | AS5: =AR5*(1+AS15) -> 601.59876 | AT5: =AS5*(1+AT15) -> 421.11913 | AU5: =AT5*(1+AU15) -> 357.95126 | AV5: =AU5*(1+AV15) -> 322.15614 | AW5: =AV5*(1+AW15) -> 289.94052 | AX5: =AW5*(1+AX15) -> 260.94647 | AY5: =AX5*(1+AY15) -> 247.89915 | ... BA5: =AZ5*(1+BA15) -> 223.72898
B6: Product Revenues | C6: =SUM(C4:C5) -> 100.448 | D6: =SUM(D4:D5) -> 111.34 | E6: =SUM(E4:E5) -> 121.429 | F6: =SUM(F4:F5) -> 122.648 | G6: =SUM(G4:G5) -> 124.926 | H6: =SUM(H4:H5) -> 141.839 | I6: =SUM(I4:I5) -> 166.911 | J6: =SUM(J4:J5) -> 178.725 | ... AD6: =SUM(AD4:AD5) -> 425 | AM6: =SUM(C6:F6) -> 455.865 | AN6: =SUM(G6:J6) -> 612.401 | AO6: =SUM(K6:N6) -> 843.769 | AP6: =SUM(O6:R6) -> 1144.876 | AQ6: =SUM(S6:V6) -> 1787.96 | AR6: =SUM(AR4:AR5) -> 1888.938 | AS6: =SUM(AS4:AS5) -> 1511.2212 | AT6: =SUM(AT4:AT5) -> 1376.2227 | AU6: =SUM(AU4:AU5) -> 1351.259 | AV6: =SUM(AV4:AV5) -> 1350.2296 | AW6: =SUM(AW4:AW5) -> 1348.8562 | AX6: =SUM(AX4:AX5) -> 1346.335 | AY6: =SUM(AY4:AY5) -> 1354.9955 | ... BA6: =SUM(BA4:BA5) -> 1358.6688
B7: Collaboration Revenues | C7: 0 | D7: 0 | E7: 0 | F7: 0 | G7: 0 | H7: 0 | I7: 0 | J7: 0 | K7: 0 | L7: 0 | M7: 0 | N7: 0 | O7: 0 | P7: 0 | Q7: 0 | R7: 0 | S7: 48 | T7: 0 | U7: 0 | V7: =48-SUM(S7:U7) -> 0 | W7: 112 | X7: 63.5 | Y7: 0 | AM7: =SUM(C7:F7) -> 0 | AN7: =SUM(G7:J7) -> 0 | AO7: =SUM(K7:N7) -> 0 | AP7: =SUM(O7:R7) -> 0 | AQ7: =SUM(S7:V7) -> 48
B8: Contract Manufacturing | C8: 0 | D8: 0 | E8: 0 | F8: 0 | G8: 0 | H8: 0 | I8: 0 | J8: 0 | K8: 0 | L8: 0 | M8: 0 | N8: 0 | O8: 0 | P8: 0 | Q8: 0 | R8: =9.216-SUM(O8:Q8) -> 9.216 | S8: 5.8 | T8: 2.38 | U8: 27.89 | V8: =49.038-SUM(S8:U8) -> 12.968 | W8: 17.379 | X8: 27.02 | Y8: 18.7 | AM8: =SUM(C8:F8) -> 0 | AN8: =SUM(G8:J8) -> 0 | AO8: =SUM(K8:N8) -> 0 | AP8: =SUM(O8:R8) -> 9.216 | AQ8: =SUM(S8:V8) -> 49.038
B9: Royalty Revenues | C9: 0 | D9: 0 | E9: 0 | F9: 0 | G9: 0 | H9: 0 | I9: 0 | J9: 0 | K9: 0 | L9: 0 | M9: 0 | N9: 0 | O9: 0 | P9: 0 | Q9: 0 | R9: 0 | S9: 0.173 | T9: 0 | U9: 9.51 | V9: =16.981-SUM(S9:U9) -> 7.298 | W9: 4.05 | X9: 7.445 | Y9: 10.608 | AM9: =SUM(C9:F9) -> 0 | AN9: =SUM(G9:J9) -> 0 | AO9: =SUM(K9:N9) -> 0 | AP9: =SUM(O9:R9) -> 0 | AQ9: =SUM(S9:V9) -> 16.981
B10: Amortization of PO | C10: 13.226 | D10: 26.019 | E10: 22.495 | F10: =84.234-SUM(C10:E10) -> 22.494 | G10: 22.005 | H10: 22.25 | I10: 22.459 | J10: =89.444-SUM(G10:I10) -> 22.73 | K10: 22.005 | L10: 22.3 | M10: 22.5 | N10: =89.244-SUM(K10:M10) -> 22.439 | O10: 22 | P10: 22.25 | Q10: 22.49 | R10: =89.244-SUM(O10:Q10) -> 22.504 | S10: 0 | T10: 0 | U10: 0 | V10: =0-SUM(S10:U10) -> 0 | W10: 0 | X10: 0 | Y10: 0 | AM10: =SUM(C10:F10) -> 84.234 | AN10: =SUM(G10:J10) -> 89.444 | AO10: =SUM(K10:N10) -> 89.244 | AP10: =SUM(O10:R10) -> 89.244 | AQ10: =SUM(S10:V10) -> 0
B11: Collaboration and Other Revenues | C11: =SUM(C7:C10) -> 13.226 | D11: =SUM(D7:D10) -> 26.019 | E11: =SUM(E7:E10) -> 22.495 | F11: =SUM(F7:F10) -> 22.494 | G11: =SUM(G7:G10) -> 22.005 | H11: =SUM(H7:H10) -> 22.25 | I11: =SUM(I7:I10) -> 22.459 | J11: =SUM(J7:J10) -> 22.73 | ... Y11: =SUM(Y7:Y10) -> 29.308 | AM11: =AM10 -> 84.234 | AN11: =AN10 -> 89.444 | AO11: =SUM(K11:N11) -> 89.244 | AP11: =SUM(O11:R11) -> 98.46 | AQ11: =SUM(S11:V11) -> 114.019 | AR11: =AQ11*(1+AR16) -> 285.0475 | AS11: =AR11*(1+AS16) -> 128.27138 | AT11: =AS11*(1+AT16) -> 121.85781 | AU11: =AT11*(1+AU16) -> 125.51354 | AV11: =AU11*(1+AV16) -> 128.96516 | AW11: =AV11*(1+AW16) -> 132.18929 | AX11: =AW11*(1+AX16) -> 135.16355 | AY11: =AX11*(1+AY16) -> 137.191 | ... BA11: =AZ11*(1+BA16) -> 139.25573
B12: Ttl Revenues | C12: =C6+C11 -> 113.674 | D12: =D11+D6 -> 137.359 | E12: =E6+E11 -> 143.924 | F12: =F6+F11 -> 145.142 | G12: =G6+G11 -> 146.931 | H12: =H6+H11 -> 164.089 | I12: =I6+I11 -> 189.37 | J12: =J6+J11 -> 201.455 | K12: =K6+K11 -> 210.83 | L12: =L6+L11 -> 233.537 | ... AD12: =AD6+AD11 -> 425 | AM12: =AM6+AM11 -> 540.099 | AN12: =AN6+AN11 -> 701.845 | AO12: =SUM(K12:N12) -> 933.013 | AP12: =SUM(O12:R12) -> 1243.336 | AQ12: =SUM(S12:V12) -> 1901.979 | AR12: =AR6+AR11 -> 2173.9855 | AS12: =AS6+AS11 -> 1639.4926 | AT12: =AT6+AT11 -> 1498.0805 | AU12: =AU6+AU11 -> 1476.7725 | AV12: =AV6+AV11 -> 1479.1948 | AW12: =AW6+AW11 -> 1481.0455 | AX12: =AX6+AX11 -> 1481.4986 | AY12: =AY6+AY11 -> 1492.1865 | ... BA12: =BA6+BA11 -> 1497.9245
B14: PMO Products Growth Y/y | G14: =G4/C4-1 -> 0.24368828 | H14: =H4/D4-1 -> 0.27392671 | I14: =I4/E4-1 -> 0.37455633 | J14: =J4/F4-1 -> 0.45721903 | K14: =K4/G4-1 -> 0.5114948 | L14: =L4/H4-1 -> 0.48927305 | M14: =M4/I4-1 -> 0.2448191 | N14: =N4/J4-1 -> 0.32008952 | ... X14: =X4/T4-1 -> -0.031633777 | Y14: 0.04 | Z14: =Z4/V4-1 -> -0.05514043 | AA14: =AA4/W4-1 -> 0.078050884 | AB14: =AB4/X4-1 -> 0.12421737 | AC14: =AC4/Y4-1 -> 0.13186191 | AD14: =AD4/Z4-1 -> 0.14583333 | AN14: =AN4/AM4-1 -> 0.34338236 | AO14: =AO4/AN4-1 -> 0.37780474 | AP14: =AP4/AO4-1 -> 0.1194059 | AQ14: =AQ4/AP4-1 -> 0.023979376 | AR14: 0.045 | AS14: -0.1 | AT14: 0.05 | AU14: 0.04 | AV14: 0.035 | AW14: 0.03 | AX14: 0.025 | AY14: 0.02 | AZ14: 0.015 | BA14: 0.01
B15: ELEVIDYS Growth Y/y | U15: =U5/Q5-1 -> 1.618843 | V15: =V5/R5-1 -> 1.926917 | W15: =W5/S5-1 -> 1.7990607 | X15: =X5/T5-1 -> 1.3155685 | Y15: 0.48 | Z15: =Z5/V5-1 -> -0.5834982 | AA15: =AA5/W5-1 -> -0.53320263 | AB15: =AB5/X5-1 -> -0.39684443 | AC15: =AC5/Y5-1 -> 0.21682257 | AD15: =AD5/Z5-1 -> -0.0625 | AQ15: =AQ5/AP5-1 -> 3.0966629 | AR15: 0.07 | AS15: -0.315 | AT15: -0.3 | AU15: -0.15 | AV15: -0.1 | AW15: -0.1 | AX15: -0.1 | AY15: -0.05 | AZ15: -0.05 | BA15: -0.05
B16: Other Growth Y/y | G16: =G11/C11-1 -> 0.66376834 | H16: =H11/D11-1 -> -0.14485568 | I16: =I11/E11-1 -> -0.0016003556 | J16: =J11/F11-1 -> 0.010491687 | K16: =K11/G11-1 -> 0 | L16: =L11/H11-1 -> 0.002247191 | M16: =M11/I11-1 -> 0.0018255488 | N16: =N11/J11-1 -> -0.012802464 | ... X16: =X11/T11-1 -> 40.161765 | Y16: 1.15 | AN16: =AN11/AM11-1 -> 0.061851509 | AO16: =AO11/AN11-1 -> -0.002236036 | AP16: =AP11/AO11-1 -> 0.10326745 | AQ16: =AQ11/AP11-1 -> 0.15802356 | AR16: 1.5 | AS16: -0.55 | AT16: -0.05 | AU16: 0.03 | AV16: 0.0275 | AW16: 0.025 | AX16: 0.0225 | AY16: 0.015 | AZ16: 0.01 | BA16: 0.005
B17: Ttl Revenue Growth Y/y | G17: =G6/C6-1 -> 0.24368828 | H17: =H6/D6-1 -> 0.27392671 | I17: =I6/E6-1 -> 0.37455633 | J17: =J6/F6-1 -> 0.45721903 | K17: =K6/G6-1 -> 0.5114948 | L17: =L6/H6-1 -> 0.48927305 | M17: =M6/I6-1 -> 0.2448191 | N17: =N6/J6-1 -> 0.32008952 | ... Y17: =Y6/U6-1 -> -0.13899495 | Z17: =Z12/V12-1 -> -0.39248873 | AA17: =AA12/W12-1 -> -0.42271186 | AB17: =AB12/X12-1 -> -0.29633703 | AC17: =AC12/Y12-1 -> 0.076768592 | AD17: =AD12/Z12-1 -> 0.0625 | AN17: =AN12/AM12-1 -> 0.29947473 | AO17: =AO12/AN12-1 -> 0.32937187 | AP17: =AP12/AO12-1 -> 0.33260308 | AQ17: =AQ12/AP12-1 -> 0.52973854 | AR17: =AR12/AQ12-1 -> 0.14301234 | AS17: =AS12/AR12-1 -> -0.24585854 | AT17: =AT12/AS12-1 -> -0.086253562 | AU17: =AU12/AT12-1 -> -0.01422353 | ... BA17: =BA12/AZ12-1 -> 0.00010324214
B19: PMO % of Ttl Revenues | C19: =C4/C12 -> 0.88364974 | D19: =D4/D12 -> 0.81057666 | E19: =E4/E12 -> 0.84370223 | F19: =F4/F12 -> 0.84502074 | G19: =G4/G12 -> 0.85023582 | H19: =H4/H12 -> 0.86440285 | I19: =I4/I12 -> 0.88140149 | J19: =J4/J12 -> 0.88717083 | ... Y19: =Y4/Y12 -> 0.59734364 | AM19: =AM4/AM6 -> 1 | AN19: =AN4/AN6 -> 1 | AO19: =AO4/AO6 -> 1 | AP19: =AP4/AP6 -> 0.82499764 | AQ19: =AQ4/AQ6 -> 0.54093436 | AR19: =AR4/AR12 -> 0.46490265 | AS19: =AS4/AS12 -> 0.55481949 | AT19: =AT4/AT12 -> 0.63755156 | AU19: =AU4/AU12 -> 0.67262066 | AV19: =AV4/AV12 -> 0.69502238 | AW19: =AW4/AW12 -> 0.7149785 | AX19: =AX4/AX12 -> 0.73262882 | AY19: =AY4/AY12 -> 0.74192894 | ... BA19: =BA4/BA12 -> 0.7576749
B20: ELEVIDYS % of Ttl Revenues | Q20: =Q5/Q12 -> 0.20827708 | R20: =R5/R12 -> 0.3307703 | S20: =S5/S12 -> 0.32394179 | T20: =T5/T12 -> 0.33538425 | U20: =U5/U12 -> 0.38740204 | V20: =V5/V12 -> 0.58344167 | W20: =W5/W12 -> 0.503308 | X20: =X5/X12 -> 0.46122817 | Y20: =Y5/Y12 -> 0.32926582 | AM20: =AM5/AM6 -> 0 | AN20: =AN5/AN6 -> 0 | AO20: =AO5/AO6 -> 0 | AP20: =AP5/AP6 -> 0.17500236 | AQ20: =AQ5/AQ6 -> 0.45906564 | AR20: =AR5/AR12 -> 0.40397987 | AS20: =AS5/AS12 -> 0.36694205 | AT20: =AT5/AT12 -> 0.28110581 | AU20: =AU5/AU12 -> 0.24238755 | AV20: =AV5/AV12 -> 0.21779156 | AW20: =AW5/AW12 -> 0.19576747 | AX20: =AX5/AX12 -> 0.17613683 | AY20: =AY5/AY12 -> 0.16613148 | ... BA20: =BA5/BA12 -> 0.14935931
B21: Other % of Ttl Revenues | C21: =C11/C12 -> 0.11635026 | D21: =D11/D12 -> 0.18942334 | E21: =E11/E12 -> 0.15629777 | F21: =F11/F12 -> 0.15497926 | G21: =G11/G12 -> 0.14976418 | H21: =H11/H12 -> 0.13559715 | I21: =I11/I12 -> 0.11859851 | J21: =J11/J12 -> 0.11282917 | ... Y21: =Y11/Y12 -> 0.073390544
B23: Revenues | C23: =C12 -> 113.674 | D23: =D12 -> 137.359 | E23: =E12 -> 143.924 | F23: =F12 -> 145.142 | G23: =G12 -> 146.931 | H23: =H12 -> 164.089 | I23: =I12 -> 189.37 | J23: =J12 -> 201.455 | ... Y23: =Y12 -> 399.343 | AM23: =SUM(C23:F23) -> 540.099 | AN23: =SUM(G23:J23) -> 701.845 | AO23: =SUM(K23:N23) -> 933.013 | AP23: =SUM(O23:R23) -> 1243.336 | AQ23: =SUM(S23:V23) -> 1901.979 | AR23: =AR12 -> 2173.9855 | AS23: =AS12 -> 1639.4926 | AT23: =AT12 -> 1498.0805 | AU23: =AU12 -> 1476.7725 | AV23: =AV12 -> 1479.1948 | AW23: =AW12 -> 1481.0455 | AX23: =AX12 -> 1481.4986 | AY23: =AY12 -> 1492.1865 | ... BA23: =BA12 -> 1497.9245
B24: COGS | C24: 12.622 | D24: 13.341 | E24: 15.015 | F24: =63.382-SUM(C24:E24) -> 22.404 | G24: 22.346 | H24: 19.515 | I24: 23.44 | J24: =97.049-SUM(G24:I24) -> 31.748 | K24: 31.443 | L24: 37.795 | M24: 39.952 | N24: =139.989-SUM(K24:M24) -> 30.799 | O24: 35.017 | P24: 34.124 | Q24: 37.026 | R24: =150.343-SUM(O24:Q24) -> 44.176 | S24: 50.559 | T24: 44.54 | U24: 91.691 | V24: =319.099-SUM(S24:U24) -> 132.309 | W24: 137.56 | X24: 152.558 | Y24: 150.775 | AM24: =SUM(C24:F24) -> 63.382 | AN24: =SUM(G24:J24) -> 97.049 | AO24: =SUM(K24:N24) -> 139.989 | AP24: =SUM(O24:R24) -> 150.343 | AQ24: =SUM(S24:V24) -> 319.099 | AR24: =AR23*(1-AR39) -> 521.75651 | AS24: =AS23*(1-AS39) -> 360.68837 | AT24: =AT23*(1-AT39) -> 314.59691 | AU24: =AU23*(1-AU39) -> 302.73837 | AV24: =AV23*(1-AV39) -> 295.83896 | AW24: =AW23*(1-AW39) -> 288.80387 | AX24: =AX23*(1-AX39) -> 281.48473 | AY24: =AY23*(1-AY39) -> 283.51543 | ... BA24: =BA23*(1-BA39) -> 284.60566
B25: GP | C25: =C23-C24 -> 101.052 | D25: =D23-D24 -> 124.018 | E25: =E23-E24 -> 128.909 | F25: =F23-F24 -> 122.738 | G25: =G23-G24 -> 124.585 | H25: =H23-H24 -> 144.574 | I25: =I23-I24 -> 165.93 | J25: =J23-J24 -> 169.707 | ... Y25: =Y23-Y24 -> 248.568 | AM25: =SUM(C25:F25) -> 476.717 | AN25: =SUM(G25:J25) -> 604.796 | AO25: =SUM(K25:N25) -> 793.024 | AP25: =SUM(O25:R25) -> 1092.993 | AQ25: =SUM(S25:V25) -> 1582.88 | AR25: =AR23-AR24 -> 1652.229 | AS25: =AS23-AS24 -> 1278.8042 | AT25: =AT23-AT24 -> 1183.4836 | AU25: =AU23-AU24 -> 1174.0341 | AV25: =AV23-AV24 -> 1183.3558 | AW25: =AW23-AW24 -> 1192.2416 | AX25: =AX23-AX24 -> 1200.0139 | AY25: =AY23-AY24 -> 1208.6711 | ... BA25: =BA23-BA24 -> 1213.3189
B26: R&D | C26: 136.144 | D26: 188.522 | E26: 190.438 | F26: =722.343-SUM(C26:E26) -> 207.239 | G26: 195.149 | H26: 239.622 | I26: 139.115 | J26: =771.182-SUM(G26:I26) -> 197.296 | K26: 194.25 | L26: 252.329 | M26: 216.7 | N26: =877.09-SUM(K26:M26) -> 213.811 | O26: 245.679 | P26: 241.89 | Q26: 194.301 | R26: =877.387-SUM(O26:Q26) -> 195.517 | S26: 200.396 | T26: 179.69 | U26: 224.483 | V26: =804.522-SUM(S26:U26) -> 199.953 | W26: 773.448 | X26: 204.392 | Y26: 218.89 | AM26: =SUM(C26:F26) -> 722.343 | AN26: =SUM(G26:J26) -> 771.182 | AO26: =SUM(K26:N26) -> 877.09 | AP26: =SUM(O26:R26) -> 877.387 | AQ26: =SUM(S26:V26) -> 804.522 | AR26: =AR23*AR40 -> 1391.3507 | AS26: =AS23*AS40 -> 901.72092 | AT26: =AT23*AT40 -> 479.38576 | AU26: =AU23*AU40 -> 443.03175 | AV26: =AV23*AV40 -> 414.17454 | AW26: =AW23*AW40 -> 399.88228 | AX26: =AX23*AX40 -> 385.18964 | AY26: =AY23*AY40 -> 373.04662 | ... BA26: =BA23*BA40 -> 359.50189
B27: SG&A | C27: 82.768 | D27: 73.688 | E27: 75.373 | F27: =317.875-SUM(C27:E27) -> 86.046 | G27: 71.131 | H27: 72.347 | I27: 61.127 | J27: =282.66-SUM(G27:I27) -> 78.055 | K27: 71.84 | L27: 154.316 | M27: 104.787 | N27: =451.421-SUM(K27:M27) -> 120.478 | O27: 110.714 | P27: 118.56 | Q27: 120.893 | R27: =481.871-SUM(O27:Q27) -> 131.704 | S27: 127.003 | T27: 138.796 | U27: 128.2 | V27: =557.87-SUM(S27:U27) -> 163.871 | W27: 133.629 | X27: 137.897 | Y27: 91.89 | AM27: =SUM(C27:F27) -> 317.875 | AN27: =SUM(G27:J27) -> 282.66 | AO27: =SUM(K27:N27) -> 451.421 | AP27: =SUM(O27:R27) -> 481.871 | AQ27: =SUM(S27:V27) -> 557.87 | AR27: =AR23*AR41 -> 500.01666 | AS27: =AS23*AS41 -> 327.89852 | AT27: =AT23*AT41 -> 292.1257 | AU27: =AU23*AU41 -> 280.58678 | AV27: =AV23*AV41 -> 273.65103 | AW27: =AW23*AW41 -> 266.58819 | AX27: =AX23*AX41 -> 266.66975 | AY27: =AY23*AY41 -> 268.59357 | ... BA27: =BA23*BA41 -> 269.62642
B28: Settlement and Liscence | C28: 0 | D28: 0 | E28: 0 | F28: =0-SUM(C28:E28) -> 0 | G28: 10 | H28: 0 | I28: 0 | J28: =10-SUM(G28:I28) -> 0 | K28: 0 | L28: 0 | M28: 0 | N28: =0-SUM(K28:M28) -> 0 | O28: 0 | P28: 0 | Q28: =0-SUM(N28:P28) -> 0 | R28: =0-SUM(O28:Q28) -> 0 | S28: =0-SUM(P28:R28) -> 0 | T28: =0-SUM(Q28:S28) -> 0 | U28: 0 | V28: 0 | W28: 0 | X28: 0 | Y28: 40.51 | AM28: =SUM(C28:F28) -> 0 | AN28: =SUM(G28:J28) -> 10 | AO28: =SUM(K28:N28) -> 0 | AP28: =SUM(O28:R28) -> 0 | AQ28: =SUM(S28:V28) -> 0 | AR28: 0 | AS28: 0 | AT28: 0 | AU28: 0 | AV28: 0 | AW28: 0 | AX28: 0 | AY28: 0 | AZ28: 0 | BA28: 0
B29: Amortization of In-Liscensed Rights | C29: 0.166 | D29: 0.165 | E29: 0.166 | F29: =0.662-SUM(C29:E29) -> 0.165 | G29: 0.17 | H29: 0.179 | I29: 0.178 | J29: =0.706-SUM(G29:I29) -> 0.179 | K29: 0.178 | L29: 0.179 | M29: 0.178 | N29: =0.71-SUM(K29:M29) -> 0.175 | O29: 0.178 | P29: 0.179 | Q29: 0.439 | R29: =1.559-SUM(O29:Q29) -> 0.763 | S29: 0.601 | T29: 0.601 | U29: 0.6 | V29: =2.405-SUM(S29:U29) -> 0.603 | W29: 0.6 | X29: 0.667 | Y29: 0.677 | AM29: =SUM(C29:F29) -> 0.662 | AN29: =SUM(G29:J29) -> 0.706 | AO29: =SUM(K29:N29) -> 0.71 | AP29: =SUM(O29:R29) -> 1.559 | AQ29: =SUM(S29:V29) -> 2.405 | AR29: 0 | AS29: 0 | AT29: 0 | AU29: 0 | AV29: 0 | AW29: 0 | AX29: 0 | AY29: 0 | AZ29: 0 | BA29: 0
B30: Operating Income | C30: =C25-SUM(C26:C29) -> -118.026 | D30: =D25-SUM(D26:D29) -> -138.357 | E30: =E25-SUM(E26:E29) -> -137.068 | F30: =F25-SUM(F26:F29) -> -170.712 | G30: =G25-SUM(G26:G29) -> -151.865 | H30: =H25-SUM(H26:H29) -> -167.574 | I30: =I25-SUM(I26:I29) -> -34.49 | J30: =J25-SUM(J26:J29) -> -105.823 | ... Y30: =Y25-SUM(Y26:Y29) -> -103.399 | AM30: =SUM(C30:F30) -> -564.163 | AN30: =SUM(G30:J30) -> -459.752 | AO30: =SUM(K30:N30) -> -536.197 | AP30: =SUM(O30:R30) -> -267.824 | AQ30: =SUM(S30:V30) -> 218.083 | AR30: =AR25-SUM(AR26:AR29) -> -239.1384 | AS30: =AS25-SUM(AS26:AS29) -> 49.184777 | AT30: =AT25-SUM(AT26:AT29) -> 411.97214 | AU30: =AU25-SUM(AU26:AU29) -> 450.41562 | AV30: =AV25-SUM(AV26:AV29) -> 495.53025 | AW30: =AW25-SUM(AW26:AW29) -> 525.77115 | AX30: =AX25-SUM(AX26:AX29) -> 548.15448 | AY30: =AY25-SUM(AY26:AY29) -> 567.03087 | ... BA30: =BA25-SUM(BA26:BA29) -> 584.19057
B31: Other Income (Expenses) | C31: -7.42 | D31: 0 | E31: -45 | F31: =-51.971-SUM(C31:E31) -> 0.449 | G31: -15.528 | H31: 102 | I31: -20.649 | J31: =-68.43-SUM(G31:I31) -> -134.253 | K31: -17.26 | L31: 0 | M31: =6.7-125.44 -> -118.74 | N31: =-125.441+6.7-SUM(K31:M31) -> 17.259 | O31: 12.7 | P31: 16.934 | Q31: -12.33 | R31: =33.055-SUM(O31:Q31) -> 15.751 | S31: 6.54 | T31: 14.278 | U31: 11.81 | V31: =42.693-SUM(S31:U31) -> 10.065 | W31: -83.132 | X31: 38.06 | Y31: -138.61 | AM31: =SUM(C31:F31) -> -51.971 | AN31: =SUM(G31:J31) -> -68.43 | AO31: =SUM(K31:N31) -> -118.741 | AP31: =SUM(O31:R31) -> 33.055 | AQ31: =SUM(S31:V31) -> 42.693 | AR31: 40 | AS31: =AR46*($BA$48) -> 53.634881 | AT31: =AS31*1.04 -> 55.780276 | AU31: =AT31*1.04 -> 58.011487 | AV31: =AU31*1.04 -> 60.331946 | AW31: =AV31*1.04 -> 62.745224 | AX31: =AW31*1.04 -> 65.255033 | AY31: =AX31*1.04 -> 67.865235 | AZ31: =AY31*1.04 -> 70.579844 | BA31: =AZ31*1.04 -> 73.403038
B32: Gain on, Income | C32: 108.069 | D32: -12.447 | E32: -14.335 | F32: =108.1-45-SUM(C32:E32) -> -18.187 | G32: 0 | H32: -16.185 | I32: 7.2 | J32: =102+7.2-SUM(G32:I32) -> 118.185 | K32: 0 | L32: -16.961 | M32: -6.33 | N32: =-35.021-SUM(K32:M32) -> -11.73 | O32: -387.32 | P32: 102 | Q32: 0 | R32: =-387.329+102-SUM(O32:Q32) -> -0.009 | S32: 0 | T32: 0 | U32: 0 | V32: =0-SUM(S32:U32) -> 0 | W32: 0 | X32: 0 | Y32: 47.95 | AM32: =SUM(C32:F32) -> 63.1 | AN32: =SUM(G32:J32) -> 109.2 | AO32: =SUM(K32:N32) -> -35.021 | AP32: =SUM(O32:R32) -> -285.329 | AQ32: =SUM(S32:V32) -> 0 | AR32: 0 | AS32: 0 | AT32: 0 | AU32: 0 | AV32: 0 | AW32: 0 | AX32: 0 | AY32: 0 | AZ32: 0 | BA32: 0
B33: Pretax Income | C33: =C30+SUM(C31:C32) -> -17.377 | D33: =D30+SUM(D31:D32) -> -150.804 | E33: =E30+SUM(E31:E32) -> -196.403 | F33: =F30+SUM(F31:F32) -> -188.45 | G33: =G30+SUM(G31:G32) -> -167.393 | H33: =H30+SUM(H31:H32) -> -81.759 | I33: =I30+SUM(I31:I32) -> -47.939 | J33: =J30+SUM(J31:J32) -> -121.891 | ... Y33: =Y30+SUM(Y31:Y32) -> -194.059 | AM33: =SUM(C33:F33) -> -553.034 | AN33: =SUM(G33:J33) -> -418.982 | AO33: =SUM(K33:N33) -> -689.959 | AP33: =SUM(O33:R33) -> -520.098 | AQ33: =SUM(S33:V33) -> 260.776 | AR33: =AR30+SUM(AR31:AR32) -> -199.1384 | AS33: =AS30+SUM(AS31:AS32) -> 102.81966 | AT33: =AT30+SUM(AT31:AT32) -> 467.75242 | AU33: =AU30+SUM(AU31:AU32) -> 508.4271 | AV33: =AV30+SUM(AV31:AV32) -> 555.8622 | AW33: =AW30+SUM(AW31:AW32) -> 588.51638 | AX33: =AX30+SUM(AX31:AX32) -> 613.40951 | AY33: =AY30+SUM(AY31:AY32) -> 634.8961 | ... BA33: =BA30+SUM(BA31:BA32) -> 657.5936
B34: Taxes | C34: 0.115 | D34: 0.2 | E34: 0.096 | F34: =1.063-SUM(C34:E34) -> 0.652 | G34: -0.143 | H34: -0.35 | I34: 0.237 | J34: =-0.168-SUM(G34:I34) -> 0.088 | K34: 0.879 | L34: 3.388 | M34: 1.32 | N34: =13.525-SUM(K34:M34) -> 7.938 | O34: 4.045 | P34: 9.355 | Q34: 7.763 | R34: =15.879-SUM(O34:Q34) -> -5.284 | S34: 5.329 | T34: 7.117 | U34: 0.395 | V34: =25.535-SUM(S34:U34) -> 12.694 | W34: 63.99 | X34: -43.25 | Y34: -14.1 | AM34: =SUM(C34:F34) -> 1.063 | AN34: =SUM(G34:J34) -> -0.168 | AO34: =SUM(K34:N34) -> 13.525 | AP34: =SUM(O34:R34) -> 15.879 | AQ34: =SUM(S34:V34) -> 25.535 | AR34: =AR33*AR43 -> 9.9569201 | AS34: =AS33*AS43 -> 8.2255727 | AT34: =AT33*AT43 -> 46.775242 | AU34: =AU33*AU43 -> 50.84271 | AV34: =AV33*AV43 -> 55.58622 | AW34: =AW33*AW43 -> 58.851638 | AX34: =AX33*AX43 -> 61.340951 | AY34: =AY33*AY43 -> 63.48961 | ... BA34: =BA33*BA43 -> 65.75936
B35: Net Income | C35: =C33-C34 -> -17.492 | D35: =D33-D34 -> -151.004 | E35: =E33-E34 -> -196.499 | F35: =F33-F34 -> -189.102 | G35: =G33-G34 -> -167.25 | H35: =H33-H34 -> -81.409 | I35: =I33-I34 -> -48.176 | J35: =J33-J34 -> -121.979 | K35: =K33-K34 -> -105.02 | L35: =L33-L34+-2.2 -> -233.631 | M35: =M33-M34-0.72 -> -258.453 | N35: =N33-N34 -> -109.3 | O35: =O33-O34 -> -516.758 | P35: =P33-P34 -> -23.936 | Q35: =Q33-Q34 -> -40.944 | R35: =R33-R34 -> 45.661 | S35: =S33-S34-1.6 -> 34.509 | T35: =T33-T34 -> 6.461 | U35: =U33-U34 -> 33.612 | V35: =V33-V34 -> 159.059 | W35: =W33-W34 -> -447.497 | X35: =X33-X34 -> 196.884 | Y35: =Y33-Y34 -> -179.959 | AM35: =SUM(C35:F35) -> -554.097 | AN35: =SUM(G35:J35) -> -418.814 | AO35: =SUM(K35:N35) -> -706.404 | AP35: =SUM(O35:R35) -> -535.977 | AQ35: =SUM(S35:V35) -> 233.641 | AR35: =AR33-AR34 -> -209.09532 | AS35: =AS33-AS34 -> 94.594085 | AT35: =AT33-AT34 -> 420.97717 | AU35: =AU33-AU34 -> 457.58439 | AV35: =AV33-AV34 -> 500.27598 | AW35: =AW33-AW34 -> 529.66474 | AX35: =AX33-AX34 -> 552.06856 | AY35: =AY33-AY34 -> 571.40649 | ... BA35: =BA33-BA34 -> 591.83424 | BB35: =BA35*(1+$BA$49) -> 532.65082 | BC35: =BB35*(1+$BA$49) -> 479.38574 | BD35: =BC35*(1+$BA$49) -> 431.44716 | BE35: =BD35*(1+$BA$49) -> 388.30245
B36: SC | C36: 76.432 | D36: 77.968 | E36: 78.501 | F36: 77.77 | G36: 79.454 | H36: 79.746 | I36: 79.88 | J36: 87.12 | K36: 87.253 | L36: 87.511 | M36: 87.62 | N36: 87.981 | O36: 88.186 | P36: 88.743 | Q36: 88.889 | R36: 92.398 | S36: 93.99 | T36: 94.618 | U36: 95.39 | V36: 97.032 | W36: 97.362 | X36: 98.005 | Y36: 100.23 | AM36: =AVERAGE(C36:F36) -> 77.66775 | AN36: =AVERAGE(G36:J36) -> 81.55 | AO36: =AVERAGE(K36:N36) -> 87.59125 | AP36: =AVERAGE(O36:R36) -> 89.554 | AQ36: =AVERAGE(S36:V36) -> 95.2575
B37: EPS | C37: =C35/C36 -> -0.22885702 | D37: =D35/D36 -> -1.9367433 | E37: =E35/E36 -> -2.5031401 | F37: =F35/F36 -> -2.4315546 | G37: =G35/G36 -> -2.1049916 | H37: =H35/H36 -> -1.0208537 | I37: =I35/I36 -> -0.60310466 | J37: =(J35/J36) -> -1.4001263 | K37: =K35/K36 -> -1.2036262 | L37: =L35/L36 -> -2.6697329 | M37: =M35/M36 -> -2.9497033 | N37: =N35/N36 -> -1.2423137 | O37: =O35/O36 -> -5.8598644 | P37: =P35/P36 -> -0.26972268 | Q37: =Q35/Q36 -> -0.46061942 | R37: =R35/R36 -> 0.49417736 | ... Y37: =Y35/Y36 -> -1.7954604 | AM37: =SUM(C37:F37) -> -7.100295 | AN37: =SUM(G37:J37) -> -5.1290762 | AO37: =SUM(K37:N37) -> -8.0653761 | AP37: =SUM(O37:R37) -> -6.0960291 | AQ37: =SUM(S37:V37) -> 2.4270479
B39: Gross Profit Margin | C39: =C25/C23 -> 0.88896318 | D39: =D25/D23 -> 0.90287495 | E39: =E25/E23 -> 0.89567411 | F39: =F25/F23 -> 0.84564082 | G39: =G25/G23 -> 0.84791501 | H39: =H25/H23 -> 0.88107064 | I39: =I25/I23 -> 0.87622115 | J39: =J25/J23 -> 0.84240649 | ... Y39: =Y25/Y23 -> 0.62244236 | AM39: =AM25/AM23 -> 0.88264744 | AN39: =AN25/AN23 -> 0.86172303 | AO39: =AO25/AO23 -> 0.84996029 | AP39: =AP25/AP23 -> 0.87908096 | AQ39: =AQ25/AQ23 -> 0.83222791 | AR39: 0.76 | AS39: 0.78 | AT39: 0.79 | AU39: 0.795 | AV39: 0.8 | AW39: 0.805 | AX39: 0.81 | AY39: 0.81 | AZ39: 0.81 | BA39: 0.81
B40: R&D as % of Revenue | C40: =C26/C23 -> 1.1976705 | D40: =D26/D23 -> 1.3724765 | E40: =E26/E23 -> 1.3231845 | F40: =F26/F23 -> 1.4278362 | G40: =G26/G23 -> 1.3281676 | H40: =H26/H23 -> 1.4603173 | I40: =I26/I23 -> 0.73462006 | J40: =J26/J23 -> 0.97935519 | ... Y40: =Y26/Y23 -> 0.5481253 | AM40: =AM26/AM23 -> 1.337427 | AN40: =AN26/AN23 -> 1.0987925 | AO40: =AO26/AO23 -> 0.94006193 | AP40: =AP26/AP23 -> 0.70567168 | AQ40: =AQ26/AQ23 -> 0.42299205 | AR40: 0.64 | AS40: 0.55 | AT40: 0.32 | AU40: 0.3 | AV40: 0.28 | AW40: 0.27 | AX40: 0.26 | AY40: 0.25 | AZ40: 0.245 | BA40: 0.24
B41: SG&A as % of Revenue | C41: =C27/C23 -> 0.72811725 | D41: =D27/D23 -> 0.53646285 | E41: =E27/E23 -> 0.52370001 | F41: =F27/F23 -> 0.59284012 | G41: =G27/G23 -> 0.48411159 | H41: =H27/H23 -> 0.44090097 | I41: =I27/I23 -> 0.32279136 | J41: =J27/J23 -> 0.38745626 | ... Y41: =Y27/Y23 -> 0.23010294 | AM41: =AM27/AM23 -> 0.58854951 | AN41: =AN27/AN23 -> 0.4027385 | AO41: =AO27/AO23 -> 0.48383141 | AP41: =AP27/AP23 -> 0.38756298 | AQ41: =AQ27/AQ23 -> 0.29331028 | AR41: 0.23 | AS41: 0.2 | AT41: 0.195 | AU41: 0.19 | AV41: 0.185 | AW41: 0.18 | AX41: 0.18 | AY41: 0.18 | AZ41: 0.18 | BA41: 0.18
B42: Operating Profit Margin | C42: =C30/C23 -> -1.0382849 | D42: =D30/D23 -> -1.0072656 | E42: =E30/E23 -> -0.95236375 | F42: =F30/F23 -> -1.1761723 | G42: =G30/G23 -> -1.0335804 | H42: =H30/H23 -> -1.0212385 | I42: =I30/I23 -> -0.18213022 | J42: =J30/J23 -> -0.52529349 | ... Y42: =Y30/Y23 -> -0.25892278 | AM42: =AM30/AM23 -> -1.0445548 | AN42: =AN30/AN23 -> -0.65506202 | AO42: =AO30/AO23 -> -0.57469403 | AP42: =AP30/AP23 -> -0.21540758 | AQ42: =AQ30/AQ23 -> 0.1146611 | AR42: =AR30/AR23 -> -0.11 | AS42: =AS30/AS23 -> 0.03 | AT42: =AT30/AT23 -> 0.275 | ... BA42: =BA30/BA23 -> 0.39
B43: Effective Tax Rate | C43: =-C34/C33 -> 0.0066179433 | D43: =-D34/D33 -> 0.0013262248 | E43: =-E34/E33 -> 0.0004887909 | F43: =-F34/F33 -> 0.0034598037 | G43: =-G34/G33 -> -0.00085427706 | H43: =-H34/H33 -> -0.0042808743 | I43: =-I34/I33 -> 0.0049437827 | J43: =-J34/J33 -> 0.0007219565 | ... Q43: =-Q34/Q33 -> 0.23395919 | R43: =R34/R33 -> -0.13086658 | S43: =S34/S33 -> 0.12860177 | T43: =T34/T33 -> 0.52415672 | U43: =U34/U33 -> 0.011615256 | V43: =V34/V33 -> 0.073908462 | W43: =-W34/W33 -> 0.16685484 | X43: =X34/X33 -> -0.28151321 | Y43: =Y34/Y33 -> 0.072658315 | AM43: =-AM34/AM33 -> 0.0019221241 | AN43: =-AN34/AN33 -> -0.00040097188 | AO43: =-AO34/AO33 -> 0.019602614 | AP43: =-AP34/AP33 -> 0.030530785 | AQ43: =-AQ34/AQ33 -> -0.097919287 | AR43: -0.05 | AS43: 0.08 | AT43: 0.1 | AU43: 0.1 | AV43: 0.1 | AW43: 0.1 | AX43: 0.1 | AY43: 0.1 | AZ43: 0.1 | BA43: 0.1
B44: Net Profit Margin | C44: =C35/C23 -> -0.15387864 | D44: =D35/D23 -> -1.0993382 | E44: =E35/E23 -> -1.365297 | F44: =F35/F23 -> -1.3028758 | G44: =G35/G23 -> -1.1382894 | H44: =H35/H23 -> -0.4961271 | I44: =I35/I23 -> -0.25440144 | J44: =J35/J23 -> -0.60549006 | ... Y44: =Y35/Y23 -> -0.45063767 | AM44: =AM35/AM23 -> -1.0259175 | AN44: =AN35/AN23 -> -0.5967329 | AO44: =AO35/AO23 -> -0.75712128 | AP44: =AP35/AP23 -> -0.43107977 | AQ44: =AQ35/AQ23 -> 0.122841 | AR44: =AR35/AR23 -> -0.096180644 | AS44: =AS35/AS23 -> 0.057697172 | AT44: =AT35/AT23 -> 0.28101105 | ... BA44: =BA35/BA23 -> 0.39510285
...

Sheet Bear Case (30%)
C1: Q1 2020 | G1: Q1 2021 | K1: Q1 2022 | O1: Q1 2023 | S1: Q1 2024 | W1: Q1 2025
B2: Quarterly
