Workbook

Sheet Main
A1: Master
A2: Capital Structure Snapshot:
B4: TFX
B5: Price | C5: 125.12 | D5: 2/20/2026
B6: SO | C6: 42.372 | D6: Q2'26
B7: MC | C7: =C5*C6 -> 5301.5846
B8: Cash | C8: 300.159 | D8: Q2'26
B9: Debt | C9: =87.5+2720.509 -> 2808.009 | D9: Q2'26
B10: EV | C10: =C7-C8+C9 -> 7809.4346
B12: Teleflex Inc. (TFX)
B14: Founder(s): Morse Smith | F14: Registered Exchange: NYSE | N14: Resources:
B15: Founded: 1943 | F15: Address: 550 East Swedesford Rd. Wayne, PA | N15: SEC filings | Q15: https://www.sec.gov/edgar/browse/?CIK=96943&owner=exclude
B16: Headquarters: Wayne, PA | F16: Investor Relations Contact: | N16: Teleflex Homepage | Q16: https://www.teleflex.com/usa/en/
B17: Current CEO: Liam Kelly | F17: Investors Relation Department | O17: Teleflex Product Page | R17: https://www.teleflexvascular.com/
B18: Employees: 14,100 | F18: Phone: | G18: 1 (610) 948-2836 | I18: Email: | J18: investor.relations@teleflex.com | O18: Teleflex IR Page | R18: https://investors.teleflex.com/home/default.aspx
B19: Industry: Med-Tech and Supplies | N19: Earnings Calls | Q19: https://seekingalpha.com/symbol/TFX/earnings/transcripts
B20: Sector: Healthcare | N20: Equity Analysis | Q20: https://stockanalysis.com/stocks/tfx/company/
B21: IPO: Feb. 18, 1988 | N21: MacroTrends | Q21: https://www.macrotrends.net/stocks/charts/ISRG/intuitive-surgical/cash-flow-statement?q=
B22: Fiscal Year: [January - December] | N22: ROIC, WACC | Q22: https://www.gurufocus.com/term/wacc/TFX
N23: Godel Terminal | Q23: https://app.godelterminal.com/
A24: Company Overview:
B25: Teleflex is a global medical technology company specializing in the design, development, manufacturing, and supply of single-use medical devices primarily used by hospitals and healthcare providers for diagnostic and therapeutic procedures in critical care and surgical settings worldwide
C26: Its products are marketed worldwide to hospitals and healthcare providers through a direct sales force and distributors
C27: The Company focuses on achieving sustainable and profitable growth by expanding its product portfolio through new product development, technology investments, geographic expansion, operational efficiencies, and strategic acquisitions or partnerships
D28: Teleflex’s operational strategy emphasizes innovation, low-cost manufacturing, and broad market reach to enhance patient outcomes and provider efficiencies globally
C29: The Company’s portfolio consists mainly of Class I and II medical devices, many of which require FDA 510(k) clearance, allowing for quicker and less costly market entry compared to Class III devices
B30: The Company is currently focused on restructuring through the separation of its Urology, Acute Care, and OEM businesses into a new publicly traded company, referred to by management as "NewCo."
C31: This strategic move aims to streamline operations and enhance management focus … “RemainCo” will concentrate on high-growth hospital-focused markets
C32: The remaining company (RemainCo) will integrate the recently acquired Biotronik Vascular Intervention business and concentrate on high-growth hospital-focused markets such as vascular access, interventional, and surgical procedures performed in critical care settings like intensive care units and catheter labs
D33: This restructuring aims to streamline operations, sharpen management focus, and drive profitability and innovation in core categories such as vascular access, interventional cardiology, and surgical products
B34: Teleflex was incorporated in 1943 and is headquartered in Wayne, Pennsylvania
A36: History:
B37: Teleflex was founded in 1943 as a manufacturer of precision mechanical push/pull controls for military aircraft
C38: From this original single market, single product orientation, The Company expanded and evolved through entries into new businesses, development of new products, introduction of products into new geographic or end-markets and acquisitions and dispositions of businesses
C39: Throughout The Company's history, management has continually focused on providing innovative, technology-driven, specialty-engineered products that help customers meet their business requirements
B40: Beginning in 2007, Managers significantly restructured the composition of The Company's portfolio of businesses, expanding its presence in the medical device industry, while spinning off all all other businesses, which served the aerospace, automotive, industrial and marine markets
C41: Following the divestitures of the marine business and cargo container and systems businesses in 2011, The Company became exclusively a medical device business
B42: In 2017, The Company completed two large scale acquisitions: NeoTract, Inc. ("NeoTract") and Vascular Solutions, Inc. (“Vascular Solutions”)
C43: NeoTract was a medical device company that developed and commercialized the UroLift System, a minimally invasive medical device for treating lower urinary tract symptoms due to benign prostatic hyperplasia, or BPH
C44: Vascular Solutions was a medical device company that developed and marketed clinical products for use in minimally invasive coronary and peripheral vascular procedures
...

Sheet Bull Case
B1: [Use for Graphing] | AQ1: Q1 2020 | AU1: Q1 2021 | AY1: Q1 2022 | BC1: Q1 2023 | BG1: Q1 2024 | BK1: Q1 2025 | BO1: Q1 2026
B2: Quarterly
B3: Revenues | C3: Q1 2010 | D3: Q2 2010 | E3: Q3 2010 | F3: Q4 2010 | G3: Q1 2011 | H3: Q2 2011 | I3: Q3 2011 | J3: Q4 2011 | K3: Q1 2012 | L3: Q2 2012 | M3: Q3 2012 | N3: Q4 2012 | O3: Q1 2013 | P3: Q2 2013 | Q3: Q3 2013 | R3: Q4 2013 | S3: Q1 2014 | T3: Q2 2014 | U3: Q3 2014 | V3: Q4 2014 | W3: Q1 2015 | X3: Q2 2015 | Y3: Q3 2015 | Z3: Q4 2015 | AA3: Q1 2016 | AB3: Q2 2016 | AC3: Q3 2016 | AD3: Q4 2016 | AE3: Q1 2017 | AF3: Q2 2017 | AG3: Q3 2017 | AH3: Q4 2017 | AI3: Q1 2018 | AJ3: Q2 2018 | AK3: Q3 2018 | AL3: Q4 2018 | AM3: Q1 2019 | AN3: Q2 2019 | AO3: Q3 2019 | AP3: Q4 2019 | AQ3: Q1 2020 | AR3: Q2 2020 | AS3: Q3 2020 | AT3: Q4 2020 | AU3: Q1 2021 | AV3: Q2 2021 | AW3: Q3 2021 | AX3: Q4 2021 | AY3: Q1 2022 | AZ3: Q2 2022 | BA3: Q3 2022 | BB3: Q4 2022 | BC3: Q1 2023 | BD3: Q2 2023 | BE3: Q3 2023 | BF3: Q4 2023 | BG3: Q1 2024 | BH3: Q2 2024 | BI3: Q3 2024 | BJ3: Q4 2024 | BK3: Q1 2025 | BL3: Q2 2025 | BM3: Q3 2025 | BN3: Q4 2025 | BO3: Q1 2026 | BP3: Q2 2026 | BQ3: Q3 2026 | BR3: Q4 2026 | BW3: 2010 | BX3: =BW3+1 -> 2011 | BY3: =BX3+1 -> 2012 | BZ3: =BY3+1 -> 2013 | CA3: =BZ3+1 -> 2014 | CB3: =CA3+1 -> 2015 | CC3: =CB3+1 -> 2016 | CD3: =CC3+1 -> 2017 | CE3: =CD3+1 -> 2018 | ... ES3: =ER3+1 -> 2084
B4: Vascular Access | AQ4: 150.25 | AR4: 164.958 | AS4: 160.05 | AT4: =657.703-SUM(AQ4:AS4) -> 182.445 | AU4: 163.97 | AV4: 167.73 | AW4: 175.47 | AX4: =700.24-SUM(AU4:AW4) -> 193.07 | AY4: 166.13 | AZ4: 163.9 | BA4: 167.14 | BB4: =683.612-SUM(AY4:BA4) -> 186.442 | BC4: 177.65 | BD4: 173.785 | BE4: 169.91 | BF4: =708.04-SUM(BC4:BE4) -> 186.695 | BG4: 181.35 | BH4: 181.1 | BI4: 180.89 | BJ4: =732.67-SUM(BG4:BI4) -> 189.33 | BK4: 182.36 | BL4: 185.53 | BM4: 191.02 | BO4: 236.812 | BP4: 246.337 | CG4: =SUM(AQ4:AT4) -> 657.703 | CH4: =SUM(AU4:AX4) -> 700.24 | CI4: =SUM(AY4:BB4) -> 683.612 | CJ4: =SUM(BC4:BF4) -> 708.04 | CK4: =SUM(BG4:BJ4) -> 732.67 | CL4: =CK4*(1+CL13) -> 752.81843 | CM4: =CL4*(1+CM13) -> 779.16707 | CN4: =CM4*(1+CN13) -> 810.33375 | CO4: =CN4*(1+CO13) -> 844.36777 | CP4: =CO4*(1+CP13) -> 878.14248 | CQ4: =CP4*(1+CQ13) -> 911.5119 | CR4: =CQ4*(1+CR13) -> 944.32632 | CS4: =CR4*(1+CS13) -> 976.43342 | ... CU4: =CT4*(1+CU13) -> 1037.9097
B5: Interventional Cardiology | AQ5: 99.93 | AR5: 82.594 | AS5: 93.18 | AT5: =382.43-SUM(AQ5:AS5) -> 106.726 | AU5: 96.173 | AV5: 112.08 | AW5: 104.304 | AX5: =427.5-SUM(AU5:AW5) -> 114.943 | AY5: 96.85 | AZ5: 114.34 | BA5: 97.6 | BB5: =445.01-SUM(AY5:BA5) -> 136.22 | BC5: 116.89 | BD5: 124.78 | BE5: 134.089 | BF5: =511.434-SUM(BC5:BE5) -> 135.675 | BG5: 134.665 | BH5: 141.15 | BI5: 149.86 | BJ5: =586.05-SUM(BG5:BI5) -> 160.375 | BK5: 137.55 | BL5: 170.01 | BM5: 266.41 | BO5: 204.656 | BP5: 211.874 | CG5: =SUM(AQ5:AT5) -> 382.43 | CH5: =SUM(AU5:AX5) -> 427.5 | CI5: =SUM(AY5:BB5) -> 445.01 | CJ5: =SUM(BC5:BF5) -> 511.434 | CK5: =SUM(BG5:BJ5) -> 586.05 | CL5: =CK5*(1+CL14) -> 785.307 | CM5: =CL5*(1+CM14) -> 973.78068 | CN5: =CM5*(1+CN14) -> 1129.5856 | CO5: =CN5*(1+CO14) -> 1287.7276 | CP5: =CO5*(1+CP14) -> 1442.2549 | CQ5: =CP5*(1+CQ14) -> 1586.4804 | CR5: =CQ5*(1+CR14) -> 1729.2636 | CS5: =CR5*(1+CS14) -> 1867.6047 | ... CU5: =CT5*(1+CU14) -> 2118.2372
B6: Anesthesia | AQ6: 75.7 | AR6: 64.867 | AS6: 75.64 | AT6: =302.293-SUM(AQ5:AS5) -> 26.589 | AU6: 84.85 | AV6: 95.42 | AW6: 97.07 | AX6: =380.14-SUM(AU6:AW6) -> 102.8 | AY6: 86.95 | AZ6: 104.695 | BA6: 108.73 | BB6: =388.89-SUM(AY6:BA6) -> 88.515 | BC6: 93.33 | BD6: 100.84 | BE6: 97.61 | BF6: =389.957-SUM(BC6:BE6) -> 98.177 | BG6: 96.352 | BH6: 102.49 | BI6: 101.15 | BJ6: =395.28-SUM(BG6:BI6) -> 95.288 | BK6: 86.59 | BL6: 96.38 | BM6: 101.44 | BO6: 0 | BP6: 0 | CG6: =SUM(AQ6:AT6) -> 242.796 | CH6: =SUM(AU6:AX6) -> 380.14 | CI6: =SUM(AW6:BB6) -> 588.76 | CJ6: =SUM(AW6:BF6) -> 978.717 | CK6: =SUM(BG6:BJ6) -> 395.28 | CL6: =CK6*(1+CL15) -> 379.4688 | CM6: =CL6*(1+CM15) -> 246.65472 | CN6: =CM6*(1+CN15) -> 0 | CO6: =CN6*(1+CO15) -> 0 | CP6: =CO6*(1+CP15) -> 0 | CQ6: =CP6*(1+CQ15) -> 0 | CR6: =CQ6*(1+CR15) -> 0 | CS6: =CR6*(1+CS15) -> 0 | ... CU6: =CT6*(1+CU15) -> 0
B7: Surgical | AQ7: 75.432 | AR7: 67.275 | AS7: 82.22 | AT7: =317.2-SUM(AQ7:AS7) -> 92.273 | AU7: 80.386 | AV7: 98.18 | AW7: 92.83 | AX7: =377.75-SUM(AU7:AW7) -> 106.354 | AY7: 89.7 | AZ7: 99.64 | BA7: 93.12 | BB7: =392.91-SUM(AY7:BA7) -> 110.45 | BC7: 99.02 | BD7: 105.95 | BE7: 112.8 | BF7: =427.359-SUM(BC7:BE7) -> 109.589 | BG7: 105.52 | BH7: 111.3 | BI7: 111.746 | BJ7: =450.48-SUM(BG7:BI7) -> 121.914 | BK7: 105.78 | BL7: 114.04 | BM7: 122.87 | BO7: 106.794 | BP7: 112.121 | CG7: =SUM(AQ7:AT7) -> 317.2 | CH7: =SUM(AU7:AX7) -> 377.75 | CI7: =SUM(AY7:BB7) -> 392.91 | CJ7: =SUM(BC7:BF7) -> 427.359 | CK7: =SUM(BG7:BJ7) -> 450.48 | CL7: =CK7*(1+CL16) -> 477.5088 | CM7: =CL7*(1+CM16) -> 515.7095 | CN7: =CM7*(1+CN16) -> 551.80917 | CO7: =CN7*(1+CO16) -> 584.91772 | CP7: =CO7*(1+CP16) -> 617.08819 | CQ7: =CP7*(1+CQ16) -> 647.9426 | CR7: =CQ7*(1+CR16) -> 677.10002 | CS7: =CR7*(1+CS16) -> 704.18402 | ... CU7: =CT7*(1+CU16) -> 761.64544
B8: Interventional Urology | AQ8: 74.19 | AR8: 40.09 | AS8: 81.77 | AT8: =290.02-SUM(AQ8:AS8) -> 93.97 | AU8: 73.36 | AV8: 92.24 | AW8: 83.107 | AX8: =341.66-SUM(AU8:AW8) -> 92.953 | AY8: 74.89 | AZ8: 79.81 | BA8: 78.969 | BB8: =322.83-SUM(AY8:BA8) -> 89.161 | BC8: 75.37 | BD8: 77.81 | BE8: 73.622 | BF8: =319.785-SUM(BC8:BE8) -> 92.983 | BG8: 79.74 | BH8: 83.1 | BI8: 83.39 | BJ8: =331.092-SUM(BG8:BI8) -> 84.862 | BK8: 70.96 | BL8: 76.38 | BM8: 71.77 | BO8: 0 | BP8: 0 | CG8: =SUM(AQ8:AT8) -> 290.02 | CH8: =SUM(AU8:AX8) -> 341.66 | CI8: =SUM(AY8:BB8) -> 322.83 | CJ8: =SUM(BC8:BF8) -> 319.785 | CK8: =SUM(BG8:BJ8) -> 331.092 | CL8: =CK8*(1+CL17) -> 281.4282 | CM8: =CL8*(1+CM17) -> 140.7141 | CN8: =CM8*(1+CN17) -> 0 | CO8: =CN8*(1+CO17) -> 0 | CP8: =CO8*(1+CP17) -> 0 | CQ8: =CP8*(1+CQ17) -> 0 | CR8: =CQ8*(1+CR17) -> 0 | CS8: =CR8*(1+CS17) -> 0 | ... CU8: =CT8*(1+CU17) -> 0
B9: OEM | AQ9: 63.389 | AR9: 55.832 | AS9: 49.399 | AT9: =220.246-SUM(AQ9:AS9) -> 51.626 | AU9: 53.48 | AV9: 60.95 | AW9: 64.08 | AX9: =245.681-SUM(AU9:AW9) -> 67.171 | AY9: 57.656 | AZ9: 70 | BA9: 71.28 | BB9: =272.624-SUM(AY9:BA9) -> 73.688 | BC9: 76.99 | BD9: 84.12 | BE9: 82.309 | BF9: =326.008-SUM(BC9:BE9) -> 82.589 | BG9: 87.69 | BH9: 88.82 | BI9: 82.55 | BJ9: =344.51-SUM(BG9:BI9) -> 85.45 | BK9: 63.88 | BL9: 78.67 | BM9: 80.41 | BO9: 0 | BP9: 0 | CG9: =SUM(AQ9:AT9) -> 220.246 | CH9: =SUM(AU9:AX9) -> 245.681 | CI9: =SUM(AY9:BB9) -> 272.624 | CJ9: =SUM(BC9:BF9) -> 326.008 | CK9: =SUM(BG9:BJ9) -> 344.51 | CL9: =CK9*(1+CL18) -> 294.55605 | CM9: =CL9*(1+CM18) -> 265.10044 | CN9: =CM9*(1+CN18) -> 0 | CO9: =CN9*(1+CO18) -> 0 | CP9: =CO9*(1+CP18) -> 0 | CQ9: =CP9*(1+CQ18) -> 0 | CR9: =CQ9*(1+CR18) -> 0 | CS9: =CR9*(1+CS18) -> 0 | ... CU9: =CT9*(1+CU18) -> 0
B10: Other | AQ10: 91.73 | AR10: 91.414 | AS10: 86.02 | AT10: =367.25-SUM(AQ10:AS10) -> 98.086 | AU10: 81.683 | AV10: 86.84 | AW10: 83.37 | AX10: =336.585-SUM(AU10:AW10) -> 84.692 | AY10: 69.512 | AZ10: 72.13 | BA10: 69.9 | BB10: =285.148-SUM(AY10:BA10) -> 73.606 | BC10: 71.65 | BD10: 75.95 | BE10: 76.033 | BF10: =291.902-SUM(BC10:BE10) -> 68.269 | BG10: 52.51 | BH10: 41.7 | BI10: 54.76 | BJ10: =207.222-SUM(BG10:BI10) -> 58.252 | BK10: 53.6 | BL10: 59.84 | BM10: 79.07 | BO10: 0 | BP10: 0 | CG10: =SUM(AQ10:AT10) -> 367.25 | CH10: =SUM(AU10:AX10) -> 336.585 | CI10: =SUM(AY10:BB10) -> 285.148 | CJ10: =SUM(BC10:BF10) -> 291.902 | CK10: =SUM(BG10:BJ10) -> 207.222 | CL10: =CK10*(1+CL19) -> 261.09972 | CM10: =CL10*(1+CM19) -> 266.32171 | CN10: =CM10*(1+CN19) -> 271.64815 | CO10: =CN10*(1+CO19) -> 277.08111 | CP10: =CO10*(1+CP19) -> 282.62273 | CQ10: =CP10*(1+CQ19) -> 288.27519 | CR10: =CQ10*(1+CR19) -> 294.04069 | CS10: =CR10*(1+CS19) -> 299.92151 | ... CU10: =CT10*(1+CU19) -> 312.03834
B11: Ttl Revenues | AQ11: =SUM(AQ4:AQ10) -> 630.621 | AR11: =SUM(AR4:AR10) -> 567.03 | AS11: =SUM(AS4:AS10) -> 628.279 | AT11: =SUM(AT4:AT10) -> 651.715 | AU11: =SUM(AU4:AU10) -> 633.902 | AV11: =SUM(AV4:AV10) -> 713.44 | AW11: =SUM(AW4:AW10) -> 700.231 | AX11: =SUM(AX4:AX10) -> 761.983 | ... BM11: =SUM(BM4:BM10) -> 912.99 | BO11: =SUM(BO4:BO10) -> 548.262 | BP11: =SUM(BP4:BP10) -> 570.332 | CG11: =SUM(AQ11:AT11) -> 2477.645 | CH11: =SUM(AU11:AX11) -> 2809.556 | CI11: =SUM(AY11:BB11) -> 2791.024 | CJ11: =SUM(BC11:BF11) -> 2974.485 | CK11: =SUM(BG11:BJ11) -> 3047.304 | CL11: =SUM(CL4:CL10) -> 3232.187 | CM11: =SUM(CM4:CM10) -> 3187.4482 | CN11: =SUM(CN4:CN10) -> 2763.3767 | CO11: =SUM(CO4:CO10) -> 2994.0942 | CP11: =SUM(CP4:CP10) -> 3220.1083 | CQ11: =SUM(CQ4:CQ10) -> 3434.2101 | CR11: =SUM(CR4:CR10) -> 3644.7306 | CS11: =SUM(CS4:CS10) -> 3848.1436 | ... CU11: =SUM(CU4:CU10) -> 4229.8307
B13: Vascular Access Growth Y/y | AU13: =AU4/AQ4-1 -> 0.091314476 | AV13: =AV4/AR4-1 -> 0.016804277 | AW13: =AW4/AS4-1 -> 0.096344892 | AX13: =AX4/AT4-1 -> 0.058236729 | AY13: =AY4/AU4-1 -> 0.013173141 | AZ13: =AZ4/AV4-1 -> -0.022834317 | BA13: =BA4/AW4-1 -> -0.047472502 | BB13: =BB4/AX4-1 -> -0.034329518 | ... BM13: =BM4/BI4-1 -> 0.056000885 | BO13: =BO4/BK4-1 -> 0.29859618 | BP13: =BP4/BL4-1 -> 0.32774753 | CH13: =CH4/CG4-1 -> 0.064675089 | CI13: =CI4/CH4-1 -> -0.023746144 | CJ13: =CJ4/CI4-1 -> 0.03573372 | CK13: =CK4/CJ4-1 -> 0.03478617 | CL13: 0.0275 | CM13: 0.035 | CN13: 0.04 | CO13: 0.042 | CP13: 0.04 | CQ13: 0.038 | CR13: 0.036 | CS13: 0.034 | CT13: 0.032 | CU13: 0.03
B14: Vascular Intervention Growth Y/y | AU14: =AU5/AQ5-1 -> -0.037596317 | AV14: =AV5/AR5-1 -> 0.3569993 | AW14: =AW5/AS5-1 -> 0.11938184 | AX14: =AX5/AT5-1 -> 0.076991548 | AY14: =AY5/AU5-1 -> 0.0070393978 | AZ14: =AZ5/AV5-1 -> 0.020164168 | BA14: =BA5/AW5-1 -> -0.064273662 | BB14: =BB5/AX5-1 -> 0.18510914 | ... BM14: =BM5/BI5-1 -> 0.77772588 | BO14: =BO5/BK5-1 -> 0.48786623 | BP14: =BP5/BL5-1 -> 0.24624434 | CH14: =CH5/CG5-1 -> 0.11785163 | CI14: =CI5/CH5-1 -> 0.040959064 | CJ14: =CJ5/CI5-1 -> 0.14926406 | CK14: =CK5/CJ5-1 -> 0.14589566 | CL14: 0.34 | CM14: 0.24 | CN14: 0.16 | CO14: 0.14 | CP14: 0.12 | CQ14: 0.1 | CR14: 0.09 | CS14: 0.08 | CT14: 0.07 | CU14: 0.06
B15: Anesthesia Growth Y/y | AU15: =AU6/AQ6-1 -> 0.12087186 | AV15: =AV6/AR6-1 -> 0.47100991 | AW15: =AW6/AS6-1 -> 0.28331571 | AX15: =AX6/AT6-1 -> 2.8662605 | AY15: =AY6/AU6-1 -> 0.024749558 | AZ15: =AZ6/AV6-1 -> 0.097201844 | BA15: =BA6/AW6-1 -> 0.1201195 | BB15: =BB6/AX6-1 -> -0.13895914 | ... BM15: =BM6/BI6-1 -> 0.0028670292 | BO15: =BO6/BK6-1 -> -1 | BP15: =BP6/BL6-1 -> -1 | CH15: =CH6/CG6-1 -> 0.56567654 | CI15: =CI6/CH6-1 -> 0.54879781 | CJ15: =CJ6/CI6-1 -> 0.6623361 | CK15: =CK6/CJ6-1 -> -0.59612431 | CL15: -0.04 | CM15: -0.35 | CN15: -1 | CO15: 0 | CP15: 0 | CQ15: 0 | CR15: 0 | CS15: 0 | CT15: 0 | CU15: 0
B16: Surgical Growth Y/y | AU16: =AU7/AQ7-1 -> 0.065675045 | AV16: =AV7/AR7-1 -> 0.45938313 | AW16: =AW7/AS7-1 -> 0.12904403 | AX16: =AX7/AT7-1 -> 0.15260152 | AY16: =AY7/AU7-1 -> 0.11586595 | AZ16: =AZ7/AV7-1 -> 0.014870646 | BA16: =BA7/AW7-1 -> 0.0031239901 | BB16: =BB7/AX7-1 -> 0.038512891 | ... BM16: =BM7/BI7-1 -> 0.099547187 | BO16: =BO7/BK7-1 -> 0.0095859331 | BP16: =BP7/BL7-1 -> -0.016827429 | CH16: =CH7/CG7-1 -> 0.19088903 | CI16: =CI7/CH7-1 -> 0.040132363 | CJ16: =CJ7/CI7-1 -> 0.087676567 | CK16: =CK7/CJ7-1 -> 0.054102055 | CL16: 0.06 | CM16: 0.08 | CN16: 0.07 | CO16: 0.06 | CP16: 0.055 | CQ16: 0.05 | CR16: 0.045 | CS16: 0.04 | CT16: 0.04 | CU16: 0.04
B17: Interventional Urology Growth Y/y | AU17: =AU8/AQ8-1 -> -0.011187492 | AV17: =AV8/AR8-1 -> 1.3008231 | AW17: =AW8/AS8-1 -> 0.01635074 | AX17: =AX8/AT8-1 -> -0.010822603 | AY17: =AY8/AU8-1 -> 0.020856052 | AZ17: =AZ8/AV8-1 -> -0.13475716 | BA17: =BA8/AW8-1 -> -0.049791233 | BB17: =BB8/AX8-1 -> -0.04079481 | ... BM17: =BM8/BI8-1 -> -0.13934525 | BO17: =BO8/BK8-1 -> -1 | BP17: =BP8/BL8-1 -> -1 | CH17: =CH8/CG8-1 -> 0.17805669 | CI17: =CI8/CH8-1 -> -0.055113271 | CJ17: =CJ8/CI8-1 -> -0.0094322089 | CK17: =CK8/CJ8-1 -> 0.035358131 | CL17: -0.15 | CM17: -0.5 | CN17: -1 | CO17: 0 | CP17: 0 | CQ17: 0 | CR17: 0 | CS17: 0 | CT17: 0 | CU17: 0
B18: OEM Growth Y/y | AU18: =AU9/AQ9-1 -> -0.1563205 | AV18: =AV9/AR9-1 -> 0.091667861 | AW18: =AW9/AS9-1 -> 0.29719225 | AX18: =AX9/AT9-1 -> 0.30110797 | AY18: =AY9/AU9-1 -> 0.078085266 | AZ18: =AZ9/AV9-1 -> 0.14848236 | BA18: =BA9/AW9-1 -> 0.11235955 | BB18: =BB9/AX9-1 -> 0.097021036 | ... BM18: =BM9/BI9-1 -> -0.025923683 | BO18: =BO9/BK9-1 -> -1 | BP18: =BP9/BL9-1 -> -1 | CH18: =CH9/CG9-1 -> 0.1154845 | CI18: =CI9/CH9-1 -> 0.1096666 | CJ18: =CJ9/CI9-1 -> 0.19581548 | CK18: =CK9/CJ9-1 -> 0.056753209 | CL18: -0.145 | CM18: -0.1 | CN18: -1 | CO18: 0 | CP18: 0 | CQ18: 0 | CR18: 0 | CS18: 0 | CT18: 0 | CU18: 0
B19: Other Growth Y/y | AU19: =AU10/AQ10-1 -> -0.10952796 | AV19: =AV10/AR10-1 -> -0.0500361 | AW19: =AW10/AS10-1 -> -0.030806789 | AX19: =AX10/AT10-1 -> -0.13655364 | AY19: =AY10/AU10-1 -> -0.14900285 | AZ19: =AZ10/AV10-1 -> -0.16939199 | BA19: =BA10/AW10-1 -> -0.16156891 | BB19: =BB10/AX10-1 -> -0.13089784 | ... BM19: =BM10/BI10-1 -> 0.44393718 | BO19: =BO10/BK10-1 -> -1 | BP19: =BP10/BL10-1 -> -1 | CH19: =CH10/CG10-1 -> -0.083498979 | CI19: =CI10/CH10-1 -> -0.15282024 | CJ19: =CJ10/CI10-1 -> 0.023685946 | CK19: =CK10/CJ10-1 -> -0.29009736 | CL19: 0.26 | CM19: 0.02 | CN19: 0.02 | CO19: 0.02 | CP19: 0.02 | CQ19: 0.02 | CR19: 0.02 | CS19: 0.02 | CT19: 0.02 | CU19: 0.02
B20: Ttl Revenues Growth Y/y | AU20: =AU11/AQ11-1 -> 0.005202808 | AV20: =AV11/AR11-1 -> 0.25820503 | AW20: =AW11/AS11-1 -> 0.11452237 | AX20: =AX11/AT11-1 -> 0.16919666 | AY20: =AY11/AU11-1 -> 0.012282656 | AZ20: =AZ11/AV11-1 -> -0.012509812 | BA20: =BA11/AW11-1 -> -0.019267927 | BB20: =BB11/AX11-1 -> -0.0051195368 | ... BM20: =BM11/BI11-1 -> 0.19447214 | BO20: =BO11/BK11-1 -> -0.21757335 | BP20: =BP11/BL11-1 -> -0.26960108 | CH20: =CH11/CG11-1 -> 0.13396229 | CI20: =CI11/CH11-1 -> -0.00659606 | CJ20: =CJ11/CI11-1 -> 0.065732505 | CK20: =CK11/CJ11-1 -> 0.024481213 | CL20: =CL11/CK11-1 -> 0.060671005 | CM20: =CM11/CL11-1 -> -0.013841638 | CN20: =CN11/CM11-1 -> -0.13304422 | CO20: =CO11/CN11-1 -> 0.083491157 | ... CU20: =CU11/CT11-1 -> 0.045877809
B22: Vascular Access % of Ttl Revenues | AQ22: =AQ4/AQ11 -> 0.23825721 | AR22: =AR4/AR11 -> 0.29091582 | AS22: =AS4/AS11 -> 0.25474351 | AT22: =AT4/AT11 -> 0.27994599 | AU22: =AU4/AU11 -> 0.25866774 | AV22: =AV4/AV11 -> 0.23510036 | AW22: =AW4/AW11 -> 0.25058873 | AX22: =AX4/AX11 -> 0.25337836 | ... BM22: =BM4/BM11 -> 0.20922464 | BO22: =BO4/BO11 -> 0.43193218 | BP22: =BP4/BP11 -> 0.4319186 | CG22: =CG4/CG11 -> 0.2654549 | CH22: =CH4/CH11 -> 0.24923511 | CI22: =CI4/CI11 -> 0.24493233 | CJ22: =CJ4/CJ11 -> 0.23803785 | CK22: =CK4/CK11 -> 0.2404322
B23: Interventional % of Ttl Revenues | AQ23: =AQ5/AQ11 -> 0.15846285 | AR23: =AR5/AR11 -> 0.14566072 | AS23: =AS5/AS11 -> 0.14830991 | AT23: =AT5/AT11 -> 0.16376177 | AU23: =AU5/AU11 -> 0.15171588 | AV23: =AV5/AV11 -> 0.157098 | AW23: =AW5/AW11 -> 0.14895656 | AX23: =AX5/AX11 -> 0.1508472 | ... BM23: =BM5/BM11 -> 0.29179947 | BO23: =BO5/BO11 -> 0.37328139 | BP23: =BP5/BP11 -> 0.37149239 | CG23: =CG5/CG11 -> 0.15435222 | CH23: =CH5/CH11 -> 0.15215927 | CI23: =CI5/CI11 -> 0.15944327 | CJ23: =CJ5/CJ11 -> 0.17194035 | CK23: =CK5/CK11 -> 0.19231754
B24: Anesthesia % of Ttl Revenues | AQ24: =AQ6/AQ11 -> 0.1200404 | AR24: =AR6/AR11 -> 0.11439783 | AS24: =AS6/AS11 -> 0.12039237 | AT24: =AT6/AT11 -> 0.040798509 | AU24: =AU6/AU11 -> 0.1338535 | AV24: =AV6/AV11 -> 0.13374636 | AW24: =AW6/AW11 -> 0.13862568 | AX24: =AX6/AX11 -> 0.13491115 | ... BM24: =BM6/BM11 -> 0.11110746 | BO24: =BO6/BO11 -> 0 | BP24: =BP6/BP11 -> 0 | CG24: =CG6/CG11 -> 0.097994668 | CH24: =CH6/CH11 -> 0.13530252 | CI24: =CI6/CI11 -> 0.21094767 | CJ24: =CJ6/CJ11 -> 0.32903746 | CK24: =CK6/CK11 -> 0.12971466
B25: Surgical % of Ttl Revenues | AQ25: =AQ7/AQ11 -> 0.11961543 | AR25: =AR7/AR11 -> 0.11864452 | AS25: =AS7/AS11 -> 0.13086543 | AT25: =AT7/AT11 -> 0.1415849 | AU25: =AU7/AU11 -> 0.1268114 | AV25: =AV7/AV11 -> 0.13761494 | AW25: =AW7/AW11 -> 0.13257054 | AX25: =AX7/AX11 -> 0.13957529 | ... BM25: =BM7/BM11 -> 0.13457979 | BO25: =BO7/BO11 -> 0.19478643 | BP25: =BP7/BP11 -> 0.196589 | CG25: =CG7/CG11 -> 0.1280248 | CH25: =CH7/CH11 -> 0.13445185 | CI25: =CI7/CI11 -> 0.14077629 | CJ25: =CJ7/CJ11 -> 0.14367496 | CK25: =CK7/CK11 -> 0.14782903
B26: Interventional Urology % of Ttl Revenues | AQ26: =AQ8/AQ11 -> 0.11764594 | AR26: =AR8/AR11 -> 0.070701727 | AS26: =AS8/AS11 -> 0.13014919 | AT26: =AT8/AT11 -> 0.14418879 | AU26: =AU8/AU11 -> 0.11572767 | AV26: =AV8/AV11 -> 0.12928908 | AW26: =AW8/AW11 -> 0.11868512 | AX26: =AX8/AX11 -> 0.12198829 | ... BM26: =BM8/BM11 -> 0.078609842 | BO26: =BO8/BO11 -> 0 | BP26: =BP8/BP11 -> 0 | CG26: =CG8/CG11 -> 0.1170547 | CH26: =CH8/CH11 -> 0.1216064 | CI26: =CI8/CI11 -> 0.11566722 | CJ26: =CJ8/CJ11 -> 0.10750937 | CK26: =CK8/CK11 -> 0.10865079
B27: OEM % of Ttl Revenues | AQ27: =AQ9/AQ11 -> 0.10051838 | AR27: =AR9/AR11 -> 0.098463926 | AS27: =AS9/AS11 -> 0.078625897 | AT27: =AT9/AT11 -> 0.079215608 | AU27: =AU9/AU11 -> 0.084366353 | AV27: =AV9/AV11 -> 0.08543115 | AW27: =AW9/AW11 -> 0.091512658 | AX27: =AX9/AX11 -> 0.088152885 | ... BM27: =BM9/BM11 -> 0.088073254 | BO27: =BO9/BO11 -> 0 | BP27: =BP9/BP11 -> 0 | CG27: =CG9/CG11 -> 0.088893284 | CH27: =CH9/CH11 -> 0.087444778 | CI27: =CI9/CI11 -> 0.097678845 | CJ27: =CJ9/CJ11 -> 0.10960149 | CK27: =CK9/CK11 -> 0.11305403
B28: Other % of Ttl Revenues | AQ28: =AQ10/AQ11 -> 0.14545979 | AR28: =AR10/AR11 -> 0.16121546 | AS28: =AS10/AS11 -> 0.1369137 | AT28: =AT10/AT11 -> 0.15050444 | AU28: =AU10/AU11 -> 0.12885746 | AV28: =AV10/AV11 -> 0.12172012 | AW28: =AW10/AW11 -> 0.11906071 | AX28: =AX10/AX11 -> 0.11114684 | ... BM28: =BM10/BM11 -> 0.086605549 | BO28: =BO10/BO11 -> 0 | BP28: =BP10/BP11 -> 0 | CG28: =CG10/CG11 -> 0.14822543 | CH28: =CH10/CH11 -> 0.11980007 | CI28: =CI10/CI11 -> 0.10216609 | CJ28: =CJ10/CJ11 -> 0.098135307 | CK28: =CK10/CK11 -> 0.068001748
B30: U.S. Revenues | BC30: =411.86+76.99 -> 488.85 | BD30: =424.64+84.128 -> 508.768 | BE30: =428.206+82.309 -> 510.515 | BF30: =2041.4-SUM(BC30:BE30) -> 533.267 | BG30: 494 | BH30: 515.6 | BI30: =433.3+82.6 -> 515.9 | BJ30: =2066.3-SUM(BG30:BI30) -> 540.8 | BK30: 475.7 | BL30: 525.7 | BM30: 555.9 | BN30: =1279.197-SUM(BK30:BM30) -> -278.103 | BO30: 332.653 | BP30: 348.838 | CJ30: =SUM(BC30:BF30) -> 2041.4 | CK30: =SUM(BG30:BJ30) -> 2066.3
B31: EMEA Revenues | BC31: 143.34 | BD31: 147.809 | BE31: 142.723 | BF31: =586.2-SUM(BC31:BE31) -> 152.328 | BG31: 159.6 | BH31: 147.1 | BI31: 150.22 | BJ31: =618-SUM(BG31:BI31) -> 161.08 | BK31: 151.2 | BL31: 166.2 | BM31: 234.24 | BN31: =472.411-SUM(BK31:BM31) -> -79.229 | BO31: 146.678 | BP31: 145.531 | CJ31: =SUM(BC31:BF31) -> 586.2 | CK31: =SUM(BG31:BJ31) -> 618
B32: Asia Revenues | BC32: 78.731 | BD32: 86.678 | BE32: 93.151 | BF32: =346.9-SUM(BC32:BE32) -> 88.34 | BG32: 84.2 | BH32: 87 | BI32: 98.26 | BJ32: =363-SUM(BG32:BI32) -> 93.54 | BK32: 73.8 | BL32: 89 | BM32: 122.87 | BN32: =241.105-SUM(BK32:BM32) -> -44.565 | BO32: 68.93 | BP32: 75.963 | CJ32: =SUM(BC32:BF32) -> 346.9 | CK32: =SUM(BG32:BJ32) -> 363
B33: Ttl Revenues | BC33: =SUM(BC30:BC32) -> 710.921 | BD33: =SUM(BD30:BD32) -> 743.255 | BE33: =SUM(BE30:BE32) -> 746.389 | BF33: =SUM(BF30:BF32) -> 773.935 | BG33: =SUM(BG30:BG32) -> 737.8 | BH33: =SUM(BH30:BH32) -> 749.7 | BI33: =SUM(BI30:BI32) -> 764.38 | BJ33: =SUM(BJ30:BJ32) -> 795.42 | ... BP33: =SUM(BP30:BP32) -> 570.332 | CJ33: =SUM(BC33:BF33) -> 2974.5 | CK33: =SUM(BG33:BJ33) -> 3047.3
B35: U.S. Revenues Growth Y/y | BG35: =BG30/BC30-1 -> 0.010534929 | BH35: =BH30/BD30-1 -> 0.013428518 | BI35: =BI30/BE30-1 -> 0.010548172 | BJ35: =BJ30/BF30-1 -> 0.014126132 | BK35: =BK30/BG30-1 -> -0.037044534 | BL35: =BL30/BH30-1 -> 0.019588829 | BM35: =BM30/BI30-1 -> 0.077534406 | BN35: =BN30/BJ30-1 -> -1.5142437 | ... BP35: =BP30/BL30-1 -> -0.33643142 | CK35: =CK30/CJ30-1 -> 0.012197512
B36: EMEA Revenues Growth Y/y | BG36: =BG31/BC31-1 -> 0.11343658 | BH36: =BH31/BD31-1 -> -0.0047967309 | BI36: =BI31/BE31-1 -> 0.052528324 | BJ36: =BJ31/BF31-1 -> 0.057454966 | BK36: =BK31/BG31-1 -> -0.052631579 | BL36: =BL31/BH31-1 -> 0.12984364 | BM36: =BM31/BI31-1 -> 0.55931301 | BN36: =BN31/BJ31-1 -> -1.4918612 | ... BP36: =BP31/BL31-1 -> -0.12436221 | CK36: =CK31/CJ31-1 -> 0.054247697
B37: Asia Revenues Growth Y/y | BG37: =BG32/BC32-1 -> 0.069464379 | BH37: =BH32/BD32-1 -> 0.0037148988 | BI37: =BI32/BE32-1 -> 0.054846432 | BJ37: =BJ32/BF32-1 -> 0.058863482 | BK37: =BK32/BG32-1 -> -0.12351544 | BL37: =BL32/BH32-1 -> 0.022988506 | BM37: =BM32/BI32-1 -> 0.25045797 | BN37: =BN32/BJ32-1 -> -1.4764272 | ... BP37: =BP32/BL32-1 -> -0.14648315 | CK37: =CK32/CJ32-1 -> 0.046411069
B38: Ttl Revenues Growth Y/y | BG38: =BG33/BC33-1 -> 0.037808702 | BH38: =BH33/BD33-1 -> 0.0086713174 | BI38: =BI33/BE33-1 -> 0.024104053 | BJ38: =BJ33/BF33-1 -> 0.027760729 | BK38: =BK33/BG33-1 -> -0.05028463 | BL38: =BL33/BH33-1 -> 0.041616647 | BM38: =BM33/BI33-1 -> 0.19444517 | BN38: =BN33/BJ33-1 -> -1.5052639 | ... BP38: =BP33/BL33-1 -> -0.26964784 | CK38: =CK33/CJ33-1 -> 0.024474702
B40: U.S. Revenues % of Revenues | BC40: =BC30/BC33 -> 0.68762915 | BD40: =BD30/BD33 -> 0.68451339 | BE40: =BE30/BE33 -> 0.6839798 | BF40: =BF30/BF33 -> 0.68903332 | BG40: =BG30/BG33 -> 0.66955815 | BH40: =BH30/BH33 -> 0.68774176 | BI40: =BI30/BI33 -> 0.67492608 | BJ40: =BJ30/BJ33 -> 0.67989238 | ... BP40: =BP30/BP33 -> 0.61164024 | CJ40: =CJ30/CJ33 -> 0.68630022 | CK40: =CK30/CK33 -> 0.67807567
B41: EMEA Revenues % of Revenues | BC41: =BC31/BC33 -> 0.20162578 | BD41: =BD31/BD33 -> 0.19886715 | BE41: =BE31/BE33 -> 0.19121798 | BF41: =BF31/BF33 -> 0.19682273 | BG41: =BG31/BG33 -> 0.21631879 | BH41: =BH31/BH33 -> 0.19621182 | BI41: =BI31/BI33 -> 0.19652529 | BJ41: =BJ31/BJ33 -> 0.20250937 | ... BP41: =BP31/BP33 -> 0.25516892 | CJ41: =CJ31/CJ33 -> 0.19707514 | CK41: =CK31/CK33 -> 0.20280248
B42: Asia Revenues % of Revenues | BC42: =BC32/BC33 -> 0.11074508 | BD42: =BD32/BD33 -> 0.11661946 | BE42: =BE32/BE33 -> 0.12480221 | BF42: =BF32/BF33 -> 0.11414395 | BG42: =BG32/BG33 -> 0.11412307 | BH42: =BH32/BH33 -> 0.11604642 | BI42: =BI32/BI33 -> 0.12854863 | BJ42: =BJ32/BJ33 -> 0.11759825 | ... BP42: =BP32/BP33 -> 0.13319084 | CJ42: =CJ32/CJ33 -> 0.11662464 | CK42: =CK32/CK33 -> 0.11912185
B44: Revenues | C44: 367.3 | D44: 358.4 | E44: 345 | F44: 326.9 | G44: 354 | H44: 381.2 | I44: 362.7 | J44: 394.6 | K44: 380.6 | L44: 383.3 | M44: 368.1 | N44: 419.1 | O44: 411.9 | P44: 420.1 | Q44: 413.8 | R44: 450.5 | S44: 438.5 | T44: 468.1 | U44: 457.2 | V44: 476 | W44: 429.4 | X44: 452 | Y44: 443.7 | Z44: 484.5 | AA44: 424.9 | AB44: 473.6 | AC44: 455.6 | AD44: 513.9 | AE44: 487.9 | AF44: 528.6 | AG44: 534.7 | AH44: 595.1 | AI44: 587.2 | AJ44: 609.9 | AK44: 609.7 | AL44: 641.6 | AM44: 613.6 | AN44: 652.5 | AO44: 648.3 | AP44: 681 | AQ44: =AQ11 -> 630.621 | AR44: =AR11 -> 567.03 | AS44: =AS11 -> 628.279 | AT44: =AT11 -> 651.715 | AU44: =AU11 -> 633.902 | AV44: =AV11 -> 713.44 | AW44: =AW11 -> 700.231 | AX44: =AX11 -> 761.983 | ... BM44: =BM11 -> 912.99 | BN44: 530 | BO44: =BO33 -> 548.261 | BP44: =BP33 -> 570.332 | BW44: =SUM(C44:F44) -> 1397.6 | BX44: =SUM(G44:J44) -> 1492.5 | BY44: =SUM(K44:N44) -> 1551.1 | BZ44: =SUM(O44:R44) -> 1696.3 | CA44: =SUM(S44:V44) -> 1839.8 | CB44: =SUM(W44:Z44) -> 1809.6 | CC44: =SUM(AA44:AD44) -> 1868 | CD44: =SUM(AE44:AH44) -> 2146.3 | CE44: =SUM(AI44:AL44) -> 2448.4 | CF44: =SUM(AM44:AP44) -> 2595.4 | CG44: =SUM(AQ44:AT44) -> 2477.645 | CH44: =SUM(AU44:AX44) -> 2809.556 | CI44: =SUM(AY44:BB44) -> 2791.024 | CJ44: =SUM(BC44:BF44) -> 2974.485 | CK44: =SUM(BG44:BJ44) -> 3047.304 | CL44: =CL11 -> 3232.187 | CM44: =CM11 -> 3187.4482 | CN44: =CN11 -> 2763.3767 | CO44: =CO11 -> 2994.0942 | CP44: =CP11 -> 3220.1083 | CQ44: =CQ11 -> 3434.2101 | CR44: =CR11 -> 3644.7306 | CS44: =CS11 -> 3848.1436 | ... CU44: =CU11 -> 4229.8307
B45: COGS | C45: 190.4 | D45: 184.1 | E45: 178.5 | F45: 165.8 | G45: 189.5 | H45: 199.8 | I45: 187.1 | J45: 207.3 | K45: 196.5 | L45: 199 | M45: 187.5 | N45: 219.9 | O45: 211.4 | P45: 210.6 | Q45: 209.8 | R45: 225.6 | S45: 217.4 | T45: 224 | U45: 221 | V45: 235 | W45: 206.8 | X45: 218.8 | Y45: 215.5 | Z45: 224.2 | AA45: 199.7 | AB45: 217.2 | AC45: 214 | AD45: 240.9 | AE45: 232.3 | AF45: 238.3 | AG45: 239.5 | AH45: 264.4 | AI45: 256 | AJ45: 265.1 | AK45: 267.1 | AL45: 357.4 | AM45: 289.6 | AN45: 300.3 | AO45: 293.2 | AP45: 303.2 | AQ45: 297.018 | AR45: 288.66 | AS45: 298.977 | AT45: =1212.28-SUM(AQ45:AS45) -> 327.625 | AU45: 289.398 | AV45: 315.917 | AW45: 312.464 | AX45: =1259.961-SUM(AU45:AW45) -> 342.182 | AY45: 295.48 | AZ45: 315.709 | BA45: 312.833 | BB45: =1259.95-SUM(AY45:BA45) -> 335.928 | BC45: 319.55 | BD45: 335.436 | BE45: 330.07 | BF45: =1327.55-SUM(BC45:BE45) -> 342.494 | BG45: 321.715 | BH45: 333.23 | BI45: 334.203 | BJ45: =1344.64-SUM(BG45:BI45) -> 355.492 | BK45: 311.23 | BL45: 349.804 | BM45: 461.37 | BN45: =871.959-SUM(BK45:BM45) -> -250.445 | BO45: 240.836 | BP45: 238.625 | BW45: =SUM(C45:F45) -> 718.8 | BX45: =SUM(G45:J45) -> 783.7 | BY45: =SUM(K45:N45) -> 802.9 | BZ45: =SUM(O45:R45) -> 857.4 | CA45: =SUM(S45:V45) -> 897.4 | CB45: =SUM(W45:Z45) -> 865.3 | CC45: =SUM(AA45:AD45) -> 871.8 | CD45: =SUM(AE45:AH45) -> 974.5 | CE45: =SUM(AI45:AL45) -> 1145.6 | CF45: =SUM(AM45:AP45) -> 1186.3 | CG45: =SUM(AQ45:AT45) -> 1212.28 | CH45: =SUM(AU45:AX45) -> 1259.961 | CI45: =SUM(AY45:BB45) -> 1259.95 | CJ45: =SUM(BC45:BF45) -> 1327.55 | CK45: =SUM(BG45:BJ45) -> 1344.64 | CL45: =CL44*(1-CL63) -> 1422.1623 | CM45: =CM44*(1-CM63) -> 1386.54 | CN45: =CN44*(1-CN63) -> 1188.252 | CO45: =CO44*(1-CO63) -> 1287.4605 | CP45: =CP44*(1-CP63) -> 1384.6466 | CQ45: =CQ44*(1-CQ63) -> 1476.7103 | CR45: =CR44*(1-CR63) -> 1567.2342 | CS45: =CS44*(1-CS63) -> 1654.7018 | ... CU45: =CU44*(1-CU63) -> 1818.8272
B46: GP | C46: =C44-C45 -> 176.9 | D46: =D44-D45 -> 174.3 | E46: =E44-E45 -> 166.5 | F46: =F44-F45 -> 161.1 | G46: =G44-G45 -> 164.5 | H46: =H44-H45 -> 181.4 | I46: =I44-I45 -> 175.6 | J46: =J44-J45 -> 187.3 | ... BP46: =BP44-BP45 -> 331.707 | BW46: =SUM(C46:F46) -> 678.8 | BX46: =SUM(G46:J46) -> 708.8 | BY46: =SUM(K46:N46) -> 748.2 | BZ46: =SUM(O46:R46) -> 838.9 | CA46: =SUM(S46:V46) -> 942.4 | CB46: =SUM(W46:Z46) -> 944.3 | CC46: =SUM(AA46:AD46) -> 996.2 | CD46: =SUM(AE46:AH46) -> 1171.8 | CE46: =SUM(AI46:AL46) -> 1302.8 | CF46: =SUM(AM46:AP46) -> 1409.1 | CG46: =SUM(AQ46:AT46) -> 1265.365 | CH46: =SUM(AU46:AX46) -> 1549.595 | CI46: =SUM(AY46:BB46) -> 1531.074 | CJ46: =SUM(BC46:BF46) -> 1646.935 | CK46: =SUM(BG46:BJ46) -> 1702.664 | CL46: =CL44-CL45 -> 1810.0247 | CM46: =CM44-CM45 -> 1800.9083 | CN46: =CN44-CN45 -> 1575.1247 | CO46: =CO44-CO45 -> 1706.6337 | CP46: =CP44-CP45 -> 1835.4617 | CQ46: =CQ44-CQ45 -> 1957.4997 | CR46: =CR44-CR45 -> 2077.4965 | CS46: =CS44-CS45 -> 2193.4419 | ... CU46: =CU44-CU45 -> 2411.0035
...

Sheet Base Case
B1: [Use for Graphing] | AQ1: Q1 2020 | AU1: Q1 2021 | AY1: Q1 2022 | BC1: Q1 2023 | BG1: Q1 2024 | BK1: Q1 2025 | BO1: Q1 2026
B2: Quarterly
B3: Revenues | C3: Q1 2010 | D3: Q2 2010 | E3: Q3 2010 | F3: Q4 2010 | G3: Q1 2011 | H3: Q2 2011 | I3: Q3 2011 | J3: Q4 2011 | K3: Q1 2012 | L3: Q2 2012 | M3: Q3 2012 | N3: Q4 2012 | O3: Q1 2013 | P3: Q2 2013 | Q3: Q3 2013 | R3: Q4 2013 | S3: Q1 2014 | T3: Q2 2014 | U3: Q3 2014 | V3: Q4 2014 | W3: Q1 2015 | X3: Q2 2015 | Y3: Q3 2015 | Z3: Q4 2015 | AA3: Q1 2016 | AB3: Q2 2016 | AC3: Q3 2016 | AD3: Q4 2016 | AE3: Q1 2017 | AF3: Q2 2017 | AG3: Q3 2017 | AH3: Q4 2017 | AI3: Q1 2018 | AJ3: Q2 2018 | AK3: Q3 2018 | AL3: Q4 2018 | AM3: Q1 2019 | AN3: Q2 2019 | AO3: Q3 2019 | AP3: Q4 2019 | AQ3: Q1 2020 | AR3: Q2 2020 | AS3: Q3 2020 | AT3: Q4 2020 | AU3: Q1 2021 | AV3: Q2 2021 | AW3: Q3 2021 | AX3: Q4 2021 | AY3: Q1 2022 | AZ3: Q2 2022 | BA3: Q3 2022 | BB3: Q4 2022 | BC3: Q1 2023 | BD3: Q2 2023 | BE3: Q3 2023 | BF3: Q4 2023 | BG3: Q1 2024 | BH3: Q2 2024 | BI3: Q3 2024 | BJ3: Q4 2024 | BK3: Q1 2025 | BL3: Q2 2025 | BM3: Q3 2025 | BN3: Q4 2025 | BO3: Q1 2026 | BP3: Q2 2026 | BQ3: Q3 2026 | BR3: Q4 2026 | CA3: 2010 | CB3: =CA3+1 -> 2011 | CC3: =CB3+1 -> 2012 | CD3: =CC3+1 -> 2013 | CE3: =CD3+1 -> 2014 | CF3: =CE3+1 -> 2015 | CG3: =CF3+1 -> 2016 | CH3: =CG3+1 -> 2017 | CI3: =CH3+1 -> 2018 | ... EW3: =EV3+1 -> 2084
B4: Vascular Access | AQ4: 150.25 | AR4: 164.958 | AS4: 160.05 | AT4: =657.703-SUM(AQ4:AS4) -> 182.445 | AU4: 163.97 | AV4: 167.73 | AW4: 175.47 | AX4: =700.24-SUM(AU4:AW4) -> 193.07 | AY4: 166.13 | AZ4: 163.9 | BA4: 167.14 | BB4: =683.612-SUM(AY4:BA4) -> 186.442 | BC4: 177.65 | BD4: 173.785 | BE4: 169.91 | BF4: =708.04-SUM(BC4:BE4) -> 186.695 | BG4: 181.35 | BH4: 181.1 | BI4: 180.89 | BJ4: =732.67-SUM(BG4:BI4) -> 189.33 | BK4: 182.36 | BL4: 185.53 | BM4: 191.02 | BO4: 236.812 | BP4: 246.337 | CK4: =SUM(AQ4:AT4) -> 657.703 | CL4: =SUM(AU4:AX4) -> 700.24 | CM4: =SUM(AY4:BB4) -> 683.612 | CN4: =SUM(BC4:BF4) -> 708.04 | CO4: =SUM(BG4:BJ4) -> 732.67 | CP4: =CO4*(1+CP13) -> 752.81843 | CQ4: =CP4*(1+CQ13) -> 779.16707 | CR4: =CQ4*(1+CR13) -> 804.49 | CS4: =CR4*(1+CS13) -> 828.6247 | CT4: =CS4*(1+CT13) -> 853.48344 | CU4: =CT4*(1+CU13) -> 879.08794 | CV4: =CU4*(1+CV13) -> 905.46058 | CW4: =CV4*(1+CW13) -> 932.6244 | ... CY4: =CX4*(1+CY13) -> 989.42123
B5: Interventional Cardiology | AQ5: 99.93 | AR5: 82.594 | AS5: 93.18 | AT5: =382.43-SUM(AQ5:AS5) -> 106.726 | AU5: 96.173 | AV5: 112.08 | AW5: 104.304 | AX5: =427.5-SUM(AU5:AW5) -> 114.943 | AY5: 96.85 | AZ5: 114.34 | BA5: 97.6 | BB5: =445.01-SUM(AY5:BA5) -> 136.22 | BC5: 116.89 | BD5: 124.78 | BE5: 134.089 | BF5: =511.434-SUM(BC5:BE5) -> 135.675 | BG5: 134.665 | BH5: 141.15 | BI5: 149.86 | BJ5: =586.05-SUM(BG5:BI5) -> 160.375 | BK5: 137.55 | BL5: 170.01 | BM5: 266.41 | BO5: 204.656 | BP5: 211.874 | CK5: =SUM(AQ5:AT5) -> 382.43 | CL5: =SUM(AU5:AX5) -> 427.5 | CM5: =SUM(AY5:BB5) -> 445.01 | CN5: =SUM(BC5:BF5) -> 511.434 | CO5: =SUM(BG5:BJ5) -> 586.05 | CP5: =CO5*(1+CP14) -> 791.1675 | CQ5: =CP5*(1+CQ14) -> 957.31268 | CR5: =CQ5*(1+CR14) -> 1120.0558 | CS5: =CR5*(1+CS14) -> 1276.8636 | CT5: =CS5*(1+CT14) -> 1417.3186 | CU5: =CT5*(1+CU14) -> 1544.8773 | CV5: =CU5*(1+CV14) -> 1668.4675 | CW5: =CV5*(1+CW14) -> 1785.2602 | ... CY5: =CX5*(1+CY14) -> 1986.9946
B6: Anesthesia | AQ6: 75.7 | AR6: 64.867 | AS6: 75.64 | AT6: =302.293-SUM(AQ5:AS5) -> 26.589 | AU6: 84.85 | AV6: 95.42 | AW6: 97.07 | AX6: =380.14-SUM(AU6:AW6) -> 102.8 | AY6: 86.95 | AZ6: 104.695 | BA6: 108.73 | BB6: =388.89-SUM(AY6:BA6) -> 88.515 | BC6: 93.33 | BD6: 100.84 | BE6: 97.61 | BF6: =389.957-SUM(BC6:BE6) -> 98.177 | BG6: 96.352 | BH6: 102.49 | BI6: 101.15 | BJ6: =395.28-SUM(BG6:BI6) -> 95.288 | BK6: 86.59 | BL6: 96.38 | BM6: 101.44 | BO6: 0 | BP6: 0 | CK6: =SUM(AQ6:AT6) -> 242.796 | CL6: =SUM(AU6:AX6) -> 380.14 | CM6: =SUM(AW6:BB6) -> 588.76 | CN6: =SUM(AW6:BF6) -> 978.717 | CO6: =SUM(BG6:BJ6) -> 395.28 | CP6: =CO6*(1+CP15) -> 379.4688 | CQ6: =CP6*(1+CQ15) -> 0 | CR6: =CQ6*(1+CR15) -> 0 | CS6: =CR6*(1+CS15) -> 0 | CT6: =CS6*(1+CT15) -> 0 | CU6: =CT6*(1+CU15) -> 0 | CV6: =CU6*(1+CV15) -> 0 | CW6: =CV6*(1+CW15) -> 0 | ... CY6: =CX6*(1+CY15) -> 0
B7: Surgical | AQ7: 75.432 | AR7: 67.275 | AS7: 82.22 | AT7: =317.2-SUM(AQ7:AS7) -> 92.273 | AU7: 80.386 | AV7: 98.18 | AW7: 92.83 | AX7: =377.75-SUM(AU7:AW7) -> 106.354 | AY7: 89.7 | AZ7: 99.64 | BA7: 93.12 | BB7: =392.91-SUM(AY7:BA7) -> 110.45 | BC7: 99.02 | BD7: 105.95 | BE7: 112.8 | BF7: =427.359-SUM(BC7:BE7) -> 109.589 | BG7: 105.52 | BH7: 111.3 | BI7: 111.746 | BJ7: =450.48-SUM(BG7:BI7) -> 121.914 | BK7: 105.78 | BL7: 114.04 | BM7: 122.87 | BO7: 106.794 | BP7: 112.121 | CK7: =SUM(AQ7:AT7) -> 317.2 | CL7: =SUM(AU7:AX7) -> 377.75 | CM7: =SUM(AY7:BB7) -> 392.91 | CN7: =SUM(BC7:BF7) -> 427.359 | CO7: =SUM(BG7:BJ7) -> 450.48 | CP7: =CO7*(1+CP16) -> 477.5088 | CQ7: =CP7*(1+CQ16) -> 510.93442 | CR7: =CQ7*(1+CR16) -> 551.80917 | CS7: =CR7*(1+CS16) -> 584.91772 | CT7: =CS7*(1+CT16) -> 614.16361 | CU7: =CT7*(1+CU16) -> 641.80097 | CV7: =CU7*(1+CV16) -> 667.47301 | CW7: =CV7*(1+CW16) -> 690.83456 | ... CY7: =CX7*(1+CY16) -> 734.68529
B8: Interventional Urology | AQ8: 74.19 | AR8: 40.09 | AS8: 81.77 | AT8: =290.02-SUM(AQ8:AS8) -> 93.97 | AU8: 73.36 | AV8: 92.24 | AW8: 83.107 | AX8: =341.66-SUM(AU8:AW8) -> 92.953 | AY8: 74.89 | AZ8: 79.81 | BA8: 78.969 | BB8: =322.83-SUM(AY8:BA8) -> 89.161 | BC8: 75.37 | BD8: 77.81 | BE8: 73.622 | BF8: =319.785-SUM(BC8:BE8) -> 92.983 | BG8: 79.74 | BH8: 83.1 | BI8: 83.39 | BJ8: =331.092-SUM(BG8:BI8) -> 84.862 | BK8: 70.96 | BL8: 76.38 | BM8: 71.77 | BO8: 0 | BP8: 0 | CK8: =SUM(AQ8:AT8) -> 290.02 | CL8: =SUM(AU8:AX8) -> 341.66 | CM8: =SUM(AY8:BB8) -> 322.83 | CN8: =SUM(BC8:BF8) -> 319.785 | CO8: =SUM(BG8:BJ8) -> 331.092 | CP8: =CO8*(1+CP17) -> 314.5374 | CQ8: =CP8*(1+CQ17) -> 0 | CR8: =CQ8*(1+CR17) -> 0 | CS8: =CR8*(1+CS17) -> 0 | CT8: =CS8*(1+CT17) -> 0 | CU8: =CT8*(1+CU17) -> 0 | CV8: =CU8*(1+CV17) -> 0 | CW8: =CV8*(1+CW17) -> 0 | ... CY8: =CX8*(1+CY17) -> 0
B9: OEM | AQ9: 63.389 | AR9: 55.832 | AS9: 49.399 | AT9: =220.246-SUM(AQ9:AS9) -> 51.626 | AU9: 53.48 | AV9: 60.95 | AW9: 64.08 | AX9: =245.681-SUM(AU9:AW9) -> 67.171 | AY9: 57.656 | AZ9: 70 | BA9: 71.28 | BB9: =272.624-SUM(AY9:BA9) -> 73.688 | BC9: 76.99 | BD9: 84.12 | BE9: 82.309 | BF9: =326.008-SUM(BC9:BE9) -> 82.589 | BG9: 87.69 | BH9: 88.82 | BI9: 82.55 | BJ9: =344.51-SUM(BG9:BI9) -> 85.45 | BK9: 63.88 | BL9: 78.67 | BM9: 80.41 | BO9: 0 | BP9: 0 | CK9: =SUM(AQ9:AT9) -> 220.246 | CL9: =SUM(AU9:AX9) -> 245.681 | CM9: =SUM(AY9:BB9) -> 272.624 | CN9: =SUM(BC9:BF9) -> 326.008 | CO9: =SUM(BG9:BJ9) -> 344.51 | CP9: =CO9*(1+CP18) -> 310.059 | CQ9: =CP9*(1+CQ18) -> 0 | CR9: =CQ9*(1+CR18) -> 0 | CS9: =CR9*(1+CS18) -> 0 | CT9: =CS9*(1+CT18) -> 0 | CU9: =CT9*(1+CU18) -> 0 | CV9: =CU9*(1+CV18) -> 0 | CW9: =CV9*(1+CW18) -> 0 | ... CY9: =CX9*(1+CY18) -> 0
B10: Other | AQ10: 91.73 | AR10: 91.414 | AS10: 86.02 | AT10: =367.25-SUM(AQ10:AS10) -> 98.086 | AU10: 81.683 | AV10: 86.84 | AW10: 83.37 | AX10: =336.585-SUM(AU10:AW10) -> 84.692 | AY10: 69.512 | AZ10: 72.13 | BA10: 69.9 | BB10: =285.148-SUM(AY10:BA10) -> 73.606 | BC10: 71.65 | BD10: 75.95 | BE10: 76.033 | BF10: =291.902-SUM(BC10:BE10) -> 68.269 | BG10: 52.51 | BH10: 41.7 | BI10: 54.76 | BJ10: =207.222-SUM(BG10:BI10) -> 58.252 | BK10: 53.6 | BL10: 59.84 | BM10: 79.07 | BO10: 0 | BP10: 0 | CK10: =SUM(AQ10:AT10) -> 367.25 | CL10: =SUM(AU10:AX10) -> 336.585 | CM10: =SUM(AY10:BB10) -> 285.148 | CN10: =SUM(BC10:BF10) -> 291.902 | CO10: =SUM(BG10:BJ10) -> 207.222 | CP10: =CO10*(1+CP19) -> 211.36644 | CQ10: =CP10*(1+CQ19) -> 215.59377 | CR10: =CQ10*(1+CR19) -> 219.90564 | CS10: =CR10*(1+CS19) -> 224.30376 | CT10: =CS10*(1+CT19) -> 228.78983 | CU10: =CT10*(1+CU19) -> 233.36563 | CV10: =CU10*(1+CV19) -> 238.03294 | CW10: =CV10*(1+CW19) -> 242.7936 | ... CY10: =CX10*(1+CY19) -> 252.60246
B11: Ttl Revenues | AQ11: =SUM(AQ4:AQ10) -> 630.621 | AR11: =SUM(AR4:AR10) -> 567.03 | AS11: =SUM(AS4:AS10) -> 628.279 | AT11: =SUM(AT4:AT10) -> 651.715 | AU11: =SUM(AU4:AU10) -> 633.902 | AV11: =SUM(AV4:AV10) -> 713.44 | AW11: =SUM(AW4:AW10) -> 700.231 | AX11: =SUM(AX4:AX10) -> 761.983 | ... BM11: =SUM(BM4:BM10) -> 912.99 | BO11: =SUM(BO4:BO10) -> 548.262 | BP11: =SUM(BP4:BP10) -> 570.332 | CK11: =SUM(AQ11:AT11) -> 2477.645 | CL11: =SUM(AU11:AX11) -> 2809.556 | CM11: =SUM(AY11:BB11) -> 2791.024 | CN11: =SUM(BC11:BF11) -> 2974.485 | CO11: =SUM(BG11:BJ11) -> 3047.304 | CP11: =SUM(CP4:CP10) -> 3236.9264 | CQ11: =SUM(CQ4:CQ10) -> 2463.0079 | CR11: =SUM(CR4:CR10) -> 2696.2606 | CS11: =SUM(CS4:CS10) -> 2914.7098 | CT11: =SUM(CT4:CT10) -> 3113.7555 | CU11: =SUM(CU4:CU10) -> 3299.1319 | CV11: =SUM(CV4:CV10) -> 3479.434 | CW11: =SUM(CW4:CW10) -> 3651.5128 | ... CY11: =SUM(CY4:CY10) -> 3963.7036
B13: Vascular Access Growth Y/y | AU13: =AU4/AQ4-1 -> 0.091314476 | AV13: =AV4/AR4-1 -> 0.016804277 | AW13: =AW4/AS4-1 -> 0.096344892 | AX13: =AX4/AT4-1 -> 0.058236729 | AY13: =AY4/AU4-1 -> 0.013173141 | AZ13: =AZ4/AV4-1 -> -0.022834317 | BA13: =BA4/AW4-1 -> -0.047472502 | BB13: =BB4/AX4-1 -> -0.034329518 | ... BM13: =BM4/BI4-1 -> 0.056000885 | BO13: =BO4/BK4-1 -> 0.29859618 | BP13: =BP4/BL4-1 -> 0.32774753 | CL13: =CL4/CK4-1 -> 0.064675089 | CM13: =CM4/CL4-1 -> -0.023746144 | CN13: =CN4/CM4-1 -> 0.03573372 | CO13: =CO4/CN4-1 -> 0.03478617 | CP13: 0.0275 | CQ13: 0.035 | CR13: 0.0325 | CS13: 0.03 | CT13: 0.03 | CU13: 0.03 | CV13: 0.03 | CW13: 0.03 | CX13: 0.03 | CY13: 0.03
B14: Vascular Intervention Growth Y/y | AU14: =AU5/AQ5-1 -> -0.037596317 | AV14: =AV5/AR5-1 -> 0.3569993 | AW14: =AW5/AS5-1 -> 0.11938184 | AX14: =AX5/AT5-1 -> 0.076991548 | AY14: =AY5/AU5-1 -> 0.0070393978 | AZ14: =AZ5/AV5-1 -> 0.020164168 | BA14: =BA5/AW5-1 -> -0.064273662 | BB14: =BB5/AX5-1 -> 0.18510914 | ... BM14: =BM5/BI5-1 -> 0.77772588 | BO14: =BO5/BK5-1 -> 0.48786623 | BP14: =BP5/BL5-1 -> 0.24624434 | CL14: =CL5/CK5-1 -> 0.11785163 | CM14: =CM5/CL5-1 -> 0.040959064 | CN14: =CN5/CM5-1 -> 0.14926406 | CO14: =CO5/CN5-1 -> 0.14589566 | CP14: 0.35 | CQ14: 0.21 | CR14: 0.17 | CS14: 0.14 | CT14: 0.11 | CU14: 0.09 | CV14: 0.08 | CW14: 0.07 | CX14: 0.06 | CY14: 0.05
B15: Anesthesia Growth Y/y | AU15: =AU6/AQ6-1 -> 0.12087186 | AV15: =AV6/AR6-1 -> 0.47100991 | AW15: =AW6/AS6-1 -> 0.28331571 | AX15: =AX6/AT6-1 -> 2.8662605 | AY15: =AY6/AU6-1 -> 0.024749558 | AZ15: =AZ6/AV6-1 -> 0.097201844 | BA15: =BA6/AW6-1 -> 0.1201195 | BB15: =BB6/AX6-1 -> -0.13895914 | ... BM15: =BM6/BI6-1 -> 0.0028670292 | BO15: =BO6/BK6-1 -> -1 | BP15: =BP6/BL6-1 -> -1 | CL15: =CL6/CK6-1 -> 0.56567654 | CM15: =CM6/CL6-1 -> 0.54879781 | CN15: =CN6/CM6-1 -> 0.6623361 | CO15: =CO6/CN6-1 -> -0.59612431 | CP15: -0.04 | CQ15: -1 | CR15: -1 | CS15: 0 | CT15: 0 | CU15: 0 | CV15: 0 | CW15: 0 | CX15: 0 | CY15: 0
B16: Surgical Growth Y/y | AU16: =AU7/AQ7-1 -> 0.065675045 | AV16: =AV7/AR7-1 -> 0.45938313 | AW16: =AW7/AS7-1 -> 0.12904403 | AX16: =AX7/AT7-1 -> 0.15260152 | AY16: =AY7/AU7-1 -> 0.11586595 | AZ16: =AZ7/AV7-1 -> 0.014870646 | BA16: =BA7/AW7-1 -> 0.0031239901 | BB16: =BB7/AX7-1 -> 0.038512891 | ... BM16: =BM7/BI7-1 -> 0.099547187 | BO16: =BO7/BK7-1 -> 0.0095859331 | BP16: =BP7/BL7-1 -> -0.016827429 | CL16: =CL7/CK7-1 -> 0.19088903 | CM16: =CM7/CL7-1 -> 0.040132363 | CN16: =CN7/CM7-1 -> 0.087676567 | CO16: =CO7/CN7-1 -> 0.054102055 | CP16: 0.06 | CQ16: 0.07 | CR16: 0.08 | CS16: 0.06 | CT16: 0.05 | CU16: 0.045 | CV16: 0.04 | CW16: 0.035 | CX16: 0.0325 | CY16: 0.03
B17: Interventional Urology Growth Y/y | AU17: =AU8/AQ8-1 -> -0.011187492 | AV17: =AV8/AR8-1 -> 1.3008231 | AW17: =AW8/AS8-1 -> 0.01635074 | AX17: =AX8/AT8-1 -> -0.010822603 | AY17: =AY8/AU8-1 -> 0.020856052 | AZ17: =AZ8/AV8-1 -> -0.13475716 | BA17: =BA8/AW8-1 -> -0.049791233 | BB17: =BB8/AX8-1 -> -0.04079481 | ... BM17: =BM8/BI8-1 -> -0.13934525 | BO17: =BO8/BK8-1 -> -1 | BP17: =BP8/BL8-1 -> -1 | CL17: =CL8/CK8-1 -> 0.17805669 | CM17: =CM8/CL8-1 -> -0.055113271 | CN17: =CN8/CM8-1 -> -0.0094322089 | CO17: =CO8/CN8-1 -> 0.035358131 | CP17: -0.05 | CQ17: -1 | CR17: -1 | CS17: 0 | CT17: 0 | CU17: 0 | CV17: 0 | CW17: 0 | CX17: 0 | CY17: 0
B18: OEM Growth Y/y | AU18: =AU9/AQ9-1 -> -0.1563205 | AV18: =AV9/AR9-1 -> 0.091667861 | AW18: =AW9/AS9-1 -> 0.29719225 | AX18: =AX9/AT9-1 -> 0.30110797 | AY18: =AY9/AU9-1 -> 0.078085266 | AZ18: =AZ9/AV9-1 -> 0.14848236 | BA18: =BA9/AW9-1 -> 0.11235955 | BB18: =BB9/AX9-1 -> 0.097021036 | ... BM18: =BM9/BI9-1 -> -0.025923683 | BO18: =BO9/BK9-1 -> -1 | BP18: =BP9/BL9-1 -> -1 | CL18: =CL9/CK9-1 -> 0.1154845 | CM18: =CM9/CL9-1 -> 0.1096666 | CN18: =CN9/CM9-1 -> 0.19581548 | CO18: =CO9/CN9-1 -> 0.056753209 | CP18: -0.1 | CQ18: -1 | CR18: -1 | CS18: 0 | CT18: 0 | CU18: 0 | CV18: 0 | CW18: 0 | CX18: 0 | CY18: 0
B19: Other Growth Y/y | AU19: =AU10/AQ10-1 -> -0.10952796 | AV19: =AV10/AR10-1 -> -0.0500361 | AW19: =AW10/AS10-1 -> -0.030806789 | AX19: =AX10/AT10-1 -> -0.13655364 | AY19: =AY10/AU10-1 -> -0.14900285 | AZ19: =AZ10/AV10-1 -> -0.16939199 | BA19: =BA10/AW10-1 -> -0.16156891 | BB19: =BB10/AX10-1 -> -0.13089784 | ... BM19: =BM10/BI10-1 -> 0.44393718 | BO19: =BO10/BK10-1 -> -1 | BP19: =BP10/BL10-1 -> -1 | CL19: =CL10/CK10-1 -> -0.083498979 | CM19: =CM10/CL10-1 -> -0.15282024 | CN19: =CN10/CM10-1 -> 0.023685946 | CO19: =CO10/CN10-1 -> -0.29009736 | CP19: 0.02 | CQ19: 0.02 | CR19: 0.02 | CS19: 0.02 | CT19: 0.02 | CU19: 0.02 | CV19: 0.02 | CW19: 0.02 | CX19: 0.02 | CY19: 0.02
B20: Ttl Revenues Growth Y/y | AU20: =AU11/AQ11-1 -> 0.005202808 | AV20: =AV11/AR11-1 -> 0.25820503 | AW20: =AW11/AS11-1 -> 0.11452237 | AX20: =AX11/AT11-1 -> 0.16919666 | AY20: =AY11/AU11-1 -> 0.012282656 | AZ20: =AZ11/AV11-1 -> -0.012509812 | BA20: =BA11/AW11-1 -> -0.019267927 | BB20: =BB11/AX11-1 -> -0.0051195368 | ... BM20: =BM11/BI11-1 -> 0.19447214 | BO20: =BO11/BK11-1 -> -0.21757335 | BP20: =BP11/BL11-1 -> -0.26960108 | CL20: =CL11/CK11-1 -> 0.13396229 | CM20: =CM11/CL11-1 -> -0.00659606 | CN20: =CN11/CM11-1 -> 0.065732505 | CO20: =CO11/CN11-1 -> 0.024481213 | CP20: =CP11/CO11-1 -> 0.062226271 | CQ20: =CQ11/CP11-1 -> -0.23909053 | CR20: =CR11/CQ11-1 -> 0.09470238 | CS20: =CS11/CR11-1 -> 0.081019311 | ... CY20: =CY11/CX11-1 -> 0.039274203
B22: Vascular Access % of Ttl Revenues | AQ22: =AQ4/AQ11 -> 0.23825721 | AR22: =AR4/AR11 -> 0.29091582 | AS22: =AS4/AS11 -> 0.25474351 | AT22: =AT4/AT11 -> 0.27994599 | AU22: =AU4/AU11 -> 0.25866774 | AV22: =AV4/AV11 -> 0.23510036 | AW22: =AW4/AW11 -> 0.25058873 | AX22: =AX4/AX11 -> 0.25337836 | ... BM22: =BM4/BM11 -> 0.20922464 | BO22: =BO4/BO11 -> 0.43193218 | BP22: =BP4/BP11 -> 0.4319186 | CK22: =CK4/CK11 -> 0.2654549 | CL22: =CL4/CL11 -> 0.24923511 | CM22: =CM4/CM11 -> 0.24493233 | CN22: =CN4/CN11 -> 0.23803785 | CO22: =CO4/CO11 -> 0.2404322
B23: Interventional % of Ttl Revenues | AQ23: =AQ5/AQ11 -> 0.15846285 | AR23: =AR5/AR11 -> 0.14566072 | AS23: =AS5/AS11 -> 0.14830991 | AT23: =AT5/AT11 -> 0.16376177 | AU23: =AU5/AU11 -> 0.15171588 | AV23: =AV5/AV11 -> 0.157098 | AW23: =AW5/AW11 -> 0.14895656 | AX23: =AX5/AX11 -> 0.1508472 | ... BM23: =BM5/BM11 -> 0.29179947 | BO23: =BO5/BO11 -> 0.37328139 | BP23: =BP5/BP11 -> 0.37149239 | CK23: =CK5/CK11 -> 0.15435222 | CL23: =CL5/CL11 -> 0.15215927 | CM23: =CM5/CM11 -> 0.15944327 | CN23: =CN5/CN11 -> 0.17194035 | CO23: =CO5/CO11 -> 0.19231754
B24: Anesthesia % of Ttl Revenues | AQ24: =AQ6/AQ11 -> 0.1200404 | AR24: =AR6/AR11 -> 0.11439783 | AS24: =AS6/AS11 -> 0.12039237 | AT24: =AT6/AT11 -> 0.040798509 | AU24: =AU6/AU11 -> 0.1338535 | AV24: =AV6/AV11 -> 0.13374636 | AW24: =AW6/AW11 -> 0.13862568 | AX24: =AX6/AX11 -> 0.13491115 | ... BM24: =BM6/BM11 -> 0.11110746 | BO24: =BO6/BO11 -> 0 | BP24: =BP6/BP11 -> 0 | CK24: =CK6/CK11 -> 0.097994668 | CL24: =CL6/CL11 -> 0.13530252 | CM24: =CM6/CM11 -> 0.21094767 | CN24: =CN6/CN11 -> 0.32903746 | CO24: =CO6/CO11 -> 0.12971466
B25: Surgical % of Ttl Revenues | AQ25: =AQ7/AQ11 -> 0.11961543 | AR25: =AR7/AR11 -> 0.11864452 | AS25: =AS7/AS11 -> 0.13086543 | AT25: =AT7/AT11 -> 0.1415849 | AU25: =AU7/AU11 -> 0.1268114 | AV25: =AV7/AV11 -> 0.13761494 | AW25: =AW7/AW11 -> 0.13257054 | AX25: =AX7/AX11 -> 0.13957529 | ... BM25: =BM7/BM11 -> 0.13457979 | BO25: =BO7/BO11 -> 0.19478643 | BP25: =BP7/BP11 -> 0.196589 | CK25: =CK7/CK11 -> 0.1280248 | CL25: =CL7/CL11 -> 0.13445185 | CM25: =CM7/CM11 -> 0.14077629 | CN25: =CN7/CN11 -> 0.14367496 | CO25: =CO7/CO11 -> 0.14782903
B26: Interventional Urology % of Ttl Revenues | AQ26: =AQ8/AQ11 -> 0.11764594 | AR26: =AR8/AR11 -> 0.070701727 | AS26: =AS8/AS11 -> 0.13014919 | AT26: =AT8/AT11 -> 0.14418879 | AU26: =AU8/AU11 -> 0.11572767 | AV26: =AV8/AV11 -> 0.12928908 | AW26: =AW8/AW11 -> 0.11868512 | AX26: =AX8/AX11 -> 0.12198829 | ... BM26: =BM8/BM11 -> 0.078609842 | BO26: =BO8/BO11 -> 0 | BP26: =BP8/BP11 -> 0 | CK26: =CK8/CK11 -> 0.1170547 | CL26: =CL8/CL11 -> 0.1216064 | CM26: =CM8/CM11 -> 0.11566722 | CN26: =CN8/CN11 -> 0.10750937 | CO26: =CO8/CO11 -> 0.10865079
B27: OEM % of Ttl Revenues | AQ27: =AQ9/AQ11 -> 0.10051838 | AR27: =AR9/AR11 -> 0.098463926 | AS27: =AS9/AS11 -> 0.078625897 | AT27: =AT9/AT11 -> 0.079215608 | AU27: =AU9/AU11 -> 0.084366353 | AV27: =AV9/AV11 -> 0.08543115 | AW27: =AW9/AW11 -> 0.091512658 | AX27: =AX9/AX11 -> 0.088152885 | ... BM27: =BM9/BM11 -> 0.088073254 | BO27: =BO9/BO11 -> 0 | BP27: =BP9/BP11 -> 0 | CK27: =CK9/CK11 -> 0.088893284 | CL27: =CL9/CL11 -> 0.087444778 | CM27: =CM9/CM11 -> 0.097678845 | CN27: =CN9/CN11 -> 0.10960149 | CO27: =CO9/CO11 -> 0.11305403
B28: Other % of Ttl Revenues | AQ28: =AQ10/AQ11 -> 0.14545979 | AR28: =AR10/AR11 -> 0.16121546 | AS28: =AS10/AS11 -> 0.1369137 | AT28: =AT10/AT11 -> 0.15050444 | AU28: =AU10/AU11 -> 0.12885746 | AV28: =AV10/AV11 -> 0.12172012 | AW28: =AW10/AW11 -> 0.11906071 | AX28: =AX10/AX11 -> 0.11114684 | ... BM28: =BM10/BM11 -> 0.086605549 | BO28: =BO10/BO11 -> 0 | BP28: =BP10/BP11 -> 0 | CK28: =CK10/CK11 -> 0.14822543 | CL28: =CL10/CL11 -> 0.11980007 | CM28: =CM10/CM11 -> 0.10216609 | CN28: =CN10/CN11 -> 0.098135307 | CO28: =CO10/CO11 -> 0.068001748
B30: U.S. Revenues | BC30: =411.86+76.99 -> 488.85 | BD30: =424.64+84.128 -> 508.768 | BE30: =428.206+82.309 -> 510.515 | BF30: =2041.4-SUM(BC30:BE30) -> 533.267 | BG30: 494 | BH30: 515.6 | BI30: =433.3+82.6 -> 515.9 | BJ30: =2066.3-SUM(BG30:BI30) -> 540.8 | BK30: 475.7 | BL30: 525.7 | BM30: 555.9 | BN30: =1279.197-SUM(BK30:BM30) -> -278.103 | BO30: 332.653 | BP30: 348.838 | CN30: =SUM(BC30:BF30) -> 2041.4 | CO30: =SUM(BG30:BJ30) -> 2066.3
B31: EMEA Revenues | BC31: 143.34 | BD31: 147.809 | BE31: 142.723 | BF31: =586.2-SUM(BC31:BE31) -> 152.328 | BG31: 159.6 | BH31: 147.1 | BI31: 150.22 | BJ31: =618-SUM(BG31:BI31) -> 161.08 | BK31: 151.2 | BL31: 166.2 | BM31: 234.24 | BN31: =472.411-SUM(BK31:BM31) -> -79.229 | BO31: 146.678 | BP31: 145.531 | CN31: =SUM(BC31:BF31) -> 586.2 | CO31: =SUM(BG31:BJ31) -> 618
B32: Asia Revenues | BC32: 78.731 | BD32: 86.678 | BE32: 93.151 | BF32: =346.9-SUM(BC32:BE32) -> 88.34 | BG32: 84.2 | BH32: 87 | BI32: 98.26 | BJ32: =363-SUM(BG32:BI32) -> 93.54 | BK32: 73.8 | BL32: 89 | BM32: 122.87 | BN32: =241.105-SUM(BK32:BM32) -> -44.565 | BO32: 68.93 | BP32: 75.963 | CN32: =SUM(BC32:BF32) -> 346.9 | CO32: =SUM(BG32:BJ32) -> 363
B33: Ttl Revenues | BC33: =SUM(BC30:BC32) -> 710.921 | BD33: =SUM(BD30:BD32) -> 743.255 | BE33: =SUM(BE30:BE32) -> 746.389 | BF33: =SUM(BF30:BF32) -> 773.935 | BG33: =SUM(BG30:BG32) -> 737.8 | BH33: =SUM(BH30:BH32) -> 749.7 | BI33: =SUM(BI30:BI32) -> 764.38 | BJ33: =SUM(BJ30:BJ32) -> 795.42 | ... BP33: =SUM(BP30:BP32) -> 570.332 | CN33: =SUM(BC33:BF33) -> 2974.5 | CO33: =SUM(BG33:BJ33) -> 3047.3
B35: U.S. Revenues Growth Y/y | BG35: =BG30/BC30-1 -> 0.010534929 | BH35: =BH30/BD30-1 -> 0.013428518 | BI35: =BI30/BE30-1 -> 0.010548172 | BJ35: =BJ30/BF30-1 -> 0.014126132 | BK35: =BK30/BG30-1 -> -0.037044534 | BL35: =BL30/BH30-1 -> 0.019588829 | BM35: =BM30/BI30-1 -> 0.077534406 | BN35: =BN30/BJ30-1 -> -1.5142437 | ... BP35: =BP30/BL30-1 -> -0.33643142 | CO35: =CO30/CN30-1 -> 0.012197512
B36: EMEA Revenues Growth Y/y | BG36: =BG31/BC31-1 -> 0.11343658 | BH36: =BH31/BD31-1 -> -0.0047967309 | BI36: =BI31/BE31-1 -> 0.052528324 | BJ36: =BJ31/BF31-1 -> 0.057454966 | BK36: =BK31/BG31-1 -> -0.052631579 | BL36: =BL31/BH31-1 -> 0.12984364 | BM36: =BM31/BI31-1 -> 0.55931301 | BN36: =BN31/BJ31-1 -> -1.4918612 | ... BP36: =BP31/BL31-1 -> -0.12436221 | CO36: =CO31/CN31-1 -> 0.054247697
B37: Asia Revenues Growth Y/y | BG37: =BG32/BC32-1 -> 0.069464379 | BH37: =BH32/BD32-1 -> 0.0037148988 | BI37: =BI32/BE32-1 -> 0.054846432 | BJ37: =BJ32/BF32-1 -> 0.058863482 | BK37: =BK32/BG32-1 -> -0.12351544 | BL37: =BL32/BH32-1 -> 0.022988506 | BM37: =BM32/BI32-1 -> 0.25045797 | BN37: =BN32/BJ32-1 -> -1.4764272 | ... BP37: =BP32/BL32-1 -> -0.14648315 | CO37: =CO32/CN32-1 -> 0.046411069
B38: Ttl Revenues Growth Y/y | BG38: =BG33/BC33-1 -> 0.037808702 | BH38: =BH33/BD33-1 -> 0.0086713174 | BI38: =BI33/BE33-1 -> 0.024104053 | BJ38: =BJ33/BF33-1 -> 0.027760729 | BK38: =BK33/BG33-1 -> -0.05028463 | BL38: =BL33/BH33-1 -> 0.041616647 | BM38: =BM33/BI33-1 -> 0.19444517 | BN38: =BN33/BJ33-1 -> -1.5052639 | ... BP38: =BP33/BL33-1 -> -0.26964784 | CO38: =CO33/CN33-1 -> 0.024474702
B40: U.S. Revenues % of Revenues | BC40: =BC30/BC33 -> 0.68762915 | BD40: =BD30/BD33 -> 0.68451339 | BE40: =BE30/BE33 -> 0.6839798 | BF40: =BF30/BF33 -> 0.68903332 | BG40: =BG30/BG33 -> 0.66955815 | BH40: =BH30/BH33 -> 0.68774176 | BI40: =BI30/BI33 -> 0.67492608 | BJ40: =BJ30/BJ33 -> 0.67989238 | ... BP40: =BP30/BP33 -> 0.61164024 | CN40: =CN30/CN33 -> 0.68630022 | CO40: =CO30/CO33 -> 0.67807567
B41: EMEA Revenues % of Revenues | BC41: =BC31/BC33 -> 0.20162578 | BD41: =BD31/BD33 -> 0.19886715 | BE41: =BE31/BE33 -> 0.19121798 | BF41: =BF31/BF33 -> 0.19682273 | BG41: =BG31/BG33 -> 0.21631879 | BH41: =BH31/BH33 -> 0.19621182 | BI41: =BI31/BI33 -> 0.19652529 | BJ41: =BJ31/BJ33 -> 0.20250937 | ... BP41: =BP31/BP33 -> 0.25516892 | CN41: =CN31/CN33 -> 0.19707514 | CO41: =CO31/CO33 -> 0.20280248
B42: Asia Revenues % of Revenues | BC42: =BC32/BC33 -> 0.11074508 | BD42: =BD32/BD33 -> 0.11661946 | BE42: =BE32/BE33 -> 0.12480221 | BF42: =BF32/BF33 -> 0.11414395 | BG42: =BG32/BG33 -> 0.11412307 | BH42: =BH32/BH33 -> 0.11604642 | BI42: =BI32/BI33 -> 0.12854863 | BJ42: =BJ32/BJ33 -> 0.11759825 | ... BP42: =BP32/BP33 -> 0.13319084 | CN42: =CN32/CN33 -> 0.11662464 | CO42: =CO32/CO33 -> 0.11912185
B44: Revenues | C44: 367.3 | D44: 358.4 | E44: 345 | F44: 326.9 | G44: 354 | H44: 381.2 | I44: 362.7 | J44: 394.6 | K44: 380.6 | L44: 383.3 | M44: 368.1 | N44: 419.1 | O44: 411.9 | P44: 420.1 | Q44: 413.8 | R44: 450.5 | S44: 438.5 | T44: 468.1 | U44: 457.2 | V44: 476 | W44: 429.4 | X44: 452 | Y44: 443.7 | Z44: 484.5 | AA44: 424.9 | AB44: 473.6 | AC44: 455.6 | AD44: 513.9 | AE44: 487.9 | AF44: 528.6 | AG44: 534.7 | AH44: 595.1 | AI44: 587.2 | AJ44: 609.9 | AK44: 609.7 | AL44: 641.6 | AM44: 613.6 | AN44: 652.5 | AO44: 648.3 | AP44: 681 | AQ44: =AQ11 -> 630.621 | AR44: =AR11 -> 567.03 | AS44: =AS11 -> 628.279 | AT44: =AT11 -> 651.715 | AU44: =AU11 -> 633.902 | AV44: =AV11 -> 713.44 | AW44: =AW11 -> 700.231 | AX44: =AX11 -> 761.983 | ... BM44: =BM11 -> 912.99 | BN44: 500 | BO44: =BO33 -> 548.261 | BP44: =BP33 -> 570.332 | CA44: =SUM(C44:F44) -> 1397.6 | CB44: =SUM(G44:J44) -> 1492.5 | CC44: =SUM(K44:N44) -> 1551.1 | CD44: =SUM(O44:R44) -> 1696.3 | CE44: =SUM(S44:V44) -> 1839.8 | CF44: =SUM(W44:Z44) -> 1809.6 | CG44: =SUM(AA44:AD44) -> 1868 | CH44: =SUM(AE44:AH44) -> 2146.3 | CI44: =SUM(AI44:AL44) -> 2448.4 | CJ44: =SUM(AM44:AP44) -> 2595.4 | CK44: =SUM(AQ44:AT44) -> 2477.645 | CL44: =SUM(AU44:AX44) -> 2809.556 | CM44: =SUM(AY44:BB44) -> 2791.024 | CN44: =SUM(BC44:BF44) -> 2974.485 | CO44: =SUM(BG44:BJ44) -> 3047.304 | CP44: =CP11 -> 3236.9264 | CQ44: =CQ11 -> 2463.0079 | CR44: =CR11 -> 2696.2606 | CS44: =CS11 -> 2914.7098 | CT44: =CT11 -> 3113.7555 | CU44: =CU11 -> 3299.1319 | CV44: =CV11 -> 3479.434 | CW44: =CW11 -> 3651.5128 | ... CY44: =CY11 -> 3963.7036
B45: COGS | C45: 190.4 | D45: 184.1 | E45: 178.5 | F45: 165.8 | G45: 189.5 | H45: 199.8 | I45: 187.1 | J45: 207.3 | K45: 196.5 | L45: 199 | M45: 187.5 | N45: 219.9 | O45: 211.4 | P45: 210.6 | Q45: 209.8 | R45: 225.6 | S45: 217.4 | T45: 224 | U45: 221 | V45: 235 | W45: 206.8 | X45: 218.8 | Y45: 215.5 | Z45: 224.2 | AA45: 199.7 | AB45: 217.2 | AC45: 214 | AD45: 240.9 | AE45: 232.3 | AF45: 238.3 | AG45: 239.5 | AH45: 264.4 | AI45: 256 | AJ45: 265.1 | AK45: 267.1 | AL45: 357.4 | AM45: 289.6 | AN45: 300.3 | AO45: 293.2 | AP45: 303.2 | AQ45: 297.018 | AR45: 288.66 | AS45: 298.977 | AT45: =1212.28-SUM(AQ45:AS45) -> 327.625 | AU45: 289.398 | AV45: 315.917 | AW45: 312.464 | AX45: =1259.961-SUM(AU45:AW45) -> 342.182 | AY45: 295.48 | AZ45: 315.709 | BA45: 312.833 | BB45: =1259.95-SUM(AY45:BA45) -> 335.928 | BC45: 319.55 | BD45: 335.436 | BE45: 330.07 | BF45: =1327.55-SUM(BC45:BE45) -> 342.494 | BG45: 321.715 | BH45: 333.23 | BI45: 334.203 | BJ45: =1344.64-SUM(BG45:BI45) -> 355.492 | BK45: 311.23 | BL45: 349.804 | BM45: 461.37 | BN45: 225 | BO45: 240.836 | BP45: 238.625 | CA45: =SUM(C45:F45) -> 718.8 | CB45: =SUM(G45:J45) -> 783.7 | CC45: =SUM(K45:N45) -> 802.9 | CD45: =SUM(O45:R45) -> 857.4 | CE45: =SUM(S45:V45) -> 897.4 | CF45: =SUM(W45:Z45) -> 865.3 | CG45: =SUM(AA45:AD45) -> 871.8 | CH45: =SUM(AE45:AH45) -> 974.5 | CI45: =SUM(AI45:AL45) -> 1145.6 | CJ45: =SUM(AM45:AP45) -> 1186.3 | CK45: =SUM(AQ45:AT45) -> 1212.28 | CL45: =SUM(AU45:AX45) -> 1259.961 | CM45: =SUM(AY45:BB45) -> 1259.95 | CN45: =SUM(BC45:BF45) -> 1327.55 | CO45: =SUM(BG45:BJ45) -> 1344.64 | CP45: =CP44*(1-CP63) -> 1424.2476 | CQ45: =CQ44*(1-CQ63) -> 1077.566 | CR45: =CR44*(1-CR63) -> 1172.8734 | CS45: =CS44*(1-CS63) -> 1267.8988 | CT45: =CT44*(1-CT63) -> 1354.4837 | CU45: =CU44*(1-CU63) -> 1435.1224 | CV45: =CV44*(1-CV63) -> 1513.5538 | CW45: =CW44*(1-CW63) -> 1588.4081 | ... CY45: =CY44*(1-CY63) -> 1724.2111
B46: GP | C46: =C44-C45 -> 176.9 | D46: =D44-D45 -> 174.3 | E46: =E44-E45 -> 166.5 | F46: =F44-F45 -> 161.1 | G46: =G44-G45 -> 164.5 | H46: =H44-H45 -> 181.4 | I46: =I44-I45 -> 175.6 | J46: =J44-J45 -> 187.3 | ... BP46: =BP44-BP45 -> 331.707 | CA46: =SUM(C46:F46) -> 678.8 | CB46: =SUM(G46:J46) -> 708.8 | CC46: =SUM(K46:N46) -> 748.2 | CD46: =SUM(O46:R46) -> 838.9 | CE46: =SUM(S46:V46) -> 942.4 | CF46: =SUM(W46:Z46) -> 944.3 | CG46: =SUM(AA46:AD46) -> 996.2 | CH46: =SUM(AE46:AH46) -> 1171.8 | CI46: =SUM(AI46:AL46) -> 1302.8 | CJ46: =SUM(AM46:AP46) -> 1409.1 | CK46: =SUM(AQ46:AT46) -> 1265.365 | CL46: =SUM(AU46:AX46) -> 1549.595 | CM46: =SUM(AY46:BB46) -> 1531.074 | CN46: =SUM(BC46:BF46) -> 1646.935 | CO46: =SUM(BG46:BJ46) -> 1702.664 | CP46: =CP44-CP45 -> 1812.6788 | CQ46: =CQ44-CQ45 -> 1385.442 | CR46: =CR44-CR45 -> 1523.3873 | CS46: =CS44-CS45 -> 1646.811 | CT46: =CT44-CT45 -> 1759.2719 | CU46: =CU44-CU45 -> 1864.0095 | CV46: =CV44-CV45 -> 1965.8802 | CW46: =CW44-CW45 -> 2063.1047 | ... CY46: =CY44-CY45 -> 2239.4925
...

Sheet Notes | Quant Analysis
CA1: 0
H2: Employee Scope: | AC2: Teleflex Q2'25 Earnings Scope
I30: Notes: | J30: [X]
J31: [Y]
J32: [Z]
H34: Institutional Ownership Snapshot (7/30/2025) | AC34: General Notes/Observations (Updated Q1'25)
AD35: Acquisition of BIOTRONIK Vascular Intervention business
AE36: On February 24, 2025, Managers executed a definitive agreement to acquire substantially all of the Vascular Intervention business (the “VI Business”) of BIOTRONIK SE & Co. KG ("BIOTRONIK")
AF37: The acquisition will include a broad suite of coronary and peripheral medical devices, such as drug-coated balloons, stents, and balloon catheters, which will complement our interventional product portfolio
AF38: Under the terms of the agreement, we will acquire the VI Business for an initial cash payment of €760 million reduced by certain adjustments as provided in the purchase agreement including certain working capital not transferring and other customary adjustments
AF39: The acquisition is subject to customary closing conditions, including receipt of certain regulatory approvals, and is expected to be completed in the third quarter of 2025
