Workbook

Sheet Main
A1: Master
B2: TMO
B3: Price | C3: 694.02 | D3: 10/21/2026
B4: SO | C4: 370 | D4: Q3'26
B5: MC | C5: =C3*C4 -> 256787.4
B6: Cash | C6: =5461+600 -> 6061 | D6: Q3'26
B7: Debt | C7: =2262+39108 -> 41370 | D7: Q3'26
B8: EV | C8: =C5-C6+C7 -> 292096.4
B10: Thermo Fisher Scientific, Inc. | N10: Resources:
N11: SEC filings | Q11: https://www.sec.gov/edgar/browse/?CIK=97745&owner=exclude
B12: Founder(s): George Hatsopoulos & Peter Nomikos | F12: Registered Exchange: NYSE | N12: Thermofisher Homepage | Q12: https://www.thermofisher.com/us/en/home.html
B13: Founded: 1956 | F13: Address: 168 THIRD AVENUE, WALTHAM, MA, 02451 | O13: TMO IR page | R13: https://ir.thermofisher.com/investors/overview/default.aspx
B14: Headquarters: Waltham, Massachusetts | F14: Investor Relations Contact: | N14: FDA Med Device Reporting's | Q14: https://www.fda.gov/medical-devices
B15: Current CEO: Marc Casper | F15: Investors Relation Department | N15: U.S. Patent Office Search | Q15: https://ppubs.uspto.gov/pubThe Companybapp/static/pages/ppubsbasic.html
B16: Employees: 125,000 | F16: Phone: | G16: (781) 622 - 1000 | I16: Email: | J16: BSXInvestorRelations@bsci.com | N16: MedTech News | Q16: https://www.medtechdive.com/
B17: Sector: Healthcare | N17: Earnings Calls | Q17: https://seekingalpha.com/symbol/BSX/earnings/transcripts
B18: Industry: Medical Devices | N18: Equity Analysis | Q18: https://stockanalysis.com/stocks/tmo/company/
B19: IPO: May 19, 1992 -- $1.6B valuation | N19: MacroTrends | Q19: https://www.macrotrends.net/stocks/charts/BSX/boston-scientific/income-statement?freq=Q
B20: Fiscal Year: [January - December] | N20: ROIC, WACC | Q20: https://www.gurufocus.com/term/wacc/BSX
N21: Godel Terminal | Q21: https://app.godelterminal.com/
A23: Company Overview:
B24: Thermo Fisher Scientific is a life sciences and lab equipment maker that sells scientific instruments, reagents, consumables, and software. It also provides contract drug development, manufacturing, and clinical research services
C25: Brands include Thermo Scientific, Applied Biosystems, Invitrogen, Fisher Scientific, Patheon, and PPD in the North America, Europe, Asia-Pacific, and internationally
B26: The Company’s Life Sciences Solutions segment offers reagents, instruments, and consumables for biological and medical research, discovery and production of drugs and vaccines, as well as diagnosis of infections and diseases
B27: Its Analytical Instruments segment provides instruments, consumables, software, and services for pharmaceutical, biotechnology, academic, government, environmental, and other research and industrial markets, as well as clinical laboratories
B28: The Company’s Specialty Diagnostics segment includes clinical diagnostics offering liquid, ready-to-use, and lyophilized immunodiagnostic reagent kits, as well as calibrators, controls, protein detection assays, and instruments
C29: immunodiagnostics offers develops, manufactures, and markets complete blood test systems to support the clinical diagnosis and monitoring of allergy, asthma, and autoimmune diseases
C30: microbiology offers dehydrated and prepared culture media, collection and transport systems, instrumentation, and consumables; transplant diagnostics products include human leukocyte antigen typing and testing for organ transplant market
C31: healthcare market channel offers consumables, diagnostic kits and reagents, equipment, instruments, solutions, and services
B32: Laboratory Products and Biopharma Services segment provides laboratory products, research and safety market channel, and pharma services and clinical research
B33: The Company offers products and services through a direct sales force, customer-service professionals, electronic commerce, and third-party distributors under Thermo Scientific; Applied Biosystems; Invitrogen; Fisher Scientific; Unity Lab Services; and Patheon and PPD
B34: Thermo Fisher Scientific Inc. was founded in 1956 and is headquartered in Waltham, Massachusetts
A36: Business Segments and Geographical Info:

Sheet Model
B1: [Use for Graphing] | AQ1: Q1 2020 | AU1: Q1 2021 | AY1: Q1 2022 | BC1: Q1 2023 | BG1: Q1 2024 | BK1: Q1 2025 | BO1: Q1 2026
B2: Quarterly
B3: Revenues | C3: {="Q"&MOD(_xlfn.SEQUENCE(1,68)-1,4)+1&" "&(2010+INT((_xlfn.SEQUENCE(1,68)-1)/4))} -> Q1 2010 | D3: Q2 2010 | E3: Q3 2010 | F3: Q4 2010 | G3: Q1 2011 | H3: Q2 2011 | I3: Q3 2011 | J3: Q4 2011 | K3: Q1 2012 | L3: Q2 2012 | M3: Q3 2012 | N3: Q4 2012 | O3: Q1 2013 | P3: Q2 2013 | Q3: Q3 2013 | R3: Q4 2013 | S3: Q1 2014 | T3: Q2 2014 | U3: Q3 2014 | V3: Q4 2014 | W3: Q1 2015 | X3: Q2 2015 | Y3: Q3 2015 | Z3: Q4 2015 | AA3: Q1 2016 | AB3: Q2 2016 | AC3: Q3 2016 | AD3: Q4 2016 | AE3: Q1 2017 | AF3: Q2 2017 | AG3: Q3 2017 | AH3: Q4 2017 | AI3: Q1 2018 | AJ3: Q2 2018 | AK3: Q3 2018 | AL3: Q4 2018 | AM3: Q1 2019 | AN3: Q2 2019 | AO3: Q3 2019 | AP3: Q4 2019 | AQ3: Q1 2020 | AR3: Q2 2020 | AS3: Q3 2020 | AT3: Q4 2020 | AU3: Q1 2021 | AV3: Q2 2021 | AW3: Q3 2021 | AX3: Q4 2021 | AY3: Q1 2022 | AZ3: Q2 2022 | BA3: Q3 2022 | BB3: Q4 2022 | BC3: Q1 2023 | BD3: Q2 2023 | BE3: Q3 2023 | BF3: Q4 2023 | BG3: Q1 2024 | BH3: Q2 2024 | BI3: Q3 2024 | BJ3: Q4 2024 | BK3: Q1 2025 | BL3: Q2 2025 | BM3: Q3 2025 | BN3: Q4 2025 | BO3: Q1 2026 | BP3: Q2 2026 | BQ3: Q3 2026 | BR3: Q4 2026 | CA3: 2010 | CB3: =CA3+1 -> 2011 | CC3: =CB3+1 -> 2012 | CD3: =CC3+1 -> 2013 | CE3: =CD3+1 -> 2014 | CF3: =CE3+1 -> 2015 | CG3: =CF3+1 -> 2016 | CH3: =CG3+1 -> 2017 | CI3: =CH3+1 -> 2018 | ... EX3: =EW3+1 -> 2085
B4: Consumables | AU4: 5964 | AV4: 5372 | AW4: 5544 | AX4: =22608-SUM(AU4:AW4) -> 5728 | AY4: 6110 | AZ4: 4993 | BA4: 4651 | BB4: =20624-SUM(AY4:BA4) -> 4870 | BC4: 4506 | BD4: 4433 | BE4: 4289 | BF4: =17597-SUM(BC4:BE4) -> 4369 | BG4: 4328 | BH4: 4363 | BI4: 4379 | BJ4: =17587-SUM(BG4:BI4) -> 4517 | BK4: 4354 | BL4: 4606 | BM4: 4679 | BN4: =18664-SUM(BK4:BM4) -> 5025 | BO4: 4722 | BP4: 5073 | BQ4: 5132 | CL4: =SUM(AU4:AX4) -> 22608 | CM4: =SUM(AY4:BB4) -> 20624 | CN4: =SUM(BC4:BF4) -> 17597 | CO4: =SUM(BG4:BJ4) -> 17587 | CP4: =SUM(BK4:BN4) -> 18664 | CQ4: =CP4*(1+CQ9) -> 20390.42 | CR4: =CQ4*(1+CR9) -> 22327.51 | CS4: =CR4*(1+CS9) -> 24381.641 | CT4: =CS4*(1+CT9) -> 26454.08 | CU4: =CT4*(1+CU9) -> 28570.407 | CV4: =CU4*(1+CV9) -> 30713.187 | CW4: =CV4*(1+CW9) -> 32709.544 | CX4: =CW4*(1+CX9) -> 34672.117 | ... CZ4: =CY4*(1+CZ9) -> 38408.038
B5: Instruments | AU5: 1892 | AV5: 1842 | AW5: 1816 | AX5: =7753-SUM(AU5:AW5) -> 2203 | AY5: 1907 | AZ5: 2010 | BA5: 1932 | BB5: =7924-SUM(AY5:BA5) -> 2075 | BC5: 1898 | BD5: 1838 | BE5: 1868 | BF5: =7646-SUM(BC5:BE5) -> 2042 | BG5: 1627 | BH5: 1800 | BI5: 1769 | BJ5: =7446-SUM(BG5:BI5) -> 2250 | BK5: 1626 | BL5: 1644 | BM5: 1811 | BN5: =7301-SUM(BK5:BM5) -> 2220 | BO5: 1555 | BP5: 1750 | BQ5: 1840 | CL5: =SUM(AU5:AX5) -> 7753 | CM5: =SUM(AY5:BB5) -> 7924 | CN5: =SUM(BC5:BF5) -> 7646 | CO5: =SUM(BG5:BJ5) -> 7446 | CP5: =SUM(BK5:BN5) -> 7301 | CQ5: =CP5*(1+CQ10) -> 7483.525 | CR5: =CQ5*(1+CR10) -> 7708.0307 | CS5: =CR5*(1+CS10) -> 8016.352 | CT5: =CS5*(1+CT10) -> 8296.9243 | CU5: =CT5*(1+CU10) -> 8545.832 | CV5: =CU5*(1+CV10) -> 8759.4778 | CW5: =CV5*(1+CW10) -> 8956.5661 | CX5: =CW5*(1+CX10) -> 9135.6974 | ... CZ5: =CY5*(1+CZ10) -> 9435.0057
B6: Services | AU6: 2050 | AV6: 2059 | AW6: 1970 | AX6: =8850-SUM(AU6:AW6) -> 2771 | AY6: 3801 | AZ6: 3967 | BA6: 4094 | BB6: =16367-SUM(AY6:BA6) -> 4505 | BC6: 4306 | BD6: 4416 | BE6: 4417 | BF6: =17614-SUM(BC6:BE6) -> 4475 | BG6: 4390 | BH6: 4378 | BI6: 4450 | BJ6: =17845-SUM(BG6:BI6) -> 4627 | BK6: 4384 | BL6: 4605 | BM6: 4633 | BN6: =18592-SUM(BK6:BM6) -> 4970 | BO6: 4728 | BP6: 5171 | BQ6: 5165 | CL6: =SUM(AU6:AX6) -> 8850 | CM6: =SUM(AY6:BB6) -> 16367 | CN6: =SUM(BC6:BF6) -> 17614 | CO6: =SUM(BG6:BJ6) -> 17845 | CP6: =SUM(BK6:BN6) -> 18592 | CQ6: =CP6*(1+CQ11) -> 20404.72 | CR6: =CQ6*(1+CR11) -> 22853.286 | CS6: =CR6*(1+CS11) -> 25824.214 | CT6: =CS6*(1+CT11) -> 28664.877 | CU6: =CT6*(1+CU11) -> 31531.365 | CV6: =CU6*(1+CV11) -> 34369.188 | CW6: =CV6*(1+CW11) -> 37118.723 | CX6: =CW6*(1+CX11) -> 39717.033 | ... CZ6: =CY6*(1+CZ11) -> 44415.558
B7: Ttl Revenue | AU7: =SUM(AU4:AU6) -> 9906 | AV7: =SUM(AV4:AV6) -> 9273 | AW7: =SUM(AW4:AW6) -> 9330 | AX7: =SUM(AX4:AX6) -> 10702 | AY7: =SUM(AY4:AY6) -> 11818 | AZ7: =SUM(AZ4:AZ6) -> 10970 | BA7: =SUM(BA4:BA6) -> 10677 | BB7: =SUM(BB4:BB6) -> 11450 | ... BQ7: =SUM(BQ4:BQ6) -> 12137 | CL7: =SUM(AU7:AX7) -> 39211 | CM7: =SUM(AY7:BB7) -> 44915 | CN7: =SUM(BC7:BF7) -> 42857 | CO7: =SUM(BG7:BJ7) -> 42878 | CP7: =SUM(BK7:BN7) -> 44557 | CQ7: =SUM(CQ4:CQ6) -> 48278.665 | CR7: =SUM(CR4:CR6) -> 52888.827 | CS7: =SUM(CS4:CS6) -> 58222.206 | CT7: =SUM(CT4:CT6) -> 63415.882 | CU7: =SUM(CU4:CU6) -> 68647.604 | CV7: =SUM(CV4:CV6) -> 73841.853 | CW7: =SUM(CW4:CW6) -> 78784.833 | CX7: =SUM(CX4:CX6) -> 83524.848 | ... CZ7: =SUM(CZ4:CZ6) -> 92258.602
B9: Consumables Growth Y/y | AX9: =AX4/AT4-1 -> #DIV/0! | AY9: =AY4/AU4-1 -> 0.024480215 | AZ9: =AZ4/AV4-1 -> -0.070551005 | BA9: =BA4/AW4-1 -> -0.16107504 | BB9: =BB4/AX4-1 -> -0.1497905 | BC9: =BC4/AY4-1 -> -0.26252046 | BD9: =BD4/AZ4-1 -> -0.11215702 | BE9: =BE4/BA4-1 -> -0.077832724 | ... BQ9: =BQ4/BM4-1 -> 0.096815559 | CM9: =CM4/CL4-1 -> -0.087756546 | CN9: =CN4/CM4-1 -> -0.14677075 | CO9: =CO4/CN4-1 -> -0.00056827868 | CP9: =CP4/CO4-1 -> 0.061238415 | CQ9: 0.0925 | CR9: 0.095 | CS9: 0.092 | CT9: 0.085 | CU9: 0.08 | CV9: 0.075 | CW9: 0.065 | CX9: 0.06 | CY9: 0.055 | CZ9: 0.05
B10: Instruments Growth Y/y | AX10: =AX5/AT5-1 -> #DIV/0! | AY10: =AY5/AU5-1 -> 0.0079281184 | AZ10: =AZ5/AV5-1 -> 0.091205212 | BA10: =BA5/AW5-1 -> 0.063876652 | BB10: =BB5/AX5-1 -> -0.058102587 | BC10: =BC5/AY5-1 -> -0.0047194546 | BD10: =BD5/AZ5-1 -> -0.085572139 | BE10: =BE5/BA5-1 -> -0.033126294 | ... BQ10: =BQ5/BM5-1 -> 0.016013252 | CM10: =CM5/CL5-1 -> 0.022055978 | CN10: =CN5/CM5-1 -> -0.035083291 | CO10: =CO5/CN5-1 -> -0.026157468 | CP10: =CP5/CO5-1 -> -0.019473543 | CQ10: 0.025 | CR10: 0.03 | CS10: 0.04 | CT10: 0.035 | CU10: 0.03 | CV10: 0.025 | CW10: 0.0225 | CX10: 0.02 | CY10: 0.0175 | CZ10: 0.015
B11: Services Growth Y/y | AX11: =AX6/AT6-1 -> #DIV/0! | AY11: =AY6/AU6-1 -> 0.85414634 | AZ11: =AZ6/AV6-1 -> 0.92666343 | BA11: =BA6/AW6-1 -> 1.0781726 | BB11: =BB6/AX6-1 -> 0.62576687 | BC11: =BC6/AY6-1 -> 0.13285977 | BD11: =BD6/AZ6-1 -> 0.11318377 | BE11: =BE6/BA6-1 -> 0.078895945 | ... BQ11: =BQ6/BM6-1 -> 0.1148284 | CM11: =CM6/CL6-1 -> 0.84937853 | CN11: =CN6/CM6-1 -> 0.076189894 | CO11: =CO6/CN6-1 -> 0.013114568 | CP11: =CP6/CO6-1 -> 0.041860465 | CQ11: 0.0975 | CR11: 0.12 | CS11: 0.13 | CT11: 0.11 | CU11: 0.1 | CV11: 0.09 | CW11: 0.08 | CX11: 0.07 | CY11: 0.06 | CZ11: 0.055
B12: Ttl Revenue Growth Y/y | AX12: =AX7/AT7-1 -> #DIV/0! | AY12: =AY7/AU7-1 -> 0.19301433 | AZ12: =AZ7/AV7-1 -> 0.18300442 | BA12: =BA7/AW7-1 -> 0.14437299 | BB12: =BB7/AX7-1 -> 0.069893478 | BC12: =BC7/AY7-1 -> -0.093755289 | BD12: =BD7/AZ7-1 -> -0.02579763 | BE12: =BE7/BA7-1 -> -0.0096469046 | ... BQ12: =BQ7/BM7-1 -> 0.091162456 | CM12: =CM7/CL7-1 -> 0.14546938 | CN12: =CN7/CM7-1 -> -0.045819882 | CO12: =CO7/CN7-1 -> 0.00049000163 | CP12: =CP7/CO7-1 -> 0.03915761 | CQ12: =CQ7/CP7-1 -> 0.083525933 | CR12: =CR7/CQ7-1 -> 0.09549067 | CS12: =CS7/CR7-1 -> 0.10084132 | CT12: =CT7/CS7-1 -> 0.089204371 | ... CZ12: =CZ7/CY7-1 -> 0.048694571
B14: Consumables % of Ttl Revenues | AU14: =AU4/AU7 -> 0.60205936 | AV14: =AV4/AV7 -> 0.57931629 | AW14: =AW4/AW7 -> 0.59421222 | AX14: =AX4/AX7 -> 0.53522706 | AY14: =AY4/AY7 -> 0.51700795 | AZ14: =AZ4/AZ7 -> 0.45515041 | BA14: =BA4/BA7 -> 0.43560925 | BB14: =BB4/BB7 -> 0.42532751 | ... BQ14: =BQ4/BQ7 -> 0.42283925 | CL14: =CL4/CL7 -> 0.5765729 | CM14: =CM4/CM7 -> 0.45917845 | CN14: =CN4/CN7 -> 0.41059804 | CO14: =CO4/CO7 -> 0.41016372 | CP14: =CP4/CP7 -> 0.41887919
B15: Instruments % of Ttl Revenues | AU15: =AU5/AU7 -> 0.19099536 | AV15: =AV5/AV7 -> 0.19864122 | AW15: =AW5/AW7 -> 0.19464094 | AX15: =AX5/AX7 -> 0.20584937 | AY15: =AY5/AY7 -> 0.16136402 | AZ15: =AZ5/AZ7 -> 0.18322698 | BA15: =BA5/BA7 -> 0.1809497 | BB15: =BB5/BB7 -> 0.18122271 | ... BQ15: =BQ5/BQ7 -> 0.15160254 | CL15: =CL5/CL7 -> 0.19772513 | CM15: =CM5/CM7 -> 0.17642213 | CN15: =CN5/CN7 -> 0.17840726 | CO15: =CO5/CO7 -> 0.17365549 | CP15: =CP5/CP7 -> 0.16385753
B16: Services % of Ttl Revenues | AU16: =AU6/AU7 -> 0.20694529 | AV16: =AV6/AV7 -> 0.22204249 | AW16: =AW6/AW7 -> 0.21114684 | AX16: =AX6/AX7 -> 0.25892357 | AY16: =AY6/AY7 -> 0.32162803 | AZ16: =AZ6/AZ7 -> 0.36162261 | BA16: =BA6/BA7 -> 0.38344104 | BB16: =BB6/BB7 -> 0.39344978 | ... BQ16: =BQ6/BQ7 -> 0.42555821 | CL16: =CL6/CL7 -> 0.22570197 | CM16: =CM6/CM7 -> 0.36439942 | CN16: =CN6/CN7 -> 0.4109947 | CO16: =CO6/CO7 -> 0.41618079 | CP16: =CP6/CP7 -> 0.41726328
B18: U.S. | AU18: 5101 | AV18: 4529 | AW18: 4662 | AX18: =19659-SUM(AU18:AW18) -> 5367 | AY18: 6323 | AZ18: 6032 | BA18: 5962 | BB18: =24594-SUM(AY18:BA18) -> 6277 | BC18: 5778 | BD18: 5714 | BE18: 5668 | BF18: =22764-SUM(BC18:BE18) -> 5604 | BG18: 5519 | BH18: 5529 | BI18: 5591 | BJ18: =22504-SUM(BG18:BI18) -> 5865 | BK18: 5513 | BL18: 5722 | BM18: 5689 | BN18: =23033-SUM(BK18:BM18) -> 6109 | BO18: 5705 | BP18: 6149 | CL18: =SUM(AU18:AX18) -> 19659 | CM18: =SUM(AY18:BB18) -> 24594 | CN18: =SUM(BC18:BF18) -> 22764 | CO18: =SUM(BG18:BJ18) -> 22504 | CP18: =SUM(BK18:BN18) -> 23033
B19: Euro | AU19: 2785 | AV19: 2695 | AW19: 2557 | AX19: =11134-SUM(AU19:AW19) -> 3097 | AY19: 3050 | AZ19: 2551 | BA19: 2406 | BB19: =10762-SUM(AY19:BA19) -> 2755 | BC19: 2601 | BD19: 2654 | BE19: 2643 | BF19: =10741-SUM(BC19:BE19) -> 2843 | BG19: 2619 | BH19: 2663 | BI19: 2686 | BJ19: =10857-SUM(BG19:BI19) -> 2889 | BK19: 2624 | BL19: 2830 | BM19: 3005 | BN19: =11826-SUM(BK19:BM19) -> 3367 | BO19: 2957 | BP19: 3311 | CL19: =SUM(AU19:AX19) -> 11134 | CM19: =SUM(AY19:BB19) -> 10762 | CN19: =SUM(BC19:BF19) -> 10741 | CO19: =SUM(BG19:BJ19) -> 10857 | CP19: =SUM(BK19:BN19) -> 11826
B20: APAC | AU20: 1709 | AV20: 1749 | AW20: 1836 | AX20: =7218-SUM(AU20:AW20) -> 1924 | AY20: 2064 | AZ20: 2042 | BA20: 1971 | BB20: =8115-SUM(AY20:BA20) -> 2038 | BC20: 1986 | BD20: 1902 | BE20: 1913 | BF20: =7873-SUM(BC20:BE20) -> 2072 | BG20: 1861 | BH20: 1971 | BI20: 1923 | BJ20: =7956-SUM(BG20:BI20) -> 2201 | BK20: 1891 | BL20: 1920 | BM20: 2013 | BN20: =8101-SUM(BK20:BM20) -> 2277 | BO20: 1970 | BP20: 2104 | CL20: =SUM(AU20:AX20) -> 7218 | CM20: =SUM(AY20:BB20) -> 8115 | CN20: =SUM(BC20:BF20) -> 7873 | CO20: =SUM(BG20:BJ20) -> 7956 | CP20: =SUM(BK20:BN20) -> 8101
B21: Other Regions | AU21: 311 | AV21: 300 | AW21: 275 | AX21: =1200-SUM(AU21:AW21) -> 314 | AY21: 381 | AZ21: 345 | BA21: 338 | BB21: =1444-SUM(AY21:BA21) -> 380 | BC21: 345 | BD21: 417 | BE21: 350 | BF21: =1479-SUM(BC21:BE21) -> 367 | BG21: 346 | BH21: 379 | BI21: 397 | BJ21: =1561-SUM(BG21:BI21) -> 439 | BK21: 336 | BL21: 383 | BM21: 415 | BN21: =1597-SUM(BK21:BM21) -> 463 | BO21: 373 | BP21: 430 | BQ21: 12137 | CL21: =SUM(AU21:AX21) -> 1200 | CM21: =SUM(AY21:BB21) -> 1444 | CN21: =SUM(BC21:BF21) -> 1479 | CO21: =SUM(BG21:BJ21) -> 1561 | CP21: =SUM(BK21:BN21) -> 1597
B22: Ttl Revenue | AU22: =SUM(AU18:AU21) -> 9906 | AV22: =SUM(AV18:AV21) -> 9273 | AW22: =SUM(AW18:AW21) -> 9330 | AX22: =SUM(AX18:AX21) -> 10702 | AY22: =SUM(AY18:AY21) -> 11818 | AZ22: =SUM(AZ18:AZ21) -> 10970 | BA22: =SUM(BA18:BA21) -> 10677 | BB22: =SUM(BB18:BB21) -> 11450 | ... BQ22: =SUM(BQ18:BQ21) -> 12137 | CL22: =SUM(AU22:AX22) -> 39211 | CM22: =SUM(AY22:BB22) -> 44915 | CN22: =SUM(BC22:BF22) -> 42857 | CO22: =SUM(BG22:BJ22) -> 42878 | CP22: =SUM(BK22:BN22) -> 44557
B24: U.S. Growth Y/y | AY24: =AY18/AU18-1 -> 0.23956087 | AZ24: =AZ18/AV18-1 -> 0.33186134 | BA24: =BA18/AW18-1 -> 0.27885028 | BB24: =BB18/AX18-1 -> 0.16955469 | BC24: =BC18/AY18-1 -> -0.086193263 | BD24: =BD18/AZ18-1 -> -0.052718833 | BE24: =BE18/BA18-1 -> -0.049312311 | BF24: =BF18/BB18-1 -> -0.10721682 | ... BQ24: =BQ18/BM18-1 -> -1 | CM24: =CM18/CL18-1 -> 0.25103006 | CN24: =CN18/CM18-1 -> -0.074408392 | CO24: =CO18/CN18-1 -> -0.011421543 | CP24: =CP18/CO18-1 -> 0.023506932
B25: Euro Growth Y/y | AY25: =AY19/AU19-1 -> 0.095152603 | AZ25: =AZ19/AV19-1 -> -0.053432282 | BA25: =BA19/AW19-1 -> -0.059053578 | BB25: =BB19/AX19-1 -> -0.11042945 | BC25: =BC19/AY19-1 -> -0.14721311 | BD25: =BD19/AZ19-1 -> 0.040376323 | BE25: =BE19/BA19-1 -> 0.098503741 | BF25: =BF19/BB19-1 -> 0.031941924 | ... BQ25: =BQ19/BM19-1 -> -1 | CM25: =CM19/CL19-1 -> -0.033411173 | CN25: =CN19/CM19-1 -> -0.0019513102 | CO25: =CO19/CN19-1 -> 0.010799739 | CP25: =CP19/CO19-1 -> 0.089251174
B26: APAC Growth Y/y | AY26: =AY20/AU20-1 -> 0.20772382 | AZ26: =AZ20/AV20-1 -> 0.1675243 | BA26: =BA20/AW20-1 -> 0.073529412 | BB26: =BB20/AX20-1 -> 0.059251559 | BC26: =BC20/AY20-1 -> -0.037790698 | BD26: =BD20/AZ20-1 -> -0.068560235 | BE26: =BE20/BA20-1 -> -0.029426687 | BF26: =BF20/BB20-1 -> 0.016683023 | ... BQ26: =BQ20/BM20-1 -> -1 | CM26: =CM20/CL20-1 -> 0.12427265 | CN26: =CN20/CM20-1 -> -0.029821319 | CO26: =CO20/CN20-1 -> 0.01054236 | CP26: =CP20/CO20-1 -> 0.018225239
B27: Other Regions Growth Y/y | AY27: =AY21/AU21-1 -> 0.22508039 | AZ27: =AZ21/AV21-1 -> 0.15 | BA27: =BA21/AW21-1 -> 0.22909091 | BB27: =BB21/AX21-1 -> 0.21019108 | BC27: =BC21/AY21-1 -> -0.094488189 | BD27: =BD21/AZ21-1 -> 0.20869565 | BE27: =BE21/BA21-1 -> 0.035502959 | BF27: =BF21/BB21-1 -> -0.034210526 | ... BQ27: =BQ21/BM21-1 -> 28.245783 | CM27: =CM21/CL21-1 -> 0.20333333 | CN27: =CN21/CM21-1 -> 0.024238227 | CO27: =CO21/CN21-1 -> 0.055442867 | CP27: =CP21/CO21-1 -> 0.02306214
B28: Ttl Revenue Growth Y/y | AY28: =AY22/AU22-1 -> 0.19301433 | AZ28: =AZ22/AV22-1 -> 0.18300442 | BA28: =BA22/AW22-1 -> 0.14437299 | BB28: =BB22/AX22-1 -> 0.069893478 | BC28: =BC22/AY22-1 -> -0.093755289 | BD28: =BD22/AZ22-1 -> -0.02579763 | BE28: =BE22/BA22-1 -> -0.0096469046 | BF28: =BF22/BB22-1 -> -0.049257642 | ... BQ28: =BQ22/BM22-1 -> 0.091260565 | CM28: =CM22/CL22-1 -> 0.14546938 | CN28: =CN22/CM22-1 -> -0.045819882 | CO28: =CO22/CN22-1 -> 0.00049000163 | CP28: =CP22/CO22-1 -> 0.03915761
B30: North America % of Ttl Revenues | AU30: =AU18/AU22 -> 0.51494044 | AV30: =AV18/AV22 -> 0.4884072 | AW30: =AW18/AW22 -> 0.49967846 | AX30: =AX18/AX22 -> 0.50149505 | AY30: =AY18/AY22 -> 0.53503131 | AZ30: =AZ18/AZ22 -> 0.54986326 | BA30: =BA18/BA22 -> 0.55839655 | BB30: =BB18/BB22 -> 0.54820961 | ... BQ30: =BQ18/BQ22 -> 0 | CL30: =CL18/CL22 -> 0.50136441 | CM30: =CM18/CM22 -> 0.54756763 | CN30: =CN18/CN22 -> 0.53116177 | CO30: =CO18/CO22 -> 0.52483791 | CP30: =CP18/CP22 -> 0.51693337
B31: Euro % of Ttl Revenues | AU31: =AU19/AU22 -> 0.28114274 | AV31: =AV19/AV22 -> 0.29062871 | AW31: =AW19/AW22 -> 0.27406217 | AX31: =AX19/AX22 -> 0.28938516 | AY31: =AY19/AY22 -> 0.25808089 | AZ31: =AZ19/AZ22 -> 0.2325433 | BA31: =BA19/BA22 -> 0.2253442 | BB31: =BB19/BB22 -> 0.24061135 | ... BQ31: =BQ19/BQ22 -> 0 | CL31: =CL19/CL22 -> 0.28395093 | CM31: =CM19/CM22 -> 0.23960815 | CN31: =CN19/CN22 -> 0.25062417 | CO31: =CO19/CO22 -> 0.25320677 | CP31: =CP19/CP22 -> 0.26541284
B32: APAC % of Ttl Revenues | AU32: =AU20/AU22 -> 0.1725217 | AV32: =AV20/AV22 -> 0.1886121 | AW32: =AW20/AW22 -> 0.19678457 | AX32: =AX20/AX22 -> 0.17977948 | AY32: =AY20/AY22 -> 0.17464884 | AZ32: =AZ20/AZ22 -> 0.18614403 | BA32: =BA20/BA22 -> 0.18460242 | BB32: =BB20/BB22 -> 0.17799127 | ... BQ32: =BQ20/BQ22 -> 0 | CL32: =CL20/CL22 -> 0.184081 | CM32: =CM20/CM22 -> 0.18067461 | CN32: =CN20/CN22 -> 0.18370395 | CO32: =CO20/CO22 -> 0.1855497 | CP32: =CP20/CP22 -> 0.18181206
B33: Other Regions % of Ttl Revenues | AU33: =AU21/AU22 -> 0.031395114 | AV33: =AV21/AV22 -> 0.03235199 | AW33: =AW21/AW22 -> 0.029474812 | AX33: =AX21/AX22 -> 0.02934031 | AY33: =AY21/AY22 -> 0.032238958 | AZ33: =AZ21/AZ22 -> 0.031449407 | BA33: =BA21/BA22 -> 0.031656832 | BB33: =BB21/BB22 -> 0.033187773 | ... BQ33: =BQ21/BQ22 -> 1 | CL33: =CL21/CL22 -> 0.030603657 | CM33: =CM21/CM22 -> 0.032149616 | CN33: =CN21/CN22 -> 0.034510115 | CO33: =CO21/CO22 -> 0.036405616 | CP33: =CP21/CP22 -> 0.035841731
B35: Bioscience | BK35: 993 | BL35: 1075 | BM35: 1023 | BN35: =4169-SUM(BK35:BM35) -> 1078 | BO35: 981 | BP35: 1060 | CN35: 4238 | CO35: 4192 | CP35: =SUM(BK35:BN35) -> 4169
B36: Genetic Sciences | BK36: 677 | BL36: 679 | BM36: 720 | BN36: =2870-SUM(BK36:BM36) -> 794 | BO36: 655 | BP36: 703 | CN36: 2816 | CO36: 2787 | CP36: =SUM(BK36:BN36) -> 2870
B37: Bioproduction | BK37: 671 | BL37: 745 | BM37: 817 | BN37: =3200-SUM(BK37:BM37) -> 967 | BO37: 893 | BP37: 941 | CN37: 2923 | CO37: 2652 | CP37: =SUM(BK37:BN37) -> 3200
B38: Other | BK38: 0 | BL38: 0 | BM38: 28 | BN38: =136-SUM(BK38:BM38) -> 108 | BO38: 107 | BP38: 112 | CN38: 1 | CO38: 0 | CP38: =SUM(BK38:BN38) -> 136
B39: Life Science Solutions | BK39: =SUM(BK35:BK38) -> 2341 | BL39: =SUM(BL35:BL38) -> 2499 | BM39: =SUM(BM35:BM38) -> 2588 | BN39: =SUM(BN35:BN38) -> 2947 | BO39: =SUM(BO35:BO38) -> 2636 | BP39: =SUM(BP35:BP38) -> 2816 | BQ39: =SUM(BQ35:BQ38) -> 0 | CN39: 9977 | CO39: 9631 | CP39: =SUM(BK39:BN39) -> 10375
B40: Chromatography & Spectrometry | BK40: 773 | BL40: 784 | BM40: 841 | BN40: =3360-SUM(BK40:BM40) -> 962 | BO40: 798 | BP40: 821 | CN40: 3329 | CO40: 3278 | CP40: =SUM(BK40:BN40) -> 3360
B41: Chemical Analysis | BK41: 286 | BL41: 292 | BM41: 320 | BN41: =1237-SUM(BK41:BM41) -> 339 | BO41: 285 | BP41: 318 | CN41: 1371 | CO41: 1315 | CP41: =SUM(BK41:BN41) -> 1237
B42: Electronic Microscopy | BK42: 659 | BL42: 652 | BM42: 732 | BN42: =2957-SUM(BK42:BM42) -> 914 | BO42: 633 | BP42: 707 | CN42: 2564 | CO42: 2870 | CP42: =SUM(BK42:BN42) -> 2957
B43: Analytical Instruments | BK43: =SUM(BK40:BK42) -> 1718 | BL43: =SUM(BL40:BL42) -> 1728 | BM43: =SUM(BM40:BM42) -> 1893 | BN43: =SUM(BN40:BN42) -> 2215 | BO43: =SUM(BO40:BO42) -> 1716 | BP43: =SUM(BP40:BP42) -> 1846 | BQ43: =SUM(BQ40:BQ42) -> 0 | CN43: 7263 | CO43: 7463 | CP43: =SUM(BK43:BN43) -> 7554
B44: Clinical Diagnostics | BK44: 263 | BL44: 276 | BM44: 283 | BN44: =1115-SUM(BK44:BM44) -> 293 | BO44: 271 | BP44: 290 | CN44: 1104 | CO44: 1063 | CP44: =SUM(BK44:BN44) -> 1115
B45: ImmunoDiagnostics | BK45: 217 | BL45: 234 | BM45: 230 | BN45: =912-SUM(BK45:BM45) -> 231 | BO45: 230 | BP45: 248 | CN45: 802 | CO45: 864 | CP45: =SUM(BK45:BN45) -> 912
B46: Microbiology | BK46: 152 | BL46: 159 | BM46: 162 | BN46: =645-SUM(BK46:BM46) -> 172 | BO46: 160 | BP46: 166 | CN46: 618 | CO46: 633 | CP46: =SUM(BK46:BN46) -> 645
...

Sheet Notes | Quant Analysis
CC1: 0
H2: TMO Employee Snapshot (Q4'25) | AF2: General Notes/Observations (Updated Q2'25)
I32: Notes: | J32: [X]
J33: [Y]
J34: [Z]
H36: Institutional Ownership Snapshot (8/24/2026) | AF36: Financial Stmts. Notes/Observations (Updated Q2'25)
AF37: Revenues:
I71: Notes: | J71: [X]
J72: [Y]
J73: [Z]
H75: Revenue Breakdown by Segment (Build graph for this section if applicable…. See example below)
I107: Notes: | J107: [X]
J108: [Y]
J109: [Z]
H111: Total Revenues, Net Income, FCF
I140: Notes: | J140: [X]
J141: [Y]
J142: [Z]
H144: Total Revenues, Net Income, FCF
AF149: Earnings Scope:
I173: Notes: | J173: [X]
J174: [Y]
J175: [Z]
H177: [TMO] Historical Return Histogram
A195: 1256 Trading Days? (From: 9/21/20 - 9/21/25)
A196: Close | B196: High | C196: Low | D196: Open | E196: Volume | F196: UTC Date | G196: Change
A197: 479.58 | B197: 487.99 | C197: 478.0201 | D197: 483.29 | E197: 4244050 | F197: Fri, 19 Sep 2025 00:00:00 GMT | G197: =A197/D197-1 -> -0.0076765503
A198: 481.1 | B198: 482.255 | C198: 473.03 | D198: 477.15 | E198: 1563249 | F198: Thu, 18 Sep 2025 00:00:00 GMT | G198: =A198/D198-1 -> 0.0082783192
A199: 472.64 | B199: 486.57 | C199: 469.14 | D199: 482.96 | E199: 1947751 | F199: Wed, 17 Sep 2025 00:00:00 GMT | G199: =A199/D199-1 -> -0.021368229
A200: 480.74 | B200: 484.59 | C200: 470.05 | D200: 470.27 | E200: 1798297 | F200: Tue, 16 Sep 2025 00:00:00 GMT | G200: =A200/D200-1 -> 0.022263806
A201: 474.46 | B201: 482.94 | C201: 470.74 | D201: 478.78 | E201: 1663465 | F201: Mon, 15 Sep 2025 00:00:00 GMT | G201: =A201/D201-1 -> -0.0090229333
A202: 479.46 | B202: 491.26 | C202: 479.46 | D202: 488.61 | E202: 1538547 | F202: Fri, 12 Sep 2025 00:00:00 GMT | G202: =A202/D202-1 -> -0.018726592
A203: 491.41 | B203: 492 | C203: 480.3575 | D203: 480.575 | E203: 1505086 | F203: Thu, 11 Sep 2025 00:00:00 GMT | G203: =A203/D203-1 -> 0.022545909
A204: 476.54 | B204: 485.8199 | C204: 475.635 | D204: 481.12 | E204: 1442005 | F204: Wed, 10 Sep 2025 00:00:00 GMT | G204: =A204/D204-1 -> -0.0095194546
A205: 482.41 | B205: 489.99 | C205: 481.52 | D205: 486.48 | E205: 1501000 | F205: Tue, 09 Sep 2025 00:00:00 GMT | G205: =A205/D205-1 -> -0.0083662227
A206: 487.65 | B206: 490.065 | C206: 480.95 | D206: 487.77 | E206: 2222973 | F206: Mon, 08 Sep 2025 00:00:00 GMT | G206: =A206/D206-1 -> -0.00024601759
A207: 492.6 | B207: 502 | C207: 489.12 | D207: 490 | E207: 1440451 | F207: Fri, 05 Sep 2025 00:00:00 GMT | G207: =A207/D207-1 -> 0.0053061224 | J207: Min | K207: =MIN(G197:G1452) -> -0.070595797
A208: 489.49 | B208: 490.26 | C208: 471.61 | D208: 482.08 | E208: 1391914 | F208: Thu, 04 Sep 2025 00:00:00 GMT | G208: =A208/D208-1 -> 0.015370893 | J208: Max | K208: =MAX(G197:G1452) -> 0.093866821
A209: 484.55 | B209: 489.54 | C209: 481.53 | D209: 487.03 | E209: 1213141 | F209: Wed, 03 Sep 2025 00:00:00 GMT | G209: =A209/D209-1 -> -0.0050920888 | J209: Mean μ | K209: =AVERAGE(G197:G1452) -> -9.5221812e-05
A210: 487.53 | B210: 492.7 | C210: 479.03 | D210: 489.31 | E210: 1289669 | F210: Tue, 02 Sep 2025 00:00:00 GMT | G210: =A210/D210-1 -> -0.0036377756 | J210: Median | K210: =MEDIAN(G197:G1452) -> -8.5423273e-05
...

Sheet Consumables

Sheet Instruments

Sheet Services

Sheet Management

Sheet Table Formatting
B2: [Bold Title] | G2: [Bold Title]
B3: Line Titles | G3: <-- General
B4: Line Titles | G4: <-- Info
B5: Line Titles | G5: <-- General
B6: Line Titles | G6: <-- Info
B7: Line Titles | G7: <-- General
B8: Line Titles | G8: <-- Info
